Workbook

Sheet NECESIDADES TRIMESTRALES
B1: Pedido de Necesidades Trimestrales
A3: JURISDICCION: | C3: 30 - MINISTERIO DE HACIENDA PUBLICA
A4: SAF N°: | C4: SAF 9 - DIRECCION PROVINCIAL DE ADMINISTRACION DE LA SECRETARIA DE FINANZAS PUBLICAS
A5: EJERCICIO: | C5: 2021
A6: TRIMESTRE: | C6: 3
A7: ID | B7: CODIGO ITEM | C7: RUBRO DE COMPRA | D7: I.P.P. | E7: DESCRIPCION | F7: UNIDAD DE MEDIDA | G7: CANTIDAD | H7: PRECIO UNITARIO ESTIMADO | I7: IMPORTE TOTAL ESTIMADO
A8: 1 | B8: 2.5.2-711.33 | C8: PROD. MEDICO/FARMACEUTICOS/LAB | D8: 2.5.2 | E8: ALCOHOL USO MEDICINAL; PUREZA: 70 %, PRESENTACION: ENVASE X 500 CM3 | F8: UNIDAD | G8: =+'NP - MHP'!G11+'NP - SAF'!G11+'NP - FINANZAS'!G11+'NP - TGP'!G11+'NP - SSP'!G11+'NP - CGP'!G13+'NP - CAU'!G11+'NP - CP'!G11 -> 121 | H8: 275 | I8: =H8*G8 -> 33275
A9: 2 | B9: 2.5.2-711.15 | C9: PROD. MEDICO/FARMACEUTICOS/LAB | D9: 2.5.2 | E9: ALCOHOL USO MEDICINAL; PUREZA: 70 %, PRESENTACION: ENVASE X 1 L | F9: UNIDAD | G9: =+'NP - MHP'!G12+'NP - SAF'!G12+'NP - SCyA'!G12+'NP - FINANZAS'!G12+'NP - TGP'!G12+'NP - SSP'!G12+'NP - CGP'!G12+'NP - CAU'!G12 -> 247 | H9: 260 | I9: =H9*G9 -> 64220
A10: 3 | B10: 2.5.2-711.45 | C10: PROD. MEDICO/FARMACEUTICOS/LAB | D10: 2.5.2 | E10: ALCOHOL USO MEDICINAL; PUREZA: 70 %, PRESENTACION: GEL ENVASE X 1 L | F10: UNIDAD | G10: =+'NP - MHP'!G13+'NP - SAF'!G13+'NP - FINANZAS'!G13+'NP - TGP'!G13+'NP - CAU'!G13 -> 61 | H10: 450 | I10: =H10*G10 -> 27450
A11: 4 | B11: 2.5.2-711.24 | C11: PROD. MEDICO/FARMACEUTICOS/LAB | D11: 2.5.2 | E11: ALCOHOL USO MEDICINAL; PUREZA: 70 %, PRESENTACION: GEL EN ENVASE X 5 L | F11: UNIDAD | G11: =+'NP - CGP'!G11 -> 10 | H11: 1300 | I11: =H11*G11 -> 13000
A12: 5 | B12: 2.9.5-428.19 | C12: PROD. MEDICO/FARMACEUTICOS/LAB | D12: 2.9.5 | E12: BARBIJOS; TIPO: PLISADO | F12: UNIDAD | G12: =+'NP - MHP'!G14+'NP - SAF'!G14+'NP - FINANZAS'!G14+'NP - TGP'!G14+'NP - SSP'!G13+'NP - CAU'!G14+'NP - CP'!G12 -> 330 | H12: 650 | I12: =H12*G12 -> 214500
A13: 6 | B13: 2.5.2-710.1 | C13: PROD. MEDICO/FARMACEUTICOS/LAB | D13: 2.5.2 | E13: AGUA OXIGENADA; CAPACIDAD: 100 CM3, VOLUMEN: 10, PRESENTACION: ENVASE X 100 CM3 | F13: UNIDAD | G13: =+'NP - SCyA'!G11 -> 1 | H13: 100 | I13: =H13*G13 -> 100
A14: 7 | B14: 2.9.5-470.14 | C14: PROD. MEDICO/FARMACEUTICOS/LAB | D14: 2.9.5 | E14: ALGODONES; CAPACIDAD: 200 GR, TIPO: PLISADO, PRESENTACION: ENVASE X 200 GR | F14: UNIDAD | G14: =+'NP - SCyA'!G13 -> 1 | H14: 200 | I14: =H14*G14 -> 200
A15: 8 | B15: 2.5.2-1724.121 | C15: PROD. MEDICO/FARMACEUTICOS/LAB | D15: 2.5.2 | E15: ANALGESICOS ; TIPO: MONODROGA, DROGA GENERICA: IBUPROFENO 400 mGr, FORMA FARMACEUTICA: COMPRIMIDO, PRESENTACION: ENVASE X 10 UN | F15: CAJA | G15: =+'NP - SCyA'!G14 -> 2 | H15: 100 | I15: =H15*G15 -> 200
A16: 9 | B16: 2.5.2-1723.14 | C16: PROD. MEDICO/FARMACEUTICOS/LAB | D16: 2.5.2 | E16: ANTISEPTICOS LOCALES P/PERSONA; DROGA GENERICA: POVIDONA IODADA, FORMA FARMACEUTICA: SOLUCION, PRESENTACION: FRASCO X 100 mL, TIPO: MONODROGA | F16: FRASCO | G16: =+'NP - SCyA'!G15 -> 1 | H16: 400 | I16: =H16*G16 -> 400
A17: 10 | B17: 2.9.5-427.23 | C17: PROD. MEDICO/FARMACEUTICOS/LAB | D17: 2.9.5 | E17: APOSITOS; TIPO: TELA ADHESIVA, TAMAÑO: MEDIANO X 10 UN | F17: CAJA | G17: =+'NP - SCyA'!G16 -> 2 | H17: 90 | I17: =H17*G17 -> 180
A18: 11 | B18: 4.3.3-65.20 | C18: PROD. MEDICO/FARMACEUTICOS/LAB | D18: 295 | E18: BOTIQUINES PRIMEROS AUXILIOS; MEDIDA: 31 X 42 X 15 Cm, MATERIAL: PLASTICO | F18: UNIDAD | G18: =+'NP - SCyA'!G17 -> 1 | H18: 1100 | I18: =H18*G18 -> 1100
A19: 12 | B19: 2.9.5-473.16 | C19: PROD. MEDICO/FARMACEUTICOS/LAB | D19: 2.9.5 | E19: GASAS; MEDIDA: 10 X 10 Cm, UNIDAD VENTA: CAJA X 20 UN, TIPO: FURANIZADA, PRESENTACION: CAJA X 20 UN | F19: CAJA | G19: =+'NP - SCyA'!G18 -> 1 | H19: 900 | I19: =H19*G19 -> 900
A20: 13 | B20: 2.9.5-931.1 | C20: PROD. MEDICO/FARMACEUTICOS/LAB | D20: 2.9.5 | E20: TELAS ADHESIVAS; ANCHO: 1.25 Cm, LONG.DE CUERPO: 9 M, TIPO: HIPOALERGENICA | F20: UNIDAD | G20: =+'NP - SCyA'!G19 -> 2 | H20: 275 | I20: =H20*G20 -> 550
G21: =+'NP - MHP'!G16+'NP - SAF'!G16+'NP - SCyA'!G21+'NP - FINANZAS'!G16+'NP - TGP'!G16+'NP - SSP'!G15+'NP - CGP'!G15+'NP - CAU'!G16+'NP - CP'!G14 -> 780 | H21: CONTROL | I21: =+'APG - MHP'!Q18+'APG - SAF'!Q18+'APG - SCyA'!Q22+'APG - FINANZAS'!Q18+'APG - TGP'!Q22+'APG - SSP'!Q18+'APG - CGP'!Q23+'APG - CAU'!Q19+'APG - CP'!Q19 -> 366905
B23: PARA TODOS LOS ITEMS: El plazo de entrega no podrá ser superior a los diez (10) días hábiles a partir de la fecha de recepción de la respectiva Orden de Compra en el domicilio especial electrónico constituido, en virtud del método de contratación.
B28: Manteniniento de Oferta: 45 días
B30: Lugares de Entrega:
B31: Ministerio de Hacienda Pública - Sarmiento 589, 8vo Piso
B32: Secretaría de Finanzas Públicas - Sarmiento 589, 8vo Piso
B33: Subsecretaría de Presupuesto - Sarmiento 589, 7mo piso
B34: Dir. Prov. De Adm. De Finanzas - Sarmiento 589, 5to piso
B35: Dir. Prov. De Credito Público - Sarmiento 589, 5to piso
B36: Centro de Ayuda a Usuarios - Sarmiento 589, 5to piso
B37: Contaduria Gral. de la Prov. - Av Venezuela S/N - CAPE Pabellón 21
B38: Sec. De Compras y Abastecimiento - Av Venezuela S/N - CAPE Pabellón 21
B39: Tesorería Gral de la Prov. - Av Venezuela S/N - CAPE Pabellón 21
B41: Especificidades Item N°: | D41: 1
B43: Descripción técnica
B44: Alcohol - 70% - 500cc - con rociador - tipo Bialcohol Porta
B48: Especificidades Item N°: | D48: 2
B50: Descripción técnica
B51: Alcohol - 70% - para reponer - 1 litro (o equivalente en bidones de 5 litros) - tipo Bialcohol Porta
B55: Especificidades Item N°: | D55: 3
B57: Descripción técnica
...

Sheet NP - MHP
A1: NOTA DE PEDIDO | F1: Nº | G1: 05/2021
A4: JURISDICCION: | C4: 30 - MINISTERIO DE HACIENDA PUBLICA
A5: SAF N°: | C5: SAF 9 - DIRECCION PROVINCIAL DE ADMINISTRACION DE LA SECRETARIA DE FINANZAS PUBLICAS
A6: UNIDAD EJECUTORA | C6: MINISTERIO DE HACIENDA PUBLICA
A7: DEPENDENCIA SOLICITANTE | C7: MINISTERIO DE HACIENDA PUBLICA
A8: TRIMESTRE: | C8: TERCER TRIMESTRE 2021
A9: OBJETO | C9: Adquisicion de elementos de higiene y cuidado personal para el Ministerio de Hacienda Pública
A10: ID | B10: CODIGO | C10: DESCRIPCION | D10: ADJUNTA DETALLE TECNICO | E10: UNIDAD DE MEDIDA | F10: PRECIO UNITARIO ESTIMADO | G10: CANTIDAD
A11: 1 | B11: 2.5.2-711.33 | C11: ALCOHOL USO MEDICINAL; PUREZA: 70 %, PRESENTACION: ENVASE X 500 CM3 | D11: SI | E11: UNIDAD | F11: 350 | G11: 20 | H11: =+G11*F11 -> 7000
A12: 2 | B12: 2.5.2-711.15 | C12: ALCOHOL USO MEDICINAL; PUREZA: 70 %, PRESENTACION: ENVASE X 1 L | D12: SI | E12: UNIDAD | F12: 275 | G12: 20 | H12: =+G12*F12 -> 5500
A13: 3 | B13: 2.5.2-711.45 | C13: ALCOHOL USO MEDICINAL; PUREZA: 70 %, PRESENTACION: GEL ENVASE X 1 L | D13: SI | E13: UNIDAD | F13: 450 | G13: 15 | H13: =+G13*F13 -> 6750
A14: 4 | B14: 2.9.5-428.19 | C14: BARBIJOS; TIPO: PLISADO | D14: SI | E14: UNIDAD | F14: 650 | G14: 30 | H14: =+G14*F14 -> 19500
B15: COSTO TOTAL ESTIMADO | C15: PESOS TREINTA Y OCHO MIL SETECIENTOS CINCUENTA CON 00/100 | F15: =+H14+H13+H12+H11+H10+H9+H8 -> 38750
G16: =+G14+G13+G12+G11 -> 85

Sheet APG - MHP
A1: EJERCICIO: | D1: =+'[1]NECESIDADES TRIMESTRALES'!C6 -> 2021 | P1: AUTORIZACION PARA GASTAR
A4: JURISDICCIÓN: | G4: 30 - Ministerio de Hacienda Publica
A5: SAF: | G5: 9 - Direccion Provincial de Administracion de la Secretaria de Finanzas Publicas
A6: UNIDAD EJECUTORA: | G6: MINISTERIO DE HACIENDA PUBLICA
A7: DEPENDENCIA SOLICITANTE: | G7: MINISTERIO DE HACIENDA PUBLICA
A8: AUTORIZACIÓN:
A9: Señor Jefe de Servicio Administrativo Financiero:
A10: Autorizo la realización de los trámites correspondientes, a fin de proveer a este Organismo los bienes y/o servicios que se detallan en Nota de Pedido N° 05/2021, afectando la erogación resultante a los créditos presupuestarios aprobados a favor de esta Unidad Ejecutora, conforme al siguiente detalle.
A12: IMPUTACIÓN PRESUPUESTARIA
A13: CÓDIGO | O13: DENOMINACIÓN DE LA PARTIDA PRESUPUESTARIA | Q13: IMPORTE
A14: PR | B14: SB | C14: PY | D14: AC | E14: OB | F14: UG | G14: FIN | H14: FUN | I14: I | J14: P | K14: P | L14: SubP | M14: M | N14: FF
A15: 1 | B15: 0 | C15: 0 | D15: 1 | E15: 0 | F15: 4901 | G15: 1 | H15: 3 | I15: 2 | J15: 5 | K15: 2 | L15: 0 | M15: 1 | N15: 1.1 | O15: Productos Farmacéuticos y Medicinales | Q15: 19250
A16: 1 | B16: 0 | C16: 0 | D16: 1 | E16: 0 | F16: 4901 | G16: 1 | H16: 3 | I16: 2 | J16: 9 | K16: 5 | L16: 0 | M16: 1 | N16: 1.1 | O16: Utiles Menores Médico, Quirúrgico y de Laboratorio | Q16: 19500
A18: TOTAL DE PESOS: TREINTA Y OCHO MIL SETECIENTOS CINCUENTA CON 00/100 | Q18: =SUM(Q15:Q17) -> 38750
A20: JUSTIFICACIÓN:
A21: Adquisicion de elementos de higiene y cuidado personal para el Ministerio de Hacienda Pública
A23: OBSERVACIONES:

Sheet NP - SAF
A1: NOTA DE PEDIDO | F1: Nº | G1: 178/2021
A4: JURISDICCION: | C4: 30 - MINISTERIO DE HACIENDA PUBLICA
A5: SAF N°: | C5: SAF 9 - DIRECCION PROVINCIAL DE ADMINISTRACION DE LA SECRETARIA DE FINANZAS PUBLICAS
A6: UNIDAD EJECUTORA | C6: DIRECCION PROVINCIAL DE ADMINISTRACION DE LA SECRETARIA DE FINANZAS PUBLICAS
A7: DEPENDENCIA SOLICITANTE | C7: DIRECCION PROVINCIAL DE ADMINISTRACION DE LA SECRETARIA DE FINANZAS PUBLICAS
A8: TRIMESTRE: | C8: TERCER TRIMESTRE 2021
A9: OBJETO | C9: Adquisicion de elementos de higiene y cuidado personal
A10: ID | B10: CODIGO | C10: DESCRIPCION | D10: ADJUNTA DETALLE TECNICO | E10: UNIDAD DE MEDIDA | F10: PRECIO UNITARIO ESTIMADO | G10: CANTIDAD
A11: 1 | B11: 2.5.2-711.33 | C11: ALCOHOL USO MEDICINAL; PUREZA: 70 %, PRESENTACION: ENVASE X 500 CM3 | D11: SI | E11: UNIDAD | F11: 350 | G11: 15 | H11: =+G11*F11 -> 5250
A12: 2 | B12: 2.5.2-711.15 | C12: ALCOHOL USO MEDICINAL; PUREZA: 70 %, PRESENTACION: ENVASE X 1 L | D12: SI | E12: UNIDAD | F12: 275 | G12: 20 | H12: =+G12*F12 -> 5500
A13: 3 | B13: 2.5.2-711.45 | C13: ALCOHOL USO MEDICINAL; PUREZA: 70 %, PRESENTACION: GEL ENVASE X 1 L | D13: SI | E13: UNIDAD | F13: 450 | G13: 15 | H13: =+G13*F13 -> 6750
A14: 4 | B14: 2.9.5-428.19 | C14: BARBIJOS; TIPO: PLISADO | D14: SI | E14: UNIDAD | F14: 650 | G14: 80 | H14: =+G14*F14 -> 52000
B15: COSTO TOTAL ESTIMADO | C15: PESOS SESENTA Y NUEVE MIL QUINIENTOS CON 00/100 | F15: =+H14+H13+H12+H11 -> 69500
G16: =+G13+G14+G12+G11 -> 130

Sheet APG - SAF
A1: EJERCICIO: | D1: =+'[2]NECESIDADES TRIMESTRALES'!C6 -> 2021 | P1: AUTORIZACION PARA GASTAR
A4: JURISDICCIÓN: | G4: 30 - Ministerio de Hacienda Publica
A5: SAF: | G5: 9 - Direccion Provincial de Administracion de la Secretaria de Finanzas Publicas
A6: UNIDAD EJECUTORA: | G6: DIRECCION PROVINCIAL DE ADMINISTRACION DE LA SECRETARIA DE FINANZAS PUBLICAS
A7: DEPENDENCIA SOLICITANTE: | G7: DIRECCION PROVINCIAL DE ADMINISTRACION DE LA SECRETARIA DE FINANZAS PUBLICAS
A8: AUTORIZACIÓN:
A9: Señor Jefe de Servicio Administrativo Financiero:
A10: Autorizo la realización de los trámites correspondientes, a fin de proveer a este Organismo los bienes y/o servicios que se detallan en Nota de Pedido N° 178/2021, afectando la erogación resultante a los créditos presupuestarios aprobados a favor de esta Unidad Ejecutora, conforme al siguiente detalle.
A12: IMPUTACIÓN PRESUPUESTARIA
A13: CÓDIGO | O13: DENOMINACIÓN DE LA PARTIDA PRESUPUESTARIA | Q13: IMPORTE
A14: PR | B14: SB | C14: PY | D14: AC | E14: OB | F14: UG | G14: FIN | H14: FUN | I14: I | J14: P | K14: P | L14: SubP | M14: M | N14: FF
A15: 2 | B15: 0 | C15: 0 | D15: 1 | E15: 0 | F15: 4901 | G15: 1 | H15: 6 | I15: 2 | J15: 5 | K15: 2 | L15: 0 | M15: 1 | N15: 1.1 | O15: Productos Farmacéuticos y Medicinales | Q15: 17500
A16: 2 | B16: 0 | C16: 0 | D16: 1 | E16: 0 | F16: 4901 | G16: 1 | H16: 6 | I16: 2 | J16: 9 | K16: 5 | L16: 0 | M16: 1 | N16: 1.1 | O16: Utiles Menores Médico, Quirúrgico y de Laboratorio | Q16: 52000
A18: TOTAL DE PESOS: SESENTA Y NUEVE MIL QUINIENTOS CON 00/100 | Q18: =SUM(Q15:Q17) -> 69500
A20: JUSTIFICACIÓN:
A21: Adquisicion de elementos de higiene y cuidado personal
A23: OBSERVACIONES:

Sheet NP - SCyA
A1: NOTA DE PEDIDO | F1: Nº | G1: 98/2021
A4: JURISDICCION: | C4: 30 - MINISTERIO DE HACIENDA PUBLICA
A5: SAF N°: | C5: SAF 9 - DIRECCION PROVINCIAL DE ADMINISTRACION DE LA SECRETARIA DE FINANZAS PUBLICAS
A6: UNIDAD EJECUTORA | C6: SECRETARIA DE COMPRAS Y ABASTECIMIENTO
A7: DEPENDENCIA SOLICITANTE | C7: SECRETARIA DE COMPRAS Y ABASTECIMIENTO
A8: TRIMESTRE: | C8: TERCER TRIMESTRE 2021
A9: OBJETO | C9: Adquisicion de elementos e insumos medicos para el armado de un botiquin destinado a la S.C.A-M.H.P.
A10: ID | B10: CODIGO | C10: DESCRIPCION | D10: ADJUNTA DETALLE TECNICO | E10: UNIDAD DE MEDIDA | F10: PRECIO UNITARIO ESTIMADO | G10: CANTIDAD
A11: 1 | B11: 2.5.2-710.1 | C11: AGUA OXIGENADA; CAPACIDAD: 100 CM3, VOLUMEN: 10, PRESENTACION: ENVASE X 100 CM3 | D11: NO | E11: UNIDAD | F11: 100 | G11: 1 | H11: =+G11*F11 -> 100
A12: 2 | B12: 2.5.2-711.15 | C12: ALCOHOL USO MEDICINAL; PUREZA: 70 %, PRESENTACION: ENVASE X 1 L | D12: NO | E12: UNIDAD | F12: 260 | G12: 90 | H12: =+G12*F12 -> 23400
A13: 3 | B13: 2.9.5-470.14 | C13: ALGODONES; CAPACIDAD: 200 GR, TIPO: PLISADO, PRESENTACION: ENVASE X 200 GR | D13: NO | E13: UNIDAD | F13: 200 | G13: 1 | H13: =+G13*F13 -> 200
A14: 4 | B14: 2.5.2-1724.121 | C14: ANALGESICOS ; TIPO: MONODROGA, DROGA GENERICA: IBUPROFENO 400 mGr, FORMA FARMACEUTICA: COMPRIMIDO, PRESENTACION: ENVASE X 10 UN | D14: NO | E14: CAJA | F14: 100 | G14: 2 | H14: =+G14*F14 -> 200
A15: 5 | B15: 2.5.2-1723.14 | C15: ANTISEPTICOS LOCALES P/PERSONA; DROGA GENERICA: POVIDONA IODADA, FORMA FARMACEUTICA: SOLUCION, PRESENTACION: FRASCO X 100 mL, TIPO: MONODROGA | D15: NO | E15: FRASCO | F15: 400 | G15: 1 | H15: =+G15*F15 -> 400
A16: 6 | B16: 2.9.5-427.23 | C16: APOSITOS; TIPO: TELA ADHESIVA, TAMAÑO: MEDIANO X 10 UN | D16: NO | E16: CAJA | F16: 90 | G16: 2 | H16: =+G16*F16 -> 180
A17: 7 | B17: 4.3.3-65.20 | C17: BOTIQUINES PRIMEROS AUXILIOS; MEDIDA: 31 X 42 X 15 Cm, MATERIAL: PLASTICO | D17: NO | E17: UNIDAD | F17: 1100 | G17: 1 | H17: =+G17*F17 -> 1100
A18: 8 | B18: 2.9.5-473.16 | C18: GASAS; MEDIDA: 10 X 10 Cm, UNIDAD VENTA: CAJA X 20 UN, TIPO: FURANIZADA, PRESENTACION: CAJA X 20 UN | D18: NO | E18: CAJA | F18: 900 | G18: 1 | H18: =+G18*F18 -> 900
A19: 9 | B19: 2.9.5-931.1 | C19: TELAS ADHESIVAS; ANCHO: 1.25 Cm, LONG.DE CUERPO: 9 M, TIPO: HIPOALERGENICA | D19: NO | E19: UNIDAD | F19: 275 | G19: 2 | H19: =+G19*F19 -> 550
B20: COSTO TOTAL ESTIMADO | C20: PESOS VEINTE MIL TREINTA CON 00/100.- | F20: =+H19+H18+H17+H16+H15+H14+H13+H12+H11 -> 27030
G21: =+G19+G18+G17+G16+G15+G14+G13+G12+G11 -> 101

Sheet APG - SCyA
A1: EJERCICIO: | D1: ='[3]Necesidades Trimestrales'!C6 -> 2021 | P1: AUTORIZACION PARA GASTAR
A4: JURISDICCIÓN: | G4: 30 - Ministerio de Hacienda Publica
A5: SAF: | G5: 9 - Direccion Provincial de Administracion de la Secretaria de Finanzas Publicas
A6: UNIDAD EJECUTORA: | G6: Secretaria de Compras y Abastecimiento
A7: DEPENDENCIA SOLICITANTE: | G7: Secretaria de Compras y Abastecimiento
A8: AUTORIZACIÓN:
A9: Señor Jefe de Servicio Administrativo Financiero:
A10: ="Autorizo la realización de los trámites correspondientes, a fin de proveer a este Organismo los bienes y/o servicios que se detallan en Nota de Pedido N° " & '[3] NotaPedido'!H1&", afectando la erogación resultante a los créditos presupuestarios aprobados a favor de esta Unidad Ejecutora, conforme al siguiente detalle:" -> Autorizo la realización de los trámites correspondientes, a fin de proveer a este Organismo los bienes y/o servicios que se detallan en Nota de Pedido N° 98/2021, afectando la erogación resultante a los créditos presupuestarios aprobados a favor de esta Unidad Ejecutora, conforme al siguiente detalle:
A12: IMPUTACIÓN PRESUPUESTARIA
A13: CÓDIGO | O13: DENOMINACIÓN DE LA PARTIDA PRESUPUESTARIA | Q13: IMPORTE
A14: PR | B14: SB | C14: PY | D14: AC | E14: OB | F14: UG | G14: FIN | H14: FUN | I14: I | J14: P | K14: P | L14: SubP | M14: M | N14: FF
A15: 4 | B15: 0 | C15: 0 | D15: 1 | E15: 0 | F15: 4901 | G15: 1 | H15: 7 | I15: 2 | J15: 5 | K15: 2 | L15: 0 | M15: 1 | N15: 1.1 | O15: Productos farmaceuticos y medicinales | Q15: 24100
A16: 4 | B16: 0 | C16: 0 | D16: 1 | E16: 0 | F16: 4901 | G16: 1 | H16: 7 | I16: 2 | J16: 9 | K16: 5 | L16: 0 | M16: 1 | N16: 1.1 | O16: Utiles menores medico,quirurgico y de laboratorio | Q16: 2930
A22: TOTAL DE PESOS: Veintisiete mil treinta con 00/100.- | Q22: =+Q15+Q16 -> 27030
A24: JUSTIFICACIÓN:
A25: Adquisicion de elementos e insumos medicos para el armado de un botiquin destinado a la S.C.A-M.H.P.
A27: OBSERVACIONES:

Sheet NP - FINANZAS
A1: NOTA DE PEDIDO | F1: Nº | G1: 03/2021
A4: JURISDICCION: | C4: 30 - MINISTERIO DE HACIENDA PUBLICA
A5: SAF N°: | C5: SAF 9 - DIRECCION PROVINCIAL DE ADMINISTRACION DE LA SECRETARIA DE FINANZAS PUBLICAS
A6: UNIDAD EJECUTORA | C6: SECRETARIA DE FINANZAS PUBLICAS
A7: DEPENDENCIA SOLICITANTE | C7: SECRETARIA DE FINANZAS PUBLICAS
A8: TRIMESTRE: | C8: TERCER TRIMESTRE 2021
A9: OBJETO | C9: Adquisicion de elementos de higiene y cuidado personal
A10: ID | B10: CODIGO | C10: DESCRIPCION | D10: ADJUNTA DETALLE TECNICO | E10: UNIDAD DE MEDIDA | F10: PRECIO UNITARIO ESTIMADO | G10: CANTIDAD
A11: 1 | B11: 2.5.2-711.33 | C11: ALCOHOL USO MEDICINAL; PUREZA: 70 %, PRESENTACION: ENVASE X 500 CM3 | D11: SI | E11: UNIDAD | F11: 350 | G11: 20 | H11: =+G11*F11 -> 7000
A12: 2 | B12: 2.5.2-711.15 | C12: ALCOHOL USO MEDICINAL; PUREZA: 70 %, PRESENTACION: ENVASE X 1 L | D12: SI | E12: UNIDAD | F12: 275 | G12: 20 | H12: =+G12*F12 -> 5500
A13: 3 | B13: 2.5.2-711.45 | C13: ALCOHOL USO MEDICINAL; PUREZA: 70 %, PRESENTACION: GEL ENVASE X 1 L | D13: SI | E13: UNIDAD | F13: 450 | G13: 15 | H13: =+G13*F13 -> 6750
A14: 4 | B14: 2.9.5-428.19 | C14: BARBIJOS; TIPO: PLISADO | D14: SI | E14: UNIDAD | F14: 650 | G14: 30 | H14: =+G14*F14 -> 19500
B15: COSTO TOTAL ESTIMADO | C15: PESOS TREINTA Y OCHO MIL SETECIENTOS CINCUENTA CON 00/100 | F15: =+H14+H13+H12+H11 -> 38750
G16: =+G14+G13+G12+G11 -> 85

Sheet APG - FINANZAS
A1: EJERCICIO: | D1: =+'[4]NECESIDADES TRIMESTRALES'!C6 -> 2021 | P1: AUTORIZACION PARA GASTAR
A4: JURISDICCIÓN: | G4: 30 - Ministerio de Hacienda Publica
A5: SAF: | G5: 9 - Direccion Provincial de Administracion de la Secretaria de Finanzas Publicas
A6: UNIDAD EJECUTORA: | G6: SECRETARIA DE FINANZAS PUBLICAS
A7: DEPENDENCIA SOLICITANTE: | G7: SECRETARIA DE FINANZAS PUBLICAS
A8: AUTORIZACIÓN:
A9: Señor Jefe de Servicio Administrativo Financiero:
A10: Autorizo la realización de los trámites correspondientes, a fin de proveer a este Organismo los bienes y/o servicios que se detallan en Nota de Pedido N° 03/2021, afectando la erogación resultante a los créditos presupuestarios aprobados a favor de esta Unidad Ejecutora, conforme al siguiente detalle.
A12: IMPUTACIÓN PRESUPUESTARIA
A13: CÓDIGO | O13: DENOMINACIÓN DE LA PARTIDA PRESUPUESTARIA | Q13: IMPORTE
A14: PR | B14: SB | C14: PY | D14: AC | E14: OB | F14: UG | G14: FIN | H14: FUN | I14: I | J14: P | K14: P | L14: SubP | M14: M | N14: FF
A15: 17 | B15: 0 | C15: 0 | D15: 1 | E15: 0 | F15: 4901 | G15: 1 | H15: 6 | I15: 2 | J15: 5 | K15: 2 | L15: 0 | M15: 1 | N15: 1.1 | O15: Productos Farmacéuticos y Medicinales | Q15: 19250
A16: 17 | B16: 0 | C16: 0 | D16: 1 | E16: 0 | F16: 4901 | G16: 1 | H16: 6 | I16: 2 | J16: 9 | K16: 5 | L16: 0 | M16: 1 | N16: 1.1 | O16: Utiles Menores Médico, Quirúrgico y de Laboratorio | Q16: 19500
A18: TOTAL DE PESOS: TREINTA Y OCHO MIL SETECIENTOS CINCUENTA CON 00/100 | Q18: =SUM(Q15:Q17) -> 38750
A20: JUSTIFICACIÓN:
A21: Adquisicion de elementos de higiene y cuidado personal
A23: OBSERVACIONES:

Sheet NP - TGP
A1: NOTA DE PEDIDO | F1: Nº | G1: 03/2021
A4: JURISDICCION: | C4: 30 - MINISTERIO DE HACIENDA PUBLICA
A5: SAF N°: | C5: SAF 9 - DIRECCION PROVINCIAL DE ADMINISTRACION DE LA SECRETARIA DE FINANZAS PUBLICAS
A6: UNIDAD EJECUTORA | C6: TESORERIA GENERAL DE LA PROVINCIA
A7: DEPENDENCIA SOLICITANTE | C7: TESORERIA GENERAL DE LA PROVINCIA
A8: TRIMESTRE: | C8: 3º trimestre
A9: OBJETO | C9: Adquisición de productos farmaceuticos destinados a prevensión COVID19.
A10: ID | B10: CODIGO | C10: DESCRIPCION | D10: ADJUNTA DETALLE TECNICO | E10: UNIDAD DE MEDIDA | F10: PRECIO UNITARIO ESTIMADO | G10: CANTIDAD
A11: 1 | B11: 2.5.2-711.33 | C11: ALCOHOL USO MEDICINAL; PUREZA: 70 %, PRESENTACION: ENVASE X 500 CM3 | D11: SI | E11: UNIDAD | F11: 350 | G11: 15 | H11: =+G11*F11 -> 5250
A12: 2 | B12: 2.5.2-711.15 | C12: ALCOHOL USO MEDICINAL; PUREZA: 70 %, PRESENTACION: ENVASE X 1 L | D12: SI | E12: UNIDAD | F12: 275 | G12: 30 | H12: =+G12*F12 -> 8250
A13: 3 | B13: 2.5.2-711.45 | C13: ALCOHOL USO MEDICINAL; PUREZA: 70 %, PRESENTACION: GEL ENVASE X 1 L | D13: SI | E13: UNIDAD | F13: 450 | G13: 10 | H13: =+G13*F13 -> 4500
A14: 4 | B14: 2.9.5-428.19 | C14: BARBIJOS; TIPO: PLISADO | D14: SI | E14: UNIDAD | F14: 650 | G14: 50 | H14: =+G14*F14 -> 32500
B15: COSTO TOTAL ESTIMADO | C15: PESOS CINCUENTA MIL QUINIENTOS CON 00/100 | F15: =+H14+H13+H12+H11 -> 50500
G16: =+G14+G13+G12+G11 -> 105

Sheet APG - TGP
A1: EJERCICIO: | D1: 2021 | P1: AUTORIZACION PARA GASTAR
A4: JURISDICCIÓN: | G4: 30 - Ministerio de Hacienda Pública
A5: SAF: | G5: 9 - Dirección Provincial de Administración de la Secretaría de Finanzas Públicas
A6: UNIDAD EJECUTORA: | G6: Tesorería General de la Provincia
A7: DEPENDENCIA SOLICITANTE: | G7: Tesorería General de la Provincia
A8: AUTORIZACIÓN:
A9: Señor Director de Administración o Titular del Servicio Administrativo Financiero:
A10: Autorizo la realización de los trámites correspondientes, a fin de (proveer a este Organismo los bienes, servicios o ejecución de obras públicas que se detallan en Nota de Pedido N° 03/21, afectando la erogación resultante a los créditos presupuestarios aprobados a favor de esta Unidad Ejecutora, conforme al siguiente detalle:
A12: IMPUTACIÓN PRESUPUESTARIA
A13: CÓDIGO | O13: DENOMINACIÓN DE LA PARTIDA PRESUPUESTARIA | Q13: IMPORTE
A14: PR | B14: SB | C14: PY | D14: AC | E14: OB | F14: UG | G14: FIN | H14: FUN | I14: I | J14: P | K14: P | L14: SubP | M14: M | N14: FF
A15: 17 | D15: 2 | F15: 4901 | G15: 1 | H15: 6 | I15: 2 | J15: 5 | K15: 2 | M15: 1 | N15: 1.1 | O15: Productos farmacéuticos y medicinales | Q15: 18000
A16: 17 | D16: 2 | F16: 4901 | G16: 1 | H16: 6 | I16: 2 | J16: 9 | K16: 5 | M16: 1 | N16: 1.1 | O16: Utiles menores médicos quirurgicos y de laboratorio | Q16: 32500
A22: TOTAL DE PESOS: CINCUENTA MIL, QUINIENTOS.- | Q22: =SUM(Q15:Q21) -> 50500
A24: JUSTIFICACIÓN:
A25: Adquisición de productos farmaceuticos destinados a prevensión COVID19 del personal de la T.G.P.- MHP
A27: OBSERVACIONES:

Sheet NP - SSP
A1: NOTA DE PEDIDO | F1: Nº | G1: 4/2021
A4: JURISDICCION: | C4: 30 - MINISTERIO DE HACIENDA PUBLICA
A5: SAF N°: | C5: SAF 9 - DIRECCION PROVINCIAL DE ADMINISTRACION DE LA SECRETARIA DE FINANZAS PUBLICAS
A6: UNIDAD EJECUTORA | C6: SUBSECRETARIA DE PRESUPUESTO
A7: DEPENDENCIA SOLICITANTE | C7: SUBSECRETARIA DE PRESUPUESTO
A8: TRIMESTRE: | C8: TERCER TRIMESTRE 2021
A9: OBJETO | C9: Adquisicion de elementos de higiene y cuidado personal
A10: ID | B10: CODIGO | C10: DESCRIPCION | D10: ADJUNTA DETALLE TECNICO | E10: UNIDAD DE MEDIDA | F10: PRECIO UNITARIO ESTIMADO | G10: CANTIDAD
A11: 1 | B11: 2.5.2-711.33 | C11: ALCOHOL USO MEDICINAL; PUREZA: 70 %, PRESENTACION: ENVASE X 500 CM3 | D11: NO | E11: UNIDAD | F11: 350 | G11: 15 | H11: =+G11*F11 -> 5250
A12: 2 | B12: 2.5.2-711.15 | C12: ALCOHOL USO MEDICINAL; PUREZA: 70 %, PRESENTACION: ENVASE X 1 L | D12: NO | E12: UNIDAD | F12: 275 | G12: 50 | H12: =+G12*F12 -> 13750
A13: 3 | B13: 2.9.5-428.19 | C13: BARBIJOS; TIPO: PLISADO | D13: SI | E13: UNIDAD | F13: 650 | G13: 80 | H13: =+G13*F13 -> 52000
B14: COSTO TOTAL ESTIMADO | C14: PESOS SETENTA Y UN MIL CON 00/100 | F14: =+H13+H12+H11 -> 71000
G15: =+G13+G12+G11 -> 145

Sheet APG - SSP
A1: EJERCICIO: | D1: =+'[5]NECESIDADES TRIMESTRALES'!C6 -> 2021 | P1: AUTORIZACION PARA GASTAR
A4: JURISDICCIÓN: | G4: 30 - Ministerio de Hacienda Publica
A5: SAF: | G5: 9 - Direccion Provincial de Administracion de la Secretaria de Finanzas Publicas
A6: UNIDAD EJECUTORA: | G6: SUBSECRETARIA DE PRESUPUESTO
A7: DEPENDENCIA SOLICITANTE: | G7: SUBSECRETARIA DE PRESUPUESTO
A8: AUTORIZACIÓN:
A9: Señor Jefe de Servicio Administrativo Financiero:
A10: Autorizo la realización de los trámites correspondientes, a fin de proveer a este Organismo los bienes y/o servicios que se detallan en Nota de Pedido N° 4/2021, afectando la erogación resultante a los créditos presupuestarios aprobados a favor de esta Unidad Ejecutora, conforme al siguiente detalle.
A12: IMPUTACIÓN PRESUPUESTARIA
A13: CÓDIGO | O13: DENOMINACIÓN DE LA PARTIDA PRESUPUESTARIA | Q13: IMPORTE
A14: PR | B14: SB | C14: PY | D14: AC | E14: OB | F14: UG | G14: FIN | H14: FUN | I14: I | J14: P | K14: P | L14: SubP | M14: M | N14: FF
A15: 25 | B15: 0 | C15: 0 | D15: 1 | E15: 0 | F15: 4901 | G15: 1 | H15: 6 | I15: 2 | J15: 5 | K15: 2 | L15: 0 | M15: 1 | N15: 1.1 | O15: Productos Farmacéuticos y Medicinales | Q15: 19000
A16: 25 | B16: 0 | C16: 0 | D16: 1 | E16: 0 | F16: 4901 | G16: 1 | H16: 6 | I16: 2 | J16: 9 | K16: 5 | L16: 0 | M16: 1 | N16: 1.1 | O16: Utiles Menores Médico, Quirúrgico y de Laboratorio | Q16: 52000
A18: TOTAL DE PESOS: SETENTA Y UN MIL CON 00/100 | Q18: =SUM(Q15:Q17) -> 71000
A20: JUSTIFICACIÓN:
A21: Adquisicion de elementos de higiene y cuidado personal
A23: OBSERVACIONES:

Sheet NP - CGP
A1: NOTA DE PEDIDO | F1: Nº | G1: 9/2021
A4: JURISDICCION: | C4: 30 - MINISTERIO DE HACIENDA PUBLICA
A5: SAF N°: | C5: SAF 9 - DIRECCION PROVINCIAL DE ADMINISTRACION DE LA SECRETARIA DE FINANZAS PUBLICAS
A6: UNIDAD EJECUTORA | C6: CONTADURIA GENERAL DE LA PROVINCIA
A7: DEPENDENCIA SOLICITANTE | C7: CONTADURIA GENERAL DE LA PROVINCIA
A8: TRIMESTRE: | C8: TERCER TRIMESTRE 2021
A9: OBJETO | C9: Adquisición de Elementos de Higiene Personal
A10: ID | B10: CODIGO | C10: DESCRIPCION | D10: ADJUNTA DETALLE TECNICO | E10: UNIDAD DE MEDIDA | F10: PRECIO UNITARIO ESTIMADO | G10: CANTIDAD
A11: 1 | B11: 2.5.2-711.24 | C11: ALCOHOL USO MEDICINAL; PUREZA: 70 %, PRESENTACION: GEL EN ENVASE X 5 L | D11: SI | E11: UNIDAD | F11: 1300 | G11: 10 | H11: =+G11*F11 -> 13000
A12: 2 | B12: 2.5.2-711.15 | C12: ALCOHOL USO MEDICINAL; PUREZA: 70 %, PRESENTACION: ENVASE X 1 L | D12: SI | E12: UNIDAD | F12: 350 | G12: 12 | H12: =+G12*F12 -> 4200
A13: 3 | B13: 2.5.2-711.33 | C13: ALCOHOL USO MEDICINAL; PUREZA: 70 %, PRESENTACION: ENVASE X 500 CM3 | D13: SI | E13: UNIDAD | F13: 275 | G13: 20 | H13: =+G13*F13 -> 5500
B14: COSTO TOTAL ESTIMADO | C14: PESOS VEINTIDOS MIL SETECIENTOS CON 00/100 | F14: =+H13+H12+H11 -> 22700
G15: =+G13+G12+G11 -> 42

Sheet APG - CGP
A1: EJERCICIO: 2021 | P1: AUTORIZACION PARA GASTAR
A4: JURISDICCIÓN: | G4: 30 - Ministerio de Hacienda Publica
A5: SAF: | G5: 9 - Direccion Provincial de Administracion de la Secretaria de Finanzas Publicas
A6: UNIDAD EJECUTORA: | G6: Contaduria General de la Provincia
A7: DEPENDENCIA SOLICITANTE: | G7: Contaduria General de la Provincia
A8: AUTORIZACIÓN:
A9: Señor Jefe de Servicio Administrativo Financiero:
A10: Autorizo la realización de los trámites correspondientes, a fin de proveer a este Organismo los bienes y/o servicios que se detallan en Nota de Pedido N° 09/2021, afectando la erogación resultante a los créditos presupuestarios aprobados a favor de esta Unidad Ejecutora, conforme al siguiente detalle:
A12: IMPUTACIÓN PRESUPUESTARIA
A13: CÓDIGO | O13: DENOMINACIÓN DE LA PARTIDA PRESUPUESTARIA | Q13: IMPORTE
A14: PR | B14: SB | C14: PY | D14: AC | E14: OB | F14: UG | G14: FIN | H14: FUN | I14: I | J14: P | K14: P | L14: SubP | M14: M | N14: FF
A15: 029 | B15: 0 | C15: 0 | D15: 1 | E15: 0 | F15: 4901 | G15: 1 | H15: 7 | I15: 2 | J15: 5 | K15: 2 | L15: 0 | M15: 1 | N15: 1.1 | O15: Productos Farmaceúticos y Medicinales | Q15: 22700
A23: TOTAL DE PESOS: Veintidos Mil Setecientos con 00/100.- | Q23: =SUM(Q15:Q22) -> 22700
A25: JUSTIFICACIÓN:
A26: ADQUISICIÓN DE ELEMENTOS DE HIGIENE PERSONAL DESTINADOS AL FUNCIONAMIENTO DE C.G.P- MHP
A28: OBSERVACIONES:

Sheet NP - CAU
A1: NOTA DE PEDIDO | F1: Nº | G1: 1/2021
A4: JURISDICCION: | C4: 30 - MINISTERIO DE HACIENDA PUBLICA
A5: SAF N°: | C5: SAF 9 - DIRECCION PROVINCIAL DE ADMINISTRACION DE LA SECRETARIA DE FINANZAS PUBLICAS
A6: UNIDAD EJECUTORA | C6: CENTRO DE ATENCION AL USUARIO - ESIDIF
A7: DEPENDENCIA SOLICITANTE | C7: CENTRO DE ATENCION AL USUARIO - ESIDIF
A8: TRIMESTRE: | C8: TERCER TRIMESTRE 2021
A9: OBJETO | C9: Adquisicion de elementos de Higiene personal.
A10: ID | B10: CODIGO | C10: DESCRIPCION | D10: ADJUNTA DETALLE TECNICO | E10: UNIDAD DE MEDIDA | F10: PRECIO UNITARIO ESTIMADO | G10: CANTIDAD
A11: 1 | B11: 2.5.2-711.33 | C11: ALCOHOL USO MEDICINAL; PUREZA: 70 %, PRESENTACION: ENVASE X 500 CM3 | D11: SI | E11: UNIDAD | F11: 350 | G11: 10 | H11: =+G11*F11 -> 3500
A12: 2 | B12: 2.5.2-711.15 | C12: ALCOHOL USO MEDICINAL; PUREZA: 70 %, PRESENTACION: ENVASE X 1 L | D12: SI | E12: UNIDAD | F12: 275 | G12: 5 | H12: =+G12*F12 -> 1375
A13: 3 | B13: 2.5.2-711.45 | C13: ALCOHOL USO MEDICINAL; PUREZA: 70 %, PRESENTACION: GEL ENVASE X 1 L | D13: SI | E13: UNIDAD | F13: 450 | G13: 6 | H13: =+G13*F13 -> 2700
A14: 4 | B14: 2.9.5-428.19 | C14: BARBIJOS; TIPO: PLISADO | D14: SI | E14: UNIDAD | F14: 650 | G14: 40 | H14: =+G14*F14 -> 26000
B15: COSTO TOTAL ESTIMADO | C15: PESOS TREINTA Y TRES MIL QUINIENTOS SETENTA Y CINCO CON 00/100 | F15: =+H13+H12+H11+H14 -> 33575
G16: =+G14+G13+G12+G11 -> 61

Sheet APG - CAU
A1: EJERCICIO: | D1: 2021 | P1: AUTORIZACION PARA GASTAR
A4: JURISDICCIÓN: | G4: 30 - Ministerio de Hacienda Publica
A5: SAF: | G5: 9 - Direccion Provincial de Administracion de la Secretaria de Finanzas Publicas
A6: UNIDAD EJECUTORA: | G6: CENTRO DE ATENCION AL USUARIO - ESIDIF
A7: DEPENDENCIA SOLICITANTE: | G7: CENTRO DE ATENCION AL USUARIO - ESIDIF
A8: AUTORIZACIÓN:
A9: Señor Jefe de Servicio Administrativo Financiero:
A10: Autorizo la realización de los trámites correspondientes, a fin de proveer a este Organismo los bienes y/o servicios que se detallan en Nota de Pedido N° 01/2021, afectando la erogación resultante a los créditos presupuestarios aprobados a favor de esta Unidad Ejecutora, conforme al siguiente detalle.
A12: IMPUTACIÓN PRESUPUESTARIA
A13: CÓDIGO | O13: DENOMINACIÓN DE LA PARTIDA PRESUPUESTARIA | Q13: IMPORTE
A14: PR | B14: SB | C14: PY | D14: AC | E14: OB | F14: UG | G14: FIN | H14: FUN | I14: I | J14: P | K14: P | L14: SubP | M14: M | N14: FF
A15: 1 | B15: 0 | C15: 0 | D15: 3 | E15: 0 | F15: 4901 | G15: 1 | H15: 3 | I15: 2 | J15: 5 | K15: 2 | L15: 0 | M15: 1 | N15: 1.1 | O15: Productos Farmacéuticos y Medicinales | Q15: 7575
A16: 1 | B16: 0 | C16: 0 | D16: 3 | E16: 0 | F16: 4901 | G16: 1 | H16: 3 | I16: 2 | J16: 9 | K16: 5 | L16: 0 | M16: 1 | N16: 1.1 | O16: Utiles Menores, Médico, Quirúrgico y de Lab. | Q16: 26000
A19: TOTAL DE PESOS: TREINTA Y TRES MIL QUINIENTOS SETENTA Y CINCO CON 00/100 | Q19: =SUM(Q15:Q18) -> 33575
A21: JUSTIFICACIÓN:
A22: Adquisicion de elementos de higiene
A24: OBSERVACIONES:

Sheet NP - CP
A1: NOTA DE PEDIDO | F1: Nº | G1: 2/2021
A4: JURISDICCION: | C4: 30 - MINISTERIO DE HACIENDA PUBLICA
A5: SAF N°: | C5: SAF 9 - DIRECCION PROVINCIAL DE ADMINISTRACION DE LA SECRETARIA DE FINANZAS PUBLICAS
A6: UNIDAD EJECUTORA | C6: DIRECCION PROVINCIAL DE CREDITO PUBLICO
A7: DEPENDENCIA SOLICITANTE | C7: DIRECCION PROVINCIAL DE CREDITO PUBLICO
A8: TRIMESTRE: | C8: TERCER TRIMESTRE 2021
A9: OBJETO | C9: Adquisicion de elementos de Higiene personal.
A10: ID | B10: CODIGO | C10: DESCRIPCION | D10: ADJUNTA DETALLE TECNICO | E10: UNIDAD DE MEDIDA | F10: PRECIO UNITARIO ESTIMADO | G10: CANTIDAD
A11: 1 | B11: 2.5.2-711.33 | C11: ALCOHOL USO MEDICINAL; PUREZA: 70 %, PRESENTACION: ENVASE X 500 CM3 | D11: SI | E11: UNIDAD | F11: 350 | G11: 6 | H11: =+G11*F11 -> 2100
A12: 2 | B12: 2.9.5-428.19 | C12: BARBIJOS; TIPO: PLISADO | D12: SI | E12: UNIDAD | F12: 650 | G12: 20 | H12: =+G12*F12 -> 13000
B13: COSTO TOTAL ESTIMADO | C13: PESOS QUINCE MIL CIEN CON 00/100 | F13: =+H12+H11 -> 15100
G14: =+G12+G11 -> 26

Sheet APG - CP
A1: EJERCICIO: | D1: 2021 | P1: AUTORIZACION PARA GASTAR
A4: JURISDICCIÓN: | G4: 30 - Ministerio de Hacienda Publica
A5: SAF: | G5: 9 - Direccion Provincial de Administracion de la Secretaria de Finanzas Publicas
A6: UNIDAD EJECUTORA: | G6: DIRECCION PROVINCIAL DE CREDITO PUBLICO
A7: DEPENDENCIA SOLICITANTE: | G7: DIRECCION PROVINCIAL DE CREDITO PUBLICO
A8: AUTORIZACIÓN:
A9: Señor Jefe de Servicio Administrativo Financiero:
A10: Autorizo la realización de los trámites correspondientes, a fin de proveer a este Organismo los bienes y/o servicios que se detallan en Nota de Pedido N° 02/2021, afectando la erogación resultante a los créditos presupuestarios aprobados a favor de esta Unidad Ejecutora, conforme al siguiente detalle.
A12: IMPUTACIÓN PRESUPUESTARIA
A13: CÓDIGO | O13: DENOMINACIÓN DE LA PARTIDA PRESUPUESTARIA | Q13: IMPORTE
A14: PR | B14: SB | C14: PY | D14: AC | E14: OB | F14: UG | G14: FIN | H14: FUN | I14: I | J14: P | K14: P | L14: SubP | M14: M | N14: FF
A15: 27 | B15: 0 | C15: 0 | D15: 1 | E15: 0 | F15: 4901 | G15: 1 | H15: 6 | I15: 2 | J15: 5 | K15: 2 | L15: 0 | M15: 1 | N15: 1.1 | O15: Productos Farmaceúticos y Medicinales | Q15: 2100
A16: 27 | B16: 0 | C16: 0 | D16: 1 | E16: 0 | F16: 4901 | G16: 1 | H16: 6 | I16: 2 | J16: 9 | K16: 5 | L16: 0 | M16: 1 | N16: 1.1 | O16: Utiles Menores Médico, Quirúrgico y de Laboratorio | Q16: 13000
A19: TOTAL DE PESOS: QUINCE MIL CIEN CON 00/100 | Q19: =SUM(Q15:Q18) -> 15100
A21: JUSTIFICACIÓN:
A22: Adquisicion de elementos de Higiene Personal
A24: OBSERVACIONES:
