Workbook

Sheet SAF 011
A1: 2022
B2: Pedido de Necesidades Trimestrales
A4: JURISDICCION: | C4: 040 - MINISTERIO DE SALUD
A5: SAF N°: | C5: 011 - DIRECCION PROVINCIAL DE ADMINISTRACION - MINISTERIO DE SALUD
A6: EJERCICIO: | C6: 2022
A7: TRIMESTRE: | C7: CUARTO
A9: ID | B9: CODIGO ITEM | C9: RUBRO DE COMPRA | D9: I.P.P. | E9: DESCRIPCION | F9: UNIDAD DE MEDIDA | G9: DIR. LAB. CENTRAL | H9: TOTAL DE LAB CENTRAL | I9: BCO DE SANGRE | J9: TOTAL BANCO DE SANGRE | K9: CANTIDAD TOTAL | L9: PRECIO UNITARIO ESTIMADO | M9: IMPORTE TOTAL ESTIMADO | N9: ESPECIFICACION TECNICA
A10: 1 | B10: 2.9.5-441.470 | C10: PROD. MEDICO/FARMACEUTICOS/LAB. | D10: 2.9.5 | E10: AGUJAS QUIRURGICAS; TIPO: TERUMO 21GX1", ESPECIFICACION: 25/8, UNIDAD VENTA: CAJA X 100, PRESENTACION: CAJA X 100 | F10: CAJA | G10: 500 | H10: =+G10*L10 -> 1502500 | K10: =+G10+I10 -> 500 | L10: 3005 | M10: =+K10*L10 -> 1502500
A11: 2 | B11: 2.9.5-441.471 | C11: PROD. MEDICO/FARMACEUTICOS/LAB. | D11: 2.9.5 | E11: AGUJAS QUIRURGICAS; TIPO: TERUMO 25GX5/8", ESPECIFICACION: 16/5, UNIDAD VENTA: CAJA X 100, PRESENTACION: CAJA X 100 | F11: CAJA | G11: 400 | H11: =+G11*L11 -> 1296800 | K11: =+G11+I11 -> 400 | L11: 3242 | M11: =+K11*L11 -> 1296800
A12: 3 | B12: 2.9.5-470.13 | C12: PROD. MEDICO/FARMACEUTICOS/LAB. | D12: 2.9.5 | E12: ALGODONES; TIPO: HIDROFILADO, CAPACIDAD: 500 GR, PRESENTACION: ENVASE X 500 GR | F12: PAQUETE | G12: 200 | H12: =+G12*L12 -> 172400 | I12: 40 | J12: =+I12*L12 -> 34480 | K12: =+G12+I12 -> 240 | L12: 862 | M12: =+K12*L12 -> 206880 | N12: ALGODONES PLISADO PRE-CORTADO - ENVASE X 500 GR
A13: 4 | B13: 2.9.5-5703.15 | C13: PROD. MEDICO/FARMACEUTICOS/LAB. | D13: 2.9.5 | E13: ANSA; PRESENTACION: UNIDAD, TIPO: PLASTICA DESCARTABLE | F13: BOLSA | G13: 100 | H13: =+G13*L13 -> 47500 | K13: =+G13+I13 -> 100 | L13: 475 | M13: =+K13*L13 -> 47500 | N13: ANSA DESCARTABLE DE PLASTICO CALIBRADA DE 10 ul ESTERIL X 20 UNIDADES Tipo DELTALAB
A14: 5 | B14: 2.9.5-427.131 | C14: PROD.MEDICO/FARMACEUTICOS/LAB | D14: 2.9.5 | E14: APOSITOS; TIPO: HIPOALARGENICO, TAMAÑO: 40 X 40 MM | F14: CAJA | I14: 50 | J14: =+I14*L14 -> 35100 | K14: =+G14+I14 -> 50 | L14: 702 | M14: =+K14*L14 -> 35100 | N14: CAJA X 250 UNID
A15: 6 | B15: 2.9.5-427.74 | C15: PROD. MEDICO/FARMACEUTICOS/LAB. | D15: 2.9.5 | E15: APOSITOS; TIPO: POST EXTRACCION SANGUINEA, TAMAÑO: 2 X 7,5 Cm | F15: CAJA | G15: 250 | H15: =+G15*L15 -> 244250 | K15: =+G15+I15 -> 250 | L15: 977 | M15: =+K15*L15 -> 244250 | N15: APOSITO POST EXTRACCION SANGUNEA 2X7,5 CM CAJA X 250 UNIDADES Tipo BANDERM
A16: 7 | B16: 2.9.5-2505.10 | C16: PROD. MEDICO/FARMACEUTICOS/LAB. | D16: 2.9.5 | E16: BOLSAS COLECTORAS; TIPO: DE ORINA, USO: PEDIATRICO, CAPACIDAD: 100 mL | F16: UNIDAD | G16: 10000 | H16: =+G16*L16 -> 2300000 | K16: =+G16+I16 -> 10000 | L16: 230 | M16: =+K16*L16 -> 2300000 | N16: RECOLECTORES DE ORINA PEDIATRICOS
A17: 8 | B17: 2.9.5-2694.22 | C17: PROD.MEDICO/FARMACEUTICOS/LAB | D17: 2.9.5 | E17: BOLSAS P/TRANSFUSIONES SANGRE; CAPACIDAD: 450 mL, SOLUCIONES: CFD CON ADENINA, TIPO: HEMOTERAPIA | F17: UNIDAD | I17: 1800 | J17: =+I17*L17 -> 2142000 | K17: =+G17+I17 -> 1800 | L17: 1190 | M17: =+K17*L17 -> 2142000 | N17: BOLSAS DE SANGRE TRIPLE KS TIPO GRIFOLS
A18: 9 | B18: 2.9.5-1908.28 | C18: PROD.MEDICO/FARMACEUTICOS/LAB | D18: 2.9.5 | E18: CEPILLOS P/LABORATORIO; TIPO: LIMPIEZA DE TUBOS, MATERIAL: CERDA, TAMAÑO: DIAM. 9 mm | F18: UNIDAD | I18: 10 | J18: =+I18*L18 -> 1250 | K18: =+G18+I18 -> 10 | L18: 125 | M18: =+K18*L18 -> 1250 | N18: CEPILLO LIMPIA PIPETA DE CERDA NATURAL
A19: 10 | B19: 2.9.5-4047.6 | C19: PROD. MEDICO/FARMACEUTICOS/LAB. | D19: 2.9.5 | E19: CRIOVIALES; MATERIAL: POLIPROPILENO, VOLUMEN: 5 mL | F19: UNIDAD | G19: 5000 | H19: =+G19*L19 -> 332000 | K19: =+G19+I19 -> 5000 | L19: 66.4 | M19: =+K19*L19 -> 332000 | N19: CRIOTUBO CON TAPA A ROSCA ESTERIL 5 ML
A20: 11 | B20: 2.9.5-5410.11 | C20: PROD. MEDICO/FARMACEUTICOS/LAB. | D20: 2.9.5 | E20: CUBETAS DE REACCION; MATERIAL: PLASTICO, CELDAS: 500 C/AGITADOR, USO: COAGULOMETRO | F20: CAJA | G20: 20 | H20: =+G20*L20 -> 357360 | K20: =+G20+I20 -> 20 | L20: 17868 | M20: =+K20*L20 -> 357360 | N20: CUBETAS SERIE X 500 UN PARA COAGULOMETRO COATRON Tipo TECO GMBH
A21: 12 | B21: 2.9.5-5410.11 | C21: PROD. MEDICO/FARMACEUTICOS/LAB. | D21: 2.9.5 | E21: CUBETAS DE REACCION; MATERIAL: PLASTICO, CELDAS: 500 C/AGITADOR, USO: COAGULOMETRO | F21: CAJA | G21: 20 | H21: =+G21*L21 -> 640360 | K21: =+G21+I21 -> 20 | L21: 32018 | M21: =+K21*L21 -> 640360 | N21: CUBETA PARA FIBRINTIMER x 500 UN. Tipo WIENER
A22: 13 | B22: 2.9.5-2557.32 | C22: PROD. MEDICO/FARMACEUTICOS/LAB. | D22: 2.9.5 | E22: CUBREOBJETOS; MATERIAL: VIDRIO, DIMENSION: 20 X 20 mm, PRESENTACION: ENVASE X 200 UN | F22: CAJA | G22: 400 | H22: =+G22*L22 -> 150000 | K22: =+G22+I22 -> 400 | L22: 375 | M22: =+K22*L22 -> 150000
A23: 14 | B23: 2.9.5-2160.1 | C23: PROD.MEDICO/FARMACEUTICOS/LAB | D23: 2.9.5 | E23: DESCARTADORES DE AGUJAS; BOCA: 1, CAPACIDAD: 500 AGUJAS, MODELO: 500, MODELO EQUIPO: 500, SISTEMA DE CIERRE: 500 | F23: UNIDAD | I23: 200 | J23: =+I23*L23 -> 39000 | K23: =+G23+I23 -> 200 | L23: 195 | M23: =+K23*L23 -> 39000
A24: 15 | B24: 2.9.2-675.161 | C24: LIBRERIA,PAP. Y UTILES OFICINA | D24: 2.3.4 | E24: ETIQUETAS AUTOADHESIVAS; MEDIDA: 80 X 25 mm, PRESENTACION: ROLLO X 380 GR, PAPEL BASE: AUTOADHESIVO | F24: PACK | G24: 10 | H24: =+G24*L24 -> 23080 | K24: =+G24+I24 -> 10 | L24: 2308 | M24: =+K24*L24 -> 23080 | N24: ETIQUETAS TERMICO PARA IMPRESORA ZEBRA 80X25 MM X 12 ROLLOS
A25: 16 | B25: 2.9.5-6877.16 | C25: PROD. MEDICO/FARMACEUTICOS/LAB. | D25: 2.9.5 | E25: FUENTES DE LUZ; USO: ILUMINADOR DE MICROSCOPIO, POTENCIA: 20 W, LAMPARA: LED | F25: UNIDAD | G25: 50 | H25: =+G25*L25 -> 110350 | K25: =+G25+I25 -> 50 | L25: 2207 | M25: =+K25*L25 -> 110350 | N25: LAMPARA PARA MICROSCOPIO 6V 20 W
A26: 17 | B26: 2.9.5-3017.27 | C26: PROD. MEDICO/FARMACEUTICOS/LAB. | D26: 2.9.5 | E26: GRADILLAS P/LABORATORIO; TAMAÑO TUBO: 15 X 2 Cm, CANTIDAD DE TUBOS: 36, MATERIAL: ALAMBRE REV.EN RESINA ANTIAD., MEDIDA TUBO: 15 X 2 Cm, CANT. DE ELEMENTOS: 36, MEDIDA: 15 X 2 Cm | F26: UNIDAD | G26: 40 | H26: =+G26*L26 -> 133440 | K26: =+G26+I26 -> 40 | L26: 3336 | M26: =+K26*L26 -> 133440 | N26: GRADILLA ALAMBRE PLASTIFICADO PARA 36 TUBOS FALCON de25 mm DIAMETRO Tipo ARGA
A27: 18 | B27: 2.9.5-3017.45 | C27: PROD. MEDICO/FARMACEUTICOS/LAB. | D27: 2.9.5 | E27: GRADILLAS P/LABORATORIO; TAMAÑO TUBO: 25 mm, CANTIDAD DE TUBOS: 24, MATERIAL: ALAMBRE PLASTIFICADO, MEDIDA TUBO: 25 mm, CANT. DE ELEMENTOS: 24, MEDIDA: 25 mm | F27: UNIDAD | G27: 40 | H27: =+G27*L27 -> 108160 | K27: =+G27+I27 -> 40 | L27: 2704 | M27: =+K27*L27 -> 108160 | N27: GRADILLA ALAMBRE PLASTIFICADO PARA 24 TUBOS FALCON de 25 mm DIAMETRO Tipo ARGA
A28: 19 | B28: 2.9.5-3017.36 | C28: PROD. MEDICO/FARMACEUTICOS/LAB. | D28: 2.9.5 | E28: GRADILLAS P/LABORATORIO; TAMAÑO TUBO: DIAM. EXT. 15 mm, CANTIDAD DE TUBOS: 48, MATERIAL: POLIPROPILENO, MEDIDA TUBO: DIAM. EXT. 15 mm, CANT. DE ELEMENTOS: 48, MEDIDA: DIAM. EXT. 15 mm | F28: UNIDAD | G28: 40 | H28: =+G28*L28 -> 169720 | K28: =+G28+I28 -> 40 | L28: 4243 | M28: =+K28*L28 -> 169720 | N28: GRADILLA ALAMBRE PLASTIFICADO PARA 48 TUBOS DE KAHN 1,6x1,6 cmTipo ARGA
A29: 20 | B29: 2.9.5-1909.77 | C29: PROD. MEDICO/FARMACEUTICOS/LAB. | D29: 2.9.5 | E29: GUANTES USO MEDICINAL; TIPO: DESCARTABLE, TAMAÑO: CHICO, MATERIAL: LATEX, PRESENTACION: ENVASE X 100 UN | F29: CAJA | G29: 800 | H29: =+G29*L29 -> 472000 | I29: 50 | J29: =+I29*L29 -> 29500 | K29: =+G29+I29 -> 850 | L29: 590 | M29: =+K29*L29 -> 501500 | N29: GUANTES DE LATEX TALLE "S" (CHICO) CAJA X 100 UNIDADES Tipo SRITRANG
A30: 21 | B30: 2.9.5-1909.81 | C30: PROD.MEDICO/FARMACEUTICOS/LAB | D30: 2.9.5 | E30: GUANTES USO MEDICINAL; TIPO: DESCARTABLE, TAMAÑO: GRANDE, MATERIAL: LATEX, PRESENTACION: ENVASE X 100 UNID. | F30: CAJA | I30: 50 | J30: =+I30*L30 -> 29500 | K30: =+G30+I30 -> 50 | L30: 590 | M30: =+K30*L30 -> 29500 | N30: GUANTES USO MEDICINAL; TIPO: EXAMINACION , TAMAÑO: GRANDE, MATERIAL: LATEX, PRESENTACION: ENVASE X 100 UN
A31: 22 | B31: 2.9.5-1909.87 | C31: PROD.MEDICO/FARMACEUTICOS/LAB | D31: 2.9.5 | E31: GUANTES USO MEDICINAL; TIPO: DESCARTABLE, TAMAÑO: MEDIANO, MATERIAL: LATEX, PRESENTACION: ENVASE X 100 UNID. | F31: CAJA | G31: 800 | H31: =+G31*L31 -> 472000 | I31: 50 | J31: =+I31*L31 -> 29500 | K31: =+G31+I31 -> 850 | L31: 590 | M31: =+K31*L31 -> 501500 | N31: GUANTES USO MEDICINAL; TIPO: EXAMINACION , TAMAÑO: MEDIANO, MATERIAL: LATEX, PRESENTACION: ENVASE X 100 UN
A32: 23 | B32: 2.9.5-1909.96 | C32: PROD. MEDICO/FARMACEUTICOS/LAB. | D32: 2.9.5 | E32: GUANTES USO MEDICINAL; TIPO: MANOPLA, TAMAÑO: MEDIANO, MATERIAL: POLIETILENO, PRESENTACION: ENVASE X 100 | F32: BOLSA | G32: 500 | H32: =+G32*L32 -> 1025000 | K32: =+G32+I32 -> 500 | L32: 2050 | M32: =+K32*L32 -> 1025000 | N32: MANOPLAS DE POLIETILENO x 100 U Tipo NP
A33: 24 | B33: 2.9.5-1909.84 | C33: PROD. MEDICO/FARMACEUTICOS/LAB. | D33: 2.9.5 | E33: GUANTES USO MEDICINAL; TIPO: P/QUIMICOS, TAMAÑO: CHICO, MATERIAL: NITRILO, PRESENTACION: ENVASE X 100 UN | F33: CAJA | G33: 400 | H33: =+G33*L33 -> 551200 | K33: =+G33+I33 -> 400 | L33: 1378 | M33: =+K33*L33 -> 551200 | N33: GUANTES DE NITRILO SIN POLVO TALLE "S" (CHICO) CAJAX100 UNIDADES Tipo TOP GLOVE
A34: 25 | B34: 2.9.5-1909.82 | C34: PROD. MEDICO/FARMACEUTICOS/LAB. | D34: 2.9.5 | E34: GUANTES USO MEDICINAL; TIPO: P/QUIMICOS, TAMAÑO: GRANDE, MATERIAL: NITRILO, PRESENTACION: ENVASE X 100 UN | F34: CAJA | G34: 50 | H34: =+G34*L34 -> 68900 | K34: =+G34+I34 -> 50 | L34: 1378 | M34: =+K34*L34 -> 68900 | N34: GUANTES DE NITRILO SIN POLVO TALLE "L" (GRANDE) CAJAX100 UNIDADES Tipo TOP GLOVE
A35: 26 | B35: 2.9.5-1909.83 | C35: PROD. MEDICO/FARMACEUTICOS/LAB. | D35: 2.9.5 | E35: GUANTES USO MEDICINAL; TIPO: P/QUIMICOS, TAMAÑO: MEDIANO, MATERIAL: NITRILO, PRESENTACION: ENVASE X 100 UN | F35: CAJA | G35: 500 | H35: =+G35*L35 -> 689000 | K35: =+G35+I35 -> 500 | L35: 1378 | M35: =+K35*L35 -> 689000 | N35: GUANTES DE NITRILO SIN POLVO TALLE "M" (MEDIANO) CAJAX100 UNIDADES Tipo TOP GLOVE
A36: 27 | B36: 2.9.5-2366.2 | C36: PROD. MEDICO/FARMACEUTICOS/LAB. | D36: 2.9.5 | E36: HISOPOS; MATERIAL DE EXTREMOS: ALGODON, PRESENTACION: CAJA X 100 | F36: BOLSA | G36: 400 | H36: =+G36*L36 -> 110400 | K36: =+G36+I36 -> 400 | L36: 276 | M36: =+K36*L36 -> 110400 | N36: HISOPO DE ALGODÓN BOLSAX 100 UNIDADES
A37: 28 | B37: 2.9.5-8799.12 | C37: PROD. MEDICO/FARMACEUTICOS/LAB. | D37: 2.9.5 | E37: JERINGA; MATERIAL: PLASTICO, CAPACIDAD: 10 CM3, ACCESORIOS: SIN, TIPO: ESTERIL, ACCESORIO: SIN | F37: CAJA | G37: 300 | H37: =+G37*L37 -> 608100 | K37: =+G37+I37 -> 300 | L37: 2027 | M37: =+K37*L37 -> 608100 | N37: JERINGAS 10 ML X 100 UNIDADES Tipo BREMEN
A38: 29 | B38: 2.9.5-8799.8 | C38: PROD. MEDICO/FARMACEUTICOS/LAB. | D38: 2.9.5 | E38: JERINGA; MATERIAL: PLASTICO, CAPACIDAD: 3 mL, ACCESORIOS: SIN, TIPO: NICHIRYO, ACCESORIO: SIN | F38: CAJA | G38: 500 | H38: =+G38*L38 -> 702500 | K38: =+G38+I38 -> 500 | L38: 1405 | M38: =+K38*L38 -> 702500 | N38: JERINGAS 3 ML X 100 UNIDADES Tipo BREMEN
A39: 30 | B39: 2.9.5-8799.11 | C39: PROD. MEDICO/FARMACEUTICOS/LAB. | D39: 2.9.5 | E39: JERINGA; MATERIAL: PLASTICO, CAPACIDAD: 5 CM3, ACCESORIOS: SIN, TIPO: ESTERIL, ACCESORIO: SIN | F39: CAJA | G39: 800 | H39: =+G39*L39 -> 1104000 | K39: =+G39+I39 -> 800 | L39: 1380 | M39: =+K39*L39 -> 1104000 | N39: JERINGAS 5 ML X 100 UNIDADES Tipo BREMEN
A40: 31 | B40: 2.9.5-7870.15 | C40: PROD. MEDICO/FARMACEUTICOS/LAB. | D40: 2.9.3 | E40: LAMPARAS P/AUTOANALIZADOR; TIPO: HALOGENA, TENSION: 6 V, POTENCIA: 10 W | F40: UNIDAD | G40: 15 | H40: =+G40*L40 -> 69000 | K40: =+G40+I40 -> 15 | L40: 4600 | M40: =+K40*L40 -> 69000 | N40: LAMPARA PARA ESPECTROFOTOMETRO MINDRAY BA 88A CON ZOCALO
A41: 32 | B41: 2.9.5-7870.15 | C41: PROD. MEDICO/FARMACEUTICOS/LAB. | D41: 2.9.3 | E41: LAMPARAS P/AUTOANALIZADOR; TIPO: HALOGENA, TENSION: 6 V, POTENCIA: 10 W | F41: UNIDAD | G41: 30 | H41: =+G41*L41 -> 77250 | K41: =+G41+I41 -> 30 | L41: 2575 | M41: =+K41*L41 -> 77250 | N41: LAMPARA PARA ESPECTROFOTOMETRO METROLAB 1600 SIN ZOCALO 6V 10 W
A42: 33 | B42: 2.9.5-7870.16 | C42: PROD. MEDICO/FARMACEUTICOS/LAB. | D42: 2.9.3 | E42: LAMPARAS P/AUTOANALIZADOR; TIPO: HALOGENA, TENSION: 6 V, POTENCIA: 20 W | F42: UNIDAD | G42: 5 | H42: =+G42*L42 -> 19000 | K42: =+G42+I42 -> 5 | L42: 3800 | M42: =+K42*L42 -> 19000 | N42: LAMPARA PARA ESPECTROFOTOMETRO MINDRAY BS-200 E CON ZOCALO
...

Sheet NP LABORATORIO
A1: NOTA DE PEDIDO | J1: N° | K1: XX/2022
A3: JURISDICCIÓN: | D3: ='SAF 011'!C4 -> 040 - MINISTERIO DE SALUD
A4: SAF: | D4: ='SAF 011'!C5 -> 011 - DIRECCION PROVINCIAL DE ADMINISTRACION - MINISTERIO DE SALUD
A5: UNIDAD EJECUTORA: | D5: 468 - DIRECCION PROVINCIAL DE LABORATORIO
A6: DEPENDENCIA SOLICITANTE: | D6: 468 - DIRECCION PROVINCIAL DE LABORATORIO
A7: PERIODO UTILIZACIÓN: | D7: TRES MESES
A8: OBJETO: | D8: ADQUISICION DEL RUBRO INSUMOS PARA LABORATORIO
A10: Ítem | B10: Codigo Item | C10: DESCRIPCIÓN | H10: Adjunta Detalle Técnico | I10: Unidad Medida | J10: Precio Unitario Estimado | K10: Cantidad Solicitada
A12: 1 | B12: ='SAF 011'!B10 -> 2.9.5-441.470 | C12: ='SAF 011'!E10 -> AGUJAS QUIRURGICAS; TIPO: TERUMO 21GX1", ESPECIFICACION: 25/8, UNIDAD VENTA: CAJA X 100, PRESENTACION: CAJA X 100 | H12: NO | I12: ='SAF 011'!F10 -> CAJA | J12: ='SAF 011'!L10 -> 3005 | K12: ='SAF 011'!G10 -> 500 | O12: =+J12*K12 -> 1502500
A13: 2 | B13: ='SAF 011'!B11 -> 2.9.5-441.471 | C13: ='SAF 011'!E11 -> AGUJAS QUIRURGICAS; TIPO: TERUMO 25GX5/8", ESPECIFICACION: 16/5, UNIDAD VENTA: CAJA X 100, PRESENTACION: CAJA X 100 | H13: NO | I13: ='SAF 011'!F11 -> CAJA | J13: ='SAF 011'!L11 -> 3242 | K13: ='SAF 011'!G11 -> 400 | O13: =+J13*K13 -> 1296800
A14: 3 | B14: ='SAF 011'!B12 -> 2.9.5-470.13 | C14: ='SAF 011'!E12 -> ALGODONES; TIPO: HIDROFILADO, CAPACIDAD: 500 GR, PRESENTACION: ENVASE X 500 GR | H14: SI | I14: ='SAF 011'!F12 -> PAQUETE | J14: ='SAF 011'!L12 -> 862 | K14: ='SAF 011'!G12 -> 200 | O14: =+J14*K14 -> 172400
A15: 4 | B15: ='SAF 011'!B13 -> 2.9.5-5703.15 | C15: ='SAF 011'!E13 -> ANSA; PRESENTACION: UNIDAD, TIPO: PLASTICA DESCARTABLE | H15: SI | I15: ='SAF 011'!F13 -> BOLSA | J15: ='SAF 011'!L13 -> 475 | K15: ='SAF 011'!G13 -> 100 | O15: =+J15*K15 -> 47500
A16: 5 | B16: ='SAF 011'!B15 -> 2.9.5-427.74 | C16: ='SAF 011'!E15 -> APOSITOS; TIPO: POST EXTRACCION SANGUINEA, TAMAÑO: 2 X 7,5 Cm | H16: SI | I16: ='SAF 011'!F15 -> CAJA | J16: ='SAF 011'!L15 -> 977 | K16: ='SAF 011'!G15 -> 250 | O16: =+J16*K16 -> 244250
A17: 6 | B17: ='SAF 011'!B16 -> 2.9.5-2505.10 | C17: ='SAF 011'!E16 -> BOLSAS COLECTORAS; TIPO: DE ORINA, USO: PEDIATRICO, CAPACIDAD: 100 mL | H17: SI | I17: ='SAF 011'!F16 -> UNIDAD | J17: ='SAF 011'!L16 -> 230 | K17: ='SAF 011'!G16 -> 10000 | O17: =+J17*K17 -> 2300000
A18: 7 | B18: ='SAF 011'!B19 -> 2.9.5-4047.6 | C18: ='SAF 011'!E19 -> CRIOVIALES; MATERIAL: POLIPROPILENO, VOLUMEN: 5 mL | H18: SI | I18: ='SAF 011'!F19 -> UNIDAD | J18: ='SAF 011'!L19 -> 66.4 | K18: ='SAF 011'!G19 -> 5000 | O18: =+J18*K18 -> 332000
A19: 8 | B19: ='SAF 011'!B20 -> 2.9.5-5410.11 | C19: ='SAF 011'!E20 -> CUBETAS DE REACCION; MATERIAL: PLASTICO, CELDAS: 500 C/AGITADOR, USO: COAGULOMETRO | H19: SI | I19: ='SAF 011'!F20 -> CAJA | J19: ='SAF 011'!L20 -> 17868 | K19: ='SAF 011'!G20 -> 20 | O19: =+J19*K19 -> 357360
A20: 9 | B20: ='SAF 011'!B21 -> 2.9.5-5410.11 | C20: ='SAF 011'!E21 -> CUBETAS DE REACCION; MATERIAL: PLASTICO, CELDAS: 500 C/AGITADOR, USO: COAGULOMETRO | H20: SI | I20: ='SAF 011'!F21 -> CAJA | J20: ='SAF 011'!L21 -> 32018 | K20: ='SAF 011'!G21 -> 20 | O20: =+J20*K20 -> 640360
A21: 10 | B21: ='SAF 011'!B22 -> 2.9.5-2557.32 | C21: ='SAF 011'!E22 -> CUBREOBJETOS; MATERIAL: VIDRIO, DIMENSION: 20 X 20 mm, PRESENTACION: ENVASE X 200 UN | H21: NO | I21: ='SAF 011'!F22 -> CAJA | J21: ='SAF 011'!L22 -> 375 | K21: ='SAF 011'!G22 -> 400 | O21: =+J21*K21 -> 150000
A22: 11 | B22: ='SAF 011'!B24 -> 2.9.2-675.161 | C22: ='SAF 011'!E24 -> ETIQUETAS AUTOADHESIVAS; MEDIDA: 80 X 25 mm, PRESENTACION: ROLLO X 380 GR, PAPEL BASE: AUTOADHESIVO | H22: SI | I22: ='SAF 011'!F24 -> PACK | J22: ='SAF 011'!L24 -> 2308 | K22: ='SAF 011'!G24 -> 10 | M22: =+J22*K22 -> 23080
A23: 12 | B23: ='SAF 011'!B25 -> 2.9.5-6877.16 | C23: ='SAF 011'!E25 -> FUENTES DE LUZ; USO: ILUMINADOR DE MICROSCOPIO, POTENCIA: 20 W, LAMPARA: LED | H23: SI | I23: ='SAF 011'!F25 -> UNIDAD | J23: ='SAF 011'!L25 -> 2207 | K23: ='SAF 011'!G25 -> 50 | O23: =+J23*K23 -> 110350
A24: 13 | B24: ='SAF 011'!B26 -> 2.9.5-3017.27 | C24: ='SAF 011'!E26 -> GRADILLAS P/LABORATORIO; TAMAÑO TUBO: 15 X 2 Cm, CANTIDAD DE TUBOS: 36, MATERIAL: ALAMBRE REV.EN RESINA ANTIAD., MEDIDA TUBO: 15 X 2 Cm, CANT. DE ELEMENTOS: 36, MEDIDA: 15 X 2 Cm | H24: SI | I24: ='SAF 011'!F26 -> UNIDAD | J24: ='SAF 011'!L26 -> 3336 | K24: ='SAF 011'!G26 -> 40 | O24: =+J24*K24 -> 133440
A25: 14 | B25: ='SAF 011'!B27 -> 2.9.5-3017.45 | C25: ='SAF 011'!E27 -> GRADILLAS P/LABORATORIO; TAMAÑO TUBO: 25 mm, CANTIDAD DE TUBOS: 24, MATERIAL: ALAMBRE PLASTIFICADO, MEDIDA TUBO: 25 mm, CANT. DE ELEMENTOS: 24, MEDIDA: 25 mm | H25: SI | I25: ='SAF 011'!F27 -> UNIDAD | J25: ='SAF 011'!L27 -> 2704 | K25: ='SAF 011'!G27 -> 40 | O25: =+J25*K25 -> 108160
A26: 15 | B26: ='SAF 011'!B28 -> 2.9.5-3017.36 | C26: ='SAF 011'!E28 -> GRADILLAS P/LABORATORIO; TAMAÑO TUBO: DIAM. EXT. 15 mm, CANTIDAD DE TUBOS: 48, MATERIAL: POLIPROPILENO, MEDIDA TUBO: DIAM. EXT. 15 mm, CANT. DE ELEMENTOS: 48, MEDIDA: DIAM. EXT. 15 mm | H26: SI | I26: ='SAF 011'!F28 -> UNIDAD | J26: ='SAF 011'!L28 -> 4243 | K26: ='SAF 011'!G28 -> 40 | O26: =+J26*K26 -> 169720
A27: 16 | B27: ='SAF 011'!B29 -> 2.9.5-1909.77 | C27: ='SAF 011'!E29 -> GUANTES USO MEDICINAL; TIPO: DESCARTABLE, TAMAÑO: CHICO, MATERIAL: LATEX, PRESENTACION: ENVASE X 100 UN | H27: SI | I27: ='SAF 011'!F29 -> CAJA | J27: ='SAF 011'!L29 -> 590 | K27: ='SAF 011'!G29 -> 800 | O27: =+J27*K27 -> 472000
A28: 17 | B28: ='SAF 011'!B31 -> 2.9.5-1909.87 | C28: ='SAF 011'!E31 -> GUANTES USO MEDICINAL; TIPO: DESCARTABLE, TAMAÑO: MEDIANO, MATERIAL: LATEX, PRESENTACION: ENVASE X 100 UNID. | H28: SI | I28: ='SAF 011'!F31 -> CAJA | J28: ='SAF 011'!L31 -> 590 | K28: ='SAF 011'!G31 -> 800 | O28: =+J28*K28 -> 472000
A29: 18 | B29: ='SAF 011'!B32 -> 2.9.5-1909.96 | C29: ='SAF 011'!E32 -> GUANTES USO MEDICINAL; TIPO: MANOPLA, TAMAÑO: MEDIANO, MATERIAL: POLIETILENO, PRESENTACION: ENVASE X 100 | H29: SI | I29: ='SAF 011'!F32 -> BOLSA | J29: ='SAF 011'!L32 -> 2050 | K29: ='SAF 011'!G32 -> 500 | O29: =+J29*K29 -> 1025000
A30: 19 | B30: ='SAF 011'!B33 -> 2.9.5-1909.84 | C30: ='SAF 011'!E33 -> GUANTES USO MEDICINAL; TIPO: P/QUIMICOS, TAMAÑO: CHICO, MATERIAL: NITRILO, PRESENTACION: ENVASE X 100 UN | H30: SI | I30: ='SAF 011'!F33 -> CAJA | J30: ='SAF 011'!L33 -> 1378 | K30: ='SAF 011'!G33 -> 400 | O30: =+J30*K30 -> 551200
A31: 20 | B31: ='SAF 011'!B34 -> 2.9.5-1909.82 | C31: ='SAF 011'!E34 -> GUANTES USO MEDICINAL; TIPO: P/QUIMICOS, TAMAÑO: GRANDE, MATERIAL: NITRILO, PRESENTACION: ENVASE X 100 UN | H31: SI | I31: ='SAF 011'!F34 -> CAJA | J31: ='SAF 011'!L34 -> 1378 | K31: ='SAF 011'!G34 -> 50 | O31: =+J31*K31 -> 68900
A32: 21 | B32: ='SAF 011'!B35 -> 2.9.5-1909.83 | C32: ='SAF 011'!E35 -> GUANTES USO MEDICINAL; TIPO: P/QUIMICOS, TAMAÑO: MEDIANO, MATERIAL: NITRILO, PRESENTACION: ENVASE X 100 UN | H32: SI | I32: ='SAF 011'!F35 -> CAJA | J32: ='SAF 011'!L35 -> 1378 | K32: ='SAF 011'!G35 -> 500 | O32: =+J32*K32 -> 689000
A33: 22 | B33: ='SAF 011'!B36 -> 2.9.5-2366.2 | C33: ='SAF 011'!E36 -> HISOPOS; MATERIAL DE EXTREMOS: ALGODON, PRESENTACION: CAJA X 100 | H33: SI | I33: ='SAF 011'!F36 -> BOLSA | J33: ='SAF 011'!L36 -> 276 | K33: ='SAF 011'!G36 -> 400 | O33: =+J33*K33 -> 110400
A34: 23 | B34: ='SAF 011'!B37 -> 2.9.5-8799.12 | C34: ='SAF 011'!E37 -> JERINGA; MATERIAL: PLASTICO, CAPACIDAD: 10 CM3, ACCESORIOS: SIN, TIPO: ESTERIL, ACCESORIO: SIN | H34: SI | I34: ='SAF 011'!F37 -> CAJA | J34: ='SAF 011'!L37 -> 2027 | K34: ='SAF 011'!G37 -> 300 | O34: =+J34*K34 -> 608100
A35: 24 | B35: ='SAF 011'!B38 -> 2.9.5-8799.8 | C35: ='SAF 011'!E38 -> JERINGA; MATERIAL: PLASTICO, CAPACIDAD: 3 mL, ACCESORIOS: SIN, TIPO: NICHIRYO, ACCESORIO: SIN | H35: SI | I35: ='SAF 011'!F38 -> CAJA | J35: ='SAF 011'!L38 -> 1405 | K35: ='SAF 011'!G38 -> 500 | O35: =+J35*K35 -> 702500
A36: 25 | B36: ='SAF 011'!B39 -> 2.9.5-8799.11 | C36: ='SAF 011'!E39 -> JERINGA; MATERIAL: PLASTICO, CAPACIDAD: 5 CM3, ACCESORIOS: SIN, TIPO: ESTERIL, ACCESORIO: SIN | H36: SI | I36: ='SAF 011'!F39 -> CAJA | J36: ='SAF 011'!L39 -> 1380 | K36: ='SAF 011'!G39 -> 800 | O36: =+J36*K36 -> 1104000
A37: 26 | B37: ='SAF 011'!B40 -> 2.9.5-7870.15 | C37: ='SAF 011'!E40 -> LAMPARAS P/AUTOANALIZADOR; TIPO: HALOGENA, TENSION: 6 V, POTENCIA: 10 W | H37: SI | I37: ='SAF 011'!F40 -> UNIDAD | J37: ='SAF 011'!L40 -> 4600 | K37: ='SAF 011'!G40 -> 15 | N37: =+K37*J37 -> 69000
A38: 27 | B38: ='SAF 011'!B41 -> 2.9.5-7870.15 | C38: ='SAF 011'!E41 -> LAMPARAS P/AUTOANALIZADOR; TIPO: HALOGENA, TENSION: 6 V, POTENCIA: 10 W | H38: SI | I38: ='SAF 011'!F41 -> UNIDAD | J38: ='SAF 011'!L41 -> 2575 | K38: ='SAF 011'!G41 -> 30 | N38: =+K38*J38 -> 77250
A39: 28 | B39: ='SAF 011'!B42 -> 2.9.5-7870.16 | C39: ='SAF 011'!E42 -> LAMPARAS P/AUTOANALIZADOR; TIPO: HALOGENA, TENSION: 6 V, POTENCIA: 20 W | H39: SI | I39: ='SAF 011'!F42 -> UNIDAD | J39: ='SAF 011'!L42 -> 3800 | K39: ='SAF 011'!G42 -> 5 | N39: =+K39*J39 -> 19000
A40: 29 | B40: ='SAF 011'!B43 -> 2.9.5-2516.3 | C40: ='SAF 011'!E43 -> LAZOS P/EXTRACCION; MATERIAL: LATEX, DIAMETRO: PLANO 2 X 35 Cm | H40: SI | I40: ='SAF 011'!F43 -> CAJA | J40: ='SAF 011'!L43 -> 427 | K40: ='SAF 011'!G43 -> 100 | O40: =+J40*K40 -> 42700
A41: 30 | B41: ='SAF 011'!B44 -> 2.9.5-6479.44 | C41: ='SAF 011'!E44 -> MICROPIPETAS AUTOMATICAS; TIPO: MONOCANAL, ESCALA: 1 µL, VOLUMEN: 2 A 20 µL, SENSIBILIDAD: 0,01 µL | H41: SI | I41: ='SAF 011'!F44 -> UNIDAD | J41: ='SAF 011'!L44 -> 151734 | K41: ='SAF 011'!G44 -> 10 | O41: =+J41*K41 -> 1517340
A42: 31 | B42: ='SAF 011'!B45 -> 2.9.5-6479.46 | C42: ='SAF 011'!E45 -> MICROPIPETAS AUTOMATICAS; TIPO: MONOCANAL, ESCALA: 1 µL, VOLUMEN: 20 A 200 µL, SENSIBILIDAD: 0,1 µL | H42: SI | I42: ='SAF 011'!F45 -> UNIDAD | J42: ='SAF 011'!L45 -> 151734 | K42: ='SAF 011'!G45 -> 10 | O42: =+J42*K42 -> 1517340
A43: 32 | B43: ='SAF 011'!B46 -> 2.9.5-6479.35 | C43: ='SAF 011'!E46 -> MICROPIPETAS AUTOMATICAS; TIPO: MONOCANAL, ESCALA: 1 A 10 µL, VOLUMEN: 10 µL, SENSIBILIDAD: 0,1 µL | H43: SI | I43: ='SAF 011'!F46 -> UNIDAD | J43: ='SAF 011'!L46 -> 151734 | K43: ='SAF 011'!G46 -> 10 | O43: =+J43*K43 -> 1517340
...

Sheet APG LABORATORIO
A1: EJERCICIO: | D1: 2022 | P1: AUTORIZACION PARA GASTAR
A4: JURISDICCIÓN: | G4: ='NP LABORATORIO'!D3 -> 040 - MINISTERIO DE SALUD
A5: SAF: | G5: ='NP LABORATORIO'!D4 -> 011 - DIRECCION PROVINCIAL DE ADMINISTRACION - MINISTERIO DE SALUD
A6: UNIDAD EJECUTORA: | G6: ='NP LABORATORIO'!D5 -> 468 - DIRECCION PROVINCIAL DE LABORATORIO
A7: DEPENDENCIA SOLICITANTE: | G7: ='NP LABORATORIO'!D6 -> 468 - DIRECCION PROVINCIAL DE LABORATORIO
A8: AUTORIZACIÓN:
A9: Señor Director de Administración o Titular del Servicio Administrativo Financiero:
A10: Autorizo la realización de los trámites correspondientes, a fin de proveer a este Organismo los bienes que se detallan en Nota de Pedido N°....... , afectando la erogación resultante a los créditos presupuestarios aprobados a favor de esta Unidad Ejecutora, conforme al siguiente detalle:
A12: IMPUTACIÓN PRESUPUESTARIA
A13: CÓDIGO | O13: DENOMINACIÓN DE LA PARTIDA PRESUPUESTARIA | Q13: IMPORTE
A14: PR | B14: SB | C14: PY | D14: AC | E14: OB | F14: UG | G14: FIN | H14: FUN | I14: I | J14: P | K14: P | L14: SubP | M14: M | N14: FF
A15: 62 | D15: 1 | F15: 4901 | G15: 3 | H15: 1 | I15: 2 | J15: 3 | K15: 4 | M15: 1 | N15: 1.1 | O15: PRODUCTOS DE PAPEL Y CARTON | Q15: ='NP LABORATORIO'!M74 -> 390080
A16: 62 | D16: 1 | F16: 4901 | G16: 3 | H16: 1 | I16: 2 | J16: 9 | K16: 3 | M16: 1 | N16: 1.1 | O16: UTILES Y MATERIALES ELECTRICOS | Q16: ='NP LABORATORIO'!N74 -> 165250
A17: 62 | D17: 1 | F17: 4901 | G17: 3 | H17: 1 | I17: 2 | J17: 9 | K17: 5 | M17: 1 | N17: 1.1 | O17: UTILES MENORES MEDICOS, QUIRURGICOS Y DE LABORATORIO | Q17: ='NP LABORATORIO'!O74 -> 41230340
A18: 62 | D18: 1 | F18: 4901 | G18: 3 | H18: 1 | I18: 2 | J18: 9 | K18: 6 | M18: 1 | N18: 1.1 | O18: REPUESTOS Y ACCESORIOS | Q18: ='NP LABORATORIO'!P74 -> 84190
A38: TOTAL DE PESOS: CUARENTA Y UN MILLONES OCHOCIENTOS SESENTA Y NUEVE MIL OCHOCIENTOS SESENTA CON 00/100.- | Q38: =SUM(Q15:Q37) -> 41869860
A40: JUSTIFICACIÓN:
A41: ='NP LABORATORIO'!D8 -> ADQUISICION DEL RUBRO INSUMOS PARA LABORATORIO

Sheet NP BANCO DE SANGRE
A1: NOTA DE PEDIDO | J1: N° | K1: XX/2022
A3: JURISDICCIÓN: | D3: ='SAF 011'!C4 -> 040 - MINISTERIO DE SALUD
A4: SAF: | D4: ='SAF 011'!C5 -> 011 - DIRECCION PROVINCIAL DE ADMINISTRACION - MINISTERIO DE SALUD
A5: UNIDAD EJECUTORA: | D5: 747 - DIRECCION PROVINCIAL BANCO DE SANGRE
A6: DEPENDENCIA SOLICITANTE: | D6: 747 - DIRECCION PROVINCIAL BANCO DE SANGRE
A7: PERIODO UTILIZACIÓN: | D7: TRES MESES
A8: OBJETO: | D8: ADQUISICION DEL RUBRO INSUMOS PARA LABORATORIO
A10: Ítem | B10: Codigo Item | C10: DESCRIPCIÓN | H10: Adjunta Detalle Técnico | I10: Unidad Medida | J10: Precio Unitario Estimado | K10: Cantidad Solicitada
A12: 1 | B12: ='SAF 011'!B12 -> 2.9.5-470.13 | C12: ='SAF 011'!E12 -> ALGODONES; TIPO: HIDROFILADO, CAPACIDAD: 500 GR, PRESENTACION: ENVASE X 500 GR | H12: SI | I12: ='SAF 011'!F12 -> PAQUETE | J12: ='SAF 011'!L12 -> 862 | K12: ='SAF 011'!I12 -> 40
A13: 2 | B13: ='SAF 011'!B14 -> 2.9.5-427.131 | C13: ='SAF 011'!E14 -> APOSITOS; TIPO: HIPOALARGENICO, TAMAÑO: 40 X 40 MM | H13: SI | I13: ='SAF 011'!F14 -> CAJA | J13: ='SAF 011'!L14 -> 702 | K13: ='SAF 011'!I14 -> 50
A14: 3 | B14: ='SAF 011'!B17 -> 2.9.5-2694.22 | C14: ='SAF 011'!E17 -> BOLSAS P/TRANSFUSIONES SANGRE; CAPACIDAD: 450 mL, SOLUCIONES: CFD CON ADENINA, TIPO: HEMOTERAPIA | H14: SI | I14: ='SAF 011'!F17 -> UNIDAD | J14: ='SAF 011'!L17 -> 1190 | K14: ='SAF 011'!I17 -> 1800
A15: 4 | B15: ='SAF 011'!B18 -> 2.9.5-1908.28 | C15: ='SAF 011'!E18 -> CEPILLOS P/LABORATORIO; TIPO: LIMPIEZA DE TUBOS, MATERIAL: CERDA, TAMAÑO: DIAM. 9 mm | H15: SI | I15: ='SAF 011'!F18 -> UNIDAD | J15: ='SAF 011'!L18 -> 125 | K15: ='SAF 011'!I18 -> 10
A16: 5 | B16: ='SAF 011'!B23 -> 2.9.5-2160.1 | C16: ='SAF 011'!E23 -> DESCARTADORES DE AGUJAS; BOCA: 1, CAPACIDAD: 500 AGUJAS, MODELO: 500, MODELO EQUIPO: 500, SISTEMA DE CIERRE: 500 | H16: NO | I16: ='SAF 011'!F23 -> UNIDAD | J16: ='SAF 011'!L23 -> 195 | K16: ='SAF 011'!I23 -> 200
A17: 6 | B17: ='SAF 011'!B29 -> 2.9.5-1909.77 | C17: ='SAF 011'!E29 -> GUANTES USO MEDICINAL; TIPO: DESCARTABLE, TAMAÑO: CHICO, MATERIAL: LATEX, PRESENTACION: ENVASE X 100 UN | H17: SI | I17: ='SAF 011'!F29 -> CAJA | J17: ='SAF 011'!L29 -> 590 | K17: ='SAF 011'!I29 -> 50
A18: 7 | B18: ='SAF 011'!B30 -> 2.9.5-1909.81 | C18: ='SAF 011'!E30 -> GUANTES USO MEDICINAL; TIPO: DESCARTABLE, TAMAÑO: GRANDE, MATERIAL: LATEX, PRESENTACION: ENVASE X 100 UNID. | H18: SI | I18: ='SAF 011'!F30 -> CAJA | J18: ='SAF 011'!L30 -> 590 | K18: ='SAF 011'!I30 -> 50
A19: 8 | B19: ='SAF 011'!B31 -> 2.9.5-1909.87 | C19: ='SAF 011'!E31 -> GUANTES USO MEDICINAL; TIPO: DESCARTABLE, TAMAÑO: MEDIANO, MATERIAL: LATEX, PRESENTACION: ENVASE X 100 UNID. | H19: SI | I19: ='SAF 011'!F31 -> CAJA | J19: ='SAF 011'!L31 -> 590 | K19: ='SAF 011'!I31 -> 50
A20: 9 | B20: ='SAF 011'!B48 -> 2.9.5-2578.17 | C20: ='SAF 011'!E48 -> MICROPIPETAS REGULABLES; CAPACIDAD: 100 - 1000 µL, DIVISIONES: CADA 5 µL, MATERIAL: PLASTICO | H20: SI | I20: ='SAF 011'!F48 -> CAJA | J20: ='SAF 011'!L48 -> 50350 | K20: ='SAF 011'!I48 -> 2
A21: 10 | B21: ='SAF 011'!B49 -> 2.9.5-2578.16 | C21: ='SAF 011'!E49 -> MICROPIPETAS REGULABLES; CAPACIDAD: 10-100 µL, DIVISIONES: CADA 1 µL, MATERIAL: PLASTICO | H21: SI | I21: ='SAF 011'!F49 -> CAJA | J21: ='SAF 011'!L49 -> 50350 | K21: ='SAF 011'!I49 -> 2
A22: 11 | B22: ='SAF 011'!B60 -> 2.9.5-6786.6 | C22: ='SAF 011'!E60 -> PLACAS DE TOQUE; MATERIAL: VIDRIO, LARGO: 8 Cm, ANCHO: 6 Cm, ESPESOR: 5 mm, USO: DETERMINACION VDRL | H22: SI | I22: ='SAF 011'!F60 -> UNIDAD | J22: ='SAF 011'!L60 -> 1220 | K22: ='SAF 011'!I60 -> 5
A23: 12 | B23: ='SAF 011'!B65 -> 2.9.6-8875.293 | C23: ='SAF 011'!E65 -> REP. Y ACC P/ EQUIPO MEDICO; USO: PARA EQUIPO DE AFERESIS, MARCA DE EQUIPO: GRIFOLS, ELEMENTO: KITS PARA PLAQUETOFERESIS CON FILTRO CAJA X 8 UNID; EQUIPO: HAEMONETICS CS+ | H23: SI | I23: ='SAF 011'!F65 -> CAJA | J23: ='SAF 011'!L65 -> 41019 | K23: ='SAF 011'!I65 -> 48
A24: 13 | B24: ='SAF 011'!B66 -> 2.9.6-8875.294 | C24: ='SAF 011'!E66 -> REP. Y ACC P/ EQUIPO MEDICO; USO: PARA EQUIPO DE AFERESIS, MARCA DE EQUIPO: GRIFOLS, ELEMENTO: KITS PARA PLASMAFERESIS CON FILTRO CAJA X 8UNID, EQUIPO: HAEMONETIC CS+ | H24: SI | I24: ='SAF 011'!F66 -> CAJA | J24: ='SAF 011'!L66 -> 35090 | K24: ='SAF 011'!I66 -> 24
A25: 14 | B25: ='SAF 011'!B67 -> 2.9.6-8875.295 | C25: ='SAF 011'!E67 -> REP. Y ACC. P/ EQUIPO MEDICO, USO: BAÑO TERMOSTATIZADO PARA TARJETAS DE INMUNOHEMATOLOGIA, MARCA EQUIPO: GRIFOLS, ELEMENTO:TARJETA DE GEL ABO RH 2D, EQUIPO: CENTRIFUGA | H25: SI | I25: ='SAF 011'!F67 -> UNIDAD | J25: ='SAF 011'!L67 -> 590 | K25: ='SAF 011'!I67 -> 1500
A26: 15 | B26: ='SAF 011'!B68 -> 2.9.6-8875.292 | C26: ='SAF 011'!E68 -> REP. Y ACC. P/ EQUIPO MEDICO; USO: FRACCIONADOR AUTOMATICO HEMODERIVADOS, MARCA EQUIPO: GRIFOLS, ELEMENTO: CONEXIÓN POR RADIO FRECUENCIA Y GR, MODELO DE EQUIPO: FRACTIOMATIC PLUS 2 | H26: SI | I26: ='SAF 011'!F68 -> UNIDAD | J26: ='SAF 011'!L68 -> 3950 | K26: ='SAF 011'!I68 -> 900
A27: 16 | B27: ='SAF 011'!B72 -> 2.9.5-931.3 | C27: ='SAF 011'!E72 -> TELAS ADHESIVAS; ANCHO: 5.00 Cm, LONG.DE CUERPO: 9 M, TIPO: HIPOALERGENICA | H27: SI | I27: ='SAF 011'!F72 -> CAJA | J27: ='SAF 011'!L72 -> 1661 | K27: ='SAF 011'!I72 -> 5
A28: 17 | B28: ='SAF 011'!B77 -> 2.9.5-3492.343 | C28: ='SAF 011'!E77 -> TIP; TIPO: TIPS AMARILLO CON CORONA, PRESENTACION: X 1000 UNID., CAPACIDAD:0,2 ML | H28: NO | I28: ='SAF 011'!F77 -> BOLSA | J28: ='SAF 011'!L77 -> 1540 | K28: ='SAF 011'!I77 -> 2
A29: 18 | B29: ='SAF 011'!B78 -> 2.9.5-3492.341 | C29: ='SAF 011'!E78 -> TIP; TIPO: TIPS AMARILLO SIN CORONA,PRESENTACION: X 1000 UNID., CAPACIDAD:0,2 ML | H29: NO | I29: ='SAF 011'!F78 -> BOLSA | J29: ='SAF 011'!L78 -> 1540 | K29: ='SAF 011'!I78 -> 2
A30: 19 | B30: ='SAF 011'!B79 -> 2.9.5-3492.342 | C30: ='SAF 011'!E79 -> TIP; TIPO: TIPS AZUL AUTOCLAVABLE,PRESENTACION: X 1000 UNID., CAPACIDAD: 1000 MICROLITROS | H30: NO | I30: ='SAF 011'!F79 -> BOLSA | J30: ='SAF 011'!L79 -> 2204 | K30: ='SAF 011'!I79 -> 2
A31: 20 | B31: ='SAF 011'!B85 -> 2.9.5-468.232 | C31: ='SAF 011'!E85 -> TUBOS DE ENSAYO; TIPO: CONICO P/CENTRIFUGA, MATERIAL: POLIPROPILENO, DIMENSION: 0,5 A 15 mL, ACCESORIO: TAPA A ROSCA | H31: SI | I31: ='SAF 011'!F85 -> CAJA | J31: ='SAF 011'!L85 -> 13700 | K31: ='SAF 011'!I85 -> 2
A32: 21 | B32: ='SAF 011'!B86 -> 2.9.5-468.42 | C32: ='SAF 011'!E86 -> TUBOS DE ENSAYO; TIPO: EPPENDORF, MATERIAL: PLASTICO, DIMENSION: 1.5 mL, ACCESORIOS: SIN, ACCESORIO: SIN | H32: SI | I32: ='SAF 011'!F86 -> BOLSA | J32: ='SAF 011'!L86 -> 3558 | K32: ='SAF 011'!I86 -> 10
A33: 22 | B33: ='SAF 011'!B87 -> 2.9.5-468.249 | C33: ='SAF 011'!E87 -> TUBOS DE ENSAYO; TIPO: VACUTAINER P/ SUERO, MATERIAL: PLASTICO, DIMENSION: 4 ML, ACCESORIO: SIN | H33: SI | I33: ='SAF 011'!F87 -> CAJA | J33: ='SAF 011'!L87 -> 13700 | K33: ='SAF 011'!I87 -> 2
A34: 23 | B34: ='SAF 011'!B88 -> 2.9.5-468.85 | C34: ='SAF 011'!E88 -> TUBOS DE ENSAYO; TIPO: VACUTAINER, MATERIAL: VIDRIO BOROSILICATO, DIMENSION: 10 mL, ACCESORIOS: TAPA, ACCESORIO: TAPA | H34: SI | I34: ='SAF 011'!F88 -> CAJA | J34: ='SAF 011'!L88 -> 13000 | K34: ='SAF 011'!I88 -> 2
A35: 24 | B35: ='SAF 011'!B89 -> 2.9.5-4522.1 | C35: ='SAF 011'!E89 -> TUBOS DE HEMOLISIS; MATERIAL: VIDRIO, PRESENTACION: CAJA, DIMENSION: 100 X 13 DIAM. EXT., MEDIDAS: 100 X 13 DIAM. EXT., FORMA DE PRESENTACION: SOLIDO, ESTADO: SOLIDO | H35: SI | I35: ='SAF 011'!F89 -> CAJA | J35: ='SAF 011'!L89 -> 72000 | K35: ='SAF 011'!I89 -> 1
A36: Costo total estimado: PESOS DIEZ MILLONES SEIS MIL CIENTO CINCUENTA Y CINCO CON 00/100.- | J36: =SUMPRODUCT(J12:J35,K12:K35) -> 10006155 | Q36: =SUM(M36:P36) -> 0

Sheet APG BANCO DE SANGRE
A1: EJERCICIO: | D1: 2022 | P1: AUTORIZACION PARA GASTAR
A4: JURISDICCIÓN: | G4: ='NP BANCO DE SANGRE'!D3 -> 040 - MINISTERIO DE SALUD
A5: SAF: | G5: ='NP BANCO DE SANGRE'!D4 -> 011 - DIRECCION PROVINCIAL DE ADMINISTRACION - MINISTERIO DE SALUD
A6: UNIDAD EJECUTORA: | G6: ='NP BANCO DE SANGRE'!D5 -> 747 - DIRECCION PROVINCIAL BANCO DE SANGRE
A7: DEPENDENCIA SOLICITANTE: | G7: ='NP BANCO DE SANGRE'!D6 -> 747 - DIRECCION PROVINCIAL BANCO DE SANGRE
A8: AUTORIZACIÓN:
A9: Señor Director de Administración o Titular del Servicio Administrativo Financiero:
A10: Autorizo la realización de los trámites correspondientes, a fin de proveer a este Organismo los bienes que se detallan en Nota de Pedido N°....... , afectando la erogación resultante a los créditos presupuestarios aprobados a favor de esta Unidad Ejecutora, conforme al siguiente detalle:
A12: IMPUTACIÓN PRESUPUESTARIA
A13: CÓDIGO | O13: DENOMINACIÓN DE LA PARTIDA PRESUPUESTARIA | Q13: IMPORTE
A14: PR | B14: SB | C14: PY | D14: AC | E14: OB | F14: UG | G14: FIN | H14: FUN | I14: I | J14: P | K14: P | L14: SubP | M14: M | N14: FF
A15: 27 | D15: 1 | F15: 4901 | G15: 3 | H15: 1 | I15: 2 | J15: 9 | K15: 5 | M15: 1 | N15: 1.1 | O15: UTILES MENORES MEDICOS, QUIRURGICOS Y DE LABORATORIO | Q15: ='NP BANCO DE SANGRE'!J36 -> 10006155
A38: TOTAL DE PESOS: DIEZ MILLONES SEIS MIL CIENTO CINCUENTA Y CINCO CON 00/100.- | Q38: =SUM(Q15:Q37) -> 10006155
A40: JUSTIFICACIÓN:
A41: ='NP BANCO DE SANGRE'!D8 -> ADQUISICION DEL RUBRO INSUMOS PARA LABORATORIO
