Workbook

Sheet Telas NT
B2: Pedido de Necesidades Trimestrales
A4: JURISDICCION: | C4: 40 - Ministerio de Salud
A5: SAF N°: | C5: 23 - Hospital Interzonal San Juan Bautista
A6: EJERCICIO: | C6: 2021
A7: TRIMESTRE: | C7: 2
A9: ID | B9: CODIGO ITEM | C9: RUBRO DE COMPRA | D9: I.P.P. | E9: DESCRIPCION | F9: UNIDAD DE MEDIDA | G9: CANTIDAD | H9: PRECIO UNITARIO ESTIMADO | I9: IMPORTE TOTAL ESTIMADO
A10: 1 | B10: 2.2.1-2850.5 | C10: INDUMENT.TEXTILY CONFECCIONES | D10: =LEFT(B10,5) -> 2.2.1 | E10: TELA GABARDINA; ANCHO: 1,50 M, LARGO: 50 M, MATERIAL: POLIESTER 50% ALGODON 50% | F10: ROLLO | G10: 6 | H10: 31000 | I10: =G10*H10 -> 186000
A11: 2 | B11: 2.2.1-2617.19 | C11: INDUMENT.TEXTILY CONFECCIONES | D11: =LEFT(B11,5) -> 2.2.1 | E11: TELA DE ALGODON; ANCHO: 1,5 M, LARGO ROLLO: X METRO, LARGO: X METRO | F11: ROLLO | G11: 6 | H11: 31500 | I11: =G11*H11 -> 189000
A12: 3 | B12: 2.2.1-3437.5 | C12: INDUMENT.TEXTILY CONFECCIONES | D12: =LEFT(B12,5) -> 2.2.1 | E12: LONAS; ANCHO: 1,50 M, LARGO ROLLO: 100 M, COLOR: AZUL FRANCIA, TERMINACION: SIN VALOR | F12: ROLLO | G12: 1 | H12: 75000 | I12: =G12*H12 -> 75000
A13: 4 | B13: 2.2.9-702.30 | C13: ARTICULOS DEL HOGAR | D13: =LEFT(B13,5) -> 2.2.9 | E13: ALMOHADAS; CONSTRUCCION: FIBRA, DIMENSION: 50 X 70 Cm | F13: UNIDAD | G13: 100 | H13: 1750 | I13: =G13*H13 -> 175000
A14: 5 | B14: 2.2.1-9956.61 | C14: INDUMENT.TEXTILY CONFECCIONES | D14: =LEFT(B14,5) -> 2.2.1 | E14: TELAS TEXTILES; TIPO: ALGODON POLIESTER, ANCHO: 1,50 M, LARGO: 50 M | F14: ROLLO | G14: 20 | H14: 28000 | I14: =G14*H14 -> 560000
A15: 6 | B15: 2.4.1-3331.21 | C15: TAPICERIA | D15: =LEFT(B15,5) -> 2.4.1 | E15: CUERINAS P/TAPICERIA; TIPO: P/TAPICERIA, ANCHO: 1,5 M, LARGO: 50 M | F15: ROLLO | G15: 10 | H15: 40000 | I15: =G15*H15 -> 400000
A16: 7 | B16: 2.2.9-2298.14 | C16: INDUMENT.TEXTILY CONFECCIONES | D16: =LEFT(B16,5) -> 2.2.9 | E16: ELASTICO; PRESENTACION: ROLLO X 50 M, ANCHO: 50 mm | F16: ROLLO | G16: 1 | H16: 30000 | I16: =G16*H16 -> 30000
B19: Especificidades Item N° 1:
B21: Descripción técnica
C22: TELA GABARDINA DE 8z (GRUESA) COLOR BLANCO - ROLLOS DE 1,50 METROS DE ANCHO
B23: Plazos y lugares de entrega
C24: 10 dias - Sección lavadero - Roperia - Costurero
B26: Calidad Minima esperada
B28: Mantenimiento
C29: 30 dias habiles
B30: Garantia
B34: Especificidades Item N° 2:
B36: Descripción técnica
C37: TELA NIDO DE ABEJA, DE GRAMOS CHICOS - COLOR BLANCO - ROLLOS DE 1,50 METROS DE ANCHO X 50 METROS DE LARGO
B38: Plazos y lugares de entrega
C39: 10 días - Sección lavadero - Roperia - Costurero
B41: Calidad Minima esperada
B43: Mantenimiento
C44: 30 días hábiles
B45: Garantia
B49: Especificidades Item N° 3:
B51: Descripción técnica
C52: TELA LONA CATRERA "CABEZA DE TORO" - ROLLOS DE 1,50 METROS DE ANCHO
B53: Plazos y lugares de entrega
C54: 10 días - Sección lavadero - Roperia - Costurero
B56: Calidad Minima esperada
B58: Mantenimiento
C59: 30 días hábiles
B60: Garantia
...

Sheet Telas NPYE
A1: NOTA DE PEDIDO | J1: N° | K1: 016/2021
A3: JURISDICCIÓN: | D3: ='Telas NT'!C4 -> 40 - Ministerio de Salud
A4: SAF: | D4: ='Telas NT'!C5 -> 23 - Hospital Interzonal San Juan Bautista
A5: UNIDAD EJECUTORA: | D5: 237 - Direccion de Mantenimiento
A6: DEPENDENCIA SOLICITANTE: | D6: Sección Lavadero - Roperia - Costurero
A7: PERIODO UTILIZACIÓN: | D7: ='Telas NT'!C7 & "° Trimestre - Año " & 'Telas NT'!C6 -> 2° Trimestre - Año 2021
A8: OBJETO: | D8: Adquisición de Telas
A10: Ítem | B10: Codigo Item | C10: DESCRIPCIÓN | H10: Adjunta Detalle Técnico | I10: Unidad Medida | J10: Precio Unitario Estimado | K10: Cantidad Solicitada
A12: 1 | B12: ='Telas NT'!B10 -> 2.2.1-2850.5 | C12: ='Telas NT'!E10 -> TELA GABARDINA; ANCHO: 1,50 M, LARGO: 50 M, MATERIAL: POLIESTER 50% ALGODON 50% | H12: NO | I12: ='Telas NT'!F10 -> ROLLO | J12: 31000 | K12: ='Telas NT'!G10 -> 6
A13: 2 | B13: ='Telas NT'!B11 -> 2.2.1-2617.19 | C13: ='Telas NT'!E11 -> TELA DE ALGODON; ANCHO: 1,5 M, LARGO ROLLO: X METRO, LARGO: X METRO | H13: NO | I13: ='Telas NT'!F11 -> ROLLO | J13: ='Telas NT'!H11 -> 31500 | K13: ='Telas NT'!G11 -> 6
A14: 3 | B14: ='Telas NT'!B12 -> 2.2.1-3437.5 | C14: ='Telas NT'!E12 -> LONAS; ANCHO: 1,50 M, LARGO ROLLO: 100 M, COLOR: AZUL FRANCIA, TERMINACION: SIN VALOR | H14: NO | I14: ='Telas NT'!F12 -> ROLLO | J14: ='Telas NT'!H12 -> 75000 | K14: ='Telas NT'!G12 -> 1
A15: 4 | B15: ='Telas NT'!B13 -> 2.2.9-702.30 | C15: ='Telas NT'!E13 -> ALMOHADAS; CONSTRUCCION: FIBRA, DIMENSION: 50 X 70 Cm | H15: NO | I15: ='Telas NT'!F13 -> UNIDAD | J15: ='Telas NT'!H13 -> 1750 | K15: ='Telas NT'!G13 -> 100
A16: 5 | B16: ='Telas NT'!B14 -> 2.2.1-9956.61 | C16: ='Telas NT'!E14 -> TELAS TEXTILES; TIPO: ALGODON POLIESTER, ANCHO: 1,50 M, LARGO: 50 M | H16: NO | I16: ='Telas NT'!F14 -> ROLLO | J16: ='Telas NT'!H14 -> 28000 | K16: ='Telas NT'!G14 -> 20
A17: 6 | B17: ='Telas NT'!B15 -> 2.4.1-3331.21 | C17: ='Telas NT'!E15 -> CUERINAS P/TAPICERIA; TIPO: P/TAPICERIA, ANCHO: 1,5 M, LARGO: 50 M | H17: NO | I17: ='Telas NT'!F15 -> ROLLO | J17: ='Telas NT'!H15 -> 40000 | K17: ='Telas NT'!G15 -> 10
A18: 7 | B18: ='Telas NT'!B16 -> 2.2.9-2298.14 | C18: ='Telas NT'!E16 -> ELASTICO; PRESENTACION: ROLLO X 50 M, ANCHO: 50 mm | H18: NO | I18: ='Telas NT'!F16 -> ROLLO | J18: ='Telas NT'!H16 -> 30000 | K18: ='Telas NT'!G16 -> 1
A19: Costo total estimado: UN MILLON SEISCIENTOS QUINCE MIL CON 00/100.-------------------------------------------------------------------------- | J19: =SUMPRODUCT(J12:J18,K12:K18) -> 1615000

Sheet Telas APG 
A1: EJERCICIO: | D1: ='Telas NT'!C6 -> 2021 | P1: AUTORIZACION PARA GASTAR
A4: JURISDICCIÓN: | G4: ='Telas NPYE'!D3 -> 40 - Ministerio de Salud
A5: SAF: | G5: ='Telas NPYE'!D4 -> 23 - Hospital Interzonal San Juan Bautista
A6: UNIDAD EJECUTORA: | G6: ='Telas NPYE'!D5 -> 237 - Direccion de Mantenimiento
A7: DEPENDENCIA SOLICITANTE: | G7: ='Telas NPYE'!D6 -> Sección Lavadero - Roperia - Costurero
A8: AUTORIZACIÓN:
A9: Señor Jefe de Servicio Administrativo Financiero:
A10: ="Autorizo la realización de los trámites correspondientes, a fin de proveer a este Organismo los bienes y/o servicios que se detallan en Nota de Pedido N° " & 'Telas NPYE'!K1&", afectando la erogación resultante a los créditos presupuestarios aprobados a favor de esta Unidad Ejecutora, conforme al siguiente detalle:" -> Autorizo la realización de los trámites correspondientes, a fin de proveer a este Organismo los bienes y/o servicios que se detallan en Nota de Pedido N° 016/2021, afectando la erogación resultante a los créditos presupuestarios aprobados a favor de esta Unidad Ejecutora, conforme al siguiente detalle:
A12: IMPUTACIÓN PRESUPUESTARIA
A13: CÓDIGO | O13: DENOMINACIÓN DE LA PARTIDA PRESUPUESTARIA | Q13: IMPORTE
A14: PR | B14: SB | C14: PY | D14: AC | E14: OB | F14: UG | G14: FIN | H14: FUN | I14: I | J14: P | K14: P | L14: SubP | M14: M | N14: FF
A15: 33 | D15: 4 | F15: 4901 | G15: 3 | H15: 3.1 | I15: 2 | J15: 2 | K15: 1 | M15: 1 | N15: 1.1 | O15: Hilados y Telas | Q15: 1010000
A16: 33 | D16: 4 | F16: 4901 | G16: 3 | H16: 3.1 | I16: 2 | J16: 2 | K16: 9 | M16: 1 | N16: 1.1 | O16: Otros NEP | Q16: 205000
A17: 33 | D17: 4 | F17: 4901 | G17: 3 | H17: 3.1 | I17: 2 | J17: 4 | K17: 1 | M17: 1 | N17: 1.1 | O17: Cueros y Pieles | Q17: 400000
A23: TOTAL DE PESOS: UN MILLON SEISCIENTOS QUINCE MIL CON 00/100.------ | Q23: =SUM(Q15:Q22) -> 1615000
A25: JUSTIFICACIÓN:
A26: ="Para la "& 'Telas NPYE'!D8 &" para ser destinados al " & 'Telas NPYE'!D6 &" del HISJB del Ministerio de Salud." -> Para la Adquisición de Telas para ser destinados al Sección Lavadero - Roperia - Costurero del HISJB del Ministerio de Salud.
