Workbook

Sheet Necesidades Trimestrales (2)
B2: Pedido de Necesidades Trimestrales
A4: JURISDICCION: | C4: 70 - MINISTERIO DE CIENCIA E INNOVACION TECNOLOGICA
A5: SAF N°: | C5: 20 - MINISTERIO DE CIENCIA E INNOVACION TECNOLOGICA
A6: EJERCICIO: | C6: 2021
A7: TRIMESTRE: | C7: 4
A9: ID | B9: CODIGO ITEM | C9: RUBRO DE COMPRA | D9: I.P.P. | E9: DESCRIPCION | F9: UNIDAD DE MEDIDA | G9: CANTIDAD | H9: PRECIO UNITARIO ESTIMADO | I9: IMPORTE TOTAL ESTIMADO
A10: 1 | B10: 4.3.6-6161.251 | C10: INFORMATICA | D10: =LEFT(B10,5) -> 4.3.6 | E10: IMPRESORAS; TIPO: MULTIFUNCION LASER MONOCROM., CODIGO ETAP: PR-026, VERSION ETAP: VERSION 18.1 | F10: UNIDAD | G10: 3 | H10: 83599 | I10: =G10*H10 -> 250797 | L10: =#REF!+#REF!+#REF!+#REF!+#REF! -> #REF!
A11: 2 | B11: 4.3.6-6170.59 | C11: INFORMATICA | D11: =LEFT(B11,5) -> 4.3.6 | E11: DIG. DE IMAGENES/ESCANER; TIPO: ESCANER DOCUMENTOS PRODUCCION, CODIGO ETAP: SC-006, VERSION ETAP: 22.0 | F11: UNIDAD | G11: 2 | H11: 80000 | I11: =G11*H11 -> 160000
A12: 3 | B12: 4.3.5-241.86 | C12: ARTICULOS DEL HOGAR | D12: =LEFT(B12,5) -> 4.3.5 | E12: TELEVISORES; PANTALLA: LED 50 pulg, NORMA: MULTINORMA, CANTIDAD DE CANALES: 180, APAGADO: AUTOMATICO, VISION MULTICANAL: SI | F12: UNIDAD | G12: 5 | H12: 100000 | I12: =G12*H12 -> 500000
A13: 4 | B13: 4.3.5-9163.83 | C13: EQUIPOS | D13: =LEFT(B13,5) -> 4.3.5 | E13: EQUIPOS DIDACTICOS TECNICOS; NOMBRE: MARCO TOUCH, TIPO: P/PANTALLA | F13: UNIDAD | G13: 5 | H13: 30000 | I13: =G13*H13 -> 150000
A14: 5 | B14: 4.3.5-9163.83 | C14: EQUIPOS | D14: =LEFT(B14,5) -> 4.3.5 | E14: EQUIPOS DIDACTICOS TECNICOS; NOMBRE: MARCO TOUCH, TIPO: P/PANTALLA | F14: UNIDAD | G14: 4 | H14: 30000 | I14: =G14*H14 -> 120000
A15: Costo total estimado: | I15: =SUM(I10:I14) -> 1180797
B18: Especificidades Item N° 1:
B20: Descripción técnica
C21: IMPRESORA MULTIFUNCION: # monocromática. # Imprime, escanea y hace copias. # Impresión doble faz automática. # Tecnología de impresión: láser. # Su pantalla táctil hace que el uso sea más intuitivo. # Con conexión bluetooth y entrada USB. # Cuenta con 2 bandejas. # Capacidad máxima de 400 hojas. #Soporta papel tamaño A4, A5, A6, B5 JIS, Oficio, Tarjeta postal japonesa, Tarjeta postal japonesa con rotación doble, Sobre B5, Sobre C5, Sobre DL, 76.2 x 127 mm - 215.9 x 355.6 mm, 104.9 x 148.59 mm - 215.9 x 355.6 mm, 16.000 (195 x 270 mm), 16.000 (184 x 260 mm), 16.000 (197 x 273 mm), Sobre N10, Sobre monarca, 4 x 6 ", 5 x 8 ", Declaración, A5-R, B6 JIS
B22: Plazos y lugares de entrega
C23: El plazo de entrega no podrá ser superior a los diez (10) días hábiles a partir de la fecha de recepción de la respectiva Orden de Compra en el domicilio especial electrónico constituido, en virtud del método de contratación. La entrega de dichos bienes se realizará en el Ministerio de Ciencia e Innovación Tecnologica, sito en Avenida Belgrano N° 1494 - CAPE- Pabellón N° 26 San Fernando del Valle de Catamarca. Se presentará Remito que deberá cumplimentar lo dispuesto por la R.G. AFIP 1415/03, sin excepción.
B25: Calidad Minima esperada
B27: Mantenimiento: treinta (30) dias corridos
B29: Garantia
C30: Garantía del fabricante minima de un (1) año.
B33: Especificidades Item N° 2:
B35: Descripción técnica
C36: Escáner, Alimentador de hojas múltiples * Medidas 330 mm x 246 mm x 162 mm * Velocidades de producción: Hasta 30 ppm / 60 ipm a 200 dpi y 300 dpi * Volumen diario recomendado: Hasta 3,000 páginas al día * Tamaño máximo del documento: 216 x 356 mm; documentos largos hasta 3 metros * Alimentador: Hasta 75 hojas; compatible con documentos pequeños * Conectividad: USB 2.0 de alta velocidad * Resolución óptica: 600 dpi * Panel de control: Pantalla gráfica LCD en color.
B37: Plazos y lugares de entrega
C38: El plazo de entrega no podrá ser superior a los diez (10) días hábiles a partir de la fecha de recepción de la respectiva Orden de Compra en el domicilio especial electrónico constituido, en virtud del método de contratación. La entrega de dichos bienes se realizará en el Ministerio de Ciencia e Innovación Tecnologica, sito en Avenida Belgrano N° 1494 - CAPE- Pabellón N° 26 San Fernando del Valle de Catamarca. Se presentará Remito que deberá cumplimentar lo dispuesto por la R.G. AFIP 1415/03, sin excepción.
B40: Calidad Minima esperada
B42: Mantenimiento: treinta (30) dias corridos
B44: Garantia
C45: Garantía del fabricante minima de un (1) año.
B49: Especificidades Item N° 3:
B51: Descripción técnica
C52: Smart Tv 50". Resolucion FHD 1920x1080. Entradas HDMI y puertos USB disponibles. Sintonizador digital incorporado con funcion PVR y Timeshift para grabar tus programas favoritos. Wi-fi. Netflix, Youtube y Vewd (ex Opera store).
B53: Plazos y lugares de entrega
C54: El plazo de entrega no podrá ser superior a los diez (10) días hábiles a partir de la fecha de recepción de la respectiva Orden de Compra en el domicilio especial electrónico constituido, en virtud del método de contratación. La entrega de dichos bienes se realizará en el Ministerio de Ciencia e Innovación Tecnologica, sito en Avenida Belgrano N° 1494 - CAPE- Pabellón N° 26 San Fernando del Valle de Catamarca. Se presentará Remito que deberá cumplimentar lo dispuesto por la R.G. AFIP 1415/03, sin excepción.
B56: Calidad Minima esperada
B58: Mantenimiento: treinta (30) dias corridos
B60: Garantia
C61: Garantía del fabricante minima de un (1) año.
B65: Especificidades Item N° 4:
...

Sheet  NotaPedido
A1: NOTA DE PEDIDO | J1: N° | K1: 049/2021
A3: JURISDICCIÓN: | D3: 70 - MINISTERIO DE CIENCIA E INNOVACION TECNOLOGICA
A4: SAF: | D4: 20 - MINISTERIO DE CIENCIA E INNOVACION TECNOLOGICA
A5: UNIDAD EJECUTORA: | D5: SECRETARIA DE INNOVACION TECNOLOGICA - DIRECCION PROVINCIAL DE GESTION ADMINISTRATIVA RECURSOS HUMANOS
A6: DEPENDENCIA SOLICITANTE: | D6: DIRECCION PROVINCIAL DE GESTION ADMINISTRATIVA RECURSOS HUMANOS
A7: PERIODO UTILIZACIÓN: | D7: 4° TRIMESTRE 2021
A8: OBJETO: | D8: ADQUISICIÓN DE DIVERSOS EQUIPOS DESTINADO AL LABORATORIO DE ROBOTICA DEPENDIENTE DEL MINISTERIO DE CIENCIA E INNOVACIÓN TECNOLOGICA.-
A10: Ítem | B10: Codigo Item | C10: DESCRIPCIÓN | H10: Adjunta Detalle Técnico | I10: Unidad Medida | J10: Precio Unitario Estimado | K10: Cantidad Solicitada
A12: 1 | B12: ='Necesidades Trimestrales (2)'!B10 -> 4.3.6-6161.251 | C12: ='Necesidades Trimestrales (2)'!E10 -> IMPRESORAS; TIPO: MULTIFUNCION LASER MONOCROM., CODIGO ETAP: PR-026, VERSION ETAP: VERSION 18.1 | D12: COMPUTADORAS; TIPO: NOTEBOOK, CODIGO ETAP: PC-008, VERSION ETAP: 22.0 | E12: COMPUTADORAS; TIPO: NOTEBOOK, CODIGO ETAP: PC-008, VERSION ETAP: 22.0 | F12: COMPUTADORAS; TIPO: NOTEBOOK, CODIGO ETAP: PC-008, VERSION ETAP: 22.0 | G12: COMPUTADORAS; TIPO: NOTEBOOK, CODIGO ETAP: PC-008, VERSION ETAP: 22.0 | H12: SI | I12: UNIDAD | J12: ='Necesidades Trimestrales (2)'!H10 -> 83599 | K12: ='Necesidades Trimestrales (2)'!G10 -> 3
A13: 2 | B13: ='Necesidades Trimestrales (2)'!B11 -> 4.3.6-6170.59 | C13: ='Necesidades Trimestrales (2)'!E11 -> DIG. DE IMAGENES/ESCANER; TIPO: ESCANER DOCUMENTOS PRODUCCION, CODIGO ETAP: SC-006, VERSION ETAP: 22.0 | D13: COMPUTADORAS; TIPO: NOTEBOOK, CODIGO ETAP: PC-008, VERSION ETAP: 22.0 | E13: COMPUTADORAS; TIPO: NOTEBOOK, CODIGO ETAP: PC-008, VERSION ETAP: 22.0 | F13: COMPUTADORAS; TIPO: NOTEBOOK, CODIGO ETAP: PC-008, VERSION ETAP: 22.0 | G13: COMPUTADORAS; TIPO: NOTEBOOK, CODIGO ETAP: PC-008, VERSION ETAP: 22.0 | H13: SI | I13: UNIDAD | J13: ='Necesidades Trimestrales (2)'!H11 -> 80000 | K13: ='Necesidades Trimestrales (2)'!G11 -> 2
A14: 3 | B14: ='Necesidades Trimestrales (2)'!B12 -> 4.3.5-241.86 | C14: ='Necesidades Trimestrales (2)'!E12 -> TELEVISORES; PANTALLA: LED 50 pulg, NORMA: MULTINORMA, CANTIDAD DE CANALES: 180, APAGADO: AUTOMATICO, VISION MULTICANAL: SI | D14: COMPUTADORAS; TIPO: NOTEBOOK, CODIGO ETAP: PC-008, VERSION ETAP: 22.0 | E14: COMPUTADORAS; TIPO: NOTEBOOK, CODIGO ETAP: PC-008, VERSION ETAP: 22.0 | F14: COMPUTADORAS; TIPO: NOTEBOOK, CODIGO ETAP: PC-008, VERSION ETAP: 22.0 | G14: COMPUTADORAS; TIPO: NOTEBOOK, CODIGO ETAP: PC-008, VERSION ETAP: 22.0 | H14: SI | I14: UNIDAD | J14: ='Necesidades Trimestrales (2)'!H12 -> 100000 | K14: ='Necesidades Trimestrales (2)'!G12 -> 5
A15: 4 | B15: ='Necesidades Trimestrales (2)'!B13 -> 4.3.5-9163.83 | C15: ='Necesidades Trimestrales (2)'!E13 -> EQUIPOS DIDACTICOS TECNICOS; NOMBRE: MARCO TOUCH, TIPO: P/PANTALLA | D15: COMPUTADORAS; TIPO: NOTEBOOK, CODIGO ETAP: PC-008, VERSION ETAP: 22.0 | E15: COMPUTADORAS; TIPO: NOTEBOOK, CODIGO ETAP: PC-008, VERSION ETAP: 22.0 | F15: COMPUTADORAS; TIPO: NOTEBOOK, CODIGO ETAP: PC-008, VERSION ETAP: 22.0 | G15: COMPUTADORAS; TIPO: NOTEBOOK, CODIGO ETAP: PC-008, VERSION ETAP: 22.0 | H15: SI | I15: UNIDAD | J15: ='Necesidades Trimestrales (2)'!H13 -> 30000 | K15: ='Necesidades Trimestrales (2)'!G13 -> 5
A16: 5 | B16: ='Necesidades Trimestrales (2)'!B14 -> 4.3.5-9163.83 | C16: ='Necesidades Trimestrales (2)'!E14 -> EQUIPOS DIDACTICOS TECNICOS; NOMBRE: MARCO TOUCH, TIPO: P/PANTALLA | D16: COMPUTADORAS; TIPO: NOTEBOOK, CODIGO ETAP: PC-008, VERSION ETAP: 22.0 | E16: COMPUTADORAS; TIPO: NOTEBOOK, CODIGO ETAP: PC-008, VERSION ETAP: 22.0 | F16: COMPUTADORAS; TIPO: NOTEBOOK, CODIGO ETAP: PC-008, VERSION ETAP: 22.0 | G16: COMPUTADORAS; TIPO: NOTEBOOK, CODIGO ETAP: PC-008, VERSION ETAP: 22.0 | H16: SI | I16: UNIDAD | J16: ='Necesidades Trimestrales (2)'!H14 -> 30000 | K16: ='Necesidades Trimestrales (2)'!G14 -> 4
A17: Costo total estimado: PESOS UN MILLON CIENTO OCHENTA MIL SETECIENTOS NOVENTA Y SIETE CON 00/100.- | J17: =SUMPRODUCT(J12:J16,K12:K16) -> 1180797

Sheet Autor Gastar
A1: EJERCICIO: | D1: 2021 | P1: AUTORIZACION PARA GASTAR
A4: JURISDICCIÓN: | G4: =' NotaPedido'!D3 -> 70 - MINISTERIO DE CIENCIA E INNOVACION TECNOLOGICA
A5: SAF: | G5: =' NotaPedido'!D4 -> 20 - MINISTERIO DE CIENCIA E INNOVACION TECNOLOGICA
A6: UNIDAD EJECUTORA: | G6: =' NotaPedido'!D5 -> SECRETARIA DE INNOVACION TECNOLOGICA - DIRECCION PROVINCIAL DE GESTION ADMINISTRATIVA RECURSOS HUMANOS
A7: DEPENDENCIA SOLICITANTE: | G7: =' NotaPedido'!D6 -> DIRECCION PROVINCIAL DE GESTION ADMINISTRATIVA RECURSOS HUMANOS
A8: AUTORIZACIÓN:
A9: Señor Jefe de Servicio Administrativo Financiero:
A10: ="Autorizo la realización de los trámites correspondientes, a fin de proveer a este Organismo los bienes y/o servicios que se detallan en Nota de Pedido N° " & ' NotaPedido'!K1&", afectando la erogación resultante a los créditos presupuestarios aprobados a favor de esta Unidad Ejecutora, conforme al siguiente detalle:" -> Autorizo la realización de los trámites correspondientes, a fin de proveer a este Organismo los bienes y/o servicios que se detallan en Nota de Pedido N° 049/2021, afectando la erogación resultante a los créditos presupuestarios aprobados a favor de esta Unidad Ejecutora, conforme al siguiente detalle:
A12: IMPUTACIÓN PRESUPUESTARIA
A13: CÓDIGO | O13: DENOMINACIÓN DE LA PARTIDA PRESUPUESTARIA | Q13: IMPORTE
A14: PR | B14: SB | C14: PY | D14: AC | E14: OB | F14: UG | G14: FIN | H14: FUN | I14: I | J14: P | K14: P | L14: SubP | M14: M | N14: FF
A15: 3 | B15: 0 | C15: 0 | D15: 1 | E15: 0 | F15: 4901 | G15: 3 | H15: 5 | I15: 4 | J15: 3 | K15: 5 | L15: 0 | M15: 1 | N15: 1.1 | O15: Equipos Educacional y Recreativo | Q15: 770000
A16: 5 | B16: 0 | C16: 0 | D16: 1 | E16: 0 | F16: 4901 | G16: 3 | H16: 5 | I16: 4 | J16: 3 | K16: 6 | L16: 0 | M16: 1 | N16: 1.1 | O16: Equipos para Computación | Q16: 410797
A18: PESOS: UN MILLON CIENTO OCHENTA MIL SETECIENTOS NOVENTA Y SIETE CON 00/100.- | Q18: =SUM(Q15:Q17) -> 1180797
A20: JUSTIFICACIÓN:
A21: ADQUISICIÓN DE DIVERSOS EQUIPOS DESTINADO AL LABORATORIO DE ROBOTICA DEPENDIENTE DEL MINISTERIO DE CIENCIA E INNOVACIÓN TECNOLOGICA.-
