Workbook

Sheet Necesidades Trimestrales
B2: Pedido de Necesidades Trimestrales
A4: JURISDICCION: | C4: 40-Ministerio de Salud
A5: SAF N°: | C5: 28- Maternidad Provincial 25 de Mayo
A6: EJERCICIO: | C6: 2022
A7: TRIMESTRE: | C7: 3
A9: ID | B9: CODIGO ITEM | C9: RUBRO DE COMPRA | D9: I.P.P. | E9: DESCRIPCION | F9: UNIDAD DE MEDIDA | G9: CANTIDAD | H9: PRECIO UNITARIO ESTIMADO | I9: IMPORTE TOTAL ESTIMADO
A10: 1 | B10: 2.9.6-6745.34 | C10: REPUESTOS | D10: 2.9.6 | E10: REP. Y ACC. P/AUTOCLAVE; REPUESTO: VALVULA DE SEGURIDAD, MARCA EQUIPO: DEL GIUDICE, MODELO EQUIPO: 9 - 250L - DP - BV | F10: UNIDAD | G10: 3 | H10: 29000 | I10: =H10*G10 -> 87000 | J10: =B10='[1]Necesidades Trimestrales'!B10 -> TRUE | K10: =E10='[1]Necesidades Trimestrales'!E10 -> TRUE | L10: =+G10*H10-'[1]Necesidades Trimestrales'!I10 -> 0
A11: 2 | B11: 2.9.6-6745.34 | C11: REPUESTOS | D11: 2.9.6 | E11: REP. Y ACC. P/AUTOCLAVE; REPUESTO: VALVULA DE SEGURIDAD, MARCA EQUIPO: DEL GIUDICE, MODELO EQUIPO: 9 - 250L - DP - BV | F11: UNIDAD | G11: 1 | H11: 35000 | I11: =H11*G11 -> 35000 | J11: =B11='[1]Necesidades Trimestrales'!B11 -> TRUE | K11: =E11='[1]Necesidades Trimestrales'!E11 -> TRUE | L11: =+G11*H11-'[1]Necesidades Trimestrales'!I11 -> 0
A12: 3 | B12: 2.9.6-8875.289 | C12: REPUESTOS | D12: 2.9.6 | E12: REP. Y ACC. P/EQUIPO MEDICO; USO: TENSIOMETRO ANEROIDE, ELEMENTO: PERITA INSUFLADORA | F12: UNIDAD | G12: 15 | H12: 352 | I12: =H12*G12 -> 5280 | J12: =B12='[1]Necesidades Trimestrales'!B12 -> TRUE | K12: =E12='[1]Necesidades Trimestrales'!E12 -> TRUE | L12: =+G12*H12-'[1]Necesidades Trimestrales'!I12 -> 0
A13: 4 | B13: 2.9.6-8875.290 | C13: REPUESTOS | D13: 2.9.6 | E13: REP. Y ACC. P/EQUIPO MEDICO; USO: TENSIOMETRO ANEROIDE, ELEMENTO: CAMARA DE DOS VIAS | F13: UNIDAD | G13: 15 | H13: 860 | I13: =H13*G13 -> 12900 | J13: =B13='[1]Necesidades Trimestrales'!B13 -> TRUE | K13: =E13='[1]Necesidades Trimestrales'!E13 -> TRUE | L13: =+G13*H13-'[1]Necesidades Trimestrales'!I13 -> 0
A14: 5 | B14: 2.9.6-8875.277 | C14: REPUESTOS | D14: 2.9.6 | E14: REP. Y ACC. P/EQUIPO MEDICO; USO: MESA DE ANESTESIA, MARCA EQUIPO: GENERAL ELECTRIC, ELEMENTO: CELDA DE OXIGENO, MODELO EQUIPO: AVANCE CS | F14: UNIDAD | G14: 1 | H14: 39682.03 | I14: =H14*G14 -> 39682.03 | J14: =B14='[1]Necesidades Trimestrales'!B14 -> TRUE | K14: =E14='[1]Necesidades Trimestrales'!E14 -> TRUE | L14: =+G14*H14-'[1]Necesidades Trimestrales'!I14 -> 0
A15: 6 | B15: 2.9.6-8875.278 | C15: REPUESTOS | D15: 2.9.6 | E15: REP. Y ACC. P/EQUIPO MEDICO; USO: RESPIRADOR, MARCA EQUIPO: MAQUET, ELEMENTO: CASSETE ESPIRATORIO, MODELO EQUIPO: SERVO I | F15: UNIDAD | G15: 6 | H15: 452147 | I15: =H15*G15 -> 2712882 | J15: =B15='[1]Necesidades Trimestrales'!B15 -> TRUE | K15: =E15='[1]Necesidades Trimestrales'!E15 -> TRUE | L15: =+G15*H15-'[1]Necesidades Trimestrales'!I15 -> 0
A16: 7 | B16: 2.9.6-8875.275 | C16: REPUESTOS | D16: 2.9.6 | E16: REP Y ACC P/EQUIPO MEDICO; USO: INCUBADORA NEONATAL EQUIPO: MEDIX, MODELO EQUIPO: NATAL CARE ,ELEMENTO: BASE RODANTE CON RUEDAS | F16: UNIDAD | G16: 20 | H16: 122750 | I16: =H16*G16 -> 2455000 | J16: =B16='[1]Necesidades Trimestrales'!B16 -> TRUE | K16: =E16='[1]Necesidades Trimestrales'!E16 -> TRUE | L16: =+G16*H16-'[1]Necesidades Trimestrales'!I16 -> 0
A17: 8 | B17: 2.9.6-8875.282 | C17: REPUESTOS | D17: 2.9.6 | E17: REP. Y ACC. P/EQUIPO MEDICO; USO: INCUBADORA NEONATAL, MARCA EQUIPO: MEDIX, ELEMENTO: SENSOR TEMPERATURA DE AIRE, MODELO EQUIPO: NATAL CARE | F17: UNIDAD | G17: 6 | H17: 27125 | I17: =H17*G17 -> 162750 | J17: =B17='[1]Necesidades Trimestrales'!B17 -> TRUE | K17: =E17='[1]Necesidades Trimestrales'!E17 -> TRUE | L17: =+G17*H17-'[1]Necesidades Trimestrales'!I17 -> 0
A18: 9 | B18: 2.9.6-8875.283 | C18: REPUESTOS | D18: 2.9.6 | E18: REP. Y ACC. P/EQUIPO MEDICO; USO: INCUBADORA NEONATAL, MARCA EQUIPO: MEDIX, ELEMENTO: MOTOR-TURBINA, MODELO EQUIPO: NATAL CARE | F18: UNIDAD | G18: 20 | H18: 103500 | I18: =H18*G18 -> 2070000 | J18: =B18='[1]Necesidades Trimestrales'!B18 -> TRUE | K18: =E18='[1]Necesidades Trimestrales'!E18 -> TRUE | L18: =+G18*H18-'[1]Necesidades Trimestrales'!I18 -> 0
A19: 10 | B19: 2.9.6-8875.285 | C19: REPUESTOS | D19: 2.9.6 | E19: REP. Y ACC. P/EQUIPO MEDICO; USO: LUMINOTERAPIA, MARCA EQUIPO: MEDIX, ELEMENTO: CONTADOR DE HORAS, MODELO EQUIPO: MEDILED | F19: UNIDAD | G19: 30 | H19: 19625 | I19: =H19*G19 -> 588750 | J19: =B19='[1]Necesidades Trimestrales'!B19 -> TRUE | K19: =E19='[1]Necesidades Trimestrales'!E19 -> TRUE | L19: =+G19*H19-'[1]Necesidades Trimestrales'!I19 -> 0
B22: Especificidades Item N° 1:
B24: Descripción técnica
C25: Válvula de seguridad sin capuchón. Cuerpo de bronce. Asiento de teflón. Rosca macho de 1/2". Presión de Apertura: 3 Bar. Apto para vapor | F25: =C25='[1]Necesidades Trimestrales'!C25 -> TRUE
B26: Plazos y lugares de entrega | E26: 10(diez) dias habiles
C27: Con boca de expendio en San Fernando del Valle de Catamarca-Direccion de Mantenimiento de Maternidad Provincial 25 de Mayo Domicilio: Hernando de Pedraza N° 1650 B° Jorge Bermudez
B29: Calidad Minima esperada
B31: Mantenimiento | E31: 30(treinta) dias habiles
B33: Garantia | E33: 1 (UN) AÑO
B36: Especificidades Item N° 2:
B38: Descripción técnica
C39: Válvula de seguridad sin capuchón. Cuerpo de bronce. Asiento de teflón. Rosca macho de 3/4". Presión de Apertura: 4 Bar. Apto para vapor | F39: =C39='[1]Necesidades Trimestrales'!C39 -> TRUE
B40: Plazos y lugares de entrega | E40: 10(diez) dias habiles
C41: Con boca de expendio en San Fernando del Valle de Catamarca-Direccion de Mantenimiento de Maternidad Provincial 25 de Mayo Domicilio: Hernando de Pedraza N° 1650 B° Jorge Bermudez
B43: Calidad Minima esperada
B45: Mantenimiento | E45: 30(treinta) dias habiles
B47: Garantia | E47: 1 (UN) AÑO
B52: Especificidades Item N° 3:
B54: Descripción técnica
C55: Perita insufladora. Material: goma. | F55: =C55='[1]Necesidades Trimestrales'!C55 -> TRUE
B56: Plazos y lugares de entrega | E56: 10(diez) dias habiles
C57: Con boca de expendio en San Fernando del Valle de Catamarca-Direccion de Mantenimiento de Maternidad Provincial 25 de Mayo Domicilio: Hernando de Pedraza N° 1650 B° Jorge Bermudez
B59: Calidad Minima esperada
B61: Mantenimiento | E61: 30(treinta) dias habiles
B63: Garantia | E63: 1 (UN) AÑO
...

Sheet  NotaPedido
A1: NOTA DE PEDIDO | J1: N° | K1: /2020
A3: JURISDICCIÓN: | D3: ='Necesidades Trimestrales'!C4 -> 40-Ministerio de Salud
A4: SAF: | D4: ='Necesidades Trimestrales'!C5 -> 28- Maternidad Provincial 25 de Mayo
A5: UNIDAD EJECUTORA: | D5: Direccion de Mantenimiento
A6: DEPENDENCIA SOLICITANTE: | D6: Mantenimiento
A7: PERIODO UTILIZACIÓN: | D7: ='Necesidades Trimestrales'!C7 & "° Trimestre - Año " & 'Necesidades Trimestrales'!C6 -> 3° Trimestre - Año 2022
A8: OBJETO: | D8: Adquisicion de Repuestos y Accesorios para Equipamiento Médico.
A10: Ítem | B10: Codigo Item | C10: DESCRIPCIÓN | H10: Adjunta Detalle Técnico | I10: Unidad Medida | J10: Precio Unitario Estimado | K10: Cantidad Solicitada
A12: =+'Necesidades Trimestrales'!A10 -> 1 | B12: =+'Necesidades Trimestrales'!B10 -> 2.9.6-6745.34 | C12: =+'Necesidades Trimestrales'!E10 -> REP. Y ACC. P/AUTOCLAVE; REPUESTO: VALVULA DE SEGURIDAD, MARCA EQUIPO: DEL GIUDICE, MODELO EQUIPO: 9 - 250L - DP - BV | H12: SI | I12: =+'Necesidades Trimestrales'!F10 -> UNIDAD | J12: =+'Necesidades Trimestrales'!H10 -> 29000 | K12: =+'Necesidades Trimestrales'!G10 -> 3
A13: =+'Necesidades Trimestrales'!A11 -> 2 | B13: =+'Necesidades Trimestrales'!B11 -> 2.9.6-6745.34 | C13: =+'Necesidades Trimestrales'!E11 -> REP. Y ACC. P/AUTOCLAVE; REPUESTO: VALVULA DE SEGURIDAD, MARCA EQUIPO: DEL GIUDICE, MODELO EQUIPO: 9 - 250L - DP - BV | H13: SI | I13: =+'Necesidades Trimestrales'!F11 -> UNIDAD | J13: =+'Necesidades Trimestrales'!H11 -> 35000 | K13: =+'Necesidades Trimestrales'!G11 -> 1
A14: =+'Necesidades Trimestrales'!A12 -> 3 | B14: =+'Necesidades Trimestrales'!B12 -> 2.9.6-8875.289 | C14: =+'Necesidades Trimestrales'!E12 -> REP. Y ACC. P/EQUIPO MEDICO; USO: TENSIOMETRO ANEROIDE, ELEMENTO: PERITA INSUFLADORA | H14: SI | I14: =+'Necesidades Trimestrales'!F12 -> UNIDAD | J14: =+'Necesidades Trimestrales'!H12 -> 352 | K14: =+'Necesidades Trimestrales'!G12 -> 15
A15: =+'Necesidades Trimestrales'!A13 -> 4 | B15: =+'Necesidades Trimestrales'!B13 -> 2.9.6-8875.290 | C15: =+'Necesidades Trimestrales'!E13 -> REP. Y ACC. P/EQUIPO MEDICO; USO: TENSIOMETRO ANEROIDE, ELEMENTO: CAMARA DE DOS VIAS | H15: SI | I15: =+'Necesidades Trimestrales'!F13 -> UNIDAD | J15: =+'Necesidades Trimestrales'!H13 -> 860 | K15: =+'Necesidades Trimestrales'!G13 -> 15
A16: =+'Necesidades Trimestrales'!A14 -> 5 | B16: =+'Necesidades Trimestrales'!B14 -> 2.9.6-8875.277 | C16: =+'Necesidades Trimestrales'!E14 -> REP. Y ACC. P/EQUIPO MEDICO; USO: MESA DE ANESTESIA, MARCA EQUIPO: GENERAL ELECTRIC, ELEMENTO: CELDA DE OXIGENO, MODELO EQUIPO: AVANCE CS | H16: SI | I16: =+'Necesidades Trimestrales'!F14 -> UNIDAD | J16: =+'Necesidades Trimestrales'!H14 -> 39682.03 | K16: =+'Necesidades Trimestrales'!G14 -> 1
A17: =+'Necesidades Trimestrales'!A15 -> 6 | B17: =+'Necesidades Trimestrales'!B15 -> 2.9.6-8875.278 | C17: =+'Necesidades Trimestrales'!E15 -> REP. Y ACC. P/EQUIPO MEDICO; USO: RESPIRADOR, MARCA EQUIPO: MAQUET, ELEMENTO: CASSETE ESPIRATORIO, MODELO EQUIPO: SERVO I | H17: NO | I17: =+'Necesidades Trimestrales'!F15 -> UNIDAD | J17: =+'Necesidades Trimestrales'!H15 -> 452147 | K17: =+'Necesidades Trimestrales'!G15 -> 6
A18: =+'Necesidades Trimestrales'!A16 -> 7 | B18: =+'Necesidades Trimestrales'!B16 -> 2.9.6-8875.275 | C18: =+'Necesidades Trimestrales'!E16 -> REP Y ACC P/EQUIPO MEDICO; USO: INCUBADORA NEONATAL EQUIPO: MEDIX, MODELO EQUIPO: NATAL CARE ,ELEMENTO: BASE RODANTE CON RUEDAS | H18: SI | I18: =+'Necesidades Trimestrales'!F16 -> UNIDAD | J18: =+'Necesidades Trimestrales'!H16 -> 122750 | K18: =+'Necesidades Trimestrales'!G16 -> 20
A19: =+'Necesidades Trimestrales'!A17 -> 8 | B19: =+'Necesidades Trimestrales'!B17 -> 2.9.6-8875.282 | C19: =+'Necesidades Trimestrales'!E17 -> REP. Y ACC. P/EQUIPO MEDICO; USO: INCUBADORA NEONATAL, MARCA EQUIPO: MEDIX, ELEMENTO: SENSOR TEMPERATURA DE AIRE, MODELO EQUIPO: NATAL CARE | H19: NO | I19: =+'Necesidades Trimestrales'!F17 -> UNIDAD | J19: =+'Necesidades Trimestrales'!H17 -> 27125 | K19: =+'Necesidades Trimestrales'!G17 -> 6
A20: =+'Necesidades Trimestrales'!A18 -> 9 | B20: =+'Necesidades Trimestrales'!B18 -> 2.9.6-8875.283 | C20: =+'Necesidades Trimestrales'!E18 -> REP. Y ACC. P/EQUIPO MEDICO; USO: INCUBADORA NEONATAL, MARCA EQUIPO: MEDIX, ELEMENTO: MOTOR-TURBINA, MODELO EQUIPO: NATAL CARE | H20: NO | I20: =+'Necesidades Trimestrales'!F18 -> UNIDAD | J20: =+'Necesidades Trimestrales'!H18 -> 103500 | K20: =+'Necesidades Trimestrales'!G18 -> 20
A21: =+'Necesidades Trimestrales'!A19 -> 10 | B21: =+'Necesidades Trimestrales'!B19 -> 2.9.6-8875.285 | C21: =+'Necesidades Trimestrales'!E19 -> REP. Y ACC. P/EQUIPO MEDICO; USO: LUMINOTERAPIA, MARCA EQUIPO: MEDIX, ELEMENTO: CONTADOR DE HORAS, MODELO EQUIPO: MEDILED | H21: NO | I21: =+'Necesidades Trimestrales'!F19 -> UNIDAD | J21: =+'Necesidades Trimestrales'!H19 -> 19625 | K21: =+'Necesidades Trimestrales'!G19 -> 30
A22: Costo total estimado: OCHO MILLONES CIENTO SESENTA Y NUEVE MIL DOSCIENTOS CUARENTA Y CUATRO CON 03/100 | J22: =SUMPRODUCT(J12:J21,K12:K21) -> 8169244

Sheet Autor Gastar
A1: EJERCICIO: | D1: ='Necesidades Trimestrales'!C6 -> 2022 | P1: AUTORIZACION PARA GASTAR
A4: JURISDICCIÓN: | G4: =' NotaPedido'!D3 -> 40-Ministerio de Salud
A5: SAF: | G5: =' NotaPedido'!D4 -> 28- Maternidad Provincial 25 de Mayo
A6: UNIDAD EJECUTORA: | G6: =' NotaPedido'!D5 -> Direccion de Mantenimiento
A7: DEPENDENCIA SOLICITANTE: | G7: =' NotaPedido'!D6 -> Mantenimiento
A8: AUTORIZACIÓN:
A9: Señor Jefe de Servicio Administrativo Financiero:
A10: ="Autorizo la realización de los trámites correspondientes, a fin de proveer a este Organismo los bienes y/o servicios que se detallan en Nota de Pedido N° " & ' NotaPedido'!K1&", afectando la erogación resultante a los créditos presupuestarios aprobados a favor de esta Unidad Ejecutora, conforme al siguiente detalle:" -> Autorizo la realización de los trámites correspondientes, a fin de proveer a este Organismo los bienes y/o servicios que se detallan en Nota de Pedido N° /2020, afectando la erogación resultante a los créditos presupuestarios aprobados a favor de esta Unidad Ejecutora, conforme al siguiente detalle:
A12: IMPUTACIÓN PRESUPUESTARIA
A13: CÓDIGO | O13: DENOMINACIÓN DE LA PARTIDA PRESUPUESTARIA | Q13: IMPORTE
A14: PR | B14: SB | C14: PY | D14: AC | E14: OB | F14: UG | G14: FIN | H14: FUN | I14: I | J14: P | K14: P | L14: SubP | M14: M | N14: FF
A15: 42 | D15: 4 | F15: 4901 | G15: 3 | H15: 1 | I15: 2 | J15: 9 | K15: 6 | M15: 1 | N15: 1.1 | O15: Repuestos y Accesorios | Q15: 8169244
A26: TOTAL DE PESOS: OCHO MILLONES CIENTO SESENTA Y NUEVE MIL DOSCIENTOS CUARENTA Y CUATRO CON 03/100 | Q26: =SUM(Q15:Q25) -> 8169244
A28: JUSTIFICACIÓN:
A29: Para la adquisición de Repuestos y Accesorios, para ser destinados al equipamiento electromédico de los diferentes Servicios de la Maternidad Provincial 25 de Mayo.
