Workbook

Sheet NUTRICION NT
B2: Pedido de Necesidades Trimestrales
A4: JURISDICCION: | C4: 40 - Ministerio de Salud
A5: SAF N°: | C5: 23 - Hospital Interzonal San Juan Bautista
A6: EJERCICIO: | C6: 2021
A7: TRIMESTRE: | C7: 1
A9: ID | B9: CODIGO ITEM | C9: RUBRO DE COMPRA | D9: I.P.P. | E9: DESCRIPCION | F9: UNIDAD DE MEDIDA | G9: CANTIDAD | H9: PRECIO UNITARIO ESTIMADO | I9: IMPORTE TOTAL ESTIMADO
A10: 1 | B10: 2.1.1-439.60 | C10: ALIMENTOS | D10: 2.1.1 | E10: ACEITES COMESTIBLES; TIPO: MEZCLA, PRESENTACION: ENVASE X 900 CM3, MATERIAL ENVASE: PLASTICO 1 (PET), ELEM. TRANSPORTE: SIN, MATERIAL ELEM. TRANSPORTE : SIN, LIBRE DE GLUTEN: SI | F10: BOTELLA | G10: 500 | H10: 118.46 | I10: =G10*H10 -> 59230
A11: 2 | B11: 2.1.1-481.38 | C11: ALIMENTOS | D11: 2.1.1 | E11: AZUCARES; TIPO: "A" COMUN, ESTADO: MOLIDA, PESO: 1 Kg, MATERIAL ENVASE: PLASTICO, CERTIFICADO FORESTAL (GFS): SIN, ELEM. TRANSPORTE: SIN, MATERIAL ELEM. TRANSPORTE: SIN | F11: PAQUETES | G11: 800 | H11: 72 | I11: =G11*H11 -> 57600
A12: 3 | B12: 2.1.1-705.116 | C12: ALIMENTOS | D12: 2.1.1 | E12: LECHE; ESTADO: LIQUIDO, TIPO: DESCREMADA, PROCESO: LARGA VIDA, AGREGADO: VITAMINAS A Y D, PRESENTACION: ENVASE X 1 L, MATERIAL ENVASE: PLASTICO, ELEM. TRANSPORTE: SIN, MATERIAL ELEM. TRANSPORTE: SIN, CERTIFICADO FORESTAL (GFS): SIN, LIBRE DE GLUTEN: SIN VALOR | F12: LITROS | G12: 1200 | H12: 71.98 | I12: =G12*H12 -> 86376
A13: 4 | B13: 2.1.1-2868.55 | C13: ALIMENTOS | D13: 2.1.1 | E13: FIDEOS SECOS; VARIEDAD: TALLARIN, RELLENO: SIN, PRESENTACION: ENVASE X 500 GR, MATERIAL ENVASE: PLASTICO 1 (PET), ELEM. TRANSPORTE: SIN, MATERIAL ELEM. TRANSPORTE: SIN, CERTIFICADO FORESTAL (GFS): SIN, LIBRE DE GLUTEN: NO | F13: PAQUETES | G13: 50 | H13: 46.66 | I13: =G13*H13 -> 2333
A14: 5 | B14: 2.1.1-511.8 | C14: ALIMENTOS | D14: 2.1.1 | E14: TE; SAQUITOS 2G P/CAJA: 50, PESO: SIN VALOR, TIPO: SIN VALOR, PRESENTACION: EN SAQUITOS | F14: CAJAS | G14: 1300 | H14: 81.01 | I14: =G14*H14 -> 105313
A15: 6 | B15: 2.1.1-454.25 | C15: ALIMENTOS | D15: 2.1.1 | E15: YERBAS; PALO: CON, PESO: 1 Kg, MATERIAL ENVASE : PAPEL, CERTIFICADO FORESTAL (GFS): CON, ELEM. TRANSPORTE: SIN, MATERIAL ELEM. TRANSPORTE: SIN, LIBRE DE GLUTEN: SI | F15: PAQUETES | G15: 50 | H15: 226.8 | I15: =G15*H15 -> 11340
A16: 7 | B16: 2.1.1-2126.13 | C16: ALIMENTOS | D16: 2.1.1 | E16: SEMOLAS; TIPO: VITINA, PRESENTACION: BOLSA, PESO: 500 GR, MATERIAL ENVASE: PLASTICO 1 (PET), CERTICADO FORESTAL (GFS): SIN, LIBRE DE GLUTEN: NO | F16: PAQUETES | G16: 14 | H16: 102 | I16: =G16*H16 -> 1428
A17: 8 | B17: 2.1.1-2868.53 | C17: ALIMENTOS | D17: 2.1.1 | E17: FIDEOS SECOS; VARIEDAD: TIRABUZON, RELLENO: SIN, PRESENTACION: ENVASE X 500 GR, MATERIAL ENVASE: PLASTICO 1 (PET), ELEM. TRANSPORTE: SIN, MATERIAL ELEM. TRANSPORTE: SIN, CERTIFICADO FORESTAL (GFS): SIN, LIBRE DE GLUTEN: NO | F17: PAQUETES | G17: 84 | H17: 46.66 | I17: =G17*H17 -> 3919.44
A18: 9 | B18: 2.1.1-613.9 | C18: ALIMENTOS | D18: 2.1.1 | E18: FECULA DE MAIZ; ENVASE: BOLSA, PESO: 500 GR, LIBRE DE GLUTEN: SI | F18: PAQUETES | G18: 34 | H18: 94.79 | I18: =G18*H18 -> 3222.86
A19: 10 | B19: 2.1.1-6547.57 | C19: ALIMENTOS | D19: 2.1.1 | E19: LEGUMBRES; VARIEDAD: LENTEJAS SECAS, ESTADO: SECO, PRESENTACION: BOLSA, PESO: 500 GR | F19: PAQUETES | G19: 26 | H19: 118.04 | I19: =G19*H19 -> 3069.04
A20: 11 | B20: 2.1.1-514.2 | C20: ALIMENTOS | D20: 2.1.1 | E20: SAL DE MESA; CONSISTENCIA: FINA, PESO: 500 GR, TIPO: SIN VALOR, ENVASE: PAQUETE | F20: PAQUETES | G20: 65 | H20: 45.48 | I20: =G20*H20 -> 2956.2
A21: 12 | B21: 2.1.1-514.11 | C21: ALIMENTOS | D21: 2.1.1 | E21: SAL DE MESA; CONSISTENCIA: GRUESA, PESO: 50 Kg, TIPO: SIN VALOR, ENVASE: BOLSA | F21: BOLSAS | G21: 10 | H21: 2601 | I21: =G21*H21 -> 26010
... A100: 91 | B100: 2.1.1-455.16 | C100: ALIMENTOS | D100: 2.1.1 | E100: DULCE DE LECHE; ENVASE: DE CARTON, CAPACIDAD: 5000 GR, TIPO: DE REPOSTERIA, PRESENTACION: ENVASE DE CARTON X 5 Kg | F100: UNIDAD | G100: 3 | H100: 1068.54 | I100: =G100*H100 -> 3205.62
B103: Especificidades Item N° 6:
B105: Descripción técnica
C106: YERBA MATE X 1 KG NO MARCA LA HOJA
B107: Plazos y lugares de entrega
C108: Según necesidad de servicio - Servicio de Nutricion del HISJB
B110: Calidad Minima esperada
B112: Mantenimiento
C113: 90 dias habiles
B114: Garantia
B118: Especificidades Item N° 51:
B120: Descripción técnica
C121: ROSETAS SIN SAL DE 60 GRS CADA UNA
B122: Plazos y lugares de entrega
C123: Según necesidad de servicio - Servicio de Nutricion del HISJB
B125: Calidad Minima esperada
B127: Mantenimiento
C128: 90 dias habiles
B129: Garantia
B133: Especificidades Item N° 52:
B135: Descripción técnica
C136: PAN SALVADO DE 60 GRS C/U
...

Sheet NUTRICION NPYE 
A1: NOTA DE PEDIDO | J1: N° | K1: 372 - 2020
A3: JURISDICCIÓN: | D3: ='NUTRICION NT'!C4 -> 40 - Ministerio de Salud
A4: SAF: | D4: ='NUTRICION NT'!C5 -> 23 - Hospital Interzonal San Juan Bautista
A5: UNIDAD EJECUTORA: | D5: 168 - Direccion Asistencial
A6: DEPENDENCIA SOLICITANTE: | D6: Servicio de Nutrición
A7: PERIODO UTILIZACIÓN: | D7: ='NUTRICION NT'!C7 & "° Trimestre - Año " & 'NUTRICION NT'!C6 -> 1° Trimestre - Año 2021
A8: OBJETO: | D8: Adquisición de Alimentos Perecederos y no Perecederos
A10: Ítem | B10: Codigo Item | C10: DESCRIPCIÓN | H10: Adjunta Detalle Técnico | I10: Unidad Medida | J10: Precio Unitario Estimado | K10: Cantidad Solicitada
A12: 1 | B12: ='NUTRICION NT'!B10 -> 2.1.1-439.60 | C12: ='NUTRICION NT'!E10 -> ACEITES COMESTIBLES; TIPO: MEZCLA, PRESENTACION: ENVASE X 900 CM3, MATERIAL ENVASE: PLASTICO 1 (PET), ELEM. TRANSPORTE: SIN, MATERIAL ELEM. TRANSPORTE : SIN, LIBRE DE GLUTEN: SI | H12: NO | I12: ='NUTRICION NT'!F10 -> BOTELLA | J12: ='NUTRICION NT'!H10 -> 118.46 | K12: 500
A13: 2 | B13: ='NUTRICION NT'!B11 -> 2.1.1-481.38 | C13: ='NUTRICION NT'!E11 -> AZUCARES; TIPO: "A" COMUN, ESTADO: MOLIDA, PESO: 1 Kg, MATERIAL ENVASE: PLASTICO, CERTIFICADO FORESTAL (GFS): SIN, ELEM. TRANSPORTE: SIN, MATERIAL ELEM. TRANSPORTE: SIN | H13: NO | I13: ='NUTRICION NT'!F11 -> PAQUETES | J13: ='NUTRICION NT'!H11 -> 72 | K13: 800
A14: 3 | B14: ='NUTRICION NT'!B12 -> 2.1.1-705.116 | C14: ='NUTRICION NT'!E12 -> LECHE; ESTADO: LIQUIDO, TIPO: DESCREMADA, PROCESO: LARGA VIDA, AGREGADO: VITAMINAS A Y D, PRESENTACION: ENVASE X 1 L, MATERIAL ENVASE: PLASTICO, ELEM. TRANSPORTE: SIN, MATERIAL ELEM. TRANSPORTE: SIN, CERTIFICADO FORESTAL (GFS): SIN, LIBRE DE GLUTEN: SIN VALOR | H14: NO | I14: ='NUTRICION NT'!F12 -> LITROS | J14: ='NUTRICION NT'!H12 -> 71.98 | K14: 1200
A15: 4 | B15: ='NUTRICION NT'!B13 -> 2.1.1-2868.55 | C15: ='NUTRICION NT'!E13 -> FIDEOS SECOS; VARIEDAD: TALLARIN, RELLENO: SIN, PRESENTACION: ENVASE X 500 GR, MATERIAL ENVASE: PLASTICO 1 (PET), ELEM. TRANSPORTE: SIN, MATERIAL ELEM. TRANSPORTE: SIN, CERTIFICADO FORESTAL (GFS): SIN, LIBRE DE GLUTEN: NO | H15: NO | I15: ='NUTRICION NT'!F13 -> PAQUETES | J15: ='NUTRICION NT'!H13 -> 46.66 | K15: 50
A16: 5 | B16: ='NUTRICION NT'!B14 -> 2.1.1-511.8 | C16: ='NUTRICION NT'!E14 -> TE; SAQUITOS 2G P/CAJA: 50, PESO: SIN VALOR, TIPO: SIN VALOR, PRESENTACION: EN SAQUITOS | H16: NO | I16: ='NUTRICION NT'!F14 -> CAJAS | J16: ='NUTRICION NT'!H14 -> 81.01 | K16: 1300
A17: 6 | B17: ='NUTRICION NT'!B15 -> 2.1.1-454.25 | C17: ='NUTRICION NT'!E15 -> YERBAS; PALO: CON, PESO: 1 Kg, MATERIAL ENVASE : PAPEL, CERTIFICADO FORESTAL (GFS): CON, ELEM. TRANSPORTE: SIN, MATERIAL ELEM. TRANSPORTE: SIN, LIBRE DE GLUTEN: SI | H17: NO | I17: ='NUTRICION NT'!F15 -> PAQUETES | J17: ='NUTRICION NT'!H15 -> 226.8 | K17: 50
A18: 7 | B18: ='NUTRICION NT'!B16 -> 2.1.1-2126.13 | C18: ='NUTRICION NT'!E16 -> SEMOLAS; TIPO: VITINA, PRESENTACION: BOLSA, PESO: 500 GR, MATERIAL ENVASE: PLASTICO 1 (PET), CERTICADO FORESTAL (GFS): SIN, LIBRE DE GLUTEN: NO | H18: NO | I18: ='NUTRICION NT'!F16 -> PAQUETES | J18: ='NUTRICION NT'!H16 -> 102 | K18: 14
A19: 8 | B19: ='NUTRICION NT'!B17 -> 2.1.1-2868.53 | C19: ='NUTRICION NT'!E17 -> FIDEOS SECOS; VARIEDAD: TIRABUZON, RELLENO: SIN, PRESENTACION: ENVASE X 500 GR, MATERIAL ENVASE: PLASTICO 1 (PET), ELEM. TRANSPORTE: SIN, MATERIAL ELEM. TRANSPORTE: SIN, CERTIFICADO FORESTAL (GFS): SIN, LIBRE DE GLUTEN: NO | H19: NO | I19: ='NUTRICION NT'!F17 -> PAQUETES | J19: ='NUTRICION NT'!H17 -> 46.66 | K19: 84
A20: 9 | B20: ='NUTRICION NT'!B18 -> 2.1.1-613.9 | C20: ='NUTRICION NT'!E18 -> FECULA DE MAIZ; ENVASE: BOLSA, PESO: 500 GR, LIBRE DE GLUTEN: SI | H20: NO | I20: ='NUTRICION NT'!F18 -> PAQUETES | J20: ='NUTRICION NT'!H18 -> 94.79 | K20: 34
A21: 10 | B21: ='NUTRICION NT'!B19 -> 2.1.1-6547.57 | C21: ='NUTRICION NT'!E19 -> LEGUMBRES; VARIEDAD: LENTEJAS SECAS, ESTADO: SECO, PRESENTACION: BOLSA, PESO: 500 GR | H21: NO | I21: ='NUTRICION NT'!F19 -> PAQUETES | J21: ='NUTRICION NT'!H19 -> 118.04 | K21: 26
A22: 11 | B22: ='NUTRICION NT'!B20 -> 2.1.1-514.2 | C22: ='NUTRICION NT'!E20 -> SAL DE MESA; CONSISTENCIA: FINA, PESO: 500 GR, TIPO: SIN VALOR, ENVASE: PAQUETE | H22: NO | I22: ='NUTRICION NT'!F20 -> PAQUETES | J22: ='NUTRICION NT'!H20 -> 45.48 | K22: 65
A23: 12 | B23: ='NUTRICION NT'!B21 -> 2.1.1-514.11 | C23: ='NUTRICION NT'!E21 -> SAL DE MESA; CONSISTENCIA: GRUESA, PESO: 50 Kg, TIPO: SIN VALOR, ENVASE: BOLSA | H23: NO | I23: ='NUTRICION NT'!F21 -> BOLSAS | J23: ='NUTRICION NT'!H21 -> 2601 | K23: 10
... A102: 91 | B102: ='NUTRICION NT'!B100 -> 2.1.1-455.16 | C102: ='NUTRICION NT'!E100 -> DULCE DE LECHE; ENVASE: DE CARTON, CAPACIDAD: 5000 GR, TIPO: DE REPOSTERIA, PRESENTACION: ENVASE DE CARTON X 5 Kg | H102: NO | I102: ='NUTRICION NT'!F100 -> UNIDAD | J102: ='NUTRICION NT'!H100 -> 1068.54 | K102: 3
A103: Costo total estimado: cuatro millones quinientos noventa y ocho mil treinta y dos con 77/100.------------- | J103: =SUMPRODUCT(J12:J102,K12:K102) -> 4598032.8

Sheet NUTRICION APG 
A1: EJERCICIO: | D1: ='[1]Necesidades Trimestrales'!C6 -> 2021 | P1: AUTORIZACION PARA GASTAR
A4: JURISDICCIÓN: | G4: ='NUTRICION NT'!C4 -> 40 - Ministerio de Salud
A5: SAF: | G5: ='NUTRICION NT'!C5 -> 23 - Hospital Interzonal San Juan Bautista
A6: UNIDAD EJECUTORA: | G6: ='NUTRICION NPYE '!D5 -> 168 - Direccion Asistencial
A7: DEPENDENCIA SOLICITANTE: | G7: ='NUTRICION NPYE '!D6 -> Servicio de Nutrición
A8: AUTORIZACIÓN:
A9: Señor Jefe de Servicio Administrativo Financiero:
A10: ="Autorizo la realización de los trámites correspondientes, a fin de proveer a este Organismo los bienes y/o servicios que se detallan en Nota de Pedido N° " & '[2]NUTRICION NPYE '!K1&", afectando la erogación resultante a los créditos presupuestarios aprobados a favor de esta Unidad Ejecutora, conforme al siguiente detalle:" -> Autorizo la realización de los trámites correspondientes, a fin de proveer a este Organismo los bienes y/o servicios que se detallan en Nota de Pedido N° 372 - 2020, afectando la erogación resultante a los créditos presupuestarios aprobados a favor de esta Unidad Ejecutora, conforme al siguiente detalle:
A12: IMPUTACIÓN PRESUPUESTARIA
A13: CÓDIGO | O13: DENOMINACIÓN DE LA PARTIDA PRESUPUESTARIA | Q13: IMPORTE
A14: PR | B14: SB | C14: PY | D14: AC | E14: OB | F14: UG | G14: FIN | H14: FUN | I14: I | J14: P | K14: P | L14: SubP | M14: M | N14: FF
A15: 33 | D15: 2 | F15: 4901 | G15: 3 | H15: 3.1 | I15: 2 | J15: 1 | K15: 1 | M15: 1 | N15: 1.1 | O15: Alimentos para Personas | Q15: 4598032.8
A23: TOTAL DE PESOS: CUATRO MILLONES QUINIENTOS NOVENTA Y OCHO MIL TREINTA Y DOS CON 77/100.-- | Q23: =SUM(Q15:Q22) -> 4598032.8
A25: JUSTIFICACIÓN:
A26: ="Para la "& '[2]NUTRICION NPYE '!D8 &" para ser destinados al " & '[2]NUTRICION NPYE '!D6 &" del HISJB del Ministerio de Salud." -> Para la Adquisición de Alimentos Perecederos y no Perecederos para ser destinados al Servicio de Nutrición del HISJB del Ministerio de Salud.
