Workbook

Sheet SAF 011
A1: 2022
B2: Pedido de Necesidades Trimestrales
A4: JURISDICCION: | C4: 040 - MINISTERIO DE SALUD
A5: SAF N°: | C5: 011 - DIRECCION PROVINCIAL DE ADMINISTRACION - MINISTERIO DE SALUD
A6: EJERCICIO: | C6: 2022
A7: TRIMESTRE: | C7: PRIMERO
A9: ID | B9: CODIGO ITEM | C9: RUBRO DE COMPRA | D9: I.P.P. | E9: DESCRIPCION | F9: UNIDAD DE MEDIDA | G9: CANTIDAD TOTAL | H9: PRECIO UNITARIO ESTIMADO | I9: IMPORTE TOTAL ESTIMADO | J9: ESPECIFICACION TECNICA
A10: 1 | C10: PROD. MEDICO/FARMACEUTICOS/LAB. | D10: 2.5.1 | E10: ACEITE DE INMERSION PA 100 ML Tipo CICARELLI | F10: FRASCO | G10: 10 | H10: 3419 | I10: =+G10*H10 -> 34190
A11: 2 | C11: PROD. MEDICO/FARMACEUTICOS/LAB. | D11: 2.5.1 | E11: ACTIVADOR caja por 9 bidones X 12 ML COBAS C311 TIPO ROCHE | F11: CAJA | G11: 2 | H11: 18758 | I11: =+G11*H11 -> 37516
A12: 3 | C12: PROD. MEDICO/FARMACEUTICOS/LAB. | D12: 2.5.1. | E12: AGUA BIDESTILADA X 5 LITROS | F12: BIDON | G12: 10 | H12: 574 | I12: =+G12*H12 -> 5740
A13: 4 | C13: PROD. MEDICO/FARMACEUTICOS/LAB. | D13: 2.5.1 | E13: ALB2 (ALBUMINA) COBAS C311 tipo ROCHE | F13: UNIDAD | G13: 5 | H13: 2452 | I13: =+G13*H13 -> 12260
A14: 5 | C14: PROD. MEDICO/FARMACEUTICOS/LAB. | D14: 2.5.1 | E14: ALBUMINA AA 120 ML Tipo WIENER | F14: UNIDAD | G14: 15 | H14: 745 | I14: =+G14*H14 -> 11175
A15: 6 | C15: PROD. MEDICO/FARMACEUTICOS/LAB. | D15: 2.5.1. | E15: ALBUMINA BOVINA TIPO WIENER | F15: UNIDAD | G15: 12 | H15: 1251 | I15: =+G15*H15 -> 15012
A16: 7 | C16: PROD. MEDICO/FARMACEUTICOS/LAB. | D16: 2.5.1 | E16: ALP2L (F. ALCALINA) C311 ROCHE | F16: UNIDAD | G16: 8 | H16: 10621 | I16: =+G16*H16 -> 84968
A17: 8 | C17: PROD. MEDICO/FARMACEUTICOS/LAB. | D17: 2.5.1 | E17: ANTI A MONOCLONAL FRASCO X 10 ML Tipo WIENER | F17: FRASCO | G17: 130 | H17: 1328 | I17: =+G17*H17 -> 172640
A18: 9 | C18: PROD. MEDICO/FARMACEUTICOS/LAB. | D18: 2.5.1 | E18: ANTI B MONOCLONAL FRASCO X 10 ML Tipo WIENER | F18: FRASCO | G18: 120 | H18: 1328 | I18: =+G18*H18 -> 159360
A19: 10 | C19: PROD. MEDICO/FARMACEUTICOS/LAB. | D19: 2.5.1. | E19: ANTI-AB MONOCLONAL- FRASCO 10 ML TIPO WIENER | F19: FRASCO | G19: 100 | H19: 888 | I19: =+G19*H19 -> 88800
A20: 11 | C20: PROD. MEDICO/FARMACEUTICOS/LAB. | D20: 2.5.1 | E20: ANTICOAGULANTE TP (CITRATO) 6 X 50 ML Tipo WIENER | F20: FRASCO | G20: 20 | H20: 973 | I20: =+G20*H20 -> 19460
A21: 12 | C21: PROD. MEDICO/FARMACEUTICOS/LAB. | D21: 2.5.1 | E21: ANTID (RHO) MONOCLONAL FRASCO X 10 ML Tipo WIENER | F21: FRASCO | G21: 120 | H21: 2512 | I21: =+G21*H21 -> 301440
... A146: 137 | C146: PROD. MEDICO/FARMACEUTICOS/LAB. | D146: 2.5.1 | E146: XN-CHECK CONTROL ALTO-MEDIO-BAJO (XN-550/1000) (CAJA 12X3.0 ML) TIPO SYSMEX | F146: CAJA | G146: 1 | H146: 93477 | I146: =+G146*H146 -> 93477
E147: TOTAL RUBRO REACTIVOS PARA LABORATORIO | I147: =SUM(I10:I146) -> 86666931
C149: DETALLE TECNICO Y ESPECIFICACIONES | D149: ANEXO 1-Para oferentes de la Provincia de Catamarca deberán presentar Habilitación Provincial para comercializar el producto que cotizan. 2-Para el resto de oferentes deberán presentar Certificado de Inscripción de ANMAT vigente al momento de la oferta, el mismo deberá ser correspondiente al objeto de la contratación y de encontrarse vencido adjuntar la solicitud de renovación. 3-No se aceptarán ofertas de productos no registrados y autorizada su venta por ANMAT. Se deberá especificar en cada ítem de la propuesta, marca y número de certificado otorgado por dicho ente regulador. 4-Los productos deberán tener un vencimiento posterior a doce (12) meses a partir de la fecha de su recepción.
C151: Plazos de entrega | D151: veinte (20) dias habiles
C153: Lugar de Entrega: | D153: DIR. PROV. DE LABORATORIO - CHACABUCO N° 169 - en el horario de 8:00hs a 12:00hs de lunes a viernes
C155: Calidad Minima esperada
C157: Mantenimiento | D157: cuarenta y cinco (45) días

Sheet NP LABORATORIO
A1: NOTA DE PEDIDO | J1: N° | K1: 03/2022
A3: JURISDICCIÓN: | D3: ='SAF 011'!C4 -> 040 - MINISTERIO DE SALUD
A4: SAF: | D4: ='SAF 011'!C5 -> 011 - DIRECCION PROVINCIAL DE ADMINISTRACION - MINISTERIO DE SALUD
A5: UNIDAD EJECUTORA: | D5: DIRECCION PROVINCIAL DE LABORATORIO
A6: DEPENDENCIA SOLICITANTE: | D6: DIRECCION PROVINCIAL DE LABORATORIO
A7: PERIODO UTILIZACIÓN: | D7: 1° TRIMESTRE 2022
A8: OBJETO: | D8: ADQUISICION DEL RUBRO REACTIVOS PARA LABORATORIO
A10: Ítem | B10: Codigo Item | C10: DESCRIPCIÓN | H10: Adjunta Detalle Técnico | I10: Unidad Medida | J10: Precio Unitario Estimado | K10: Cantidad Solicitada
A12: 1 | C12: ='SAF 011'!E10 -> ACEITE DE INMERSION PA 100 ML Tipo CICARELLI | H12: NO | I12: ='SAF 011'!F10 -> FRASCO | J12: ='SAF 011'!H10 -> 3419 | K12: ='SAF 011'!#REF! -> #REF! | M12: =+J12*K12 -> #REF!
A13: 2 | C13: ='SAF 011'!E11 -> ACTIVADOR caja por 9 bidones X 12 ML COBAS C311 TIPO ROCHE | H13: NO | I13: ='SAF 011'!F11 -> CAJA | J13: ='SAF 011'!H11 -> 18758 | K13: ='SAF 011'!#REF! -> #REF! | M13: =+J13*K13 -> #REF!
A14: 4 | C14: ='SAF 011'!E13 -> ALB2 (ALBUMINA) COBAS C311 tipo ROCHE | H14: NO | I14: ='SAF 011'!F13 -> UNIDAD | J14: ='SAF 011'!H13 -> 2452 | K14: ='SAF 011'!#REF! -> #REF! | M14: =+J14*K14 -> #REF!
A15: 5 | C15: ='SAF 011'!E14 -> ALBUMINA AA 120 ML Tipo WIENER | H15: NO | I15: ='SAF 011'!F14 -> UNIDAD | J15: ='SAF 011'!H14 -> 745 | K15: ='SAF 011'!#REF! -> #REF! | M15: =+J15*K15 -> #REF!
A16: 7 | C16: ='SAF 011'!E16 -> ALP2L (F. ALCALINA) C311 ROCHE | H16: NO | I16: ='SAF 011'!F16 -> UNIDAD | J16: ='SAF 011'!H16 -> 10621 | K16: ='SAF 011'!#REF! -> #REF! | M16: =+J16*K16 -> #REF!
A17: 8 | C17: ='SAF 011'!E17 -> ANTI A MONOCLONAL FRASCO X 10 ML Tipo WIENER | H17: NO | I17: ='SAF 011'!F17 -> FRASCO | J17: ='SAF 011'!H17 -> 1328 | K17: ='SAF 011'!#REF! -> #REF! | M17: =+J17*K17 -> #REF!
A18: 9 | C18: ='SAF 011'!E18 -> ANTI B MONOCLONAL FRASCO X 10 ML Tipo WIENER | H18: NO | I18: ='SAF 011'!F18 -> FRASCO | J18: ='SAF 011'!H18 -> 1328 | K18: ='SAF 011'!#REF! -> #REF! | M18: =+J18*K18 -> #REF!
A19: 11 | C19: ='SAF 011'!E20 -> ANTICOAGULANTE TP (CITRATO) 6 X 50 ML Tipo WIENER | H19: NO | I19: ='SAF 011'!F20 -> FRASCO | J19: ='SAF 011'!H20 -> 973 | K19: ='SAF 011'!#REF! -> #REF! | M19: =+J19*K19 -> #REF!
A20: 12 | C20: ='SAF 011'!E21 -> ANTID (RHO) MONOCLONAL FRASCO X 10 ML Tipo WIENER | H20: NO | I20: ='SAF 011'!F21 -> FRASCO | J20: ='SAF 011'!H21 -> 2512 | K20: ='SAF 011'!#REF! -> #REF! | M20: =+J20*K20 -> #REF!
A21: 13 | C21: ='SAF 011'!E22 -> ANTIGENO FEBRIL BRUCELLA (HUDDLESON) 1X5 ML Tipo WIENER | H21: NO | I21: ='SAF 011'!F22 -> BOLSA | J21: ='SAF 011'!H22 -> 1795 | K21: ='SAF 011'!#REF! -> #REF! | M21: =+J21*K21 -> #REF!
A22: 14 | C22: ='SAF 011'!E23 -> APTTEST 6X25 ML (150 DET) Tipo WIENER | H22: NO | I22: ='SAF 011'!F23 -> CAJA | J22: ='SAF 011'!H23 -> 8286 | K22: ='SAF 011'!#REF! -> #REF! | M22: =+J22*K22 -> #REF!
A23: 25 | C23: ='SAF 011'!E34 -> ASO LATEX 50 DET Tipo WIENER | H23: NO | I23: ='SAF 011'!F34 -> UNIDAD | J23: ='SAF 011'!H34 -> 5347 | K23: ='SAF 011'!#REF! -> #REF! | M23: =+J23*K23 -> #REF!
A24: 26 | C24: ='SAF 011'!E35 -> BILIRRUBINA STANDARD 2 FRASCOS X 5 ML Tipo WIENER | H24: NO | I24: ='SAF 011'!F35 -> CAJA | J24: ='SAF 011'!H35 -> 5155 | K24: ='SAF 011'!#REF! -> #REF! | M24: =+J24*K24 -> #REF!
A25: 30 | C25: ='SAF 011'!E39 -> CA COLOR ARSENAZO III AA 200 ML (4X50 ML) Tipo WIENER | H25: NO | I25: ='SAF 011'!F39 -> CAJA | J25: ='SAF 011'!H39 -> 3471 | K25: ='SAF 011'!#REF! -> #REF! | M25: =+J25*K25 -> #REF!
A26: 31 | C26: ='SAF 011'!E40 -> CA2 (CALCIO) C311 tipo ROCHE | H26: NO | I26: ='SAF 011'!F40 -> CASSETTE | J26: ='SAF 011'!H40 -> 5050 | K26: ='SAF 011'!#REF! -> #REF! | M26: =+J26*K26 -> #REF!
A27: 32 | C27: ='SAF 011'!E41 -> CALIBRADOR A PLUS 2 VIAL X 3 ML Tipo WIENER | H27: NO | I27: ='SAF 011'!F41 -> UNIDAD | J27: ='SAF 011'!H41 -> 5338 | K27: ='SAF 011'!#REF! -> #REF! | M27: =+J27*K27 -> #REF!
A28: 33 | C28: ='SAF 011'!E42 -> CASSETTE CALIBRADOR HEMOGLOBINA GLICOSILADA 1 U Tipo OPTI MEDICAL (USA) | H28: NO | I28: ='SAF 011'!F42 -> CASSETTE | J28: ='SAF 011'!H42 -> 14550 | K28: ='SAF 011'!#REF! -> #REF! | M28: =+J28*K28 -> #REF!
A29: 34 | C29: ='SAF 011'!E43 -> CASSETTE E-CL X 25 TEST TIPO OPTI MEDICAL | H29: NO | I29: ='SAF 011'!F43 -> CASSETTE | J29: ='SAF 011'!H43 -> 52464.5 | K29: ='SAF 011'!#REF! -> #REF! | M29: =+J29*K29 -> #REF!
A30: 36 | C30: ='SAF 011'!E45 -> CELL WASH SOLUTION 1 (NAOH-D BASIC WASH 1 BIDON 2X1800 ML) COBAS C311 TIPO ROCHE | H30: NO | I30: ='SAF 011'!F45 -> CAJA | J30: ='SAF 011'!H45 -> 7151 | K30: ='SAF 011'!#REF! -> #REF! | M30: =+J30*K30 -> #REF!
A31: 37 | C31: ='SAF 011'!E46 -> CELL WASH SOLUTION 2 (ACID WASH) (2X1800 ML) COBAS C311 TIPO ROCHE | H31: NO | I31: ='SAF 011'!F46 -> CAJA | J31: ='SAF 011'!H46 -> 41462 | K31: ='SAF 011'!#REF! -> #REF! | M31: =+J31*K31 -> #REF!
A32: 38 | C32: ='SAF 011'!E47 -> CELLPACK DCL (XN-550/1000) 20 LITROS TIPO SYSMEX | H32: NO | I32: ='SAF 011'!F47 -> UNIDAD | J32: ='SAF 011'!H47 -> 13303 | K32: ='SAF 011'!#REF! -> #REF! | M32: =+J32*K32 -> #REF!
A33: 39 | C33: ='SAF 011'!E48 -> CFAS LIPIDS (3X1 ML) COBAS C 311 TIPO ROCHE | H33: NO | I33: ='SAF 011'!F48 -> VIAL | J33: ='SAF 011'!H48 -> 43337 | K33: ='SAF 011'!#REF! -> #REF! | M33: =+J33*K33 -> #REF!
A34: 41 | C34: ='SAF 011'!E50 -> CHAGATEST ELISA RECOMBINANTE (V 4.0) 96 DET Tipo WIENER | H34: NO | I34: ='SAF 011'!F50 -> UNIDAD | J34: ='SAF 011'!H50 -> 17121 | K34: ='SAF 011'!#REF! -> #REF! | M34: =+J34*K34 -> #REF!
A35: 42 | C35: ='SAF 011'!E51 -> CHAGATEST HAI 5 TITULOS 96 DET Tipo WIENER | H35: NO | I35: ='SAF 011'!F51 -> UNIDAD | J35: ='SAF 011'!H51 -> 16429 | K35: ='SAF 011'!#REF! -> #REF! | M35: =+J35*K35 -> #REF!
A36: 43 | C36: ='SAF 011'!E52 -> CHOL2 (COLESTEROL) C311 tipo ROCHE | H36: NO | I36: ='SAF 011'!F52 -> UNIDAD | J36: ='SAF 011'!H52 -> 5050 | K36: ='SAF 011'!#REF! -> #REF! | M36: =+J36*K36 -> #REF!
A37: 44 | C37: ='SAF 011'!E53 -> CK MB2 (CPK MB) C311 tipo ROCHE | H37: NO | I37: ='SAF 011'!F53 -> UNIDAD | J37: ='SAF 011'!H53 -> 6358 | K37: ='SAF 011'!#REF! -> #REF! | M37: =+J37*K37 -> #REF!
A38: 45 | C38: ='SAF 011'!E54 -> CLOT CATCHER CAJA X 250 UN COBAS B221 TIPO ROCHE | H38: NO | I38: ='SAF 011'!F54 -> CAJA | J38: ='SAF 011'!H54 -> 2121 | K38: ='SAF 011'!#REF! -> #REF! | M38: =+J38*K38 -> #REF!
A39: 47 | C39: ='SAF 011'!E56 -> COBAS CKNAC X 200 DET TIPO ROCHE | H39: NO | I39: ='SAF 011'!F56 -> CASETTE | J39: ='SAF 011'!H56 -> 4204 | K39: ='SAF 011'!#REF! -> #REF! | M39: =+J39*K39 -> #REF!
A40: 48 | C40: ='SAF 011'!E57 -> COL-HDL C311 tipo ROCHE | H40: NO | I40: ='SAF 011'!F57 -> UNIDAD | J40: ='SAF 011'!H57 -> 22148 | K40: ='SAF 011'!#REF! -> #REF! | M40: =+J40*K40 -> #REF!
A41: 49 | C41: ='SAF 011'!E58 -> COL-LDL C311 tipo ROCHE | H41: NO | I41: ='SAF 011'!F58 -> UNIDAD | J41: ='SAF 011'!H58 -> 19934 | K41: ='SAF 011'!#REF! -> #REF! | M41: =+J41*K41 -> #REF!
A42: 50 | C42: ='SAF 011'!E59 -> COLORANTE GIEMSA 1 LITRO Tipo BIOPACK | H42: NO | I42: ='SAF 011'!F59 -> BOTELLA | J42: ='SAF 011'!H59 -> 4661 | K42: ='SAF 011'!#REF! -> #REF! | M42: =+J42*K42 -> #REF!
A43: 51 | C43: ='SAF 011'!E60 -> COMBITROL PLUS B LEVEL 1 CAJA X 30 UN COBAS B 221 TIPO ROCHE | H43: NO | I43: ='SAF 011'!F60 -> CAJA | J43: ='SAF 011'!H60 -> 26023 | K43: ='SAF 011'!#REF! -> #REF! | M43: =+J43*K43 -> #REF!
...

Sheet APG LABORATORIO
A1: EJERCICIO: | D1: 2022 | P1: AUTORIZACION PARA GASTAR
A4: JURISDICCIÓN: | G4: ='NP LABORATORIO'!D3 -> 040 - MINISTERIO DE SALUD
A5: SAF: | G5: ='NP LABORATORIO'!D4 -> 011 - DIRECCION PROVINCIAL DE ADMINISTRACION - MINISTERIO DE SALUD
A6: UNIDAD EJECUTORA: | G6: ='NP LABORATORIO'!D5 -> DIRECCION PROVINCIAL DE LABORATORIO
A7: DEPENDENCIA SOLICITANTE: | G7: ='NP LABORATORIO'!D6 -> DIRECCION PROVINCIAL DE LABORATORIO
A8: AUTORIZACIÓN:
A9: Señor Director de Administración o Titular del Servicio Administrativo Financiero:
A10: Autorizo la realización de los trámites correspondientes, a fin de proveer a este Organismo los bienes/servicios que se detallan en Nota de Pedido N° 03/2022 afectando la erogación resultante a los créditos presupuestarios aprobados a favor de esta Unidad Ejecutora, conforme al siguiente detalle:
A12: IMPUTACIÓN PRESUPUESTARIA
A13: CÓDIGO | O13: DENOMINACIÓN DE LA PARTIDA PRESUPUESTARIA | Q13: IMPORTE
A14: PR | B14: SB | C14: PY | D14: AC | E14: OB | F14: UG | G14: FIN | H14: FUN | I14: I | J14: P | K14: P | L14: SubP | M14: M | N14: FF
A15: 62 | D15: 1 | F15: 4901 | G15: 3 | H15: 1 | I15: 2 | J15: 5 | K15: 1 | M15: 1 | N15: 1.1 | O15: COMPUESTOS QUIMICOS | Q15: ='NP LABORATORIO'!M105 -> #REF!
A38: TOTAL DE PESOS: SETENTA Y UN MILLONES TRESCIENTOS CINCUENTA Y CUATRO MIL SETECIENTOS VEINTICUATRO CON 50/100.- | Q38: =SUM(Q15:Q37) -> #REF!
A40: JUSTIFICACIÓN:
A41: ='NP LABORATORIO'!D8 -> ADQUISICION DEL RUBRO REACTIVOS PARA LABORATORIO

Sheet NP BANCO DE SANGRE
A1: NOTA DE PEDIDO | J1: N° | K1: 04/2022
A3: JURISDICCIÓN: | D3: ='SAF 011'!C4 -> 040 - MINISTERIO DE SALUD
A4: SAF: | D4: ='SAF 011'!C5 -> 011 - DIRECCION PROVINCIAL DE ADMINISTRACION - MINISTERIO DE SALUD
A5: UNIDAD EJECUTORA: | D5: DIRECCION PROVINCIAL BANCO DE SANGRE
A6: DEPENDENCIA SOLICITANTE: | D6: DIRECCION PROVINCIAL BANCO DE SANGRE
A7: PERIODO UTILIZACIÓN: | D7: 1° TRIMESTRE 2022
A8: OBJETO: | D8: ADQUISICION DEL RUBRO REACTIVOS PARA LABORATORIO
A10: Ítem | B10: Codigo Item | C10: DESCRIPCIÓN | H10: Adjunta Detalle Técnico | I10: Unidad Medida | J10: Precio Unitario Estimado | K10: Cantidad Solicitada
A12: 1 | C12: ='SAF 011'!E15 -> ALBUMINA BOVINA TIPO WIENER | H12: NO | I12: ='SAF 011'!F15 -> UNIDAD | J12: ='SAF 011'!H15 -> 1251 | K12: ='SAF 011'!#REF! -> #REF! | M12: =+J12*K12 -> #REF!
A13: 2 | C13: ='SAF 011'!E16 -> ALP2L (F. ALCALINA) C311 ROCHE | H13: NO | I13: ='SAF 011'!F16 -> UNIDAD | J13: ='SAF 011'!H16 -> 10621 | K13: ='SAF 011'!#REF! -> #REF! | M13: =+J13*K13 -> #REF!
A14: 3 | C14: ='SAF 011'!E17 -> ANTI A MONOCLONAL FRASCO X 10 ML Tipo WIENER | H14: NO | I14: ='SAF 011'!F17 -> FRASCO | J14: ='SAF 011'!H17 -> 1328 | K14: ='SAF 011'!#REF! -> #REF! | M14: =+J14*K14 -> #REF!
A15: 4 | C15: ='SAF 011'!E18 -> ANTI B MONOCLONAL FRASCO X 10 ML Tipo WIENER | H15: NO | I15: ='SAF 011'!F18 -> FRASCO | J15: ='SAF 011'!H18 -> 1328 | K15: ='SAF 011'!#REF! -> #REF! | M15: =+J15*K15 -> #REF!
A16: 5 | C16: ='SAF 011'!E19 -> ANTI-AB MONOCLONAL- FRASCO 10 ML TIPO WIENER | H16: NO | I16: ='SAF 011'!F19 -> FRASCO | J16: ='SAF 011'!H19 -> 888 | K16: ='SAF 011'!#REF! -> #REF! | M16: =+J16*K16 -> #REF!
A17: 6 | C17: ='SAF 011'!E21 -> ANTID (RHO) MONOCLONAL FRASCO X 10 ML Tipo WIENER | H17: NO | I17: ='SAF 011'!F21 -> FRASCO | J17: ='SAF 011'!H21 -> 2512 | K17: ='SAF 011'!#REF! -> #REF! | M17: =+J17*K17 -> #REF!
A18: 7 | C18: ='SAF 011'!E22 -> ANTIGENO FEBRIL BRUCELLA (HUDDLESON) 1X5 ML Tipo WIENER | H18: NO | I18: ='SAF 011'!F22 -> BOLSA | J18: ='SAF 011'!H22 -> 1795 | K18: ='SAF 011'!#REF! -> #REF! | M18: =+J18*K18 -> #REF!
A19: 8 | C19: ='SAF 011'!E36 -> Biozima chagas recombinante x 192 Determinaciones. Tipo Wiener | H19: NO | I19: ='SAF 011'!F36 -> CAJA | J19: ='SAF 011'!H36 -> 11502.26 | K19: ='SAF 011'!#REF! -> #REF! | M19: =+J19*K19 -> #REF!
A20: 9 | C20: ='SAF 011'!E37 -> Biozima chagas x 192 Determinaciones. Tipo Wiener | H20: NO | I20: ='SAF 011'!F37 -> CAJA | J20: ='SAF 011'!H37 -> 10577.85 | K20: ='SAF 011'!#REF! -> #REF! | M20: =+J20*K20 -> #REF!
A21: 10 | C21: ='SAF 011'!E38 -> Buffer Tipo Wiener | H21: NO | I21: ='SAF 011'!F38 -> CAJA | J21: ='SAF 011'!H38 -> 8300 | K21: ='SAF 011'!#REF! -> #REF! | M21: =+J21*K21 -> #REF!
A22: 11 | C22: ='SAF 011'!E44 -> Celdas de Reaccion Tipo Wiener | H22: NO | I22: ='SAF 011'!F44 -> CAJA | J22: ='SAF 011'!H44 -> 11685 | K22: ='SAF 011'!#REF! -> #REF! | M22: =+J22*K22 -> #REF!
A23: 12 | C23: ='SAF 011'!E49 -> Chagatest Elisa Lisado 96 determinaciones Tipo WIENER | H23: NO | I23: ='SAF 011'!F49 -> EQUIPO | J23: ='SAF 011'!H49 -> 12000 | K23: ='SAF 011'!#REF! -> #REF! | M23: =+J23*K23 -> #REF!
A24: 13 | C24: ='SAF 011'!E50 -> CHAGATEST ELISA RECOMBINANTE (V 4.0) 96 DET Tipo WIENER | H24: NO | I24: ='SAF 011'!F50 -> UNIDAD | J24: ='SAF 011'!H50 -> 17121 | K24: ='SAF 011'!#REF! -> #REF! | M24: =+J24*K24 -> #REF!
A25: 14 | C25: ='SAF 011'!E55 -> CMV CITOMEGALOVIRUS IGM METODO ELISA 96 DET. TIPO WIENER | H25: NO | I25: ='SAF 011'!F55 -> UNIDAD | J25: ='SAF 011'!H55 -> 19749 | K25: ='SAF 011'!#REF! -> #REF! | M25: =+J25*K25 -> #REF!
A26: 15 | C26: ='SAF 011'!E68 -> Equipo para la deteccion de Anti Hb Core, por metodo de Elisa en microplacas en equipos de 96 det. Monolisa HBc Plus - Tipo Biorad | H26: NO | I26: ='SAF 011'!F68 -> CAJA | J26: ='SAF 011'!H68 -> 20160 | K26: ='SAF 011'!#REF! -> #REF! | M26: =+J26*K26 -> #REF!
A27: 16 | C27: ='SAF 011'!E69 -> Equipos Covidar IGG x 192 deterermibaciones tipo Lemos | H27: NO | I27: ='SAF 011'!F69 -> CAJA | J27: ='SAF 011'!H69 -> 19743.57 | K27: ='SAF 011'!#REF! -> #REF! | M27: =+J27*K27 -> #REF!
A28: 17 | C28: ='SAF 011'!E70 -> Equipos por metodo de Elisa para la deteccion simultanea anticuerpos y antigenos de virus de Hepatitis C por Elisa en microplaca recubierta con anticuerpos monoclonales anti caspide de HCV con antigenos reconvinantes de la region NS3 genotipos 1 y 3º y de la region no estructural NS4 y un peptido mutado de la region de la caspide del Virus HCV. En equipos de 96 det. Por metodologia EIA en microplacas con provision de reactivos, calibradores,materias descartable, buffers, liquido de lavado, y todo insumo necesario para suprocesamiento Monolisa HCV Ag- Ab Ultra v.2 - Tipo Biorad | H28: NO | I28: ='SAF 011'!F70 -> CAJA | J28: ='SAF 011'!H70 -> 36300 | K28: ='SAF 011'!#REF! -> #REF! | M28: =+J28*K28 -> #REF!
A29: 18 | C29: ='SAF 011'!E83 -> HEPATITIS B ELISA HBSAG 96 DET Tipo WIENER | H29: NO | I29: ='SAF 011'!F83 -> CAJA | J29: ='SAF 011'!H83 -> 22109 | K29: ='SAF 011'!#REF! -> #REF! | M29: =+J29*K29 -> #REF!
A30: 19 | C30: ='SAF 011'!E84 -> HEPATITIS C HCV ELISA 3º GEN. 96 DET. - TIPO WIENER | H30: NO | I30: ='SAF 011'!F84 -> UNIDAD | J30: ='SAF 011'!H84 -> 39806 | K30: ='SAF 011'!#REF! -> #REF! | M30: =+J30*K30 -> #REF!
A31: 20 | C31: ='SAF 011'!E85 -> HIV ELISA AG/AC 4° GENERACION -96 DET- TIPO WIENER | H31: NO | I31: ='SAF 011'!F85 -> Unidad | J31: ='SAF 011'!H85 -> 23147 | K31: ='SAF 011'!#REF! -> #REF! | M31: =+J31*K31 -> #REF!
A32: 21 | C32: ='SAF 011'!E86 -> HTLV 1 Y 2 ELISA-96DET. - TIPO WIENER | H32: NO | I32: ='SAF 011'!F86 -> UNIDAD | J32: ='SAF 011'!H86 -> 25747 | K32: ='SAF 011'!#REF! -> #REF! | M32: =+J32*K32 -> #REF!
A33: 22 | C33: ='SAF 011'!E87 -> HVC REACTIVO x 100 det - TIPO WIENER | H33: NO | I33: ='SAF 011'!F87 -> UNIDAD | J33: ='SAF 011'!H87 -> 50545 | K33: ='SAF 011'!#REF! -> #REF! | M33: =+J33*K33 -> #REF!
A34: 23 | C34: ='SAF 011'!E93 -> KIT PLASMAFERESIS TIPO GRIFOLS | H34: NO | I34: ='SAF 011'!F93 -> UNIDAD | J34: ='SAF 011'!H93 -> 35090 | K34: ='SAF 011'!#REF! -> #REF! | M34: =+J34*K34 -> #REF!
A35: 24 | C35: ='SAF 011'!E94 -> KITS PARA PLAQUETOFERESIS CON FILTRO TIPO GRIFOLS | H35: NO | I35: ='SAF 011'!F94 -> UNIDAD | J35: ='SAF 011'!H94 -> 35695 | K35: ='SAF 011'!#REF! -> #REF! | M35: =+J35*K35 -> #REF!
A36: 25 | C36: ='SAF 011'!E103 -> PANEL IDENTISERA DIANA TIPO GRIFOLS | H36: NO | I36: ='SAF 011'!F103 -> UNIDAD | J36: ='SAF 011'!H103 -> 29160 | K36: ='SAF 011'!#REF! -> #REF! | M36: =+J36*K36 -> #REF!
A37: 26 | C37: ='SAF 011'!E104 -> PANEL SARASCAN DIANA 2 TIPO GRIFOLS | H37: NO | I37: ='SAF 011'!F104 -> UNIDAD | J37: ='SAF 011'!H104 -> 22500 | K37: ='SAF 011'!#REF! -> #REF! | M37: =+J37*K37 -> #REF!
A38: 27 | C38: ='SAF 011'!E105 -> PANEL SERIGRUP A1/B TIPO GRIFOLS | H38: NO | I38: ='SAF 011'!F105 -> UNIDAD | J38: ='SAF 011'!H105 -> 15588 | K38: ='SAF 011'!#REF! -> #REF! | M38: =+J38*K38 -> #REF!
A39: 28 | C39: ='SAF 011'!E106 -> PANEL SERO cyte 0,8% TIPO GRIFOLS | H39: NO | I39: ='SAF 011'!F106 -> UNIDAD | J39: ='SAF 011'!H106 -> 16500 | K39: ='SAF 011'!#REF! -> #REF! | M39: =+J39*K39 -> #REF!
A40: 29 | C40: ='SAF 011'!E109 -> Pre-trigger Tipo Abott | H40: NO | I40: ='SAF 011'!F109 -> CAJA | J40: ='SAF 011'!H109 -> 16980 | K40: ='SAF 011'!#REF! -> #REF! | M40: =+J40*K40 -> #REF!
A41: 30 | C41: ='SAF 011'!E118 -> SARS- COV-2 Igm Control Tipo Abott | H41: NO | I41: ='SAF 011'!F118 -> CAJA | J41: ='SAF 011'!H118 -> 17788 | K41: ='SAF 011'!#REF! -> #REF! | M41: =+J41*K41 -> #REF!
A42: 31 | C42: ='SAF 011'!E119 -> SARS-COV-2 IgG Reactivo x 100 det Tipo Abott | H42: NO | I42: ='SAF 011'!F119 -> CAJA | J42: ='SAF 011'!H119 -> 64700 | K42: ='SAF 011'!#REF! -> #REF! | M42: =+J42*K42 -> #REF!
A43: 32 | C43: ='SAF 011'!E120 -> SARS-COV-2 IgM Calibrador Tipo Abott | H43: NO | I43: ='SAF 011'!F120 -> CAJA | J43: ='SAF 011'!H120 -> 12540 | K43: ='SAF 011'!#REF! -> #REF! | M43: =+J43*K43 -> #REF!
...

Sheet APG BANCO DE SANGRE
A1: EJERCICIO: | D1: 2022 | P1: AUTORIZACION PARA GASTAR
A4: JURISDICCIÓN: | G4: ='NP BANCO DE SANGRE'!D3 -> 040 - MINISTERIO DE SALUD
A5: SAF: | G5: ='NP BANCO DE SANGRE'!D4 -> 011 - DIRECCION PROVINCIAL DE ADMINISTRACION - MINISTERIO DE SALUD
A6: UNIDAD EJECUTORA: | G6: ='NP BANCO DE SANGRE'!D5 -> DIRECCION PROVINCIAL BANCO DE SANGRE
A7: DEPENDENCIA SOLICITANTE: | G7: ='NP BANCO DE SANGRE'!D6 -> DIRECCION PROVINCIAL BANCO DE SANGRE
A8: AUTORIZACIÓN:
A9: Señor Director de Administración o Titular del Servicio Administrativo Financiero:
A10: Autorizo la realización de los trámites correspondientes, a fin de proveer a este Organismo los bienes/servicios que se detallan en Nota de Pedido N° 04/2022 afectando la erogación resultante a los créditos presupuestarios aprobados a favor de esta Unidad Ejecutora, conforme al siguiente detalle:
A12: IMPUTACIÓN PRESUPUESTARIA
A13: CÓDIGO | O13: DENOMINACIÓN DE LA PARTIDA PRESUPUESTARIA | Q13: IMPORTE
A14: PR | B14: SB | C14: PY | D14: AC | E14: OB | F14: UG | G14: FIN | H14: FUN | I14: I | J14: P | K14: P | L14: SubP | M14: M | N14: FF
A15: 27 | D15: 1 | F15: 4901 | G15: 3 | H15: 1 | I15: 2 | J15: 5 | K15: 1 | M15: 1 | N15: 1.1 | O15: COMPUESTOS QUIMICOS | Q15: ='NP BANCO DE SANGRE'!M56 -> #REF!
A38: TOTAL DE PESOS: TRECE MILLONES OCHOCIENTOS TREINTA Y UN MIL CUATROCIENTOS TREINTA Y UNO CON 16/100.- | Q38: =SUM(Q15:Q37) -> #REF!
A40: JUSTIFICACIÓN:
A41: ='NP BANCO DE SANGRE'!D8 -> ADQUISICION DEL RUBRO REACTIVOS PARA LABORATORIO

Sheet NP CUR
A1: NOTA DE PEDIDO | J1: N° | K1: 02/2022
A3: JURISDICCIÓN: | D3: ='SAF 011'!C4 -> 040 - MINISTERIO DE SALUD
A4: SAF: | D4: ='SAF 011'!C5 -> 011 - DIRECCION PROVINCIAL DE ADMINISTRACION - MINISTERIO DE SALUD
A5: UNIDAD EJECUTORA: | D5: DIRECCION PROVINCIAL CENTRO UNICO DE REFERENCIA
A6: DEPENDENCIA SOLICITANTE: | D6: DIRECCION PROVINCIAL CENTRO UNICO DE REFERENCIA
A7: PERIODO UTILIZACIÓN: | D7: 1° TRIMESTRE 2022
A8: OBJETO: | D8: ADQUISICION DEL RUBRO REACTIVOS PARA LABORATORIO
A10: Ítem | B10: Codigo Item | C10: DESCRIPCIÓN | H10: Adjunta Detalle Técnico | I10: Unidad Medida | J10: Precio Unitario Estimado | K10: Cantidad Solicitada
C12: ='SAF 011'!E12 -> AGUA BIDESTILADA X 5 LITROS | H12: NO | I12: ='SAF 011'!F12 -> BIDON | J12: ='SAF 011'!H12 -> 574 | K12: ='SAF 011'!#REF! -> #REF! | M12: =+J12*K12 -> #REF!
C13: ='SAF 011'!E24 -> ARC ANTI HBC II RGT X 100 DET. | H13: NO | I13: ='SAF 011'!F24 -> KIT | J13: ='SAF 011'!H24 -> 40425 | K13: ='SAF 011'!#REF! -> #REF! | M13: =+J13*K13 -> #REF!
C14: ='SAF 011'!E25 -> ARC ANTI HCV RGT X 100 DET. | H14: NO | I14: ='SAF 011'!F25 -> KIT | J14: ='SAF 011'!H25 -> 71500 | K14: ='SAF 011'!#REF! -> #REF! | M14: =+J14*K14 -> #REF!
C15: ='SAF 011'!E26 -> ARC BUFFER CONCENTRADO x 4 lts | H15: NO | I15: ='SAF 011'!F26 -> BIDON | J15: ='SAF 011'!H26 -> 13810 | K15: ='SAF 011'!#REF! -> #REF! | M15: =+J15*K15 -> #REF!
C16: ='SAF 011'!E27 -> ARC CELDAS DE REACCION | H16: NO | I16: ='SAF 011'!F27 -> CAJA | J16: ='SAF 011'!H27 -> 28000 | K16: ='SAF 011'!#REF! -> #REF! | M16: =+J16*K16 -> #REF!
C17: ='SAF 011'!E28 -> ARC CMV M RGT X 100 | H17: NO | I17: ='SAF 011'!F28 -> KIT | J17: ='SAF 011'!H28 -> 103000 | K17: ='SAF 011'!#REF! -> #REF! | M17: =+J17*K17 -> #REF!
C18: ='SAF 011'!E29 -> ARC HBSAG RGT X 100 DET. | H18: NO | I18: ='SAF 011'!F29 -> KIT | J18: ='SAF 011'!H29 -> 26710 | K18: ='SAF 011'!#REF! -> #REF! | M18: =+J18*K18 -> #REF!
C19: ='SAF 011'!E30 -> ARC HIV COMBO RGT X 100 DET. | H19: NO | I19: ='SAF 011'!F30 -> KIT | J19: ='SAF 011'!H30 -> 46450 | K19: ='SAF 011'!#REF! -> #REF! | M19: =+J19*K19 -> #REF!
C20: ='SAF 011'!E31 -> ARC PRE TRIGGER x 4 lts | H20: NO | I20: ='SAF 011'!F31 -> BIDON | J20: ='SAF 011'!H31 -> 28050 | K20: ='SAF 011'!#REF! -> #REF! | M20: =+J20*K20 -> #REF!
C21: ='SAF 011'!E32 -> ARC SIFILIS RGT X 100 | H21: NO | I21: ='SAF 011'!F32 -> KIT | J21: ='SAF 011'!H32 -> 38400 | K21: ='SAF 011'!#REF! -> #REF! | M21: =+J21*K21 -> #REF!
C22: ='SAF 011'!E33 -> ARC TRIGGER x 4 lts | H22: NO | I22: ='SAF 011'!F33 -> BIDON | J22: ='SAF 011'!H33 -> 12100 | K22: ='SAF 011'!#REF! -> #REF! | M22: =+J22*K22 -> #REF!
A24: Costo total estimado: OCHOCIENTOS CINCUENTA Y CUATRO MIL TRESCIENTOS CUARENTA CON 00/100.- | J24: =+M24 -> #REF! | M24: =SUM(M12:M23) -> #REF!

Sheet APG CUR
A1: EJERCICIO: | D1: 2022 | P1: AUTORIZACION PARA GASTAR
A4: JURISDICCIÓN: | G4: ='NP CUR'!D3 -> 040 - MINISTERIO DE SALUD
A5: SAF: | G5: ='NP CUR'!D4 -> 011 - DIRECCION PROVINCIAL DE ADMINISTRACION - MINISTERIO DE SALUD
A6: UNIDAD EJECUTORA: | G6: ='NP CUR'!D5 -> DIRECCION PROVINCIAL CENTRO UNICO DE REFERENCIA
A7: DEPENDENCIA SOLICITANTE: | G7: ='NP CUR'!D6 -> DIRECCION PROVINCIAL CENTRO UNICO DE REFERENCIA
A8: AUTORIZACIÓN:
A9: Señor Director de Administración o Titular del Servicio Administrativo Financiero:
A10: Autorizo la realización de los trámites correspondientes, a fin de proveer a este Organismo los bienes/servicios que se detallan en Nota de Pedido N° 02/2022 afectando la erogación resultante a los créditos presupuestarios aprobados a favor de esta Unidad Ejecutora, conforme al siguiente detalle:
A12: IMPUTACIÓN PRESUPUESTARIA
A13: CÓDIGO | O13: DENOMINACIÓN DE LA PARTIDA PRESUPUESTARIA | Q13: IMPORTE
A14: PR | B14: SB | C14: PY | D14: AC | E14: OB | F14: UG | G14: FIN | H14: FUN | I14: I | J14: P | K14: P | L14: SubP | M14: M | N14: FF
A15: 35 | D15: 2 | F15: 4901 | G15: 3 | H15: 1 | I15: 2 | J15: 5 | K15: 1 | M15: 1 | N15: 1.1 | O15: COMPUESTOS QUIMICOS | Q15: ='NP CUR'!M24 -> #REF!
A38: TOTAL DE PESOS: OCHOCIENTOS CINCUENTA Y CUATRO MIL TRESCIENTOS CUARENTA CON 00/100.- | Q38: =SUM(Q15:Q37) -> #REF!
A40: JUSTIFICACIÓN:
A41: ='NP CUR'!D8 -> ADQUISICION DEL RUBRO REACTIVOS PARA LABORATORIO

Sheet NP VECTORES
A1: NOTA DE PEDIDO | J1: N° | K1: 01/2022
A3: JURISDICCIÓN: | D3: ='SAF 011'!C4 -> 040 - MINISTERIO DE SALUD
A4: SAF: | D4: ='SAF 011'!C5 -> 011 - DIRECCION PROVINCIAL DE ADMINISTRACION - MINISTERIO DE SALUD
A5: UNIDAD EJECUTORA: | D5: DIRECCION DE CONTROL DE VECTORES Y ZOONOSIS
A6: DEPENDENCIA SOLICITANTE: | D6: DIRECCION DE CONTROL DE VECTORES Y ZOONOSIS
A7: PERIODO UTILIZACIÓN: | D7: 1° TRIMESTRE 2022
A8: OBJETO: | D8: ADQUISICION DEL RUBRO REACTIVOS PARA LABORATORIO
A10: Ítem | B10: Codigo Item | C10: DESCRIPCIÓN | H10: Adjunta Detalle Técnico | I10: Unidad Medida | J10: Precio Unitario Estimado | K10: Cantidad Solicitada
A12: 1 | C12: ='SAF 011'!E49 -> Chagatest Elisa Lisado 96 determinaciones Tipo WIENER | H12: NO | I12: ='SAF 011'!F49 -> EQUIPO | J12: ='SAF 011'!H49 -> 12000 | K12: ='SAF 011'!#REF! -> #REF! | M12: =+J12*K12 -> #REF!
A13: 2 | C13: ='SAF 011'!E51 -> CHAGATEST HAI 5 TITULOS 96 DET Tipo WIENER | H13: NO | I13: ='SAF 011'!F51 -> UNIDAD | J13: ='SAF 011'!H51 -> 16429 | K13: ='SAF 011'!#REF! -> #REF! | M13: =+J13*K13 -> #REF!
A14: 3 | C14: ='SAF 011'!E145 -> WL CHECK CHAGAS - 25 CASSETTES - TIPO WIENER | H14: NO | I14: ='SAF 011'!F145 -> EQUIPO | J14: ='SAF 011'!H145 -> 10000 | K14: ='SAF 011'!#REF! -> #REF! | M14: =+J14*K14 -> #REF!
A16: Costo total estimado: SEISCIENTOS VEINTISEIS MIL CUATROCIENTOS TREINTA Y CINCO CON 00/100.- | J16: =+M16 -> #REF! | M16: =SUM(M12:M15) -> #REF!

Sheet APG VECTORES
A1: EJERCICIO: | D1: 2022 | P1: AUTORIZACION PARA GASTAR
A4: JURISDICCIÓN: | G4: ='NP VECTORES'!D3 -> 040 - MINISTERIO DE SALUD
A5: SAF: | G5: ='NP VECTORES'!D4 -> 011 - DIRECCION PROVINCIAL DE ADMINISTRACION - MINISTERIO DE SALUD
A6: UNIDAD EJECUTORA: | G6: ='NP VECTORES'!D5 -> DIRECCION DE CONTROL DE VECTORES Y ZOONOSIS
A7: DEPENDENCIA SOLICITANTE: | G7: ='NP VECTORES'!D6 -> DIRECCION DE CONTROL DE VECTORES Y ZOONOSIS
A8: AUTORIZACIÓN:
A9: Señor Director de Administración o Titular del Servicio Administrativo Financiero:
A10: Autorizo la realización de los trámites correspondientes, a fin de proveer a este Organismo los bienes/servicios que se detallan en Nota de Pedido N° 01/2022 afectando la erogación resultante a los créditos presupuestarios aprobados a favor de esta Unidad Ejecutora, conforme al siguiente detalle:
A12: IMPUTACIÓN PRESUPUESTARIA
A13: CÓDIGO | O13: DENOMINACIÓN DE LA PARTIDA PRESUPUESTARIA | Q13: IMPORTE
A14: PR | B14: SB | C14: PY | D14: AC | E14: OB | F14: UG | G14: FIN | H14: FUN | I14: I | J14: P | K14: P | L14: SubP | M14: M | N14: FF
A15: 23 | D15: 1 | F15: 4901 | G15: 3 | H15: 1 | I15: 2 | J15: 5 | K15: 1 | M15: 1 | N15: 1.1 | O15: COMPUESTOS QUIMICOS | Q15: ='NP VECTORES'!M16 -> #REF!
A38: TOTAL DE PESOS: SEISCIENTOS VEINTISEIS MIL CUATROCIENTOS TREINTA Y CINCO CON 00/100.- | Q38: =SUM(Q15:Q37) -> #REF!
A40: JUSTIFICACIÓN:
A41: ='NP VECTORES'!D8 -> ADQUISICION DEL RUBRO REACTIVOS PARA LABORATORIO
