Workbook

Sheet Necesidades Trimestrales
B2: Pedido de Necesidades Trimestrales
A4: JURISDICCION: | C4: 40 - Ministerio de Salud
A5: SAF N°: | C5: 23 - Hospital Interzonal San Juan Bautista
A6: EJERCICIO: | C6: 2022
A7: TRIMESTRE: | C7: 1
A9: ID | B9: CODIGO ITEM | C9: RUBRO DE COMPRA | D9: I.P.P. | E9: DESCRIPCION | F9: UNIDAD DE MEDIDA | G9: CANTIDAD | H9: PRECIO UNITARIO ESTIMADO | I9: IMPORTE TOTAL ESTIMADO
A10: 1 | B10: 2.5.1-9009.497 | C10: QUIMICOS | D10: 2.5.1 | E10: ACIDOS; COMPUESTO QUIMICO: AC. ACETICO; ESTADO SOLIDO; CALIDAD: FARMACEUTICA; CONCENTRACION/PUREZA 25/30%; PRESENTACION: 5KG | F10: BIDON | G10: 20 | H10: 3300 | I10: =G10*H10 -> 66000
A11: 2 | B11: 2.5.1-5771.11 | C11: PROD. MEDICO/FARMACEUTICOS/LAB | D11: 2.5.1 | E11: ANTISEPTICOS P/MATERIALES; TIPO: ASOCIACION, DROGA GENERICA: PEROXIDO DE HIDROGENO+ ACIDO PERACETICO, FORMA FARMACEUTICA: SOLUCION, PRESENTACION: ENVASE X 5LT, USO: EQUIPO | F11: BIDON | G11: 20 | H11: 1880 | I11: =G11*H11 -> 37600
A12: 3 | B12: 2.5.1-9009.262 | C12: QUIMICOS | D12: 2.5.1 | E12: ACIDOS; COMPUESTO QUIMICO: AC. CITRICO, ESTADO: SOLIDO, CALIDAD: BIOLOGIA MOLECULAR, CONCENTRACION/PUREZA: 99,99 %, PRESENTACION: ENVASE X 1 Kg | F12: UNIDAD | G12: 10 | H12: 1560 | I12: =G12*H12 -> 15600
A13: 4 | B13: 2.5.2-710.4 | C13: PROD. MEDICO/FARMACEUTICOS/LAB | D13: 2.5.2 | E13: AGUA OXIGENADA; CAPACIDAD: 1000 CM3, VOLUMEN: 10, PRESENTACION: ENVASE X 1000 CM3 | F13: BOTELLA | G13: 300 | H13: 128.59 | I13: =G13*H13 -> 38577
A14: 5 | B14: 2.5.2-711.32 | C14: PROD. MEDICO/FARMACEUTICOS/LAB | D14: 2.5.2 | E14: ALCOHOL USO MEDICINAL; PUREZA: 96 %, PRESENTACION: ENVASE X 1000 CM3 | F14: BOTELLA | G14: 100 | H14: 201 | I14: =G14*H14 -> 20100
A15: 6 | B15: 2.5.2-1723.110 | C15: PROD. MEDICO/FARMACEUTICOS/LAB | D15: =LEFT(B15,5) -> 2.5.2 | E15: ANTISEPTICOS LOCALES P/PERSONA; TIPO: DESINFECTANTE, DROGA GENERICA: ALCOHOL YODADO, FORMA FARMACEUTICA: SOLUCION, PRESENTACION: ENVASE X 1000 Ml | F15: BOTELLA | G15: 90 | H15: 1200 | I15: =G15*H15 -> 108000
A16: 7 | B16: 2.5.2-1723.69 | C16: PROD. MEDICO/FARMACEUTICOS/LAB | D16: =LEFT(B16,5) -> 2.5.2 | E16: ANTISEPTICOS LOCALES P/PERSONA; TIPO: MONODROGA, DROGA GENERICA: CLOROXILENOL, FORMA FARMACEUTICA: SOLUCION, PRESENTACION: ENVASE X 5 L | F16: BIDON | G16: 10 | H16: 4500 | I16: =G16*H16 -> 45000
A17: 8 | B17: 2.5.1-9065.16 | C17: QUIMICOS | D17: 2.5.1 | E17: DESINFECTANTES Y DETERGENTES; PRINCIPIO ACTIVO: AMILASA, PROTEASA, LIPASA, CALIDAD: COMERCIAL, CONCENTRACION/PUREZA: 100 %, PRESENTACION: ENVASE X 5 L | F17: BIDON | G17: 60 | H17: 4900.5 | I17: =G17*H17 -> 294030
A18: 9 | B18: 2.5.2-1726.492 | C18: PROD. MEDICO/FARMACEUTICOS/LAB | D18: 2.5.1 | E18: SOLUCIONES P/MEDICINA; TIPO: FORMOL AL 40 %, PRESENTACION: ENVASE X 1 L | F18: BOTELLA | G18: 30 | H18: 661 | I18: =G18*H18 -> 19830
A19: 10 | B19: 2.5.2-1723.30 | C19: PROD. MEDICO/FARMACEUTICOS/LAB | D19: =LEFT(B19,5) -> 2.5.2 | E19: ANTISEPTICOS LOCALES P/PERSONA; TIPO: MONODROGA, DROGA GENERICA: IODOPOVIDONA, FORMA FARMACEUTICA: SOLUCION, PRESENTACION: BIDON X 5 L | F19: BIDON | G19: 30 | H19: 2250 | I19: =G19*H19 -> 67500
A20: 11 | B20: 2.5.2-1723.50 | C20: PROD. MEDICO/FARMACEUTICOS/LAB | D20: =LEFT(B20,5) -> 2.5.2 | E20: ANTISEPTICOS LOCALES P/PERSONA; DROGA GENERICA: IODOPOVIDONA 10%, FORMA FARMACEUTICA: SOLUCION, PRESENTACION: ENVASE X 1 L, TIPO: MONODROGA | F20: BOTELLA | G20: 240 | H20: 573 | I20: =G20*H20 -> 137520
A21: 12 | B21: 2.5.2-1723.104 | C21: PROD. MEDICO/FARMACEUTICOS/LAB | D21: =LEFT(B21,5) -> 2.5.2 | E21: ANTISEPTICOS LOCALES P/PERSONA; TIPO: MONODROGA, DROGA GENERICA: IODOPOVIDONA 5 %, FORMA FARMACEUTICA: JABON LIQUIDO, PRESENTACION: ENVASE X 1 L | F21: BOTELLA | G21: 30 | H21: 450 | I21: =G21*H21 -> 13500
A22: 13 | B22: 2.5.2-1723.146 | C22: PROD. MEDICO/FARMACEUTICOS/LAB | D22: =LEFT(B22,5) -> 2.5.2 | E22: ANTISEPTICOS LOCALES P/PERSONA; TIPO: MONODROGA, DROGA GENERICA: IODOPOVIDONA 5 %, FORMA FARMACEUTICA: JABON LIQUIDO, PRESENTACION: ENVASE X 5 L | F22: BIDON | G22: 20 | H22: 1520 | I22: =G22*H22 -> 30400
A23: 14 | B23: 2.9.1-6956.122 | C23: ELEMENTOS DE LIMPIEZA | D23: 2.5.2 | E23: ARTICULOS DE TOCADOR; TIPO: JABON LIQUIDO HIPOALERGENICO, PRESENTACION: ENVASE X 800 ML BAG IN BOX | F23: BAG IN BOX | G23: 100 | H23: 1150 | I23: =G23*H23 -> 115000
A24: 15 | B24: 2.5.2-1723.175 | C24: PROD. MEDICO/FARMACEUTICOS/LAB | D24: 2.5.2 | E24: ANTISEPTICOS LOCALES P/PERSONA; TIPO: ANTIBACTERIANO, DROGA GENERICA: CLORHEXIDINA, FORMA FARMACEUTICA: LOCION ALCOHOLICA BACTERICIDA, PRESENTACION: ENVASE X 800 ML BAG IN BOX | F24: BAG IN BOX | G24: 100 | H24: 1270.5 | I24: =G24*H24 -> 127050
A25: 16 | B25: 2.5.4-505.99 | C25: ELEMENTOS DE LIMPIEZA | D25: 2.5.1 | E25: DESINFECTANTES; PRINCIPIO ACTIVO: MONOPERSUFATO DE POTASIO, CONTROL: BACTERIAS, HONGOS, VIRUS, PRESENTACION: ENVASE X 20 G | F25: SOBRE | G25: 80 | H25: 199.65 | I25: =G25*H25 -> 15972
A26: 17 | B26: 2.5.2-1723.35 | C26: PROD. MEDICO/FARMACEUTICOS/LAB | D26: 2.5.2 | E26: ANTISEPTICOS LOCALES P/PERSONA; TIPO: MONODROGA, DROGA GENERICA: NITROFURAZONA, FORMA FARMACEUTICA: SOLUCION, PRESENTACION: FRASCO X 1 L | F26: BOTELLA | G26: 100 | H26: 859 | I26: =G26*H26 -> 85900
A27: 18 | B27: 2.5.2-1723.89 | C27: PROD. MEDICO/FARMACEUTICOS/LAB | D27: 2.5.2 | E27: ANTISEPTICOS LOCALES P/PERSONA; TIPO: MONODROGA, DROGA GENERICA: TINTURA DE IODO FUERTE, FORMA FARMACEUTICA: SOLUCION, PRESENTACION: ENVASE X 1 L | F27: BOTELLA | G27: 5 | H27: 989 | I27: =G27*H27 -> 4945
B30: Presentar copia certificada de Resolución de Habilitación expedida por la Subsecretaria de Asistencia en Salud Publica o copia certificada de Certificado de Habilitación de Establecimiento y/o copia certificada de Certificado de Transito Interjurisdiccional emitido por A.N.M.A.T, el que correspondiere conforme a la situación de cada establecimiento cotizante (Laboratorio, Droguería, etc.), en caso de corresponder. Indicar Marca y Numero de Certificado de ANMAT por ítem. VENCIMIENTO DE LOS PRESENTES INSUMOS: UN PLAZO NO MENOR A 12 MESES DE LA FECHA DE RECEPCION
B31: PLAZO DE MANTENIMIENTO DE LA OFERTA: 45 DIAS HABILES
B32: PLAZO DE ENTREGA: 15 DIAS HABILES - SERVICIO DE FARMACIA - ADVA. ILLIA Y MARIANO MORENO - DE LUNES A VIERNES DE 08:00 A 11:00 HORAS
B34: Especificidades Item N° 6:
B36: Descripción técnica
C37: concentracion ALCOHOL IODADO 2%
B38: Plazos y lugares de entrega
C39: 15 dias habiles - Servicio de Farmacia del HISJB - Avda. Illia y Mariano Moreno de lunes a viernes de 08:00 a 11:00 horas
B41: Calidad Minima esperada
B43: Mantenimiento
C44: 45 dias habiles
B45: Garantia
B50: Especificidades Item N° 8:
B52: Descripción técnica
C53: Detergente trienzimatico (proteada, lipasa y amilasa). Concentración: 3 a 5 ml/litro. Libre de fenoles, Atoxico. Aprobación ANMAT. Proveer 1 válvula dosificadora cada 5 unidades.
B54: Plazos y lugares de entrega
...

Sheet NotaPedido
A1: NOTA DE PEDIDO | J1: N° | K1: 027 - 2022
A3: JURISDICCIÓN: | D3: ='Necesidades Trimestrales'!C4 -> 40 - Ministerio de Salud
A4: SAF: | D4: ='Necesidades Trimestrales'!C5 -> 23 - Hospital Interzonal San Juan Bautista
A5: UNIDAD EJECUTORA: | D5: 168 - Direccion Asistencial
A6: DEPENDENCIA SOLICITANTE: | D6: Servicio de Farmacia
A7: PERIODO UTILIZACIÓN: | D7: Un Semestre
A8: OBJETO: | D8: Adquisición de Antisepticos y Desinfectantes
A10: Ítem | B10: Codigo Item | C10: DESCRIPCIÓN | H10: Adjunta Detalle Técnico | I10: Unidad Medida | J10: Precio Unitario Estimado | K10: Cantidad Solicitada
A12: 1 | B12: ='Necesidades Trimestrales'!B10 -> 2.5.1-9009.497 | C12: ='Necesidades Trimestrales'!E10 -> ACIDOS; COMPUESTO QUIMICO: AC. ACETICO; ESTADO SOLIDO; CALIDAD: FARMACEUTICA; CONCENTRACION/PUREZA 25/30%; PRESENTACION: 5KG | H12: NO | I12: ='Necesidades Trimestrales'!F10 -> BIDON | J12: ='Necesidades Trimestrales'!H10 -> 3300 | K12: ='Necesidades Trimestrales'!G10 -> 20
A13: 2 | B13: ='Necesidades Trimestrales'!B11 -> 2.5.1-5771.11 | C13: ='Necesidades Trimestrales'!E11 -> ANTISEPTICOS P/MATERIALES; TIPO: ASOCIACION, DROGA GENERICA: PEROXIDO DE HIDROGENO+ ACIDO PERACETICO, FORMA FARMACEUTICA: SOLUCION, PRESENTACION: ENVASE X 5LT, USO: EQUIPO | H13: SI | I13: ='Necesidades Trimestrales'!F11 -> BIDON | J13: ='Necesidades Trimestrales'!H11 -> 1880 | K13: ='Necesidades Trimestrales'!G11 -> 20
A14: 3 | B14: ='Necesidades Trimestrales'!B12 -> 2.5.1-9009.262 | C14: ='Necesidades Trimestrales'!E12 -> ACIDOS; COMPUESTO QUIMICO: AC. CITRICO, ESTADO: SOLIDO, CALIDAD: BIOLOGIA MOLECULAR, CONCENTRACION/PUREZA: 99,99 %, PRESENTACION: ENVASE X 1 Kg | H14: NO | I14: ='Necesidades Trimestrales'!F12 -> UNIDAD | J14: ='Necesidades Trimestrales'!H12 -> 1560 | K14: ='Necesidades Trimestrales'!G12 -> 10
A15: 4 | B15: ='Necesidades Trimestrales'!B13 -> 2.5.2-710.4 | C15: ='Necesidades Trimestrales'!E13 -> AGUA OXIGENADA; CAPACIDAD: 1000 CM3, VOLUMEN: 10, PRESENTACION: ENVASE X 1000 CM3 | H15: NO | I15: ='Necesidades Trimestrales'!F13 -> BOTELLA | J15: ='Necesidades Trimestrales'!H13 -> 128.59 | K15: ='Necesidades Trimestrales'!G13 -> 300
A16: 5 | B16: ='Necesidades Trimestrales'!B14 -> 2.5.2-711.32 | C16: ='Necesidades Trimestrales'!E14 -> ALCOHOL USO MEDICINAL; PUREZA: 96 %, PRESENTACION: ENVASE X 1000 CM3 | H16: NO | I16: ='Necesidades Trimestrales'!F14 -> BOTELLA | J16: ='Necesidades Trimestrales'!H14 -> 201 | K16: ='Necesidades Trimestrales'!G14 -> 100
A17: 6 | B17: ='Necesidades Trimestrales'!B15 -> 2.5.2-1723.110 | C17: ='Necesidades Trimestrales'!E15 -> ANTISEPTICOS LOCALES P/PERSONA; TIPO: DESINFECTANTE, DROGA GENERICA: ALCOHOL YODADO, FORMA FARMACEUTICA: SOLUCION, PRESENTACION: ENVASE X 1000 Ml | H17: SI | I17: ='Necesidades Trimestrales'!F15 -> BOTELLA | J17: ='Necesidades Trimestrales'!H15 -> 1200 | K17: ='Necesidades Trimestrales'!G15 -> 90
A18: 7 | B18: ='Necesidades Trimestrales'!B16 -> 2.5.2-1723.69 | C18: ='Necesidades Trimestrales'!E16 -> ANTISEPTICOS LOCALES P/PERSONA; TIPO: MONODROGA, DROGA GENERICA: CLOROXILENOL, FORMA FARMACEUTICA: SOLUCION, PRESENTACION: ENVASE X 5 L | H18: NO | I18: ='Necesidades Trimestrales'!F16 -> BIDON | J18: ='Necesidades Trimestrales'!H16 -> 4500 | K18: ='Necesidades Trimestrales'!G16 -> 10
A19: 8 | B19: ='Necesidades Trimestrales'!B17 -> 2.5.1-9065.16 | C19: ='Necesidades Trimestrales'!E17 -> DESINFECTANTES Y DETERGENTES; PRINCIPIO ACTIVO: AMILASA, PROTEASA, LIPASA, CALIDAD: COMERCIAL, CONCENTRACION/PUREZA: 100 %, PRESENTACION: ENVASE X 5 L | H19: SI | I19: ='Necesidades Trimestrales'!F17 -> BIDON | J19: ='Necesidades Trimestrales'!H17 -> 4900.5 | K19: ='Necesidades Trimestrales'!G17 -> 60
A20: 9 | B20: ='Necesidades Trimestrales'!B18 -> 2.5.2-1726.492 | C20: ='Necesidades Trimestrales'!E18 -> SOLUCIONES P/MEDICINA; TIPO: FORMOL AL 40 %, PRESENTACION: ENVASE X 1 L | H20: NO | I20: ='Necesidades Trimestrales'!F18 -> BOTELLA | J20: ='Necesidades Trimestrales'!H18 -> 661 | K20: ='Necesidades Trimestrales'!G18 -> 30
A21: 10 | B21: ='Necesidades Trimestrales'!B19 -> 2.5.2-1723.30 | C21: ='Necesidades Trimestrales'!E19 -> ANTISEPTICOS LOCALES P/PERSONA; TIPO: MONODROGA, DROGA GENERICA: IODOPOVIDONA, FORMA FARMACEUTICA: SOLUCION, PRESENTACION: BIDON X 5 L | H21: NO | I21: ='Necesidades Trimestrales'!F19 -> BIDON | J21: ='Necesidades Trimestrales'!H19 -> 2250 | K21: ='Necesidades Trimestrales'!G19 -> 30
A22: 11 | B22: ='Necesidades Trimestrales'!B20 -> 2.5.2-1723.50 | C22: ='Necesidades Trimestrales'!E20 -> ANTISEPTICOS LOCALES P/PERSONA; DROGA GENERICA: IODOPOVIDONA 10%, FORMA FARMACEUTICA: SOLUCION, PRESENTACION: ENVASE X 1 L, TIPO: MONODROGA | H22: SI | I22: ='Necesidades Trimestrales'!F20 -> BOTELLA | J22: ='Necesidades Trimestrales'!H20 -> 573 | K22: ='Necesidades Trimestrales'!G20 -> 240
A23: 12 | B23: ='Necesidades Trimestrales'!B21 -> 2.5.2-1723.104 | C23: ='Necesidades Trimestrales'!E21 -> ANTISEPTICOS LOCALES P/PERSONA; TIPO: MONODROGA, DROGA GENERICA: IODOPOVIDONA 5 %, FORMA FARMACEUTICA: JABON LIQUIDO, PRESENTACION: ENVASE X 1 L | H23: SI | I23: ='Necesidades Trimestrales'!F21 -> BOTELLA | J23: ='Necesidades Trimestrales'!H21 -> 450 | K23: ='Necesidades Trimestrales'!G21 -> 30
... A29: 18 | B29: ='Necesidades Trimestrales'!B27 -> 2.5.2-1723.89 | C29: ='Necesidades Trimestrales'!E27 -> ANTISEPTICOS LOCALES P/PERSONA; TIPO: MONODROGA, DROGA GENERICA: TINTURA DE IODO FUERTE, FORMA FARMACEUTICA: SOLUCION, PRESENTACION: ENVASE X 1 L | H29: NO | I29: ='Necesidades Trimestrales'!F27 -> BOTELLA | J29: ='Necesidades Trimestrales'!H27 -> 989 | K29: ='Necesidades Trimestrales'!G27 -> 5
A30: Costo total estimado: Pesos Un millon doscientos cuarenta y dos mil quinientos veinticuatro con 00/100.- | J30: =SUMPRODUCT(J12:J29,K12:K29) -> 1242524

Sheet Autor Gastar
A1: EJERCICIO: | D1: ='Necesidades Trimestrales'!C6 -> 2022 | P1: AUTORIZACION PARA GASTAR
A4: JURISDICCIÓN: | G4: =[1]NotaPedido!D3 -> 40 - Ministerio de Salud
A5: SAF: | G5: =[1]NotaPedido!D4 -> 23 - Hospital Interzonal San Juan Bautista
A6: UNIDAD EJECUTORA: | G6: =[1]NotaPedido!D5 -> 168 - Direccion Asistencial
A7: DEPENDENCIA SOLICITANTE: | G7: =[1]NotaPedido!D6 -> Servicio de Farmacia
A8: AUTORIZACIÓN:
A9: Señor Jefe de Servicio Administrativo Financiero:
A10: ="Autorizo la realización de los trámites correspondientes, a fin de proveer a este Organismo los bienes y/o servicios que se detallan en Nota de Pedido N° " & [1]NotaPedido!K1&", afectando la erogación resultante a los créditos presupuestarios aprobados a favor de esta Unidad Ejecutora, conforme al siguiente detalle:" -> Autorizo la realización de los trámites correspondientes, a fin de proveer a este Organismo los bienes y/o servicios que se detallan en Nota de Pedido N° 027 - 2022, afectando la erogación resultante a los créditos presupuestarios aprobados a favor de esta Unidad Ejecutora, conforme al siguiente detalle:
A12: IMPUTACIÓN PRESUPUESTARIA
A13: CÓDIGO | O13: DENOMINACIÓN DE LA PARTIDA PRESUPUESTARIA | Q13: IMPORTE
A14: PR | B14: SB | C14: PY | D14: AC | E14: OB | F14: UG | G14: FIN | H14: FUN | I14: I | J14: P | K14: P | L14: SubP | M14: M | N14: FF
A15: 33 | D15: 2 | F15: 4901 | G15: 3 | H15: 3.1 | I15: 2 | J15: 5 | K15: 1 | M15: 1 | N15: 1.1 | O15: Compuestos Quimicos | Q15: 449032
A16: 33 | D16: 2 | F16: 4901 | G16: 3 | H16: 3.1 | I16: 2 | J16: 5 | K16: 2 | M16: 1 | N16: 1.1 | O16: Productos Farmaceuticos y Medicinales | Q16: 793492
A22: TOTAL DE PESOS: UN MILLON DOSCIENTOS CUARENTA Y DOS MIL QUINIENTOS VEINTICUATRO CON 00/100.---- | Q22: =SUM(Q15:Q21) -> 1242524
A24: JUSTIFICACIÓN:
A25: ="Para la "& [1]NotaPedido!D8 &" para ser destinados al " & [1]NotaPedido!D6 &" del HISJB del Ministerio de Salud." -> Para la Adquisición de Antisepticos y Desinfectantes para ser destinados al Servicio de Farmacia del HISJB del Ministerio de Salud.
