Workbook

Sheet SAF 011
A1: 2022
B2: Pedido de Necesidades Trimestrales
A4: JURISDICCION: | C4: 040 - MINISTERIO DE SALUD
A5: SAF N°: | C5: 011 - DIRECCION PROVINCIAL DE ADMINISTRACION - MINISTERIO DE SALUD
A6: EJERCICIO: | C6: 2022
A7: TRIMESTRE: | C7: TERCERO
A9: ID | B9: CODIGO ITEM | C9: RUBRO DE COMPRA | D9: I.P.P. | E9: DESCRIPCION | F9: UNIDAD DE MEDIDA | G9: SECRETARIA DE ADMINISTRACION | H9: TOTAL S.A. | I9: SMPyPS | J9: TOTAL SMPyPS | K9: DIR. LAB. CENTRAL | L9: TOTAL DE LAB CENTRAL | M9: BCO DE SANGRE | N9: TOTAL BANCO DE SANGRE | O9: APS | P9: TOTAL A.P.S. | Q9: DIR DE CANCER | R9: TOTAL DE DIR DE CANCER | S9: FARMACIA | T9: TOTAL FARMACIA | U9: ODONTOLOGIA | V9: TOTAL DE ODONTOLOG | W9: SAME | X9: TOTAL SAME | Y9: UAI | Z9: TOTAL UAI | AA9: MATERNIDAD E INFANCIA | AB9: TOTAL MATERNIDAD E INFANCIA | AC9: SASP | AD9: TOTAL SASP | AE9: SALUD Y MEDIO AMBIENTE | AF9: TOTAL SALUD Y MEDIO AMBIENTE | AG9: VECTORES Y ZOONOSIS | AH9: TOTAL DE VECT Y ZOON | AI9: DISCAPACIDAD | AJ9: TOTAL DISCAPACIDAD | AK9: REG Y CONTROL EN SALUD | AL9: TOTAL REG Y CONTROL EN SALUD | AM9: SPyGS | AN9: TOTAL SPyGS | AO9: SALUD MENTAL | AP9: TOTAL SALUD MENTAL | AQ9: AREAS Y DPAS | AR9: TOTAL DPAS | AS9: EPIDEMIOLOGIA | AT9: TOTAL EPIDEMIOLOGIA | AU9: MS | AV9: TOTAL MS | AW9: SUMAR | AX9: TOTAL SUMAR | AY9: CANTIDAD TOTAL | AZ9: PRECIO UNITARIO ESTIMADO | BA9: IMPORTE TOTAL ESTIMADO | BB9: ESPECIFICACION TECNICA
A10: 1 | B10: 2.5.6-793.31 | C10: COMBUSTIBLES Y LUBRICANTES | D10: 2.5.6 | E10: GAS OIL; PRESENTACION: POR LITRO, USO: MOTORES DIESEL,COMERCIALIZACION: GRADO 3, DESTINO: DPTO. S.F.V. DE CATAMARCA | F10: LITROS | I10: 1400 | J10: =+I10*AZ10 -> 264600 | M10: 1200 | N10: =+M10*AZ10 -> 226800 | P10: =+O10*AZ10 -> 0 | R10: =+Q10*AZ10 -> 0 | U10: 2000 | V10: =+U10*AZ10 -> 378000 | W10: 15000 | X10: =+W10*AZ10 -> 2835000 | AA10: 3000 | AB10: =+AA10*AZ10 -> 567000 | AC10: 3500 | AD10: =+AC10*AZ10 -> 661500 | AE10: 1300 | AF10: =+AE10*AZ10 -> 245700 | AG10: 1200 | AH10: =+AG10*AZ10 -> 226800 | AI10: 800 | AJ10: =+AI10*AZ10 -> 151200 | AL10: =+AK10*AZ10 -> 0 | AM10: 2000 | AN10: =+AM10*AZ10 -> 378000 | AO10: 800 | AP10: =+AO10*AZ10 -> 151200 | AQ10: 80998 | AR10: =+AQ10*AZ10 -> 15308622 | AS10: 700 | AT10: =+AS10*AZ10 -> 132300 | AU10: 2100 | AV10: =+AU10*AZ10 -> 396900 | AW10: 400 | AX10: =+AW10*AZ10 -> 75600 | AY10: =+AQ10+AO10+AM10+AK10+AI10+AG10+AE10+AC10+AA10+Y10+W10+U10+S10+Q10+O10+M10+K10+I10+AS10+G10+AU10+AW10 -> 116398 | AZ10: 189 | BA10: =+AY10*AZ10 -> 21999222 | BB10: Se Entregarán Fraccionado bajo la forma de vales de 30 Lts. cada uno y cuando la cantidad adjudicada no permita la confección de dicho vale, para completar se emitirá uno por una cantidad menor hasta completar la cantidad solicitada
E11: TOTAL RUBRO COMBUSTIBLES | P11: =+O11*AZ11 -> 0 | BA11: =+SUM(BA10:BA10) -> 21999222
C14: ITEM 1
C15: DETALLE TECNICO Y ESPECIFICACIONES | D15: Se Entregarán Fraccionado bajo la forma de vales de 30 Lts. cada uno y cuando la cantidad adjudicada no permita la confección de dicho vale, para completar se emitirá uno por una cantidad menor hasta completar la cantidad solicitada
C17: SE ADJUNTA ANEXO CON LOS DOMINIOS Y MATRICULA DE LOS VEHICULOS PARA LOS QUE SE SOLICITA EL COMBUSTIBLE
C19: Plazos de entrega | D19: cinco (5) dias habiles
C21: Lugar de Entrega: | D21: SECRETARIA DE ADMINISTRACION - MS - CHACABUCO N° 169 - en el horario de 8:00hs a 12:00hs de lunes a viernes
C23: Calidad Minima esperada
C25: Mantenimiento | D25: cuarenta y cinco (45) días

Sheet ANEXO
A1: DIRECCION PROVINCIAL ASISTENCIA SANITARIA NIVEL I Y II
A3: Vehiculo | B3: Dominio | C3: Nº de Motor | D3: Nº Chasis | E3: Año
A4: TOYOTA HYLUX 4x4 CABINA DOBLE SR3.0 TDI. Camioneta.- | B4: OMA-771 | C4: 1KDA586508 | D4: 8AJFZZ263F5027841 | E4: 2015
A6: Area Programatica Nº1
A8: Vehiculo | B8: Dominio | C8: Nº de Motor | D8: Nº Chasis | E8: Año
A9: Renault Master - Ambulancia.- | B9: GEU-277 | C9: G9UA724C030714 | D9: 93YADCUE57J787157 | E9: 2007
A10: Renault Master- Ambulancia.- | B10: GUV-922 | C10: G9UA724C035587 | D10: 93YADCUE58J896449 | E10: 2008
A11: Renault Master-PH3 DCI 120 L1H2 Ambulancia.- | B11: KNI-753 | C11: G9UA754C268409 | D11: 93YADCUE6CJ897389 | E11: 2011
A12: Ford F-100 4x2 XL PLUS 3,9 D - Ambulacia.- | B12: ILC-099 | C12: 36071580 | D12: 9EFFF22C99B859146 | E12: 2010
A13: Renault Master PH3 DCI 120 L1H2 - Ambulancia.- | B13: LAD-136 | C13: G9UA754C270571 | D13: 93YADCUE6CJ969873 | E13: 2012
A14: Fiat Ducato. Ambulancia.- | B14: NHW-650 | C14: 7173538 | D14: 93W245G84D2112772 | E14: 2013
A15: Mercedez Benz Sprinter Furgon.- | B15: GWJ-779 | C15: 61198170074458 | D15: 8AC90036628A984192 | E15: 2008
A16: Renault Master MASTER PH3 DCI 120 - Ambulancia.- | B16: LAD-135 | C16: G9UA650C244170 | D16: 93YADC1E6CJ140233 | E16: 2012
A17: Renault Master DCI 120 - Ambulancia.- | B17: GJP-880 | C17: G9UA724C026899 | D17: 93YADCUH56J706159 | E17: 2007
A18: Chevrolet S-10. Camioneta.- | B18: GWJ-742 | C18: M1A304122 | D18: 9BG124AJ08C11312 | E18: 2008
A19: Chevrolet Zafira. Camioneta.- | B19: HUD-575 | C19: 1N0006130 | D19: 9BGTT75F09C131088 | E19: 2008
A20: Fiat Ducato Amxicargo 2,3 JTD. Ambulancia.- | B20: AA-842-EL | C20: 7250765 | D20: 93W245G84H2160838 | E20: 2016
A21: Fiat Ducato Amxicargo 2,3 JTD. Ambulancia.- | B21: AA-842-EI | C21: 7250728 | D21: 93W245G84H2160833 | E21: 2016
A22: Toyota Hilux 4x4 c/s DX 2,4 TDI M/T. Ambulancia | B22: AA-793-NE | C22: 2GD-0137533 | D22: 8AJFB8CB5H1550878 | E22: 2017
A23: Renault Master- Ambulancia.- | B23: AE-041-BD | C23: M9TB870C262154 | D23: 93YMAFESCLJ213469 | E23: 2020
A25: Area Programatica Nº2
A27: Vehiculo | B27: Dominio | C27: Nº de Motor | D27: Nº Chasis | E27: Año
A28: Fiat Ducato Maxi cargo 2,3 JTD Furgon. Ambulancia.- | B28: AA-842-EH | C28: 7250726 | D28: 93W245G84H2160832 | E28: 2016
A29: Fiat Ducato Maxi cargo 2,3 JTD Furgon. Ambulancia.- | B29: AA-842-EF | C29: 7250640 | D29: 93W245G84H2160831 | E29: 2016
A30: Fiat Ducato 2,3. Ambulancia.- | B30: NSE-229 | C30: 7166125 | D30: 93W245G74D2109008 | E30: 2014
A31: Renault Master DCI120. Ambulancia - | B31: GUO-325 | C31: G9UA7240035511 | D31: 93YADCUE58J896313 | E31: 2007
A32: Renault Master DCI120 - Ambulancia .- | B32: GJS-713 | C32: G9UA724C030282 | D32: 93YADCUE57J787718 | E32: 2007
A33: Fiat iveco Daily. Ambulancia.- | B33: S/P | C33: 37344067044 | D33: 93ZC4980158318123 | E33: 2005
A34: Ford Ranger XLC/C 4x4 2,8. Camioneta.- | B34: FYK-918 | C34: B61618215 | D34: 8AFER13FX4J326463 | E34: 2007
A36: Area Programatica Nº3
A38: Vehiculo | B38: Dominio | C38: Nº de Motor | D38: Nº Chasis | E38: Año
A39: Chevrolet S10 2,8 TDI - Camioneta.- | B39: GDD-914 | C39: M1A282868 | D39: 9BG138AJ07C413213 | E39: 2007
A40: Renautl Master 2,5 D - Ambulancia.- | B40: GJC-299 | C40: J9UA724C030522 | D40: 93YADCUE57J787225 | E40: 2007
A41: Fiat Ducato Maxi cargo 2,3. Ambulancia | B41: AA-702-MN | C41: 7251288 | D41: 93W245G74H2161118 | E41: 2016
A42: Ford Transit 2,2 L 125 T350 TA C/AA - Ambulancia.- | B42: MNW-258 | C42: CYRCDTT22471 | D42: WFOXXPTTFDTT22471 | E42: 2013
A43: Mercedez Benz Sprinter - Ambulancia.- | B43: DCA-098 | C43: 10520880 | D43: 8AC690311YA537631 | E43: 1998
A44: Chevrolet S10 2,8 T.I- Ambulancia.- | B44: ESH-451 | C44: 40704192268 | D44: 986124AC05C410447 | E44: 2014
A46: Area Programatica Nº 4
A48: Vehiculo | B48: Dominio | C48: Nº de Motor | D48: Nº Chasis | E48: Año
A49: Chevrolet S10 2,8 TDI SID 4x2 - Ambulancia.- | B49: GDD-918 | C49: M1A282927 | D49: 9BG1384J07C413214 | E49: 2007
...

Sheet NP
A1: NOTA DE PEDIDO | J1: N° | K1: XX/2022
A3: JURISDICCIÓN: | D3: ='SAF 011'!C4 -> 040 - MINISTERIO DE SALUD
A4: SAF: | D4: ='SAF 011'!C5 -> 011 - DIRECCION PROVINCIAL DE ADMINISTRACION - MINISTERIO DE SALUD
A5: UNIDAD EJECUTORA: | D5: 352 - MINISTERIO DE SALUD
A6: DEPENDENCIA SOLICITANTE: | D6: 352 - MINISTERIO DE SALUD
A7: PERIODO UTILIZACIÓN: | D7: 3° TRIMESTRE 2022
A8: OBJETO: | D8: ADQ. DEL RUBRO COMBUSTIBLE (GAS OIL) PARA LAS DEPENDENCIAS DEL MINISTERIO DE SALUD
A10: Ítem | B10: Codigo Item | C10: DESCRIPCIÓN | H10: Adjunta Detalle Técnico | I10: Unidad Medida | J10: Precio Unitario Estimado | K10: Cantidad Solicitada
A12: 1 | B12: ='SAF 011'!B10 -> 2.5.6-793.31 | C12: ='SAF 011'!E10 -> GAS OIL; PRESENTACION: POR LITRO, USO: MOTORES DIESEL,COMERCIALIZACION: GRADO 3, DESTINO: DPTO. S.F.V. DE CATAMARCA | H12: SI | I12: ='SAF 011'!F10 -> LITROS | J12: ='SAF 011'!AZ10 -> 189 | K12: ='SAF 011'!AY10 -> 116398
A14: Costo total estimado: PESOS VEINTIUN MILLONES NOVECIENTOS NOVENTA Y NUEVE MIL DOSCIENTOS VEINTIDOS CON 00/100.- | J14: =+J12*K12 -> 21999222

Sheet APG
A1: EJERCICIO: | D1: 2022 | P1: AUTORIZACION PARA GASTAR
A4: JURISDICCIÓN: | G4: =NP!D3 -> 040 - MINISTERIO DE SALUD
A5: SAF: | G5: =NP!D4 -> 011 - DIRECCION PROVINCIAL DE ADMINISTRACION - MINISTERIO DE SALUD
A6: UNIDAD EJECUTORA: | G6: =NP!D5 -> 352 - MINISTERIO DE SALUD
A7: DEPENDENCIA SOLICITANTE: | G7: =NP!D6 -> 352 - MINISTERIO DE SALUD
A8: AUTORIZACIÓN:
A9: Señor Director de Administración o Titular del Servicio Administrativo Financiero:
A10: Autorizo la realización de los trámites correspondientes, a fin de proveer a este Organismo los bienes que se detallan en Nota de Pedido N° XX/2022 , afectando la erogación resultante a los créditos presupuestarios aprobados a favor de esta Unidad Ejecutora, conforme al siguiente detalle:
A12: IMPUTACIÓN PRESUPUESTARIA
A13: CÓDIGO | O13: DENOMINACIÓN DE LA PARTIDA PRESUPUESTARIA | Q13: IMPORTE
A14: PR | B14: SB | C14: PY | D14: AC | E14: OB | F14: UG | G14: FIN | H14: FUN | I14: I | J14: P | K14: P | L14: SubP | M14: M | N14: FF
A15: 1 | D15: 1 | F15: 4901 | G15: 3 | H15: 1 | I15: 2 | J15: 5 | K15: 6 | M15: 1 | N15: 1.1 | O15: COMBUSTIBLES Y LURBICANTES | Q15: =NP!J14 -> 21999222
A38: TOTAL DE PESOS: VEINTIUN MILLONES NOVECIENTOS NOVENTA Y NUEVE MIL DOSCIENTOS VEINTIDOS CON 00/100.- | Q38: =SUM(Q15:Q37) -> 21999222
A40: JUSTIFICACIÓN:
A41: =NP!D8 -> ADQ. DEL RUBRO COMBUSTIBLE (GAS OIL) PARA LAS DEPENDENCIAS DEL MINISTERIO DE SALUD
