Workbook

Sheet SAF 011
B1: 2022
C2: Pedido de Necesidades Trimestrales
B4: JURISDICCION: | D4: 040 - MINISTERIO DE SALUD
B5: SAF N°: | D5: 011 - DIRECCION PROVINCIAL DE ADMINISTRACION - MINISTERIO DE SALUD
B6: EJERCICIO: | D6: 2022
B7: TRIMESTRE: | D7: CUARTO
B9: ID | C9: CODIGO ITEM | D9: RUBRO DE COMPRA | E9: I.P.P. | F9: DESCRIPCION | G9: UNIDAD DE MEDIDA | H9: S.A. | I9: TOTAL S.A. | J9: SMPyPS | K9: TOTAL SMPyPS | L9: DIR. LAB. CENTRAL | M9: TOTAL DE LAB CENTRAL | N9: BCO DE SANGRE | O9: TOTAL BANCO DE SANGRE | P9: APS | Q9: TOTAL A.P.S. | R9: DIR DE CANCER | S9: TOTAL DE DIR DE CANCER | T9: FARMACIA | U9: TOTAL FARMACIA | V9: ODONTOLOGIA | W9: TOTAL DE ODONTOLOG | X9: SAME | Y9: TOTAL SAME | Z9: UAI | AA9: TOTAL UAI | AB9: MATERNIDAD E INFANCIA | AC9: TOTAL MATERNIDAD E INFANCIA | AD9: SASP | AE9: TOTAL SASP | AF9: SALUD Y MEDIO AMBIENTE | AG9: TOTAL SALUD Y MEDIO AMBIENTE | AH9: VECTORES Y ZOONOSIS | AI9: TOTAL DE VECT Y ZOON | AJ9: DISCAPACIDAD | AK9: TOTAL DISCAPACIDAD | AL9: REG Y CONTROL EN SALUD | AM9: TOTAL REG Y CONTROL EN SALUD | AN9: SPyGS | AO9: TOTAL SPyGS | AP9: SALUD MENTAL | AQ9: TOTAL SALUD MENTAL | AR9: AREAS Y DPAS | AS9: TOTAL DPAS | AT9: EPIDEMIOLOGIA | AU9: TOTAL EPIDEMIOLOGIA | AV9: MS | AW9: TOTAL MS | AX9: SUMAR | AY9: TOTAL SUMAR | AZ9: SIRM | BA9: TOTAL SIRM | BB9: CANTIDAD TOTAL | BC9: PRECIO UNITARIO ESTIMADO | BD9: IMPORTE TOTAL ESTIMADO | BE9: ESPECIFICACION TECNICA
B10: 1 | C10: 2.5.6-793.29 | D10: COMBUSTIBLES Y LUBRICANTES | E10: 2.5.6 | F10: GAS OIL; PRESENTACION: POR LITRO, USO: MOTORES DIESEL, COMERCIALIZACION: GRADO 3 | G10: LITROS | H10: 700 | I10: =+H10*BC10 -> 166040 | P10: 250 | Q10: =+P10*BC10 -> 59300 | X10: 21000 | Y10: =+X10*BC10 -> 4981200 | AD10: 16000 | AE10: =+AD10*BC10 -> 3795200 | AF10: 1500 | AG10: =+AF10*BC10 -> 355800 | AH10: 700 | AI10: =+AH10*BC10 -> 166040 | AJ10: 550 | AK10: =+AJ10*BC10 -> 130460 | AR10: 31500 | AS10: =+AR10*BC10 -> 7471800 | AV10: 1700 | AW10: =+AV10*BC10 -> 403240 | AX10: 0 | AY10: =+AX10*BC10 -> 0 | AZ10: 11000 | BA10: =+AZ10*BC10 -> 2609200 | BB10: =+AR10+AP10+AN10+AL10+AJ10+AH10+AF10+AD10+AB10+Z10+X10+V10+T10+R10+P10+N10+L10+J10+AT10+H10+AV10+AX10+AZ10 -> 84900 | BC10: 237.2 | BD10: =+BB10*BC10 -> 20138280 | BE10: Se Entregarán Fraccionado bajo la forma de vales de 30 Lts. cada uno y cuando la cantidad adjudicada no permita la confección de dicho vale, para completar se emitirá uno por una cantidad menor hasta completar la cantidad solicitada
F11: TOTAL RUBRO COMBUSTIBLES | Q11: =+P11*BC11 -> 0 | BD11: =+SUM(BD10:BD10) -> 20138280
D13: ITEM 1
D14: DETALLE TECNICO Y ESPECIFICACIONES | E14: *Se Entregarán Fraccionado bajo la forma de vales de 30 Lts. cada uno y cuando la cantidad adjudicada no permita la confección de dicho vale, para completar se emitirá uno por una cantidad menor hasta completar la cantidad solicitada.
D15: *Los ofertantes deberan garantizar la provision del insumo en el interior de la provincia de Catamarca, contando con surtidores ubicados en el Valle Central y en por lo menos dos zonas del interior de la provincia, preferentemente Este y Oeste Catamarqueño.
D17: SE ADJUNTA ANEXO CON LOS DOMINIOS Y MATRICULA DE LOS VEHICULOS PARA LOS QUE SE SOLICITA EL COMBUSTIBLE
D19: Plazos de entrega | E19: cinco (5) dias habiles
D21: Lugar de Entrega: | E21: SECRETARIA DE ADMINISTRACION - MS - CHACABUCO N° 169 - en el horario de 8:00hs a 12:00hs de lunes a viernes
D23: Calidad Minima esperada
D25: Mantenimiento | E25: cuarenta y cinco (45) días

Sheet ANEXO DOM VEHICULOS
A1: ANEXO VEHICULOS MINISTERIO DE SALUD
B3: Vehiculo | C3: Dominio | D3: Nº de Motor | E3: Nº de Chasis | F3: Año | G3: USO
A4: 1 | B4: Fiat Ducato Maxi Carga Multijet JTD Furgon. Ambulancia.- | C4: NUB-239 | D4: 7166186 | E4: 93W245G74D2109186 | F4: 2014 | G4: AMBULANCIA
A5: 2 | B5: Fiat Ducato Maxi Carga Multijet JTD Furgon. Ambulancia.- | C5: NWM-372 | D5: 7167174 | E5: 93W245G74D2109552 | F5: 2014 | G5: AMBULANCIA
A6: 3 | B6: Fiat Ducato Maxi Carga Multijet JTD Furgon. Ambulancia.- | C6: NYF-582 | D6: 7188314 | E6: 93W245G74E2121568 | F6: 2014 | G6: AMBULANCIA
A7: 4 | B7: Fiat Ducato Maxi Carga Multijet JTD Furgon. Ambulancia.- | C7: AA-658-GZ | D7: 72497599 | E7: 93W245G84H2161256 | F7: 2017 | G7: AMBULANCIA
A8: 5 | B8: Fiat Ducato Maxi Carga Multijet. Ambulancia.- | C8: AA-702-NG | D8: 72497500 | E8: 93W245G82H2160424 | F8: 2017 | G8: AMBULANCIA
A9: 6 | B9: Fiat Ducato Maxi Carga Multijet JTD Furgon. Ambulancia.- | C9: MPH-712 | D9: 7155140 | E9: 93W245G84D2102211 | F9: 2013 | G9: AMBULANCIA
A10: 7 | B10: Fiat Ducato Maxi Carga Multijet JTD Furgon. Ambulancia.- | C10: AB-518-CS | D10: 7257521 | E10: 93W245G84H2165048 | F10: 2017 | G10: AMBULANCIA
A11: 8 | B11: Fiat Ducato Maxi Carga Multijet JTD Furgon. Ambulancia.- | C11: AB-518-CT | D11: 7257618 | E11: 93W245G84H2165113 | F11: 2017 | G11: AMBULANCIA
A12: 9 | B12: Renault Master L2H2 AA. Amubulancia.- | C12: AD-993-OD | D12: M9TB870C260128 | E12: 93YMAFESCKJ625829 | F12: 2019 | G12: AMBULANCIA
A13: 10 | B13: Renault Master L2H2 AA. Amubulancia.- | C13: AD-993-OC | D13: M9TB870C260095 | E13: 93YMAFESCKJ625788 | F13: 2019 | G13: AMBULANCIA
A14: 11 | B14: Ford Transit 2,2 TDCI. Furgon. Ambulancia.- | C14: LYY-038 | D14: WF0XXPTTFCTC58018 | E14: CYRCCTC58018 | F14: 2013 | G14: AMBULANCIA
A15: 12 | B15: Ford Transit 2,2 L 125 T350 TA C/AA. Furgon Larga. Neonatal. Ambuancia.- | C15: MNW-260 | D15: CYRCDTS07184 | E15: WFOXXPTTFDTS07184 | F15: 2013 | G15: AMBULANCIA
A16: 13 | B16: Mercedez Benz Sprinter 313, combi 3550 9+1. Combi.- | C16: HQV-791 | D16: 61198170090932 | E16: 8AC9036629E010749 | F16: 2008 | G16: OFICIAL
A17: 14 | B17: Frod Ranger XL 3,0 TDI DC 4x4 Plus L. Camioneta.- | C17: JRJ-105 | D17: L1A008818 | E17: 8AFER13P48J398152 | F17: 2011 | G17: transp.combustible
A18: 15 | B18: Mercedez Benz 1114 Camion.- | C18: K-0022935 | D18: 37290710141314 | E18: 38400712097854 | F18: 1993 | G18: OFICIAL
A19: 16 | B19: Tanqueta Grosspal, chasis EGT2895,.- | C19: 101-JRJ105 | G19: transp.combustible
A20: 17 | B20: Ford Ranger DC 4X4 L 2.2L. Camioneta.- | C20: AD-398-KY | D20: QJ2RKJ113446 | E20: 8AFAR23KXKJ113446 | F20: 2018 | G20: OFICIAL
A21: 18 | B21: Ford Rnger XL 3,0 TDI D/C 4x4 Plus Camioneta..- | C21: FPU-504 | D21: C34197293 | E21: 8SAFDR13P56J473958 | F21: 2008 | G21: OFICIAL
A22: 19 | B22: Toyota Hilux SW4 4X4 SRX 2,8 TDI 6 M/T 7A. Camioneta.- | C22: AD-125-XM | D22: 1GD-G029980 | E22: 8AJBA3FS8H026028 | F22: 2018 | G22: OFICIAL
A23: 20 | B23: Chevrolet Blazer DLX 2,8 TDI. Camioneta.- | C23: GRL-150 | D23: M1A301900 | E23: 9BG116BJ08C407853 | F23: 2007 | G23: OFICIAL
A24: 21 | B24: Chevrolet Meriva GL 1,7 DTI. Sedan.- | C24: EQN-369 | D24: Y17DT0881965 | E24: 9BGXF75804C217860 | F24: 2006 | G24: OFICIAL
A25: 22 | B25: Iveco Turbo Daily 49,12 Chasis. Furgon.- | C25: GEG-132 | D25: 36214211157 | E25: 93ZC4980168323467 | F25: 2007 | G25: serv.especiales
A26: 23 | B26: Renault Master 2,3 DC I Furgon.- | C26: PIQ-472 | D26: M9TA876C029626 | E26: 93YMAIECATGJ94529 | F26: 2015 | G26: serv.especiales
A27: 24 | B27: TOYOTA HYLUX 4x4 CABINA DOBLE SR3.0 TDI. Camioneta.- | C27: OMA-771 | D27: 1KDA586508 | E27: 8AJFZZ263F5027841 | F27: 2015 | G27: OFICIAL
A28: 25 | B28: Ford Ranger 3,0 TDI SC 4x2 Plus. Camioneta- | C28: INA-475 | D28: D56285125 | E28: 8AFDR12P4AJ285846 | F28: 2009 | G28: OFICIAL
A29: 26 | B29: Chevrolet S10 2,8 TDI 4x2 D/C DLX EL. Camioneta.- | C29: FSI-818 | D29: M1T253871 | E29: 9BG138AC06C417378 | F29: 2005 | G29: OFICIAL
A30: 27 | B30: Crysler RAM laramie 1500 pick up 4x4 doble cabina. Camioneta.- | C30: AD-189-SN | D30: TNXE6209711768 | E30: 3C6RRBET7HG94960 | F30: 2017 | G30: OFICIAL
A31: 28 | B31: Chevrolet S10 2,8 TDI 4x2 D/C DLX EL. Camioneta.- | C31: GAJ-557 | D31: M1T241375 | E31: 9BG138AC06C426943 | F31: 2007 | G31: OFICIAL
A32: 29 | B32: VW Caddy 1,9 SD. Furgon.- | C32: DMQ-710 | D32: 1Y635412 | E32: 8AWZZZ9EZYA520052 | F32: 2000 | G32: OFICIAL
A33: 30 | B33: Ford Rnger XL 3,0 TDI D/C 4x2 Plus. Camioneta.- | C33: GVM-697 | D33: C34243556 | E33: 8AFER13P58J133751 | F33: 2007 | G33: OFICIAL
A34: 31 | B34: Ford Ranger XL T 3,0 TDI D/C 4x4 LIM. Camioneta.- | C34: GVU-547 | D34: C34243362 | E34: 8AFER13P18J133746 | F34: 2007 | G34: OFICIAL
A35: 32 | B35: Ford Ranger XL T 3,0 TDI D/C 4x2 PLUS. Camioneta.- | C35: IPE-911 | D35: D56289530 | E35: 8AFER10P6AJ299531 | F35: 2010 | G35: OFICIAL
A36: 33 | B36: Ford Ranger DC 4x2 XL Plus 3,0 D. Camioneta.- | C36: LCA-236 | D36: L1A029545 | E36: 8AFDR12PXCJ490431 | F36: 2012 | G36: OFICIAL
A37: 34 | B37: Fiat Ducato. Minibus.- | C37: AD-266-ZZ | D37: 7253701 | E37: 93W245G84H2162641 | F37: 2017 | G37: serv.especiales
A38: 35 | B38: Renault trafic. Furgon.- | C38: DNR-926 | D38: FSQJ606C012115 | E38: 8A1T31JZZYL086918 | F38: 1999 | G38: OFICIAL
A39: 36 | B39: Chevrolet S10 2,8 TED 4X2 LS Pick up . Camioneta.- | C39: AC-091-RR | D39: HRUF171781023 | E39: 9BG148CK0JC414811 | F39: 2017 | G39: OFICIAL
A40: 37 | B40: Ford Rnger XL 3,0 TDI D/C 4x2. Camioneta.- | C40: IPE-916 | D40: D56290126 | E40: 8AFER10P7AJ299795 | F40: 2010 | G40: OFICIAL
A41: 38 | B41: Toyota hylux AK-SW4-4x4 SRX 2,8 TDI. Camioneta.- | C41: AD-125-XL | D41: 1GD-4378200 | E41: 8AJBA3FS8J0250098 | F41: 2018 | G41: OFICIAL
...

Sheet NP S.A.
A1: NOTA DE PEDIDO | J1: N° | K1: XX/2022
A3: JURISDICCIÓN: | D3: ='SAF 011'!D4 -> 040 - MINISTERIO DE SALUD
A4: SAF: | D4: ='SAF 011'!D5 -> 011 - DIRECCION PROVINCIAL DE ADMINISTRACION - MINISTERIO DE SALUD
A5: UNIDAD EJECUTORA: | D5: 082 - DIR. PROV. DE ADMINISTRACION DEL MINISTERIO DE SALUD
A6: DEPENDENCIA SOLICITANTE: | D6: 082 - DIR. PROV. DE ADMINISTRACION DEL MINISTERIO DE SALUD
A7: PERIODO UTILIZACIÓN: | D7: 3 MESES
A8: OBJETO: | D8: ADQUISICION DEL RUBRO COMBUSTIBLE (GAS OIL)
A10: Ítem | B10: Codigo Item | C10: DESCRIPCIÓN | H10: Adjunta Detalle Técnico | I10: Unidad Medida | J10: Precio Unitario Estimado | K10: Cantidad Solicitada
A12: 1 | B12: ='SAF 011'!C10 -> 2.5.6-793.29 | C12: ='SAF 011'!F10 -> GAS OIL; PRESENTACION: POR LITRO, USO: MOTORES DIESEL, COMERCIALIZACION: GRADO 3 | H12: SI | I12: ='SAF 011'!G10 -> LITROS | J12: ='SAF 011'!BC10 -> 237.2 | K12: ='SAF 011'!H10 -> 700
A14: Costo total estimado: PESOS CIENTO SESENTA Y SEIS MIL CUARENTA CON 00/100.- | J14: =+K12*J12 -> 166040

Sheet APG S.A.
A1: EJERCICIO: | D1: 2022 | P1: AUTORIZACION PARA GASTAR
A4: JURISDICCIÓN: | G4: ='NP S.A.'!D3 -> 040 - MINISTERIO DE SALUD
A5: SAF: | G5: ='NP S.A.'!D4 -> 011 - DIRECCION PROVINCIAL DE ADMINISTRACION - MINISTERIO DE SALUD
A6: UNIDAD EJECUTORA: | G6: ='NP S.A.'!D5 -> 082 - DIR. PROV. DE ADMINISTRACION DEL MINISTERIO DE SALUD
A7: DEPENDENCIA SOLICITANTE: | G7: ='NP S.A.'!D6 -> 082 - DIR. PROV. DE ADMINISTRACION DEL MINISTERIO DE SALUD
A8: AUTORIZACIÓN:
A9: Señor Director de Administración o Titular del Servicio Administrativo Financiero:
A10: Autorizo la realización de los trámites correspondientes, a fin de proveer a este Organismo los bienes/servicios que se detallan en Nota de Pedido N° XX/2022 afectando la erogación resultante a los créditos presupuestarios aprobados a favor de esta Unidad Ejecutora, conforme al siguiente detalle:
A12: IMPUTACIÓN PRESUPUESTARIA
A13: CÓDIGO | O13: DENOMINACIÓN DE LA PARTIDA PRESUPUESTARIA | Q13: IMPORTE
A14: PR | B14: SB | C14: PY | D14: AC | E14: OB | F14: UG | G14: FIN | H14: FUN | I14: I | J14: P | K14: P | L14: SubP | M14: M | N14: FF
A15: 34 | D15: 1 | F15: 4901 | G15: 1 | H15: 6 | I15: 2 | J15: 5 | K15: 6 | M15: 1 | N15: 1.1 | O15: COMBUSTIBLES Y LUBRICANTES | Q15: ='NP S.A.'!J14 -> 166040
A38: TOTAL DE PESOS: CIENTO SESENTA Y SEIS MIL CUARENTA CON 00/100.- | Q38: =SUM(Q15:Q37) -> 166040
A40: JUSTIFICACIÓN:
A41: ='NP S.A.'!D8 -> ADQUISICION DEL RUBRO COMBUSTIBLE (GAS OIL)

Sheet NP APS
A1: NOTA DE PEDIDO | J1: N° | K1: XX/2022
A3: JURISDICCIÓN: | D3: ='SAF 011'!D4 -> 040 - MINISTERIO DE SALUD
A4: SAF: | D4: ='SAF 011'!D5 -> 011 - DIRECCION PROVINCIAL DE ADMINISTRACION - MINISTERIO DE SALUD
A5: UNIDAD EJECUTORA: | D5: 750 - DIRECCION PROVINCIAL PRIMER NIVEL DE ATENCION PRIMARIA DE LA SALUD
A6: DEPENDENCIA SOLICITANTE: | D6: 750 - DIRECCION PROVINCIAL PRIMER NIVEL DE ATENCION PRIMARIA DE LA SALUD
A7: PERIODO UTILIZACIÓN: | D7: 3 MESES
A8: OBJETO: | D8: ADQUISICION DEL RUBRO COMBUSTIBLE (GAS OIL)
A10: Ítem | B10: Codigo Item | C10: DESCRIPCIÓN | H10: Adjunta Detalle Técnico | I10: Unidad Medida | J10: Precio Unitario Estimado | K10: Cantidad Solicitada
A12: 1 | B12: ='SAF 011'!C10 -> 2.5.6-793.29 | C12: ='SAF 011'!F10 -> GAS OIL; PRESENTACION: POR LITRO, USO: MOTORES DIESEL, COMERCIALIZACION: GRADO 3 | H12: SI | I12: ='SAF 011'!G10 -> LITROS | J12: ='SAF 011'!BC10 -> 237.2 | K12: ='SAF 011'!P10 -> 250
A14: Costo total estimado: PESOS CINCUENTA Y NUEVE MIL TRESCIENTOS CON 00/100.- | J14: =+K12*J12 -> 59300

Sheet APG APS
A1: EJERCICIO: | D1: 2022 | P1: AUTORIZACION PARA GASTAR
A4: JURISDICCIÓN: | G4: ='NP APS'!D3 -> 040 - MINISTERIO DE SALUD
A5: SAF: | G5: ='NP APS'!D4 -> 011 - DIRECCION PROVINCIAL DE ADMINISTRACION - MINISTERIO DE SALUD
A6: UNIDAD EJECUTORA: | G6: ='NP APS'!D5 -> 750 - DIRECCION PROVINCIAL PRIMER NIVEL DE ATENCION PRIMARIA DE LA SALUD
A7: DEPENDENCIA SOLICITANTE: | G7: ='NP APS'!D6 -> 750 - DIRECCION PROVINCIAL PRIMER NIVEL DE ATENCION PRIMARIA DE LA SALUD
A8: AUTORIZACIÓN:
A9: Señor Director de Administración o Titular del Servicio Administrativo Financiero:
A10: Autorizo la realización de los trámites correspondientes, a fin de proveer a este Organismo los bienes/servicios que se detallan en Nota de Pedido N° XX/2022 afectando la erogación resultante a los créditos presupuestarios aprobados a favor de esta Unidad Ejecutora, conforme al siguiente detalle:
A12: IMPUTACIÓN PRESUPUESTARIA
A13: CÓDIGO | O13: DENOMINACIÓN DE LA PARTIDA PRESUPUESTARIA | Q13: IMPORTE
A14: PR | B14: SB | C14: PY | D14: AC | E14: OB | F14: UG | G14: FIN | H14: FUN | I14: I | J14: P | K14: P | L14: SubP | M14: M | N14: FF
A15: 47 | D15: 1 | F15: 4901 | G15: 3 | H15: 1 | I15: 2 | J15: 5 | K15: 6 | M15: 1 | N15: 1.1 | O15: COMBUSTIBLES Y LUBRICANTES | Q15: ='NP APS'!J14 -> 59300
A38: TOTAL DE PESOS: CINCUENTA Y NUEVE MIL TRESCIENTOS CON 00/100.- | Q38: =SUM(Q15:Q37) -> 59300
A40: JUSTIFICACIÓN:
A41: ='NP APS'!D8 -> ADQUISICION DEL RUBRO COMBUSTIBLE (GAS OIL)

Sheet NP SAME
A1: NOTA DE PEDIDO | J1: N° | K1: XX/2022
A3: JURISDICCIÓN: | D3: ='SAF 011'!D4 -> 040 - MINISTERIO DE SALUD
A4: SAF: | D4: ='SAF 011'!D5 -> 011 - DIRECCION PROVINCIAL DE ADMINISTRACION - MINISTERIO DE SALUD
A5: UNIDAD EJECUTORA: | D5: 748 - DIR. PROV. SISTEMA DE ATENCION MEDICA DE EMERGENCIA
A6: DEPENDENCIA SOLICITANTE: | D6: 748 - DIR. PROV. SISTEMA DE ATENCION MEDICA DE EMERGENCIA
A7: PERIODO UTILIZACIÓN: | D7: 3 MESES
A8: OBJETO: | D8: ADQUISICION DEL RUBRO COMBUSTIBLE (GAS OIL)
A10: Ítem | B10: Codigo Item | C10: DESCRIPCIÓN | H10: Adjunta Detalle Técnico | I10: Unidad Medida | J10: Precio Unitario Estimado | K10: Cantidad Solicitada
A12: 1 | B12: ='SAF 011'!C10 -> 2.5.6-793.29 | C12: ='SAF 011'!F10 -> GAS OIL; PRESENTACION: POR LITRO, USO: MOTORES DIESEL, COMERCIALIZACION: GRADO 3 | H12: SI | I12: ='SAF 011'!G10 -> LITROS | J12: ='SAF 011'!BC10 -> 237.2 | K12: ='SAF 011'!X10 -> 21000
A14: Costo total estimado: PESOS CUATRO MILLONES NOVECIENTOS OCHENTA Y UN MIL DOSCIENTOS CON 00/100.- | J14: =+K12*J12 -> 4981200

Sheet APG SAME
A1: EJERCICIO: | D1: 2022 | P1: AUTORIZACION PARA GASTAR
A4: JURISDICCIÓN: | G4: ='NP SAME'!D3 -> 040 - MINISTERIO DE SALUD
A5: SAF: | G5: ='NP SAME'!D4 -> 011 - DIRECCION PROVINCIAL DE ADMINISTRACION - MINISTERIO DE SALUD
A6: UNIDAD EJECUTORA: | G6: ='NP SAME'!D5 -> 748 - DIR. PROV. SISTEMA DE ATENCION MEDICA DE EMERGENCIA
A7: DEPENDENCIA SOLICITANTE: | G7: ='NP SAME'!D6 -> 748 - DIR. PROV. SISTEMA DE ATENCION MEDICA DE EMERGENCIA
A8: AUTORIZACIÓN:
A9: Señor Director de Administración o Titular del Servicio Administrativo Financiero:
A10: Autorizo la realización de los trámites correspondientes, a fin de proveer a este Organismo los bienes/servicios que se detallan en Nota de Pedido N° XX/2022 afectando la erogación resultante a los créditos presupuestarios aprobados a favor de esta Unidad Ejecutora, conforme al siguiente detalle:
A12: IMPUTACIÓN PRESUPUESTARIA
A13: CÓDIGO | O13: DENOMINACIÓN DE LA PARTIDA PRESUPUESTARIA | Q13: IMPORTE
A14: PR | B14: SB | C14: PY | D14: AC | E14: OB | F14: UG | G14: FIN | H14: FUN | I14: I | J14: P | K14: P | L14: SubP | M14: M | N14: FF
A15: 30 | D15: 1 | F15: 4901 | G15: 3 | H15: 1 | I15: 2 | J15: 5 | K15: 6 | M15: 1 | N15: 1.1 | O15: COMBUSTIBLES Y LUBRICANTES | Q15: ='NP SAME'!J14 -> 4981200
A38: TOTAL DE PESOS: CUATRO MILLONES NOVECIENTOS OCHENTA Y UN MIL DOSCIENTOS CON 00/100.- | Q38: =SUM(Q15:Q37) -> 4981200
A40: JUSTIFICACIÓN:
A41: ='NP SAME'!D8 -> ADQUISICION DEL RUBRO COMBUSTIBLE (GAS OIL)

Sheet NP SASP
A1: NOTA DE PEDIDO | J1: N° | K1: XX/2022
A3: JURISDICCIÓN: | D3: ='SAF 011'!D4 -> 040 - MINISTERIO DE SALUD
A4: SAF: | D4: ='SAF 011'!D5 -> 011 - DIRECCION PROVINCIAL DE ADMINISTRACION - MINISTERIO DE SALUD
A5: UNIDAD EJECUTORA: | D5: 743 - SECRETARIA DE ASISTENCIA EN SALUD PUBLICA
A6: DEPENDENCIA SOLICITANTE: | D6: 743 - SECRETARIA DE ASISTENCIA EN SALUD PUBLICA
A7: PERIODO UTILIZACIÓN: | D7: 3 MESES
A8: OBJETO: | D8: ADQUISICION DEL RUBRO COMBUSTIBLE (GAS OIL)
A10: Ítem | B10: Codigo Item | C10: DESCRIPCIÓN | H10: Adjunta Detalle Técnico | I10: Unidad Medida | J10: Precio Unitario Estimado | K10: Cantidad Solicitada
A12: 1 | B12: ='SAF 011'!C10 -> 2.5.6-793.29 | C12: ='SAF 011'!F10 -> GAS OIL; PRESENTACION: POR LITRO, USO: MOTORES DIESEL, COMERCIALIZACION: GRADO 3 | H12: SI | I12: ='SAF 011'!G10 -> LITROS | J12: ='SAF 011'!BC10 -> 237.2 | K12: ='SAF 011'!AD10 -> 16000
A14: Costo total estimado: PESOS TRES MILLONES SETECIENTOS NOVENTA Y CINCO MIL DOSCIENTOS CON 00/100.- | J14: =+K12*J12 -> 3795200

Sheet APG SASP
A1: EJERCICIO: | D1: 2022 | P1: AUTORIZACION PARA GASTAR
A4: JURISDICCIÓN: | G4: ='NP SASP'!D3 -> 040 - MINISTERIO DE SALUD
A5: SAF: | G5: ='NP SASP'!D4 -> 011 - DIRECCION PROVINCIAL DE ADMINISTRACION - MINISTERIO DE SALUD
A6: UNIDAD EJECUTORA: | G6: ='NP SASP'!D5 -> 743 - SECRETARIA DE ASISTENCIA EN SALUD PUBLICA
A7: DEPENDENCIA SOLICITANTE: | G7: ='NP SASP'!D6 -> 743 - SECRETARIA DE ASISTENCIA EN SALUD PUBLICA
A8: AUTORIZACIÓN:
A9: Señor Director de Administración o Titular del Servicio Administrativo Financiero:
A10: Autorizo la realización de los trámites correspondientes, a fin de proveer a este Organismo los bienes/servicios que se detallan en Nota de Pedido N° XX/2022 afectando la erogación resultante a los créditos presupuestarios aprobados a favor de esta Unidad Ejecutora, conforme al siguiente detalle:
A12: IMPUTACIÓN PRESUPUESTARIA
A13: CÓDIGO | O13: DENOMINACIÓN DE LA PARTIDA PRESUPUESTARIA | Q13: IMPORTE
A14: PR | B14: SB | C14: PY | D14: AC | E14: OB | F14: UG | G14: FIN | H14: FUN | I14: I | J14: P | K14: P | L14: SubP | M14: M | N14: FF
A15: 3 | D15: 1 | F15: 4901 | G15: 1 | H15: 3 | I15: 2 | J15: 5 | K15: 6 | M15: 1 | N15: 1.1 | O15: COMBUSTIBLES Y LUBRICANTES | Q15: ='NP SASP'!J14 -> 3795200
A38: TOTAL DE PESOS: TRES MILLONES SETECIENTOS NOVENTA Y CINCO MIL DOSCIENTOS CON 00/100.- | Q38: =SUM(Q15:Q37) -> 3795200
A40: JUSTIFICACIÓN:
A41: ='NP SASP'!D8 -> ADQUISICION DEL RUBRO COMBUSTIBLE (GAS OIL)

Sheet NP SyMA
A1: NOTA DE PEDIDO | J1: N° | K1: XX/2022
A3: JURISDICCIÓN: | D3: ='SAF 011'!D4 -> 040 - MINISTERIO DE SALUD
A4: SAF: | D4: ='SAF 011'!D5 -> 011 - DIRECCION PROVINCIAL DE ADMINISTRACION - MINISTERIO DE SALUD
A5: UNIDAD EJECUTORA: | D5: 488 - DIRECCION PROVINCIAL DE SALUD Y MEDIO AMBIENTE
A6: DEPENDENCIA SOLICITANTE: | D6: 488 - DIRECCION PROVINCIAL DE SALUD Y MEDIO AMBIENTE
A7: PERIODO UTILIZACIÓN: | D7: 3 MESES
A8: OBJETO: | D8: ADQUISICION DEL RUBRO COMBUSTIBLE (GAS OIL)
A10: Ítem | B10: Codigo Item | C10: DESCRIPCIÓN | H10: Adjunta Detalle Técnico | I10: Unidad Medida | J10: Precio Unitario Estimado | K10: Cantidad Solicitada
A12: 1 | B12: ='SAF 011'!C10 -> 2.5.6-793.29 | C12: ='SAF 011'!F10 -> GAS OIL; PRESENTACION: POR LITRO, USO: MOTORES DIESEL, COMERCIALIZACION: GRADO 3 | H12: SI | I12: ='SAF 011'!G10 -> LITROS | J12: ='SAF 011'!BC10 -> 237.2 | K12: ='SAF 011'!AF10 -> 1500
A14: Costo total estimado: PESOS TRESCIENTOS CINCUENTA Y CINCO MIL OCHOCIENTOS CON 00/100.- | J14: =+K12*J12 -> 355800

Sheet APG SyMA
A1: EJERCICIO: | D1: 2022 | P1: AUTORIZACION PARA GASTAR
A4: JURISDICCIÓN: | G4: ='NP SyMA'!D3 -> 040 - MINISTERIO DE SALUD
A5: SAF: | G5: ='NP SyMA'!D4 -> 011 - DIRECCION PROVINCIAL DE ADMINISTRACION - MINISTERIO DE SALUD
A6: UNIDAD EJECUTORA: | G6: ='NP SyMA'!D5 -> 488 - DIRECCION PROVINCIAL DE SALUD Y MEDIO AMBIENTE
A7: DEPENDENCIA SOLICITANTE: | G7: ='NP SyMA'!D6 -> 488 - DIRECCION PROVINCIAL DE SALUD Y MEDIO AMBIENTE
A8: AUTORIZACIÓN:
A9: Señor Director de Administración o Titular del Servicio Administrativo Financiero:
A10: Autorizo la realización de los trámites correspondientes, a fin de proveer a este Organismo los bienes/servicios que se detallan en Nota de Pedido N° XX/2022 afectando la erogación resultante a los créditos presupuestarios aprobados a favor de esta Unidad Ejecutora, conforme al siguiente detalle:
A12: IMPUTACIÓN PRESUPUESTARIA
A13: CÓDIGO | O13: DENOMINACIÓN DE LA PARTIDA PRESUPUESTARIA | Q13: IMPORTE
A14: PR | B14: SB | C14: PY | D14: AC | E14: OB | F14: UG | G14: FIN | H14: FUN | I14: I | J14: P | K14: P | L14: SubP | M14: M | N14: FF
A15: 22 | D15: 1 | F15: 4901 | G15: 4 | H15: 4 | I15: 2 | J15: 5 | K15: 6 | M15: 1 | N15: 1.1 | O15: COMBUSTIBLES Y LUBRICANTES | Q15: ='NP SyMA'!J14 -> 355800
A38: TOTAL DE PESOS: TRESCIENTOS CINCUENTA Y CINCO MIL OCHOCIENTOS CON 00/100.- | Q38: =SUM(Q15:Q37) -> 355800
A40: JUSTIFICACIÓN:
A41: ='NP SyMA'!D8 -> ADQUISICION DEL RUBRO COMBUSTIBLE (GAS OIL)

Sheet NP CVZ
A1: NOTA DE PEDIDO | J1: N° | K1: XX/2022
A3: JURISDICCIÓN: | D3: ='SAF 011'!D4 -> 040 - MINISTERIO DE SALUD
A4: SAF: | D4: ='SAF 011'!D5 -> 011 - DIRECCION PROVINCIAL DE ADMINISTRACION - MINISTERIO DE SALUD
A5: UNIDAD EJECUTORA: | D5: 746 - DIRECCION DE CONTROL DE VECTORES Y ZOONOSIS
A6: DEPENDENCIA SOLICITANTE: | D6: 746 - DIRECCION DE CONTROL DE VECTORES Y ZOONOSIS
A7: PERIODO UTILIZACIÓN: | D7: 3 MESES
A8: OBJETO: | D8: ADQUISICION DEL RUBRO COMBUSTIBLE (GAS OIL)
A10: Ítem | B10: Codigo Item | C10: DESCRIPCIÓN | H10: Adjunta Detalle Técnico | I10: Unidad Medida | J10: Precio Unitario Estimado | K10: Cantidad Solicitada
A12: 1 | B12: ='SAF 011'!C10 -> 2.5.6-793.29 | C12: ='SAF 011'!F10 -> GAS OIL; PRESENTACION: POR LITRO, USO: MOTORES DIESEL, COMERCIALIZACION: GRADO 3 | H12: SI | I12: ='SAF 011'!G10 -> LITROS | J12: ='SAF 011'!BC10 -> 237.2 | K12: ='SAF 011'!AH10 -> 700
A14: Costo total estimado: PESOS CIENTO SESENTA Y SEIS MIL CUARENTA CON 00/100.- | J14: =+K12*J12 -> 166040

Sheet APG CVZ
A1: EJERCICIO: | D1: 2022 | P1: AUTORIZACION PARA GASTAR
A4: JURISDICCIÓN: | G4: ='NP CVZ'!D3 -> 040 - MINISTERIO DE SALUD
A5: SAF: | G5: ='NP CVZ'!D4 -> 011 - DIRECCION PROVINCIAL DE ADMINISTRACION - MINISTERIO DE SALUD
A6: UNIDAD EJECUTORA: | G6: ='NP CVZ'!D5 -> 746 - DIRECCION DE CONTROL DE VECTORES Y ZOONOSIS
A7: DEPENDENCIA SOLICITANTE: | G7: ='NP CVZ'!D6 -> 746 - DIRECCION DE CONTROL DE VECTORES Y ZOONOSIS
A8: AUTORIZACIÓN:
A9: Señor Director de Administración o Titular del Servicio Administrativo Financiero:
A10: Autorizo la realización de los trámites correspondientes, a fin de proveer a este Organismo los bienes/servicios que se detallan en Nota de Pedido N° XX/2022 afectando la erogación resultante a los créditos presupuestarios aprobados a favor de esta Unidad Ejecutora, conforme al siguiente detalle:
A12: IMPUTACIÓN PRESUPUESTARIA
A13: CÓDIGO | O13: DENOMINACIÓN DE LA PARTIDA PRESUPUESTARIA | Q13: IMPORTE
A14: PR | B14: SB | C14: PY | D14: AC | E14: OB | F14: UG | G14: FIN | H14: FUN | I14: I | J14: P | K14: P | L14: SubP | M14: M | N14: FF
A15: 23 | D15: 1 | F15: 4901 | G15: 3 | H15: 1 | I15: 2 | J15: 5 | K15: 6 | M15: 1 | N15: 1.1 | O15: COMBUSTIBLES Y LUBRICANTES | Q15: ='NP CVZ'!J14 -> 166040
A38: TOTAL DE PESOS: CIENTO SESENTA Y SEIS MIL CUARENTA CON 00/100.- | Q38: =SUM(Q15:Q37) -> 166040
A40: JUSTIFICACIÓN:
A41: ='NP CVZ'!D8 -> ADQUISICION DEL RUBRO COMBUSTIBLE (GAS OIL)

Sheet NP DISCAP
A1: NOTA DE PEDIDO | J1: N° | K1: XX/2022
A3: JURISDICCIÓN: | D3: ='SAF 011'!D4 -> 040 - MINISTERIO DE SALUD
A4: SAF: | D4: ='SAF 011'!D5 -> 011 - DIRECCION PROVINCIAL DE ADMINISTRACION - MINISTERIO DE SALUD
A5: UNIDAD EJECUTORA: | D5: 093 - DIR. PROV. DE ATENCION INTEGRAL A PERSONAS CON DISCAPACIDAD
A6: DEPENDENCIA SOLICITANTE: | D6: 093 - DIR. PROV. DE ATENCION INTEGRAL A PERSONAS CON DISCAPACIDAD
A7: PERIODO UTILIZACIÓN: | D7: 3 MESES
A8: OBJETO: | D8: ADQUISICION DEL RUBRO COMBUSTIBLE (GAS OIL)
A10: Ítem | B10: Codigo Item | C10: DESCRIPCIÓN | H10: Adjunta Detalle Técnico | I10: Unidad Medida | J10: Precio Unitario Estimado | K10: Cantidad Solicitada
A12: 1 | B12: ='SAF 011'!C10 -> 2.5.6-793.29 | C12: ='SAF 011'!F10 -> GAS OIL; PRESENTACION: POR LITRO, USO: MOTORES DIESEL, COMERCIALIZACION: GRADO 3 | H12: SI | I12: ='SAF 011'!G10 -> LITROS | J12: ='SAF 011'!BC10 -> 237.2 | K12: ='SAF 011'!AJ10 -> 550
A14: Costo total estimado: PESOS CIENTO TREINTA MIL CUATROCIENTOS SESENTA CON 00/100.- | J14: =+K12*J12 -> 130460

Sheet APG DISCAP
A1: EJERCICIO: | D1: 2022 | P1: AUTORIZACION PARA GASTAR
A4: JURISDICCIÓN: | G4: ='NP DISCAP'!D3 -> 040 - MINISTERIO DE SALUD
A5: SAF: | G5: ='NP DISCAP'!D4 -> 011 - DIRECCION PROVINCIAL DE ADMINISTRACION - MINISTERIO DE SALUD
A6: UNIDAD EJECUTORA: | G6: ='NP DISCAP'!D5 -> 093 - DIR. PROV. DE ATENCION INTEGRAL A PERSONAS CON DISCAPACIDAD
A7: DEPENDENCIA SOLICITANTE: | G7: ='NP DISCAP'!D6 -> 093 - DIR. PROV. DE ATENCION INTEGRAL A PERSONAS CON DISCAPACIDAD
A8: AUTORIZACIÓN:
A9: Señor Director de Administración o Titular del Servicio Administrativo Financiero:
A10: Autorizo la realización de los trámites correspondientes, a fin de proveer a este Organismo los bienes/servicios que se detallan en Nota de Pedido N° XX/2022 afectando la erogación resultante a los créditos presupuestarios aprobados a favor de esta Unidad Ejecutora, conforme al siguiente detalle:
A12: IMPUTACIÓN PRESUPUESTARIA
A13: CÓDIGO | O13: DENOMINACIÓN DE LA PARTIDA PRESUPUESTARIA | Q13: IMPORTE
A14: PR | B14: SB | C14: PY | D14: AC | E14: OB | F14: UG | G14: FIN | H14: FUN | I14: I | J14: P | K14: P | L14: SubP | M14: M | N14: FF
A15: 26 | D15: 1 | F15: 4901 | G15: 3 | H15: 1 | I15: 2 | J15: 5 | K15: 6 | M15: 1 | N15: 1.1 | O15: COMBUSTIBLES Y LUBRICANTES | Q15: ='NP DISCAP'!J14 -> 130460
A38: TOTAL DE PESOS: CIENTO TREINTA MIL CUATROCIENTOS SESENTA CON 00/100.- | Q38: =SUM(Q15:Q37) -> 130460
A40: JUSTIFICACIÓN:
A41: ='NP DISCAP'!D8 -> ADQUISICION DEL RUBRO COMBUSTIBLE (GAS OIL)

Sheet NP ASIST. SAN.
A1: NOTA DE PEDIDO | J1: N° | K1: XX/2022
A3: JURISDICCIÓN: | D3: ='SAF 011'!D4 -> 040 - MINISTERIO DE SALUD
A4: SAF: | D4: ='SAF 011'!D5 -> 011 - DIRECCION PROVINCIAL DE ADMINISTRACION - MINISTERIO DE SALUD
A5: UNIDAD EJECUTORA: | D5: 476 - DIRECCION PROVINCIAL DE ASISTENCIA SANITARIA NIVEL I Y II
A6: DEPENDENCIA SOLICITANTE: | D6: 476 - DIRECCION PROVINCIAL DE ASISTENCIA SANITARIA NIVEL I Y II
A7: PERIODO UTILIZACIÓN: | D7: 3 MESES
A8: OBJETO: | D8: ADQUISICION DEL RUBRO COMBUSTIBLE (GAS OIL)
A10: Ítem | B10: Codigo Item | C10: DESCRIPCIÓN | H10: Adjunta Detalle Técnico | I10: Unidad Medida | J10: Precio Unitario Estimado | K10: Cantidad Solicitada
A12: 1 | B12: ='SAF 011'!C10 -> 2.5.6-793.29 | C12: ='SAF 011'!F10 -> GAS OIL; PRESENTACION: POR LITRO, USO: MOTORES DIESEL, COMERCIALIZACION: GRADO 3 | H12: SI | I12: ='SAF 011'!G10 -> LITROS | J12: ='SAF 011'!BC10 -> 237.2 | K12: ='SAF 011'!AR10 -> 31500
A14: Costo total estimado: PESOS SIETE MILLONES CUATROCIENTOS SETENTA Y UN MIL OCHOCIENTOS CON 00/100.- | J14: =+K12*J12 -> 7471800

Sheet APG ASIST. SAN.
A1: EJERCICIO: | D1: 2022 | P1: AUTORIZACION PARA GASTAR
A4: JURISDICCIÓN: | G4: ='NP ASIST. SAN.'!D3 -> 040 - MINISTERIO DE SALUD
A5: SAF: | G5: ='NP ASIST. SAN.'!D4 -> 011 - DIRECCION PROVINCIAL DE ADMINISTRACION - MINISTERIO DE SALUD
A6: UNIDAD EJECUTORA: | G6: ='NP ASIST. SAN.'!D5 -> 476 - DIRECCION PROVINCIAL DE ASISTENCIA SANITARIA NIVEL I Y II
A7: DEPENDENCIA SOLICITANTE: | G7: ='NP ASIST. SAN.'!D6 -> 476 - DIRECCION PROVINCIAL DE ASISTENCIA SANITARIA NIVEL I Y II
A8: AUTORIZACIÓN:
A9: Señor Director de Administración o Titular del Servicio Administrativo Financiero:
A10: Autorizo la realización de los trámites correspondientes, a fin de proveer a este Organismo los bienes/servicios que se detallan en Nota de Pedido N° XX/2022 afectando la erogación resultante a los créditos presupuestarios aprobados a favor de esta Unidad Ejecutora, conforme al siguiente detalle:
A12: IMPUTACIÓN PRESUPUESTARIA
A13: CÓDIGO | O13: DENOMINACIÓN DE LA PARTIDA PRESUPUESTARIA | Q13: IMPORTE
A14: PR | B14: SB | C14: PY | D14: AC | E14: OB | F14: UG | G14: FIN | H14: FUN | I14: I | J14: P | K14: P | L14: SubP | M14: M | N14: FF
A15: 21 | D15: 1 | F15: 4901 | G15: 3 | H15: 1 | I15: 2 | J15: 5 | K15: 6 | M15: 1 | N15: 1.1 | O15: COMBUSTIBLES Y LUBRICANTES | Q15: ='NP ASIST. SAN.'!J14 -> 7471800
A38: TOTAL DE PESOS: SIETE MILLONES CUATROCIENTOS SETENTA Y UN MIL OCHOCIENTOS CON 00/100.- | Q38: =SUM(Q15:Q37) -> 7471800
A40: JUSTIFICACIÓN:
A41: ='NP ASIST. SAN.'!D8 -> ADQUISICION DEL RUBRO COMBUSTIBLE (GAS OIL)

Sheet NP MS
A1: NOTA DE PEDIDO | J1: N° | K1: XX/2022
A3: JURISDICCIÓN: | D3: ='SAF 011'!D4 -> 040 - MINISTERIO DE SALUD
A4: SAF: | D4: ='SAF 011'!D5 -> 011 - DIRECCION PROVINCIAL DE ADMINISTRACION - MINISTERIO DE SALUD
A5: UNIDAD EJECUTORA: | D5: 352 - MINISTERIO DE SALUD
A6: DEPENDENCIA SOLICITANTE: | D6: 352 - MINISTERIO DE SALUD
A7: PERIODO UTILIZACIÓN: | D7: 3 MESES
A8: OBJETO: | D8: ADQUISICION DEL RUBRO COMBUSTIBLE (GAS OIL)
A10: Ítem | B10: Codigo Item | C10: DESCRIPCIÓN | H10: Adjunta Detalle Técnico | I10: Unidad Medida | J10: Precio Unitario Estimado | K10: Cantidad Solicitada
A12: 1 | B12: ='SAF 011'!C10 -> 2.5.6-793.29 | C12: ='SAF 011'!F10 -> GAS OIL; PRESENTACION: POR LITRO, USO: MOTORES DIESEL, COMERCIALIZACION: GRADO 3 | H12: SI | I12: ='SAF 011'!G10 -> LITROS | J12: ='SAF 011'!BC10 -> 237.2 | K12: ='SAF 011'!AV10 -> 1700
A14: Costo total estimado: PESOS CUATROCIENTOS TRES MIL DOSCIENTOS CUARENTA CON 00/100.- | J14: =+K12*J12 -> 403240

Sheet APG MS
A1: EJERCICIO: | D1: 2022 | P1: AUTORIZACION PARA GASTAR
A4: JURISDICCIÓN: | G4: ='NP MS'!D3 -> 040 - MINISTERIO DE SALUD
A5: SAF: | G5: ='NP MS'!D4 -> 011 - DIRECCION PROVINCIAL DE ADMINISTRACION - MINISTERIO DE SALUD
A6: UNIDAD EJECUTORA: | G6: ='NP MS'!D5 -> 352 - MINISTERIO DE SALUD
A7: DEPENDENCIA SOLICITANTE: | G7: ='NP MS'!D6 -> 352 - MINISTERIO DE SALUD
A8: AUTORIZACIÓN:
A9: Señor Director de Administración o Titular del Servicio Administrativo Financiero:
A10: Autorizo la realización de los trámites correspondientes, a fin de proveer a este Organismo los bienes/servicios que se detallan en Nota de Pedido N° XX/2022 afectando la erogación resultante a los créditos presupuestarios aprobados a favor de esta Unidad Ejecutora, conforme al siguiente detalle:
A12: IMPUTACIÓN PRESUPUESTARIA
A13: CÓDIGO | O13: DENOMINACIÓN DE LA PARTIDA PRESUPUESTARIA | Q13: IMPORTE
A14: PR | B14: SB | C14: PY | D14: AC | E14: OB | F14: UG | G14: FIN | H14: FUN | I14: I | J14: P | K14: P | L14: SubP | M14: M | N14: FF
A15: 1 | D15: 1 | F15: 4901 | G15: 3 | H15: 1 | I15: 2 | J15: 5 | K15: 6 | M15: 1 | N15: 1.1 | O15: COMBUSTIBLES Y LUBRICANTES | Q15: ='NP MS'!J14 -> 403240
A38: TOTAL DE PESOS: CUATROCIENTOS TRES MIL DOSCIENTOS CUARENTA CON 00/100.- | Q38: =SUM(Q15:Q37) -> 403240
A40: JUSTIFICACIÓN:
A41: ='NP MS'!D8 -> ADQUISICION DEL RUBRO COMBUSTIBLE (GAS OIL)

Sheet NP INTERR. MUN.
A1: NOTA DE PEDIDO | J1: N° | K1: XX/2022
A3: JURISDICCIÓN: | D3: ='SAF 011'!D4 -> 040 - MINISTERIO DE SALUD
A4: SAF: | D4: ='SAF 011'!D5 -> 011 - DIRECCION PROVINCIAL DE ADMINISTRACION - MINISTERIO DE SALUD
A5: UNIDAD EJECUTORA: | D5: 379 - SECRETARIA DE INTERRELACION MUNICIPAL
A6: DEPENDENCIA SOLICITANTE: | D6: 379 - SECRETARIA DE INTERRELACION MUNICIPAL
A7: PERIODO UTILIZACIÓN: | D7: 3 MESES
A8: OBJETO: | D8: ADQUISICION DEL RUBRO COMBUSTIBLE (GAS OIL)
A10: Ítem | B10: Codigo Item | C10: DESCRIPCIÓN | H10: Adjunta Detalle Técnico | I10: Unidad Medida | J10: Precio Unitario Estimado | K10: Cantidad Solicitada
A12: 1 | B12: ='SAF 011'!C10 -> 2.5.6-793.29 | C12: ='SAF 011'!F10 -> GAS OIL; PRESENTACION: POR LITRO, USO: MOTORES DIESEL, COMERCIALIZACION: GRADO 3 | H12: SI | I12: ='SAF 011'!G10 -> LITROS | J12: ='SAF 011'!BC10 -> 237.2 | K12: ='SAF 011'!AZ10 -> 11000
A14: Costo total estimado: PESOS DOS MILLONES SEISCIENTOS NUEVE MIL DOSCIENTOS CON 00/100.- | J14: =+K12*J12 -> 2609200

Sheet APG INTERR. MUN.
A1: EJERCICIO: | D1: 2022 | P1: AUTORIZACION PARA GASTAR
A4: JURISDICCIÓN: | G4: ='NP INTERR. MUN.'!D3 -> 040 - MINISTERIO DE SALUD
A5: SAF: | G5: ='NP INTERR. MUN.'!D4 -> 011 - DIRECCION PROVINCIAL DE ADMINISTRACION - MINISTERIO DE SALUD
A6: UNIDAD EJECUTORA: | G6: ='NP INTERR. MUN.'!D5 -> 379 - SECRETARIA DE INTERRELACION MUNICIPAL
A7: DEPENDENCIA SOLICITANTE: | G7: ='NP INTERR. MUN.'!D6 -> 379 - SECRETARIA DE INTERRELACION MUNICIPAL
A8: AUTORIZACIÓN:
A9: Señor Director de Administración o Titular del Servicio Administrativo Financiero:
A10: Autorizo la realización de los trámites correspondientes, a fin de proveer a este Organismo los bienes/servicios que se detallan en Nota de Pedido N° XX/2022 afectando la erogación resultante a los créditos presupuestarios aprobados a favor de esta Unidad Ejecutora, conforme al siguiente detalle:
A12: IMPUTACIÓN PRESUPUESTARIA
A13: CÓDIGO | O13: DENOMINACIÓN DE LA PARTIDA PRESUPUESTARIA | Q13: IMPORTE
A14: PR | B14: SB | C14: PY | D14: AC | E14: OB | F14: UG | G14: FIN | H14: FUN | I14: I | J14: P | K14: P | L14: SubP | M14: M | N14: FF
A15: 50 | D15: 1 | F15: 4901 | G15: 3 | H15: 1 | I15: 2 | J15: 5 | K15: 6 | M15: 1 | N15: 1.1 | O15: COMBUSTIBLES Y LUBRICANTES | Q15: ='NP INTERR. MUN.'!J14 -> 2609200
A38: TOTAL DE PESOS: DOS MILLONES SETECIENTOS SEISCIENTOS NUEVE MIL DOSCIENTOS CON 00/100.- | Q38: =SUM(Q15:Q37) -> 2609200
A40: JUSTIFICACIÓN:
A41: ='NP INTERR. MUN.'!D8 -> ADQUISICION DEL RUBRO COMBUSTIBLE (GAS OIL)
