Workbook

Sheet SAF 11
A1: 2022
B2: Pedido de Necesidades Trimestrales
A4: JURISDICCION: | C4: 040 - MINISTERIO DE SALUD
A5: SAF N°: | C5: 011 - DIRECCION PROVINCIAL DE ADMINISTRACION - MINISTERIO DE SALUD
A6: EJERCICIO: | C6: 2022
A7: TRIMESTRE: | C7: CUARTO
A9: ID | B9: CODIGO ITEM | C9: RUBRO DE COMPRA | D9: I.P.P. | E9: DESCRIPCION | F9: UNIDAD DE MEDIDA | G9: CANTIDAD TOTAL | H9: PRECIO UNITARIO ESTIMADO | I9: IMPORTE TOTAL ESTIMADO | J9: ESPECIFICACION TECNICA
A10: 1 | B10: 4.3.3-5080.1 | C10: EQUIPOS | D10: 4.3.3 | E10: ASPIRADORES DE SECRECION; ALIMENTACION: 12-220 V, TIPO: PORTATIL | F10: UNIDAD | G10: 20 | H10: 70156 | I10: =G10*H10 -> 1403120 | J10: Aspirador portátil de uso continuo libre de lubricantes. Debe Contar con una válvula reguladora de la aspiración desde un mínimo hasta un máximo. Debe poseer un frasco colector de 1000 cm3, con trampa antidesborde, para evitar el pasaje de líquido al cabezal aspirador. La unidad debe estar provista de un vacuómetro para proveer la indicación del vació generado por el aspirador. Características técnicas mínimas: - Tensión nominal: 220Vca. - Caudal de aspiración: 34 l/min - Vacío máximo: 58 cmHg - Presión de salida: 1,5 a 1,8 Kg/cm² - Presión sonora: 63,6 dB - Capacidad del recipiente: 1 litro Debe incluir: -Vaso de 1 litro con Trampa -Manual de uso
A11: 2 | B11: 4.3.3-6616.14 | C11: EQUIPOS | D11: 4.3.3 | E11: AUTOCLAVES ELECTRICOS; TIPO: AUTOMATICO, INDIC. TEMP: DIGITAL, CAPACIDAD: 20 L, ALIMENTACION: 220 V | F11: UNIDAD | G11: 1 | H11: 132500 | I11: =G11*H11 -> 132500 | J11: Estufa De Esterilización. De mesa. Uso: odontológico. Capacidad: hasta 20 litros. Voltaje: 220V. Potencia máxima: hasta 400 W. Medidas aproximadas: Altura: 31 cm, Largo: 34 cm, Ancho: 45 cm. Exterior pintado en blanco y el interior en acero inoxidable. Programas: por lo menos 4 reeestablecidos y 1 programa manual. Controles digitales comandados por un microprocesador. Bandejas: mínimo 4 (amplias y perforadas) de acero inoxidable que permitan acomodar gran cantidad de instrumental, no oxide a los mismos ni afecte puntas ni filos. Apertura: lateral. Terminación: hecha completamente en acero inoxidable.
A12: 3 | B12: 4.3.3-6616.14 | C12: EQUIPOS | D12: 4.3.3 | E12: AUTOCLAVES ELECTRICOS; TIPO: AUTOMATICO, INDIC. TEMP: DIGITAL, CAPACIDAD: 20 L, ALIMENTACION: 220 V | F12: UNIDAD | G12: 1 | H12: 525000 | I12: =G12*H12 -> 525000 | J12: Autoclave Digital Portatil Uso General 20 Litros: Debe contar con:- Sistema Inteligente de Control por Microprocesador que supervisa en tiempo Real los Parámetros de Ciclo (Temperatura/ Presión) dentro de la Cámara; - Sistema de Control LED Digital; - Alarma Sonora de Finalización de Proceso; - Sistema de Punto Seguridad (Cuando la Temperatura y la Presión llegan a su Punto de Seguridad, es cuando se podrá abrir la Tapa); - Sistema de Memoria (Programa Fijo de Ciclo: El Equipo dispone la Posibilidad de Programar y Setear un programa fijo de Ciclo de Esterilización); - Dispositivos de Seguridad: debe poseer dispositivos de Bloqueo contra Sobre temperatura y Sistema de Protección contra Sobre Presión y Sistema de Detección Automática de Fallas en el Proceso. -Cuerpo y Tapa construido en Acero Inoxidable Reforzado. - Rango de Timer 0-999 min. - Presion de Trabajo 0.142 Mpa. - Rango de Temperatura 50-126ºC. -Volumen de la Recamara Aprox. 20lt Volumen Util Aprox. 18lt. -Volumen de la cámara de esterilización Aprox. (diametro x altura) 280x260mm Cesta (diámetro x altura mm) Aprox. 260 x250mm. - Alimentación: 220V- 50Hz Consumo: 2 kW. INCLUYE UPS ACORDE AL EQUIPO
A13: 4 | B13: 4.3.3-8300.1 | C13: EQUIPOS | D13: 4.3.3 | E13: BICICLETAS P/ERGOMETRIA; VOLANTE DE INERCIA: 500 mm, ETAPA DE RESISTENCIA: 150 EN 150 Kgm, VOLANTE: DE INERCIA 500 mm | F13: UNIDAD | G13: 3 | H13: 396807 | I13: =G13*H13 -> 1190421 | J13: Bicicleta fija de caño reforzada y terminada en pintura epoxi, con piñón fijo y pedalera reforzada con transmisión a correa, debe ser totalmente silenciosa. Con asiento regulable en altura. Con manubrios antideslizantes y regulables en altura y posición. Con sistema de resistencia magnética que se modifique desde la consola y con 10 niveles de resistencia. Debe incluir computadora con múltiples funciones. Debe soportar hasta 150kg.
A14: 5 | B14: 4.3.3-5420.6 | C14: EQUIPOS | D14: 4.3.3 | E14: BOMBAS DE INFUSION; ALIMENTACION: 220 V, LECTURA: DISPLAY GRAFICO, VOLUMEN: 01-9999 ML, CONTRAPRESION: 40 KPA A 120 KPA | F14: UNIDAD | G14: 20 | H14: 316490 | I14: =G14*H14 -> 6329800 | J14: Bomba de infusión volumétrica totalmente microcontrolada para perfus genéricos siliconados. Debe contar con display TFT color LCD táctil de, al menos, 4”, el grado de protección al polvo y al agua debe ser IP24, construida con de material plástico de alta calidad, con baterías de alta duración (9 horas aproximadamente), el peso máximo no deberá superar los 1,6Kg., tensión de alimentación 220Vca con potencia aproximada de 50VA. Debe estar aprobada por ANMAT y tener 1 año de garantía mínima. Parámetros mínimos a cumplir: Precisión del sistema mayor a 1mL/h.Tasa de infusión con set de 60 gotas de 0,1 a 400mL/h. Tasa de bolus con set de 60 gotas de 0,1 a 400mL/h. Tasa de purga con set de 60 gotas de 400mL/h. Tasa de KVO de 0,01 a 5mL/h. Incremento de mínimo de caudal 0,01mL/h. Volumen total de infusión de 0,01 a 9999,99Ml. Intervalo de tiempo de 1minuto a 99horas. Rango de detección de oclusión aguas arriba de -75 a -600mmHg. Rango de detección de oclusión aguas abajo de 0 a 900mmHg. Rango de detección de aire (doble sensor) de 50 a 800uL. Debe indicar el nombre del medicamento que está infundiendo Modos de trabajo mínimos que debe incluir: Modo mL/h. Modo peso corporal. Modo goteo
A15: 6 | B15: 2.9.5-7987.9 | C15: PROD. MEDICO/FARMACEUTICOS/LAB | D15: 4.3.3 | E15: CAJAS DE INSTRUMENTAL; MATERIAL: ACERO INOXIDABLE, USO: CIRUGIA, CANTIDAD: 1 | F15: UNIDAD | G15: 20 | H15: 15200 | I15: =G15*H15 -> 304000 | J15: Caja acero inoxidable 18 x 8 x 3 cm lisa: incluye 1 Mango de Bisturi N3 + 10 Hojas de bisturí Nº10, 1 Pinza de disección 14.5 cm, 1 Pinza Kocher Recta 14 cm, 1 Pinza con diente de ratón 14.5cm 1x2dientes, 1 Pinza Halsted Recta 10 cm recta, 1 Pinza Halsted Curva 10 cm, 1 Pinza Adson 12 cm sin dientes, 1 Tijera curación recta 14 cm, 1 Tijera Mayo punta roma 14 cm, 1 Porta Agujas Mayo Hegar 14 cm, 1 Sonda acanalada 13cm.
A16: 7 | B16: 2.9.5-7987.9 | C16: PROD. MEDICO/FARMACEUTICOS/LAB | D16: 4.3.3 | E16: CAJAS DE INSTRUMENTAL; MATERIAL: ACERO INOXIDABLE, USO: CIRUGIA, CANTIDAD: 1 | F16: UNIDAD | G16: 20 | H16: 18000 | I16: =G16*H16 -> 360000 | J16: Caja 20 x 0,9x04cm A. Incluye: 1 Tijera mayo recta 14 CM. 1 Tijera iris curva 9 CM. Estilete. 1 Sonda acanalada 13cm. 1 Porta agujas mayo hegar 14 CM. 1 Pinza kocher recta 14 CM. 1 Pinza halstead curva 10 CM. 1 Pinza halstead recta 10 CM. 1 Pinza de disección 14,5 CM. 1 Pinza diente de ratón 14.5 1x2 dientes CM. 1 Mango para bisturí nro3. 1Separador farabeuf 15x1.5 CM (par)
A17: 8 | B17: 2.9.5-7987.1 | C17: PROD. MEDICO/FARMACEUTICOS/LAB | D17: 4.3.3 | E17: CAJAS DE INSTRUMENTAL; MATERIAL: ACERO INOXIDABLE, USO: EXAMEN GINECOLOG./INST.DE DIU, CANT.INSTRUMETAL: 10, CANTIDAD: 1 | F17: UNIDAD | G17: 7 | H17: 36100 | I17: =G17*H17 -> 252700 | J17: CAJA DE COLOCACION DE DIU: caja acero inoxidable. 30 x 15 x 8 cm aprox. Incluyre: - 2 pinza maier 20 cm recta, - 1 pinza bertola 18 cm recta, - 1 pinza bertola 18 cm curva, - 1 pinza allis 19 cm. 5 x 6 dientes, - 2 tijera metzenbaum 20 cm, - 2 pinza pozzi erina 25 cm, - 1 histerómetro sims 32 cm maleable
A18: 9 | B18: 4.3.3-1719.48 | C18: EQUIPOS | D18: 4.3.3 | E18: CAMILLAS; ANCHO: 60 Cm, LARGO: 200 Cm, ALTO: 70 Cm, ARNESES: SIN, TIPO: RODANTE | F18: UNIDAD | G18: 20 | H18: 62710 | I18: =G18*H18 -> 1254200 | J18: Camilla de transporte reforzada con estructura metálica acabada en pintura epoxi, con barandas rebatibles, porta suero, porta oxígeno, con cuatro ruedas de 125 mm de diámetro como mínimo, con frenos. De espuma de poliuretano de alta densidad tapizada en ecocuero de primera calidad de color negro
A19: 10 | B19: 4.3.3-1719.27 | C19: EQUIPOS | D19: 4.3.3 | E19: CAMILLAS; ANCHO: 75 Cm, LARGO: 185 Cm, ALTO: 75 Cm, ARNESES: SIN, TIPO: KINESICA | F19: UNIDAD | G19: 3 | H19: 66300 | I19: =G19*H19 -> 198900 | J19: Camilla fija para kinesiología con medidas aproximadas de: 75cm ancho, 185cm de largo y 75cm de alto, que soporte al menos 200kg de peso. Compuesta de caño estructural terminado en pintura epoxi. Con espuma de poliuretano de alta densidad tapizada en ecocuero de primera calidad de color negro.
A20: 11 | B20: 4.3.2-6331.12 | C20: TRANSPORTE Y DEPOSITO | D20: 4.3.3 | E20: CARROS P/TRANSP.; SUPERFICIE: 30 X 40 Cm, ALTURA: 120 Cm, MATERIAL: CHAPA METAL PLEGADA, ESTRUCTURA: METALICA, RUEDAS: 2 REFORZADAS- DIAM. 180 mm, ACCESORIO: 2 AGARRADERAS, MATERIAL ESTRUCTURA: METALICA | F20: UNIDAD | G20: 14 | H20: 16756 | I20: =G20*H20 -> 234584 | J20: Carro metálico protegido por pintura epoxi, para tubo de oxígeno de 6m3, con ruedas de goma de aproximadamente 175 a 180 mm y sistema de sujeción del tubo.
A21: 12 | B21: 4.3.3-5416.1 | C21: EQUIPOS | D21: 4.3.3 | E21: CARROS USO HOSPITALARIO; TERMINACION: ANTIOXIDANTE, ESTRUCTURA: REFORZADA DE CHAPA ACERO SAE, MEDIDAS: 0,70 X 0,50 X 0,90 M, PARACHOQUE: GOMA, PLANO SUPERIOR: ESTRATIFICADOS CON BARANDAS, CAJONES: CON, DIVISIONES: P/MATERIALES, MASTIL: CON, CONTENEDOR: P/RESIDUOS BIOLOGICOS, ALZADA SUPERIOR: PORTA CARDIODESFIBRILADOR, CANTIDAD DE CAJONES: CON, MATERIAL ESTRUCTURA: REFORZADA DE CHAPA ACERO SAE, DIMENSION: 0,70 X 0,50 X 0,90 M, TIPO: DE PARO | F21: UNIDAD | G21: 14 | H21: 408143 | I21: =G21*H21 -> 5714002 | J21: Carro de paro de 5 cajones. Construido en chapa SAE 1010. Cinco cajones con cerradura central, uno de ellos con división para medicamentos. Alzada para monitor Bandeja auxiliar lateral corrediza de acero inoxidable. Porta suero, porta tubo de oxígeno y parachoque perimetral. Manija de arrastre. Ruedas de aproximadamente 100mm, al menos dos de ellas con freno. Contenedor para residuos patógenos. Terminación pintura epoxi.
... A46: 37 | B46: 2.9.5-2020.1 | C46: PROD. MEDICO/FARMACEUTICOS/LAB | D46: 4.3.3 | E46: TAMBORES QUIRURGICOS; MATERIAL: ACERO INOXIDABLE, DIMENSION: 10 X 12 Cm | F46: UNIDAD | G46: 20 | H46: 11000 | I46: =G46*H46 -> 220000 | J46: Tambor Algodonero, tapa perforada
A47: TOTAL RUBRO | I47: =SUM(I10:I46) -> 50728263
C49: ESPECIFICIDADES Y DETALLE TECNICO:
C50: * ADJUNTAR FOLLETERIA, MANUALES Y/O CUALQUIER OTRA DOCUMENTACION QUE EL PROVEEDOR ESTIME NECESARIO PARA ACLARAR EL BIEN COTIZADO. EN CASO DE CORRESPONDER ADJUNTAR CERTIFICADO DE ANMAT.
C52: Plazos de entrega: | D52: veinte (20) dias habiles
C54: Lugar de Entrega: | D54: MINISTERIO DE SALUD - CHACABUCO N° 169 - en el horario de 8:00hs a 12:00hs de lunes a viernes
C56: Calidad Minima esperada:
C58: Garantia: | D58: garantia integral de doce (12) meses.
C60: Mantenimiento de oferta: | D60: cuarenta y cinco (45) días
C63: ESPECIFICIDADES ITEM 1
C64: =J10 -> Aspirador portátil de uso continuo libre de lubricantes. Debe Contar con una válvula reguladora de la aspiración desde un mínimo hasta un máximo. Debe poseer un frasco colector de 1000 cm3, con trampa antidesborde, para evitar el pasaje de líquido al cabezal aspirador. La unidad debe estar provista de un vacuómetro para proveer la indicación del vació generado por el aspirador. Características técnicas mínimas: - Tensión nominal: 220Vca. - Caudal de aspiración: 34 l/min - Vacío máximo: 58 cmHg - Presión de salida: 1,5 a 1,8 Kg/cm² - Presión sonora: 63,6 dB - Capacidad del recipiente: 1 litro Debe incluir: -Vaso de 1 litro con Trampa -Manual de uso
C66: ESPECIFICIDADES ITEM 2
C67: =J11 -> Estufa De Esterilización. De mesa. Uso: odontológico. Capacidad: hasta 20 litros. Voltaje: 220V. Potencia máxima: hasta 400 W. Medidas aproximadas: Altura: 31 cm, Largo: 34 cm, Ancho: 45 cm. Exterior pintado en blanco y el interior en acero inoxidable. Programas: por lo menos 4 reeestablecidos y 1 programa manual. Controles digitales comandados por un microprocesador. Bandejas: mínimo 4 (amplias y perforadas) de acero inoxidable que permitan acomodar gran cantidad de instrumental, no oxide a los mismos ni afecte puntas ni filos. Apertura: lateral. Terminación: hecha completamente en acero inoxidable.
C69: ESPECIFICIDADES ITEM 3
C70: =J12 -> Autoclave Digital Portatil Uso General 20 Litros: Debe contar con:- Sistema Inteligente de Control por Microprocesador que supervisa en tiempo Real los Parámetros de Ciclo (Temperatura/ Presión) dentro de la Cámara; - Sistema de Control LED Digital; - Alarma Sonora de Finalización de Proceso; - Sistema de Punto Seguridad (Cuando la Temperatura y la Presión llegan a su Punto de Seguridad, es cuando se podrá abrir la Tapa); - Sistema de Memoria (Programa Fijo de Ciclo: El Equipo dispone la Posibilidad de Programar y Setear un programa fijo de Ciclo de Esterilización); - Dispositivos de Seguridad: debe poseer dispositivos de Bloqueo contra Sobre temperatura y Sistema de Protección contra Sobre Presión y Sistema de Detección Automática de Fallas en el Proceso. -Cuerpo y Tapa construido en Acero Inoxidable Reforzado. - Rango de Timer 0-999 min. - Presion de Trabajo 0.142 Mpa. - Rango de Temperatura 50-126ºC. -Volumen de la Recamara Aprox. 20lt Volumen Util Aprox. 18lt. -Volumen de la cámara de esterilización Aprox. (diametro x altura) 280x260mm Cesta (diámetro x altura mm) Aprox. 260 x250mm. - Alimentación: 220V- 50Hz Consumo: 2 kW. INCLUYE UPS ACORDE AL EQUIPO
C72: ESPECIFICIDADES ITEM 4
C73: =J13 -> Bicicleta fija de caño reforzada y terminada en pintura epoxi, con piñón fijo y pedalera reforzada con transmisión a correa, debe ser totalmente silenciosa. Con asiento regulable en altura. Con manubrios antideslizantes y regulables en altura y posición. Con sistema de resistencia magnética que se modifique desde la consola y con 10 niveles de resistencia. Debe incluir computadora con múltiples funciones. Debe soportar hasta 150kg.
C75: ESPECIFICIDADES ITEM 5
C76: =J14 -> Bomba de infusión volumétrica totalmente microcontrolada para perfus genéricos siliconados. Debe contar con display TFT color LCD táctil de, al menos, 4”, el grado de protección al polvo y al agua debe ser IP24, construida con de material plástico de alta calidad, con baterías de alta duración (9 horas aproximadamente), el peso máximo no deberá superar los 1,6Kg., tensión de alimentación 220Vca con potencia aproximada de 50VA. Debe estar aprobada por ANMAT y tener 1 año de garantía mínima. Parámetros mínimos a cumplir: Precisión del sistema mayor a 1mL/h.Tasa de infusión con set de 60 gotas de 0,1 a 400mL/h. Tasa de bolus con set de 60 gotas de 0,1 a 400mL/h. Tasa de purga con set de 60 gotas de 400mL/h. Tasa de KVO de 0,01 a 5mL/h. Incremento de mínimo de caudal 0,01mL/h. Volumen total de infusión de 0,01 a 9999,99Ml. Intervalo de tiempo de 1minuto a 99horas. Rango de detección de oclusión aguas arriba de -75 a -600mmHg. Rango de detección de oclusión aguas abajo de 0 a 900mmHg. Rango de detección de aire (doble sensor) de 50 a 800uL. Debe indicar el nombre del medicamento que está infundiendo Modos de trabajo mínimos que debe incluir: Modo mL/h. Modo peso corporal. Modo goteo
C78: ESPECIFICIDADES ITEM 6
C79: =J15 -> Caja acero inoxidable 18 x 8 x 3 cm lisa: incluye 1 Mango de Bisturi N3 + 10 Hojas de bisturí Nº10, 1 Pinza de disección 14.5 cm, 1 Pinza Kocher Recta 14 cm, 1 Pinza con diente de ratón 14.5cm 1x2dientes, 1 Pinza Halsted Recta 10 cm recta, 1 Pinza Halsted Curva 10 cm, 1 Pinza Adson 12 cm sin dientes, 1 Tijera curación recta 14 cm, 1 Tijera Mayo punta roma 14 cm, 1 Porta Agujas Mayo Hegar 14 cm, 1 Sonda acanalada 13cm.
...

Sheet NP
A1: NOTA DE PEDIDO | J1: N°
A3: JURISDICCIÓN: | D3: 040 - MINISTERIO DE SALUD
A4: SAF: | D4: 011 - DIRECCION PROVINCIAL DE ADMINISTRACION DEL MINISTERIO DE SALUD
A5: UNIDAD EJECUTORA: | D5: 352 - MINISTERIO DE SALUD
A6: DEPENDENCIA SOLICITANTE: | D6: 352 - MINISTERIO DE SALUD
A7: PERIODO UTILIZACIÓN: | D7: DIEZ (10) AÑOS
A8: OBJETO: | D8: ADQUISICION DE UTILES MEDICOS Y EQUIPOS SANITARIOS Y DE LABORATORIO CON DESTINO A HOSPITALES DE LA PROVINCIA
A10: Ítem | B10: Codigo Item | C10: DESCRIPCIÓN | H10: Adjunta Detalle Técnico | I10: Unidad Medida | J10: Precio Unitario Estimado | K10: Cantidad Solicitada
A12: 1 | B12: ='SAF 11'!B10 -> 4.3.3-5080.1 | C12: ='SAF 11'!E10 -> ASPIRADORES DE SECRECION; ALIMENTACION: 12-220 V, TIPO: PORTATIL | H12: SI | I12: ='SAF 11'!F10 -> UNIDAD | J12: ='SAF 11'!H10 -> 70156 | K12: ='SAF 11'!G10 -> 20
A13: 2 | B13: ='SAF 11'!B11 -> 4.3.3-6616.14 | C13: ='SAF 11'!E11 -> AUTOCLAVES ELECTRICOS; TIPO: AUTOMATICO, INDIC. TEMP: DIGITAL, CAPACIDAD: 20 L, ALIMENTACION: 220 V | H13: SI | I13: ='SAF 11'!F11 -> UNIDAD | J13: ='SAF 11'!H11 -> 132500 | K13: ='SAF 11'!G11 -> 1
A14: 3 | B14: ='SAF 11'!B12 -> 4.3.3-6616.14 | C14: ='SAF 11'!E12 -> AUTOCLAVES ELECTRICOS; TIPO: AUTOMATICO, INDIC. TEMP: DIGITAL, CAPACIDAD: 20 L, ALIMENTACION: 220 V | H14: SI | I14: ='SAF 11'!F12 -> UNIDAD | J14: ='SAF 11'!H12 -> 525000 | K14: ='SAF 11'!G12 -> 1
A15: 4 | B15: ='SAF 11'!B13 -> 4.3.3-8300.1 | C15: ='SAF 11'!E13 -> BICICLETAS P/ERGOMETRIA; VOLANTE DE INERCIA: 500 mm, ETAPA DE RESISTENCIA: 150 EN 150 Kgm, VOLANTE: DE INERCIA 500 mm | H15: SI | I15: ='SAF 11'!F13 -> UNIDAD | J15: ='SAF 11'!H13 -> 396807 | K15: ='SAF 11'!G13 -> 3
A16: 5 | B16: ='SAF 11'!B14 -> 4.3.3-5420.6 | C16: ='SAF 11'!E14 -> BOMBAS DE INFUSION; ALIMENTACION: 220 V, LECTURA: DISPLAY GRAFICO, VOLUMEN: 01-9999 ML, CONTRAPRESION: 40 KPA A 120 KPA | H16: SI | I16: ='SAF 11'!F14 -> UNIDAD | J16: ='SAF 11'!H14 -> 316490 | K16: ='SAF 11'!G14 -> 20
A17: 6 | B17: ='SAF 11'!B15 -> 2.9.5-7987.9 | C17: ='SAF 11'!E15 -> CAJAS DE INSTRUMENTAL; MATERIAL: ACERO INOXIDABLE, USO: CIRUGIA, CANTIDAD: 1 | H17: SI | I17: ='SAF 11'!F15 -> UNIDAD | J17: ='SAF 11'!H15 -> 15200 | K17: ='SAF 11'!G15 -> 20
A18: 7 | B18: ='SAF 11'!B16 -> 2.9.5-7987.9 | C18: ='SAF 11'!E16 -> CAJAS DE INSTRUMENTAL; MATERIAL: ACERO INOXIDABLE, USO: CIRUGIA, CANTIDAD: 1 | H18: SI | I18: ='SAF 11'!F16 -> UNIDAD | J18: ='SAF 11'!H16 -> 18000 | K18: ='SAF 11'!G16 -> 20
A19: 8 | B19: ='SAF 11'!B17 -> 2.9.5-7987.1 | C19: ='SAF 11'!E17 -> CAJAS DE INSTRUMENTAL; MATERIAL: ACERO INOXIDABLE, USO: EXAMEN GINECOLOG./INST.DE DIU, CANT.INSTRUMETAL: 10, CANTIDAD: 1 | H19: SI | I19: ='SAF 11'!F17 -> UNIDAD | J19: ='SAF 11'!H17 -> 36100 | K19: ='SAF 11'!G17 -> 7
A20: 9 | B20: ='SAF 11'!B18 -> 4.3.3-1719.48 | C20: ='SAF 11'!E18 -> CAMILLAS; ANCHO: 60 Cm, LARGO: 200 Cm, ALTO: 70 Cm, ARNESES: SIN, TIPO: RODANTE | H20: SI | I20: ='SAF 11'!F18 -> UNIDAD | J20: ='SAF 11'!H18 -> 62710 | K20: ='SAF 11'!G18 -> 20
A21: 10 | B21: ='SAF 11'!B19 -> 4.3.3-1719.27 | C21: ='SAF 11'!E19 -> CAMILLAS; ANCHO: 75 Cm, LARGO: 185 Cm, ALTO: 75 Cm, ARNESES: SIN, TIPO: KINESICA | H21: SI | I21: ='SAF 11'!F19 -> UNIDAD | J21: ='SAF 11'!H19 -> 66300 | K21: ='SAF 11'!G19 -> 3
A22: 11 | B22: ='SAF 11'!B20 -> 4.3.2-6331.12 | C22: ='SAF 11'!E20 -> CARROS P/TRANSP.; SUPERFICIE: 30 X 40 Cm, ALTURA: 120 Cm, MATERIAL: CHAPA METAL PLEGADA, ESTRUCTURA: METALICA, RUEDAS: 2 REFORZADAS- DIAM. 180 mm, ACCESORIO: 2 AGARRADERAS, MATERIAL ESTRUCTURA: METALICA | H22: SI | I22: ='SAF 11'!F20 -> UNIDAD | J22: ='SAF 11'!H20 -> 16756 | K22: ='SAF 11'!G20 -> 14
A23: 12 | B23: ='SAF 11'!B21 -> 4.3.3-5416.1 | C23: ='SAF 11'!E21 -> CARROS USO HOSPITALARIO; TERMINACION: ANTIOXIDANTE, ESTRUCTURA: REFORZADA DE CHAPA ACERO SAE, MEDIDAS: 0,70 X 0,50 X 0,90 M, PARACHOQUE: GOMA, PLANO SUPERIOR: ESTRATIFICADOS CON BARANDAS, CAJONES: CON, DIVISIONES: P/MATERIALES, MASTIL: CON, CONTENEDOR: P/RESIDUOS BIOLOGICOS, ALZADA SUPERIOR: PORTA CARDIODESFIBRILADOR, CANTIDAD DE CAJONES: CON, MATERIAL ESTRUCTURA: REFORZADA DE CHAPA ACERO SAE, DIMENSION: 0,70 X 0,50 X 0,90 M, TIPO: DE PARO | H23: SI | I23: ='SAF 11'!F21 -> UNIDAD | J23: ='SAF 11'!H21 -> 408143 | K23: ='SAF 11'!G21 -> 14
... A48: 37 | B48: ='SAF 11'!B46 -> 2.9.5-2020.1 | C48: ='SAF 11'!E46 -> TAMBORES QUIRURGICOS; MATERIAL: ACERO INOXIDABLE, DIMENSION: 10 X 12 Cm | H48: SI | I48: ='SAF 11'!F46 -> UNIDAD | J48: ='SAF 11'!H46 -> 11000 | K48: ='SAF 11'!G46 -> 20
A50: Costo total estimado: PESOS CINCUENTA MILLONES SETECIENTOS VEINTIOCHO MIL DOSCIENTOS SESENTA Y TRES CON 00/100.- | J50: =SUMPRODUCT(J12:J48,K12:K48) -> 50728263

Sheet APG
A1: EJERCICIO: | D1: 2022 | P1: AUTORIZACION PARA GASTAR
A4: JURISDICCIÓN: | G4: =NP!D3 -> 040 - MINISTERIO DE SALUD
A5: SAF: | G5: =NP!D4 -> 011 - DIRECCION PROVINCIAL DE ADMINISTRACION DEL MINISTERIO DE SALUD
A6: UNIDAD EJECUTORA: | G6: =NP!D5 -> 352 - MINISTERIO DE SALUD
A7: DEPENDENCIA SOLICITANTE: | G7: =NP!D6 -> 352 - MINISTERIO DE SALUD
A8: AUTORIZACIÓN:
A9: Señor Director de Administración o Titular del Servicio Administrativo Financiero:
A10: Autorizo la realización de los trámites correspondientes, a fin de proveer a este Organismo los bienes, servicios o ejecución de obras públicas que se detallan en Nota de Pedido N° XX/2022 , afectando la erogación resultante a los créditos presupuestarios aprobados a favor de esta Unidad Ejecutora, conforme al siguiente detalle:
A12: IMPUTACIÓN PRESUPUESTARIA
A13: CÓDIGO | O13: DENOMINACIÓN DE LA PARTIDA PRESUPUESTARIA | Q13: IMPORTE
A14: PR | B14: SB | C14: PY | D14: AC | E14: OB | F14: UG | G14: FIN | H14: FUN | I14: I | J14: P | K14: P | L14: SubP | M14: M | N14: FF
A15: 1 | D15: 1 | F15: 4901 | G15: 3 | H15: 1 | I15: 4 | J15: 3 | K15: 3 | M15: 1 | N15: 1.1 | O15: EQUIPOS SANITARIOS Y DE LABORATORIO | Q15: =NP!J50 -> 50728263
A38: TOTAL DE PESOS: CINCUENTA MILLONES SETECIENTOS VEINTIOCHO MIL DOSCIENTOS SESENTA Y TRES CON 00/100.- | Q38: =SUM(Q15:Q37) -> 50728263
A40: JUSTIFICACIÓN:
A41: =NP!D8 -> ADQUISICION DE UTILES MEDICOS Y EQUIPOS SANITARIOS Y DE LABORATORIO CON DESTINO A HOSPITALES DE LA PROVINCIA
