Workbook

Sheet REACTIVOS NT
B2: Pedido de Necesidades Trimestrales
A4: JURISDICCION: | C4: 40 - Ministerio de Salud
A5: SAF N°: | C5: 23 - Hospital Interzonal San Juan Bautista
A6: EJERCICIO: | C6: 2021
A7: TRIMESTRE: | C7: 1
A9: ID | B9: CODIGO ITEM | C9: RUBRO DE COMPRA | D9: I.P.P. | E9: DESCRIPCION | F9: UNIDAD DE MEDIDA | G9: CANTIDAD | H9: PRECIO UNITARIO ESTIMADO | I9: IMPORTE TOTAL ESTIMADO
A10: 1 | B10: 2.5.1-9016.181 | C10: QUIMICOS | D10: =LEFT(B10,5) -> 2.5.1 | E10: MEDIOS DE CULTIVO Y SUPLEMENTO; NOMBRE DEL PRODUCTO: AGAR MANITOL SALADO, ESTADO: SOLIDO, PRESENTACION: ENVASE X 100 GR | F10: Fco. | G10: 1 | H10: 1904.4 | I10: =G10*H10 -> 1904.4
A11: 2 | B11: 2.5.1-9016.148 | C11: QUIMICOS | D11: =LEFT(B11,5) -> 2.5.1 | E11: MEDIOS DE CULTIVO Y SUPLEMENTO; NOMBRE DEL PRODUCTO: AGAR BASE MUELLER-HINTON, ESTADO: SOLIDO, PRESENTACION: ENVASE X 500 GR | F11: Fco. | G11: 2 | H11: 12303.6 | I11: =G11*H11 -> 24607.2
A12: 3 | B12: 2.5.1-9016.713 | C12: QUIMICOS | D12: =LEFT(B12,5) -> 2.5.1 | E12: MEDIOS DE CULTIVO Y SUPLEMENTO; NOMBRE DEL PRODUCTO: AGAR LEVINE, ESTADO: SOLIDO, PRESENTACION: ENVASE X 500 GR | F12: Fco. | G12: 1 | H12: 9331.2 | I12: =G12*H12 -> 9331.2
A13: 4 | B13: 2.5.1-9016.383 | C13: QUIMICOS | D13: =LEFT(B13,5) -> 2.5.1 | E13: MEDIOS DE CULTIVO Y SUPLEMENTO; NOMBRE DEL PRODUCTO: AGAR C.L.D.E, ESTADO: SOLIDO, PRESENTACION: ENVASE X 500 GR | F13: Fco. | G13: 1 | H13: 9242.4 | I13: =G13*H13 -> 9242.4
A14: 5 | B14: 2.5.1-9016.630 | C14: QUIMICOS | D14: =LEFT(B14,5) -> 2.5.1 | E14: MEDIOS DE CULTIVO Y SUPLEMENTO; NOMBRE DEL PRODUCTO: AGAR BASE SANGRE, ESTADO: SOLIDO, PRESENTACION: ENVASE X 500 GR | F14: Fco. | G14: 2 | H14: 13279.2 | I14: =G14*H14 -> 26558.4
A15: 6 | B15: 2.5.1-9016.497 | C15: QUIMICOS | D15: =LEFT(B15,5) -> 2.5.1 | E15: MEDIOS DE CULTIVO Y SUPLEMENTO; NOMBRE DEL PRODUCTO: MEDIO MIO, ESTADO: SOLIDO, PRESENTACION: ENVASE X 100 GR | F15: Fco. | G15: 1 | H15: 8490 | I15: =G15*H15 -> 8490
A16: 7 | B16: 2.5.1-9016.271 | C16: QUIMICOS | D16: =LEFT(B16,5) -> 2.5.1 | E16: MEDIOS DE CULTIVO Y SUPLEMENTO; NOMBRE DEL PRODUCTO: AGAR TIOGLICOLATO RESAZURINA, ESTADO: SOLIDO, PRESENTACION: ENVASE X 100 GR | F16: Fco. | G16: 2 | H16: 3426 | I16: =G16*H16 -> 6852
A17: 8 | B17: 2.5.1-9016.261 | C17: QUIMICOS | D17: =LEFT(B17,5) -> 2.5.1 | E17: MEDIOS DE CULTIVO Y SUPLEMENTO; NOMBRE DEL PRODUCTO: AGAR SABOURAUD GLUCOSA, ESTADO: SOLIDO, PRESENTACION: ENVASE X 100 GR | F17: Fco. | G17: 1 | H17: 2761.2 | I17: =G17*H17 -> 2761.2
A18: 9 | B18: 2.5.1-9016.191 | C18: QUIMICOS | D18: =LEFT(B18,5) -> 2.5.1 | E18: MEDIOS DE CULTIVO Y SUPLEMENTO; NOMBRE DEL PRODUCTO: AGAR LISINA HIERRO, ESTADO: SOLIDO, PRESENTACION: ENVASE X 100 GR | F18: Fco. | G18: 1 | H18: 6540 | I18: =G18*H18 -> 6540
A19: 10 | B19: 2.5.1-9016.214 | C19: QUIMICOS | D19: =LEFT(B19,5) -> 2.5.1 | E19: MEDIOS DE CULTIVO Y SUPLEMENTO; NOMBRE DEL PRODUCTO: AGAR CITRATO DE SIMMONS, ESTADO: SOLIDO, PRESENTACION: ENVASE X 100 GR | F19: Fco. | G19: 1 | H19: 4640.4 | I19: =G19*H19 -> 4640.4
A20: 11 | B20: 2.5.1-9016.892 | C20: QUIMICOS | D20: =LEFT(B20,5) -> 2.5.1 | E20: MEDIOS DE CULTIVO Y SUPLEMENTO; NOMBRE DEL PRODUCTO: AGAR TSI, ESTADO: SOLIDO, PRESENTACION: ENVASE X 100 GR | F20: Fco. | G20: 1 | H20: 2851.2 | I20: =G20*H20 -> 2851.2
A21: 12 | B21: 2.5.1-9016.279 | C21: QUIMICOS | D21: =LEFT(B21,5) -> 2.5.1 | E21: MEDIOS DE CULTIVO Y SUPLEMENTO; NOMBRE DEL PRODUCTO: AGAR BILIS ESCULINA, ESTADO: SOLIDO, PRESENTACION: ENVASE X 100 GR | F21: Fco. | G21: 1 | H21: 15903.6 | I21: =G21*H21 -> 15903.6
... A23: 14 | B23: 2.5.1-9043.2 | C23: QUIMICOS | D23: =LEFT(B23,5) -> 2.5.1 | E23: ACEITES Y GRASAS; COMPUESTO QUIMICO: ACEITE DE INMERSION, ESTADO: LIQUIDO, CALIDAD: PRO ANALISIS, CONCENTRACION/PUREZA: 99,9 %, PRESENTACION: ENVASE X 100 Ml | F23: Fco. | G23: 12 | H23: 1671.6 | I23: =G23*H23 -> 20059.2
A24: 15 | B24: 2.5.1 | D24: =LEFT(B24,5) -> 2.5.1 | E24: IODURO DE POTASIO X 250 GR TIPO BIOPACK | F24: Fco. | G24: 1 | H24: 8918.4 | I24: =G24*H24 -> 8918.4
A25: 16 | B25: 2.5.1 | D25: =LEFT(B25,5) -> 2.5.1 | E25: DISCOS DE GENTAMICINA 10 UG X 50 T/BRITANIA | F25: Fco. | G25: 5 | H25: 587.4 | I25: =G25*H25 -> 2937
A26: 17 | B26: 2.5.1 | D26: =LEFT(B26,5) -> 2.5.1 | E26: DISCOS DE PIPERACILINA /TAZOBACTAM 100/10 X 50 T/BRITANIA | F26: Fco. | G26: 4 | H26: 584.4 | I26: =G26*H26 -> 2337.6
A27: 18 | B27: 2.5.1-9038.342 | C27: QUIMICOS | D27: =LEFT(B27,5) -> 2.5.1 | E27: REACTIVO INDICADOR-COLORANTE; COMPUESTO QUIMICO: DECOLORANTE GRAM, ESTADO: SOLUCION, CALIDAD: PRO ANALISIS, PRESENTACION: ENVASE X 500 Ml | F27: Fco. | G27: 3 | H27: 2796 | I27: =G27*H27 -> 8388
A28: 19 | B28: 2.5.1 | D28: =LEFT(B28,5) -> 2.5.1 | E28: DISCOS DE FOSFOMICINA X 200 UG X 50T/BRITANIA | F28: Fco. | G28: 4 | H28: 820.8 | I28: =G28*H28 -> 3283.2
A29: 20 | B29: 2.5.1 | D29: =LEFT(B29,5) -> 2.5.1 | E29: DISCOS DE OXACILINA 1 UG X 50 T/BRITANIA | F29: Fco. | G29: 5 | H29: 820.8 | I29: =G29*H29 -> 4104
A30: 21 | B30: 2.5.1 | D30: =LEFT(B30,5) -> 2.5.1 | E30: DISCOS DE CEFAZOLINA 30 UG X 50 T/BRITANIA | F30: Fco. | G30: 10 | H30: 820.8 | I30: =G30*H30 -> 8208
A31: 22 | B31: 2.5.1-9052.834 | C31: QUIMICOS | D31: =LEFT(B31,5) -> 2.5.1 | E31: REACTIVOS P/LAB. TEC. MANUAL ; NOMBRE: TARJETA DE GEL LISS COOMBS, USO: IDENT ANTIGENOS ERITROCITARIOS, PRESENTACION: ENVASE X 48 UN | F31: CAJA | G31: 6 | H31: 16800 | I31: =G31*H31 -> 100800
A32: 23 | B32: 2.5.1-9052.247 | C32: QUIMICOS | D32: =LEFT(B32,5) -> 2.5.1 | E32: REACTIVOS P/LAB. TEC. MANUAL ; NOMBRE: SUERO HEMOTIPIFICADOR ANTI-AB, USO: HEMOTERAPIA, PRESENTACION: ENVASE X 10 Ml | F32: FRASCO | G32: 6 | H32: 2160 | I32: =G32*H32 -> 12960
A33: 24 | B33: 2.5.1-9052.240 | C33: QUIMICOS | D33: =LEFT(B33,5) -> 2.5.1 | E33: REACTIVOS P/LAB. TEC. MANUAL ; NOMBRE: SUERO HEMOTIPIFICADOR ANTI-A1, USO: HEMOTERAPIA, PRESENTACION: ENVASE X 10 mL | F33: FRASCO | G33: 30 | H33: 2160 | I33: =G33*H33 -> 64800
A34: 25 | B34: 2.5.1-9052.241 | C34: QUIMICOS | D34: =LEFT(B34,5) -> 2.5.1 | E34: REACTIVOS P/LAB. TEC. MANUAL ; NOMBRE: SUERO HEMOTIPIFICADOR ANTI-B, USO: HEMOTERAPIA, PRESENTACION: ENVASE X 10 mL | F34: FRASCO | G34: 30 | H34: 2160 | I34: =G34*H34 -> 64800
A35: 26 | B35: 2.5.1-9052.248 | C35: QUIMICOS | D35: =LEFT(B35,5) -> 2.5.1 | E35: REACTIVOS P/LAB. TEC. MANUAL ; NOMBRE: SUERO HEMOTIPIFICADOR ANTI-D, USO: HEMOTERAPIA, PRESENTACION: ENVASE X 10 mL | F35: FRASCO | G35: 30 | H35: 3000 | I35: =G35*H35 -> 90000
A36: 27 | B36: 2.5.1-9052.1933 | C36: QUIMICOS | D36: =LEFT(B36,5) -> 2.5.1 | E36: REACTIVOS P/LAB. TEC. MANUAL ; NOMBRE: SUERO HEMOTIPIFICADOR ANTI-CDE, USO: HEMOTERAPIA, PRESENTACION: ENVASE X 10 mL | F36: FRASCO | G36: 9 | H36: 9120 | I36: =G36*H36 -> 82080
A37: 28 | B37: 2.5.1-9052.249 | C37: QUIMICOS | D37: =LEFT(B37,5) -> 2.5.1 | E37: REACTIVOS P/LAB. TEC. MANUAL ; NOMBRE: SUERO HEMOTIPIFICADOR ANTI-C, USO: HEMOTERAPIA, PRESENTACION: ENVASE X 5 mL | F37: FRASCO | G37: 6 | H37: 7800 | I37: =G37*H37 -> 46800
A38: 29 | B38: 2.5.1-9052.250 | C38: QUIMICOS | D38: =LEFT(B38,5) -> 2.5.1 | E38: REACTIVOS P/LAB. TEC. MANUAL ; NOMBRE: SUERO HEMOT. ANTI-C (MIN.), USO: HEMOTERAPIA, PRESENTACION: ENVASE X 5 mL | F38: FRASCO | G38: 6 | H38: 9600 | I38: =G38*H38 -> 57600
A39: 30 | B39: 2.5.1-9052.251 | C39: QUIMICOS | D39: =LEFT(B39,5) -> 2.5.1 | E39: REACTIVOS P/LAB. TEC. MANUAL ; NOMBRE: SUERO HEMOTIPIFICADOR ANTI-E, USO: HEMOTERAPIA, PRESENTACION: ENVASE X 5 mL | F39: FRASCO | G39: 6 | H39: 7800 | I39: =G39*H39 -> 46800
A40: 31 | B40: 2.5.1-9052.252 | C40: QUIMICOS | D40: =LEFT(B40,5) -> 2.5.1 | E40: REACTIVOS P/LAB. TEC. MANUAL ; NOMBRE: SUERO HEMOT. ANTI-E (MIN.), USO: HEMOTERAPIA, PRESENTACION: ENVASE X 5 mL | F40: FRASCO | G40: 6 | H40: 9600 | I40: =G40*H40 -> 57600
A41: 32 | B41: 2.5.1-8988.2231 | C41: QUIMICOS | D41: =LEFT(B41,5) -> 2.5.1 | E41: REACTIVOS P/EQUIPO; EQUIPO: COAGULOMETRO, MARCA EQUIPO: DESTINY, NOMBRE DEL PRODUCTO: ANTICOAGULANTE LUPICO TAMIZAJE, PRESENTACION: 10 X ENVASE X 2 mL | F41: CAJA | G41: 1 | H41: 51433.2 | I41: =G41*H41 -> 51433.2
A42: 33 | B42: 2.5.1-8988.2232 | C42: QUIMICOS | D42: =LEFT(B42,5) -> 2.5.1 | E42: REACTIVOS P/EQUIPO; EQUIPO: COAGULOMETRO, MARCA EQUIPO: DESTINY, NOMBRE DEL PRODUCTO: ANTICOAG. LUPICO CONFIRMACION, PRESENTACION: 10 X ENVASE X 2 mL | F42: CAJA | G42: 1 | H42: 57858 | I42: =G42*H42 -> 57858
... A58: 49 | B58: 2.5.9-4083.3 | C58: QUIMICOS | D58: =LEFT(B58,5) -> 2.5.9 | E58: PARAFINA; PRESENTACION: ENVASE X 1 Kg, CAPACIDAD: 1 Kg, ESTADO: SOLIDO | F58: KG | G58: 15 | H58: 1468.8 | I58: =G58*H58 -> 22032
B60: Plazo de entrega: 10 dias - Lugar de entrega: Laboratorio Central del Hospital Interzonal San Juan Bautista - Av. Illia Esq. Mariano Moreno
...

Sheet REACTIVOS NPYE
A1: NOTA DE PEDIDO | J1: N° | K1: 368 - 2020
A3: JURISDICCIÓN: | D3: ='REACTIVOS NT'!C4 -> 40 - Ministerio de Salud
A4: SAF: | D4: ='REACTIVOS NT'!C5 -> 23 - Hospital Interzonal San Juan Bautista
A5: UNIDAD EJECUTORA: | D5: 168 - Direccion Asistencial
A6: DEPENDENCIA SOLICITANTE: | D6: Direccion Asistencial
A7: PERIODO UTILIZACIÓN: | D7: ='REACTIVOS NT'!C7 & "° Trimestre - Año " & 'REACTIVOS NT'!C6 -> 1° Trimestre - Año 2021
A8: OBJETO: | D8: Reactivos
A10: Ítem | B10: Codigo Item | C10: DESCRIPCIÓN | H10: Adjunta Detalle Técnico | I10: Unidad Medida | J10: Precio Unitario Estimado | K10: Cantidad Solicitada
A12: 1 | B12: ='REACTIVOS NT'!B10 -> 2.5.1-9016.181 | C12: ='REACTIVOS NT'!E10 -> MEDIOS DE CULTIVO Y SUPLEMENTO; NOMBRE DEL PRODUCTO: AGAR MANITOL SALADO, ESTADO: SOLIDO, PRESENTACION: ENVASE X 100 GR | H12: NO | I12: ='REACTIVOS NT'!F10 -> Fco. | J12: ='REACTIVOS NT'!H10 -> 1904.4 | K12: ='REACTIVOS NT'!G10 -> 1
A13: 2 | B13: ='REACTIVOS NT'!B11 -> 2.5.1-9016.148 | C13: ='REACTIVOS NT'!E11 -> MEDIOS DE CULTIVO Y SUPLEMENTO; NOMBRE DEL PRODUCTO: AGAR BASE MUELLER-HINTON, ESTADO: SOLIDO, PRESENTACION: ENVASE X 500 GR | H13: NO | I13: ='REACTIVOS NT'!F11 -> Fco. | J13: ='REACTIVOS NT'!H11 -> 12303.6 | K13: ='REACTIVOS NT'!G11 -> 2
A14: 3 | B14: ='REACTIVOS NT'!B12 -> 2.5.1-9016.713 | C14: ='REACTIVOS NT'!E12 -> MEDIOS DE CULTIVO Y SUPLEMENTO; NOMBRE DEL PRODUCTO: AGAR LEVINE, ESTADO: SOLIDO, PRESENTACION: ENVASE X 500 GR | H14: NO | I14: ='REACTIVOS NT'!F12 -> Fco. | J14: ='REACTIVOS NT'!H12 -> 9331.2 | K14: ='REACTIVOS NT'!G12 -> 1
A15: 4 | B15: ='REACTIVOS NT'!B13 -> 2.5.1-9016.383 | C15: ='REACTIVOS NT'!E13 -> MEDIOS DE CULTIVO Y SUPLEMENTO; NOMBRE DEL PRODUCTO: AGAR C.L.D.E, ESTADO: SOLIDO, PRESENTACION: ENVASE X 500 GR | H15: NO | I15: ='REACTIVOS NT'!F13 -> Fco. | J15: ='REACTIVOS NT'!H13 -> 9242.4 | K15: ='REACTIVOS NT'!G13 -> 1
A16: 5 | B16: ='REACTIVOS NT'!B14 -> 2.5.1-9016.630 | C16: ='REACTIVOS NT'!E14 -> MEDIOS DE CULTIVO Y SUPLEMENTO; NOMBRE DEL PRODUCTO: AGAR BASE SANGRE, ESTADO: SOLIDO, PRESENTACION: ENVASE X 500 GR | H16: NO | I16: ='REACTIVOS NT'!F14 -> Fco. | J16: ='REACTIVOS NT'!H14 -> 13279.2 | K16: ='REACTIVOS NT'!G14 -> 2
A17: 6 | B17: ='REACTIVOS NT'!B15 -> 2.5.1-9016.497 | C17: ='REACTIVOS NT'!E15 -> MEDIOS DE CULTIVO Y SUPLEMENTO; NOMBRE DEL PRODUCTO: MEDIO MIO, ESTADO: SOLIDO, PRESENTACION: ENVASE X 100 GR | H17: NO | I17: ='REACTIVOS NT'!F15 -> Fco. | J17: ='REACTIVOS NT'!H15 -> 8490 | K17: ='REACTIVOS NT'!G15 -> 1
A18: 7 | B18: ='REACTIVOS NT'!B16 -> 2.5.1-9016.271 | C18: ='REACTIVOS NT'!E16 -> MEDIOS DE CULTIVO Y SUPLEMENTO; NOMBRE DEL PRODUCTO: AGAR TIOGLICOLATO RESAZURINA, ESTADO: SOLIDO, PRESENTACION: ENVASE X 100 GR | H18: NO | I18: ='REACTIVOS NT'!F16 -> Fco. | J18: ='REACTIVOS NT'!H16 -> 3426 | K18: ='REACTIVOS NT'!G16 -> 2
A19: 8 | B19: ='REACTIVOS NT'!B17 -> 2.5.1-9016.261 | C19: ='REACTIVOS NT'!E17 -> MEDIOS DE CULTIVO Y SUPLEMENTO; NOMBRE DEL PRODUCTO: AGAR SABOURAUD GLUCOSA, ESTADO: SOLIDO, PRESENTACION: ENVASE X 100 GR | H19: NO | I19: ='REACTIVOS NT'!F17 -> Fco. | J19: ='REACTIVOS NT'!H17 -> 2761.2 | K19: ='REACTIVOS NT'!G17 -> 1
A20: 9 | B20: ='REACTIVOS NT'!B18 -> 2.5.1-9016.191 | C20: ='REACTIVOS NT'!E18 -> MEDIOS DE CULTIVO Y SUPLEMENTO; NOMBRE DEL PRODUCTO: AGAR LISINA HIERRO, ESTADO: SOLIDO, PRESENTACION: ENVASE X 100 GR | H20: NO | I20: ='REACTIVOS NT'!F18 -> Fco. | J20: ='REACTIVOS NT'!H18 -> 6540 | K20: ='REACTIVOS NT'!G18 -> 1
A21: 10 | B21: ='REACTIVOS NT'!B19 -> 2.5.1-9016.214 | C21: ='REACTIVOS NT'!E19 -> MEDIOS DE CULTIVO Y SUPLEMENTO; NOMBRE DEL PRODUCTO: AGAR CITRATO DE SIMMONS, ESTADO: SOLIDO, PRESENTACION: ENVASE X 100 GR | H21: NO | I21: ='REACTIVOS NT'!F19 -> Fco. | J21: ='REACTIVOS NT'!H19 -> 4640.4 | K21: ='REACTIVOS NT'!G19 -> 1
A22: 11 | B22: ='REACTIVOS NT'!B20 -> 2.5.1-9016.892 | C22: ='REACTIVOS NT'!E20 -> MEDIOS DE CULTIVO Y SUPLEMENTO; NOMBRE DEL PRODUCTO: AGAR TSI, ESTADO: SOLIDO, PRESENTACION: ENVASE X 100 GR | H22: NO | I22: ='REACTIVOS NT'!F20 -> Fco. | J22: ='REACTIVOS NT'!H20 -> 2851.2 | K22: ='REACTIVOS NT'!G20 -> 1
A23: 12 | B23: ='REACTIVOS NT'!B21 -> 2.5.1-9016.279 | C23: ='REACTIVOS NT'!E21 -> MEDIOS DE CULTIVO Y SUPLEMENTO; NOMBRE DEL PRODUCTO: AGAR BILIS ESCULINA, ESTADO: SOLIDO, PRESENTACION: ENVASE X 100 GR | H23: NO | I23: ='REACTIVOS NT'!F21 -> Fco. | J23: ='REACTIVOS NT'!H21 -> 15903.6 | K23: ='REACTIVOS NT'!G21 -> 1
... A60: 49 | B60: ='REACTIVOS NT'!B58 -> 2.5.9-4083.3 | C60: ='REACTIVOS NT'!E58 -> PARAFINA; PRESENTACION: ENVASE X 1 Kg, CAPACIDAD: 1 Kg, ESTADO: SOLIDO | H60: NO | I60: ='REACTIVOS NT'!F58 -> KG | J60: ='REACTIVOS NT'!H58 -> 1468.8 | K60: ='REACTIVOS NT'!G58 -> 15
A61: Costo total estimado: PESOS UN MILLON TRESCIENTOS VEINTIUN MIL CIENTO NOVENTA Y TRES CON 40/100.- | J61: =SUMPRODUCT(J12:J60,K12:K60) -> 1321193.4

Sheet REACTIVOS APG 
A1: EJERCICIO: | D1: ='REACTIVOS NT'!C6 -> 2021 | P1: AUTORIZACION PARA GASTAR
A4: JURISDICCIÓN: | G4: ='REACTIVOS NPYE'!D3 -> 40 - Ministerio de Salud
A5: SAF: | G5: ='REACTIVOS NPYE'!D4 -> 23 - Hospital Interzonal San Juan Bautista
A6: UNIDAD EJECUTORA: | G6: ='REACTIVOS NPYE'!D5 -> 168 - Direccion Asistencial
A7: DEPENDENCIA SOLICITANTE: | G7: ='REACTIVOS NPYE'!D6 -> Direccion Asistencial
A8: AUTORIZACIÓN:
A9: Señor Jefe de Servicio Administrativo Financiero:
A10: ="Autorizo la realización de los trámites correspondientes, a fin de proveer a este Organismo los bienes y/o servicios que se detallan en Nota de Pedido N° " & 'REACTIVOS NPYE'!K1&", afectando la erogación resultante a los créditos presupuestarios aprobados a favor de esta Unidad Ejecutora, conforme al siguiente detalle:" -> Autorizo la realización de los trámites correspondientes, a fin de proveer a este Organismo los bienes y/o servicios que se detallan en Nota de Pedido N° 368 - 2020, afectando la erogación resultante a los créditos presupuestarios aprobados a favor de esta Unidad Ejecutora, conforme al siguiente detalle:
A12: IMPUTACIÓN PRESUPUESTARIA
A13: CÓDIGO | O13: DENOMINACIÓN DE LA PARTIDA PRESUPUESTARIA | Q13: IMPORTE
A14: PR | B14: SB | C14: PY | D14: AC | E14: OB | F14: UG | G14: FIN | H14: FUN | I14: I | J14: P | K14: P | L14: SubP | M14: M | N14: FF
A15: 33 | D15: 2 | F15: 4901 | G15: 3 | H15: 3.1 | I15: 2 | J15: 5 | K15: 1 | M15: 1 | N15: 1.1 | O15: Compuestos Quimicos | Q15: 1299161.4
A16: 33 | D16: 2 | F16: 4901 | G16: 3 | H16: 3.1 | I16: 2 | J16: 5 | K16: 9 | M16: 1 | N16: 1.1 | O16: Otros NEP | Q16: 22032
A23: TOTAL DE PESOS: UN MILLON TRESCIENTOS VEINTIUN MIL CIENTO NOVENTA Y TRES CON 40/100.-- | Q23: =SUM(Q15:Q22) -> 1321193.4
A25: JUSTIFICACIÓN:
A26: Para la adquisición de Reactivos, para ser destinados al Hospital Interzonal San Juan Bautista del Ministerio de Salud.
