Workbook

Sheet SAF 011
A1: 2022
B2: Pedido de Necesidades Trimestrales
A4: JURISDICCION: | C4: 040 - MINISTERIO DE SALUD
A5: SAF N°: | C5: 011 - DIRECCION PROVINCIAL DE ADMINISTRACION - MINISTERIO DE SALUD
A6: EJERCICIO: | C6: 2022
A7: TRIMESTRE: | C7: PRIMERO
A9: ID | B9: CODIGO ITEM | C9: RUBRO DE COMPRA | D9: I.P.P. | E9: DESCRIPCION | F9: UNIDAD DE MEDIDA | G9: CANTIDAD TOTAL | H9: PRECIO UNITARIO ESTIMADO | I9: IMPORTE TOTAL ESTIMADO | J9: ESPECIFICACION TECNICA
A10: 1 | C10: PRODUCTOS MEDICOS/FARMACEUTICOS/LAB. | D10: 2.9.5 | E10: AGUJAS BD VACUTAINER PRECISIÓN GILDE 21G X 1 X 100 UND. | F10: CAJA | G10: 5 | H10: 18600 | I10: =G10*H10 -> 93000
A11: 2 | C11: PRODUCTOS MEDICOS/FARMACEUTICOS/LAB. | D11: 2.9.5 | E11: AMPOULE ADAPTER X 150 pcs TIPO ROCHE | F11: CAJA | G11: 2 | H11: 5689 | I11: =G11*H11 -> 11378
A12: 3 | C12: PRODUCTOS MEDICOS/FARMACEUTICOS/LAB. | D12: 2.9.5 | E12: APOSITOS; TIPO: POST EXTRACCION SANGUINEA, TAMAÑO: 40 X 40 mm (X 250 UNIDADES) | F12: CAJA | G12: 55 | H12: 600 | I12: =G12*H12 -> 33000
A13: 4 | C13: PRODUCTOS MEDICOS/FARMACEUTICOS/LAB. | D13: 2.9.5 | E13: BOLSAS DE SANGRE TRIPLE | F13: UNIDAD | G13: 1000 | H13: 1207 | I13: =G13*H13 -> 1207000
A14: 5 | C14: PRODUCTOS MEDICOS/FARMACEUTICOS/LAB. | D14: 2.9.5 | E14: BOLSAS DE SANGRE TRIPLE KS TIPO GRIFOLS PARA EL EQUIPAMIENTO DE AFERESIS GRIFOLS | F14: UNIDAD | G14: 1794 | H14: 1095 | I14: =G14*H14 -> 1964430
A15: 6 | C15: PRODUCTOS MEDICOS/FARMACEUTICOS/LAB. | D15: 2.9.5 | E15: CEPILLO LIMPIA PIPETA DE CERDA NATURAL DE 10 MM | F15: UNIDAD | G15: 10 | H15: 125 | I15: =G15*H15 -> 1250
A16: 7 | C16: PRODUCTOS MEDICOS/FARMACEUTICOS/LAB. | D16: 2.9.5 | E16: CEPILLO LIMPIA TUBOS DE HEMOLISIS TAMAÑO UNIVERSAL | F16: UNIDAD | G16: 100 | H16: 250 | I16: =G16*H16 -> 25000
A17: 8 | C17: PRODUCTOS MEDICOS/FARMACEUTICOS/LAB. | D17: 2.9.5 | E17: Criotubo Expell 5 ml Pre-esterilizados, graduado - Bolsa x 100 un Tipo CAPP (Dinamarca) | F17: BOLSA | G17: 30 | H17: 4690 | I17: =G17*H17 -> 140700
A18: 9 | C18: PRODUCTOS MEDICOS/FARMACEUTICOS/LAB. | D18: 2.9.5 | E18: CUBREOBJETOS HDA 20x20 MM x 200 U Tipo KINDER | F18: CAJA | G18: 400 | H18: 270 | I18: =G18*H18 -> 108000
A19: 10 | C19: PRODUCTOS MEDICOS/FARMACEUTICOS/LAB. | D19: 2.9.5 | E19: EPENDORF 0,5 ML BOLSA POR 200 UNIDADES CALIDAD BIOLOGIA MOLECULAR | F19: BOLSA | G19: 10 | H19: 4100 | I19: =G19*H19 -> 41000
A20: 11 | C20: PRODUCTOS MEDICOS/FARMACEUTICOS/LAB. | D20: 2.9.5 | E20: Ependorf 1,5 ml esteriles libres de ADNasa y RNAsa Bolsa fondo en U autoclaves x 500 tipo CAPP (Dinamarca) | F20: BOLSA | G20: 5 | H20: 2170 | I20: =G20*H20 -> 10850
A21: 12 | C21: PRODUCTOS MEDICOS/FARMACEUTICOS/LAB. | D21: 2.9.5 | E21: Ependorf 2 ml esteriles libres de ADNasa y RNAsa Bolsa x 500 tipo DELTALAB | F21: BOLSA | G21: 40 | H21: 3889 | I21: =G21*H21 -> 155560
... A65: 56 | C65: PRODUCTOS MEDICOS/FARMACEUTICOS/LAB. | D65: 2.9.5 | E65: TUBOS VACUTAINER SST TAPA AMARILLA 3.5 ML (100 TUBOS) | F65: CAJA | G65: 21 | H65: 22200 | I65: =G65*H65 -> 466200
E66: TOTAL RUBRO DESCARTABLE PARA LABORATORIO | I66: =SUM(I10:I65) -> 20071022
C68: DETALLE TECNICO Y ESPECIFICACIONES | D68: ANEXO 1-Para oferentes de la Provincia de Catamarca deberán presentar Habilitación Provincial para comercializar el producto que cotizan. 2-Para el resto de oferentes deberán presentar Certificado de Inscripción de ANMAT vigente al momento de la oferta, el mismo deberá ser correspondiente al objeto de la contratación y de encontrarse vencido adjuntar la solicitud de renovación. 3-No se aceptarán ofertas de productos no registrados y autorizada su venta por ANMAT. Se deberá especificar en cada ítem de la propuesta, marca y número de certificado otorgado por dicho ente regulador. 4-Los productos deberán tener un vencimiento posterior a doce (12) meses a partir de la fecha de su recepción.
C70: Plazos de entrega | D70: veinte (20) dias habiles
C72: Lugar de Entrega: | D72: * Los items 2, 7 AL 17, 19, 20, 22, 23, 26 AL 30, 32 AL 35, 37 (30 UNID), 38 (10 UNID), 39 AL 49 DIR. PROV. DE LABORATORIO - CHACABUCO N° 169 - en el horario de 8:00hs a 12:00hs de lunes a viernes * Los items 1, 3 (5 UNID), 21, 36 (3 UNID), 54 Y 56 DIR. PROV. CUR - CENTRO UNICO DE REFERENCIA - Dr Julio Herrera N° 250. en el horario de 8:00hs a 12:00hs de lunes a viernes - Los items 3 (50 UNID), 4 AL 6, 18, 24, 25, 31, 36 (7 UNID), 37, 38, 50, 51, 52, 53 y 55 DIR. PROV. BANCO DE SANGRE - Pasaje Boto Gray N°500 (frente la Maternida Provincial 25 de Mayo) en el horario de 8:00hs a 12:00hs de lunes a viernes.
C74: Calidad Minima esperada
C76: Mantenimiento | D76: cuarenta y cinco (45) días

Sheet NP LABORATORIO
A1: NOTA DE PEDIDO | J1: N° | K1: 04/2022
A3: JURISDICCIÓN: | D3: ='SAF 011'!C4 -> 040 - MINISTERIO DE SALUD
A4: SAF: | D4: ='SAF 011'!C5 -> 011 - DIRECCION PROVINCIAL DE ADMINISTRACION - MINISTERIO DE SALUD
A5: UNIDAD EJECUTORA: | D5: DIRECCION PROVINCIAL DE LABORATORIO
A6: DEPENDENCIA SOLICITANTE: | D6: DIRECCION PROVINCIAL DE LABORATORIO
A7: PERIODO UTILIZACIÓN: | D7: 1° TRIMESTRE 2022
A8: OBJETO: | D8: ADQ. DEL RUBRO DESCARTABLES PARA LABORATORIO
A10: Ítem | B10: Codigo Item | C10: DESCRIPCIÓN | H10: Adjunta Detalle Técnico | I10: Unidad Medida | J10: Precio Unitario Estimado | K10: Cantidad Solicitada
A12: 1 | C12: ='SAF 011'!E11 -> AMPOULE ADAPTER X 150 pcs TIPO ROCHE | H12: NO | I12: ='SAF 011'!F11 -> CAJA | J12: ='SAF 011'!H11 -> 5689 | K12: ='SAF 011'!#REF! -> #REF! | L12: =+K12*J12 -> #REF! | M12: =+J12*K12 -> #REF! | O12: =+M12 -> #REF!
A13: 2 | C13: ='SAF 011'!E16 -> CEPILLO LIMPIA TUBOS DE HEMOLISIS TAMAÑO UNIVERSAL | H13: NO | I13: ='SAF 011'!F16 -> UNIDAD | J13: ='SAF 011'!H16 -> 250 | K13: ='SAF 011'!#REF! -> #REF! | L13: =+K13*J13 -> #REF! | M13: =+J13*K13 -> #REF! | O13: =+M13 -> #REF!
A14: 3 | C14: ='SAF 011'!E17 -> Criotubo Expell 5 ml Pre-esterilizados, graduado - Bolsa x 100 un Tipo CAPP (Dinamarca) | H14: NO | I14: ='SAF 011'!F17 -> BOLSA | J14: ='SAF 011'!H17 -> 4690 | K14: ='SAF 011'!#REF! -> #REF! | L14: =+K14*J14 -> #REF! | M14: =+J14*K14 -> #REF! | O14: =+M14 -> #REF!
A15: 4 | C15: ='SAF 011'!E18 -> CUBREOBJETOS HDA 20x20 MM x 200 U Tipo KINDER | H15: NO | I15: ='SAF 011'!F18 -> CAJA | J15: ='SAF 011'!H18 -> 270 | K15: ='SAF 011'!#REF! -> #REF! | L15: =+K15*J15 -> #REF! | M15: =+J15*K15 -> #REF! | O15: =+M15 -> #REF!
A16: 5 | C16: ='SAF 011'!E19 -> EPENDORF 0,5 ML BOLSA POR 200 UNIDADES CALIDAD BIOLOGIA MOLECULAR | H16: NO | I16: ='SAF 011'!F19 -> BOLSA | J16: ='SAF 011'!H19 -> 4100 | K16: ='SAF 011'!#REF! -> #REF! | L16: =+K16*J16 -> #REF! | M16: =+J16*K16 -> #REF! | O16: =+M16 -> #REF!
A17: 6 | C17: ='SAF 011'!E20 -> Ependorf 1,5 ml esteriles libres de ADNasa y RNAsa Bolsa fondo en U autoclaves x 500 tipo CAPP (Dinamarca) | H17: NO | I17: ='SAF 011'!F20 -> BOLSA | J17: ='SAF 011'!H20 -> 2170 | K17: ='SAF 011'!#REF! -> #REF! | L17: =+K17*J17 -> #REF! | M17: =+J17*K17 -> #REF! | O17: =+M17 -> #REF!
A18: 7 | C18: ='SAF 011'!E21 -> Ependorf 2 ml esteriles libres de ADNasa y RNAsa Bolsa x 500 tipo DELTALAB | H18: NO | I18: ='SAF 011'!F21 -> BOLSA | J18: ='SAF 011'!H21 -> 3889 | K18: ='SAF 011'!#REF! -> #REF! | L18: =+K18*J18 -> #REF! | M18: =+J18*K18 -> #REF! | O18: =+M18 -> #REF!
A19: 8 | C19: ='SAF 011'!E22 -> ETIQUETAS PARA IMPRESORA ZEBRA x 12 ROLLOS DE 1800 ETIQUETAS C/U | H19: NO | I19: ='SAF 011'!F22 -> CAJA | J19: ='SAF 011'!H22 -> 15800 | K19: ='SAF 011'!#REF! -> #REF! | L19: =+K19*J19 -> #REF! | M19: =+J19*K19 -> #REF! | N19: =+M19 -> #REF!
A20: 9 | C20: ='SAF 011'!E23 -> Frasco de Bioseguridad Triple Tipo SISTEG M6 | H20: NO | I20: ='SAF 011'!F23 -> UNIDAD | J20: ='SAF 011'!H23 -> 7100.5 | K20: ='SAF 011'!#REF! -> #REF! | L20: =+K20*J20 -> #REF! | M20: =+J20*K20 -> #REF! | O20: =+M20 -> #REF!
A21: 10 | C21: ='SAF 011'!E24 -> Gradilla alambre / plastico 24 Tubos 30 MM Tipo ARGA | H21: NO | I21: ='SAF 011'!F24 -> UNIDAD | J21: ='SAF 011'!H24 -> 2762 | K21: ='SAF 011'!#REF! -> #REF! | L21: =+K21*J21 -> #REF! | M21: =+J21*K21 -> #REF! | O21: =+M21 -> #REF!
A22: 11 | C22: ='SAF 011'!E25 -> Gradilla alambre / plastico 48 Tubos 30 MM Tipo ARGA | H22: NO | I22: ='SAF 011'!F25 -> UNIDAD | J22: ='SAF 011'!H25 -> 4390 | K22: ='SAF 011'!#REF! -> #REF! | L22: =+K22*J22 -> #REF! | M22: =+J22*K22 -> #REF! | O22: =+M22 -> #REF!
A23: 12 | C23: ='SAF 011'!E26 -> Gradilla PP resistente 80ºC 80 Tubos Eppendorf Tipo DELTALAB | H23: NO | I23: ='SAF 011'!F26 -> UNIDAD | J23: ='SAF 011'!H26 -> 883 | K23: ='SAF 011'!#REF! -> #REF! | L23: =+K23*J23 -> #REF! | M23: =+J23*K23 -> #REF! | O23: =+M23 -> #REF!
A24: 13 | C24: ='SAF 011'!E28 -> HISOPOS NASOFARINGEOS DE DACRON O NYLON | H24: NO | I24: ='SAF 011'!F28 -> UNIDAD | J24: ='SAF 011'!H28 -> 65 | K24: ='SAF 011'!#REF! -> #REF! | L24: =+K24*J24 -> #REF! | M24: =+J24*K24 -> #REF! | O24: =+M24 -> #REF!
A25: 14 | C25: ='SAF 011'!E29 -> JERINGAS HEPARINIZADAS PARA GASES 3 ML X100 UNIDADES TIPO BD | H25: NO | I25: ='SAF 011'!F29 -> CAJA | J25: ='SAF 011'!H29 -> 10312 | K25: ='SAF 011'!#REF! -> #REF! | L25: =+K25*J25 -> #REF! | M25: =+J25*K25 -> #REF! | O25: =+M25 -> #REF!
A26: 15 | C26: ='SAF 011'!E31 -> MICROHEMATOCRITO SIN HEPARINA X100 | H26: NO | I26: ='SAF 011'!F31 -> CAJA | J26: ='SAF 011'!H31 -> 779 | K26: ='SAF 011'!#REF! -> #REF! | L26: =+K26*J26 -> #REF! | M26: =+J26*K26 -> #REF! | O26: =+M26 -> #REF!
A27: 16 | C27: ='SAF 011'!E32 -> MICROHEMATOCRITO CON HEPARINA X100 | H27: NO | I27: ='SAF 011'!F32 -> CAJA | J27: ='SAF 011'!H32 -> 892 | K27: ='SAF 011'!#REF! -> #REF! | L27: =+K27*J27 -> #REF! | M27: =+J27*K27 -> #REF! | O27: =+M27 -> #REF!
A28: 17 | C28: ='SAF 011'!E35 -> PIPETA AUTOMATICA TIPO SOCOREX VOL REGULABLE DE 10-100 ul | H28: NO | I28: ='SAF 011'!F35 -> UNIDAD | J28: ='SAF 011'!H35 -> 90938 | K28: ='SAF 011'!#REF! -> #REF! | L28: =+K28*J28 -> #REF! | M28: =+J28*K28 -> #REF! | O28: =+M28 -> #REF!
A29: 18 | C29: ='SAF 011'!E36 -> PIPETA AUTOMATICA TIPO SOCOREX VOL REGULABLE DE 20-200 ul | H29: NO | I29: ='SAF 011'!F36 -> UNIDAD | J29: ='SAF 011'!H36 -> 96849 | K29: ='SAF 011'!#REF! -> #REF! | L29: =+K29*J29 -> #REF! | M29: =+J29*K29 -> #REF! | O29: =+M29 -> #REF!
A30: 19 | C30: ='SAF 011'!E37 -> PIPETA AUTOMATICA TIPO SOCOREX VOL REGULABLE DE 5-50 ul | H30: NO | I30: ='SAF 011'!F37 -> UNIDAD | J30: ='SAF 011'!H37 -> 90938 | K30: ='SAF 011'!#REF! -> #REF! | L30: =+K30*J30 -> #REF! | M30: =+J30*K30 -> #REF! | O30: =+M30 -> #REF!
A31: 20 | C31: ='SAF 011'!E38 -> Placa de PCR Expell de 96 pocillos x 0,1 /0,2 ml, sin pollera Calidad Biologia Molecular Libre de DNAasa y RNAasa x 25 Un Tipo CAPP (Dinamarca) | H31: NO | I31: ='SAF 011'!F38 -> CAJA | J31: ='SAF 011'!H38 -> 28137 | K31: ='SAF 011'!#REF! -> #REF! | L31: =+K31*J31 -> #REF! | M31: =+J31*K31 -> #REF! | O31: =+M31 -> #REF!
A32: 21 | C32: ='SAF 011'!E39 -> PLACA DE VIDRIO PARA VDRL X 12 POCILLOS | H32: NO | I32: ='SAF 011'!F39 -> UNIDAD | J32: ='SAF 011'!H39 -> 2100 | K32: ='SAF 011'!#REF! -> #REF! | L32: =+K32*J32 -> #REF! | M32: =+J32*K32 -> #REF! | O32: =+M32 -> #REF!
A33: 22 | C33: ='SAF 011'!E41 -> Portaobjetos borde sin pulir 50 U Tipo BREMEN | H33: NO | I33: ='SAF 011'!F41 -> CAJA | J33: ='SAF 011'!H41 -> 248 | K33: ='SAF 011'!#REF! -> #REF! | L33: =+K33*J33 -> #REF! | M33: =+J33*K33 -> #REF! | O33: =+M33 -> #REF!
A34: 23 | C34: ='SAF 011'!E42 -> rollo de papel para MINIVIDAS x5 unidades | H34: NO | I34: ='SAF 011'!F42 -> PACK | J34: ='SAF 011'!H42 -> 5100 | K34: ='SAF 011'!#REF! -> #REF! | L34: =+K34*J34 -> #REF! | M34: =+J34*K34 -> #REF! | N34: =+M34 -> #REF!
A35: 24 | C35: ='SAF 011'!E43 -> TERMOMETRO DE ALCOHOL -10 A 60°C | H35: NO | I35: ='SAF 011'!F43 -> UNIDAD | J35: ='SAF 011'!H43 -> 442 | K35: ='SAF 011'!#REF! -> #REF! | L35: =+K35*J35 -> #REF! | M35: =+J35*K35 -> #REF! | O35: =+M35 -> #REF!
A36: 25 | C36: ='SAF 011'!E44 -> TIMER DIGITAL 5 TIEMPOS | H36: NO | I36: ='SAF 011'!F44 -> UNIDAD | J36: ='SAF 011'!H44 -> 1710 | K36: ='SAF 011'!#REF! -> #REF! | L36: =+K36*J36 -> #REF! | M36: =+J36*K36 -> #REF! | O36: =+M36 -> #REF!
A37: 26 | C37: ='SAF 011'!E46 -> TIPS AMARILLO 5-200 UL SIN CORONA bolsa X 1000 UNIDADES | H37: NO | I37: ='SAF 011'!F46 -> BOLSA | J37: ='SAF 011'!H46 -> 1540 | K37: ='SAF 011'!#REF! -> #REF! | L37: =+K37*J37 -> #REF! | M37: =+J37*K37 -> #REF! | O37: =+M37 -> #REF!
A38: 27 | C38: =+'SAF 011'!E47 -> TIPS AZUL 100-1000 ul bolsa X 1000 UNIDADES CON CORONA | H38: NO | I38: =+'SAF 011'!F47 -> BOLSA | J38: =+'SAF 011'!H47 -> 2204 | K38: =+'SAF 011'!#REF! -> #REF! | L38: =+K38*J38 -> #REF! | M38: =+J38*K38 -> #REF! | O38: =+M38 -> #REF!
A39: 28 | C39: ='SAF 011'!E48 -> TIPS BLANCO GRADUADO 0.1-10 ul C/CORONA BOLSA POR 1000 UNIDADES | H39: NO | I39: ='SAF 011'!F48 -> BOLSA | J39: ='SAF 011'!H48 -> 10402 | K39: ='SAF 011'!#REF! -> #REF! | L39: =+K39*J39 -> #REF! | M39: =+J39*K39 -> #REF! | O39: =+M39 -> #REF!
A40: 29 | C40: ='SAF 011'!E49 -> Tips ExpeIIPlus 10 UL Largos, c/filtro Libre de ARNasa y ADNasa Bolsa x 1000 unidades . Tipo NEW LEAF | H40: NO | I40: ='SAF 011'!F49 -> BOLSA | J40: ='SAF 011'!H49 -> 10761 | K40: ='SAF 011'!#REF! -> #REF! | L40: =+K40*J40 -> #REF! | M40: =+J40*K40 -> #REF! | O40: =+M40 -> #REF!
A41: 30 | C41: ='SAF 011'!E50 -> Tips ExpeIIPlus 1000 UL c/filtro Libre de ARNasa y ADNasa Bolsa x 1000 unidades. Tipo NEW LEAF | H41: NO | I41: ='SAF 011'!F50 -> BOLSA | J41: ='SAF 011'!H50 -> 12668 | K41: ='SAF 011'!#REF! -> #REF! | L41: =+K41*J41 -> #REF! | M41: =+J41*K41 -> #REF! | O41: =+M41 -> #REF!
A42: 31 | C42: ='SAF 011'!E51 -> Tips ExpeIIPlus 20 UL , c/filtro Libre de ARNasa y ADNasa Bolsa x 1000 unidades . Tipo NEW LEAF | H42: NO | I42: ='SAF 011'!F51 -> BOLSA | J42: ='SAF 011'!H51 -> 10761 | K42: ='SAF 011'!#REF! -> #REF! | L42: =+K42*J42 -> #REF! | M42: =+J42*K42 -> #REF! | O42: =+M42 -> #REF!
A43: 32 | C43: ='SAF 011'!E52 -> Tips ExpeIIPlus 200 UL c/filtro Libre de ARNasa y ADNasa Bolsa x 1000 unidades. Tipo NEW LEAF | H43: NO | I43: ='SAF 011'!F52 -> BOLSA | J43: ='SAF 011'!H52 -> 16783 | K43: ='SAF 011'!#REF! -> #REF! | L43: =+K43*J43 -> #REF! | M43: =+J43*K43 -> #REF! | O43: =+M43 -> #REF!
...

Sheet APG LABORATORIO
A1: EJERCICIO: | D1: 2022 | P1: AUTORIZACION PARA GASTAR
A4: JURISDICCIÓN: | G4: ='NP LABORATORIO'!D3 -> 040 - MINISTERIO DE SALUD
A5: SAF: | G5: ='NP LABORATORIO'!D4 -> 011 - DIRECCION PROVINCIAL DE ADMINISTRACION - MINISTERIO DE SALUD
A6: UNIDAD EJECUTORA: | G6: ='NP LABORATORIO'!D5 -> DIRECCION PROVINCIAL DE LABORATORIO
A7: DEPENDENCIA SOLICITANTE: | G7: ='NP LABORATORIO'!D6 -> DIRECCION PROVINCIAL DE LABORATORIO
A8: AUTORIZACIÓN:
A9: Señor Director de Administración o Titular del Servicio Administrativo Financiero:
A10: Autorizo la realización de los trámites correspondientes, a fin de proveer a este Organismo los bienes que se detallan en Nota de Pedido N° 04/2022 afectando la erogación resultante a los créditos presupuestarios aprobados a favor de esta Unidad Ejecutora, conforme al siguiente detalle:
A12: IMPUTACIÓN PRESUPUESTARIA
A13: CÓDIGO | O13: DENOMINACIÓN DE LA PARTIDA PRESUPUESTARIA | Q13: IMPORTE
A14: PR | B14: SB | C14: PY | D14: AC | E14: OB | F14: UG | G14: FIN | H14: FUN | I14: I | J14: P | K14: P | L14: SubP | M14: M | N14: FF
A15: 62 | D15: 1 | F15: 4901 | G15: 3 | H15: 1 | I15: 2 | J15: 3 | K15: 4 | M15: 1 | N15: 1.1 | O15: PRODUCTOS DE PAPEL Y CARTON | Q15: ='NP LABORATORIO'!N51 -> #REF!
A16: 62 | D16: 1 | F16: 4901 | G16: 3 | H16: 1 | I16: 2 | J16: 9 | K16: 5 | M16: 1 | N16: 1.1 | O16: UTILES MENORES MEDICOS, QUIRURGICOS Y DE LABORATORIO | Q16: ='NP LABORATORIO'!O51 -> #REF!
A36: TOTAL DE PESOS: QUINCE MILLONES SEISCIENTOS SETENTA Y DOS MIL DOSCIENTOS NOVENTA Y CUATRO CON 00/100.- | Q36: =SUM(Q15:Q35) -> #REF!
A38: JUSTIFICACIÓN:
A39: ='NP LABORATORIO'!D8 -> ADQ. DEL RUBRO DESCARTABLES PARA LABORATORIO

Sheet NP BANCO DE SANGRE
A1: NOTA DE PEDIDO | J1: N° | K1: 05/2022
A3: JURISDICCIÓN: | D3: ='SAF 011'!C4 -> 040 - MINISTERIO DE SALUD
A4: SAF: | D4: ='SAF 011'!C5 -> 011 - DIRECCION PROVINCIAL DE ADMINISTRACION - MINISTERIO DE SALUD
A5: UNIDAD EJECUTORA: | D5: DIRECCION PROVINCIAL BANCO DE SANGRE
A6: DEPENDENCIA SOLICITANTE: | D6: DIRECCION PROVINCIAL BANCO DE SANGRE
A7: PERIODO UTILIZACIÓN: | D7: 1° TRIMESTRE 2022
A8: OBJETO: | D8: ADQ. DEL RUBRO DESCARTABLES PARA LABORATORIO
A10: Ítem | B10: Codigo Item | C10: DESCRIPCIÓN | H10: Adjunta Detalle Técnico | I10: Unidad Medida | J10: Precio Unitario Estimado | K10: Cantidad Solicitada
A12: 1 | C12: =+'SAF 011'!E12 -> APOSITOS; TIPO: POST EXTRACCION SANGUINEA, TAMAÑO: 40 X 40 mm (X 250 UNIDADES) | H12: NO | I12: =+'SAF 011'!F12 -> CAJA | J12: =+'SAF 011'!H12 -> 600 | K12: =+'SAF 011'!#REF! -> #REF! | M12: =+J12*K12 -> #REF!
A13: 2 | C13: ='SAF 011'!E13 -> BOLSAS DE SANGRE TRIPLE | H13: NO | I13: ='SAF 011'!F13 -> UNIDAD | J13: ='SAF 011'!H13 -> 1207 | K13: ='SAF 011'!#REF! -> #REF! | M13: =+J13*K13 -> #REF!
A14: 3 | C14: ='SAF 011'!E14 -> BOLSAS DE SANGRE TRIPLE KS TIPO GRIFOLS PARA EL EQUIPAMIENTO DE AFERESIS GRIFOLS | H14: NO | I14: ='SAF 011'!F14 -> UNIDAD | J14: ='SAF 011'!H14 -> 1095 | K14: ='SAF 011'!#REF! -> #REF! | M14: =+J14*K14 -> #REF!
A15: 4 | C15: ='SAF 011'!E15 -> CEPILLO LIMPIA PIPETA DE CERDA NATURAL DE 10 MM | H15: NO | I15: ='SAF 011'!F15 -> UNIDAD | J15: ='SAF 011'!H15 -> 125 | K15: ='SAF 011'!#REF! -> #REF! | M15: =+J15*K15 -> #REF!
A16: 5 | C16: ='SAF 011'!E27 -> GUIA V20 C/RUEDITA *SANGRE* | H16: NO | I16: ='SAF 011'!F27 -> UNIDAD | J16: ='SAF 011'!H27 -> 92 | K16: ='SAF 011'!#REF! -> #REF! | M16: =+J16*K16 -> #REF!
A17: 6 | C17: ='SAF 011'!E33 -> MICROPIPETAS REGULABLES; CAPACIDAD: 100 - 1000 µL, DIVISIONES: CADA 5 µL, MATERIAL: PLASTICO | H17: NO | I17: ='SAF 011'!F33 -> UNIDAD | J17: ='SAF 011'!H33 -> 52350 | K17: ='SAF 011'!#REF! -> #REF! | M17: =+J17*K17 -> #REF!
A18: 7 | C18: ='SAF 011'!E34 -> MICROPIPETAS REGULABLES; CAPACIDAD: 10-100 µL, DIVISIONES: CADA 1 µL, MATERIAL: PLASTICO | H18: NO | I18: ='SAF 011'!F34 -> UNIDAD | J18: ='SAF 011'!H34 -> 50350 | K18: ='SAF 011'!#REF! -> #REF! | M18: =+J18*K18 -> #REF!
A19: 8 | C19: ='SAF 011'!E40 -> PLACA PARA VDRL CON POCILLO PROFUNDO 12 HOYOS | H19: NO | I19: ='SAF 011'!F40 -> UNIDAD | J19: ='SAF 011'!H40 -> 1220 | K19: ='SAF 011'!#REF! -> #REF! | M19: =+J19*K19 -> #REF!
A20: 9 | C20: ='SAF 011'!E45 -> TIPS AMARILLO 5-200 UL CON CORONA bolsa X 1000 UNIDADES | H20: NO | I20: ='SAF 011'!F45 -> BOLSA | J20: ='SAF 011'!H45 -> 2865 | K20: ='SAF 011'!#REF! -> #REF! | M20: =+J20*K20 -> #REF!
A21: 10 | C21: ='SAF 011'!E46 -> TIPS AMARILLO 5-200 UL SIN CORONA bolsa X 1000 UNIDADES | H21: NO | I21: ='SAF 011'!F46 -> BOLSA | J21: ='SAF 011'!H46 -> 1540 | K21: ='SAF 011'!#REF! -> #REF! | M21: =+J21*K21 -> #REF!
A22: 11 | C22: ='SAF 011'!E47 -> TIPS AZUL 100-1000 ul bolsa X 1000 UNIDADES CON CORONA | H22: NO | I22: ='SAF 011'!F47 -> BOLSA | J22: ='SAF 011'!H47 -> 2204 | K22: ='SAF 011'!#REF! -> #REF! | M22: =+J22*K22 -> #REF!
A23: 12 | C23: ='SAF 011'!E59 -> TUBOS DE ENSAYO; TIPO: CONICO P/CENTRIFUGA, MATERIAL: POLIPROPILENO, DIMENSION: 0,5 A 15 mL, ACCESORIO: SIN VALOR, ACCESORIOS: SIN VALOR (X 1000 UNIDADES) | H23: NO | I23: ='SAF 011'!F59 -> BOLSA | J23: ='SAF 011'!H59 -> 5353 | K23: ='SAF 011'!#REF! -> #REF! | M23: =+J23*K23 -> #REF!
A24: 13 | C24: ='SAF 011'!E60 -> TUBOS DE ENSAYO; TIPO: EPPENDORF, MATERIAL: PLASTICO, DIMENSION: 1.5 mL, ACCESORIOS: SIN, ACCESORIO: SIN (X 1000 UNIDADES) | H24: NO | I24: ='SAF 011'!F60 -> BOLSA | J24: ='SAF 011'!H60 -> 3558 | K24: ='SAF 011'!#REF! -> #REF! | M24: =+J24*K24 -> #REF!
A25: 14 | C25: ='SAF 011'!E61 -> TUBOS DE ENSAYO; TIPO: VACUTAINER UN, MATERIAL: VIDRIO, DIMENSION: 10 mL, ACCESORIOS: SIN, ACCESORIO: SIN (X 100 UNIDADES) | H25: NO | I25: ='SAF 011'!F61 -> CAJA | J25: ='SAF 011'!H61 -> 13000 | K25: ='SAF 011'!#REF! -> #REF! | M25: =+J25*K25 -> #REF!
A26: 15 | C26: ='SAF 011'!E62 -> TUBOS DE HEMOLISIS; MATERIAL: VIDRIO, PRESENTACION: CAJA, DIMENSION: 100 X 13 DIAM. EXT., MEDIDAS: 100 X 13 DIAM. EXT., FORMA DE PRESENTACION: SOLIDO, ESTADO: SOLIDO (CAJA X 1000 UNIDADES) | H26: NO | I26: ='SAF 011'!F62 -> CAJA | J26: ='SAF 011'!H62 -> 72000 | K26: ='SAF 011'!#REF! -> #REF! | M26: =+J26*K26 -> #REF!
A27: 16 | C27: ='SAF 011'!E64 -> TUBOS VACUTAINER P/SUERO DE 4ML, TAPA ROJA C/ETIQUETA (1000 TUBOS) | H27: NO | I27: ='SAF 011'!F64 -> CAJA | J27: ='SAF 011'!H64 -> 13700 | K27: ='SAF 011'!#REF! -> #REF! | M27: =+J27*K27 -> #REF!
A29: Costo total estimado: TRES MILLONES SETECIENTOS ONCE MIL CUATROCIENTOS TREINTA Y TRES CON 00/100.- | J29: =+M29 -> #REF! | M29: =SUM(M12:M28) -> #REF!

Sheet APG BANCO DE SANGRE
A1: EJERCICIO: | D1: 2022 | P1: AUTORIZACION PARA GASTAR
A4: JURISDICCIÓN: | G4: ='NP BANCO DE SANGRE'!D3 -> 040 - MINISTERIO DE SALUD
A5: SAF: | G5: ='NP BANCO DE SANGRE'!D4 -> 011 - DIRECCION PROVINCIAL DE ADMINISTRACION - MINISTERIO DE SALUD
A6: UNIDAD EJECUTORA: | G6: ='NP BANCO DE SANGRE'!D5 -> DIRECCION PROVINCIAL BANCO DE SANGRE
A7: DEPENDENCIA SOLICITANTE: | G7: ='NP BANCO DE SANGRE'!D6 -> DIRECCION PROVINCIAL BANCO DE SANGRE
A8: AUTORIZACIÓN:
A9: Señor Director de Administración o Titular del Servicio Administrativo Financiero:
A10: Autorizo la realización de los trámites correspondientes, a fin de proveer a este Organismo los bienes que se detallan en Nota de Pedido N° 05/2022 afectando la erogación resultante a los créditos presupuestarios aprobados a favor de esta Unidad Ejecutora, conforme al siguiente detalle:
A12: IMPUTACIÓN PRESUPUESTARIA
A13: CÓDIGO | O13: DENOMINACIÓN DE LA PARTIDA PRESUPUESTARIA | Q13: IMPORTE
A14: PR | B14: SB | C14: PY | D14: AC | E14: OB | F14: UG | G14: FIN | H14: FUN | I14: I | J14: P | K14: P | L14: SubP | M14: M | N14: FF
A15: 27 | D15: 1 | F15: 4901 | G15: 3 | H15: 1 | I15: 2 | J15: 9 | K15: 5 | M15: 1 | N15: 1.1 | O15: UTILES MENORES MEDICOS, QUIRURGICOS Y DE LABORATORIO | Q15: ='NP BANCO DE SANGRE'!M29 -> #REF!
A38: TOTAL DE PESOS: TRES MILLONES SETECIENTOS ONCE MIL CUATROCIENTOS TREINTA Y TRES CON 00/100.- | Q38: =SUM(Q15:Q37) -> #REF!
A40: JUSTIFICACIÓN:
A41: ='NP BANCO DE SANGRE'!D8 -> ADQ. DEL RUBRO DESCARTABLES PARA LABORATORIO

Sheet NP CUR
A1: NOTA DE PEDIDO | J1: N° | K1: 03/2022
A3: JURISDICCIÓN: | D3: ='SAF 011'!C4 -> 040 - MINISTERIO DE SALUD
A4: SAF: | D4: ='SAF 011'!C5 -> 011 - DIRECCION PROVINCIAL DE ADMINISTRACION - MINISTERIO DE SALUD
A5: UNIDAD EJECUTORA: | D5: DIRECCION PROVINCIAL CENTRO UNICO DE REFERENCIA
A6: DEPENDENCIA SOLICITANTE: | D6: DIRECCION PROVINCIAL CENTRO UNICO DE REFERENCIA
A7: PERIODO UTILIZACIÓN: | D7: 1° TRIMESTRE 2022
A8: OBJETO: | D8: ADQ. DEL RUBRO DESCARTABLES PARA LABORATORIO
A10: Ítem | B10: Codigo Item | C10: DESCRIPCIÓN | H10: Adjunta Detalle Técnico | I10: Unidad Medida | J10: Precio Unitario Estimado | K10: Cantidad Solicitada
A12: 1 | C12: ='SAF 011'!E10 -> AGUJAS BD VACUTAINER PRECISIÓN GILDE 21G X 1 X 100 UND. | H12: NO | I12: ='SAF 011'!F10 -> CAJA | J12: ='SAF 011'!H10 -> 18600 | K12: ='SAF 011'!#REF! -> #REF! | L12: =+K12*J12 -> #REF! | M12: =+J12*K12 -> #REF!
A13: 2 | C13: ='SAF 011'!E12 -> APOSITOS; TIPO: POST EXTRACCION SANGUINEA, TAMAÑO: 40 X 40 mm (X 250 UNIDADES) | H13: NO | I13: ='SAF 011'!F12 -> CAJA | J13: ='SAF 011'!H12 -> 600 | K13: ='SAF 011'!#REF! -> #REF! | L13: =+K13*J13 -> #REF! | M13: =+J13*K13 -> #REF!
A14: 3 | C14: ='SAF 011'!E30 -> LANCETAS RETRÁCTIL BD MICROTAINER X 100 UND. | H14: NO | I14: ='SAF 011'!F30 -> CAJA | J14: ='SAF 011'!H30 -> 6800 | K14: ='SAF 011'!#REF! -> #REF! | L14: =+K14*J14 -> #REF! | M14: =+J14*K14 -> #REF!
A15: 4 | C15: =+'SAF 011'!E45 -> TIPS AMARILLO 5-200 UL CON CORONA bolsa X 1000 UNIDADES | H15: NO | I15: =+'SAF 011'!F45 -> BOLSA | J15: =+'SAF 011'!H45 -> 2865 | K15: =+'SAF 011'!#REF! -> #REF! | L15: =+K15*J15 -> #REF! | M15: =+J15*K15 -> #REF!
A16: 5 | C16: ='SAF 011'!E63 -> TUBOS VACUTAINER K2 EDTA TAPA LILA 3.0 ML (100 TUBOS) | H16: NO | I16: ='SAF 011'!F63 -> CAJA | J16: ='SAF 011'!H63 -> 16500 | K16: ='SAF 011'!#REF! -> #REF! | L16: =+K16*J16 -> #REF! | M16: =+J16*K16 -> #REF!
A17: 6 | C17: ='SAF 011'!E65 -> TUBOS VACUTAINER SST TAPA AMARILLA 3.5 ML (100 TUBOS) | H17: NO | I17: ='SAF 011'!F65 -> CAJA | J17: ='SAF 011'!H65 -> 22200 | K17: ='SAF 011'!#REF! -> #REF! | L17: =+K17*J17 -> #REF! | M17: =+J17*K17 -> #REF!
A19: Costo total estimado: SEISCIENTOS OCHENTA Y SIETE MIL DOSCIENTOS NOVENTA Y CINCO CON 00/100.- | J19: =SUM(L12:L17) -> #REF! | M19: =SUM(M12:M18) -> #REF!

Sheet APG CUR
A1: EJERCICIO: | D1: 2022 | P1: AUTORIZACION PARA GASTAR
A4: JURISDICCIÓN: | G4: ='NP CUR'!D3 -> 040 - MINISTERIO DE SALUD
A5: SAF: | G5: ='NP CUR'!D4 -> 011 - DIRECCION PROVINCIAL DE ADMINISTRACION - MINISTERIO DE SALUD
A6: UNIDAD EJECUTORA: | G6: ='NP CUR'!D5 -> DIRECCION PROVINCIAL CENTRO UNICO DE REFERENCIA
A7: DEPENDENCIA SOLICITANTE: | G7: ='NP CUR'!D6 -> DIRECCION PROVINCIAL CENTRO UNICO DE REFERENCIA
A8: AUTORIZACIÓN:
A9: Señor Director de Administración o Titular del Servicio Administrativo Financiero:
A10: Autorizo la realización de los trámites correspondientes, a fin de proveer a este Organismo los bienes que se detallan en Nota de Pedido N° 03/2022 afectando la erogación resultante a los créditos presupuestarios aprobados a favor de esta Unidad Ejecutora, conforme al siguiente detalle:
A12: IMPUTACIÓN PRESUPUESTARIA
A13: CÓDIGO | O13: DENOMINACIÓN DE LA PARTIDA PRESUPUESTARIA | Q13: IMPORTE
A14: PR | B14: SB | C14: PY | D14: AC | E14: OB | F14: UG | G14: FIN | H14: FUN | I14: I | J14: P | K14: P | L14: SubP | M14: M | N14: FF
A15: 35 | D15: 1 | F15: 4901 | G15: 3 | H15: 1 | I15: 2 | J15: 9 | K15: 5 | M15: 1 | N15: 1.1 | O15: UTILES MENORES MEDICOS, QUIRURGICOS Y DE LABORATORIO | Q15: 187295
A16: 35 | D16: 2 | F16: 4901 | G16: 3 | H16: 1 | I16: 2 | J16: 9 | K16: 5 | M16: 1 | N16: 1.1 | O16: UTILES MENORES MEDICOS, QUIRURGICOS Y DE LABORATORIO | Q16: 500000
A38: TOTAL DE PESOS: SEISCIENTOS OCHENTA Y SIETE MIL DOSCIENTOS NOVENTA Y CINCO CON 00/100.- | Q38: =SUM(Q15:Q37) -> 687295
A40: JUSTIFICACIÓN:
A41: ='NP CUR'!D8 -> ADQ. DEL RUBRO DESCARTABLES PARA LABORATORIO
