Workbook

Sheet Necesidades Trimestrales
B2: Pedido de Necesidades Trimestrales
A4: JURISDICCION: | C4: 12 -Ministerio de Trabajo y Recursos Humanos
A5: SAF N°: | C5: 22 - Secretaria de Administración del Ministerio de Trabajo y Recursos Humanos
A6: EJERCICIO: | C6: 2021
A7: TRIMESTRE: | C7: 2
A9: ID | B9: CODIGO ÍTEM | C9: RUBRO DE COMPRA | D9: I.P.P. | E9: DESCRIPCION | F9: UNIDAD DE MEDIDA | G9: CANTIDAD | H9: PRECIO UNITARIO ESTIMADO | I9: IMPORTE TOTAL ESTIMADO
A10: 1 | B10: 2.2.1-1053.108 | C10: INDUMENT TEXTIL Y CONFECCIONES | D10: =+LEFT(B10,5) -> 2.2.1 | E10: HILO DE ALGODON; PRESENTACION: OVILLO, USO: P/ATAR, NUMERO: 4 HEBRAS, LARGO: 800 M, TONALIDAD: BLANCO | F10: UNIDAD | G10: 6 | H10: 248 | I10: =+H10*G10 -> 1488
A11: 2 | B11: 2.3.1-6563.1009 | C11: LIBRERIA,PAP. Y UTILES OFICINA | D11: =+LEFT(B11,5) -> 2.3.1 | E11: PAPELES EN HOJA; TIPO DE PAPEL: BLANCO, DIMENSION: OFICIO, GRAMAJE: 80 GR, PRESENTACION: ENVASE X 500 HOJAS, CERTIFICADO FORESTAL (GFS): SIN, PORC. FIBRAS RECICLADAS: 0 %, CERT. FIBRA ALTERNATIVA (FCA): SIN | F11: UNIDAD | G11: 300 | H11: 504.84 | I11: =+H11*G11 -> 151452
A12: 3 | B12: 2.3.1-6563.846 | C12: LIBRERIA,PAP. Y UTILES OFICINA | D12: =+LEFT(B12,5) -> 2.3.1 | E12: PAPELES EN HOJA; TIPO DE PAPEL: CARTULINA, DIMENSION: 76 X 112 Cm, GRAMAJE: 176 GR/M2, PRESENTACION: UNIDAD, CERTIFICADO FORESTAL (GFS): SIN, PORC. FIBRAS RECICLADAS: 0 % | F12: UNIDAD | G12: 10 | H12: 28 | I12: =+H12*G12 -> 280
A13: 4 | B13: 2.3.1-6563.868 | C13: LIBRERIA,PAP. Y UTILES OFICINA | D13: =+LEFT(B13,5) -> 2.3.1 | E13: PAPELES EN HOJA; TIPO DE PAPEL: AFICHE, DIMENSION: 70 X 100 Cm, GRAMAJE: 65 GR/M2, PRESENTACION: UNIDAD, CERTIFICADO FORESTAL (GFS): CON, PORC. FIBRAS RECICLADAS: 40 % | F13: UNIDAD | G13: 10 | H13: 41.3 | I13: =+H13*G13 -> 413
A14: 5 | B14: 2.3.1-6563.938 | C14: LIBRERIA,PAP. Y UTILES OFICINA | D14: =+LEFT(B14,5) -> 2.3.1 | E14: PAPELES EN HOJA; TIPO DE PAPEL: P/FORRAR, DIMENSION: 48 X 80 Cm, GRAMAJE: NO CORRESPONDE, PRESENTACION: UNIDAD, CERTIFICADO FORESTAL (GFS): SIN, PORC. FIBRAS RECICLADAS: 0 %, CERT. FIBRA ALTERNATIVA (FCA): SIN | F14: UNIDAD | G14: 10 | H14: 85 | I14: =+H14*G14 -> 850
A15: 6 | B15: 2.3.1-6563.968 | C15: LIBRERIA,PAP. Y UTILES OFICINA | D15: =+LEFT(B15,5) -> 2.3.1 | E15: PAPELES EN HOJA; TIPO DE PAPEL: EXTRA BLANCO, DIMENSION: A4, GRAMAJE: 80 GR, PRESENTACION: RESMA X 500 HOJAS, CERTIFICADO FORESTAL (GFS): SIN, PORC. FIBRAS RECICLADAS: 0 %, CERT. FIBRA ALTERNATIVA (FCA): CON | F15: UNIDAD | G15: 400 | H15: 410.11 | I15: =+H15*G15 -> 164044
A16: 7 | B16: 2.3.1-6587.159 | C16: LIBRERIA,PAP. Y UTILES OFICINA | D16: =+LEFT(B16,5) -> 2.3.1 | E16: PAPELES ENCUADERNADOS; CANT. DE HOJAS: 200, TAMAÑO: OFICIO, TIPO: LIBRO DE ACTAS, CERTIFICADO FORESTAL (GFS): SIN, PORC. FIBRAS RECICLADAS: 0 %, CERT. FIBRA ALTERNATIVA (FCA): SIN | F16: UNIDAD | G16: 100 | H16: 387.9 | I16: =+H16*G16 -> 38790
A17: 8 | B17: 2.3.1-6587.317 | C17: LIBRERIA,PAP. Y UTILES OFICINA | D17: =+LEFT(B17,5) -> 2.3.1 | E17: PAPELES ENCUADERNADOS; CANT. DE HOJAS: 48, TAMAÑO: 21 X 16 Cm, TIPO: CUADERNO, CERTIFICADO FORESTAL (GFS): CON, PORC. FIBRAS RECICLADAS: 0 %, CERT. FIBRA ALTERNATIVA (FCA): SIN | F17: UNIDAD | G17: 10 | H17: 64 | I17: =+H17*G17 -> 640
A18: 9 | B18: 2.3.1-6587.333 | C18: LIBRERIA,PAP. Y UTILES OFICINA | D18: =+LEFT(B18,5) -> 2.3.1 | E18: PAPELES ENCUADERNADOS; CANT. DE HOJAS: 84 HOJAS, TAMAÑO: 21 X 29,7 Cm, TIPO: RAYADO ESPIRALADO, CERTIFICADO FORESTAL (GFS): CON, PORC. FIBRAS RECICLADAS: 0 %, CERT. FIBRA ALTERNATIVA (FCA): SIN | F18: UNIDAD | G18: 20 | H18: 199 | I18: =+H18*G18 -> 3980
A19: 10 | B19: 2.3.1-6587.346 | C19: LIBRERIA,PAP. Y UTILES OFICINA | D19: =+LEFT(B19,5) -> 2.3.1 | E19: PAPELES ENCUADERNADOS; CANT. DE HOJAS: 100, TAMAÑO: A4, TIPO: CUADERNO ESPIRALADO TAPA DURA, CERTIFICADO FORESTAL (GFS): SIN, PORC. FIBRAS RECICLADAS: 0 %, CERT. FIBRA ALTERNATIVA (FCA): SIN | F19: UNIDAD | G19: 6 | H19: 324 | I19: =+H19*G19 -> 1944
A20: 11 | B20: 2.3.1-6590.555 | C20: LIBRERIA,PAP. Y UTILES OFICINA | D20: =+LEFT(B20,5) -> 2.3.1 | E20: SOBRES DE PAPEL; TIPO: MANILA, TAMAÑO: OFICIO, GRAMAJE: 80 GR, PRESENTACION: UNIDAD, CERTIFICADO FORESTAL (GFS): SIN, PORC. FIBRAS RECICLADAS: 0 %, CERT. FIBRA ALTERNATIVA (FCA): SIN | F20: UNIDAD | G20: 50 | H20: 17.03 | I20: =+H20*G20 -> 851.5
A21: 12 | B21: 2.3.1-6590.556 | C21: LIBRERIA,PAP. Y UTILES OFICINA | D21: =+LEFT(B21,5) -> 2.3.1 | E21: SOBRES DE PAPEL; TIPO: MANILA, TAMAÑO: A4, GRAMAJE: 80 GR, PRESENTACION: UNIDAD, CERTIFICADO FORESTAL (GFS): SIN, PORC. FIBRAS RECICLADAS: 0 %, CERT. FIBRA ALTERNATIVA (FCA): SIN | F21: UNIDAD | G21: 50 | H21: 17.91 | I21: =+H21*G21 -> 895.5
... A27: 18 | B27: 2.9.2-1354.17 | C27: LIBRERIA,PAP. Y UTILES OFICINA | D27: =+LEFT(B27,5) -> 2.9.2 | E27: RESALTADORES; PUNTA: 5 PLANA, ACCESORIO: SIN, COLOR: AZUL, TIPO PUNTA: 5 PLANA | F27: UNIDAD | G27: 50 | H27: 69.9 | I27: =+H27*G27 -> 3495
A28: 19 | B28: 2.9.2-1354.28 | C28: LIBRERIA,PAP. Y UTILES OFICINA | D28: =+LEFT(B28,5) -> 2.9.2 | E28: RESALTADORES; PUNTA: FINA, ACCESORIO: SIN, COLOR: AMARILLO, TIPO PUNTA: FINA | F28: UNIDAD | G28: =156+50 -> 206 | H28: 38.22 | I28: =+H28*G28 -> 7873.32
A29: 20 | B29: 2.9.2-1354.29 | C29: LIBRERIA,PAP. Y UTILES OFICINA | D29: =+LEFT(B29,5) -> 2.9.2 | E29: RESALTADORES; PUNTA: FINA, ACCESORIO: SIN, COLOR: VERDE, TIPO PUNTA: FINA | F29: UNIDAD | G29: 96 | H29: 98.9 | I29: =+H29*G29 -> 9494.4
A30: 21 | B30: 2.9.2-1358.34 | C30: LIBRERIA,PAP. Y UTILES OFICINA | D30: =+LEFT(B30,5) -> 2.9.2 | E30: CARPETAS; MATERIAL PVC - TAMAÑO OFICIO | F30: UNIDAD | G30: 1200 | H30: 39.9 | I30: =+H30*G30 -> 47880
A31: 22 | B31: 2.9.2-1358.35 | C31: LIBRERIA,PAP. Y UTILES OFICINA | D31: =+LEFT(B31,5) -> 2.9.2 | E31: CARPETAS; MATERIAL PVC - TAMAÑO A4 | F31: UNIDAD | G31: 1200 | H31: 39.9 | I31: =+H31*G31 -> 47880
A32: 23 | B32: 2.9.2-1428.23 | C32: LIBRERIA,PAP. Y UTILES OFICINA | D32: =+LEFT(B32,5) -> 2.9.2 | E32: BANDAS ELASTICAS; DIAMETRO: 12 Cm, PRESENTACION: 500 GR, ESPESOR: 5 mm | F32: UNIDAD | G32: 8 | H32: 607.65 | I32: =+H32*G32 -> 4861.2
A33: 24 | B33: 2.9.2-1428.38 | C33: LIBRERIA,PAP. Y UTILES OFICINA | D33: =+LEFT(B33,5) -> 2.9.2 | E33: BANDAS ELASTICAS; DIAMETRO: 10 Cm, PRESENTACION: BOLSA DE 500 GR, ESPESOR: 1 mm | F33: UNIDAD | G33: 8 | H33: 607.65 | I33: =+H33*G33 -> 4861.2
A34: 25 | B34: 2.9.2-1450.30 | C34: LIBRERIA,PAP. Y UTILES OFICINA | D34: =+LEFT(B34,5) -> 2.9.2 | E34: TINTAS P/SELLOS; TIPO DE SELLO: DE GOMA, ENVASE: 60 CM3, COLOR: AZUL, PRESENTACION: ENVASE X 60 CM3 | F34: UNIDAD | G34: 50 | H34: 157 | I34: =+H34*G34 -> 7850
A35: 26 | B35: 2.9.2-1450.4 | C35: LIBRERIA,PAP. Y UTILES OFICINA | D35: =+LEFT(B35,5) -> 2.9.2 | E35: TINTAS P/SELLOS; TIPO DE SELLO: DE GOMA, COLOR: NEGRO, PRESENTACION: ENVASE X 50 CM3 | F35: UNIDAD | G35: 50 | H35: 157 | I35: =+H35*G35 -> 7850
A36: 27 | B36: 2.9.2-1611.1 | C36: LIBRERIA,PAP. Y UTILES OFICINA | D36: =+LEFT(B36,5) -> 2.9.2 | E36: FOLIOS TRANSPARENTES; MATERIAL: PLASTICO (POLIETILENO), TAMAÑO: OFICIO, PERFORACIONES: 5 UNIVERSALES | F36: UNIDAD | G36: 6500 | H36: 6.55 | I36: =+H36*G36 -> 42575
A37: 28 | B37: 2.9.2-1611.21 | C37: LIBRERIA,PAP. Y UTILES OFICINA | D37: =+LEFT(B37,5) -> 2.9.2 | E37: FOLIOS TRANSPARENTES; TAMAÑO: A4, PERFORACIONES: SIN, MATERIAL: POLIETILENO | F37: UNIDAD | G37: 6500 | H37: 5.86 | I37: =+H37*G37 -> 38090
A38: 29 | B38: 2.9.2-1616.128 | C38: LIBRERIA,PAP. Y UTILES OFICINA | D38: =+LEFT(B38,5) -> 2.9.2 | E38: MARCADORES; TIPO PARA PIZARRA - TRAZO GRUESO - PUNTA REDONDA - RECARGABLE NO | F38: UNIDAD | G38: 36 | H38: 142 | I38: =+H38*G38 -> 5112
A39: 30 | B39: 2.9.2-1616.134 | C39: LIBRERIA,PAP. Y UTILES OFICINA | D39: =+LEFT(B39,5) -> 2.9.2 | E39: MARCADORES; TIPO: AL SOLVENTE, TRAZO: GRUESO, PUNTA: CHANFLEADA, COLOR: VERDE, RECARGABLE:NO | F39: UNIDAD | G39: 50 | H39: 592 | I39: =+H39*G39 -> 29600
A40: 31 | B40: 2.9.2-1616.79 | C40: LIBRERIA,PAP. Y UTILES OFICINA | D40: =+LEFT(B40,5) -> 2.9.2 | E40: MARCADORES; TIPO: AL SOLVENTE, TRAZO: FINO, PUNTA: REDONDA, COLOR: NEGRO, RECARGABLE: NO | F40: UNIDAD | G40: 100 | H40: 111 | I40: =+H40*G40 -> 11100
... A75: 66 | B75: 2.9.2-873.1 | C75: LIBRERIA,PAP. Y UTILES OFICINA | D75: =+LEFT(B75,5) -> 2.9.2 | E75: PINCHES P/PAPELES; ALTURA 125mm - BASE METAL | F75: UNIDAD | G75: 20 | H75: 120 | I75: =+H75*G75 -> 2400
A76: COSTO TOTAL ESTIMADO: SON PESOS UN MILLON CUARENTA Y SEIS MIL SEISCIENTOS NOVENTA Y CUATRO CON 16/100 | I76: =SUM(I10:I75) -> 1046694.2
B82: Especificidades Ítem N° 64:
B84: Descripción técnica
C85: LIBRO DE RECIBO TAPA DURA X 200 HOJAS RAYADAS DOBLE FAZ - MEDIDAS: SIN
B90: Plazos y lugares de entrega
C91: a) LUGAR DE ENTREGA: Pabellón Nº 20 Ministerio de Trabajo y Recursos Humanos (CAPE), sito en Av. Presidente Castillo y Av. Venezuela - Capital - De 08 a 12 horas. b) FORMA DE LA ENTREGA: Libre de flete, acarreo y embalaje, como así también, de todo riesgo de pérdida o destrucción total o parcial, por causas ajenas a la Institución. c) PLAZO DE ENTREGA: El Oferente deberá establecer plazo de entrega de los elementos cotizados, debiendo ser expresado en días hábiles; que no podrá ser superior a cinco (5) días hábiles, contados a partir de la recepción de la comunicación prevista en el Artículo en el Reglamento Parcial N° 2 de la ley 4938.
B93: Calidad Mínima esperada
...

Sheet  NotaPedido
A1: NOTA DE PEDIDO | J1: N° | K1: 006/2021
A3: JURISDICCIÓN: | D3: ='Necesidades Trimestrales'!C4 -> 12 -Ministerio de Trabajo y Recursos Humanos
A4: SAF: | D4: ='Necesidades Trimestrales'!C5 -> 22 - Secretaria de Administración del Ministerio de Trabajo y Recursos Humanos
A5: UNIDAD EJECUTORA: | D5: Secretaria de Administracion
A6: DEPENDENCIA SOLICITANTE: | D6: Secretaria de Administracion
A7: PERIODO UTILIZACIÓN: | D7: ='Necesidades Trimestrales'!C7 & "° Trimestre - Año " & 'Necesidades Trimestrales'!C6 -> 2° Trimestre - Año 2021
A8: OBJETO: | D8: Adquisición de Utiles de Escritorio para las distintas dependencias de este Ministerio.
A10: Ítem | B10: Codigo Item | C10: DESCRIPCIÓN | H10: Adjunta Detalle Técnico | I10: Unidad Medida | J10: Precio Unitario Estimado | K10: Cantidad Solicitada
A12: =+'Necesidades Trimestrales'!A10 -> 1 | B12: =+'Necesidades Trimestrales'!B10 -> 2.2.1-1053.108 | C12: =+'Necesidades Trimestrales'!E10 -> HILO DE ALGODON; PRESENTACION: OVILLO, USO: P/ATAR, NUMERO: 4 HEBRAS, LARGO: 800 M, TONALIDAD: BLANCO | H12: NO | I12: =+'Necesidades Trimestrales'!F10 -> UNIDAD | J12: =+'Necesidades Trimestrales'!H10 -> 248 | K12: =+'Necesidades Trimestrales'!G10 -> 6
A13: =+'Necesidades Trimestrales'!A11 -> 2 | B13: =+'Necesidades Trimestrales'!B11 -> 2.3.1-6563.1009 | C13: =+'Necesidades Trimestrales'!E11 -> PAPELES EN HOJA; TIPO DE PAPEL: BLANCO, DIMENSION: OFICIO, GRAMAJE: 80 GR, PRESENTACION: ENVASE X 500 HOJAS, CERTIFICADO FORESTAL (GFS): SIN, PORC. FIBRAS RECICLADAS: 0 %, CERT. FIBRA ALTERNATIVA (FCA): SIN | H13: NO | I13: =+'Necesidades Trimestrales'!F11 -> UNIDAD | J13: =+'Necesidades Trimestrales'!H11 -> 504.84 | K13: =+'Necesidades Trimestrales'!G11 -> 300
A14: =+'Necesidades Trimestrales'!A12 -> 3 | B14: =+'Necesidades Trimestrales'!B12 -> 2.3.1-6563.846 | C14: =+'Necesidades Trimestrales'!E12 -> PAPELES EN HOJA; TIPO DE PAPEL: CARTULINA, DIMENSION: 76 X 112 Cm, GRAMAJE: 176 GR/M2, PRESENTACION: UNIDAD, CERTIFICADO FORESTAL (GFS): SIN, PORC. FIBRAS RECICLADAS: 0 % | H14: NO | I14: =+'Necesidades Trimestrales'!F12 -> UNIDAD | J14: =+'Necesidades Trimestrales'!H12 -> 28 | K14: =+'Necesidades Trimestrales'!G12 -> 10
A15: =+'Necesidades Trimestrales'!A13 -> 4 | B15: =+'Necesidades Trimestrales'!B13 -> 2.3.1-6563.868 | C15: =+'Necesidades Trimestrales'!E13 -> PAPELES EN HOJA; TIPO DE PAPEL: AFICHE, DIMENSION: 70 X 100 Cm, GRAMAJE: 65 GR/M2, PRESENTACION: UNIDAD, CERTIFICADO FORESTAL (GFS): CON, PORC. FIBRAS RECICLADAS: 40 % | H15: NO | I15: =+'Necesidades Trimestrales'!F13 -> UNIDAD | J15: =+'Necesidades Trimestrales'!H13 -> 41.3 | K15: =+'Necesidades Trimestrales'!G13 -> 10
A16: =+'Necesidades Trimestrales'!A14 -> 5 | B16: =+'Necesidades Trimestrales'!B14 -> 2.3.1-6563.938 | C16: =+'Necesidades Trimestrales'!E14 -> PAPELES EN HOJA; TIPO DE PAPEL: P/FORRAR, DIMENSION: 48 X 80 Cm, GRAMAJE: NO CORRESPONDE, PRESENTACION: UNIDAD, CERTIFICADO FORESTAL (GFS): SIN, PORC. FIBRAS RECICLADAS: 0 %, CERT. FIBRA ALTERNATIVA (FCA): SIN | H16: NO | I16: =+'Necesidades Trimestrales'!F14 -> UNIDAD | J16: =+'Necesidades Trimestrales'!H14 -> 85 | K16: =+'Necesidades Trimestrales'!G14 -> 10
A17: =+'Necesidades Trimestrales'!A15 -> 6 | B17: =+'Necesidades Trimestrales'!B15 -> 2.3.1-6563.968 | C17: =+'Necesidades Trimestrales'!E15 -> PAPELES EN HOJA; TIPO DE PAPEL: EXTRA BLANCO, DIMENSION: A4, GRAMAJE: 80 GR, PRESENTACION: RESMA X 500 HOJAS, CERTIFICADO FORESTAL (GFS): SIN, PORC. FIBRAS RECICLADAS: 0 %, CERT. FIBRA ALTERNATIVA (FCA): CON | H17: NO | I17: =+'Necesidades Trimestrales'!F15 -> UNIDAD | J17: =+'Necesidades Trimestrales'!H15 -> 410.11 | K17: =+'Necesidades Trimestrales'!G15 -> 400
A18: =+'Necesidades Trimestrales'!A16 -> 7 | B18: =+'Necesidades Trimestrales'!B16 -> 2.3.1-6587.159 | C18: =+'Necesidades Trimestrales'!E16 -> PAPELES ENCUADERNADOS; CANT. DE HOJAS: 200, TAMAÑO: OFICIO, TIPO: LIBRO DE ACTAS, CERTIFICADO FORESTAL (GFS): SIN, PORC. FIBRAS RECICLADAS: 0 %, CERT. FIBRA ALTERNATIVA (FCA): SIN | H18: NO | I18: =+'Necesidades Trimestrales'!F16 -> UNIDAD | J18: =+'Necesidades Trimestrales'!H16 -> 387.9 | K18: =+'Necesidades Trimestrales'!G16 -> 100
A19: =+'Necesidades Trimestrales'!A17 -> 8 | B19: =+'Necesidades Trimestrales'!B17 -> 2.3.1-6587.317 | C19: =+'Necesidades Trimestrales'!E17 -> PAPELES ENCUADERNADOS; CANT. DE HOJAS: 48, TAMAÑO: 21 X 16 Cm, TIPO: CUADERNO, CERTIFICADO FORESTAL (GFS): CON, PORC. FIBRAS RECICLADAS: 0 %, CERT. FIBRA ALTERNATIVA (FCA): SIN | H19: NO | I19: =+'Necesidades Trimestrales'!F17 -> UNIDAD | J19: =+'Necesidades Trimestrales'!H17 -> 64 | K19: =+'Necesidades Trimestrales'!G17 -> 10
A20: =+'Necesidades Trimestrales'!A18 -> 9 | B20: =+'Necesidades Trimestrales'!B18 -> 2.3.1-6587.333 | C20: =+'Necesidades Trimestrales'!E18 -> PAPELES ENCUADERNADOS; CANT. DE HOJAS: 84 HOJAS, TAMAÑO: 21 X 29,7 Cm, TIPO: RAYADO ESPIRALADO, CERTIFICADO FORESTAL (GFS): CON, PORC. FIBRAS RECICLADAS: 0 %, CERT. FIBRA ALTERNATIVA (FCA): SIN | H20: NO | I20: =+'Necesidades Trimestrales'!F18 -> UNIDAD | J20: =+'Necesidades Trimestrales'!H18 -> 199 | K20: =+'Necesidades Trimestrales'!G18 -> 20
A21: =+'Necesidades Trimestrales'!A19 -> 10 | B21: =+'Necesidades Trimestrales'!B19 -> 2.3.1-6587.346 | C21: =+'Necesidades Trimestrales'!E19 -> PAPELES ENCUADERNADOS; CANT. DE HOJAS: 100, TAMAÑO: A4, TIPO: CUADERNO ESPIRALADO TAPA DURA, CERTIFICADO FORESTAL (GFS): SIN, PORC. FIBRAS RECICLADAS: 0 %, CERT. FIBRA ALTERNATIVA (FCA): SIN | H21: NO | I21: =+'Necesidades Trimestrales'!F19 -> UNIDAD | J21: =+'Necesidades Trimestrales'!H19 -> 324 | K21: =+'Necesidades Trimestrales'!G19 -> 6
A22: =+'Necesidades Trimestrales'!A20 -> 11 | B22: =+'Necesidades Trimestrales'!B20 -> 2.3.1-6590.555 | C22: =+'Necesidades Trimestrales'!E20 -> SOBRES DE PAPEL; TIPO: MANILA, TAMAÑO: OFICIO, GRAMAJE: 80 GR, PRESENTACION: UNIDAD, CERTIFICADO FORESTAL (GFS): SIN, PORC. FIBRAS RECICLADAS: 0 %, CERT. FIBRA ALTERNATIVA (FCA): SIN | H22: NO | I22: =+'Necesidades Trimestrales'!F20 -> UNIDAD | J22: =+'Necesidades Trimestrales'!H20 -> 17.03 | K22: =+'Necesidades Trimestrales'!G20 -> 50
A23: =+'Necesidades Trimestrales'!A21 -> 12 | B23: =+'Necesidades Trimestrales'!B21 -> 2.3.1-6590.556 | C23: =+'Necesidades Trimestrales'!E21 -> SOBRES DE PAPEL; TIPO: MANILA, TAMAÑO: A4, GRAMAJE: 80 GR, PRESENTACION: UNIDAD, CERTIFICADO FORESTAL (GFS): SIN, PORC. FIBRAS RECICLADAS: 0 %, CERT. FIBRA ALTERNATIVA (FCA): SIN | H23: NO | I23: =+'Necesidades Trimestrales'!F21 -> UNIDAD | J23: =+'Necesidades Trimestrales'!H21 -> 17.91 | K23: =+'Necesidades Trimestrales'!G21 -> 50
... A77: =+'Necesidades Trimestrales'!A75 -> 66 | B77: =+'Necesidades Trimestrales'!B75 -> 2.9.2-873.1 | C77: =+'Necesidades Trimestrales'!E75 -> PINCHES P/PAPELES; ALTURA 125mm - BASE METAL | H77: NO | I77: =+'Necesidades Trimestrales'!F75 -> UNIDAD | J77: =+'Necesidades Trimestrales'!H75 -> 120 | K77: =+'Necesidades Trimestrales'!G75 -> 20
A78: =+'Necesidades Trimestrales'!A76:E76 -> COSTO TOTAL ESTIMADO: SON PESOS UN MILLON CUARENTA Y SEIS MIL SEISCIENTOS NOVENTA Y CUATRO CON 16/100 | J78: =SUMPRODUCT(J12:J77,K12:K77) -> 1046694.2

Sheet Autor Gastar
A1: EJERCICIO: | D1: ='Necesidades Trimestrales'!C6 -> 2021 | P1: AUTORIZACION PARA GASTAR
A4: JURISDICCIÓN: | G4: =' NotaPedido'!D3 -> 12 -Ministerio de Trabajo y Recursos Humanos
A5: SAF: | G5: =' NotaPedido'!D4 -> 22 - Secretaria de Administración del Ministerio de Trabajo y Recursos Humanos
A6: UNIDAD EJECUTORA: | G6: Ministerio de Trabajo y Reursos Humanos
A7: DEPENDENCIA SOLICITANTE: | G7: =' NotaPedido'!D6 -> Secretaria de Administracion
A8: AUTORIZACIÓN:
A9: Señor Jefe de Servicio Administrativo Financiero:
A10: ="Autorizo la realización de los trámites correspondientes, a fin de proveer a este Organismo los bienes y/o servicios que se detallan en Nota de Pedido N° " & ' NotaPedido'!K1&", afectando la erogación resultante a los créditos presupuestarios aprobados a favor de esta Unidad Ejecutora, conforme al siguiente detalle:" -> Autorizo la realización de los trámites correspondientes, a fin de proveer a este Organismo los bienes y/o servicios que se detallan en Nota de Pedido N° 006/2021, afectando la erogación resultante a los créditos presupuestarios aprobados a favor de esta Unidad Ejecutora, conforme al siguiente detalle:
A12: IMPUTACIÓN PRESUPUESTARIA
A13: CÓDIGO | O13: DENOMINACIÓN DE LA PARTIDA PRESUPUESTARIA | Q13: IMPORTE
A14: PR | B14: SB | C14: PY | D14: AC | E14: OB | F14: UG | G14: FIN | H14: FUN | I14: I | J14: P | K14: P | L14: SubP | M14: M | N14: FF
A15: 2 | B15: 0 | C15: 0 | D15: 1 | E15: 0 | F15: 4901 | G15: 3 | H15: 6 | I15: 2 | J15: 3 | K15: 1 | L15: 0 | M15: 1 | N15: 1.1 | O15: PAPEL DE ESCRITORIO Y CARTON | Q15: 367858.6
A16: 2 | B16: 0 | C16: 0 | D16: 1 | E16: 0 | F16: 4901 | G16: 3 | H16: 6 | I16: 2 | J16: 9 | K16: 2 | L16: 0 | M16: 1 | N16: 1.1 | O16: UTILES DE ESCRITORIO, OFICINA Y ENSEÑANZA | Q16: 81434.56
A17: 3 | B17: 0 | C17: 0 | D17: 1 | E17: 0 | F17: 4901 | G17: 1 | H17: 3 | I17: 2 | J17: 3 | K17: 3 | L17: 0 | M17: 1 | N17: 1.1 | O17: PRODUCTOS DE ARTES GRAFICOS | Q17: 10704
A18: 3 | B18: 0 | C18: 0 | D18: 1 | E18: 0 | F18: 4901 | G18: 1 | H18: 3 | I18: 2 | J18: 9 | K18: 2 | L18: 0 | M18: 1 | N18: 1.1 | O18: UTILES DE ESCRITORIO, OFICINA Y ENSEÑANZA | Q18: 210000
A19: 4 | B19: 0 | C19: 0 | D19: 1 | E19: 0 | F19: 4901 | G19: 3 | H19: 4 | I19: 2 | J19: 9 | K19: 2 | L19: 0 | M19: 1 | N19: 1.1 | O19: UTILES DE ESCRITORIO, OFICINA Y ENSEÑANZA | Q19: 68250
A20: 5 | B20: 0 | C20: 0 | D20: 1 | E20: 0 | F20: 4901 | G20: 3 | H20: 6 | I20: 2 | J20: 9 | K20: 2 | L20: 0 | M20: 1 | N20: 1.1 | O20: UTILES DE ESCRITORIO, OFICINA Y ENSEÑANZA | Q20: 33988
A21: 6 | B21: 0 | C21: 0 | D21: 1 | E21: 0 | F21: 4901 | G21: 1 | H21: 3 | I21: 2 | J21: 2 | K21: 1 | L21: 0 | M21: 1 | N21: 1.1 | O21: HILADOS Y TELAS | Q21: 1488
A22: 6 | B22: 0 | C22: 0 | D22: 1 | E22: 0 | F22: 4901 | G22: 1 | H22: 3 | I22: 2 | J22: 9 | K22: 2 | L22: 0 | M22: 1 | N22: 1.1 | O22: UTILES DE ESCRITORIO, OFICINA Y ENSEÑANZA | Q22: 200000
A23: 7 | B23: 0 | C23: 0 | D23: 1 | E23: 0 | F23: 4901 | G23: 1 | H23: 3 | I23: 2 | J23: 9 | K23: 2 | L23: 0 | M23: 1 | N23: 1.1 | O23: UTILES DE ESCRITORIO, OFICINA Y ENSEÑANZA | Q23: 42823
A24: 8 | B24: 0 | C24: 0 | D24: 1 | E24: 0 | F24: 4901 | G24: 3 | H24: 6 | I24: 2 | J24: 9 | K24: 2 | L24: 0 | M24: 1 | N24: 1.1 | O24: UTILES DE ESCRITORIO, OFICINA Y ENSEÑANZA | Q24: 30148
A25: =+'Necesidades Trimestrales'!A76:E76 -> COSTO TOTAL ESTIMADO: SON PESOS UN MILLON CUARENTA Y SEIS MIL SEISCIENTOS NOVENTA Y CUATRO CON 16/100 | Q25: =SUM(Q15:Q24) -> 1046694.2
A27: JUSTIFICACIÓN:
A28: =' NotaPedido'!D8 -> Adquisición de Utiles de Escritorio para las distintas dependencias de este Ministerio.
