Workbook

Sheet Necesidades Trimestrales
B2: Pedido de Necesidades Trimestrales
A4: JURISDICCION: | C4: 40 - Ministerio de Salud
A5: SAF N°: | C5: 28 - MATERNIDAD PROVINCIAL 25 DE MAYO
A6: EJERCICIO: | C6: 2022
A7: TRIMESTRE: | C7: 1º Trimestre
A9: ID | B9: CODIGO ITEM | C9: RUBRO DE COMPRA | D9: I.P.P. | E9: DESCRIPCION | F9: UNIDAD DE MEDIDA | G9: CANTIDAD | H9: PRECIO UNITARIO ESTIMADO | I9: IMPORTE TOTAL ESTIMADO
A10: 1 | B10: 2.9.1-6952.19 | C10: ELEMENTOS DE LIMPIEZA | D10: =LEFT(B10,5) -> 2.9.1 | E10: CEPILLOS; TIPO: DE ROPA, MATERIAL: CERDA | F10: unidad | G10: 15 | H10: 89.95 | I10: =G10*H10 -> 1349.25
A11: 2 | B11: 2.9.1-6952.20 | C11: ELEMENTOS DE LIMPIEZA | D11: =LEFT(B11,5) -> 2.9.1 | E11: CEPILLOS; TIPO: DE MANO Y UÑA, MATERIAL: CERDA | F11: unidad | G11: 15 | H11: 82 | I11: =G11*H11 -> 1230
A12: 3 | B12: 2.5.4-505.90 | C12: ELEMENTOS DE LIMPIEZA | D12: =LEFT(B12,5) -> 2.5.4 | E12: DESINFECTANTES; PRINCIPIO ACTIVO: ANTIBACTERIANO, CONTROL: BACTERIAS Y HONGOS, PRESENTACION: ENVASE X 390 CM3 | F12: unidad | G12: 100 | H12: 195 | I12: =G12*H12 -> 19500
A13: 4 | B13: 2.9.1-544.3 | C13: ELEMENTOS DE LIMPIEZA | D13: =LEFT(B13,5) -> 2.9.1 | E13: DESODORANTES DE AMBIENTE; PRESENTACION: UNIDAD, FRAGANCIA: VISTA AL MAR, CONTENIDO: 440 CM3, FORMATO: AEROSOL, LIBRE DE CFC: SI | F13: unidad | G13: 30 | H13: 151 | I13: =G13*H13 -> 4530
A14: 5 | B14: 2.9.1-544.4 | C14: ELEMENTOS DE LIMPIEZA | D14: =LEFT(B14,5) -> 2.9.1 | E14: DESODORANTES DE AMBIENTE; FRAGANCIA: CASA DE CAMPO, PRESENTACION: UNIDAD, FORMATO: AEROSOL, CONTENIDO: 440 CM3, LIBRE DE CFC: SI | F14: unidad | G14: 30 | H14: 151 | I14: =G14*H14 -> 4530
A15: 6 | B15: 2.9.1-544.7 | C15: ELEMENTOS DE LIMPIEZA | D15: =LEFT(B15,5) -> 2.9.1 | E15: DESODORANTES DE AMBIENTE; PRESENTACION: UNIDAD, CONTENIDO: 440 CM3, FORMATO: AEROSOL, FRAGANCIA: FLORECER SILVESTRE, LIBRE DE CFC: SI | F15: unidad | G15: 30 | H15: 151 | I15: =G15*H15 -> 4530
A16: 7 | B16: 2.9.1-544.66 | C16: ELEMENTOS DE LIMPIEZA | D16: =LEFT(B16,5) -> 2.9.1 | E16: DESODORANTES DE AMBIENTE; FORMATO: AEROSOL, FRAGANCIA: JAZMIN, PRESENTACION: ENVASE X 185 GR, LIBRE DE CFC: NO CORRESPONDE | F16: unidad | G16: 30 | H16: 167 | I16: =G16*H16 -> 5010
A17: 8 | B17: 2.9.1-6960.27 | C17: ELEMENTOS DE LIMPIEZA | D17: =LEFT(B17,5) -> 2.9.1 | E17: ELEM. LIMPIEZA P/INDUMENTARIA; TIPO: JABON EN PAN, PRESENTACION: 200 GR | F17: unidad | G17: 30 | H17: 47.5 | I17: =G17*H17 -> 1425
A18: 9 | B18: 2.9.1-6960.51 | C18: ELEMENTOS DE LIMPIEZA | D18: =LEFT(B18,5) -> 2.9.1 | E18: ELEM. LIMPIEZA P/INDUMENTARIA; TIPO: JABON EN POLVO BAJA ESPUMA, PRESENTACION: ENVASE X 6 Kg | F18: bolsa | G18: 100 | H18: 729 | I18: =G18*H18 -> 72900
A19: 10 | B19: 2.9.1-6961.23 | C19: ELEMENTOS DE LIMPIEZA | D19: =LEFT(B19,5) -> 2.9.1 | E19: ELEM. P/LIMPIEZA SANITARIOS; TIPO: SODA CAUSTICA, PRESENTACION: ENVASE X 1 Kg | F19: bolsa | G19: 15 | H19: 186.3 | I19: =G19*H19 -> 2794.5
A20: 11 | B20: 2.9.1-1083.8 | C20: ELEMENTOS DE LIMPIEZA | D20: =LEFT(B20,5) -> 2.9.1 | E20: ESPONJA DE ACERO; PESO: 25 GR, MATERIAL: ACERO | F20: unidad | G20: 30 | H20: 44 | I20: =G20*H20 -> 1320
A21: 12 | B21: 2.9.1-1164.1 | C21: ELEMENTOS DE LIMPIEZA | D21: =LEFT(B21,5) -> 2.9.1 | E21: ESPONJAS; MATERIAL: POLIURETANO POLIETER, USO: P/COCINA, ADITAMENTO: FIBRA POLIESTER SUAVE, FORMA: PRISMATICA, LARGO X ANCHO X ESP: 10 X 6 X 3,5 Cm, COLOR: AMARILLO | F21: unidad | G21: 60 | H21: 35 | I21: =G21*H21 -> 2100
... A26: 17 | B26: 2.3.4-786.34 | C26: ELEMENTOS DE LIMPIEZA | D26: =LEFT(B26,5) -> 2.3.4 | E26: PAPEL HIGIENICO; PRESENTACION: PAQUETE X 4 UN, TIPO: ROLLO PRECORTADO, HOJA: DOBLE, ANCHO: 10 Cm, LARGO: 30 M, TIPO DE HOJA: DOBLE, MATERIAL HOJA: DOBLE | F26: paquete | G26: 80 | H26: 105 | I26: =G26*H26 -> 8400
A27: 18 | B27: 2.3.4-938.59 | C27: ELEMENTOS DE LIMPIEZA | D27: 2.3.4 | E27: SERVILLETAS DE PAPEL; TIPO: ROLLO, MOTIVO: SIN, DIMENSION: 25 X 10 Cm, PRESENTACION: ENVASE X 3 UN | F27: paquete | G27: 200 | H27: 88 | I27: =G27*H27 -> 17600
A28: 19 | B28: 2.3.4-783.54 | C28: ELEMENTOS DE LIMPIEZA | D28: =LEFT(B28,5) -> 2.3.4 | E28: TOALLAS DE PAPEL; MATERIAL: PAPEL ECOLOGICO, GRAMAJE: 30 GR/CM2, DIMENSION: 18,4 X 24 Cm, PRESENTACION: X 10 | F28: caja | G28: 550 | H28: 1270 | I28: =G28*H28 -> 698500
A29: 20 | B29: 2.3.4-783.84 | C29: ELEMENTOS DE LIMPIEZA | D29: =LEFT(B29,5) -> 2.3.4 | E29: TOALLAS DE PAPEL; MATERIAL: FIBRA CELULOSICA, GRAMAJE: 20 GR/M2, DIMENSION: 25 Cm, PRESENTACION: 2 X BOBINA X 400 M | F29: Paquete | G29: 400 | H29: 1158 | I29: =G29*H29 -> 463200
A30: 21 | B30: 2.9.1-713.6 | C30: ELEMENTOS DE LIMPIEZA | D30: =LEFT(B30,5) -> 2.9.1 | E30: TRAPOS DE PISO; DIMENSION: 48 X 60 Cm, COLOR: GRIS | F30: unidad | G30: 50 | H30: 58 | I30: =G30*H30 -> 2900
A31: 22 | B31: 2.9.1-2029.14 | C31: ELEMENTOS DE LIMPIEZA | D31: =LEFT(B31,5) -> 2.9.1 | E31: TRAPOS REPASADORES; MATERIAL: ALGODON, DIMENSION: 60 X 60 Cm | F31: unidad | G31: 50 | H31: 108 | I31: =G31*H31 -> 5400
A32: 23 | B32: 2.9.1-6951.30 | C32: ELEMENTOS DE LIMPIEZA | D32: =LEFT(B32,5) -> 2.9.1 | E32: LIMPIADORES; TIPO: LAVANDINA, PRESENTACION: ENVASE X 5 L | F32: Bidon | G32: 400 | H32: 200 | I32: =G32*H32 -> 80000
A33: 24 | B33: 2.9.1-6951.12 | C33: ELEMENTOS DE LIMPIEZA | D33: =LEFT(B33,5) -> 2.9.1 | E33: LIMPIADORES; PRESENTACION: ENVASE X 5 L, TIPO: DETERGENTE | F33: bidon | G33: 70 | H33: 250 | I33: =G33*H33 -> 17500
A34: 25 | B34: 2.9.1-1654.13 | C34: ELEMENTOS DE LIMPIEZA | D34: =LEFT(B34,5) -> 2.9.1 | E34: TRAPOS; TIPO: MICROFIBRA MULTIUSO, PRESENTACION: UNIDAD | F34: unidad | G34: 250 | H34: 140 | I34: =G34*H34 -> 35000
A35: 26 | B35: 2.9.1-678.11 | C35: ELEMENTOS DE LIMPIEZA | D35: =LEFT(B35,5) -> 2.9.1 | E35: TRAPOS REJILLA; DIMENSION: 40 X 45 Cm, MATERIAL: ALGODON | F35: unidad | G35: 500 | H35: 80 | I35: =G35*H35 -> 40000
A36: 27 | B36: 2.9.1-2029.11 | C36: ELEMENTOS DE LIMPIEZA | D36: =LEFT(B36,5) -> 2.9.1 | E36: TRAPOS REPASADORES; MATERIAL: MICROFIBRA, DIMENSION: 30 X 40 Cm | F36: unidad | G36: 150 | H36: 90 | I36: =G36*H36 -> 13500
A37: 28 | B37: 2.9.1-646.86 | C37: ELEMENTOS DE LIMPIEZA | D37: 2.5.8 | E37: BOLSAS DE RESIDUOS; DIMENSION: 100 X 60 Cm, PRESENTACION: UNIDAD, ESPESOR: 40 Mn | F37: unidad | G37: 4000 | H37: 40 | I37: 160000
D45: Entrega de Mercaderia: Item 1 al 28
D47: Plazo de entrega: 10 dias habiles desde la firma de instrumento contractual.
D49: Plazo de mantenimiento de oferta: 30 dias
D51: Lugar de entrega: Servicio de economato de Maternidad Provincial 25 de Mayo- Hernando de Pedraza Nº 1.650
D53: Horario de entrega: de 8 a 12 hs
C57: Especificidades Item N° 1.
C59: Descripción técnica
D60: Material del Mango: plastico, Medida aproximadas del mango: 15 cm de largo x 5 cm de ancho x 5 cm de alto
C62: Plazo de Entrega : | E62: 10 dias desde la firma de instrumento contractual.
C64: Lugares de entrega: | D64: SECTOR ECONOMATO-MATERNIDAD PROVINCIAL 25 DE MAYO , HERNADO DE PEDRAZA 1650-
...

Sheet NotaPedido
A1: NOTA DE PEDIDO | J1: N° | K1: 08/2022
A3: JURISDICCIÓN: | D3: ='Necesidades Trimestrales'!C4 -> 40 - Ministerio de Salud
A4: SAF: | D4: ='Necesidades Trimestrales'!C5 -> 28 - MATERNIDAD PROVINCIAL 25 DE MAYO
A5: UNIDAD EJECUTORA: | D5: 171-Direccion de Admisnitracion
A6: DEPENDENCIA SOLICITANTE: | D6: Servicio de Economato y Nutricion
A7: PERIODO UTILIZACIÓN: | D7: 1º TRIMESTRE AÑO 2022
A8: OBJETO: | D8: Adquisición de elementos de limpieza
A10: Ítem | B10: Codigo Item | C10: DESCRIPCIÓN | H10: Adjunta Detalle Técnico | I10: Unidad Medida | J10: Precio Unitario Estimado | K10: Cantidad Solicitada
A12: ='Necesidades Trimestrales'!A10 -> 1 | B12: ='Necesidades Trimestrales'!B10 -> 2.9.1-6952.19 | C12: ='Necesidades Trimestrales'!E10 -> CEPILLOS; TIPO: DE ROPA, MATERIAL: CERDA | H12: NO | I12: ='Necesidades Trimestrales'!F10 -> unidad | J12: ='Necesidades Trimestrales'!H10 -> 89.95 | K12: ='Necesidades Trimestrales'!G10 -> 15
A13: ='Necesidades Trimestrales'!A11 -> 2 | B13: ='Necesidades Trimestrales'!B11 -> 2.9.1-6952.20 | C13: ='Necesidades Trimestrales'!E11 -> CEPILLOS; TIPO: DE MANO Y UÑA, MATERIAL: CERDA | H13: NO | I13: ='Necesidades Trimestrales'!F11 -> unidad | J13: ='Necesidades Trimestrales'!H11 -> 82 | K13: ='Necesidades Trimestrales'!G11 -> 15
A14: ='Necesidades Trimestrales'!A12 -> 3 | B14: ='Necesidades Trimestrales'!B12 -> 2.5.4-505.90 | C14: ='Necesidades Trimestrales'!E12 -> DESINFECTANTES; PRINCIPIO ACTIVO: ANTIBACTERIANO, CONTROL: BACTERIAS Y HONGOS, PRESENTACION: ENVASE X 390 CM3 | H14: SI | I14: ='Necesidades Trimestrales'!F12 -> unidad | J14: ='Necesidades Trimestrales'!H12 -> 195 | K14: ='Necesidades Trimestrales'!G12 -> 100
A15: ='Necesidades Trimestrales'!A13 -> 4 | B15: ='Necesidades Trimestrales'!B13 -> 2.9.1-544.3 | C15: ='Necesidades Trimestrales'!E13 -> DESODORANTES DE AMBIENTE; PRESENTACION: UNIDAD, FRAGANCIA: VISTA AL MAR, CONTENIDO: 440 CM3, FORMATO: AEROSOL, LIBRE DE CFC: SI | H15: NO | I15: ='Necesidades Trimestrales'!F13 -> unidad | J15: ='Necesidades Trimestrales'!H13 -> 151 | K15: ='Necesidades Trimestrales'!G13 -> 30
A16: ='Necesidades Trimestrales'!A14 -> 5 | B16: ='Necesidades Trimestrales'!B14 -> 2.9.1-544.4 | C16: ='Necesidades Trimestrales'!E14 -> DESODORANTES DE AMBIENTE; FRAGANCIA: CASA DE CAMPO, PRESENTACION: UNIDAD, FORMATO: AEROSOL, CONTENIDO: 440 CM3, LIBRE DE CFC: SI | H16: NO | I16: ='Necesidades Trimestrales'!F14 -> unidad | J16: ='Necesidades Trimestrales'!H14 -> 151 | K16: ='Necesidades Trimestrales'!G14 -> 30
A17: ='Necesidades Trimestrales'!A15 -> 6 | B17: ='Necesidades Trimestrales'!B15 -> 2.9.1-544.7 | C17: ='Necesidades Trimestrales'!E15 -> DESODORANTES DE AMBIENTE; PRESENTACION: UNIDAD, CONTENIDO: 440 CM3, FORMATO: AEROSOL, FRAGANCIA: FLORECER SILVESTRE, LIBRE DE CFC: SI | H17: NO | I17: ='Necesidades Trimestrales'!F15 -> unidad | J17: ='Necesidades Trimestrales'!H15 -> 151 | K17: ='Necesidades Trimestrales'!G15 -> 30
A18: ='Necesidades Trimestrales'!A16 -> 7 | B18: ='Necesidades Trimestrales'!B16 -> 2.9.1-544.66 | C18: ='Necesidades Trimestrales'!E16 -> DESODORANTES DE AMBIENTE; FORMATO: AEROSOL, FRAGANCIA: JAZMIN, PRESENTACION: ENVASE X 185 GR, LIBRE DE CFC: NO CORRESPONDE | H18: NO | I18: ='Necesidades Trimestrales'!F16 -> unidad | J18: ='Necesidades Trimestrales'!H16 -> 167 | K18: ='Necesidades Trimestrales'!G16 -> 30
A19: ='Necesidades Trimestrales'!A17 -> 8 | B19: ='Necesidades Trimestrales'!B17 -> 2.9.1-6960.27 | C19: ='Necesidades Trimestrales'!E17 -> ELEM. LIMPIEZA P/INDUMENTARIA; TIPO: JABON EN PAN, PRESENTACION: 200 GR | H19: NO | I19: ='Necesidades Trimestrales'!F17 -> unidad | J19: ='Necesidades Trimestrales'!H17 -> 47.5 | K19: ='Necesidades Trimestrales'!G17 -> 30
A20: ='Necesidades Trimestrales'!A18 -> 9 | B20: ='Necesidades Trimestrales'!B18 -> 2.9.1-6960.51 | C20: ='Necesidades Trimestrales'!E18 -> ELEM. LIMPIEZA P/INDUMENTARIA; TIPO: JABON EN POLVO BAJA ESPUMA, PRESENTACION: ENVASE X 6 Kg | H20: NO | I20: ='Necesidades Trimestrales'!F18 -> bolsa | J20: ='Necesidades Trimestrales'!H18 -> 729 | K20: ='Necesidades Trimestrales'!G18 -> 100
A21: ='Necesidades Trimestrales'!A19 -> 10 | B21: ='Necesidades Trimestrales'!B19 -> 2.9.1-6961.23 | C21: ='Necesidades Trimestrales'!E19 -> ELEM. P/LIMPIEZA SANITARIOS; TIPO: SODA CAUSTICA, PRESENTACION: ENVASE X 1 Kg | H21: NO | I21: ='Necesidades Trimestrales'!F19 -> bolsa | J21: ='Necesidades Trimestrales'!H19 -> 186.3 | K21: ='Necesidades Trimestrales'!G19 -> 15
A22: ='Necesidades Trimestrales'!A20 -> 11 | B22: ='Necesidades Trimestrales'!B20 -> 2.9.1-1083.8 | C22: ='Necesidades Trimestrales'!E20 -> ESPONJA DE ACERO; PESO: 25 GR, MATERIAL: ACERO | H22: NO | I22: ='Necesidades Trimestrales'!F20 -> unidad | J22: ='Necesidades Trimestrales'!H20 -> 44 | K22: ='Necesidades Trimestrales'!G20 -> 30
A23: ='Necesidades Trimestrales'!A21 -> 12 | B23: ='Necesidades Trimestrales'!B21 -> 2.9.1-1164.1 | C23: ='Necesidades Trimestrales'!E21 -> ESPONJAS; MATERIAL: POLIURETANO POLIETER, USO: P/COCINA, ADITAMENTO: FIBRA POLIESTER SUAVE, FORMA: PRISMATICA, LARGO X ANCHO X ESP: 10 X 6 X 3,5 Cm, COLOR: AMARILLO | H23: NO | I23: ='Necesidades Trimestrales'!F21 -> unidad | J23: ='Necesidades Trimestrales'!H21 -> 35 | K23: ='Necesidades Trimestrales'!G21 -> 60
... A28: ='Necesidades Trimestrales'!A26 -> 17 | B28: ='Necesidades Trimestrales'!B26 -> 2.3.4-786.34 | C28: ='Necesidades Trimestrales'!E26 -> PAPEL HIGIENICO; PRESENTACION: PAQUETE X 4 UN, TIPO: ROLLO PRECORTADO, HOJA: DOBLE, ANCHO: 10 Cm, LARGO: 30 M, TIPO DE HOJA: DOBLE, MATERIAL HOJA: DOBLE | H28: NO | I28: ='Necesidades Trimestrales'!F26 -> paquete | J28: ='Necesidades Trimestrales'!H26 -> 105 | K28: ='Necesidades Trimestrales'!G26 -> 80
A29: ='Necesidades Trimestrales'!A27 -> 18 | B29: 2.3.4-938.59 | C29: SERVILLETAS DE PAPEL; TIPO: ROLLO, MOTIVO: SIN, DIMENSION: 25 X 10 Cm, PRESENTACION: ENVASE X 3 UN | H29: NO | I29: ='Necesidades Trimestrales'!F27 -> paquete | J29: ='Necesidades Trimestrales'!H27 -> 88 | K29: ='Necesidades Trimestrales'!G27 -> 200
A30: ='Necesidades Trimestrales'!A28 -> 19 | B30: ='Necesidades Trimestrales'!B28 -> 2.3.4-783.54 | C30: ='Necesidades Trimestrales'!E28 -> TOALLAS DE PAPEL; MATERIAL: PAPEL ECOLOGICO, GRAMAJE: 30 GR/CM2, DIMENSION: 18,4 X 24 Cm, PRESENTACION: X 10 | H30: NO | I30: ='Necesidades Trimestrales'!F28 -> caja | J30: ='Necesidades Trimestrales'!H28 -> 1270 | K30: ='Necesidades Trimestrales'!G28 -> 550
A31: ='Necesidades Trimestrales'!A29 -> 20 | B31: ='Necesidades Trimestrales'!B29 -> 2.3.4-783.84 | C31: ='Necesidades Trimestrales'!E29 -> TOALLAS DE PAPEL; MATERIAL: FIBRA CELULOSICA, GRAMAJE: 20 GR/M2, DIMENSION: 25 Cm, PRESENTACION: 2 X BOBINA X 400 M | H31: SI | I31: ='Necesidades Trimestrales'!F29 -> Paquete | J31: ='Necesidades Trimestrales'!H29 -> 1158 | K31: ='Necesidades Trimestrales'!G29 -> 400
A32: ='Necesidades Trimestrales'!A30 -> 21 | B32: ='Necesidades Trimestrales'!B30 -> 2.9.1-713.6 | C32: ='Necesidades Trimestrales'!E30 -> TRAPOS DE PISO; DIMENSION: 48 X 60 Cm, COLOR: GRIS | H32: NO | I32: ='Necesidades Trimestrales'!F30 -> unidad | J32: ='Necesidades Trimestrales'!H30 -> 58 | K32: ='Necesidades Trimestrales'!G30 -> 50
A33: ='Necesidades Trimestrales'!A31 -> 22 | B33: ='Necesidades Trimestrales'!B31 -> 2.9.1-2029.14 | C33: ='Necesidades Trimestrales'!E31 -> TRAPOS REPASADORES; MATERIAL: ALGODON, DIMENSION: 60 X 60 Cm | H33: NO | I33: ='Necesidades Trimestrales'!F31 -> unidad | J33: ='Necesidades Trimestrales'!H31 -> 108 | K33: ='Necesidades Trimestrales'!G31 -> 50
A34: ='Necesidades Trimestrales'!A32 -> 23 | B34: ='Necesidades Trimestrales'!B32 -> 2.9.1-6951.30 | C34: ='Necesidades Trimestrales'!E32 -> LIMPIADORES; TIPO: LAVANDINA, PRESENTACION: ENVASE X 5 L | H34: SI | I34: ='Necesidades Trimestrales'!F32 -> Bidon | J34: ='Necesidades Trimestrales'!H32 -> 200 | K34: ='Necesidades Trimestrales'!G32 -> 400
A35: ='Necesidades Trimestrales'!A33 -> 24 | B35: ='Necesidades Trimestrales'!B33 -> 2.9.1-6951.12 | C35: ='Necesidades Trimestrales'!E33 -> LIMPIADORES; PRESENTACION: ENVASE X 5 L, TIPO: DETERGENTE | H35: NO | I35: ='Necesidades Trimestrales'!F33 -> bidon | J35: ='Necesidades Trimestrales'!H33 -> 250 | K35: ='Necesidades Trimestrales'!G33 -> 70
A36: ='Necesidades Trimestrales'!A34 -> 25 | B36: ='Necesidades Trimestrales'!B34 -> 2.9.1-1654.13 | C36: ='Necesidades Trimestrales'!E34 -> TRAPOS; TIPO: MICROFIBRA MULTIUSO, PRESENTACION: UNIDAD | H36: SI | I36: ='Necesidades Trimestrales'!F34 -> unidad | J36: ='Necesidades Trimestrales'!H34 -> 140 | K36: ='Necesidades Trimestrales'!G34 -> 250
A37: ='Necesidades Trimestrales'!A35 -> 26 | B37: ='Necesidades Trimestrales'!B35 -> 2.9.1-678.11 | C37: ='Necesidades Trimestrales'!E35 -> TRAPOS REJILLA; DIMENSION: 40 X 45 Cm, MATERIAL: ALGODON | H37: NO | I37: ='Necesidades Trimestrales'!F35 -> unidad | J37: ='Necesidades Trimestrales'!H35 -> 80 | K37: ='Necesidades Trimestrales'!G35 -> 500
A38: ='Necesidades Trimestrales'!A36 -> 27 | B38: ='Necesidades Trimestrales'!B36 -> 2.9.1-2029.11 | C38: ='Necesidades Trimestrales'!E36 -> TRAPOS REPASADORES; MATERIAL: MICROFIBRA, DIMENSION: 30 X 40 Cm | H38: NO | I38: ='Necesidades Trimestrales'!F36 -> unidad | J38: ='Necesidades Trimestrales'!H36 -> 90 | K38: ='Necesidades Trimestrales'!G36 -> 150
A39: 28 | B39: ='Necesidades Trimestrales'!B37 -> 2.9.1-646.86 | C39: ='Necesidades Trimestrales'!E37 -> BOLSAS DE RESIDUOS; DIMENSION: 100 X 60 Cm, PRESENTACION: UNIDAD, ESPESOR: 40 Mn | H39: SI | I39: ='Necesidades Trimestrales'!F37 -> unidad | J39: ='Necesidades Trimestrales'!H37 -> 40 | K39: ='Necesidades Trimestrales'!G37 -> 4000
A40: Costo total estimado: UN MILLON SETECIENTOS CUARENTA Y UN MIL CIENTO OCHO CON 75/100 | J40: =SUMPRODUCT(K12:K39,J12:J39) -> 1741108.8

Sheet Autor Gastar
A1: EJERCICIO: | D1: ='Necesidades Trimestrales'!C6 -> 2022 | P1: AUTORIZACION PARA GASTAR
A4: JURISDICCIÓN: | G4: =NotaPedido!D3 -> 40 - Ministerio de Salud
A5: SAF: | G5: =NotaPedido!D4 -> 28 - MATERNIDAD PROVINCIAL 25 DE MAYO
A6: UNIDAD EJECUTORA: | G6: =NotaPedido!D5 -> 171-Direccion de Admisnitracion
A7: DEPENDENCIA SOLICITANTE: | G7: =NotaPedido!D6 -> Servicio de Economato y Nutricion
A8: AUTORIZACIÓN:
A9: Señor Jefe de Servicio Administrativo Financiero:
A10: ="Autorizo la realización de los trámites correspondientes, a fin de proveer a este Organismo los bienes y/o servicios que se detallan en Nota de Pedido N° " & NotaPedido!K1&", afectando la erogación resultante a los créditos presupuestarios aprobados a favor de esta Unidad Ejecutora, conforme al siguiente detalle:" -> Autorizo la realización de los trámites correspondientes, a fin de proveer a este Organismo los bienes y/o servicios que se detallan en Nota de Pedido N° 08/2022, afectando la erogación resultante a los créditos presupuestarios aprobados a favor de esta Unidad Ejecutora, conforme al siguiente detalle:
A12: IMPUTACIÓN PRESUPUESTARIA
A13: CÓDIGO | O13: DENOMINACIÓN DE LA PARTIDA PRESUPUESTARIA | Q13: IMPORTE
A14: PR | B14: SB | C14: PY | D14: AC | E14: OB | F14: UG | G14: FIN | H14: FUN | I14: I | J14: P | K14: P | L14: SubP | M14: M | N14: FF
A15: 42 | D15: 3 | F15: 4901 | G15: 3 | H15: 1 | I15: 2 | J15: 3 | K15: 4 | M15: 1 | N15: 1.1 | O15: Productos de Papel y Cartón | Q15: 1187700
A16: 42 | D16: 3 | F16: 4901 | G16: 3 | H16: 1 | I16: 2 | J16: 5 | K16: 4 | M16: 1 | N16: 1.1 | O16: Insecticidas, Fumigantes y Otros | Q16: 31100
A17: 42 | D17: 3 | F17: 4901 | G17: 3 | H17: 1 | I17: 2 | J17: 9 | K17: 1 | M17: 1 | N17: 1.1 | O17: Elementos de Limpieza | Q17: 362308.75
A18: 42 | D18: 3 | F18: 4901 | G18: 3 | H18: 1 | I18: 2 | J18: 5 | K18: 8 | M18: 1 | N18: 1.1 | O18: Pructos de material plastico | Q18: 160000
A23: TOTAL DE PESOS: UN MILLON SETECIENTOS CUARENTA Y UN MIL CIENTO OCHO CON 75/100 | Q23: =SUM(Q15:Q22) -> 1741108.8
A25: JUSTIFICACIÓN:
A26: ="Para la "& NotaPedido!D8 &" para ser destinados a " & NotaPedido!D6 &" de la Maternidad Provincial 25 de Mayo del Ministerio de Salud." -> Para la Adquisición de elementos de limpieza para ser destinados a Servicio de Economato y Nutricion de la Maternidad Provincial 25 de Mayo del Ministerio de Salud.
