Workbook

Sheet Necesidades Trimestrales
B2: Pedido de Necesidades Trimestrales
A4: JURISDICCION: | C4: 40 - Ministerio de Salud
A5: SAF N°: | C5: 23 - Hospital Interzonal San Juan Bautista
A6: EJERCICIO: | C6: 2022
A7: TRIMESTRE: | C7: 4
A9: ID | B9: CODIGO ITEM | C9: RUBRO DE COMPRA | D9: I.P.P. | E9: DESCRIPCION | F9: UNIDAD DE MEDIDA | G9: CANTIDAD | H9: PRECIO UNITARIO ESTIMADO | I9: IMPORTE TOTAL ESTIMADO
A10: 1 | B10: 2.5.1-8988.2389 | C10: QUIMICOS | D10: =LEFT(B10,5) -> 2.5.1 | E10: REACTIVO P/EQUIPO; MARCA EQUIPO: COBAS LIAT; NOMBRE DEL PRODUCTO: DETERMINACIÓN SARS-COV-2 & INFLUENZA A/B; PRESENTACIÓN: KIT X 20 DET. | F10: UNIDAD | G10: 24 | H10: 156000 | I10: =G10*H10 -> 3744000
A11: 2 | B11: 2.5.1-9043.6 | C11: QUIMICOS | D11: =LEFT(B11,5) -> 2.5.1 | E11: ACEITES Y GRASAS; COMPUESTO QUIMICO: BALSAMO DE CANADA , ESTADO: LIQUIDO, CALIDAD: PRO ANALISIS, CONCENTRACION/PUREZA: 99,9 %, PRESENTACION: ENVASE X 100 Ml | F11: BOTELLA | G11: 6 | H11: 2686 | I11: =G11*H11 -> 16116
A12: 3 | B12: 2.5.1-9043.6 | C12: QUIMICOS | D12: =LEFT(B12,5) -> 2.5.1 | E12: ACEITES Y GRASAS; COMPUESTO QUIMICO: BALSAMO DE CANADA , ESTADO: LIQUIDO, CALIDAD: PRO ANALISIS, CONCENTRACION/PUREZA: 99,9 %, PRESENTACION: ENVASE X 100 Ml | F12: BOTELLA | G12: 6 | H12: 2518 | I12: =G12*H12 -> 15108
A13: 4 | B13: 2.5.1-8937.899 | C13: QUIMICOS | D13: =LEFT(B13,5) -> 2.5.1 | E13: PATRON/ESTANDAR P/CALIBRACION; EQUIPO: AUTOANAL. X QUIMIOLUMINISCENCIA,, MARCA EQUIPO: ROCHE, NOMBRE DEL PRODUCTO: CONTROL ANTI CCP 2 NIVELES, PRESENTACION: 4 X 2 ML | F13: CAJA | G13: 1 | H13: 37129 | I13: =G13*H13 -> 37129
A14: 5 | B14: 2.5.1-8988.1619 | C14: QUIMICOS | D14: =LEFT(B14,5) -> 2.5.1 | E14: REACTIVOS P/EQUIPO; EQUIPO: ANALIZADOR DE QUIMICA CLINICA, MARCA EQUIPO: ROCHE, NOMBRE DEL PRODUCTO: ANTIESTREPTOLISINA, PRESENTACION: ENVASE X 150 DETERM. | F14: CASSETTE | G14: 1 | H14: 38887 | I14: =G14*H14 -> 38887
A15: 6 | B15: 2.5.1-8988.1331 | C15: QUIMICOS | D15: =LEFT(B15,5) -> 2.5.1 | E15: REACTIVOS P/EQUIPO; EQUIPO: ANALIZADOR MULTIPARAMÉTRICO; MARCA EQUIPO: COBAS ROCHE; NOMBRE DEL PRODUCTO: DET. DE ÁCIDO ÚRICO; PRESENTACIÓN: UNIDAD S/PLIEGO | F15: CASSETTE | G15: 3 | H15: 7703 | I15: =G15*H15 -> 23109
A16: 7 | B16: 2.5.1-8988.972 | C16: QUIMICOS | D16: =LEFT(B16,5) -> 2.5.1 | E16: REACTIVOS P/EQUIPO; EQUIPO: AUTOANA. QUIMICA CLINICA, MARCA EQUIPO: COBAS ROCHE, NOMBRE DEL PRODUCTO: ALBUMINA P/MICROALBUMINURIA, PRESENTACION: ENVASE X 100 DETERM. | F16: CASSETTE | G16: 2 | H16: 14833 | I16: =G16*H16 -> 29666
A17: 8 | B17: 2.5.1-8988.930 | C17: QUIMICOS | D17: =LEFT(B17,5) -> 2.5.1 | E17: REACTIVOS P/EQUIPO; EQUIPO: AUTOANA. QUIMICA CLINICA, MARCA EQUIPO: COBAS ROCHE, NOMBRE DEL PRODUCTO: ALBUMINA, PRESENTACION: ENVASE X 300 DETERM. | F17: CASSETTE | G17: 14 | H17: 2820 | I17: =G17*H17 -> 39480
A18: 9 | B18: 2.5.1-8988.943 | C18: QUIMICOS | D18: =LEFT(B18,5) -> 2.5.1 | E18: REACTIVOS P/EQUIPO; EQUIPO: AUTOANA. QUIMICA CLINICA, MARCA EQUIPO: COBAS ROCHE, NOMBRE DEL PRODUCTO: ALP2L (IFCC), PRESENTACION: ENVASE X 400 DETERM. | F18: CASSETTE | G18: 8 | H18: 12214 | I18: =G18*H18 -> 97712
A19: 10 | B19: 2.5.1-8988.933 | C19: QUIMICOS | D19: =LEFT(B19,5) -> 2.5.1 | E19: REACTIVOS P/EQUIPO; EQUIPO: AUTOANA. QUIMICA CLINICA, MARCA EQUIPO: COBAS ROCHE, NOMBRE DEL PRODUCTO: ALTL (IFCC), PRESENTACION: ENVASE X 500 DETERM. | F19: CASSETTE | G19: 8 | H19: 12214 | I19: =G19*H19 -> 97712
A20: 11 | B20: 2.5.1-8988.931 | C20: QUIMICOS | D20: =LEFT(B20,5) -> 2.5.1 | E20: REACTIVOS P/EQUIPO; EQUIPO: AUTOANA. QUIMICA CLINICA, MARCA EQUIPO: COBAS ROCHE, NOMBRE DEL PRODUCTO: AMILASA TOTAL, PRESENTACION: ENVASE X 300 DETERM. | F20: CASSETTE | G20: 4 | H20: 14571 | I20: =G20*H20 -> 58284
A21: 12 | B21: 2.5.1-8988.932 | C21: QUIMICOS | D21: =LEFT(B21,5) -> 2.5.1 | E21: REACTIVOS P/EQUIPO; EQUIPO: AUTOANA. QUIMICA CLINICA, MARCA EQUIPO: COBAS ROCHE, NOMBRE DEL PRODUCTO: AST (IFCC), PRESENTACION: ENVASE X 500 DETERM. | F21: CASSETTE | G21: 8 | H21: 12214 | I21: =G21*H21 -> 97712
... A77: 68 | B77: 2.5.1-8988.2230 | C77: QUIMICOS | D77: =LEFT(B77,5) -> 2.5.1 | E77: REACTIVOS P/EQUIPO; EQUIPO: SISTEMA AUTOMATIZADO P/ORINA, MARCA EQUIPO: GENERICO, NOMBRE DEL PRODUCTO: TIRAS REACTIVAS 10 PARAMETROS, PRESENTACION: ENVASE X 100 UN | F77: CAJA | G77: 50 | H77: 3690 | I77: =G77*H77 -> 184500
C79: PLAZO DE MANTENIMIENTO DE OFERTA: 45 DIAS HABILES
C80: PLAZO DE ENTREGA: 15 DIAS HABILES EN EL SERVICIO DE LABORATORIO - AVDA. ILLIA Y MARIANO MORENO - DE LUNES A VIERNES EN EL HORARIO DE 08 A 11 HORAS
B83: Especificidades Item N° 2:
B85: Descripción técnica
C86: BALSAMO DE CANADA SINTETICO T/BIOPUR X 100 ML
B87: Plazos y lugares de entrega
B90: Calidad Minima esperada
B92: Mantenimiento
B94: Garantia
B98: Especificidades Item N° 3:
B100: Descripción técnica
C101: BALSAMO DE CANADA NATURAL SECADO RAPIDO T/BIOPUR X 100 ML
B102: Plazos y lugares de entrega
B105: Calidad Minima esperada
B107: Mantenimiento
B109: Garantia
B113: Especificidades Item N° 6:
B115: Descripción técnica
C116: REACTIVO ACIDO URICO COBAS C-311 ROCHE X 400 DET
B117: Plazos y lugares de entrega
B120: Calidad Minima esperada
...

Sheet NotaPedido
A1: NOTA DE PEDIDO 121 | J1: N° | K1: DOCFI-2022-01873418-CAT-DASIS#HSJB
A3: JURISDICCIÓN: | D3: ='Necesidades Trimestrales'!C4 -> 40 - Ministerio de Salud
A4: SAF: | D4: ='Necesidades Trimestrales'!C5 -> 23 - Hospital Interzonal San Juan Bautista
A5: UNIDAD EJECUTORA: | D5: 168 - Direccion Asistencial
A6: DEPENDENCIA SOLICITANTE: | D6: Servicio de Laboratorio Central
A7: PERIODO UTILIZACIÓN: | D7: ='Necesidades Trimestrales'!C7 & "° Trimestre - Año " & 'Necesidades Trimestrales'!C6 -> 4° Trimestre - Año 2022
A8: OBJETO: | D8: Adquisición de Reactivos Desiertos
A10: Ítem | B10: Codigo Item | C10: DESCRIPCIÓN | H10: Adjunta Detalle Técnico | I10: Unidad Medida | J10: Precio Unitario Estimado | K10: Cantidad Solicitada
A12: 1 | B12: ='Necesidades Trimestrales'!B10 -> 2.5.1-8988.2389 | C12: ='Necesidades Trimestrales'!E10 -> REACTIVO P/EQUIPO; MARCA EQUIPO: COBAS LIAT; NOMBRE DEL PRODUCTO: DETERMINACIÓN SARS-COV-2 & INFLUENZA A/B; PRESENTACIÓN: KIT X 20 DET. | H12: NO | I12: ='Necesidades Trimestrales'!F10 -> UNIDAD | J12: ='Necesidades Trimestrales'!H10 -> 156000 | K12: ='Necesidades Trimestrales'!G10 -> 24
A13: 2 | B13: ='Necesidades Trimestrales'!B11 -> 2.5.1-9043.6 | C13: ='Necesidades Trimestrales'!E11 -> ACEITES Y GRASAS; COMPUESTO QUIMICO: BALSAMO DE CANADA , ESTADO: LIQUIDO, CALIDAD: PRO ANALISIS, CONCENTRACION/PUREZA: 99,9 %, PRESENTACION: ENVASE X 100 Ml | H13: SI | I13: ='Necesidades Trimestrales'!F11 -> BOTELLA | J13: ='Necesidades Trimestrales'!H11 -> 2686 | K13: ='Necesidades Trimestrales'!G11 -> 6
A14: 3 | B14: ='Necesidades Trimestrales'!B12 -> 2.5.1-9043.6 | C14: ='Necesidades Trimestrales'!E12 -> ACEITES Y GRASAS; COMPUESTO QUIMICO: BALSAMO DE CANADA , ESTADO: LIQUIDO, CALIDAD: PRO ANALISIS, CONCENTRACION/PUREZA: 99,9 %, PRESENTACION: ENVASE X 100 Ml | H14: SI | I14: ='Necesidades Trimestrales'!F12 -> BOTELLA | J14: ='Necesidades Trimestrales'!H12 -> 2518 | K14: ='Necesidades Trimestrales'!G12 -> 6
A15: 4 | B15: ='Necesidades Trimestrales'!B13 -> 2.5.1-8937.899 | C15: ='Necesidades Trimestrales'!E13 -> PATRON/ESTANDAR P/CALIBRACION; EQUIPO: AUTOANAL. X QUIMIOLUMINISCENCIA,, MARCA EQUIPO: ROCHE, NOMBRE DEL PRODUCTO: CONTROL ANTI CCP 2 NIVELES, PRESENTACION: 4 X 2 ML | H15: NO | I15: ='Necesidades Trimestrales'!F13 -> CAJA | J15: ='Necesidades Trimestrales'!H13 -> 37129 | K15: ='Necesidades Trimestrales'!G13 -> 1
A16: 5 | B16: ='Necesidades Trimestrales'!B14 -> 2.5.1-8988.1619 | C16: ='Necesidades Trimestrales'!E14 -> REACTIVOS P/EQUIPO; EQUIPO: ANALIZADOR DE QUIMICA CLINICA, MARCA EQUIPO: ROCHE, NOMBRE DEL PRODUCTO: ANTIESTREPTOLISINA, PRESENTACION: ENVASE X 150 DETERM. | H16: NO | I16: ='Necesidades Trimestrales'!F14 -> CASSETTE | J16: ='Necesidades Trimestrales'!H14 -> 38887 | K16: ='Necesidades Trimestrales'!G14 -> 1
A17: 6 | B17: ='Necesidades Trimestrales'!B15 -> 2.5.1-8988.1331 | C17: ='Necesidades Trimestrales'!E15 -> REACTIVOS P/EQUIPO; EQUIPO: ANALIZADOR MULTIPARAMÉTRICO; MARCA EQUIPO: COBAS ROCHE; NOMBRE DEL PRODUCTO: DET. DE ÁCIDO ÚRICO; PRESENTACIÓN: UNIDAD S/PLIEGO | H17: SI | I17: ='Necesidades Trimestrales'!F15 -> CASSETTE | J17: ='Necesidades Trimestrales'!H15 -> 7703 | K17: ='Necesidades Trimestrales'!G15 -> 3
A18: 7 | B18: ='Necesidades Trimestrales'!B16 -> 2.5.1-8988.972 | C18: ='Necesidades Trimestrales'!E16 -> REACTIVOS P/EQUIPO; EQUIPO: AUTOANA. QUIMICA CLINICA, MARCA EQUIPO: COBAS ROCHE, NOMBRE DEL PRODUCTO: ALBUMINA P/MICROALBUMINURIA, PRESENTACION: ENVASE X 100 DETERM. | H18: NO | I18: ='Necesidades Trimestrales'!F16 -> CASSETTE | J18: ='Necesidades Trimestrales'!H16 -> 14833 | K18: ='Necesidades Trimestrales'!G16 -> 2
A19: 8 | B19: ='Necesidades Trimestrales'!B17 -> 2.5.1-8988.930 | C19: ='Necesidades Trimestrales'!E17 -> REACTIVOS P/EQUIPO; EQUIPO: AUTOANA. QUIMICA CLINICA, MARCA EQUIPO: COBAS ROCHE, NOMBRE DEL PRODUCTO: ALBUMINA, PRESENTACION: ENVASE X 300 DETERM. | H19: NO | I19: ='Necesidades Trimestrales'!F17 -> CASSETTE | J19: ='Necesidades Trimestrales'!H17 -> 2820 | K19: ='Necesidades Trimestrales'!G17 -> 14
A20: 9 | B20: ='Necesidades Trimestrales'!B18 -> 2.5.1-8988.943 | C20: ='Necesidades Trimestrales'!E18 -> REACTIVOS P/EQUIPO; EQUIPO: AUTOANA. QUIMICA CLINICA, MARCA EQUIPO: COBAS ROCHE, NOMBRE DEL PRODUCTO: ALP2L (IFCC), PRESENTACION: ENVASE X 400 DETERM. | H20: NO | I20: ='Necesidades Trimestrales'!F18 -> CASSETTE | J20: ='Necesidades Trimestrales'!H18 -> 12214 | K20: ='Necesidades Trimestrales'!G18 -> 8
A21: 10 | B21: ='Necesidades Trimestrales'!B19 -> 2.5.1-8988.933 | C21: ='Necesidades Trimestrales'!E19 -> REACTIVOS P/EQUIPO; EQUIPO: AUTOANA. QUIMICA CLINICA, MARCA EQUIPO: COBAS ROCHE, NOMBRE DEL PRODUCTO: ALTL (IFCC), PRESENTACION: ENVASE X 500 DETERM. | H21: NO | I21: ='Necesidades Trimestrales'!F19 -> CASSETTE | J21: ='Necesidades Trimestrales'!H19 -> 12214 | K21: ='Necesidades Trimestrales'!G19 -> 8
A22: 11 | B22: ='Necesidades Trimestrales'!B20 -> 2.5.1-8988.931 | C22: ='Necesidades Trimestrales'!E20 -> REACTIVOS P/EQUIPO; EQUIPO: AUTOANA. QUIMICA CLINICA, MARCA EQUIPO: COBAS ROCHE, NOMBRE DEL PRODUCTO: AMILASA TOTAL, PRESENTACION: ENVASE X 300 DETERM. | H22: NO | I22: ='Necesidades Trimestrales'!F20 -> CASSETTE | J22: ='Necesidades Trimestrales'!H20 -> 14571 | K22: ='Necesidades Trimestrales'!G20 -> 4
A23: 12 | B23: ='Necesidades Trimestrales'!B21 -> 2.5.1-8988.932 | C23: ='Necesidades Trimestrales'!E21 -> REACTIVOS P/EQUIPO; EQUIPO: AUTOANA. QUIMICA CLINICA, MARCA EQUIPO: COBAS ROCHE, NOMBRE DEL PRODUCTO: AST (IFCC), PRESENTACION: ENVASE X 500 DETERM. | H23: NO | I23: ='Necesidades Trimestrales'!F21 -> CASSETTE | J23: ='Necesidades Trimestrales'!H21 -> 12214 | K23: ='Necesidades Trimestrales'!G21 -> 8
... A79: 68 | B79: ='Necesidades Trimestrales'!B77 -> 2.5.1-8988.2230 | C79: ='Necesidades Trimestrales'!E77 -> REACTIVOS P/EQUIPO; EQUIPO: SISTEMA AUTOMATIZADO P/ORINA, MARCA EQUIPO: GENERICO, NOMBRE DEL PRODUCTO: TIRAS REACTIVAS 10 PARAMETROS, PRESENTACION: ENVASE X 100 UN | H79: NO | I79: ='Necesidades Trimestrales'!F77 -> CAJA | J79: ='Necesidades Trimestrales'!H77 -> 3690 | K79: ='Necesidades Trimestrales'!G77 -> 50
A80: Costo total estimado: PESOS DIEZ MILLONES QUINIENTOS VEINTITRES MIL TRESCIENTOS VEINTINUEVE CON 00/100 | J80: =SUMPRODUCT(J12:J79,K12:K79) -> 10523329

Sheet Autor Gastar
A1: EJERCICIO: | D1: ='Necesidades Trimestrales'!C6 -> 2022 | P1: AUTORIZACION PARA GASTAR
A4: JURISDICCIÓN: | G4: =NotaPedido!D3 -> 40 - Ministerio de Salud
A5: SAF: | G5: =NotaPedido!D4 -> 23 - Hospital Interzonal San Juan Bautista
A6: UNIDAD EJECUTORA: | G6: =NotaPedido!D5 -> 168 - Direccion Asistencial
A7: DEPENDENCIA SOLICITANTE: | G7: =NotaPedido!D6 -> Servicio de Laboratorio Central
A8: AUTORIZACIÓN:
A9: Señor Jefe de Servicio Administrativo Financiero:
A10: ="Autorizo la realización de los trámites correspondientes, a fin de proveer a este Organismo los bienes y/o servicios que se detallan en Nota de Pedido N° " & NotaPedido!K1&", afectando la erogación resultante a los créditos presupuestarios aprobados a favor de esta Unidad Ejecutora, conforme al siguiente detalle:" -> Autorizo la realización de los trámites correspondientes, a fin de proveer a este Organismo los bienes y/o servicios que se detallan en Nota de Pedido N° DOCFI-2022-01873418-CAT-DASIS#HSJB, afectando la erogación resultante a los créditos presupuestarios aprobados a favor de esta Unidad Ejecutora, conforme al siguiente detalle:
A12: IMPUTACIÓN PRESUPUESTARIA
A13: CÓDIGO | O13: DENOMINACIÓN DE LA PARTIDA PRESUPUESTARIA | Q13: IMPORTE
A14: PR | B14: SB | C14: PY | D14: AC | E14: OB | F14: UG | G14: FIN | H14: FUN | I14: I | J14: P | K14: P | L14: SubP | M14: M | N14: FF
A15: 33 | D15: 2 | F15: 4901 | G15: 3 | H15: 3.1 | I15: 2 | J15: 5 | K15: 1 | M15: 1 | N15: 1.1 | O15: Compuestos Quimicos | Q15: 10523329
A23: TOTAL DE PESOS: DIEZ MILLONES QUINIENTOS VEINTITRES MIL TRESCIENTOS VEINTINUEVE CON 00/100.----- | Q23: =SUM(Q15:Q22) -> 10523329
A25: JUSTIFICACIÓN:
A26: ="Para la "& NotaPedido!D8 &" para ser destinados al " & NotaPedido!D6 &" del HISJB del Ministerio de Salud." -> Para la Adquisición de Reactivos Desiertos para ser destinados al Servicio de Laboratorio Central del HISJB del Ministerio de Salud.
