Workbook

Sheet Necesidades Trimestrales
B2: Pedido de Necesidades Trimestrales
A4: JURISDICCION: | C4: 40- Ministerio de Salud
A5: SAF N°: | C5: 28- Maternidad Provincial 25 de Mayo
A6: EJERCICIO: | C6: 2022
A7: TRIMESTRE: | C7: 2
A9: ID | B9: CODIGO ITEM | C9: RUBRO DE COMPRA | D9: I.P.P. | E9: DESCRIPCION | F9: UNIDAD DE MEDIDA | G9: CANTIDAD | H9: PRECIO UNITARIO ESTIMADO | I9: IMPORTE TOTAL ESTIMADO
A10: 1 | B10: 2.2.3-918.29 | C10: INDUMENT TEXTIL Y CONFECCIONES | D10: =LEFT(B10,5) -> 2.2.3 | E10: MANTAS; MATERIAL: POLAR, TAMAÑO: 1 PLAZA | F10: UNIDAD | G10: 80 | H10: 4500 | I10: =+H10*G10 -> 360000
A11: 2 | B11: 2.2.3-920.5 | C11: INDUMENT TEXTIL Y CONFECCIONES | D11: =LEFT(B11,5) -> 2.2.3 | E11: FRAZADAS; TAMAÑO: 1 PLAZA, MOTIVO: LISA, MATERIAL: LANA C/POLIESTER, HILADO: LANA C/POLIESTER | F11: UNIDAD | G11: 50 | H11: 2500 | I11: =+H11*G11 -> 125000
A12: 3 | B12: 2.2.3-942.98 | C12: INDUMENT TEXTIL Y CONFECCIONES | D12: =LEFT(B12,5) -> 2.2.3 | E12: TOALLAS DE TELA: MEDIDAS 0,80 x 1,50M | F12: UNIDAD | G12: 30 | H12: 2300 | I12: =+H12*G12 -> 69000
A13: 4 | B13: 2.2.3-923.7 | C13: INDUMENT TEXTIL Y CONFECCIONES | D13: =LEFT(B13,5) -> 2.2.3 | E13: SABANAS; TELA: ALGODON C/POLIESTER, CONJUNTO: SUPERIOR,INFERIOR Y FUNDA, TAMAÑO: 1 1/2 PLAZA | F13: UNIDAD | G13: 200 | H13: 6750 | I13: =+H13*G13 -> 1350000
B31: Especificidades Item N° 1:
B33: Descripción técnica | E33: Manta de FLANNEL, suave, 300 grs. minimo X m2, 100% poliester, Tamaño Minimo 150 cm x 210 cm
E34: Preferentemente color gris, azul o blanca
B36: Plazo de Entrega: | E36: Diez ( 10) dias habiles
B38: Lugar de Entrega: | E38: DIVISION DE ENFERMERIA- MATERNIDAD PROVINCIAL 25 DE MAYO
B40: Calidad Minima esperada
B42: Mantenimiento | E42: 30(Treinta) dias habiles.
B44: Garantia
B50: Especificidades Item N° 2:
B51: Descripción técnica | E51: Frazada simil lana,Tamaño: de 150 cm x 210 cm. como minimo, con costura reforzada- Composicion 60% acrilico, 25% algodón y 15% poliester
E52: Preferentemente color gris, azul o blanca
B53: Plazo de Entrega: | E53: Diez ( 10) dias habiles
B55: Lugar de Entrega: | E55: DIVISION DE ENFERMERIA- MATERNIDAD PROVINCIAL 25 DE MAYO
B57: Calidad Minima Esperada:
B59: Mantenimiento: | E59: 30(treinta) dias habiles
B61: Garantia:
B66: Especificidades Item N° 3:
B68: Descripción técnica | E68: 100% algodón de 450 gramos
C69: Preferentemente color celeste ,azul o gris.
B70: Plazo de Entrega: | E70: Diez ( 10) dias habiles
B72: Lugar de Entrega: | E72: DIVISION DE ENFERMERIA- MATERNIDAD PROVINCIAL 25 DE MAYO
B74: Calidad Minima esperada
B76: Mantenimiento | E76: 30(Treinta) dias habiles
B78: Garantia
B82: Especificidades Item N° 4:
B84: Descripción técnica | E84: Tela: Algodon peinado-80% poliester,20% 180 hilos,Tamaño: 1 1/2, Medidas: sabana superior 1,70 x 2,50 cm aproximadamente, Sabana Inferior ajustable: 90 cm x 200 cm y 30 cm de altura aproximadamente,Funda: 50 x 80 cm aproximadamente- tejido Antialergico, resistente al lavado industrial con cloro
E85: Preferentemente color blancas
B87: Plazo de Entrega: | E87: Diez ( 10) dias habiles
B89: Lugar de Entrega: | E89: DIVISION DE ENFERMERIA- MATERNIDAD PROVINCIAL 25 DE MAYO
B90: Calidad Minima esperada
...

Sheet  NotaPedido
A1: NOTA DE PEDIDO | J1: N° | K1: 41/2022
A3: JURISDICCIÓN: | D3: ='Necesidades Trimestrales'!C4 -> 40- Ministerio de Salud
A4: SAF: | D4: ='Necesidades Trimestrales'!C5 -> 28- Maternidad Provincial 25 de Mayo
A5: UNIDAD EJECUTORA: | D5: 169-Direccion Asistencial
A6: DEPENDENCIA SOLICITANTE: | D6: División de Enfermería
A7: PERIODO UTILIZACIÓN: | D7: 2do trimestre 2022
A8: OBJETO: | D8: Adquisición de indumentaria textil.
A10: Ítem | B10: Codigo Item | C10: DESCRIPCIÓN | H10: Adjunta Detalle Técnico | I10: Unidad Medida | J10: Precio Unitario Estimado | K10: Cantidad Solicitada
A12: 1 | B12: ='Necesidades Trimestrales'!B10 -> 2.2.3-918.29 | C12: ='Necesidades Trimestrales'!E10 -> MANTAS; MATERIAL: POLAR, TAMAÑO: 1 PLAZA | H12: SI | I12: ='Necesidades Trimestrales'!F10 -> UNIDAD | J12: ='Necesidades Trimestrales'!H10 -> 4500 | K12: ='Necesidades Trimestrales'!G10 -> 80
A13: 2 | B13: ='Necesidades Trimestrales'!B11 -> 2.2.3-920.5 | C13: ='Necesidades Trimestrales'!E11 -> FRAZADAS; TAMAÑO: 1 PLAZA, MOTIVO: LISA, MATERIAL: LANA C/POLIESTER, HILADO: LANA C/POLIESTER | H13: SI | I13: ='Necesidades Trimestrales'!F11 -> UNIDAD | J13: ='Necesidades Trimestrales'!H11 -> 2500 | K13: ='Necesidades Trimestrales'!G11 -> 50
A14: 3 | B14: ='Necesidades Trimestrales'!B12 -> 2.2.3-942.98 | C14: ='Necesidades Trimestrales'!E12 -> TOALLAS DE TELA: MEDIDAS 0,80 x 1,50M | H14: SI | I14: ='Necesidades Trimestrales'!F12 -> UNIDAD | J14: ='Necesidades Trimestrales'!H12 -> 2300 | K14: ='Necesidades Trimestrales'!G12 -> 30
A15: 4 | B15: ='Necesidades Trimestrales'!B13 -> 2.2.3-923.7 | C15: ='Necesidades Trimestrales'!E13 -> SABANAS; TELA: ALGODON C/POLIESTER, CONJUNTO: SUPERIOR,INFERIOR Y FUNDA, TAMAÑO: 1 1/2 PLAZA | H15: SI | I15: ='Necesidades Trimestrales'!F13 -> UNIDAD | J15: ='Necesidades Trimestrales'!H13 -> 6750 | K15: ='Necesidades Trimestrales'!G13 -> 200
A16: Costo total estimado: UN MILLON NOVECIENTOS CUATRO MIL CON 00/100 CENTAVOS | J16: =SUMPRODUCT(J12:J15,K12:K15) -> 1904000

Sheet Autor Gastar
A1: EJERCICIO: | D1: ='Necesidades Trimestrales'!C6 -> 2022 | P1: AUTORIZACION PARA GASTAR
A4: JURISDICCIÓN: | G4: =' NotaPedido'!D3 -> 40- Ministerio de Salud
A5: SAF: | G5: =' NotaPedido'!D4 -> 28- Maternidad Provincial 25 de Mayo
A6: UNIDAD EJECUTORA: | G6: =' NotaPedido'!D5 -> 169-Direccion Asistencial
A7: DEPENDENCIA SOLICITANTE: | G7: =' NotaPedido'!D6 -> División de Enfermería
A8: AUTORIZACIÓN:
A9: Señor Jefe de Servicio Administrativo Financiero:
A10: "Autorizo la realización de los trámites correspondientes, a fin de proveer a este Organismo los bienes y/o servicios que se detallan en Nota de Pedido N° 41/2022, afectando la erogación resultante a los créditos presupuestarios aprobados a favor de esta Unidad Ejecutora, conforme al siguiente detalle:"
A12: IMPUTACIÓN PRESUPUESTARIA
A13: CÓDIGO | O13: DENOMINACIÓN DE LA PARTIDA PRESUPUESTARIA | Q13: IMPORTE
A14: PR | B14: SB | C14: PY | D14: AC | E14: OB | F14: UG | G14: FIN | H14: FUN | I14: I | J14: P | K14: P | L14: SubP | M14: M | N14: FF
A15: 42 | D15: 2 | F15: 4901 | G15: 3 | H15: 1 | I15: 2 | J15: 2 | K15: 3 | M15: 1 | N15: 1.1 | O15: CONFECCIONES TEXTILES | Q15: 1904000
A16: TOTAL DE PESOS: UN MILLON NOVECIENTOS CUATRO MIL CON 00/100 | Q16: =SUM(Q15:Q15) -> 1904000
A18: JUSTIFICACIÓN:
A19: Para la adquisición de indumentaria textil, las mismas seran destinadas a la atencion de pacientes que ingresan a nuestra institucion
