Workbook

Sheet Necesidades Trimestrales
B2: Pedido de Necesidades Trimestrales
A4: JURISDICCION: | C4: 040 - Ministerio de Salud
A5: SAF N°: | C5: 11/ 23/ 24 o 28- "…......."
A6: EJERCICIO: | C6: 2022
A7: TRIMESTRE: | C7: 4
A9: ID | B9: CODIGO ITEM | C9: RUBRO DE COMPRA | D9: I.P.P. | E9: DESCRIPCION | F9: UNIDAD DE MEDIDA | G9: CANTIDAD | H9: PRECIO UNITARIO ESTIMADO | I9: IMPORTE TOTAL ESTIMADO
A10: 1 | B10: 2.5.2-1895.67 | C10: PROD. MEDICO/FARMACEUTICOS/LAB | D10: 252 | E10: HORMONAS MEDICINALES; TIPO: MONODROGA, DROGA GENERICA: VALERATO DE ESTRADIOL, FORMA FARMACEUTICA: COMPRIMIDO 1MGR, PRESENTACION: ENVASE X 28 UN, USO: HORMONOTERAPIA DE REEMPLAZO | F10: CAJA | G10: 1 | H10: 1007.05 | I10: =+G10*H10 -> 1007.05
A11: 2 | B11: 2.5.2-3955.1 | C11: PROD. MEDICO/FARMACEUTICOS/LAB | D11: 252 | E11: ANTIANDROGENOS; TIPO: MONODROGA, DROGA GENERICA: CIPROTERONA, FORMA FARMACEUTICA: COMPRIMIDO, PRESENTACION: 50 mGr | F11: COMPRIMIDO | G11: 1 | H11: 190.52 | I11: =+G11*H11 -> 190.52
A12: 3 | B12: 2.5.2-1875.132 | C12: PROD. MEDICO/FARMACEUTICOS/LAB | D12: 252 | E12: ANTIASMATICO BRONCODILATADOR; TIPO: MONODROGA, DROGA GENERICA: N-ACETIL CISTEINA 2 GR, FORMA FARMACEUTICA: JARABE PARA PREPARAR 100 ML, PRESENTACION: UNIDAD | F12: FRASCO | G12: 1 | H12: 1253 | I12: =+G12*H12 -> 1253
A13: 4 | B13: 2.5.2-1875.133 | C13: PROD. MEDICO/FARMACEUTICOS/LAB | D13: 252 | E13: ANTIASMATICO BRONCODILATADOR; TIPO: MONODROGA, DROGA GENERICA: N-ACETIL CISTEINA 600 MGR, FORMA FARMACEUTICA: TABLETA EFERVESCENTE, PRESENTACION: UNIDAD | F13: TABLETAS | G13: 1 | H13: 35.24 | I13: =+G13*H13 -> 35.24
A14: 5 | B14: 2.5.2-2198.8 | C14: PROD. MEDICO/FARMACEUTICOS/LAB | D14: 252 | E14: ANTIDIURETICOS; DROGA GENERICA: VASOPRESINA ACUOSA, FORMA FARMACEUTICA: AMPOLLA, PRESENTACION: 1 mL, TIPO: MONODROGA | F14: CAJA | G14: 1 | H14: 775 | I14: =+G14*H14 -> 775
A15: 6 | B15: 2.5.2-1829.25 | C15: PROD. MEDICO/FARMACEUTICOS/LAB | D15: 252 | E15: ANTIVIRALES; TIPO: MONODROGA, DROGA GENERICA: ACICLOVIR 5 %, FORMA FARMACEUTICA: CREMA, PRESENTACION: ENVASE X 5 GR | F15: ENVASE | G15: 1 | H15: 285 | I15: =+G15*H15 -> 285
A16: 7 | B16: 2.5.2-1821.189 | C16: PROD. MEDICO/FARMACEUTICOS/LAB | D16: 252 | E16: ANTIBIOTICOS P/PERSONAS; DROGA GENERICA: ACIDO FUSIDICO 20MG, FORMA FARMACEUTICA: CREMA, PRESENTACION: POMO X 15 GR, TIPO: MONODROGA | F16: ENVASE | G16: 1 | H16: 650 | I16: =+G16*H16 -> 650
A17: 8 | B17: 2.5.2-1726.26 | C17: PROD. MEDICO/FARMACEUTICOS/LAB | D17: 252 | E17: SOLUCIONES P/MEDICINA; TIPO: AGUA DE ALIBOUR, PRESENTACION: 250 CM3 | F17: FRASCO | G17: 1 | H17: 560 | I17: =+G17*H17 -> 560
A18: 9 | B18: 2.5.2-1875.74 | C18: PROD. MEDICO/FARMACEUTICOS/LAB | D18: 252 | E18: ANTIASMATICO BRONCODILATADOR; TIPO: MONODROGA, DROGA GENERICA: AMINOFILINA 240MGR, FORMA FARMACEUTICA: AMPOLLA, PRESENTACION: ENVASE X 10 ML | F18: AMPOLLA | G18: 1 | H18: 86 | I18: =+G18*H18 -> 86
A19: 10 | B19: 2.9.5-427.33 | C19: PROD. MEDICO/FARMACEUTICOS/LAB | D19: 252 | E19: APOSITOS; TIPO: HIDROCOLOIDE, TAMAÑO: 15 X 17,5 Cm | F19: UNIDAD | G19: 1 | H19: 1120 | I19: =+G19*H19 -> 1120
A20: 11 | B20: 2.9.5-427.39 | C20: PROD. MEDICO/FARMACEUTICOS/LAB | D20: 252 | E20: APOSITOS; TIPO: HIDROCOLOIDE, TAMAÑO: 10 X 10 Cm | F20: UNIDAD | G20: 1 | H20: 580 | I20: =+G20*H20 -> 580
A21: 12 | B21: 2.5.2-5661.8 | C21: PROD. MEDICO/FARMACEUTICOS/LAB | D21: 252 | E21: REGULADORES HORMONALES; TIPO: MONODROGA, DROGA GENERICA: ATOSIBAN, FORMA FARMACEUTICA: AMPOLLA, PRESENTACION: ENVASE X 5 mL | F21: FRASCO | G21: 1 | H21: 29645 | I21: =+G21*H21 -> 29645
... A33: 24 | B33: 2.5.2-1855.7 | C33: PROD. MEDICO/FARMACEUTICOS/LAB | D33: 252 | E33: CORTICOESTEROIDES; TIPO: MONODROGA, DROGA GENERICA: DEXAMETASONA, FORMA FARMACEUTICA: AMPOLLA, PRESENTACION: 8 mGr | F33: AMPOLLA | G33: 1 | H33: 45 | I33: =+G33*H33 -> 45
A34: 25 | B34: 2.5.2-1855.86 | C34: PROD. MEDICO/FARMACEUTICOS/LAB | D34: 252 | E34: CORTICOESTEROIDES; TIPO: MONODROGA, DROGA GENERICA: DEXAMETASONA, FORMA FARMACEUTICA: COMPRIMIDO, PRESENTACION: 8 mGr | F34: COMPRIMIDO | G34: 1 | H34: 15 | I34: 15
A35: 26 | B35: 2.5.2-2476.74 | C35: PROD. MEDICO/FARMACEUTICOS/LAB | D35: 252 | E35: ANTIALERGICOS-ANTIHISTAMINICOS; TIPO: MONODROGA, DROGA GENERICA: DIFENHIDRAMINA 250 MG, FORMA FARMACEUTICA: JARABE, PRESENTACION: FRASCO X 120 mL | F35: FRASCO | G35: 1 | H35: 199 | I35: =+G35*H35 -> 199
A36: 27 | B36: 2.5.2-2476.36 | C36: PROD. MEDICO/FARMACEUTICOS/LAB | D36: 252 | E36: ANTIALERGICOS-ANTIHISTAMINICOS; TIPO: MONODROGA, DROGA GENERICA: DIFENHIDRAMINA, FORMA FARMACEUTICA: COMPRIMIDO, PRESENTACION: 50 mGr | F36: COMPRIMIDO | G36: 1 | H36: 4.65 | I36: =+G36*H36 -> 4.65
A37: 28 | B37: 2.5.2-2476.44 | C37: PROD. MEDICO/FARMACEUTICOS/LAB | D37: 252 | E37: ANTIALERGICOS-ANTIHISTAMINICOS; TIPO: MONODROGA, DROGA GENERICA: DIFENHIDRAMINA, FORMA FARMACEUTICA: AMPOLLA, PRESENTACION: 10 mGr | F37: AMPOLLA | G37: 1 | H37: 55 | I37: =+G37*H37 -> 55
A38: 29 | B38: 2.5.2-1853.4 | C38: PROD. MEDICO/FARMACEUTICOS/LAB | D38: 252 | E38: OCITOCICOS; TIPO: MONODROGA, DROGA GENERICA: ERGONOVINA, PRESENTACION: 0.2 mGr, FORMA FARMACEUTICA: AMPOLLAS | F38: AMPOLLA | G38: 1 | H38: 41 | I38: =+G38*H38 -> 41
A39: 30 | B39: 2.5.2-1895.32 | C39: PROD. MEDICO/FARMACEUTICOS/LAB | D39: 252 | E39: HORMONAS MEDICINALES; TIPO: MONODROGA, DROGA GENERICA: ESTRADIOL 0.6 MG/GR, FORMA FARMACEUTICA: GEL, PRESENTACION: ENVASE X 80 GR, USO: SEXUAL | F39: ENVASE | G39: 1 | H39: 7556.89 | I39: =+G39*H39 -> 7556.89
A40: 31 | B40: 2.5.2-1851.6 | C40: PROD. MEDICO/FARMACEUTICOS/LAB | D40: 252 | E40: GENITOURINARIO; TIPO: MONODROGA, DROGA GENERICA: FINASTERIDE, FORMA FARMACEUTICA: COMPRIMIDO, PRESENTACION: 5 mGr | F40: COMPRIMIDO | G40: 1 | H40: 18 | I40: =+G40*H40 -> 18
A41: 32 | B41: 2.5.2-1895.8 | C41: PROD. MEDICO/FARMACEUTICOS/LAB | D41: 252 | E41: HORMONAS MEDICINALES; TIPO: MONODROGA, DROGA GENERICA: GONADOTROFINA CORIONICA, FORMA FARMACEUTICA: AMPOLLA, PRESENTACION: 5000 UI, USO: SEXUAL | F41: UNIDAD | G41: 1 | H41: 6450 | I41: =+G41*H41 -> 6450
A42: 33 | B42: 2.5.2-1855.18 | C42: PROD. MEDICO/FARMACEUTICOS/LAB | D42: 252 | E42: CORTICOESTEROIDES; TIPO: MONODROGA, DROGA GENERICA: BETAMETASONA, FORMA FARMACEUTICA: GOTAS, PRESENTACION: 15 mL | F42: UNIDAD | G42: 1 | H42: 340 | I42: =+G42*H42 -> 340
A43: 34 | B43: 2.5.2-2200.6 | C43: PROD. MEDICO/FARMACEUTICOS/LAB | D43: 252 | E43: CORTICOIDES; DROGA GENERICA: HIDROCORTISONA X 1 GR, FORMA FARMACEUTICA: CREMA, PRESENTACION: 15 GR, TIPO: MONODROGA | F43: ENVASE | G43: 1 | H43: 280 | I43: =+G43*H43 -> 280
A44: 35 | B44: 2.5.2-1855.47 | C44: PROD. MEDICO/FARMACEUTICOS/LAB | D44: 252 | E44: CORTICOESTEROIDES; TIPO: MONODROGA, DROGA GENERICA: HIDROCORTISONA, FORMA FARMACEUTICA: AMPOLLA/FRASCO, PRESENTACION: 100 mGr | F44: AMPOLLA | G44: 1 | H44: 120 | I44: =+G44*H44 -> 120
A45: 36 | B45: 2.5.2-1855.77 | C45: PROD. MEDICO/FARMACEUTICOS/LAB | D45: 252 | E45: CORTICOESTEROIDES; TIPO: MONODROGA, DROGA GENERICA: HIDROCORTISONA, FORMA FARMACEUTICA: FRASCO AMPOLLA, PRESENTACION: ENVASE X 500 mGr | F45: AMPOLLA | G45: 1 | H45: 222 | I45: =+G45*H45 -> 222
A46: 37 | B46: 2.5.2-1895.64 | C46: PROD. MEDICO/FARMACEUTICOS/LAB | D46: 252 | E46: HORMONAS MEDICINALES; TIPO: MONODROGA, DROGA GENERICA: FOLICULO ESTIMULANTE, FORMA FARMACEUTICA: AMPOLLA, PRESENTACION: ENVASE X 75 UI, USO: SEXUAL | F46: UNIDAD | G46: 1 | H46: 8594.41 | I46: =+G46*H46 -> 8594.41
... A80: 71 | B80: 2.5.2-2481.3 | C80: PROD. MEDICO/FARMACEUTICOS/LAB | D80: 252 | E80: LAXANTES; TIPO: MONODROGA, DROGA GENERICA: VASELINA, FORMA FARMACEUTICA: SOLIDO, PRESENTACION: 1000 GR | F80: UNIDAD | G80: 1 | H80: 1260 | I80: =+G80*H80 -> 1260
B83: Especificidades:
B85: Ítem 5: VASOPRESINA 20UI AMPOLLA CAJA X 5 UNIDADES TIPO NOVOPRESSINA - V
B87: Lugar de Entrega: …........................... DE XX:00 AXX:00HS., DEBIENDO CORRER LOS GASTOS DE FLETES, ACARREO, CARGA, DESCARGA Y SEGURO A CARGO DEL ADJUDICATARIO.
B88: Plazo de entrega: XXXX
B89: Calidad Minima esperada:
B90: Mantenimiento: 45 dias habiles
B92: Especificidades:
...

Sheet  NotaPedido
A1: NOTA DE PEDIDO | J1: N° | K1: xxx/2022
A3: JURISDICCIÓN: | C3: ='Necesidades Trimestrales'!C4 -> 040 - Ministerio de Salud
A4: SAF: | C4: ='Necesidades Trimestrales'!C5 -> 11/ 23/ 24 o 28- "…......."
A5: UNIDAD EJECUTORA: | C5: XXXX
A6: DEPENDENCIA SOLICITANTE: | C6: XXXX
A7: PERIODO UTILIZACIÓN: | C7: Cuatrimestral
A8: OBJETO: | C8: Adquisición de TERAPIA DERMATOLOGICA/SISTEMA GENITOURINARIO Y HORMONAS SEXUALES /HORMONAS SISTEMICAS /CORTICOIDES SISTEMICOS/RESPIRATORIO/ANTIHISTAMINICOS
A10: Ítem | B10: CODIGO ITEM | C10: DESCRIPCIÓN | H10: Adjunta Detalle Técnico | I10: Unidad Medida | J10: Precio Unitario Estimado | K10: Cantidad Solicitada
A12: 1 | B12: ='Necesidades Trimestrales'!B10 -> 2.5.2-1895.67 | C12: ='Necesidades Trimestrales'!E10 -> HORMONAS MEDICINALES; TIPO: MONODROGA, DROGA GENERICA: VALERATO DE ESTRADIOL, FORMA FARMACEUTICA: COMPRIMIDO 1MGR, PRESENTACION: ENVASE X 28 UN, USO: HORMONOTERAPIA DE REEMPLAZO | H12: NO | I12: ='Necesidades Trimestrales'!F10 -> CAJA | J12: ='Necesidades Trimestrales'!H10 -> 1007.05 | K12: ='Necesidades Trimestrales'!G10 -> 1
A13: 2 | B13: ='Necesidades Trimestrales'!B11 -> 2.5.2-3955.1 | C13: ='Necesidades Trimestrales'!E11 -> ANTIANDROGENOS; TIPO: MONODROGA, DROGA GENERICA: CIPROTERONA, FORMA FARMACEUTICA: COMPRIMIDO, PRESENTACION: 50 mGr | H13: NO | I13: ='Necesidades Trimestrales'!F11 -> COMPRIMIDO | J13: ='Necesidades Trimestrales'!H11 -> 190.52 | K13: =+'Necesidades Trimestrales'!G11 -> 1
A14: 3 | B14: ='Necesidades Trimestrales'!B12 -> 2.5.2-1875.132 | C14: ='Necesidades Trimestrales'!E12 -> ANTIASMATICO BRONCODILATADOR; TIPO: MONODROGA, DROGA GENERICA: N-ACETIL CISTEINA 2 GR, FORMA FARMACEUTICA: JARABE PARA PREPARAR 100 ML, PRESENTACION: UNIDAD | H14: NO | I14: ='Necesidades Trimestrales'!F12 -> FRASCO | J14: ='Necesidades Trimestrales'!H12 -> 1253 | K14: =+'Necesidades Trimestrales'!G12 -> 1
A15: 4 | B15: ='Necesidades Trimestrales'!B13 -> 2.5.2-1875.133 | C15: ='Necesidades Trimestrales'!E13 -> ANTIASMATICO BRONCODILATADOR; TIPO: MONODROGA, DROGA GENERICA: N-ACETIL CISTEINA 600 MGR, FORMA FARMACEUTICA: TABLETA EFERVESCENTE, PRESENTACION: UNIDAD | H15: NO | I15: ='Necesidades Trimestrales'!F13 -> TABLETAS | J15: ='Necesidades Trimestrales'!H13 -> 35.24 | K15: =+'Necesidades Trimestrales'!G13 -> 1
A16: 5 | B16: ='Necesidades Trimestrales'!B14 -> 2.5.2-2198.8 | C16: ='Necesidades Trimestrales'!E14 -> ANTIDIURETICOS; DROGA GENERICA: VASOPRESINA ACUOSA, FORMA FARMACEUTICA: AMPOLLA, PRESENTACION: 1 mL, TIPO: MONODROGA | H16: SI | I16: ='Necesidades Trimestrales'!F14 -> CAJA | J16: ='Necesidades Trimestrales'!H14 -> 775 | K16: =+'Necesidades Trimestrales'!G14 -> 1
A17: 6 | B17: ='Necesidades Trimestrales'!B15 -> 2.5.2-1829.25 | C17: ='Necesidades Trimestrales'!E15 -> ANTIVIRALES; TIPO: MONODROGA, DROGA GENERICA: ACICLOVIR 5 %, FORMA FARMACEUTICA: CREMA, PRESENTACION: ENVASE X 5 GR | H17: NO | I17: ='Necesidades Trimestrales'!F15 -> ENVASE | J17: ='Necesidades Trimestrales'!H15 -> 285 | K17: =+'Necesidades Trimestrales'!G15 -> 1
A18: 7 | B18: ='Necesidades Trimestrales'!B16 -> 2.5.2-1821.189 | C18: ='Necesidades Trimestrales'!E16 -> ANTIBIOTICOS P/PERSONAS; DROGA GENERICA: ACIDO FUSIDICO 20MG, FORMA FARMACEUTICA: CREMA, PRESENTACION: POMO X 15 GR, TIPO: MONODROGA | H18: NO | I18: ='Necesidades Trimestrales'!F16 -> ENVASE | J18: ='Necesidades Trimestrales'!H16 -> 650 | K18: =+'Necesidades Trimestrales'!G16 -> 1
A19: 8 | B19: ='Necesidades Trimestrales'!B17 -> 2.5.2-1726.26 | C19: ='Necesidades Trimestrales'!E17 -> SOLUCIONES P/MEDICINA; TIPO: AGUA DE ALIBOUR, PRESENTACION: 250 CM3 | H19: NO | I19: ='Necesidades Trimestrales'!F17 -> FRASCO | J19: ='Necesidades Trimestrales'!H17 -> 560 | K19: =+'Necesidades Trimestrales'!G17 -> 1
A20: 9 | B20: ='Necesidades Trimestrales'!B18 -> 2.5.2-1875.74 | C20: ='Necesidades Trimestrales'!E18 -> ANTIASMATICO BRONCODILATADOR; TIPO: MONODROGA, DROGA GENERICA: AMINOFILINA 240MGR, FORMA FARMACEUTICA: AMPOLLA, PRESENTACION: ENVASE X 10 ML | H20: NO | I20: ='Necesidades Trimestrales'!F18 -> AMPOLLA | J20: ='Necesidades Trimestrales'!H18 -> 86 | K20: =+'Necesidades Trimestrales'!G18 -> 1
A21: 10 | B21: ='Necesidades Trimestrales'!B19 -> 2.9.5-427.33 | C21: ='Necesidades Trimestrales'!E19 -> APOSITOS; TIPO: HIDROCOLOIDE, TAMAÑO: 15 X 17,5 Cm | H21: NO | I21: ='Necesidades Trimestrales'!F19 -> UNIDAD | J21: ='Necesidades Trimestrales'!H19 -> 1120 | K21: =+'Necesidades Trimestrales'!G19 -> 1
A22: 11 | B22: ='Necesidades Trimestrales'!B20 -> 2.9.5-427.39 | C22: ='Necesidades Trimestrales'!E20 -> APOSITOS; TIPO: HIDROCOLOIDE, TAMAÑO: 10 X 10 Cm | H22: NO | I22: ='Necesidades Trimestrales'!F20 -> UNIDAD | J22: ='Necesidades Trimestrales'!H20 -> 580 | K22: =+'Necesidades Trimestrales'!G20 -> 1
A23: 12 | B23: ='Necesidades Trimestrales'!B21 -> 2.5.2-5661.8 | C23: ='Necesidades Trimestrales'!E21 -> REGULADORES HORMONALES; TIPO: MONODROGA, DROGA GENERICA: ATOSIBAN, FORMA FARMACEUTICA: AMPOLLA, PRESENTACION: ENVASE X 5 mL | H23: NO | I23: ='Necesidades Trimestrales'!F21 -> FRASCO | J23: ='Necesidades Trimestrales'!H21 -> 29645 | K23: =+'Necesidades Trimestrales'!G21 -> 1
A24: 13 | B24: ='Necesidades Trimestrales'!B22 -> 2.5.2-5661.11 | C24: ='Necesidades Trimestrales'!E22 -> REGULADORES HORMONALES; TIPO: MONODROGA, DROGA GENERICA: ATOSIBAN, FORMA FARMACEUTICA: AMPOLLA, PRESENTACION: ENVASE X 0,9 mL | H24: NO | I24: ='Necesidades Trimestrales'!F22 -> FRASCO | J24: ='Necesidades Trimestrales'!H22 -> 18320 | K24: =+'Necesidades Trimestrales'!G22 -> 1
... A82: 71 | B82: ='Necesidades Trimestrales'!B80 -> 2.5.2-2481.3 | C82: ='Necesidades Trimestrales'!E80 -> LAXANTES; TIPO: MONODROGA, DROGA GENERICA: VASELINA, FORMA FARMACEUTICA: SOLIDO, PRESENTACION: 1000 GR | H82: NO | I82: ='Necesidades Trimestrales'!F80 -> UNIDAD | J82: ='Necesidades Trimestrales'!H80 -> 1260 | K82: =+'Necesidades Trimestrales'!G80 -> 1
A83: Costo total estimado: xxxxxxxxxxxxxxxxxxxx con 00/100. | J83: =SUMPRODUCT(J12:J82,K12:K82) -> 174965.95

Sheet Autor Gastar
A1: EJERCICIO: | D1: ='Necesidades Trimestrales'!C6 -> 2022 | P1: AUTORIZACION PARA GASTAR
A4: JURISDICCIÓN: | G4: =' NotaPedido'!C3 -> 040 - Ministerio de Salud
A5: SAF: | G5: =' NotaPedido'!C4 -> 11/ 23/ 24 o 28- "…......."
A6: UNIDAD EJECUTORA: | G6: =' NotaPedido'!C5 -> XXXX
A7: DEPENDENCIA SOLICITANTE: | G7: =' NotaPedido'!C6 -> XXXX
A8: AUTORIZACIÓN:
A9: Señor Jefe de Servicio Administrativo Financiero:
A10: ="Autorizo la realización de los trámites correspondientes, a fin de proveer a este Organismo los bienes y/o servicios que se detallan en Nota de Pedido N° " & ' NotaPedido'!K1&", afectando la erogación resultante a los créditos presupuestarios aprobados a favor de esta Unidad Ejecutora, conforme al siguiente detalle:" -> Autorizo la realización de los trámites correspondientes, a fin de proveer a este Organismo los bienes y/o servicios que se detallan en Nota de Pedido N° xxx/2022, afectando la erogación resultante a los créditos presupuestarios aprobados a favor de esta Unidad Ejecutora, conforme al siguiente detalle:
A12: IMPUTACIÓN PRESUPUESTARIA
A13: CÓDIGO | O13: DENOMINACIÓN DE LA PARTIDA PRESUPUESTARIA | Q13: IMPORTE
A14: PR | B14: SB | C14: PY | D14: AC | E14: OB | F14: UG | G14: FIN | H14: FUN | I14: I | J14: P | K14: P | L14: SubP | M14: M | N14: FF
F15: 4901 | G15: 3 | H15: 310 | I15: 2 | J15: 5 | K15: 2 | M15: 1 | N15: 1.1 | O15: Productos Farmacéuticos y Medicinales | Q15: =+' NotaPedido'!J83 -> 174965.95
A23: TOTAL DE PESOS: xxxxxxxxxxxxxxx con 00/100. | Q23: =SUM(Q15:Q22) -> 174965.95
A25: JUSTIFICACIÓN:
A26: Para la adquisición de .... … destinados al servico de …... del Hospital …...............
