Workbook

Sheet Necesidades Trimestrales
B2: Pedido de Necesidades Trimestrales
A4: JURISDICCION: | C4: 90 - Ministerio de Seguridad
A5: SAF N°: | C5: 7- Dirección Provincial de Administración de la Policía de la Provincia de Catamarca
A6: EJERCICIO: | C6: 2021
A7: TRIMESTRE: | C7: 3
A9: ID | B9: CODIGO ITEM | C9: RUBRO DE COMPRA | D9: I.P.P. | E9: DESCRIPCION | F9: UNIDAD DE MEDIDA | G9: CANTIDAD | H9: PRECIO UNITARIO ESTIMADO | I9: IMPORTE TOTAL ESTIMADO
A10: 1 | B10: 2.9.6-9688.624 | C10: REPUESTOS | D10: 2.9.6 | E10: REP. Y ACC. P/CAMIONETAS; MARCA AUTOMOTOR: SEGÚN PLIEGO, MODELO AUTOMOTOR: SEGÚN PLIEGO, ELEMENTO: KIT DE FILTROS | F10: UNIDAD | G10: 170 | H10: 12343.27 | I10: =G10*H10 -> 2098355.9
A11: 2 | B11: 2.9.6-9688.390 | C11: REPUESTOS | D11: 2.9.6 | E11: REP. Y ACC. P/CAMIONETAS; MARCA AUTOMOTOR: TOYOTA, MODELO AUTOMOTOR: HILUX, ELEMENTO: KIT DE FILTROS | F11: UNIDAD | G11: 200 | H11: 9314 | I11: =G11*H11 -> 1862800
A12: 3 | B12: 2.9.6-9688.386 | C12: REPUESTOS | D12: 2.9.6 | E12: REP. Y ACC. P/CAMIONETAS; MARCA AUTOMOTOR: CHEVROLET, MODELO AUTOMOTOR: S10, ELEMENTO: KIT DE FILTROS | F12: UNIDAD | G12: 70 | H12: 7990 | I12: =G12*H12 -> 559300
A13: 4 | B13: 2.9.6-9688.521 | C13: REPUESTOS | D13: 2.9.6 | E13: REP. Y ACC. P/CAMIONETAS; MARCA AUTOMOTOR: VOLKSWAGEN, MODELO AUTOMOTOR: AMAROK, ELEMENTO: AMORTIGUADOR | F13: UNIDAD | G13: 10 | H13: 24900 | I13: =G13*H13 -> 249000
A14: 5 | B14: 2.9.6-9688.521 | C14: REPUESTOS | D14: 2.9.6 | E14: REP. Y ACC. P/CAMIONETAS; MARCA AUTOMOTOR: VOLKSWAGEN, MODELO AUTOMOTOR: AMAROK, ELEMENTO: AMORTIGUADOR | F14: UNIDAD | G14: 10 | H14: 10896 | I14: =G14*H14 -> 108960
A15: 6 | B15: 2.9.6-9688.376 | C15: REPUESTOS | D15: 2.9.6 | E15: REP. Y ACC. P/CAMIONETAS; MARCA AUTOMOTOR: TOYOTA, MODELO AUTOMOTOR: HILUX, ELEMENTO: AMORTIGUADOR DELANTERO | F15: UNIDAD | G15: 10 | H15: 15998 | I15: =G15*H15 -> 159980
A16: 7 | B16: 2.9.6-9688.377 | C16: REPUESTOS | D16: 2.9.6 | E16: REP. Y ACC. P/CAMIONETAS; MARCA AUTOMOTOR: TOYOTA, MODELO AUTOMOTOR: HILUX, ELEMENTO: AMORTIGUADOR TRASERO | F16: UNIDAD | G16: 10 | H16: 9500 | I16: =G16*H16 -> 95000
A17: 8 | B17: 2.9.6-9688.376 | C17: REPUESTOS | D17: 2.9.6 | E17: REP. Y ACC. P/CAMIONETAS; MARCA AUTOMOTOR: TOYOTA, MODELO AUTOMOTOR: HILUX, ELEMENTO: AMORTIGUADOR DELANTERO | F17: UNIDAD | G17: 5 | H17: 15998 | I17: =G17*H17 -> 79990
A18: 9 | B18: 2.9.6-9688.377 | C18: REPUESTOS | D18: 2.9.6 | E18: REP. Y ACC. P/CAMIONETAS; MARCA AUTOMOTOR: TOYOTA, MODELO AUTOMOTOR: HILUX, ELEMENTO: AMORTIGUADOR TRASERO | F18: UNIDAD | G18: 5 | H18: 9500 | I18: =G18*H18 -> 47500
A19: 10 | B19: 2.9.6-9688.534 | C19: REPUESTOS | D19: 2.9.6 | E19: REP. Y ACC. P/CAMIONETAS; MARCA AUTOMOTOR: CHEVROLET, MODELO AUTOMOTOR: S10, ELEMENTO: AMORTIGUADOR DELANTERO | F19: UNIDAD | G19: 10 | H19: 9453 | I19: =G19*H19 -> 94530
A20: 11 | B20: 2.9.6-9688.535 | C20: REPUESTOS | D20: 2.9.6 | E20: REP. Y ACC. P/CAMIONETAS; MARCA AUTOMOTOR: CHEVROLET, MODELO AUTOMOTOR: S10, ELEMENTO: AMORTIGUADOR TRASERO | F20: UNIDAD | G20: 10 | H20: 16736 | I20: =G20*H20 -> 167360
A21: 12 | B21: 2.9.6-9688.534 | C21: REPUESTOS | D21: 2.9.6 | E21: REP. Y ACC. P/CAMIONETAS; MARCA AUTOMOTOR: CHEVROLET, MODELO AUTOMOTOR: S10, ELEMENTO: AMORTIGUADOR DELANTERO | F21: UNIDAD | G21: 10 | H21: 9453 | I21: =G21*H21 -> 94530
... A118: 109 | B118: 2.9.6-3997.546 | C118: REPUESTOS | D118: 2.9.6. | E118: REP. Y ACC. P/MOTOS; REPUESTO: KIT EMBRAGUE, USO: HONDA, MODELO MOTO: XR 250 TORNADO | F118: UNIDAD | G118: 30 | H118: 7655 | I118: =G118*H118 -> 229650
I119: =SUM(I10:I118) -> 23482274
B121: Especificidades
B122: Item N° : 01
C123: Descripción técnica | D123: MARCA VOLKSWAGEN. MODELO: AMAROK 4x2, AÑO: 2015, ELEMENTO: KIT DE FILTROS PARA SERVIS Incluye filtro de aire, filtro de aceite, filtro de aire acondicionado, filtro de combustible
B125: Item N° : 02
C126: Descripción técnica | D126: MARCA TOYOTA. MODELO: HILUX 4X2, AÑO: 2015 ELEMENTO: KIT DE FILTROS PARA SERVIS Incluye filtro de aire, filtro de aceite, filtro de aire acondicionado,
F127: filtro decombustible
B128: Item N° : 03
C129: Descripción técnica | D129: MARCA CHEVROLET MODELO: S-10 4X2 AÑO: 2019, ELEMENTO: KIT DE FILTROS PARA SERVIS Incluye filtro de aire, filtro de aceite, filtro de aire acondicionado, filtro de combustible
B131: Item N° : 04
C132: Descripción técnica | D132: MARCA VOLKSWAGEN. MODELO: AMAROK 4X2 AÑO: 2015 ELEMENTO: JUEGO AMORTIGUADORES DELANTEROS (incluye 2: 1 Derecho y 1 Izquierdo)
B133: Item N° : 05
C134: Descripción técnica | D134: MARCA VOLKSWAGEN. MODELO: AMAROK 4X2 AÑO: 2015, ELEMENTO: JUEGO AMORTIGUADORES TRASEROS (incluye 2: 1 Derecho y 1 Izquierdo)
B136: Item N° : 06
C137: Descripción técnica | D137: MARCA TOYOTA MODELO: HILUX 4X2 AÑO: 2015 ELEMENTO: JUEGO AMORTIGUADORES DELANTEROS (incluye 2: 1 Derecho y 1 Izquierdo)
B139: Item N° : 07
C140: Descripción técnica | D140: MARCA TOYOTA MODELO: HILUX 4X2 AÑO: 2015 ELEMENTO: JUEGO AMORTIGUADORES TRASEROS (incluye 2: 1 Derecho y 1 Izquierdo)
B142: Item N° : 08
C143: Descripción técnica | D143: MARCA TOYOTA MODELO: HILUX 4X4 AÑO: 2012 ELEMENTO: JUEGO AMORTIGUADORES DELANTEROS (incluye 2: 1 Derecho y 1 Izquierdo)
B145: Item N° : 09
C146: Descripción técnica | D146: MARCA TOYOTA MODELO: HILUX 4X4, AÑO: 2012 ELEMENTO: JUEGO AMORTIGUADORES TRASEROS (incluye 2: 1 Derecho y 1 Izquierdo)
...

Sheet NOTA
A1: ACLARACIÒN PARA ITEMS, 99, 100, 101, 102 Y 105: DICHOS REPUESTOS DEBEN SER COMPATIBLES CON LOS SIGUIENES MODELOS DE MOTOS MARCA HONDA: XR 150 CC, XR 250 CC TORNADO Y CBX 250 CC TWISTER.

Sheet  NotaPedido
A1: NOTA DE PEDIDO | J1: N° | K1: 57/2021
A3: JURISDICCIÓN: | D3: ='Necesidades Trimestrales'!C4 -> 90 - Ministerio de Seguridad
A4: SAF: | D4: ='Necesidades Trimestrales'!C5 -> 7- Dirección Provincial de Administración de la Policía de la Provincia de Catamarca
A5: UNIDAD EJECUTORA: | D5: Jefatura de Policía de la Provincia de Catamarca
A6: DEPENDENCIA SOLICITANTE: | D6: División Transporte (D-4)
A7: PERIODO UTILIZACIÓN: | D7: ='Necesidades Trimestrales'!C7 & "° Trimestre - Año " & 'Necesidades Trimestrales'!C6 -> 3° Trimestre - Año 2021
A8: OBJETO: | D8: Adquisición de Repuestos de Automotor destinados a División Transporte (D-4)- Policia de Catamarca
A10: Ítem | B10: Codigo Item | C10: DESCRIPCIÓN | H10: Adjunta Detalle Técnico | I10: Unidad Medida | J10: Precio Unitario Estimado | K10: Cantidad Solicitada
A12: ='Necesidades Trimestrales'!A10 -> 1 | B12: ='Necesidades Trimestrales'!B10 -> 2.9.6-9688.624 | C12: ='Necesidades Trimestrales'!E10 -> REP. Y ACC. P/CAMIONETAS; MARCA AUTOMOTOR: SEGÚN PLIEGO, MODELO AUTOMOTOR: SEGÚN PLIEGO, ELEMENTO: KIT DE FILTROS | H12: SI | I12: ='Necesidades Trimestrales'!F10 -> UNIDAD | J12: ='Necesidades Trimestrales'!H10 -> 12343.27 | K12: ='Necesidades Trimestrales'!G10 -> 170
A13: 2 | B13: ='Necesidades Trimestrales'!B11 -> 2.9.6-9688.390 | C13: ='Necesidades Trimestrales'!E11 -> REP. Y ACC. P/CAMIONETAS; MARCA AUTOMOTOR: TOYOTA, MODELO AUTOMOTOR: HILUX, ELEMENTO: KIT DE FILTROS | H13: SI | I13: ='Necesidades Trimestrales'!F11 -> UNIDAD | J13: ='Necesidades Trimestrales'!H11 -> 9314 | K13: ='Necesidades Trimestrales'!G11 -> 200
A14: 3 | B14: ='Necesidades Trimestrales'!B12 -> 2.9.6-9688.386 | C14: ='Necesidades Trimestrales'!E12 -> REP. Y ACC. P/CAMIONETAS; MARCA AUTOMOTOR: CHEVROLET, MODELO AUTOMOTOR: S10, ELEMENTO: KIT DE FILTROS | H14: SI | I14: ='Necesidades Trimestrales'!F12 -> UNIDAD | J14: ='Necesidades Trimestrales'!H12 -> 7990 | K14: ='Necesidades Trimestrales'!G12 -> 70
A15: 4 | B15: ='Necesidades Trimestrales'!B13 -> 2.9.6-9688.521 | C15: ='Necesidades Trimestrales'!E13 -> REP. Y ACC. P/CAMIONETAS; MARCA AUTOMOTOR: VOLKSWAGEN, MODELO AUTOMOTOR: AMAROK, ELEMENTO: AMORTIGUADOR | H15: SI | I15: ='Necesidades Trimestrales'!F13 -> UNIDAD | J15: ='Necesidades Trimestrales'!H13 -> 24900 | K15: ='Necesidades Trimestrales'!G13 -> 10
A16: 5 | B16: ='Necesidades Trimestrales'!B14 -> 2.9.6-9688.521 | C16: ='Necesidades Trimestrales'!E14 -> REP. Y ACC. P/CAMIONETAS; MARCA AUTOMOTOR: VOLKSWAGEN, MODELO AUTOMOTOR: AMAROK, ELEMENTO: AMORTIGUADOR | H16: SI | I16: ='Necesidades Trimestrales'!F14 -> UNIDAD | J16: ='Necesidades Trimestrales'!H14 -> 10896 | K16: ='Necesidades Trimestrales'!G14 -> 10
A17: 6 | B17: ='Necesidades Trimestrales'!B15 -> 2.9.6-9688.376 | C17: ='Necesidades Trimestrales'!E15 -> REP. Y ACC. P/CAMIONETAS; MARCA AUTOMOTOR: TOYOTA, MODELO AUTOMOTOR: HILUX, ELEMENTO: AMORTIGUADOR DELANTERO | H17: SI | I17: ='Necesidades Trimestrales'!F15 -> UNIDAD | J17: ='Necesidades Trimestrales'!H15 -> 15998 | K17: ='Necesidades Trimestrales'!G15 -> 10
A18: 7 | B18: ='Necesidades Trimestrales'!B16 -> 2.9.6-9688.377 | C18: ='Necesidades Trimestrales'!E16 -> REP. Y ACC. P/CAMIONETAS; MARCA AUTOMOTOR: TOYOTA, MODELO AUTOMOTOR: HILUX, ELEMENTO: AMORTIGUADOR TRASERO | H18: SI | I18: ='Necesidades Trimestrales'!F16 -> UNIDAD | J18: ='Necesidades Trimestrales'!H16 -> 9500 | K18: ='Necesidades Trimestrales'!G16 -> 10
A19: 8 | B19: ='Necesidades Trimestrales'!B17 -> 2.9.6-9688.376 | C19: ='Necesidades Trimestrales'!E17 -> REP. Y ACC. P/CAMIONETAS; MARCA AUTOMOTOR: TOYOTA, MODELO AUTOMOTOR: HILUX, ELEMENTO: AMORTIGUADOR DELANTERO | H19: SI | I19: ='Necesidades Trimestrales'!F17 -> UNIDAD | J19: ='Necesidades Trimestrales'!H17 -> 15998 | K19: ='Necesidades Trimestrales'!G17 -> 5
A20: 9 | B20: ='Necesidades Trimestrales'!B18 -> 2.9.6-9688.377 | C20: ='Necesidades Trimestrales'!E18 -> REP. Y ACC. P/CAMIONETAS; MARCA AUTOMOTOR: TOYOTA, MODELO AUTOMOTOR: HILUX, ELEMENTO: AMORTIGUADOR TRASERO | H20: SI | I20: ='Necesidades Trimestrales'!F18 -> UNIDAD | J20: ='Necesidades Trimestrales'!H18 -> 9500 | K20: ='Necesidades Trimestrales'!G18 -> 5
A21: 10 | B21: ='Necesidades Trimestrales'!B19 -> 2.9.6-9688.534 | C21: ='Necesidades Trimestrales'!E19 -> REP. Y ACC. P/CAMIONETAS; MARCA AUTOMOTOR: CHEVROLET, MODELO AUTOMOTOR: S10, ELEMENTO: AMORTIGUADOR DELANTERO | H21: SI | I21: ='Necesidades Trimestrales'!F19 -> UNIDAD | J21: ='Necesidades Trimestrales'!H19 -> 9453 | K21: ='Necesidades Trimestrales'!G19 -> 10
A22: 11 | B22: ='Necesidades Trimestrales'!B20 -> 2.9.6-9688.535 | C22: ='Necesidades Trimestrales'!E20 -> REP. Y ACC. P/CAMIONETAS; MARCA AUTOMOTOR: CHEVROLET, MODELO AUTOMOTOR: S10, ELEMENTO: AMORTIGUADOR TRASERO | H22: SI | I22: ='Necesidades Trimestrales'!F20 -> UNIDAD | J22: ='Necesidades Trimestrales'!H20 -> 16736 | K22: ='Necesidades Trimestrales'!G20 -> 10
A23: 12 | B23: ='Necesidades Trimestrales'!B21 -> 2.9.6-9688.534 | C23: ='Necesidades Trimestrales'!E21 -> REP. Y ACC. P/CAMIONETAS; MARCA AUTOMOTOR: CHEVROLET, MODELO AUTOMOTOR: S10, ELEMENTO: AMORTIGUADOR DELANTERO | H23: SI | I23: ='Necesidades Trimestrales'!F21 -> UNIDAD | J23: ='Necesidades Trimestrales'!H21 -> 9453 | K23: ='Necesidades Trimestrales'!G21 -> 10
A24: 13 | B24: ='Necesidades Trimestrales'!B22 -> 2.9.6-9688.535 | C24: ='Necesidades Trimestrales'!E22 -> REP. Y ACC. P/CAMIONETAS; MARCA AUTOMOTOR: CHEVROLET, MODELO AUTOMOTOR: S10, ELEMENTO: AMORTIGUADOR TRASERO | H24: SI | I24: ='Necesidades Trimestrales'!F22 -> UNIDAD | J24: ='Necesidades Trimestrales'!H22 -> 16736 | K24: ='Necesidades Trimestrales'!G22 -> 10
... A120: 109 | B120: ='Necesidades Trimestrales'!B118 -> 2.9.6-3997.546 | C120: ='Necesidades Trimestrales'!E118 -> REP. Y ACC. P/MOTOS; REPUESTO: KIT EMBRAGUE, USO: HONDA, MODELO MOTO: XR 250 TORNADO | H120: SI | I120: ='Necesidades Trimestrales'!F118 -> UNIDAD | J120: ='Necesidades Trimestrales'!H118 -> 7655 | K120: ='Necesidades Trimestrales'!G118 -> 30
A121: Costo total estimado: Pesos Veintitres millones doscientos cincuenta y cinco mil cuatrocientos cuarenta y ocho con 90/100 | J121: =SUMPRODUCT(J12:J120,K12:K120) -> 23482274

Sheet Autor Gastar
A1: EJERCICIO: | D1: ='Necesidades Trimestrales'!C6 -> 2021 | P1: AUTORIZACION PARA GASTAR
A4: JURISDICCIÓN: | G4: =' NotaPedido'!D3 -> 90 - Ministerio de Seguridad
A5: SAF: | G5: =' NotaPedido'!D4 -> 7- Dirección Provincial de Administración de la Policía de la Provincia de Catamarca
A6: UNIDAD EJECUTORA: | G6: =' NotaPedido'!D5 -> Jefatura de Policía de la Provincia de Catamarca
A7: DEPENDENCIA SOLICITANTE: | G7: =' NotaPedido'!D6 -> División Transporte (D-4)
A8: AUTORIZACIÓN:
A9: Señor Jefe de Servicio Administrativo Financiero:
A10: ="Autorizo la realización de los trámites correspondientes, a fin de proveer a este Organismo los bienes y/o servicios que se detallan en Nota de Pedido N° " & ' NotaPedido'!K1&", afectando la erogación resultante a los créditos presupuestarios aprobados a favor de esta Unidad Ejecutora, conforme al siguiente detalle:" -> Autorizo la realización de los trámites correspondientes, a fin de proveer a este Organismo los bienes y/o servicios que se detallan en Nota de Pedido N° 57/2021, afectando la erogación resultante a los créditos presupuestarios aprobados a favor de esta Unidad Ejecutora, conforme al siguiente detalle:
A12: IMPUTACIÓN PRESUPUESTARIA
A13: CÓDIGO | O13: DENOMINACIÓN DE LA PARTIDA PRESUPUESTARIA | Q13: IMPORTE
A14: PR | B14: SB | C14: PY | D14: AC | E14: OB | F14: UG | G14: FIN | H14: FUN | I14: I | J14: P | K14: P | L14: SubP | M14: M | N14: FF
A15: 16 | B15: 0 | C15: 0 | D15: 1 | E15: 0 | F15: 10 | G15: 2 | H15: 1 | I15: 2 | J15: 9 | K15: 6 | L15: 0 | M15: 1 | N15: 1.1 | O15: REPUESTOS Y ACCESORIOS | Q15: 4200000
A16: 16 | B16: 0 | C16: 0 | D16: 7 | E16: 0 | F16: 10 | G16: 2 | H16: 1 | I16: 2 | J16: 9 | K16: 6 | L16: 0 | M16: 1 | N16: 1.1 | O16: REPUESTOS Y ACCESORIOS | Q16: 19055449
A17: TOTAL DE PESOS: Pesos Veintitres millones doscientos cincuenta y cinco mil cuatrocientos cuarenta y ocho con 90/100 | Q17: =SUM(Q15:Q16) -> 23255449
A19: JUSTIFICACIÓN:
A20: =' NotaPedido'!D8 -> Adquisición de Repuestos de Automotor destinados a División Transporte (D-4)- Policia de Catamarca
