Workbook

Sheet Necesidades Trimestrales
B2: Pedido de Necesidades Trimestrales
A4: JURISDICCION: | C4: 40 - Ministerio de Salud
A5: SAF N°: | C5: 23 - Hospital Interzonal San Juan Bautista
A6: EJERCICIO: | C6: 2022
A7: TRIMESTRE: | C7: 2
A9: ID | B9: CODIGO ITEM | C9: RUBRO DE COMPRA | D9: I.P.P. | E9: DESCRIPCION | F9: UNIDAD DE MEDIDA | G9: CANTIDAD | H9: PRECIO UNITARIO ESTIMADO | I9: IMPORTE TOTAL ESTIMADO
A10: 1 | B10: 2.1.1-439.60 | C10: ALIMENTOS | D10: =LEFT(B10,5) -> 2.1.1 | E10: ACEITES COMESTIBLES; TIPO: MEZCLA, PRESENTACION: ENVASE X 900 CM3, MATERIAL ENVASE: PLASTICO 1 (PET), ELEM. TRANSPORTE: SIN, MATERIAL ELEM. TRANSPORTE : SIN, LIBRE DE GLUTEN: SI | F10: UNIDAD | G10: 800 | H10: 275 | I10: =G10*H10 -> 220000
A11: 2 | B11: 2.1.1-435.38 | C11: ALIMENTOS | D11: =LEFT(B11,5) -> 2.1.1 | E11: ARROZ; TIPO GRANO: DOBLE, TIPO: BLANCO, PROCESO: PARBOLIZADO, PRESENTACION: ENVASE X 1 Kg, MATERIAL ENVASE: CARTON, CERTIFICADO FORESTAL (GFS): SIN, ELEM. TRANSPORTE: SIN, MATERIAL ELEM. TRANSPORTE: SIN | F11: UNIDAD | G11: 500 | H11: 233.5 | I11: =G11*H11 -> 116750
A12: 3 | B12: 2.1.1-435.50 | C12: ALIMENTOS | D12: =LEFT(B12,5) -> 2.1.1 | E12: ARROZ; TIPO GRANO: ENTERO, TIPO: BLANCO, PROCESO: FORTIFICADO, PRESENTACION: ENVASE X 1 Kg, MATERIAL ENVASE: PLASTICO 1 (PET), CERTIFICADO FORESTAL (GFS): SIN, ELEM. TRANSPORTE: SIN, MATERIAL ELEM. TRANSPORTE: SIN, LIBRE DE GLUTEN: NO | F12: UNIDAD | G12: 50 | H12: 130 | I12: =G12*H12 -> 6500
A13: 4 | B13: 2.1.1-2124.3 | C13: ALIMENTOS | D13: =LEFT(B13,5) -> 2.1.1 | E13: AVENAS; TIPO: ARROLLADA, ESTADO: NATURAL, PRESENTACION: BOLSA, PESO: 1 Kg | F13: UNIDAD | G13: 15 | H13: 338 | I13: =G13*H13 -> 5070
A14: 5 | B14: 2.1.1-481.38 | C14: ALIMENTOS | D14: =LEFT(B14,5) -> 2.1.1 | E14: AZUCARES; TIPO: "A" COMUN, ESTADO: MOLIDA, PESO: 1 Kg, MATERIAL ENVASE: PLASTICO, CERTIFICADO FORESTAL (GFS): SIN, ELEM. TRANSPORTE: SIN, MATERIAL ELEM. TRANSPORTE: SIN | F14: UNIDAD | G14: 1200 | H14: 87 | I14: =G14*H14 -> 104400
A15: 6 | B15: 2.1.1-5917.8 | C15: ALIMENTOS | D15: =LEFT(B15,5) -> 2.1.1 | E15: CEREALES; TIPO: TRIGO BURGOL, PRESENTACION: ENVASE X 1 Kg | F15: UNIDAD | G15: 15 | H15: 260 | I15: =G15*H15 -> 3900
A16: 7 | B16: 2.1.1-597.41 | C16: ALIMENTOS | D16: =LEFT(B16,5) -> 2.1.1 | E16: CONSERVAS DE FRUTAS; VARIEDAD: COCTEL, ENVASE: LATA, PESO: 800 GR, ELEM. TRANSPORTE: SIN, MATERIAL ELEM. TRANSPORTE: SIN, LIBRE DE GLUTEN: NO | F16: UNIDAD | G16: 300 | H16: 422 | I16: =G16*H16 -> 126600
A17: 8 | B17: 2.1.1-597.43 | C17: ALIMENTOS | D17: =LEFT(B17,5) -> 2.1.1 | E17: CONSERVAS DE FRUTAS; VARIEDAD: COCTEL, ENVASE: LATA, PESO: 820 GR, ELEM. TRANSPORTE: SIN, MATERIAL ELEM. TRANSPORTE: SIN, LIBRE DE GLUTEN: SI | F17: UNIDAD | G17: 300 | H17: 422 | I17: =G17*H17 -> 126600
A18: 9 | B18: 2.1.1-708.43 | C18: ALIMENTOS | D18: =LEFT(B18,5) -> 2.1.1 | E18: CONSERVAS PESCADO Y FRUTOS MAR; TIPO: ATUN, ESTADO: AL NATURAL, PESO: 170 GR, ENVASE: LATA, ELEM. TRANSPORTE: SIN, MATERIAL ELEM. TRANSPORTE: SIN | F18: UNIDAD | G18: 150 | H18: 140.9 | I18: =G18*H18 -> 21135
A19: 10 | B19: 2.1.1-455.16 | C19: ALIMENTOS | D19: =LEFT(B19,5) -> 2.1.1 | E19: DULCE DE LECHE; ENVASE: DE CARTON, CAPACIDAD: 5000 GR, TIPO: DE REPOSTERIA, PRESENTACION: ENVASE DE CARTON X 5 Kg | F19: UNIDAD | G19: 5 | H19: 1990 | I19: =G19*H19 -> 9950
A20: 11 | B20: 2.1.1-2113.21 | C20: ALIMENTOS | D20: =LEFT(B20,5) -> 2.1.1 | E20: DULCES; TIPO: BATATA A LA VAINILLA, PRESENTACION: LATA, PESO: 5 Kg | F20: UNIDAD | G20: 20 | H20: 1485 | I20: =G20*H20 -> 29700
A21: 12 | B21: 2.1.1-2113.2 | C21: ALIMENTOS | D21: =LEFT(B21,5) -> 2.1.1 | E21: DULCES; TIPO: DE MEMBRILLO, PRESENTACION: LATA, PESO: 5 Kg | F21: UNIDAD | G21: 20 | H21: 1716 | I21: =G21*H21 -> 34320
... A69: 60 | B69: 2.1.1-454.25 | C69: ALIMENTOS | D69: =LEFT(B69,5) -> 2.1.1 | E69: YERBAS; PALO: CON, PESO: 1 Kg, MATERIAL ENVASE : PAPEL, CERTIFICADO FORESTAL (GFS): CON, ELEM. TRANSPORTE: SIN, MATERIAL ELEM. TRANSPORTE: SIN, LIBRE DE GLUTEN: SI | F69: UNIDAD | G69: 10 | H69: 449 | I69: =G69*H69 -> 4490
I70: =SUM(I10:I69) -> 2039486
B71: PLAZO DE ENTREGA: 10 DIAS HABILES - LUGAR DE ENTREGA: SERVICIO DE NUTRICION - HOSPITAL INTERZONAL SAN JUAN BAUTISTA - AV. ILLIA ESQ. MARIANO MORENO - DE LUNES A VIERNES DE 08:00 HORAS A 11:00 HORAS.
B72: “Todos los productos deberán presentar en el envase el rótulo bien legible y responder a toda la información establecida en el Código Alimentario Argentino – Cap. V: “Normas para la Rotulación y Publicidad de Alimentos”. ANEXO Reglamento Técnico MERCOSUR para la rotulación de Alimentos Envasados – Inciso 5: Información Obligatoria: Denominación de venta del alimento; Lista de ingredientes; Contenidos netos; Identificación del origen; Nombre o razón social y dirección del importador, para alimentos importados; Identificación del lote; Fecha de duración mínima; Instrucción de uso del alimento, cuando corresponda. La fecha de vencimiento de los productos adjudicados debe ser mayor a 6 (seis) meses al momento de ser bajada en el lugar de entrega y responder a las marcas y características presentadas en la oferta de la presente contratación. Además, debe presentarse el envase en óptimas condiciones de higiene e integridad del mismo.
B73: MANTENIMIENTO DE OFERTA: 45 DIAS HABILES
B76: Especificidades Item N° 06
B78: Descripción técnica
C79: TRIGO BURGOL FINO
B80: Plazos y lugares de entrega
C81: 10 DIAS HABILES - LUGAR DE ENTREGA: SERVICIO DE NUTRICION - HOSPITAL INTERZONAL SAN JUAN BAUTISTA - AV. ILLIA ESQ. MARIANO MORENO - DE LUNES A VIERNES DE 08:00 HORAS A 11:00 HORAS
B83: Calidad Minima esperada
B85: Mantenimiento
C86: 45 dias habiles
B87: Garantia
B92: Especificidades Item N° 50
B94: Descripción técnica
C95: SAL DE MESA TIPO COMUN
B96: Plazos y lugares de entrega
C97: 10 DIAS HABILES - LUGAR DE ENTREGA: SERVICIO DE NUTRICION - HOSPITAL INTERZONAL SAN JUAN BAUTISTA - AV. ILLIA ESQ. MARIANO MORENO - DE LUNES A VIERNES DE 08:00 HORAS A 11:00 HORAS
B99: Calidad Minima esperada
B101: Mantenimiento
C102: 45 dias habiles
...

Sheet NotaPedido
A1: NOTA DE PEDIDO | J1: N° | K1: 042 - 2022
A3: JURISDICCIÓN: | D3: ='Necesidades Trimestrales'!C4 -> 40 - Ministerio de Salud
A4: SAF: | D4: ='Necesidades Trimestrales'!C5 -> 23 - Hospital Interzonal San Juan Bautista
A5: UNIDAD EJECUTORA: | D5: 168 - Direccion Asistencial
A6: DEPENDENCIA SOLICITANTE: | D6: Servicio de Nutricion
A7: PERIODO UTILIZACIÓN: | D7: 2° TRIMESTRE - AÑO 2022
A8: OBJETO: | D8: Adquisición de Alimentos no perecederos
A10: Ítem | B10: Codigo Item | C10: DESCRIPCIÓN | H10: Adjunta Detalle Técnico | I10: Unidad Medida | J10: Precio Unitario Estimado | K10: Cantidad Solicitada
A12: 1 | B12: ='Necesidades Trimestrales'!B10 -> 2.1.1-439.60 | C12: ='Necesidades Trimestrales'!E10 -> ACEITES COMESTIBLES; TIPO: MEZCLA, PRESENTACION: ENVASE X 900 CM3, MATERIAL ENVASE: PLASTICO 1 (PET), ELEM. TRANSPORTE: SIN, MATERIAL ELEM. TRANSPORTE : SIN, LIBRE DE GLUTEN: SI | H12: NO | I12: ='Necesidades Trimestrales'!F10 -> UNIDAD | J12: 275 | K12: 800
A13: 2 | B13: ='Necesidades Trimestrales'!B11 -> 2.1.1-435.38 | C13: ='Necesidades Trimestrales'!E11 -> ARROZ; TIPO GRANO: DOBLE, TIPO: BLANCO, PROCESO: PARBOLIZADO, PRESENTACION: ENVASE X 1 Kg, MATERIAL ENVASE: CARTON, CERTIFICADO FORESTAL (GFS): SIN, ELEM. TRANSPORTE: SIN, MATERIAL ELEM. TRANSPORTE: SIN | H13: NO | I13: ='Necesidades Trimestrales'!F11 -> UNIDAD | J13: 233.5 | K13: 500
A14: 3 | B14: ='Necesidades Trimestrales'!B12 -> 2.1.1-435.50 | C14: ='Necesidades Trimestrales'!E12 -> ARROZ; TIPO GRANO: ENTERO, TIPO: BLANCO, PROCESO: FORTIFICADO, PRESENTACION: ENVASE X 1 Kg, MATERIAL ENVASE: PLASTICO 1 (PET), CERTIFICADO FORESTAL (GFS): SIN, ELEM. TRANSPORTE: SIN, MATERIAL ELEM. TRANSPORTE: SIN, LIBRE DE GLUTEN: NO | H14: NO | I14: ='Necesidades Trimestrales'!F12 -> UNIDAD | J14: 130 | K14: 50
A15: 4 | B15: ='Necesidades Trimestrales'!B13 -> 2.1.1-2124.3 | C15: ='Necesidades Trimestrales'!E13 -> AVENAS; TIPO: ARROLLADA, ESTADO: NATURAL, PRESENTACION: BOLSA, PESO: 1 Kg | H15: NO | I15: ='Necesidades Trimestrales'!F13 -> UNIDAD | J15: 338 | K15: 15
A16: 5 | B16: ='Necesidades Trimestrales'!B14 -> 2.1.1-481.38 | C16: ='Necesidades Trimestrales'!E14 -> AZUCARES; TIPO: "A" COMUN, ESTADO: MOLIDA, PESO: 1 Kg, MATERIAL ENVASE: PLASTICO, CERTIFICADO FORESTAL (GFS): SIN, ELEM. TRANSPORTE: SIN, MATERIAL ELEM. TRANSPORTE: SIN | H16: NO | I16: ='Necesidades Trimestrales'!F14 -> UNIDAD | J16: 87 | K16: 1200
A17: 6 | B17: ='Necesidades Trimestrales'!B15 -> 2.1.1-5917.8 | C17: ='Necesidades Trimestrales'!E15 -> CEREALES; TIPO: TRIGO BURGOL, PRESENTACION: ENVASE X 1 Kg | H17: NO | I17: ='Necesidades Trimestrales'!F15 -> UNIDAD | J17: 260 | K17: 15
A18: 7 | B18: ='Necesidades Trimestrales'!B16 -> 2.1.1-597.41 | C18: ='Necesidades Trimestrales'!E16 -> CONSERVAS DE FRUTAS; VARIEDAD: COCTEL, ENVASE: LATA, PESO: 800 GR, ELEM. TRANSPORTE: SIN, MATERIAL ELEM. TRANSPORTE: SIN, LIBRE DE GLUTEN: NO | H18: NO | I18: ='Necesidades Trimestrales'!F16 -> UNIDAD | J18: 422 | K18: 300
A19: 8 | B19: ='Necesidades Trimestrales'!B17 -> 2.1.1-597.43 | C19: ='Necesidades Trimestrales'!E17 -> CONSERVAS DE FRUTAS; VARIEDAD: COCTEL, ENVASE: LATA, PESO: 820 GR, ELEM. TRANSPORTE: SIN, MATERIAL ELEM. TRANSPORTE: SIN, LIBRE DE GLUTEN: SI | H19: NO | I19: ='Necesidades Trimestrales'!F17 -> UNIDAD | J19: 422 | K19: 300
A20: 9 | B20: ='Necesidades Trimestrales'!B18 -> 2.1.1-708.43 | C20: ='Necesidades Trimestrales'!E18 -> CONSERVAS PESCADO Y FRUTOS MAR; TIPO: ATUN, ESTADO: AL NATURAL, PESO: 170 GR, ENVASE: LATA, ELEM. TRANSPORTE: SIN, MATERIAL ELEM. TRANSPORTE: SIN | H20: NO | I20: ='Necesidades Trimestrales'!F18 -> UNIDAD | J20: 140.9 | K20: 150
A21: 10 | B21: ='Necesidades Trimestrales'!B19 -> 2.1.1-455.16 | C21: ='Necesidades Trimestrales'!E19 -> DULCE DE LECHE; ENVASE: DE CARTON, CAPACIDAD: 5000 GR, TIPO: DE REPOSTERIA, PRESENTACION: ENVASE DE CARTON X 5 Kg | H21: NO | I21: ='Necesidades Trimestrales'!F19 -> UNIDAD | J21: 1990 | K21: 5
A22: 11 | B22: ='Necesidades Trimestrales'!B20 -> 2.1.1-2113.21 | C22: ='Necesidades Trimestrales'!E20 -> DULCES; TIPO: BATATA A LA VAINILLA, PRESENTACION: LATA, PESO: 5 Kg | H22: NO | I22: ='Necesidades Trimestrales'!F20 -> UNIDAD | J22: 1485 | K22: 20
A23: 12 | B23: ='Necesidades Trimestrales'!B21 -> 2.1.1-2113.2 | C23: ='Necesidades Trimestrales'!E21 -> DULCES; TIPO: DE MEMBRILLO, PRESENTACION: LATA, PESO: 5 Kg | H23: NO | I23: ='Necesidades Trimestrales'!F21 -> UNIDAD | J23: 1716 | K23: 20
... A60: 49 | B60: ='Necesidades Trimestrales'!B58 -> 2.1.1-517.86 | C60: ='Necesidades Trimestrales'!E58 -> POSTRES; ESTADO PREPARACION: CON COCCION, TIPO: POLVO, ENVASE: CAJA DE CARTON, PESO: 80 GR, SABOR: VAINILLA, LIBRE DE GLUTEN: SI | H60: NO | I60: ='Necesidades Trimestrales'!F58 -> UNIDAD | J60: 73 | K60: 120
A61: 50 | B61: ='Necesidades Trimestrales'!B59 -> 2.1.1-514.2 | C61: ='Necesidades Trimestrales'!E59 -> SAL DE MESA; CONSISTENCIA: FINA, PESO: 500 GR, TIPO: SIN VALOR, ENVASE: PAQUETE | H61: NO | I61: ='Necesidades Trimestrales'!F58 -> UNIDAD | J61: 43 | K61: 100
A62: 51 | B62: ='Necesidades Trimestrales'!B60 -> 2.1.1-514.15 | C62: ='Necesidades Trimestrales'!E60 -> SAL DE MESA; CONSISTENCIA: GRUESA, ENVASE: BOLSA, PESO: 1 Kg, TIPO: SIN VALOR | H62: NO | I62: ='Necesidades Trimestrales'!F59 -> UNIDAD | J62: 63 | K62: 15
A63: 52 | B63: ='Necesidades Trimestrales'!B61 -> 2.1.1-2126.13 | C63: ='Necesidades Trimestrales'!E61 -> SEMOLAS; TIPO: VITINA, PRESENTACION: BOLSA, PESO: 500 GR, MATERIAL ENVASE: PLASTICO 1 (PET), CERTICADO FORESTAL (GFS): SIN, LIBRE DE GLUTEN: NO | H63: NO | I63: ='Necesidades Trimestrales'!F60 -> UNIDAD | J63: 197 | K63: 20
A64: 53 | B64: ='Necesidades Trimestrales'!B62 -> 2.1.1-511.8 | C64: ='Necesidades Trimestrales'!E62 -> TE; SAQUITOS 2G P/CAJA: 50, PESO: SIN VALOR, TIPO: SIN VALOR, PRESENTACION: EN SAQUITOS | H64: NO | I64: ='Necesidades Trimestrales'!F61 -> UNIDAD | J64: 185.8 | K64: 700
A65: 54 | B65: ='Necesidades Trimestrales'!B63 -> 2.1.1-6546.336 | C65: ='Necesidades Trimestrales'!E63 -> VERDURAS Y HORTALIZAS; VARIEDAD: CHOCLO, ESTADO: CREMOSO, PRESENTACION: LATA, PESO: 350 GR, ELEM. TRANSPORTE: SIN, MATERIAL ELEM. TRANSPORTE: SIN, LIBRE DE GLUTEN: NO | H65: NO | I65: ='Necesidades Trimestrales'!F62 -> UNIDAD | J65: 118 | K65: 200
A66: 55 | B66: ='Necesidades Trimestrales'!B64 -> 2.1.1-6546.269 | C66: ='Necesidades Trimestrales'!E64 -> VERDURAS Y HORTALIZAS; VARIEDAD: CHOCLO, ESTADO: GRANO, PRESENTACION: LATA, PESO: 350 GR | H66: NO | I66: ='Necesidades Trimestrales'!F63 -> UNIDAD | J66: 133 | K66: 200
A67: 56 | B67: ='Necesidades Trimestrales'!B65 -> 2.1.1-6546.183 | C67: ='Necesidades Trimestrales'!E65 -> VERDURAS Y HORTALIZAS; VARIEDAD: TOMATE PERITA, ESTADO: NATURAL, PRESENTACION: LATA, PESO: 380 GR | H67: NO | I67: ='Necesidades Trimestrales'!F64 -> UNIDAD | J67: 88.25 | K67: 300
A68: 57 | B68: ='Necesidades Trimestrales'!B66 -> 2.1.1-6546.81 | C68: ='Necesidades Trimestrales'!E66 -> VERDURAS Y HORTALIZAS; VARIEDAD: TOMATE, ESTADO: PURE NATURAL, PRESENTACION: CAJA, PESO: 500 GR | H68: NO | I68: ='Necesidades Trimestrales'!F65 -> UNIDAD | J68: 77 | K68: 300
A69: 58 | B69: ='Necesidades Trimestrales'!B67 -> 2.1.1-519.23 | C69: ='Necesidades Trimestrales'!E67 -> VINAGRES; TIPO: MANZANA, PRESENTACION: ENVASE X 1 L, MATERIAL ENVASE: PLASTICO 1 (PET) | H69: NO | I69: ='Necesidades Trimestrales'!F66 -> UNIDAD | J69: 179 | K69: 30
A70: 59 | B70: ='Necesidades Trimestrales'!B68 -> 2.1.1-519.27 | C70: ='Necesidades Trimestrales'!E68 -> VINAGRES; TIPO: VINO, PRESENTACION: ENVASE X 1 L, MATERIAL ENVASE: PLASTICO 1 (PET), LIBRE DE GLUTEN: NO | H70: NO | I70: ='Necesidades Trimestrales'!F67 -> UNIDAD | J70: 164 | K70: 30
A71: 60 | B71: ='Necesidades Trimestrales'!B69 -> 2.1.1-454.25 | C71: ='Necesidades Trimestrales'!E69 -> YERBAS; PALO: CON, PESO: 1 Kg, MATERIAL ENVASE : PAPEL, CERTIFICADO FORESTAL (GFS): CON, ELEM. TRANSPORTE: SIN, MATERIAL ELEM. TRANSPORTE: SIN, LIBRE DE GLUTEN: SI | H71: NO | I71: ='Necesidades Trimestrales'!F68 -> UNIDAD | J71: 449 | K71: 10
A72: Costo total estimado: PESOS DOS MILLONES TREINTA Y NUEVE MIL CUATROCIENTOS OCHENTA Y SEIS CON 00/100.--- | J72: =SUMPRODUCT(J12:J71,K12:K71) -> 2039486

Sheet Autor Gastar
A1: EJERCICIO: | D1: ='Necesidades Trimestrales'!C6 -> 2022 | P1: AUTORIZACION PARA GASTAR
A4: JURISDICCIÓN: | G4: =NotaPedido!D3 -> 40 - Ministerio de Salud
A5: SAF: | G5: =NotaPedido!D4 -> 23 - Hospital Interzonal San Juan Bautista
A6: UNIDAD EJECUTORA: | G6: =NotaPedido!D5 -> 168 - Direccion Asistencial
A7: DEPENDENCIA SOLICITANTE: | G7: =NotaPedido!D6 -> Servicio de Nutricion
A8: AUTORIZACIÓN:
A9: Señor Jefe de Servicio Administrativo Financiero:
A10: ="Autorizo la realización de los trámites correspondientes, a fin de proveer a este Organismo los bienes y/o servicios que se detallan en Nota de Pedido N° "&NotaPedido!K1&", afectando la erogación resultante a los créditos presupuestarios aprobados a favor de esta Unidad Ejecutora, conforme al siguiente detalle:" -> Autorizo la realización de los trámites correspondientes, a fin de proveer a este Organismo los bienes y/o servicios que se detallan en Nota de Pedido N° 042 - 2022, afectando la erogación resultante a los créditos presupuestarios aprobados a favor de esta Unidad Ejecutora, conforme al siguiente detalle:
A12: IMPUTACIÓN PRESUPUESTARIA
A13: CÓDIGO | O13: DENOMINACIÓN DE LA PARTIDA PRESUPUESTARIA | Q13: IMPORTE
A14: PR | B14: SB | C14: PY | D14: AC | E14: OB | F14: UG | G14: FIN | H14: FUN | I14: I | J14: P | K14: P | L14: SubP | M14: M | N14: FF
A15: 33 | D15: 2 | F15: 4901 | G15: 3 | H15: 3.1 | I15: 2 | J15: 1 | K15: 1 | M15: 1 | N15: 1.1 | O15: Alimentos para personas | Q15: 2039486
A22: TOTAL DE PESOS: DOS MILLONES TREINTA Y NUEVE MIL CUATROCIENTOS OCHENTA Y SEIS CON 00/100.----- | Q22: =SUM(Q15:Q21) -> 2039486
A24: JUSTIFICACIÓN:
A25: ="Para la "&NotaPedido!D8&" para ser destinados al "&NotaPedido!D6&" del HISJB del Ministerio de Salud." -> Para la Adquisición de Alimentos no perecederos para ser destinados al Servicio de Nutricion del HISJB del Ministerio de Salud.
