Workbook

Sheet LAB. CENTRAL NT 
B2: Pedido de Necesidades Trimestrales
A4: JURISDICCION: | C4: 40 - Ministerio de Salud
A5: SAF N°: | C5: 23 - Hospital Interzonal San Juan Bautista
A6: EJERCICIO: | C6: 2021
A7: TRIMESTRE: | C7: 1
A9: ID | B9: CODIGO ITEM | C9: RUBRO DE COMPRA | D9: I.P.P. | E9: DESCRIPCION | F9: UNIDAD DE MEDIDA | G9: CANTIDAD | H9: PRECIO UNITARIO ESTIMADO | I9: IMPORTE TOTAL ESTIMADO
A10: 1 | D10: 2.9.5 | E10: DILUYENTES P/LABORATORIOS; TIPO : BUFFER DILUYENTE, USO: LABORATORIO, PRESENTACION: ENVASE X 20 L, TIPO: BUFFER DILUYENTE | F10: BIDON | G10: 20 | H10: 6632 | I10: =G10*H10 -> 132640
A11: 2 | D11: 2.5.1 | E11: REACTIVOS P/EQUIPO; EQUIPO: CONTADOR HEMATOLOGICO, MARCA EQUIPO: SYSMEX ROCHE, NOMBRE DEL PRODUCTO: LISANTE, PRESENTACION: ENVASE X 5 L | F11: BIDON | G11: 2 | H11: 47407 | I11: =G11*H11 -> 94814
A12: 3 | D12: 2.9.9 | E12: CELLCLEAN AUTO X 20 VIALES -TIPO SYSMEX XNL - 20 X 4 ML | F12: CAJA | G12: 20 | H12: 7502 | I12: =G12*H12 -> 150040
A13: 4 | D13: 2.5.1 | E13: REACTIVOS P/EQUIPO; EQUIPO: CONTADOR HEMATOLOGICO, MARCA EQUIPO: SYSMEX ROCHE, NOMBRE DEL PRODUCTO: REACTIVO DIFERENCIAL, PRESENTACION: ENVASE X 5 L | F13: BIDON | G13: 4 | H13: 14490 | I13: =G13*H13 -> 57960
A14: 5 | D14: 2.5.1 | E14: XN CHECK - TIPO SYSMEX XNL - 12 X 30 ML | F14: CAJA | G14: 6 | H14: 71186 | I14: =G14*H14 -> 427116
A15: 6 | D15: 2.5.1 | E15: FLUOROCELL 2 X 42 MML P/SYSMEX XN | F15: BIDON | G15: 4 | H15: 60322 | I15: =G15*H15 -> 241288
A16: 7 | D16: 2.5.1 | E16: S1 RINSE SOLUTION 2 PCS P/COBAS B221 - 2 U | F16: BIDON | G16: 10 | H16: 21395 | I16: =G16*H16 -> 213950
A17: 8 | D17: 2.5.1 | E17: S2 FLUID PACK P/COBAS 221 | F17: BIDON | G17: 20 | H17: 35079 | I17: =G17*H17 -> 701580
A18: 9 | D18: 2.5.1 | E18: S3 FLUID PACK P/COBAS 221 | F18: BIDON | G18: 20 | H18: 46545 | I18: =G18*H18 -> 930900
A19: 10 | D19: 2.5.1 | E19: PATRON/ESTANDAR P/CALIBRACION; PRESENTACION: 30 X ENVASE X 1,7 mL, NOMBRE DEL PRODUCTO: COMBITROL TS NIVEL 1, MARCA EQUIPO: ROCHE, EQUIPO: ANALIZADOR DE GASES | F19: CAJA | G19: 4 | H19: 14924 | I19: =G19*H19 -> 59696
A20: 11 | D20: 2.5.1 | E20: PATRON/ESTANDAR P/CALIBRACION; PRESENTACION: 30 X ENVASE X 1,7 mL, NOMBRE DEL PRODUCTO: COMBITROL TS NIVEL 2, MARCA EQUIPO: ROCHE, EQUIPO: ANALIZADOR DE GASES | F20: CAJA | G20: 4 | H20: 14924 | I20: =G20*H20 -> 59696
A21: 12 | D21: 2.5.1 | E21: PATRON/ESTANDAR P/CALIBRACION; PRESENTACION: 30 X ENVASE X 1,7 mL, NOMBRE DEL PRODUCTO: COMBITROL TS NIVEL 3, MARCA EQUIPO: ROCHE, EQUIPO: ANALIZADOR DE GASES | F21: CAJA | G21: 4 | H21: 14924 | I21: =G21*H21 -> 59696
... A123: 114 | D123: 2.5.1 | E123: REACTIVOS P/LAB. TEC. MANUAL ; NOMBRE: DET. FIBRINOGENO, USO: HEMATOLOGIA, PRESENTACION: ENVASE X 100 DETERM. | F123: CAJA | G123: 5 | H123: 21767 | I123: =G123*H123 -> 108835
I124: =SUM(I10:I123) -> 8892434
B126: Especificidades Item N° 1:
B128: Descripción técnica
C129: CELL PACK DCL x 20 LTS- TIPO SYSMEX XNL
B130: Plazos y lugares de entrega
C131: 10 dias - Servicio de Laboratorio Central del HISJB
B133: Calidad Minima esperada
B135: Mantenimiento
C136: 45 dias habiles
B137: Garantia
B141: Especificidades Item N° 2:
B143: Descripción técnica
C144: SULFOLYSER x 5 LTS - TIPO SYSMEX XNL
B145: Plazos y lugares de entrega
C146: 10 dias - Servicio de Laboratorio Central del HISJB
B148: Calidad Minima esperada
B150: Mantenimiento
C151: 45 dias habiles
B152: Garantia
B156: Especificidades Item N° 3:
B158: Descripción técnica
...

Sheet LAB. CENTRAL NPYE
A1: NOTA DE PEDIDO | J1: N° | K1: 386 - 2020
A3: JURISDICCIÓN: | D3: ='[1]Necesidades Trimestrales'!C4 -> 40 - Ministerio de Salud
A4: SAF: | D4: ='[1]Necesidades Trimestrales'!C5 -> 23 - Hospital Interzonal San Juan Bautista
A5: UNIDAD EJECUTORA: | D5: 168 - Direccion Asistencial
A6: DEPENDENCIA SOLICITANTE: | D6: Servicio de Laboratorio Central
A7: PERIODO UTILIZACIÓN: | D7: ='[1]Necesidades Trimestrales'!C7 & "° Trimestre - Año " & '[1]Necesidades Trimestrales'!C6 -> 1° Trimestre - Año 2021
A8: OBJETO: | D8: Adquisición de Insumos para Laboratorio del HISJB
A10: Ítem | B10: Codigo Item | C10: DESCRIPCIÓN | H10: Adjunta Detalle Técnico | I10: Unidad Medida | J10: Precio Unitario Estimado | K10: Cantidad Solicitada
A12: 1 | C12: ='LAB. CENTRAL NT '!E10 -> DILUYENTES P/LABORATORIOS; TIPO : BUFFER DILUYENTE, USO: LABORATORIO, PRESENTACION: ENVASE X 20 L, TIPO: BUFFER DILUYENTE | H12: NO | I12: ='[1]Necesidades Trimestrales'!F10 -> BIDON | J12: ='[1]Necesidades Trimestrales'!H10 -> 6632 | K12: ='[1]Necesidades Trimestrales'!G10 -> 20
A13: 2 | C13: ='LAB. CENTRAL NT '!E11 -> REACTIVOS P/EQUIPO; EQUIPO: CONTADOR HEMATOLOGICO, MARCA EQUIPO: SYSMEX ROCHE, NOMBRE DEL PRODUCTO: LISANTE, PRESENTACION: ENVASE X 5 L | H13: NO | I13: ='[1]Necesidades Trimestrales'!F11 -> BIDON | J13: ='[1]Necesidades Trimestrales'!H11 -> 47407 | K13: ='[1]Necesidades Trimestrales'!G11 -> 2
A14: 3 | C14: ='LAB. CENTRAL NT '!E12 -> CELLCLEAN AUTO X 20 VIALES -TIPO SYSMEX XNL - 20 X 4 ML | H14: NO | I14: ='[1]Necesidades Trimestrales'!F12 -> CAJA | J14: ='[1]Necesidades Trimestrales'!H12 -> 7502 | K14: ='[1]Necesidades Trimestrales'!G12 -> 20
A15: 4 | C15: ='LAB. CENTRAL NT '!E13 -> REACTIVOS P/EQUIPO; EQUIPO: CONTADOR HEMATOLOGICO, MARCA EQUIPO: SYSMEX ROCHE, NOMBRE DEL PRODUCTO: REACTIVO DIFERENCIAL, PRESENTACION: ENVASE X 5 L | H15: NO | I15: ='[1]Necesidades Trimestrales'!F13 -> BIDON | J15: ='[1]Necesidades Trimestrales'!H13 -> 14490 | K15: ='[1]Necesidades Trimestrales'!G13 -> 4
A16: 5 | C16: ='LAB. CENTRAL NT '!E14 -> XN CHECK - TIPO SYSMEX XNL - 12 X 30 ML | H16: NO | I16: ='[1]Necesidades Trimestrales'!F14 -> CAJA | J16: ='[1]Necesidades Trimestrales'!H14 -> 71186 | K16: ='[1]Necesidades Trimestrales'!G14 -> 6
A17: 6 | C17: ='LAB. CENTRAL NT '!E15 -> FLUOROCELL 2 X 42 MML P/SYSMEX XN | H17: NO | I17: ='[1]Necesidades Trimestrales'!F15 -> BIDON | J17: ='[1]Necesidades Trimestrales'!H15 -> 60322 | K17: ='[1]Necesidades Trimestrales'!G15 -> 4
A18: 7 | C18: ='LAB. CENTRAL NT '!E16 -> S1 RINSE SOLUTION 2 PCS P/COBAS B221 - 2 U | H18: NO | I18: ='[1]Necesidades Trimestrales'!F16 -> BIDON | J18: ='[1]Necesidades Trimestrales'!H16 -> 21395 | K18: ='[1]Necesidades Trimestrales'!G16 -> 10
A19: 8 | C19: ='LAB. CENTRAL NT '!E17 -> S2 FLUID PACK P/COBAS 221 | H19: NO | I19: ='[1]Necesidades Trimestrales'!F17 -> BIDON | J19: ='[1]Necesidades Trimestrales'!H17 -> 35079 | K19: ='[1]Necesidades Trimestrales'!G17 -> 20
A20: 9 | C20: ='LAB. CENTRAL NT '!E18 -> S3 FLUID PACK P/COBAS 221 | H20: NO | I20: ='[1]Necesidades Trimestrales'!F18 -> BIDON | J20: ='[1]Necesidades Trimestrales'!H18 -> 46545 | K20: ='[1]Necesidades Trimestrales'!G18 -> 20
A21: 10 | C21: ='LAB. CENTRAL NT '!E19 -> PATRON/ESTANDAR P/CALIBRACION; PRESENTACION: 30 X ENVASE X 1,7 mL, NOMBRE DEL PRODUCTO: COMBITROL TS NIVEL 1, MARCA EQUIPO: ROCHE, EQUIPO: ANALIZADOR DE GASES | H21: NO | I21: ='[1]Necesidades Trimestrales'!F19 -> CAJA | J21: ='[1]Necesidades Trimestrales'!H19 -> 14924 | K21: ='[1]Necesidades Trimestrales'!G19 -> 4
A22: 11 | C22: ='LAB. CENTRAL NT '!E20 -> PATRON/ESTANDAR P/CALIBRACION; PRESENTACION: 30 X ENVASE X 1,7 mL, NOMBRE DEL PRODUCTO: COMBITROL TS NIVEL 2, MARCA EQUIPO: ROCHE, EQUIPO: ANALIZADOR DE GASES | H22: NO | I22: ='[1]Necesidades Trimestrales'!F20 -> CAJA | J22: ='[1]Necesidades Trimestrales'!H20 -> 14924 | K22: ='[1]Necesidades Trimestrales'!G20 -> 4
A23: 12 | C23: ='LAB. CENTRAL NT '!E21 -> PATRON/ESTANDAR P/CALIBRACION; PRESENTACION: 30 X ENVASE X 1,7 mL, NOMBRE DEL PRODUCTO: COMBITROL TS NIVEL 3, MARCA EQUIPO: ROCHE, EQUIPO: ANALIZADOR DE GASES | H23: NO | I23: ='[1]Necesidades Trimestrales'!F21 -> CAJA | J23: ='[1]Necesidades Trimestrales'!H21 -> 14924 | K23: ='[1]Necesidades Trimestrales'!G21 -> 4
... A125: 114 | C125: ='LAB. CENTRAL NT '!E123 -> REACTIVOS P/LAB. TEC. MANUAL ; NOMBRE: DET. FIBRINOGENO, USO: HEMATOLOGIA, PRESENTACION: ENVASE X 100 DETERM. | H125: NO | I125: ='[1]Necesidades Trimestrales'!F123 -> CAJA | J125: ='[1]Necesidades Trimestrales'!H123 -> 21767 | K125: ='[1]Necesidades Trimestrales'!G123 -> 5
A126: Costo total estimado: Ocho millones ochocientos noventa y dos mil cuatrocientos treinta y cuatro con 00/100.----- | J126: =SUMPRODUCT(J12:J125,K12:K125) -> 8892434

Sheet LAB. CENTRAL APG
A1: EJERCICIO: | D1: ='[1]Necesidades Trimestrales'!C6 -> 2021 | P1: AUTORIZACION PARA GASTAR
A4: JURISDICCIÓN: | G4: =[1]NotaPedido!D3 -> 40 - Ministerio de Salud
A5: SAF: | G5: =[1]NotaPedido!D4 -> 23 - Hospital Interzonal San Juan Bautista
A6: UNIDAD EJECUTORA: | G6: =[1]NotaPedido!D5 -> 168 - Direccion Asistencial
A7: DEPENDENCIA SOLICITANTE: | G7: =[1]NotaPedido!D6 -> Servicio de Laboratorio Central
A8: AUTORIZACIÓN:
A9: Señor Jefe de Servicio Administrativo Financiero:
A10: ="Autorizo la realización de los trámites correspondientes, a fin de proveer a este Organismo los bienes y/o servicios que se detallan en Nota de Pedido N° " & [1]NotaPedido!K1&", afectando la erogación resultante a los créditos presupuestarios aprobados a favor de esta Unidad Ejecutora, conforme al siguiente detalle:" -> Autorizo la realización de los trámites correspondientes, a fin de proveer a este Organismo los bienes y/o servicios que se detallan en Nota de Pedido N° 386 - 2020, afectando la erogación resultante a los créditos presupuestarios aprobados a favor de esta Unidad Ejecutora, conforme al siguiente detalle:
A12: IMPUTACIÓN PRESUPUESTARIA
A13: CÓDIGO | O13: DENOMINACIÓN DE LA PARTIDA PRESUPUESTARIA | Q13: IMPORTE
A14: PR | B14: SB | C14: PY | D14: AC | E14: OB | F14: UG | G14: FIN | H14: FUN | I14: I | J14: P | K14: P | L14: SubP | M14: M | N14: FF
A15: 33 | D15: 2 | F15: 4901 | G15: 3 | H15: 3.1 | I15: 2 | J15: 5 | K15: 1 | M15: 1 | N15: 1.1 | O15: Compuestos Químicos | Q15: 7553846
A16: 33 | D16: 2 | F16: 4901 | G16: 3 | H16: 3.1 | I16: 2 | J16: 9 | K16: 5 | M16: 1 | N16: 1.1 | O16: Utiles Menores Médico, Quirúrgico y de Laboratorio | Q16: 1188548
A17: 33 | D17: 2 | F17: 4901 | G17: 3 | H17: 3.1 | I17: 2 | J17: 9 | K17: 9 | M17: 1 | N17: 1.1 | O17: Otros N.E.P. | Q17: 150040
A22: SON PESOS: OCHO MILLONES OCHOCIENTOS NOVENTA Y DOS MIL CUATROCIENTOS TREINTA Y CUATRO CON 00/100 | Q22: =SUM(Q15:Q21) -> 8892434
A24: JUSTIFICACIÓN:
A25: ="Para la "& [1]NotaPedido!D8 &" para ser destinados al " & [1]NotaPedido!D6 &" del HISJB del Ministerio de Salud." -> Para la Adquisición de Insumos para Laboratorio del HISJB para ser destinados al Servicio de Laboratorio Central del HISJB del Ministerio de Salud.
