Workbook

Sheet Necesidades Trimestrales
A1: 2022
B2: Pedido de Necesidades Trimestrales
A4: JURISDICCION: | C4: 040 - MINISTERIO DE SALUD
A5: SAF N°: | C5: 011 - DIRECCION PROVINCIAL DE ADMINISTRACION - MS
A6: EJERCICIO: | C6: 2022
A7: TRIMESTRE: | C7: 3
A9: ID | B9: CODIGO ITEM | C9: RUBRO DE COMPRA | D9: I.P.P. | E9: DESCRIPCION | F9: UNIDAD DE MEDIDA | G9: FARMACIA | H9: TOTAL FCIA | I9: SAME | J9: TOTAL SAME | K9: CANTIDAD | L9: PRECIO UNITARIO ESTIMADO | M9: IMPORTE TOTAL ESTIMADO
A10: 1 | B10: 2.5.2-1843.63 | C10: PROD. MEDICO/FARMACEUTICOS/LAB | D10: 252 | E10: ANTIESPASMODICOS; TIPO: MONODROGA, DROGA GENERICA: ATROPINA 1%, FORMA FARMACEUTICA: AMPOLLA, PRESENTACION: ENVASE X 1 mL | F10: AMPOLLA | G10: 4000 | H10: =+G10*L10 -> 201600 | I10: 200 | J10: =+I10*L10 -> 10080 | K10: =+G10+I10 -> 4200 | L10: 50.4 | M10: =+K10*L10 -> 211680
A11: 2 | B11: 2.5.2-1843.51 | C11: PROD. MEDICO/FARMACEUTICOS/LAB | D11: 252 | E11: ANTIESPASMODICOS; TIPO: MONODROGA, DROGA GENERICA: HIOSCINA N-BUTILBROMURO 20 MG, FORMA FARMACEUTICA: AMPOLLA, PRESENTACION: 1 ML | F11: AMPOLLA | G11: 100000 | H11: =+G11*L11 -> 6500000 | I11: 200 | J11: =+I11*L11 -> 13000 | K11: =+G11+I11 -> 100200 | L11: 65 | M11: =+K11*L11 -> 6513000
A12: 3 | B12: 2.5.2-1843.1 | C12: PROD. MEDICO/FARMACEUTICOS/LAB | D12: 252 | E12: ANTIESPASMODICOS; TIPO: MONODROGA, PRESENTACION: 10 mGr, FORMA FARMACEUTICA: COMPRIMIDO, DROGA GENERICA: HIOSCINA N-BUTILBROMURO | F12: COMPRIMIDO | G12: 100000 | H12: =+G12*L12 -> 1100000 | J12: =+I12*L12 -> 0 | K12: =+G12+I12 -> 100000 | L12: 11 | M12: =+K12*L12 -> 1100000
A13: 4 | B13: 2.5.2-1724.57 | C13: PROD. MEDICO/FARMACEUTICOS/LAB | D13: 252 | E13: ANALGESICOS ; TIPO: ASOCIACION, DROGA GENERICA: DIPIRONA+ HIOSCINA, FORMA FARMACEUTICA: AMPOLLA, PRESENTACION: AMPOLLA X 5 mL | F13: AMPOLLA | H13: =+G13*L13 -> 0 | I13: 200 | J13: =+I13*L13 -> 18400 | K13: =+G13+I13 -> 200 | L13: 92 | M13: =+K13*L13 -> 18400
A14: 5 | B14: 2.5.2-8078.68 | C14: QUIMICOS | D14: 252 | E14: EXCIPIENTES; TIPO: MONODROGA, PRESENTACION: ENVASE X 1 Kg, COMPUESTO: CARBON ACTIVADO, CONCENTRACION/PUREZA: 100 % | F14: UNIDAD | G14: 20 | H14: =+G14*L14 -> 36000 | J14: =+I14*L14 -> 0 | K14: =+G14+I14 -> 20 | L14: 1800 | M14: =+K14*L14 -> 36000
A15: 6 | B15: 2.5.2-1901.7 | C15: PROD. MEDICO/FARMACEUTICOS/LAB | D15: 252 | E15: VITAMINAS; FORMA FARMACEUTICA: AMPOLLA, PRESENTACION: 2 mL, TIPO: MONODROGA, DROGA GENERICA: VITAMINA B | F15: AMPOLLA | G15: 100 | H15: =+G15*L15 -> 11000 | J15: =+I15*L15 -> 0 | K15: =+G15+I15 -> 100 | L15: 110 | M15: =+K15*L15 -> 11000
A16: 7 | B16: 2.5.2-1872.65 | C16: PROD. MEDICO/FARMACEUTICOS/LAB | D16: 252 | E16: ANTIANEMICOS; TIPO: MONODROGA, DROGA GENERICA: COMPLEJO VITAMINICO B, FORMA FARMACEUTICA: COMPRIMIDO, PRESENTACION: UNIDAD | F16: COMPRIMIDO | G16: 10000 | H16: =+G16*L16 -> 178000 | J16: =+I16*L16 -> 0 | K16: =+G16+I16 -> 10000 | L16: 17.8 | M16: =+K16*L16 -> 178000
A17: 8 | B17: 2.5.2-1816.19 | C17: PROD. MEDICO/FARMACEUTICOS/LAB | D17: 252 | E17: ANTIDIARREICOS; TIPO: MONODROGA, DROGA GENERICA: BISMUTO, FORMA FARMACEUTICA: CREMA, PRESENTACION: 90 mL | F17: FRASCO | G17: 50 | H17: =+G17*L17 -> 26500 | J17: =+I17*L17 -> 0 | K17: =+G17+I17 -> 50 | L17: 530 | M17: =+K17*L17 -> 26500
A18: 9 | B18: 2.5.2-1862.3 | C18: PROD. MEDICO/FARMACEUTICOS/LAB | D18: 252 | E18: HIPOGLUCEMIANTES ORALES; TIPO: MONODROGA, FORMA FARMACEUTICA: COMPRIMIDO, PRESENTACION: 5 mGr, DROGA GENERICA: GLIBENCLAMIDA | F18: COMPRIMIDO | G18: 5000 | H18: =+G18*L18 -> 22500 | J18: =+I18*L18 -> 0 | K18: =+G18+I18 -> 5000 | L18: 4.5 | M18: =+K18*L18 -> 22500
A19: 10 | B19: 2.5.2-1861.38 | C19: PROD. MEDICO/FARMACEUTICOS/LAB | D19: 252 | E19: HIPOGLUCEMIANTES INYECTABLES; TIPO: MONODROGA, DROGA GENERICA: INSULINA ASPARTICA, FORMA FARMACEUTICA: LAPICERA PRELLENADA, PRESENTACION: 5 UNIDADES | F19: CAJA | G19: 1400 | H19: =+G19*L19 -> 21772800 | J19: =+I19*L19 -> 0 | K19: =+G19+I19 -> 1400 | L19: 15552 | M19: =+K19*L19 -> 21772800
A20: 11 | B20: 2.5.2-1861.33 | C20: PROD. MEDICO/FARMACEUTICOS/LAB | D20: 252 | E20: HIPOGLUCEMIANTES INYECTABLES; TIPO: MONODROGA, DROGA GENERICA: INSULINA CTE, FORMA FARMACEUTICA: AMPOLLA, PRESENTACION: ENVASE X 10 mL | F20: FRASCO AMPOLLA | G20: 300 | H20: =+G20*L20 -> 502500 | J20: =+I20*L20 -> 0 | K20: =+G20+I20 -> 300 | L20: 1675 | M20: =+K20*L20 -> 502500
A21: 12 | B21: 2.5.2-1861.10 | C21: PROD. MEDICO/FARMACEUTICOS/LAB | D21: 252 | E21: HIPOGLUCEMIANTES INYECTABLES; TIPO: MONODROGA, DROGA GENERICA: INSULINA HUMANA NHP 100 UI, FORMA FARMACEUTICA: AMPOLLA, PRESENTACION: 10 mL | F21: FRASCO AMPOLLA | G21: 300 | H21: =+G21*L21 -> 502500 | J21: =+I21*L21 -> 0 | K21: =+G21+I21 -> 300 | L21: 1675 | M21: =+K21*L21 -> 502500
A22: 13 | B22: 2.5.2-1861.39 | C22: PROD. MEDICO/FARMACEUTICOS/LAB | D22: 252 | E22: HIPOGLUCEMIANTES INYECTABLES; TIPO: MONODROGA, DROGA GENERICA: INSULINA HUMANA NHP 100 UI, FORMA FARMACEUTICA: LAPICERA PRELLENADA, PRESENTACION: 5 AMPOLLAS | F22: CAJA | G22: 4200 | H22: =+G22*L22 -> 37522800 | J22: =+I22*L22 -> 0 | K22: =+G22+I22 -> 4200 | L22: 8934 | M22: =+K22*L22 -> 37522800
A23: 14 | B23: 2.5.2-1816.34 | C23: PROD. MEDICO/FARMACEUTICOS/LAB | D23: 252 | E23: ANTIDIARREICOS; TIPO: MONODROGA, DROGA GENERICA: LOPERAMIDA, FORMA FARMACEUTICA: CAPSULA, PRESENTACION: 2 mGr | F23: COMPRIMIDO | G23: 2000 | H23: =+G23*L23 -> 5400 | J23: =+I23*L23 -> 0 | K23: =+G23+I23 -> 2000 | L23: 2.7 | M23: =+K23*L23 -> 5400
A24: 15 | B24: 2.5.2-1862.1 | C24: PROD. MEDICO/FARMACEUTICOS/LAB | D24: 252 | E24: HIPOGLUCEMIANTES ORALES; TIPO: MONODROGA, DROGA GENERICA: METFORMINA, FORMA FARMACEUTICA: COMPRIMIDO, PRESENTACION: 500 mGr | F24: COMPRIMIDO | G24: 50000 | H24: =+G24*L24 -> 285000 | J24: =+I24*L24 -> 0 | K24: =+G24+I24 -> 50000 | L24: 5.7 | M24: =+K24*L24 -> 285000
A25: 16 | B25: 2.5.2-1862.16 | C25: PROD. MEDICO/FARMACEUTICOS/LAB | D25: 252 | E25: HIPOGLUCEMIANTES ORALES; TIPO: MONODROGA, DROGA GENERICA: METFORMINA, FORMA FARMACEUTICA: COMPRIMIDO, PRESENTACION: 850 mGr | F25: COMPRIMIDO | G25: 80000 | H25: =+G25*L25 -> 576000 | J25: =+I25*L25 -> 0 | K25: =+G25+I25 -> 80000 | L25: 7.2 | M25: =+K25*L25 -> 576000
... A27: 18 | B27: 2.5.2-6910.21 | C27: PROD. MEDICO/FARMACEUTICOS/LAB | D27: 252 | E27: ANTIEMETICOS; TIPO: MONODROGA, DROGA GENERICA: METOCLOPRAMIDA 0.5%, FORMA FARMACEUTICA: GOTAS, PRESENTACION: ENVASE X 20 ML | F27: GOTERO | G27: 500 | H27: =+G27*L27 -> 75000 | J27: =+I27*L27 -> 0 | K27: =+G27+I27 -> 500 | L27: 150 | M27: =+K27*L27 -> 75000
A28: 19 | B28: 2.5.2-6910.6 | C28: PROD. MEDICO/FARMACEUTICOS/LAB | D28: 252 | E28: ANTIEMETICOS; TIPO: MONODROGA, DROGA GENERICA: METOCLOPRAMIDA, FORMA FARMACEUTICA: AMPOLLA, PRESENTACION: 2 mL | F28: AMPOLLA | G28: 60000 | H28: =+G28*L28 -> 2148000 | I28: 200 | J28: =+I28*L28 -> 7160 | K28: =+G28+I28 -> 60200 | L28: 35.8 | M28: =+K28*L28 -> 2155160
A29: 20 | B29: 2.5.2-1823.46 | C29: PROD. MEDICO/FARMACEUTICOS/LAB | D29: 252 | E29: ANTIMICOTICOS; TIPO: MONODROGA, DROGA GENERICA: NISTATINA 100000 UI/ML, FORMA FARMACEUTICA: SUSPENSION, PRESENTACION: ENVASE X 60 mL | F29: FRASCO | G29: 200 | H29: =+G29*L29 -> 57000 | J29: =+I29*L29 -> 0 | K29: =+G29+I29 -> 200 | L29: 285 | M29: =+K29*L29 -> 57000
A30: 21 | B30: 2.5.2-1849.3 | C30: PROD. MEDICO/FARMACEUTICOS/LAB | D30: 252 | E30: ANTIULCEROSOS; TIPO: MONODROGA, DROGA GENERICA: OMEPRAZOL, FORMA FARMACEUTICA: CAPSULA, PRESENTACION: 20 mGr | F30: CAPSULA | G30: 200000 | H30: =+G30*L30 -> 460000 | J30: =+I30*L30 -> 0 | K30: =+G30+I30 -> 200000 | L30: 2.3 | M30: =+K30*L30 -> 460000
A31: 22 | B31: 2.5.2-1901.127 | C31: PROD. MEDICO/FARMACEUTICOS/LAB | D31: 252 | E31: VITAMINAS; TIPO: ASOCIACION, DROGA GENERICA: VIT.A +D+C, FORMA FARMACEUTICA: GOTA, PRESENTACION: 30 ML | F31: FRASCO | G31: 2000 | H31: =+G31*L31 -> 420000 | J31: =+I31*L31 -> 0 | K31: =+G31+I31 -> 2000 | L31: 210 | M31: =+K31*L31 -> 420000
A32: 23 | B32: 2.5.2-1841.17 | C32: PROD. MEDICO/FARMACEUTICOS/LAB | D32: 252 | E32: ANTIACIDOS; TIPO: MONODROGA, DROGA GENERICA: RANITIDINA, FORMA FARMACEUTICA: AMPOLLA, PRESENTACION: UNIDAD | F32: AMPOLLA | G32: 80000 | H32: =+G32*L32 -> 3800000 | I32: 200 | J32: =+I32*L32 -> 9500 | K32: =+G32+I32 -> 80200 | L32: 47.5 | M32: =+K32*L32 -> 3809500
A33: 24 | B33: 2.5.2-1903.85 | C33: PROD. MEDICO/FARMACEUTICOS/LAB | D33: 252 | E33: RECONSTITUYENTE GENERAL; TIPO: ASOCIACION, DROGA GENERICA: SALES DE REHIDRATACION, FORMA FARMACEUTICA: POLVO, PRESENTACION: SOBRE X 27,9 GR | F33: UNIDAD | G33: 4000 | H33: =+G33*L33 -> 352000 | J33: =+I33*L33 -> 0 | K33: =+G33+I33 -> 4000 | L33: 88 | M33: =+K33*L33 -> 352000
A34: 25 | B34: 2.5.2-5520.5 | C34: PROD. MEDICO/FARMACEUTICOS/LAB | D34: 252 | E34: VASELINA; TIPO: LIQUIDA, PRESENTACION: ENVASE X 1000 mL | F34: FRASCO | G34: 150 | H34: =+G34*L34 -> 147000 | J34: =+I34*L34 -> 0 | K34: =+G34+I34 -> 150 | L34: 980 | M34: =+K34*L34 -> 147000
A35: 26 | B35: 2.5.2-1901.129 | C35: PROD. MEDICO/FARMACEUTICOS/LAB | D35: 252 | E35: VITAMINAS; TIPO: MONODROGA, DROGA GENERICA: VITAMINA C, FORMA FARMACEUTICA: COMPRIMIDOS, PRESENTACION: 10 COMPRIMIDOS | F35: CAJA | G35: 600 | H35: =+G35*L35 -> 529500 | J35: =+I35*L35 -> 0 | K35: =+G35+I35 -> 600 | L35: 882.5 | M35: =+K35*L35 -> 529500
A36: 27 | B36: 2.5.2-1901.130 | C36: PROD. MEDICO/FARMACEUTICOS/LAB | D36: 252 | E36: VITAMINAS; TIPO: MONODROGA, DROGA GENERICA: VITAMINA D3 2000 UI/ML, FORMA FARMACEUTICA: SOLUCION, PRESENTACION: 2 ML | F36: FRASCO | G36: 500 | H36: =+G36*L36 -> 479000 | J36: =+I36*L36 -> 0 | K36: =+G36+I36 -> 500 | L36: 958 | M36: =+K36*L36 -> 479000
A37: TOTAL RUBRO TRACTO ALIMENTARIO Y METABOLISMO / VITAMINAS Y OTROS /ANTIDIABETICOS E INSULINAS | H37: =SUM(H10:H36) -> 77782600 | J37: =SUM(J10:J36) -> 58140 | M37: =SUM(M10:M36) -> 77840740
B39: Especificidades: ITEMS N 5 de la Nota de Pedido D.P.FARMACIA: VITAMINAS; FORMA FARMACEUTICA: AMPOLLA, PRESENTACION: 2 mL, TIPO: BECOZYM NF AMPOLLAS
B42: Especificidades Item N° 12 de la Nota de Pedido D.P.FARMACIA:
B43: Descripción técnica: INSULINA CORRIENTE HUMANA 100 UI FCO AMP 10 ML
B45: Especificidades Item N° 25 de la Nota de Pedido D.P.FARMACIA:
B46: Descripción técnica: VITAMINA C , CONCENTRACION 2GRS , COMPRIMIDOS EFERVESCENTES
B48: DETALLE TECNICO Y ESPECIFICACIONES | D48: ANEXO 1-Para oferentes de la Provincia de Catamarca deberán presentar Habilitación Provincial para comercializar el producto que cotizan. 2-Para el resto de oferentes deberán presentar Certificado de Inscripción de ANMAT vigente al momento de la oferta, el mismo deberá ser correspondiente al objeto de la contratación y de encontrarse vencido adjuntar la solicitud de renovación. 3-No se aceptarán ofertas de productos no registrados y autorizada su venta por ANMAT. Se deberá especificar en cada ítem de la propuesta, marca y número de certificado otorgado por dicho ente regulador. 4-Los productos deberán tener un vencimiento posterior a doce (12) meses a partir de la fecha de su recepción.
...

Sheet NP DPFeI
A1: NOTA DE PEDIDO | J1: N° | K1: xxx/2022
A3: JURISDICCIÓN: | D3: ='Necesidades Trimestrales'!C4 -> 040 - MINISTERIO DE SALUD
A4: SAF: | D4: ='Necesidades Trimestrales'!C5 -> 011 - DIRECCION PROVINCIAL DE ADMINISTRACION - MS
A5: UNIDAD EJECUTORA: | D5: 469 - DIRECCION PROVINCIAL DE FARMACIA E INSUMOS
A6: DEPENDENCIA SOLICITANTE: | D6: 469 - DIRECCION PROVINCIAL DE FARMACIA E INSUMOS
A7: PERIODO UTILIZACIÓN: | D7: Semestral
A8: OBJETO: | D8: Adquisición de TRACTO ALIMENTARIO Y METABOLISMO / VITAMINAS Y OTROS /ANTIDIABETICOS E INSULINAS
A10: Ítem | B10: Codigo Item | C10: DESCRIPCIÓN | H10: Adjunta Detalle Técnico | I10: Unidad Medida | J10: Precio Unitario Estimado | K10: Cantidad Solicitada
A12: 1 | B12: ='Necesidades Trimestrales'!B10 -> 2.5.2-1843.63 | C12: ='Necesidades Trimestrales'!E10 -> ANTIESPASMODICOS; TIPO: MONODROGA, DROGA GENERICA: ATROPINA 1%, FORMA FARMACEUTICA: AMPOLLA, PRESENTACION: ENVASE X 1 mL | H12: NO | I12: ='Necesidades Trimestrales'!F10 -> AMPOLLA | J12: ='Necesidades Trimestrales'!L10 -> 50.4 | K12: ='Necesidades Trimestrales'!G10 -> 4000
A13: 2 | B13: ='Necesidades Trimestrales'!B11 -> 2.5.2-1843.51 | C13: ='Necesidades Trimestrales'!E11 -> ANTIESPASMODICOS; TIPO: MONODROGA, DROGA GENERICA: HIOSCINA N-BUTILBROMURO 20 MG, FORMA FARMACEUTICA: AMPOLLA, PRESENTACION: 1 ML | H13: NO | I13: ='Necesidades Trimestrales'!F11 -> AMPOLLA | J13: ='Necesidades Trimestrales'!L11 -> 65 | K13: ='Necesidades Trimestrales'!G11 -> 100000
A14: 3 | B14: ='Necesidades Trimestrales'!B12 -> 2.5.2-1843.1 | C14: ='Necesidades Trimestrales'!E12 -> ANTIESPASMODICOS; TIPO: MONODROGA, PRESENTACION: 10 mGr, FORMA FARMACEUTICA: COMPRIMIDO, DROGA GENERICA: HIOSCINA N-BUTILBROMURO | H14: NO | I14: ='Necesidades Trimestrales'!F12 -> COMPRIMIDO | J14: ='Necesidades Trimestrales'!L12 -> 11 | K14: ='Necesidades Trimestrales'!G12 -> 100000
A15: 4 | B15: ='Necesidades Trimestrales'!B14 -> 2.5.2-8078.68 | C15: ='Necesidades Trimestrales'!E14 -> EXCIPIENTES; TIPO: MONODROGA, PRESENTACION: ENVASE X 1 Kg, COMPUESTO: CARBON ACTIVADO, CONCENTRACION/PUREZA: 100 % | H15: NO | I15: ='Necesidades Trimestrales'!F14 -> UNIDAD | J15: ='Necesidades Trimestrales'!L14 -> 1800 | K15: ='Necesidades Trimestrales'!G14 -> 20
A16: 5 | B16: ='Necesidades Trimestrales'!B15 -> 2.5.2-1901.7 | C16: ='Necesidades Trimestrales'!E15 -> VITAMINAS; FORMA FARMACEUTICA: AMPOLLA, PRESENTACION: 2 mL, TIPO: MONODROGA, DROGA GENERICA: VITAMINA B | H16: SI | I16: ='Necesidades Trimestrales'!F15 -> AMPOLLA | J16: ='Necesidades Trimestrales'!L15 -> 110 | K16: ='Necesidades Trimestrales'!G15 -> 100
A17: 6 | B17: ='Necesidades Trimestrales'!B16 -> 2.5.2-1872.65 | C17: ='Necesidades Trimestrales'!E16 -> ANTIANEMICOS; TIPO: MONODROGA, DROGA GENERICA: COMPLEJO VITAMINICO B, FORMA FARMACEUTICA: COMPRIMIDO, PRESENTACION: UNIDAD | H17: NO | I17: ='Necesidades Trimestrales'!F16 -> COMPRIMIDO | J17: ='Necesidades Trimestrales'!L16 -> 17.8 | K17: ='Necesidades Trimestrales'!G16 -> 10000
A18: 7 | B18: ='Necesidades Trimestrales'!B17 -> 2.5.2-1816.19 | C18: ='Necesidades Trimestrales'!E17 -> ANTIDIARREICOS; TIPO: MONODROGA, DROGA GENERICA: BISMUTO, FORMA FARMACEUTICA: CREMA, PRESENTACION: 90 mL | H18: NO | I18: ='Necesidades Trimestrales'!F17 -> FRASCO | J18: ='Necesidades Trimestrales'!L17 -> 530 | K18: ='Necesidades Trimestrales'!G17 -> 50
A19: 8 | B19: ='Necesidades Trimestrales'!B18 -> 2.5.2-1862.3 | C19: ='Necesidades Trimestrales'!E18 -> HIPOGLUCEMIANTES ORALES; TIPO: MONODROGA, FORMA FARMACEUTICA: COMPRIMIDO, PRESENTACION: 5 mGr, DROGA GENERICA: GLIBENCLAMIDA | H19: NO | I19: ='Necesidades Trimestrales'!F18 -> COMPRIMIDO | J19: ='Necesidades Trimestrales'!L18 -> 4.5 | K19: ='Necesidades Trimestrales'!G18 -> 5000
A20: 9 | B20: ='Necesidades Trimestrales'!B19 -> 2.5.2-1861.38 | C20: ='Necesidades Trimestrales'!E19 -> HIPOGLUCEMIANTES INYECTABLES; TIPO: MONODROGA, DROGA GENERICA: INSULINA ASPARTICA, FORMA FARMACEUTICA: LAPICERA PRELLENADA, PRESENTACION: 5 UNIDADES | H20: NO | I20: ='Necesidades Trimestrales'!F19 -> CAJA | J20: ='Necesidades Trimestrales'!L19 -> 15552 | K20: ='Necesidades Trimestrales'!G19 -> 1400
A21: 10 | B21: ='Necesidades Trimestrales'!B20 -> 2.5.2-1861.33 | C21: ='Necesidades Trimestrales'!E20 -> HIPOGLUCEMIANTES INYECTABLES; TIPO: MONODROGA, DROGA GENERICA: INSULINA CTE, FORMA FARMACEUTICA: AMPOLLA, PRESENTACION: ENVASE X 10 mL | H21: NO | I21: ='Necesidades Trimestrales'!F20 -> FRASCO AMPOLLA | J21: ='Necesidades Trimestrales'!L20 -> 1675 | K21: ='Necesidades Trimestrales'!G20 -> 300
A22: 11 | B22: ='Necesidades Trimestrales'!B21 -> 2.5.2-1861.10 | C22: ='Necesidades Trimestrales'!E21 -> HIPOGLUCEMIANTES INYECTABLES; TIPO: MONODROGA, DROGA GENERICA: INSULINA HUMANA NHP 100 UI, FORMA FARMACEUTICA: AMPOLLA, PRESENTACION: 10 mL | H22: NO | I22: ='Necesidades Trimestrales'!F21 -> FRASCO AMPOLLA | J22: ='Necesidades Trimestrales'!L21 -> 1675 | K22: ='Necesidades Trimestrales'!G21 -> 300
A23: 12 | B23: ='Necesidades Trimestrales'!B22 -> 2.5.2-1861.39 | C23: ='Necesidades Trimestrales'!E22 -> HIPOGLUCEMIANTES INYECTABLES; TIPO: MONODROGA, DROGA GENERICA: INSULINA HUMANA NHP 100 UI, FORMA FARMACEUTICA: LAPICERA PRELLENADA, PRESENTACION: 5 AMPOLLAS | H23: SI | I23: ='Necesidades Trimestrales'!F22 -> CAJA | J23: ='Necesidades Trimestrales'!L22 -> 8934 | K23: ='Necesidades Trimestrales'!G22 -> 4200
A24: 13 | B24: ='Necesidades Trimestrales'!B23 -> 2.5.2-1816.34 | C24: ='Necesidades Trimestrales'!E23 -> ANTIDIARREICOS; TIPO: MONODROGA, DROGA GENERICA: LOPERAMIDA, FORMA FARMACEUTICA: CAPSULA, PRESENTACION: 2 mGr | H24: NO | I24: ='Necesidades Trimestrales'!F23 -> COMPRIMIDO | J24: ='Necesidades Trimestrales'!L23 -> 2.7 | K24: ='Necesidades Trimestrales'!G23 -> 2000
A25: 14 | B25: ='Necesidades Trimestrales'!B24 -> 2.5.2-1862.1 | C25: ='Necesidades Trimestrales'!E24 -> HIPOGLUCEMIANTES ORALES; TIPO: MONODROGA, DROGA GENERICA: METFORMINA, FORMA FARMACEUTICA: COMPRIMIDO, PRESENTACION: 500 mGr | H25: NO | I25: ='Necesidades Trimestrales'!F24 -> COMPRIMIDO | J25: ='Necesidades Trimestrales'!L24 -> 5.7 | K25: ='Necesidades Trimestrales'!G24 -> 50000
A26: 15 | B26: ='Necesidades Trimestrales'!B25 -> 2.5.2-1862.16 | C26: ='Necesidades Trimestrales'!E25 -> HIPOGLUCEMIANTES ORALES; TIPO: MONODROGA, DROGA GENERICA: METFORMINA, FORMA FARMACEUTICA: COMPRIMIDO, PRESENTACION: 850 mGr | H26: NO | I26: ='Necesidades Trimestrales'!F25 -> COMPRIMIDO | J26: ='Necesidades Trimestrales'!L25 -> 7.2 | K26: ='Necesidades Trimestrales'!G25 -> 80000
... A37: 26 | B37: ='Necesidades Trimestrales'!B36 -> 2.5.2-1901.130 | C37: ='Necesidades Trimestrales'!E36 -> VITAMINAS; TIPO: MONODROGA, DROGA GENERICA: VITAMINA D3 2000 UI/ML, FORMA FARMACEUTICA: SOLUCION, PRESENTACION: 2 ML | H37: NO | I37: ='Necesidades Trimestrales'!F36 -> FRASCO | J37: ='Necesidades Trimestrales'!L36 -> 958 | K37: ='Necesidades Trimestrales'!G36 -> 500
A38: Costo total estimado: PESOS SETENTA Y SIETE MILLONES SETECIENTOS OCHENTA Y DOS MIL SEISCIENTOS con 00/100. | J38: =SUMPRODUCT(J12:J37,K12:K37) -> 77782600

Sheet APG DPFeI
A1: EJERCICIO: | D1: ='Necesidades Trimestrales'!C6 -> 2022 | P1: AUTORIZACION PARA GASTAR
A4: JURISDICCIÓN: | G4: ='NP DPFeI'!D3 -> 040 - MINISTERIO DE SALUD
A5: SAF: | G5: ='NP DPFeI'!D4 -> 011 - DIRECCION PROVINCIAL DE ADMINISTRACION - MS
A6: UNIDAD EJECUTORA: | G6: ='NP DPFeI'!D5 -> 469 - DIRECCION PROVINCIAL DE FARMACIA E INSUMOS
A7: DEPENDENCIA SOLICITANTE: | G7: ='NP DPFeI'!D6 -> 469 - DIRECCION PROVINCIAL DE FARMACIA E INSUMOS
A8: AUTORIZACIÓN:
A9: Señor Jefe de Servicio Administrativo Financiero:
A10: ="Autorizo la realización de los trámites correspondientes, a fin de proveer a este Organismo los bienes y/o servicios que se detallan en Nota de Pedido N° " & 'NP DPFeI'!K1&", afectando la erogación resultante a los créditos presupuestarios aprobados a favor de esta Unidad Ejecutora, conforme al siguiente detalle:" -> Autorizo la realización de los trámites correspondientes, a fin de proveer a este Organismo los bienes y/o servicios que se detallan en Nota de Pedido N° xxx/2022, afectando la erogación resultante a los créditos presupuestarios aprobados a favor de esta Unidad Ejecutora, conforme al siguiente detalle:
A12: IMPUTACIÓN PRESUPUESTARIA
A13: CÓDIGO | O13: DENOMINACIÓN DE LA PARTIDA PRESUPUESTARIA | Q13: IMPORTE
A14: PR | B14: SB | C14: PY | D14: AC | E14: OB | F14: UG | G14: FIN | H14: FUN | I14: I | J14: P | K14: P | L14: SubP | M14: M | N14: FF
A15: 30 | D15: 1 | F15: 4901 | G15: 3 | H15: 1 | I15: 2 | J15: 5 | K15: 2 | M15: 1 | N15: 1.1 | O15: Product. Farmaceut. Y Medicinales | Q15: ='NP DPFeI'!J38 -> 77782600
A23: TOTAL DE PESOS: SETENTA Y SIETE MILLONES SETECIENTOS OCHENTA Y DOS MIL SEISCIENTOS con 00/100. | Q23: =SUM(Q15:Q22) -> 77782600
A25: JUSTIFICACIÓN:
A26: ='NP DPFeI'!D8 -> Adquisición de TRACTO ALIMENTARIO Y METABOLISMO / VITAMINAS Y OTROS /ANTIDIABETICOS E INSULINAS

Sheet NP SAME
A1: NOTA DE PEDIDO | J1: N° | K1: xxx/2022
A3: JURISDICCIÓN: | D3: ='Necesidades Trimestrales'!C4 -> 040 - MINISTERIO DE SALUD
A4: SAF: | D4: ='Necesidades Trimestrales'!C5 -> 011 - DIRECCION PROVINCIAL DE ADMINISTRACION - MS
A5: UNIDAD EJECUTORA: | D5: DIRECCION PROVINCIAL SISTEMA DE ATENCION MEDICA DE EMERGENCIA
A6: DEPENDENCIA SOLICITANTE: | D6: DIRECCION PROVINCIAL SISTEMA DE ATENCION MEDICA DE EMERGENCIA
A7: PERIODO UTILIZACIÓN: | D7: Semestral
A8: OBJETO: | D8: Adquisición de TRACTO ALIMENTARIO Y METABOLISMO / VITAMINAS Y OTROS /ANTIDIABETICOS E INSULINAS
A10: Ítem | B10: Codigo Item | C10: DESCRIPCIÓN | H10: Adjunta Detalle Técnico | I10: Unidad Medida | J10: Precio Unitario Estimado | K10: Cantidad Solicitada
A12: 1 | B12: ='Necesidades Trimestrales'!B10 -> 2.5.2-1843.63 | C12: ='Necesidades Trimestrales'!E10 -> ANTIESPASMODICOS; TIPO: MONODROGA, DROGA GENERICA: ATROPINA 1%, FORMA FARMACEUTICA: AMPOLLA, PRESENTACION: ENVASE X 1 mL | H12: NO | I12: ='Necesidades Trimestrales'!F10 -> AMPOLLA | J12: ='Necesidades Trimestrales'!L10 -> 50.4 | K12: ='Necesidades Trimestrales'!I10 -> 200
A13: 2 | B13: ='Necesidades Trimestrales'!B11 -> 2.5.2-1843.51 | C13: ='Necesidades Trimestrales'!E11 -> ANTIESPASMODICOS; TIPO: MONODROGA, DROGA GENERICA: HIOSCINA N-BUTILBROMURO 20 MG, FORMA FARMACEUTICA: AMPOLLA, PRESENTACION: 1 ML | H13: NO | I13: ='Necesidades Trimestrales'!F11 -> AMPOLLA | J13: ='Necesidades Trimestrales'!L11 -> 65 | K13: ='Necesidades Trimestrales'!I11 -> 200
A14: 3 | B14: ='Necesidades Trimestrales'!B13 -> 2.5.2-1724.57 | C14: ='Necesidades Trimestrales'!E13 -> ANALGESICOS ; TIPO: ASOCIACION, DROGA GENERICA: DIPIRONA+ HIOSCINA, FORMA FARMACEUTICA: AMPOLLA, PRESENTACION: AMPOLLA X 5 mL | H14: NO | I14: ='Necesidades Trimestrales'!F13 -> AMPOLLA | J14: ='Necesidades Trimestrales'!L13 -> 92 | K14: ='Necesidades Trimestrales'!I13 -> 200
A15: 4 | B15: ='Necesidades Trimestrales'!B28 -> 2.5.2-6910.6 | C15: ='Necesidades Trimestrales'!E28 -> ANTIEMETICOS; TIPO: MONODROGA, DROGA GENERICA: METOCLOPRAMIDA, FORMA FARMACEUTICA: AMPOLLA, PRESENTACION: 2 mL | H15: NO | I15: ='Necesidades Trimestrales'!F28 -> AMPOLLA | J15: ='Necesidades Trimestrales'!L28 -> 35.8 | K15: ='Necesidades Trimestrales'!I28 -> 200
A16: 5 | B16: ='Necesidades Trimestrales'!B32 -> 2.5.2-1841.17 | C16: ='Necesidades Trimestrales'!E32 -> ANTIACIDOS; TIPO: MONODROGA, DROGA GENERICA: RANITIDINA, FORMA FARMACEUTICA: AMPOLLA, PRESENTACION: UNIDAD | H16: NO | I16: ='Necesidades Trimestrales'!F32 -> AMPOLLA | J16: ='Necesidades Trimestrales'!L32 -> 47.5 | K16: ='Necesidades Trimestrales'!I32 -> 200
A17: Costo total estimado: PESOS CINCUENTA Y OCHO MIL CIENTO CUARENTA con 00/100. | J17: =SUMPRODUCT(J12:J16,K12:K16) -> 58140

Sheet APG SAME
A1: EJERCICIO: | D1: ='Necesidades Trimestrales'!C6 -> 2022 | P1: AUTORIZACION PARA GASTAR
A4: JURISDICCIÓN: | G4: ='NP SAME'!D3 -> 040 - MINISTERIO DE SALUD
A5: SAF: | G5: ='NP SAME'!D4 -> 011 - DIRECCION PROVINCIAL DE ADMINISTRACION - MS
A6: UNIDAD EJECUTORA: | G6: ='NP SAME'!D5 -> DIRECCION PROVINCIAL SISTEMA DE ATENCION MEDICA DE EMERGENCIA
A7: DEPENDENCIA SOLICITANTE: | G7: ='NP SAME'!D6 -> DIRECCION PROVINCIAL SISTEMA DE ATENCION MEDICA DE EMERGENCIA
A8: AUTORIZACIÓN:
A9: Señor Jefe de Servicio Administrativo Financiero:
A10: ="Autorizo la realización de los trámites correspondientes, a fin de proveer a este Organismo los bienes y/o servicios que se detallan en Nota de Pedido N° " & 'NP SAME'!K1&", afectando la erogación resultante a los créditos presupuestarios aprobados a favor de esta Unidad Ejecutora, conforme al siguiente detalle:" -> Autorizo la realización de los trámites correspondientes, a fin de proveer a este Organismo los bienes y/o servicios que se detallan en Nota de Pedido N° xxx/2022, afectando la erogación resultante a los créditos presupuestarios aprobados a favor de esta Unidad Ejecutora, conforme al siguiente detalle:
A12: IMPUTACIÓN PRESUPUESTARIA
A13: CÓDIGO | O13: DENOMINACIÓN DE LA PARTIDA PRESUPUESTARIA | Q13: IMPORTE
A14: PR | B14: SB | C14: PY | D14: AC | E14: OB | F14: UG | G14: FIN | H14: FUN | I14: I | J14: P | K14: P | L14: SubP | M14: M | N14: FF
A15: 31 | D15: 1 | F15: 4901 | G15: 3 | H15: 1 | I15: 2 | J15: 5 | K15: 2 | M15: 1 | N15: 1.1 | O15: Product. Farmaceut. Y Medicinales | Q15: ='NP SAME'!J17 -> 58140
A23: TOTAL DE PESOS: CINCUENTA Y OCHO MIL CIENTO CUARENTA con 00/100. | Q23: =SUM(Q15:Q22) -> 58140
A25: JUSTIFICACIÓN:
A26: ='NP SAME'!D8 -> Adquisición de TRACTO ALIMENTARIO Y METABOLISMO / VITAMINAS Y OTROS /ANTIDIABETICOS E INSULINAS
