Workbook

Sheet Necesidades Trimestrales
B2: Pedido de Necesidades Trimestrales
A4: JURISDICCION: | C4: 40 - Ministerio de Salud
A5: SAF N°: | C5: 28 - MATERNIDAD PROVINCIAL 25 DE MAYO
A6: EJERCICIO: | C6: 2022
A7: TRIMESTRE: | C7: 2
A9: ID | B9: CODIGO ITEM | C9: RUBRO DE COMPRA | D9: I.P.P. | E9: DESCRIPCION | F9: UNIDAD DE MEDIDA | G9: CANTIDAD | H9: PRECIO UNITARIO ESTIMADO | I9: IMPORTE TOTAL ESTIMADO
A10: 1 | B10: 2.9.2-262.40 | C10: LIBRERIA,PAP. Y UTILES OFICINA | D10: =LEFT(B10,5) -> 2.9.2 | E10: ADHESIVOS P/PAPEL; PRESENTACION: 50 mL, TIPO: SINTETICO TRANSPARENTE | F10: unidad | G10: 250 | H10: 85 | I10: =G10*H10 -> 21250
A11: 2 | B11: 2.9.2-1428.14 | C11: LIBRERIA,PAP. Y UTILES OFICINA | D11: =LEFT(B11,5) -> 2.9.2 | E11: BANDAS ELASTICAS; DIAMETRO: 5 Cm, PRESENTACION: CAJA DE 50 GR, ESPESOR: 2 mm | F11: caja | G11: 150 | H11: 138 | I11: =G11*H11 -> 20700
A12: 3 | B12: 2.9.2-317.1 | C12: LIBRERIA,PAP. Y UTILES OFICINA | D12: =LEFT(B12,5) -> 2.9.2 | E12: BOLIGRAFOS; COLOR TINTA: AZUL, TRAZO: 0,7 mm | F12: unidad | G12: 300 | H12: 87.5 | I12: =G12*H12 -> 26250
A13: 4 | B13: 2.9.2-317.5 | C13: LIBRERIA,PAP. Y UTILES OFICINA | D13: =LEFT(B13,5) -> 2.9.2 | E13: BOLIGRAFOS; TRAZO 1,0mm | F13: unidad | G13: 300 | H13: 32 | I13: =G13*H13 -> 9600
A14: 5 | B14: 2.9.2-317.17 | C14: LIBRERIA,PAP. Y UTILES OFICINA | D14: =LEFT(B14,5) -> 2.9.2 | E14: BOLIGRAFOS; TRAZO: GRUESO, COLOR TINTA: NEGRO | F14: unidad | G14: 300 | H14: 32 | I14: =G14*H14 -> 9600
A15: 6 | B15: 2.9.2-317.32 | C15: LIBRERIA,PAP. Y UTILES OFICINA | D15: =LEFT(B15,5) -> 2.9.2 | E15: BOLIGRAFOS; TRAZO: 0,8 mm | F15: unidad | G15: 300 | H15: 87.5 | I15: =G15*H15 -> 26250
A16: 7 | B16: 2.9.2-700.2 | C16: LIBRERIA,PAP. Y UTILES OFICINA | D16: =LEFT(B16,5) -> 2.9.2 | E16: BROCHES P/ABROCHADORA; NUMERO: 21/6, PRESENTACION: CAJA X 1000 UNIDADES | F16: caja | G16: 200 | H16: 180 | I16: =G16*H16 -> 36000
A17: 8 | B17: 2.9.2-700.56 | C17: LIBRERIA,PAP. Y UTILES OFICINA | D17: =LEFT(B17,5) -> 2.9.2 | E17: BROCHES P/ABROCHADORA; NUMERO: 10/50, PRESENTACION: CAJA X 2000 UN | F17: caja | G17: 200 | H17: 129 | I17: =G17*H17 -> 25800
A18: 9 | B18: 2.9.2-6873.6 | C18: LIBRERIA,PAP. Y UTILES OFICINA | D18: =LEFT(B18,5) -> 2.9.2 | E18: BROCHES PLASTICOS; TIPO: NEPACO, TAMAÑO: Nº 2, PRESENTACION: CAJA X 50 UN | F18: caja | G18: 300 | H18: 402 | I18: =G18*H18 -> 120600
A19: 10 | B19: 2.9.2-1153.19 | C19: LIBRERIA,PAP. Y UTILES OFICINA | D19: =LEFT(B19,5) -> 2.9.2 | E19: CINTAS ADHESIVAS; TIPO: DE ENMASCARAR, ANCHO: 24 mm, LARGO ROLLO: 50 M, ACCESORIO: SIN, MATERIAL: PAPEL, LARGO: 50 M | F19: unidad | G19: 550 | H19: 365.5 | I19: =G19*H19 -> 201025
A20: 11 | B20: 2.9.2-1153.166 | C20: LIBRERIA,PAP. Y UTILES OFICINA | D20: =LEFT(B20,5) -> 2.9.2 | E20: CINTAS ADHESIVAS; TIPO: P/EMBALAR, ANCHO: 48 mm, LARGO: 40 M, MATERIAL: TRANSPARENTE, ACCESORIO: SIN | F20: unidad | G20: 150 | H20: 161 | I20: =G20*H20 -> 24150
A21: 12 | B21: 2.9.2-660.7 | C21: LIBRERIA,PAP. Y UTILES OFICINA | D21: =LEFT(B21,5) -> 2.9.2 | E21: CLIPS P/PAPEL; NUMERO: 5, MATERIAL: METAL, CANT. X CAJA: 50, PRESENTACION: CAJA X 50 | F21: caja | G21: 100 | H21: 129.5 | I21: =G21*H21 -> 12950
... A52: 43 | B52: 2.9.2-1358.354 | C52: LIBRERIA,PAP. Y UTILES OFICINA | D52: =LEFT(B52,5) -> 2.9.2 | E52: CARPETAS; MATERIAL PLASTICO - TAMAÑO OFICIO. | F52: unidad | G52: 200 | H52: 100 | I52: =G52*H52 -> 20000
B55: Especificidades Item N° 1 al 43
B57: Descripción técnica
B59: Plazos de entrega | D59: 10 Dias habiles desde la firma del instrumento contractual
B61: Lugar de Entrega : | C61: MATERNIDAD PROVINCIAL 25 DE MAYO , HERNADO DE PEDRAZA 1650-SECTOR ECONOMATO
B63: Hora de entrega: | D63: 8 a 12 Hs
B65: Calidad Minima esperada
B67: Mantenimiento
C68: 30 dias habiles
B69: Garantia
B75: Especificidades Item N° 4
B77: Descripción técnica
C78: BOLIGRAFOS; TRAZO 1,0mm TINTA COLOR AZUL. TIPO BIG
B80: Plazos de entrega | C80: 10 Dias habiles desde la firma del instrumento contractual
B82: Lugar de entrega: | C82: MATERNIDAD PROVINCIAL 25 DE MAYO , HERNADO DE PEDRAZA 1650-SECTOR ECONOMATO
B84: Hora de entrega: | D84: 8 a 12 Hs
B86: Calidad Minima esperada
B88: Mantenimiento
C89: 30 dias habiles
B90: Garantia
B94: Especificidades Item N° 6:
B96: Descripción técnica
...

Sheet NotaPedido
A1: NOTA DE PEDIDO | J1: N° | K1: 31/2022
A3: JURISDICCIÓN: | D3: ='Necesidades Trimestrales'!C4 -> 40 - Ministerio de Salud
A4: SAF: | D4: ='Necesidades Trimestrales'!C5 -> 28 - MATERNIDAD PROVINCIAL 25 DE MAYO
A5: UNIDAD EJECUTORA: | D5: 171-Direccion de Administración
A6: DEPENDENCIA SOLICITANTE: | D6: Economato y nutrición
A7: PERIODO UTILIZACIÓN: | D7: ='Necesidades Trimestrales'!C7 & "° Trimestre - Año " & 'Necesidades Trimestrales'!C6 -> 2° Trimestre - Año 2022
A8: OBJETO: | D8: Adquisición de Artículos de librería y papelería
A10: Ítem | B10: Codigo Item | C10: DESCRIPCIÓN | H10: Adjunta Detalle Técnico | I10: Unidad Medida | J10: Precio Unitario Estimado | K10: Cantidad Solicitada
A12: ='Necesidades Trimestrales'!A10 -> 1 | B12: ='Necesidades Trimestrales'!B10 -> 2.9.2-262.40 | C12: ='Necesidades Trimestrales'!E10 -> ADHESIVOS P/PAPEL; PRESENTACION: 50 mL, TIPO: SINTETICO TRANSPARENTE | H12: NO | I12: ='Necesidades Trimestrales'!F10 -> unidad | J12: ='Necesidades Trimestrales'!H10 -> 85 | K12: ='Necesidades Trimestrales'!G10 -> 250
A13: ='Necesidades Trimestrales'!A11 -> 2 | B13: ='Necesidades Trimestrales'!B11 -> 2.9.2-1428.14 | C13: ='Necesidades Trimestrales'!E11 -> BANDAS ELASTICAS; DIAMETRO: 5 Cm, PRESENTACION: CAJA DE 50 GR, ESPESOR: 2 mm | H13: NO | I13: ='Necesidades Trimestrales'!F11 -> caja | J13: ='Necesidades Trimestrales'!H11 -> 138 | K13: ='Necesidades Trimestrales'!G11 -> 150
A14: ='Necesidades Trimestrales'!A12 -> 3 | B14: ='Necesidades Trimestrales'!B12 -> 2.9.2-317.1 | C14: ='Necesidades Trimestrales'!E12 -> BOLIGRAFOS; COLOR TINTA: AZUL, TRAZO: 0,7 mm | H14: NO | I14: ='Necesidades Trimestrales'!F12 -> unidad | J14: ='Necesidades Trimestrales'!H12 -> 87.5 | K14: ='Necesidades Trimestrales'!G12 -> 300
A15: ='Necesidades Trimestrales'!A13 -> 4 | B15: ='Necesidades Trimestrales'!B13 -> 2.9.2-317.5 | C15: ='Necesidades Trimestrales'!E13 -> BOLIGRAFOS; TRAZO 1,0mm | H15: si | I15: ='Necesidades Trimestrales'!F13 -> unidad | J15: ='Necesidades Trimestrales'!H13 -> 32 | K15: ='Necesidades Trimestrales'!G13 -> 300
A16: ='Necesidades Trimestrales'!A14 -> 5 | B16: ='Necesidades Trimestrales'!B14 -> 2.9.2-317.17 | C16: ='Necesidades Trimestrales'!E14 -> BOLIGRAFOS; TRAZO: GRUESO, COLOR TINTA: NEGRO | H16: NO | I16: ='Necesidades Trimestrales'!F14 -> unidad | J16: ='Necesidades Trimestrales'!H14 -> 32 | K16: ='Necesidades Trimestrales'!G14 -> 300
A17: ='Necesidades Trimestrales'!A15 -> 6 | B17: ='Necesidades Trimestrales'!B15 -> 2.9.2-317.32 | C17: ='Necesidades Trimestrales'!E15 -> BOLIGRAFOS; TRAZO: 0,8 mm | H17: si | I17: ='Necesidades Trimestrales'!F15 -> unidad | J17: ='Necesidades Trimestrales'!H15 -> 87.5 | K17: ='Necesidades Trimestrales'!G15 -> 300
A18: ='Necesidades Trimestrales'!A16 -> 7 | B18: ='Necesidades Trimestrales'!B16 -> 2.9.2-700.2 | C18: ='Necesidades Trimestrales'!E16 -> BROCHES P/ABROCHADORA; NUMERO: 21/6, PRESENTACION: CAJA X 1000 UNIDADES | H18: NO | I18: ='Necesidades Trimestrales'!F16 -> caja | J18: ='Necesidades Trimestrales'!H16 -> 180 | K18: ='Necesidades Trimestrales'!G16 -> 200
A19: ='Necesidades Trimestrales'!A17 -> 8 | B19: ='Necesidades Trimestrales'!B17 -> 2.9.2-700.56 | C19: ='Necesidades Trimestrales'!E17 -> BROCHES P/ABROCHADORA; NUMERO: 10/50, PRESENTACION: CAJA X 2000 UN | H19: NO | I19: ='Necesidades Trimestrales'!F17 -> caja | J19: ='Necesidades Trimestrales'!H17 -> 129 | K19: ='Necesidades Trimestrales'!G17 -> 200
A20: ='Necesidades Trimestrales'!A18 -> 9 | B20: ='Necesidades Trimestrales'!B18 -> 2.9.2-6873.6 | C20: ='Necesidades Trimestrales'!E18 -> BROCHES PLASTICOS; TIPO: NEPACO, TAMAÑO: Nº 2, PRESENTACION: CAJA X 50 UN | H20: NO | I20: ='Necesidades Trimestrales'!F18 -> caja | J20: ='Necesidades Trimestrales'!H18 -> 402 | K20: ='Necesidades Trimestrales'!G18 -> 300
A21: ='Necesidades Trimestrales'!A19 -> 10 | B21: ='Necesidades Trimestrales'!B19 -> 2.9.2-1153.19 | C21: ='Necesidades Trimestrales'!E19 -> CINTAS ADHESIVAS; TIPO: DE ENMASCARAR, ANCHO: 24 mm, LARGO ROLLO: 50 M, ACCESORIO: SIN, MATERIAL: PAPEL, LARGO: 50 M | H21: NO | I21: ='Necesidades Trimestrales'!F19 -> unidad | J21: ='Necesidades Trimestrales'!H19 -> 365.5 | K21: ='Necesidades Trimestrales'!G19 -> 550
A22: ='Necesidades Trimestrales'!A20 -> 11 | B22: ='Necesidades Trimestrales'!B20 -> 2.9.2-1153.166 | C22: ='Necesidades Trimestrales'!E20 -> CINTAS ADHESIVAS; TIPO: P/EMBALAR, ANCHO: 48 mm, LARGO: 40 M, MATERIAL: TRANSPARENTE, ACCESORIO: SIN | H22: NO | I22: ='Necesidades Trimestrales'!F20 -> unidad | J22: ='Necesidades Trimestrales'!H20 -> 161 | K22: ='Necesidades Trimestrales'!G20 -> 150
A23: ='Necesidades Trimestrales'!A21 -> 12 | B23: ='Necesidades Trimestrales'!B21 -> 2.9.2-660.7 | C23: ='Necesidades Trimestrales'!E21 -> CLIPS P/PAPEL; NUMERO: 5, MATERIAL: METAL, CANT. X CAJA: 50, PRESENTACION: CAJA X 50 | H23: NO | I23: ='Necesidades Trimestrales'!F21 -> caja | J23: ='Necesidades Trimestrales'!H21 -> 129.5 | K23: ='Necesidades Trimestrales'!G21 -> 100
... A50: ='Necesidades Trimestrales'!A48 -> 39 | B50: ='Necesidades Trimestrales'!B48 -> 2.3.1-860.19 | C50: ='Necesidades Trimestrales'!E48 -> FICHAS P/ARCHIVOS; MATERIAL: CARTULINA, IMPRESION: RAYADA, DIMENSION: 14,8 X 21 Cm, PAQUETE: X 100 HOJAS, FONDO: BLANCO | H50: NO | I50: ='Necesidades Trimestrales'!F48 -> unidad | J50: ='Necesidades Trimestrales'!H48 -> 390 | K50: ='Necesidades Trimestrales'!G48 -> 50
A51: 40 | B51: ='Necesidades Trimestrales'!B49 -> 2.9.2-758.31 | C51: ='Necesidades Trimestrales'!E49 -> TIJERAS P/CORTAR PAPELES; LONG.DE CUERPO: 17 Cm, MATERIAL: METAL, CUCHILLA: PUNTIAGUDA, MANGO: PLASTICO | H51: NO | I51: ='Necesidades Trimestrales'!F49 -> unidad | J51: ='Necesidades Trimestrales'!H49 -> 403 | K51: ='Necesidades Trimestrales'!G49 -> 30
A52: 41 | B52: ='Necesidades Trimestrales'!B50 -> 2.9.2-758.25 | C52: ='Necesidades Trimestrales'!E50 -> TIJERAS P/CORTAR PAPELES; LONG.DE CUERPO: 22 Cm, MATERIAL: ACERO INOXIDABLE, CUCHILLA: REDONDEADAS, MANGO: ERGONOMETRICO DE PLASTICO | H52: NO | I52: ='Necesidades Trimestrales'!F50 -> unidad | J52: ='Necesidades Trimestrales'!H50 -> 563 | K52: ='Necesidades Trimestrales'!G50 -> 50
A53: 42 | B53: ='Necesidades Trimestrales'!B51 -> 2.9.2-1358.353 | C53: ='Necesidades Trimestrales'!E51 -> CARPETAS; MATERIAL PLASTICO - TAMAÑO A4. | H53: SI | I53: ='Necesidades Trimestrales'!F51 -> unidad | J53: ='Necesidades Trimestrales'!H51 -> 85 | K53: ='Necesidades Trimestrales'!G51 -> 200
A54: 43 | B54: ='Necesidades Trimestrales'!B52 -> 2.9.2-1358.354 | C54: =+'Necesidades Trimestrales'!E52 -> CARPETAS; MATERIAL PLASTICO - TAMAÑO OFICIO. | H54: SI | I54: =+I53 -> unidad | J54: ='Necesidades Trimestrales'!H52 -> 100 | K54: ='Necesidades Trimestrales'!G52 -> 200
A55: Costo total estimado: DOS MILLONES CUATROCIENTOS SEIS MIL NOVECIENTOS CUARENTA Y CINCO CON 00/100. | J55: =SUMPRODUCT(J12:J54,K12:K54) -> 2406945

Sheet Autor Gastar
A1: EJERCICIO: | D1: ='Necesidades Trimestrales'!C6 -> 2022 | P1: AUTORIZACION PARA GASTAR
A4: JURISDICCIÓN: | G4: =NotaPedido!D3 -> 40 - Ministerio de Salud
A5: SAF: | G5: =NotaPedido!D4 -> 28 - MATERNIDAD PROVINCIAL 25 DE MAYO
A6: UNIDAD EJECUTORA: | G6: =NotaPedido!D5 -> 171-Direccion de Administración
A7: DEPENDENCIA SOLICITANTE: | G7: =NotaPedido!D6 -> Economato y nutrición
A8: AUTORIZACIÓN:
A9: Señor Jefe de Servicio Administrativo Financiero:
A10: ="Autorizo la realización de los trámites correspondientes, a fin de proveer a este Organismo los bienes y/o servicios que se detallan en Nota de Pedido N° " & NotaPedido!K1&", afectando la erogación resultante a los créditos presupuestarios aprobados a favor de esta Unidad Ejecutora, conforme al siguiente detalle:" -> Autorizo la realización de los trámites correspondientes, a fin de proveer a este Organismo los bienes y/o servicios que se detallan en Nota de Pedido N° 31/2022, afectando la erogación resultante a los créditos presupuestarios aprobados a favor de esta Unidad Ejecutora, conforme al siguiente detalle:
A12: IMPUTACIÓN PRESUPUESTARIA
A13: CÓDIGO | O13: DENOMINACIÓN DE LA PARTIDA PRESUPUESTARIA | Q13: IMPORTE
A14: PR | B14: SB | C14: PY | D14: AC | E14: OB | F14: UG | G14: FIN | H14: FUN | I14: I | J14: P | K14: P | L14: SubP | M14: M | N14: FF
A15: 42 | D15: 3 | F15: 4901 | G15: 1 | H15: 6 | I15: 2 | J15: 3 | K15: 1 | M15: 1 | N15: 1.1 | O15: Papel de Escritorio y Cartón | Q15: 1559550
A16: 42 | D16: 3 | F16: 4901 | G16: 1 | H16: 6 | I16: 2 | J16: 5 | K16: 8 | M16: 1 | N16: 1.1 | O16: Productos de material plastico | Q16: 68850
A17: 42 | D17: 3 | F17: 4901 | G17: 1 | H17: 6 | I17: 2 | J17: 9 | K17: 2 | M17: 1 | N17: 1.1 | O17: Utiles de Escritorio, Oficina y Enseñanza | Q17: 778545
A22: TOTAL DE PESOS: DOS MILLONES CUATROCIENTOS SEIS MIL NOVECIENTOS CUARENTA Y CINCO CON 00/100. | Q22: =SUM(Q15:Q21) -> 2406945
A24: JUSTIFICACIÓN:
A25: ="Para la "& NotaPedido!D8 &" para ser destinados a " & NotaPedido!D6 &" de la Maternidad Provincial 25 de Mayo del Ministerio de Salud." -> Para la Adquisición de Artículos de librería y papelería para ser destinados a Economato y nutrición de la Maternidad Provincial 25 de Mayo del Ministerio de Salud.
