Workbook

Sheet SAF 011
A1: 2022
B2: Pedido de Necesidades Trimestrales
A4: JURISDICCION: | C4: 040 - MINISTERIO DE SALUD
A5: SAF N°: | C5: 011 - DIRECCION PROVINCIAL DE ADMINISTRACION - MINISTERIO DE SALUD
A6: EJERCICIO: | C6: 2022
A7: TRIMESTRE: | C7: CUARTO
A9: ID | B9: CODIGO ITEM | C9: RUBRO DE COMPRA | D9: I.P.P. | E9: DESCRIPCION | F9: UNIDAD DE MEDIDA | G9: CANTIDAD TOTAL | H9: PRECIO UNITARIO ESTIMADO | I9: IMPORTE TOTAL ESTIMADO | J9: ESPECIFICACION TECNICA
A10: 1 | B10: 2.5.1-9043.2 | C10: QUIMICOS | D10: 2.5.1. | E10: ACEITES Y GRASAS; COMPUESTO QUIMICO: ACEITE DE INMERSION, ESTADO: LIQUIDO, CALIDAD: PRO ANALISIS, CONCENTRACION/PUREZA: 99,9 %, PRESENTACION: ENVASE X 100 mL | F10: FRASCO | G10: 40 | H10: 5017 | I10: 200680 | J10: ACEITE DE INMERSION 100 ML Tipo CICARELLI
A11: 2 | B11: 2.5.1-9017.381 | C11: QUIMICOS | D11: 2.5.1. | E11: ANTICUERPOS P/LABORATORIO; NOMBRE: ANTI-A, ESTADO: LIQUIDO, MARCADO CON: SIN MARCAR, ORIGEN: HUMANO, PRESENTACION: ENVASE X 10 mL, TIPO: MONOCLONAL | F11: FRASCO | G11: 100 | H11: 876 | I11: 87600
A12: 3 | B12: 2.5.1-9017.136 | C12: QUIMICOS | D12: 2.5.1. | E12: ANTICUERPOS P/LABORATORIO; NOMBRE: ANTI-B, ESTADO: SOLUCION, MARCADO CON: SIN MARCAR, ORIGEN: HUMANO, PRESENTACION: ENVASE X 10 mL, TIPO: MONOCLONAL | F12: FRASCO | G12: 100 | H12: 876 | I12: 87600
A13: 4 | B13: 2.5.1-9017.137 | C13: QUIMICOS | D13: 2.5.1. | E13: ANTICUERPOS P/LABORATORIO; NOMBRE: ANTI-D, ESTADO: SOLUCION, MARCADO CON: SIN MARCAR, ORIGEN: HUMANO, PRESENTACION: ENVASE X 10 mL, TIPO: MONOCLONAL | F13: UNIDAD | G13: 100 | H13: 1657 | I13: 165700 | J13: ANTI-D (RHO) MONOCLONAL-FRASCOS 10 ML
A14: 5 | B14: 2.5.1-9007.169 | C14: QUIMICOS | D14: 2.5.1. | E14: COMP. HIDROXILADOS Y ALCOHOLES; COMPUESTO QUIMICO: METANOL, ESTADO: LIQUIDO, CALIDAD: PRO ANALISIS, CONCENTRACION/PUREZA: 98 %, PRESENTACION: ENVASE X 1 L | F14: BOTELLA | G14: 50 | H14: 3980 | I14: 199000 | J14: ALCOHOL METILICO X LITRO Tipo CICARELLI
A15: 6 | B15: 2.5.1-9019.119 | C15: QUIMICOS | D15: 2.5.1. | E15: HIDRATOS DE CARBONO; COMPUESTO QUIMICO: GLUCOCURVE 75 GR, ESTADO: SOLIDO, CALIDAD: PRO ANALISIS, CONCENTRACION/PUREZA: SIN VALOR, PRESENTACION: ENVASE X 10 SOBRES | F15: CAJA | G15: 100 | H15: 1781 | I15: 178100 | J15: GLUCOCURVE SDA 75 GR X 10 SOBRES Tipo GLUCOCURVE
A16: 7 | B16: 2.9.9-3646.23 | C16: PROD. MEDICO/FARMACEUTICOS/LAB | D16: 2.5.1. | E16: INSUMOS P/CONTADOR HEMATOL; TIPO: DETERGENTE, USO: CONTADOR HEMATOLOGICO MINDRAY | F16: BIDON | G16: 15 | H16: 10600 | I16: 159000 | J16: RINSE DETERGENTE X 20 LT Tipo MINDRAY
A17: 8 | B17: 2.9.9-3646.22 | C17: PROD. MEDICO/FARMACEUTICOS/LAB | D17: 2.5.1. | E17: INSUMOS P/CONTADOR HEMATOL; TIPO: DILUYENTE, USO: CONTADOR HEMATOLOGICO MINDRAY | F17: BIDON | G17: 60 | H17: 11200 | I17: 672000 | J17: DILUYENTE 20 LITROS Tipo MINDRAY
A18: 9 | B18: 2.9.9-3646.21 | C18: PROD. MEDICO/FARMACEUTICOS/LAB | D18: 2.5.1. | E18: INSUMOS P/CONTADOR HEMATOL; TIPO: LISANTE, USO: CONTADOR HEMATOLOGICO MINDRAY | F18: BOTELLA | G18: 40 | H18: 17700 | I18: 708000 | J18: LISANTE Tipo MINDRAY X 500 ML
A19: 10 | B19: 2.5.1-9016.223 | C19: QUIMICOS | D19: 2.5.1. | E19: MEDIOS DE CULTIVO Y SUPLEMENTO; NOMBRE DEL PRODUCTO: AGAR DIFERENCIAL ACETATO, ESTADO: SOLIDO, PRESENTACION: ENVASE X 500 GR | F19: FRASCO | G19: 2 | H19: 18017 | I19: 36034 | J19: MEDIO ACETATO DIFERENCIAL AGAR X 500 GR
A20: 11 | B20: 2.5.1-9016.547 | C20: QUIMICOS | D20: 2.5.1. | E20: MEDIOS DE CULTIVO Y SUPLEMENTO; NOMBRE DEL PRODUCTO: AGAR SANGRE C/POLINUTRIENTES, ESTADO: SOLIDO EN PLACA, PRESENTACION: ENVASE X 10 UN | F20: CAJA | G20: 20 | H20: 12000 | I20: 240000 | J20: MEDIO AGAR SANGRE PLACA X 10 UNIDADES Tipo BIOMERIEUX
A21: 12 | B21: 2.5.1-9016.1014 | C21: QUIMICOS | D21: 2.5.1. | E21: MEDIOS DE CULTIVO Y SUPLEMENTO; NOMBRE DEL PRODUCTO: CALDO TODD HEWITT, ESTADO: LIQUIDO, PRESENTACION: 10 FRASCOS X 10 ML | F21: CAJA | G21: 10 | H21: 38000 | I21: 380000 | J21: CALDO TODD HEWITT 10 FRASCOS X 10 ML Tipo BRITANIA
A22: 13 | B22: 2.5.1-9016.1014 | C22: QUIMICOS | D22: 2.5.1. | E22: MEDIOS DE CULTIVO Y SUPLEMENTO; NOMBRE DEL PRODUCTO: CALDO TODD HEWITT, ESTADO: LIQUIDO, PRESENTACION: 10 FRASCOS X 10 ML | F22: CAJA | G22: 30 | H22: 42900 | I22: 1287000 | J22: MEDIO TODD HEWITT CALDO 10X10 ML Tipo BRITANIA
A23: 14 | B23: 2.5.1-9016.89 | C23: QUIMICOS | D23: 2.5.1. | E23: MEDIOS DE CULTIVO Y SUPLEMENTO; NOMBRE DEL PRODUCTO: CALDO TRIPTEINA SOJA, ESTADO: SOLIDO, PRESENTACION: ENVASE X 500 GR | F23: FRASCO | G23: 2 | H23: 11000 | I23: 22000 | J23: MEDIO TRIPTEINA SOYA AGAR 500 GR
A24: 15 | B24: 2.5.1-9016.429 | C24: QUIMICOS | D24: 2.5.1. | E24: MEDIOS DE CULTIVO Y SUPLEMENTO; NOMBRE DEL PRODUCTO: CROMAGAR ESTREPTO B, ESTADO: SOLIDO EN PLACA, PRESENTACION: ENVASE X 20 UN | F24: CAJA | G24: 30 | H24: 15000 | I24: 450000 | J24: MEDIO CHROM ID STREPTO B X 20 PLACAS Tipo BIOMERIEUX
... A37: 28 | B37: 2.5.1-8937.921 | C37: QUIMICOS | D37: 2.5.1. | E37: PATRÓN/ESTANDAR P/CALIBRACIÓN; EQUIPO: CONTADOR HEMATOLÓGICO; MARCA EQUIPO: SYSMEX ROCHE; NOMBRE DEL PRODUCTO: CONTROL P/HEMATOLOGÍA; PRESENTACIÓN: 4 X 2 X 3 ML | F37: UNIDAD | G37: 4 | H37: 116900 | I37: 467600 | J37: CONTROL HEMATOLOGIA XP 300 EIGTCHEK 3WPX-TRA 3X4X2ML Tipo SYSMEX
A38: 29 | B38: 2.5.1-9037.72 | C38: QUIMICOS | D38: 2.5.1. | E38: PROTEINAS; COMPUESTO QUIMICO: ALBUMINA BOVINA, ESTADO: LIQUIDO, CALIDAD: TECNICA MANUAL, CONCENTRACION/PUREZA: 30%, PRESENTACION: ENVASE X 10 ML | F38: UNIDAD | G38: 12 | H38: 1251 | I38: 15012
A39: 30 | B39: 2.5.1-9038.83 | C39: QUIMICOS | D39: 2.5.1. | E39: REACTIVO INDICADOR-COLORANTE; COMPUESTO QUIMICO: COLORACION DE GRAM, ESTADO: SOLUCION, CALIDAD: PRO ANALISIS, PRESENTACION: ENVASE X 100 mL | F39: CAJA | G39: 20 | H39: 3510 | I39: 70200 | J39: COLORACION DE GRAM X 100 ML Tipo BRITANIA
A40: 31 | B40: 2.5.1-9038.342 | C40: QUIMICOS | D40: 2.5.1. | E40: REACTIVO INDICADOR-COLORANTE; COMPUESTO QUIMICO: DECOLORANTE GRAM, ESTADO: SOLUCION, CALIDAD: PRO ANALISIS, PRESENTACION: ENVASE X 500 mL | F40: BOTELLA | G40: 20 | H40: 8600 | I40: 172000 | J40: SOLUCION DECOLORANTE PARA GRAM X 500 MLTipo BRITANIA
A41: 32 | B41: 2.5.1-9038.117 | C41: QUIMICOS | D41: 2.5.1. | E41: REACTIVO INDICADOR-COLORANTE; COMPUESTO QUIMICO: GIEMSA, ESTADO: LIQUIDO, CALIDAD: PRO ANALISIS, PRESENTACION: ENVASE X 1 L | F41: BOTELLA | G41: 60 | H41: 7052 | I41: 423120 | J41: COLORANTE GIEMSA X LITRO Tipo BIOPUR
A42: 33 | B42: 2.5.1-9038.46 | C42: QUIMICOS | D42: 2.5.1. | E42: REACTIVO INDICADOR-COLORANTE; COMPUESTO QUIMICO: MAY GRUNWALD, ESTADO: SOLUCION, CALIDAD: PRO ANALISIS, PRESENTACION: ENVASE X 1 L | F42: BOTELLA | G42: 20 | H42: 6970 | I42: 139400 | J42: COLORANTE MAY GRUNGUAL X 1 LT Tipo CICARELLI
A43: 34 | B43: 2.5.1-9038.228 | C43: QUIMICOS | D43: 2.5.1. | E43: REACTIVO INDICADOR-COLORANTE; COMPUESTO QUIMICO: ZIEL-NIELSEN, ESTADO: SOLUCION, CALIDAD: PRO ANALISIS, PRESENTACION: ENVASE X 100 mL | F43: CAJA | G43: 20 | H43: 3634 | I43: 72680 | J43: COLORACION DE ZIEHL NEELSEN X 100 ML Tipo BRITANIA
A44: 35 | B44: 2.5.1-8988.2507 | C44: QUIMICOS | D44: 2.5.1. | E44: REACTIVOS P/EQUIPO; EQUIPO: AFERESIS, MARCA EQUIPO: HAEMONETICS MCS PLUS, NOMBRE DEL PRODUCTO: SOLUCION ACD FORMULA A ANTI COAGULANTE TIPO RIVERO FENVAL SOLUFLEX 679-S, PRESENTACION: 600ML | F44: UNIDAD | G44: 81 | H44: 4350 | I44: 352350
A45: 36 | B45: 2.5.1-8988.372 | C45: QUIMICOS | D45: 2.5.1. | E45: REACTIVOS P/EQUIPO; EQUIPO: ANALIZ. X ENZIMO-INMUNO-ENSAYO, MARCA EQUIPO: ABBOTT, NOMBRE DEL PRODUCTO: DET. ANTIG. CORE/ANTIC ANTIHCV, PRESENTACION: ENVASE X 96 DETERM. | F45: CAJA | G45: 3 | H45: 50545 | I45: 151635
A46: 37 | B46: 2.5.1-8988.521 | C46: QUIMICOS | D46: 2.5.1. | E46: REACTIVOS P/EQUIPO; EQUIPO: ANALIZADOR DE CREATININA, MARCA EQUIPO: WIENER LAB, NOMBRE DEL PRODUCTO: CREATININA DIRECTA, PRESENTACION: ENVASE X 120 DETERM. | F46: CAJA | G46: 30 | H46: 4693 | I46: 140790 | J46: CREATININA DIRECTA 120 Det TIPO WIENER
A47: 38 | B47: 2.5.1-8988.1224 | C47: QUIMICOS | D47: 2.5.1. | E47: REACTIVOS P/EQUIPO; EQUIPO: ANALIZADOR DE GASES EN SANGRE, MARCA EQUIPO: OPTIMEDICAL, NOMBRE DEL PRODUCTO: MEDICION DE PH PO2 PCO2, PRESENTACION: UNIDAD | F47: CAJA | G47: 24 | H47: 100000 | I47: 2400000 | J47: CASSETTE MEDICION DE PH PO2 PCO2 X25 DET. "E-CL" OSMETECH OPTI CCA, Tipo OPTIMEDICAL
A48: 39 | B48: 2.5.1-8988.197 | C48: QUIMICOS | D48: 2.5.1. | E48: REACTIVOS P/EQUIPO; EQUIPO: ANALIZADOR DE INMUNOENSAYO, MARCA EQUIPO: ABBOTT, NOMBRE DEL PRODUCTO: HIV 1-2, PRESENTACION: ENVASE X 96 DETERM. | F48: CAJA | G48: 48 | H48: 23147 | I48: 1111056 | J48: HIV ELISA AG/AC 4° GENERACION -96 DET-
A49: 40 | B49: 2.5.1-8988.630 | C49: QUIMICOS | D49: 2.5.1. | E49: REACTIVOS P/EQUIPO; EQUIPO: ANALIZADOR DE IONES, MARCA EQUIPO: DIESTRO, NOMBRE DEL PRODUCTO: SOLUCIONES NA, KCL, CAL, PRESENTACION: PACK DE SOLUCIONES | F49: PACK | G49: 40 | H49: 28900 | I49: 1156000 | J49: PACK DIESTRO
A50: 41 | B50: 2.5.1-8988.482 | C50: QUIMICOS | D50: 2.5.1. | E50: REACTIVOS P/EQUIPO; EQUIPO: ANALIZADOR DE QUIMICA CLINICA, MARCA EQUIPO: METROLAB, NOMBRE DEL PRODUCTO: SOLUCION DE LIMPIEZA, PRESENTACION: 2 X ENVASE X 500 mL | F50: CAJA | G50: 20 | H50: 6900 | I50: 138000 | J50: SOLUCION DE LIMPIEZA SE ML Tipo WIENER
A51: 42 | B51: 2.5.1-8988.2426 | C51: QUIMICOS | D51: 2.5.1. | E51: REACTIVOS P/EQUIPO; EQUIPO: ANALIZADOR HEMATOLOGICO, MARCA EQUIPO: MINDRAY, NOMBRE DEL PRODUCTO: E-Z CLEANSER, PRESENTACION: FRASCO 100 ML | F51: UNIDAD | G51: 20 | H51: 15520 | I51: 310400 | J51: EZ CLEANSER COUNTER 19 SOLUCION DE LIMPIEZA Tipo WIENER X 100 ML
A52: 43 | B52: 2.5.1-8988.2426 | C52: QUIMICOS | D52: 2.5.1. | E52: REACTIVOS P/EQUIPO; EQUIPO: ANALIZADOR HEMATOLOGICO, MARCA EQUIPO: MINDRAY, NOMBRE DEL PRODUCTO: E-Z CLEANSER, PRESENTACION: FRASCO 100 ML | F52: UNIDAD | G52: 30 | H52: 2100 | I52: 63000 | J52: EZ CLEANSER SOLUCION DE LIMPIEZA TIPO MINDRAY 100 ML
A53: 44 | B53: 2.5.1-8988.2424 | C53: QUIMICOS | D53: 2.5.1. | E53: REACTIVOS P/EQUIPO; EQUIPO: ANALIZADOR QUIMICA CLINICA, MARCA EQUIPO: WIENER, NOMBRE DEL PRODUCTO: DETERGENTE NO IONICO, PRESENTACION: 2 X 500 ML | F53: CAJA | G53: 40 | H53: 17800 | I53: 712000 | J53: DETERGENTE NO IONICO TIPO WIENER
A54: 45 | B54: 2.5.1-8988.2423 | C54: QUIMICOS | D54: 2.5.1. | E54: REACTIVOS P/EQUIPO; EQUIPO: ANALIZADOR, MARCA EQUIPO: MINDRAY, NOMBRE DEL PRODUCTO: DETERGENTE CD80, PRESENTACION: 1 LITRO | F54: BOTELLA | G54: 40 | H54: 17800 | I54: 712000 | J54: DETERGENTE CONCENTRADO CD 80 TIPO MINDRAY
...

Sheet NP LABORATORIO
B1: Nota de Pedido
A2: Jurisdicción: | C2: 040 - MINISTERIO DE SALUD
A3: SAF: | C3: 011 - DIRECCION PROVINCIAL DE ADMINISTRACION - MINISTERIO DE SALUD
A4: Unidad Ejecutora: | C4: 468 - DIRECCION PROVINCIAL DE LABORATORIO
A5: Dependencia Solicitante: | C5: 468 - DIRECCION PROVINCIAL DE LABORATORIO
A6: Objeto: | C6: ADQUISICION DEL RUBRO REACTIVOS PARA LABORATORIO
A7: Periodo de Utilización: | C7: 3 (TRES) MESES
A9: Orden | B9: Código | C9: Descripción | D9: Detalle Técnico | E9: Unidad de Medida | F9: Precio Unitario Estimado | G9: Cantidad Solicitada
A10: 1 | B10: ='SAF 011'!B10 -> 2.5.1-9043.2 | C10: ='SAF 011'!E10 -> ACEITES Y GRASAS; COMPUESTO QUIMICO: ACEITE DE INMERSION, ESTADO: LIQUIDO, CALIDAD: PRO ANALISIS, CONCENTRACION/PUREZA: 99,9 %, PRESENTACION: ENVASE X 100 mL | D10: SI | E10: ='SAF 011'!F10 -> FRASCO | F10: ='SAF 011'!H10 -> 5017 | G10: ='SAF 011'!#REF! -> #REF!
A11: 2 | B11: ='SAF 011'!B14 -> 2.5.1-9007.169 | C11: ='SAF 011'!E14 -> COMP. HIDROXILADOS Y ALCOHOLES; COMPUESTO QUIMICO: METANOL, ESTADO: LIQUIDO, CALIDAD: PRO ANALISIS, CONCENTRACION/PUREZA: 98 %, PRESENTACION: ENVASE X 1 L | D11: SI | E11: ='SAF 011'!F14 -> BOTELLA | F11: ='SAF 011'!H14 -> 3980 | G11: ='SAF 011'!#REF! -> #REF!
A12: 3 | B12: ='SAF 011'!B15 -> 2.5.1-9019.119 | C12: ='SAF 011'!E15 -> HIDRATOS DE CARBONO; COMPUESTO QUIMICO: GLUCOCURVE 75 GR, ESTADO: SOLIDO, CALIDAD: PRO ANALISIS, CONCENTRACION/PUREZA: SIN VALOR, PRESENTACION: ENVASE X 10 SOBRES | D12: SI | E12: ='SAF 011'!F15 -> CAJA | F12: ='SAF 011'!H15 -> 1781 | G12: ='SAF 011'!#REF! -> #REF!
A13: 4 | B13: ='SAF 011'!B16 -> 2.9.9-3646.23 | C13: ='SAF 011'!E16 -> INSUMOS P/CONTADOR HEMATOL; TIPO: DETERGENTE, USO: CONTADOR HEMATOLOGICO MINDRAY | D13: SI | E13: ='SAF 011'!F16 -> BIDON | F13: ='SAF 011'!H16 -> 10600 | G13: ='SAF 011'!#REF! -> #REF!
A14: 5 | B14: ='SAF 011'!B17 -> 2.9.9-3646.22 | C14: ='SAF 011'!E17 -> INSUMOS P/CONTADOR HEMATOL; TIPO: DILUYENTE, USO: CONTADOR HEMATOLOGICO MINDRAY | D14: SI | E14: ='SAF 011'!F17 -> BIDON | F14: ='SAF 011'!H17 -> 11200 | G14: ='SAF 011'!#REF! -> #REF!
A15: 6 | B15: ='SAF 011'!B18 -> 2.9.9-3646.21 | C15: ='SAF 011'!E18 -> INSUMOS P/CONTADOR HEMATOL; TIPO: LISANTE, USO: CONTADOR HEMATOLOGICO MINDRAY | D15: SI | E15: ='SAF 011'!F18 -> BOTELLA | F15: ='SAF 011'!H18 -> 17700 | G15: ='SAF 011'!#REF! -> #REF!
A16: 7 | B16: ='SAF 011'!B19 -> 2.5.1-9016.223 | C16: ='SAF 011'!E19 -> MEDIOS DE CULTIVO Y SUPLEMENTO; NOMBRE DEL PRODUCTO: AGAR DIFERENCIAL ACETATO, ESTADO: SOLIDO, PRESENTACION: ENVASE X 500 GR | D16: SI | E16: ='SAF 011'!F19 -> FRASCO | F16: ='SAF 011'!H19 -> 18017 | G16: ='SAF 011'!#REF! -> #REF!
A17: 8 | B17: ='SAF 011'!B20 -> 2.5.1-9016.547 | C17: ='SAF 011'!E20 -> MEDIOS DE CULTIVO Y SUPLEMENTO; NOMBRE DEL PRODUCTO: AGAR SANGRE C/POLINUTRIENTES, ESTADO: SOLIDO EN PLACA, PRESENTACION: ENVASE X 10 UN | D17: SI | E17: ='SAF 011'!F20 -> CAJA | F17: ='SAF 011'!H20 -> 12000 | G17: ='SAF 011'!#REF! -> #REF!
A18: 9 | B18: ='SAF 011'!B21 -> 2.5.1-9016.1014 | C18: ='SAF 011'!E21 -> MEDIOS DE CULTIVO Y SUPLEMENTO; NOMBRE DEL PRODUCTO: CALDO TODD HEWITT, ESTADO: LIQUIDO, PRESENTACION: 10 FRASCOS X 10 ML | D18: SI | E18: ='SAF 011'!F21 -> CAJA | F18: ='SAF 011'!H21 -> 38000 | G18: ='SAF 011'!#REF! -> #REF!
A19: 10 | B19: ='SAF 011'!B22 -> 2.5.1-9016.1014 | C19: ='SAF 011'!E22 -> MEDIOS DE CULTIVO Y SUPLEMENTO; NOMBRE DEL PRODUCTO: CALDO TODD HEWITT, ESTADO: LIQUIDO, PRESENTACION: 10 FRASCOS X 10 ML | D19: SI | E19: ='SAF 011'!F22 -> CAJA | F19: ='SAF 011'!H22 -> 42900 | G19: ='SAF 011'!#REF! -> #REF!
A20: 11 | B20: ='SAF 011'!B23 -> 2.5.1-9016.89 | C20: ='SAF 011'!E23 -> MEDIOS DE CULTIVO Y SUPLEMENTO; NOMBRE DEL PRODUCTO: CALDO TRIPTEINA SOJA, ESTADO: SOLIDO, PRESENTACION: ENVASE X 500 GR | D20: SI | E20: ='SAF 011'!F23 -> FRASCO | F20: ='SAF 011'!H23 -> 11000 | G20: ='SAF 011'!#REF! -> #REF!
A21: 12 | B21: ='SAF 011'!B24 -> 2.5.1-9016.429 | C21: ='SAF 011'!E24 -> MEDIOS DE CULTIVO Y SUPLEMENTO; NOMBRE DEL PRODUCTO: CROMAGAR ESTREPTO B, ESTADO: SOLIDO EN PLACA, PRESENTACION: ENVASE X 20 UN | D21: SI | E21: ='SAF 011'!F24 -> CAJA | F21: ='SAF 011'!H24 -> 15000 | G21: ='SAF 011'!#REF! -> #REF!
A22: 13 | B22: ='SAF 011'!B25 -> 2.5.1-9016.1011 | C22: ='SAF 011'!E25 -> MEDIOS DE CULTIVO Y SUPLEMENTO; NOMBRE DEL PRODUCTO: MEDIO DE TRANSPORTE CARY BLAIR, ESTADO: SOLIDO, PRESENTACION: HISOPOS X 100 UNIDADES | D22: SI | E22: ='SAF 011'!F25 -> CAJA | F22: ='SAF 011'!H25 -> 18800 | G22: ='SAF 011'!#REF! -> #REF!
... A34: 25 | B34: ='SAF 011'!B37 -> 2.5.1-8937.921 | C34: ='SAF 011'!E37 -> PATRÓN/ESTANDAR P/CALIBRACIÓN; EQUIPO: CONTADOR HEMATOLÓGICO; MARCA EQUIPO: SYSMEX ROCHE; NOMBRE DEL PRODUCTO: CONTROL P/HEMATOLOGÍA; PRESENTACIÓN: 4 X 2 X 3 ML | D34: SI | E34: ='SAF 011'!F37 -> UNIDAD | F34: ='SAF 011'!H37 -> 116900 | G34: ='SAF 011'!#REF! -> #REF!
A35: 26 | B35: ='SAF 011'!B39 -> 2.5.1-9038.83 | C35: ='SAF 011'!E39 -> REACTIVO INDICADOR-COLORANTE; COMPUESTO QUIMICO: COLORACION DE GRAM, ESTADO: SOLUCION, CALIDAD: PRO ANALISIS, PRESENTACION: ENVASE X 100 mL | D35: SI | E35: ='SAF 011'!F39 -> CAJA | F35: ='SAF 011'!H39 -> 3510 | G35: ='SAF 011'!#REF! -> #REF!
A36: 27 | B36: ='SAF 011'!B40 -> 2.5.1-9038.342 | C36: ='SAF 011'!E40 -> REACTIVO INDICADOR-COLORANTE; COMPUESTO QUIMICO: DECOLORANTE GRAM, ESTADO: SOLUCION, CALIDAD: PRO ANALISIS, PRESENTACION: ENVASE X 500 mL | D36: SI | E36: ='SAF 011'!F40 -> BOTELLA | F36: ='SAF 011'!H40 -> 8600 | G36: ='SAF 011'!#REF! -> #REF!
A37: 28 | B37: ='SAF 011'!B41 -> 2.5.1-9038.117 | C37: ='SAF 011'!E41 -> REACTIVO INDICADOR-COLORANTE; COMPUESTO QUIMICO: GIEMSA, ESTADO: LIQUIDO, CALIDAD: PRO ANALISIS, PRESENTACION: ENVASE X 1 L | D37: SI | E37: ='SAF 011'!F41 -> BOTELLA | F37: ='SAF 011'!H41 -> 7052 | G37: ='SAF 011'!#REF! -> #REF!
A38: 29 | B38: ='SAF 011'!B42 -> 2.5.1-9038.46 | C38: ='SAF 011'!E42 -> REACTIVO INDICADOR-COLORANTE; COMPUESTO QUIMICO: MAY GRUNWALD, ESTADO: SOLUCION, CALIDAD: PRO ANALISIS, PRESENTACION: ENVASE X 1 L | D38: SI | E38: ='SAF 011'!F42 -> BOTELLA | F38: ='SAF 011'!H42 -> 6970 | G38: ='SAF 011'!#REF! -> #REF!
A39: 30 | B39: ='SAF 011'!B43 -> 2.5.1-9038.228 | C39: ='SAF 011'!E43 -> REACTIVO INDICADOR-COLORANTE; COMPUESTO QUIMICO: ZIEL-NIELSEN, ESTADO: SOLUCION, CALIDAD: PRO ANALISIS, PRESENTACION: ENVASE X 100 mL | D39: SI | E39: ='SAF 011'!F43 -> CAJA | F39: ='SAF 011'!H43 -> 3634 | G39: ='SAF 011'!#REF! -> #REF!
A40: 31 | B40: ='SAF 011'!B46 -> 2.5.1-8988.521 | C40: ='SAF 011'!E46 -> REACTIVOS P/EQUIPO; EQUIPO: ANALIZADOR DE CREATININA, MARCA EQUIPO: WIENER LAB, NOMBRE DEL PRODUCTO: CREATININA DIRECTA, PRESENTACION: ENVASE X 120 DETERM. | D40: SI | E40: ='SAF 011'!F46 -> CAJA | F40: ='SAF 011'!H46 -> 4693 | G40: ='SAF 011'!#REF! -> #REF!
A41: 32 | B41: ='SAF 011'!B47 -> 2.5.1-8988.1224 | C41: ='SAF 011'!E47 -> REACTIVOS P/EQUIPO; EQUIPO: ANALIZADOR DE GASES EN SANGRE, MARCA EQUIPO: OPTIMEDICAL, NOMBRE DEL PRODUCTO: MEDICION DE PH PO2 PCO2, PRESENTACION: UNIDAD | D41: SI | E41: ='SAF 011'!F47 -> CAJA | F41: ='SAF 011'!H47 -> 100000 | G41: ='SAF 011'!#REF! -> #REF!
A42: 33 | B42: ='SAF 011'!B49 -> 2.5.1-8988.630 | C42: ='SAF 011'!E49 -> REACTIVOS P/EQUIPO; EQUIPO: ANALIZADOR DE IONES, MARCA EQUIPO: DIESTRO, NOMBRE DEL PRODUCTO: SOLUCIONES NA, KCL, CAL, PRESENTACION: PACK DE SOLUCIONES | D42: SI | E42: ='SAF 011'!F49 -> PACK | F42: ='SAF 011'!H49 -> 28900 | G42: ='SAF 011'!#REF! -> #REF!
A43: 34 | B43: ='SAF 011'!B50 -> 2.5.1-8988.482 | C43: ='SAF 011'!E50 -> REACTIVOS P/EQUIPO; EQUIPO: ANALIZADOR DE QUIMICA CLINICA, MARCA EQUIPO: METROLAB, NOMBRE DEL PRODUCTO: SOLUCION DE LIMPIEZA, PRESENTACION: 2 X ENVASE X 500 mL | D43: SI | E43: ='SAF 011'!F50 -> CAJA | F43: ='SAF 011'!H50 -> 6900 | G43: ='SAF 011'!#REF! -> #REF!
A44: 35 | B44: ='SAF 011'!B51 -> 2.5.1-8988.2426 | C44: ='SAF 011'!E51 -> REACTIVOS P/EQUIPO; EQUIPO: ANALIZADOR HEMATOLOGICO, MARCA EQUIPO: MINDRAY, NOMBRE DEL PRODUCTO: E-Z CLEANSER, PRESENTACION: FRASCO 100 ML | D44: SI | E44: ='SAF 011'!F51 -> UNIDAD | F44: ='SAF 011'!H51 -> 15520 | G44: ='SAF 011'!#REF! -> #REF!
A45: 36 | B45: ='SAF 011'!B52 -> 2.5.1-8988.2426 | C45: ='SAF 011'!E52 -> REACTIVOS P/EQUIPO; EQUIPO: ANALIZADOR HEMATOLOGICO, MARCA EQUIPO: MINDRAY, NOMBRE DEL PRODUCTO: E-Z CLEANSER, PRESENTACION: FRASCO 100 ML | D45: SI | E45: ='SAF 011'!F52 -> UNIDAD | F45: ='SAF 011'!H52 -> 2100 | G45: ='SAF 011'!#REF! -> #REF!
A46: 37 | B46: ='SAF 011'!B53 -> 2.5.1-8988.2424 | C46: ='SAF 011'!E53 -> REACTIVOS P/EQUIPO; EQUIPO: ANALIZADOR QUIMICA CLINICA, MARCA EQUIPO: WIENER, NOMBRE DEL PRODUCTO: DETERGENTE NO IONICO, PRESENTACION: 2 X 500 ML | D46: SI | E46: ='SAF 011'!F53 -> CAJA | F46: ='SAF 011'!H53 -> 17800 | G46: ='SAF 011'!#REF! -> #REF!
A47: 38 | B47: ='SAF 011'!B54 -> 2.5.1-8988.2423 | C47: ='SAF 011'!E54 -> REACTIVOS P/EQUIPO; EQUIPO: ANALIZADOR, MARCA EQUIPO: MINDRAY, NOMBRE DEL PRODUCTO: DETERGENTE CD80, PRESENTACION: 1 LITRO | D47: SI | E47: ='SAF 011'!F54 -> BOTELLA | F47: ='SAF 011'!H54 -> 17800 | G47: ='SAF 011'!#REF! -> #REF!
A48: 39 | B48: ='SAF 011'!B55 -> 2.5.1-8988.2428 | C48: ='SAF 011'!E55 -> REACTIVOS P/EQUIPO; EQUIPO: ANALIZADOR, MARCA EQUIPO: WIENER, NOMBRE DEL PRODUCTO: FOSFATASA ALCALINA OPTIMIZADA, PRESENTACION: CAJA X 200 DETERMINACIONES | D48: SI | E48: ='SAF 011'!F55 -> CAJA | F48: ='SAF 011'!H55 -> 10113 | G48: ='SAF 011'!#REF! -> #REF!
A49: 40 | B49: ='SAF 011'!B56 -> 2.5.1-8988.2420 | C49: ='SAF 011'!E56 -> REACTIVOS P/EQUIPO; EQUIPO: ANALIZADOR, MARCA EQUIPO: WIENER, NOMBRE DEL PRODUCTO: PROTI 2 C/TESTIGO , PRESENTACION: 140 DETERMINACIONES | D49: SI | E49: ='SAF 011'!F56 -> CAJA | F49: ='SAF 011'!H56 -> 12000 | G49: ='SAF 011'!#REF! -> #REF!
A50: 41 | B50: ='SAF 011'!B57 -> 2.5.1-8988.2421 | C50: ='SAF 011'!E57 -> REACTIVOS P/EQUIPO; EQUIPO: ANALIZADOR, MARCA EQUIPO: WIENER, NOMBRE DEL PRODUCTO: PROTI U/LCR , PRESENTACION: ENVASE X 100 ML | D50: SI | E50: ='SAF 011'!F57 -> BOTELLA | F50: ='SAF 011'!H57 -> 6277 | G50: ='SAF 011'!#REF! -> #REF!
A51: 42 | B51: ='SAF 011'!B58 -> 2.5.1-8988.1088 | C51: ='SAF 011'!E58 -> REACTIVOS P/EQUIPO; EQUIPO: AUTOANA. QUIMICA CLINICA, MARCA EQUIPO: WIENER, NOMBRE DEL PRODUCTO: CALIBRADOR A PLUS, PRESENTACION: 2 X ENVASE X 3 mL | D51: SI | E51: ='SAF 011'!F58 -> CAJA | F51: ='SAF 011'!H58 -> 7900 | G51: ='SAF 011'!#REF! -> #REF!
A52: 43 | B52: ='SAF 011'!B59 -> 2.5.1-8988.1085 | C52: ='SAF 011'!E59 -> REACTIVOS P/EQUIPO; EQUIPO: AUTOANA. QUIMICA CLINICA, MARCA EQUIPO: WIENER, NOMBRE DEL PRODUCTO: COLESTEROL ENZIMATICO AA, PRESENTACION: 4 X ENVASE X 100 mL | D52: SI | E52: ='SAF 011'!F59 -> CAJA | F52: ='SAF 011'!H59 -> 8000 | G52: ='SAF 011'!#REF! -> #REF!
...

Sheet APG LABORATORIO
A1: EJERCICIO: | D1: 2022 | P1: AUTORIZACION PARA GASTAR
A4: JURISDICCIÓN: | G4: ='NP LABORATORIO'!C2 -> 040 - MINISTERIO DE SALUD
A5: SAF: | G5: ='NP LABORATORIO'!C3 -> 011 - DIRECCION PROVINCIAL DE ADMINISTRACION - MINISTERIO DE SALUD
A6: UNIDAD EJECUTORA: | G6: ='NP LABORATORIO'!C4 -> 468 - DIRECCION PROVINCIAL DE LABORATORIO
A7: DEPENDENCIA SOLICITANTE: | G7: ='NP LABORATORIO'!C5 -> 468 - DIRECCION PROVINCIAL DE LABORATORIO
A8: AUTORIZACIÓN:
A9: Señor Director de Administración o Titular del Servicio Administrativo Financiero:
A10: Autorizo la realización de los trámites correspondientes, a fin de proveer a este Organismo los bienes que se detallan en Nota de Pedido N°....... , afectando la erogación resultante a los créditos presupuestarios aprobados a favor de esta Unidad Ejecutora, conforme al siguiente detalle:
A12: IMPUTACIÓN PRESUPUESTARIA
A13: CÓDIGO | O13: DENOMINACIÓN DE LA PARTIDA PRESUPUESTARIA | Q13: IMPORTE
A14: PR | B14: SB | C14: PY | D14: AC | E14: OB | F14: UG | G14: FIN | H14: FUN | I14: I | J14: P | K14: P | L14: SubP | M14: M | N14: FF
A15: 62 | D15: 1 | F15: 4901 | G15: 3 | H15: 1 | I15: 2 | J15: 5 | K15: 1 | M15: 1 | N15: 1.1 | O15: COMPUESTOS QUIMICOS | Q15: ='NP LABORATORIO'!F148 -> #REF!
A38: TOTAL DE PESOS: SESENTA Y OCHO MILLONES TRESCIENTOS NOVENTA Y SIETE MIL CIENTO SESENTA Y NUEVE CON 00/100 | Q38: =SUM(Q15:Q37) -> #REF!
A40: JUSTIFICACIÓN:
A41: ='NP LABORATORIO'!C6 -> ADQUISICION DEL RUBRO REACTIVOS PARA LABORATORIO

Sheet NP BCO DE SANGRE
B1: Nota de Pedido
A2: Jurisdicción: | C2: 040 - MINISTERIO DE SALUD
A3: SAF: | C3: 011 - DIRECCION PROVINCIAL DE ADMINISTRACION - MINISTERIO DE SALUD
A4: Unidad Ejecutora: | C4: 747 - DIRECCION PROVINCIAL BANCO DE SANGRE
A5: Dependencia Solicitante: | C5: 747 - DIRECCION PROVINCIAL BANCO DE SANGRE
A6: Objeto: | C6: ADQUISICION DEL RUBRO REACTIVOS PARA LABORATORIO
A7: Periodo de Utilización: | C7: 3 (TRES) MESES
A9: Orden | B9: Código | C9: Descripción | D9: Detalle Técnico | E9: Unidad de Medida | F9: Precio Unitario Estimado | G9: Cantidad Solicitada
A10: 1 | B10: ='SAF 011'!B11 -> 2.5.1-9017.381 | C10: ='SAF 011'!E11 -> ANTICUERPOS P/LABORATORIO; NOMBRE: ANTI-A, ESTADO: LIQUIDO, MARCADO CON: SIN MARCAR, ORIGEN: HUMANO, PRESENTACION: ENVASE X 10 mL, TIPO: MONOCLONAL | D10: NO | E10: ='SAF 011'!F11 -> FRASCO | F10: ='SAF 011'!H11 -> 876 | G10: ='SAF 011'!#REF! -> #REF!
A11: 2 | B11: ='SAF 011'!B12 -> 2.5.1-9017.136 | C11: ='SAF 011'!E12 -> ANTICUERPOS P/LABORATORIO; NOMBRE: ANTI-B, ESTADO: SOLUCION, MARCADO CON: SIN MARCAR, ORIGEN: HUMANO, PRESENTACION: ENVASE X 10 mL, TIPO: MONOCLONAL | D11: NO | E11: ='SAF 011'!F12 -> FRASCO | F11: ='SAF 011'!H12 -> 876 | G11: ='SAF 011'!#REF! -> #REF!
A12: 3 | B12: ='SAF 011'!B13 -> 2.5.1-9017.137 | C12: ='SAF 011'!E13 -> ANTICUERPOS P/LABORATORIO; NOMBRE: ANTI-D, ESTADO: SOLUCION, MARCADO CON: SIN MARCAR, ORIGEN: HUMANO, PRESENTACION: ENVASE X 10 mL, TIPO: MONOCLONAL | D12: SI | E12: ='SAF 011'!F13 -> UNIDAD | F12: ='SAF 011'!H13 -> 1657 | G12: ='SAF 011'!#REF! -> #REF!
A13: 4 | B13: ='SAF 011'!B38 -> 2.5.1-9037.72 | C13: ='SAF 011'!E38 -> PROTEINAS; COMPUESTO QUIMICO: ALBUMINA BOVINA, ESTADO: LIQUIDO, CALIDAD: TECNICA MANUAL, CONCENTRACION/PUREZA: 30%, PRESENTACION: ENVASE X 10 ML | D13: NO | E13: ='SAF 011'!F38 -> UNIDAD | F13: ='SAF 011'!H38 -> 1251 | G13: ='SAF 011'!#REF! -> #REF!
A14: 5 | B14: ='SAF 011'!B44 -> 2.5.1-8988.2507 | C14: ='SAF 011'!E44 -> REACTIVOS P/EQUIPO; EQUIPO: AFERESIS, MARCA EQUIPO: HAEMONETICS MCS PLUS, NOMBRE DEL PRODUCTO: SOLUCION ACD FORMULA A ANTI COAGULANTE TIPO RIVERO FENVAL SOLUFLEX 679-S, PRESENTACION: 600ML | D14: NO | E14: ='SAF 011'!F44 -> UNIDAD | F14: ='SAF 011'!H44 -> 4350 | G14: ='SAF 011'!#REF! -> #REF!
A15: 6 | B15: ='SAF 011'!B45 -> 2.5.1-8988.372 | C15: ='SAF 011'!E45 -> REACTIVOS P/EQUIPO; EQUIPO: ANALIZ. X ENZIMO-INMUNO-ENSAYO, MARCA EQUIPO: ABBOTT, NOMBRE DEL PRODUCTO: DET. ANTIG. CORE/ANTIC ANTIHCV, PRESENTACION: ENVASE X 96 DETERM. | D15: NO | E15: ='SAF 011'!F45 -> CAJA | F15: ='SAF 011'!H45 -> 50545 | G15: ='SAF 011'!#REF! -> #REF!
A16: 7 | B16: ='SAF 011'!B48 -> 2.5.1-8988.197 | C16: ='SAF 011'!E48 -> REACTIVOS P/EQUIPO; EQUIPO: ANALIZADOR DE INMUNOENSAYO, MARCA EQUIPO: ABBOTT, NOMBRE DEL PRODUCTO: HIV 1-2, PRESENTACION: ENVASE X 96 DETERM. | D16: SI | E16: ='SAF 011'!F48 -> CAJA | F16: ='SAF 011'!H48 -> 23147 | G16: ='SAF 011'!#REF! -> #REF!
A17: 8 | B17: ='SAF 011'!B95 -> 2.5.1-8988.2287 | C17: ='SAF 011'!E95 -> REACTIVOS P/EQUIPO; EQUIPO: AUTOMATIZADO, MARCA EQUIPO: A DEFINIR, NOMBRE DEL PRODUCTO: RH/PHENO/KELL DONANTES, PRESENTACION: ENVASE X 48 DETERM. | D17: SI | E17: ='SAF 011'!F95 -> UNIDAD | F17: ='SAF 011'!H95 -> 795 | G17: ='SAF 011'!#REF! -> #REF!
A18: 9 | B18: ='SAF 011'!B124 -> 2.5.1-8988.2404 | C18: ='SAF 011'!E124 -> REACTIVOS P/EQUIPO; EQUIPO: ELECTROLUMINISCENCIA, MARCA EQUIPO: COBAS ROCHE, NOMBRE DEL PRODUCTO: ATG SUPERFICIE HEPATITIS B, PRESENTACION: ENVASE X 100 DETERM. | D18: NO | E18: ='SAF 011'!F124 -> CAJA | F18: ='SAF 011'!H124 -> 27546 | G18: ='SAF 011'!#REF! -> #REF!
A19: 10 | B19: ='SAF 011'!B125 -> 2.5.1-8988.2406 | C19: ='SAF 011'!E125 -> REACTIVOS P/EQUIPO; EQUIPO: ELECTROLUMINISCENCIA, MARCA EQUIPO: COBAS ROCHE, NOMBRE DEL PRODUCTO: REACTIVO CHAGAS, PRESENTACION: ENVASE X 100 DETERM. | D19: NO | E19: ='SAF 011'!F125 -> CAJA | F19: ='SAF 011'!H125 -> 51404 | G19: ='SAF 011'!#REF! -> #REF!
A20: 11 | B20: ='SAF 011'!B126 -> 2.5.1-8988.2405 | C20: ='SAF 011'!E126 -> REACTIVOS P/EQUIPO; EQUIPO: ELECTROLUMINISCENCIA, MARCA EQUIPO: COBAS ROCHE, NOMBRE DEL PRODUCTO: REACTIVO HTLV, PRESENTACION: ENVASE X 100 DETERM. | D20: NO | E20: ='SAF 011'!F126 -> CAJA | F20: ='SAF 011'!H126 -> 61263 | G20: ='SAF 011'!#REF! -> #REF!
A21: 12 | B21: ='SAF 011'!B127 -> 2.5.1-8988.2407 | C21: ='SAF 011'!E127 -> REACTIVOS P/EQUIPO; EQUIPO: ELECTROLUMINISCENCIA, MARCA EQUIPO: COBAS ROCHE, NOMBRE DEL PRODUCTO: REACTIVO SYPHILIS, PRESENTACION: ENVASE X 100 DETERM. | D21: NO | E21: ='SAF 011'!F127 -> CAJA | F21: ='SAF 011'!H127 -> 63289 | G21: ='SAF 011'!#REF! -> #REF!
A22: 13 | B22: ='SAF 011'!B131 -> 2.5.1-8988.1446 | C22: ='SAF 011'!E131 -> REACTIVOS P/EQUIPO; EQUIPO: MICROTUBOS C/GEL, MARCA EQUIPO: GRIFOLS, NOMBRE DEL PRODUCTO: TARJETAS LISS COOMBS, PRESENTACION: ENVASE X 48 UN | D22: SI | E22: ='SAF 011'!F131 -> UNIDAD | F22: ='SAF 011'!H131 -> 725 | G22: ='SAF 011'!#REF! -> #REF!
A23: 14 | B23: ='SAF 011'!B142 -> 2.5.1-9052.2130 | C23: ='SAF 011'!E142 -> REACTIVOS P/LAB. TEC. MANUAL ; NOMBRE: BIOZIMA CHAGAS, USO: DETECCION ANTICUERPOS ANTI-TRIPANOSOMA CRUZI, PRESENTACION: ENVASE X 192 DETERM. | D23: SI | E23: ='SAF 011'!F142 -> CAJA | F23: ='SAF 011'!H142 -> 10578 | G23: ='SAF 011'!#REF! -> #REF!
A24: 15 | B24: ='SAF 011'!B143 -> 2.5.1-9052.2131 | C24: ='SAF 011'!E143 -> REACTIVOS P/LAB. TEC. MANUAL ; NOMBRE: BIOZIMA RECONVINANTE CHAGAS, USO: DETECCION ANTICUERPOS ANTI-TRIPANOSOMA CRUZI, PRESENTACION: ENVASE X 192 DETERM. | D24: SI | E24: ='SAF 011'!F143 -> CAJA | F24: ='SAF 011'!H143 -> 11503 | G24: ='SAF 011'!#REF! -> #REF!
A25: 16 | B25: ='SAF 011'!B145 -> 2.5.1-9052.2126 | C25: ='SAF 011'!E145 -> REACTIVOS P/LAB. TEC. MANUAL ; NOMBRE: CELDAS DE REACCION TEMPERATURA AMBIENTE-SISTEMA DE INMUNO ENSAYO. TIPO ABBOT, USO:INMUNOSEROLOGIA ; PRESENTACION: 4000 DETERMINACIONES. | D25: NO | E25: ='SAF 011'!F145 -> CAJA | F25: ='SAF 011'!H145 -> 373520 | G25: ='SAF 011'!#REF! -> #REF!
A26: 17 | B26: ='SAF 011'!B147 -> 2.5.1-9052.2129 | C26: ='SAF 011'!E147 -> REACTIVOS P/LAB. TEC. MANUAL ; NOMBRE: COVIDAR IGG(SEROKIT MAS ELISA IGG), USO: DIAGNOSTICO SARS-COV-2, PRESENTACION: ENVASE X 192 DETERM. | D26: NO | E26: ='SAF 011'!F147 -> CAJA | F26: ='SAF 011'!H147 -> 64700 | G26: ='SAF 011'!#REF! -> #REF!
A27: 18 | B27: ='SAF 011'!B148 -> 2.5.1-9052.2129 | C27: ='SAF 011'!E148 -> REACTIVOS P/LAB. TEC. MANUAL ; NOMBRE: COVIDAR IGG(SEROKIT MAS ELISA IGG), USO: DIAGNOSTICO SARS-COV-2, PRESENTACION: ENVASE X 192 DETERM. | D27: SI | E27: ='SAF 011'!F148 -> CAJA | F27: ='SAF 011'!H148 -> 19744 | G27: ='SAF 011'!#REF! -> #REF!
A28: 19 | B28: ='SAF 011'!B151 -> 2.5.1-9052.1488 | C28: ='SAF 011'!E151 -> REACTIVOS P/LAB. TEC. MANUAL ; NOMBRE: ELISA ANTI HCV, USO: DETERMINACION DE ANTICUERPOS, PRESENTACION: ENVASE X 96 DETERM. | D28: SI | E28: ='SAF 011'!F151 -> CAJA | F28: ='SAF 011'!H151 -> 39806 | G28: ='SAF 011'!#REF! -> #REF!
A29: 20 | B29: ='SAF 011'!B152 -> 2.5.1-9052.740 | C29: ='SAF 011'!E152 -> REACTIVOS P/LAB. TEC. MANUAL ; NOMBRE: ELISA P/DET. ANTIC ANTI-HBSAG, USO: DETERMINACION HEPATITIS B, PRESENTACION: ENVASE X 96 DETERM. | D29: SI | E29: ='SAF 011'!F152 -> CAJA | F29: ='SAF 011'!H152 -> 14586 | G29: ='SAF 011'!#REF! -> #REF!
A30: 21 | B30: ='SAF 011'!B153 -> 2.5.1-9052.862 | C30: ='SAF 011'!E153 -> REACTIVOS P/LAB. TEC. MANUAL ; NOMBRE: ELISA PARA HTLV, USO: SEROLOGIA, PRESENTACION: ENVASE X 96 DETERM. | D30: SI | E30: ='SAF 011'!F153 -> CAJA | F30: ='SAF 011'!H153 -> 25747 | G30: ='SAF 011'!#REF! -> #REF!
A31: 22 | B31: ='SAF 011'!B158 -> 2.5.1-9052.2132 | C31: ='SAF 011'!E158 -> REACTIVOS P/LAB. TEC. MANUAL ; NOMBRE: REACTIVO ANTI HBC TEC. ELECTROLIMINISCENCIA TIPO ROCHE COBAS E411 CRACK, USO: INMUNOSEROLOGIA; PRESENTACION: X 100 DETERMINACIONES. | D31: NO | E31: ='SAF 011'!F158 -> CAJA | F31: ='SAF 011'!H158 -> 41413 | G31: ='SAF 011'!#REF! -> #REF!
A32: 23 | B32: ='SAF 011'!B159 -> 2.5.1-9052.2134 | C32: ='SAF 011'!E159 -> REACTIVOS P/LAB. TEC. MANUAL ; NOMBRE: REACTIVO ANTI HCV TEC. ELECTROLUMINISCENCIA TIPO ROCHE COBAS E411 CRACK; USO: INMUNOSEROLOGIA ; PRESENTACION: X 100 DETERMINACIONES. | D32: NO | E32: ='SAF 011'!F159 -> CAJA | F32: ='SAF 011'!H159 -> 93380 | G32: ='SAF 011'!#REF! -> #REF!
A33: 24 | B33: ='SAF 011'!B160 -> 2.5.1-9052.2133 | C33: ='SAF 011'!E160 -> REACTIVOS P/LAB. TEC. MANUAL ; NOMBRE: REACTIVO HC1V TEC. ELECTROLUNINISCENCIA TIPO ROCHE COBAS E411 CRACK, USO: INMUNOSEROLOGIA ; PRESENTACION: X 100 DETERMINACIONES. | D33: NO | E33: ='SAF 011'!F160 -> CAJA | F33: ='SAF 011'!H160 -> 27563 | G33: ='SAF 011'!#REF! -> #REF!
A34: 25 | B34: ='SAF 011'!B161 -> 2.5.1-9052.294 | C34: ='SAF 011'!E161 -> REACTIVOS P/LAB. TEC. MANUAL ; NOMBRE: REACTIVO HUDDLESON, USO: DIAGNOSTICO DE BRUCELOSIS, PRESENTACION: ENVASE X 5 mL | D34: SI | E34: ='SAF 011'!F161 -> UNIDAD | F34: ='SAF 011'!H161 -> 1184 | G34: ='SAF 011'!#REF! -> #REF!
A35: 26 | B35: ='SAF 011'!B163 -> 2.5.1-9052.288 | C35: ='SAF 011'!E163 -> REACTIVOS P/LAB. TEC. MANUAL ; NOMBRE: SUERO COOMBS MONOES. ANTI-IGA, USO: HEMOTERAPIA, PRESENTACION: ENVASE X 5 mL | D35: SI | E35: ='SAF 011'!F163 -> UNIDAD | F35: ='SAF 011'!H163 -> 1325 | G35: ='SAF 011'!#REF! -> #REF!
A36: 27 | B36: ='SAF 011'!B166 -> 2.5.1-9052.247 | C36: ='SAF 011'!E166 -> REACTIVOS P/LAB. TEC. MANUAL ; NOMBRE: SUERO HEMOTIPIFICADOR ANTI-AB, USO: HEMOTERAPIA, PRESENTACION: ENVASE X 10 mL | D36: SI | E36: ='SAF 011'!F166 -> CAJA | F36: ='SAF 011'!H166 -> 888 | G36: ='SAF 011'!#REF! -> #REF!
A37: 28 | B37: ='SAF 011'!B170 -> 2.5.1-9052.354 | C37: ='SAF 011'!E170 -> REACTIVOS P/LAB. TEC. MANUAL ; NOMBRE: TOXOTEST HAI, USO: INMUNOLOGIA, PRESENTACION: ENVASE X 96 DETERM. | D37: NO | E37: ='SAF 011'!F170 -> CAJA | F37: ='SAF 011'!H170 -> 16645 | G37: ='SAF 011'!#REF! -> #REF!
A38: 29 | B38: ='SAF 011'!B172 -> 2.5.1-9052.645 | C38: ='SAF 011'!E172 -> REACTIVOS P/LAB. TEC. MANUAL ; NOMBRE: VDRL, USO: DIAGNOSTICO, PRESENTACION: ENVASE X 250 DETERM. | D38: SI | E38: ='SAF 011'!F172 -> CAJA | F38: ='SAF 011'!H172 -> 3800 | G38: ='SAF 011'!#REF! -> #REF!
A39: 30 | B39: ='SAF 011'!B173 -> 2.5.1-9052.2123 | C39: ='SAF 011'!E173 -> REACTIVOS P/LAB. TEC. MANUAL ; NOMBRE:SARS- COV-2 IGM CONTROL, USO: IDENTIFICACION DE ANTICUERPOS, PRESENTACION: 2 X ENVASE X 10 ML | D39: SI | E39: ='SAF 011'!F173 -> CAJA | F39: ='SAF 011'!H173 -> 17788 | G39: ='SAF 011'!#REF! -> #REF!
A40: 31 | B40: ='SAF 011'!B174 -> 2.5.1-9052.2155 | C40: ='SAF 011'!E174 -> REACTIVOS P/LAB. TEC. MANUAL, NOMBRE:CMV CITOMEGALOVIRUS IGM , USO: METODO ELISA TIPO WIENER, PRESENTACION: 96 DETERMINACIONES | D40: NO | E40: ='SAF 011'!F174 -> CAJA | F40: ='SAF 011'!H174 -> 19749 | G40: ='SAF 011'!#REF! -> #REF!
A41: 32 | B41: ='SAF 011'!B178 -> 2.5.1-9052.2127 | C41: ='SAF 011'!E178 -> REACTIVOS P/LAB. TEC. MANUAL; NOMBRE: REACTIVO PARA HEPATITIS C, USO: DETECCION DE ANTIGENO- ANTICUERPO TIPO BIORAD ; PRESENTACION: X 96 DETERMINACIONES. | D41: SI | E41: ='SAF 011'!F178 -> CAJA | F41: ='SAF 011'!H178 -> 130000 | G41: ='SAF 011'!#REF! -> #REF!
...

Sheet APG BCO DE SANGRE
A1: EJERCICIO: | D1: 2022 | P1: AUTORIZACION PARA GASTAR
A4: JURISDICCIÓN: | G4: ='NP BCO DE SANGRE'!C2 -> 040 - MINISTERIO DE SALUD
A5: SAF: | G5: ='NP BCO DE SANGRE'!C3 -> 011 - DIRECCION PROVINCIAL DE ADMINISTRACION - MINISTERIO DE SALUD
A6: UNIDAD EJECUTORA: | G6: ='NP BCO DE SANGRE'!C4 -> 747 - DIRECCION PROVINCIAL BANCO DE SANGRE
A7: DEPENDENCIA SOLICITANTE: | G7: ='NP BCO DE SANGRE'!C5 -> 747 - DIRECCION PROVINCIAL BANCO DE SANGRE
A8: AUTORIZACIÓN:
A9: Señor Director de Administración o Titular del Servicio Administrativo Financiero:
A10: Autorizo la realización de los trámites correspondientes, a fin de proveer a este Organismo los bienes que se detallan en Nota de Pedido N°....... , afectando la erogación resultante a los créditos presupuestarios aprobados a favor de esta Unidad Ejecutora, conforme al siguiente detalle:
A12: IMPUTACIÓN PRESUPUESTARIA
A13: CÓDIGO | O13: DENOMINACIÓN DE LA PARTIDA PRESUPUESTARIA | Q13: IMPORTE
A14: PR | B14: SB | C14: PY | D14: AC | E14: OB | F14: UG | G14: FIN | H14: FUN | I14: I | J14: P | K14: P | L14: SubP | M14: M | N14: FF
A15: 27 | D15: 1 | F15: 4901 | G15: 3 | H15: 1 | I15: 2 | J15: 5 | K15: 1 | M15: 1 | N15: 1.1 | O15: COMPUESTOS QUIMICOS | Q15: ='NP BCO DE SANGRE'!F50 -> #REF!
A38: TOTAL DE PESOS: CATORCE MILLONES QUINIENTOS TRES MIL DOSCIENTOS TRECE CON 00/100.- | Q38: =SUM(Q15:Q37) -> #REF!
A40: JUSTIFICACIÓN:
A41: ='NP BCO DE SANGRE'!C6 -> ADQUISICION DEL RUBRO REACTIVOS PARA LABORATORIO
