Workbook

Sheet Necesidades Trimestrales
B2: Pedido de Necesidades Trimestrales
A4: JURISDICCION: | C4: 70 - MINISTERIO DE CIENCIA E INNOVACION TECNOLOGICA
A5: SAF N°: | C5: 20 - MINISTERIO DE CIENCIA E INNOVACION TECNOLOGICA
A6: EJERCICIO: | C6: 2021
A7: TRIMESTRE: | C7: 2
A9: ID | B9: CODIGO ITEM | C9: RUBRO DE COMPRA | D9: I.P.P. | E9: DESCRIPCION | F9: UNIDAD DE MEDIDA | G9: CANTIDAD | H9: PRECIO UNITARIO ESTIMADO | I9: IMPORTE TOTAL ESTIMADO
A10: 1 | B10: 4.3.5-9163.80 | C10: EQUIPOS | D10: =LEFT(B10,5) -> 4.3.5 | E10: EQUIPOS DIDACTICOS TECNICOS; NOMBRE: LENTES, TIPO: REALIDAD VIRTUAL | F10: UNIDAD | G10: 3 | H10: 198036.7 | I10: =H10*G10 -> 594110.1
A11: 2 | B11: 4.3.5-9163.80 | C11: EQUIPOS | D11: =LEFT(B11,5) -> 4.3.5 | E11: EQUIPOS DIDACTICOS TECNICOS; NOMBRE: LENTES, TIPO: REALIDAD VIRTUAL | F11: UNIDAD | G11: 4 | H11: 92202 | I11: =H11*G11 -> 368808
A12: 3 | B12: 4.3.6-9604.3 | C12: INFORMATICA | D12: =LEFT(B12,5) -> 4.3.6 | E12: TABLETA PC; RESOLUCION: 1280 X 800 PXL, PANTALLA: 9,4 pulg, MEMORIA: 32 Gb, MEMORIA RAM: 32 Gb | F12: UNIDAD | G12: 6 | H12: 55055 | I12: =H12*G12 -> 330330
A13: 4 | B13: 4.3.5-9163.90 | C13: EQUIPOS | D13: =LEFT(B13,5) -> 4.3.5 | E13: EQUIPOS DIDACTICOS TECNICOS; NOMBRE: KIT EXPERIMENTAL , TIPO: SEGÚN PLIEGO | F13: UNIDAD | G13: 1 | H13: 748264 | I13: =H13*G13 -> 748264
B16: Especificidades Item N° 1
B18: Descripción técnica
C20: DISPOSITIVO DE REALIDAD VITUAL CON TECNOLOGIA TIPO OCULUS QUEST: Tipo de Panel: LCD Resolución: 1920 x1832 por ojo Frecuencia de Refresco: 90 Hz Capada a 72 hz Procesador: Snapdragon XR2 o Similar Conectividad Inalámbrica: WiFi 6 Bluetooth 5.1 Puertos: USD Tipo C Almacenamiento: 64 GB Sonido: 3D Tracking: Cámaras internas Más valija diseñada para contener y almacenar los equipos en buen estado
B27: Plazos y lugares de entrega
C28: El plazo de entrega no podrá ser superior a los noventa (90) días corridos a partir de la fecha de recepción de la respectiva Orden de Compra en el domicilio especial electrónico constituido, en virtud del método de contratación. La entrega de dichos bienes se realizará en la Secretaria de Ciencia y Tecnología dependiente del Mrio. Ciencia e Innovación Tecnológica, sito en Avenida Republica de Venezuela S/N° - CAPE- Pabellón N° 26 San Fernando del Valle de Catamarca. Se presentará Remito que deberá cumplimentar lo dispuesto por la R.G. AFIP 1415/03, sin excepción.
B31: Calidad Minima esperada: muy buena calidad, tipo Hellbot -modelo 507
B33: Mantenimiento: Treinta Días Hábiles.-
B35: Garantia | C35: Mínima de Un (1) año
B39: Especificidades Item N° 2
B41: Descripción técnica
C43: DISPOSITIVO DE REALIDAD VITUAL CON TECNOLOGIA TIPO OCULUS GO: Tipo de Panel: LCD Resolución: QHD (2.650 x 1.440 puntos) Frecuencia de Refresco: 72 Hz Procesador: Qualcomm Snapdragon 821 Conectividad Inalámbrica: WiFi y Bluetooth Puertos: Micro-USB y Jack para auriculares 3,55 mm Almacenamiento: 32/64 GB Sonido: Estéreo 3D Más valija diseñada para contener y almacenar los equipos en buen estado
B48: Plazos y lugares de entrega
C49: El plazo de entrega no podrá ser superior a los noventa (90) días corridos a partir de la fecha de recepción de la respectiva Orden de Compra en el domicilio especial electrónico constituido, en virtud del método de contratación. La entrega de dichos bienes se realizará en la Secretaria de Ciencia y Tecnología dependiente del Mrio. Ciencia e Innovación Tecnológica, sito en Avenida Republica de Venezuela S/N° - CAPE- Pabellón N° 26 San Fernando del Valle de Catamarca. Se presentará Remito que deberá cumplimentar lo dispuesto por la R.G. AFIP 1415/03, sin excepción.
B52: Calidad Minima esperada:
B54: Mantenimiento: Treinta Días Hábiles.-
B56: Garantia | C56: Mínima de Un (1) año
B61: Especificidades Item N°3
B63: Descripción técnica
C65: TABLET: Sistema operativo: Android. Con procesador de 2GHz. ○ superior Resolución de pantalla de 1280px x 800px. Con lector micro SD. 32 gb de almacenamiento Memoria expandible Sistema de altavoces Más valija diseñada para contener y almacenar los equipos en buen estado
C66: Cantidad de extrusores: 2
C68: Volumen de la zona de impresión: 220 x 220 x 260 mm
B73: Plazos y lugares de entrega
C74: El plazo de entrega no podrá ser superior a los noventa (90) días corridos a partir de la fecha de recepción de la respectiva Orden de Compra en el domicilio especial electrónico constituido, en virtud del método de contratación. La entrega de dichos bienes se realizará en la Secretaria de Ciencia y Tecnología dependiente del Mrio. Ciencia e Innovación Tecnológica, sito en Avenida Republica de Venezuela S/N° - CAPE- Pabellón N° 26 San Fernando del Valle de Catamarca. Se presentará Remito que deberá cumplimentar lo dispuesto por la R.G. AFIP 1415/03, sin excepción.
B77: Calidad Minima esperada:
B79: Mantenimiento: Treinta Días Hábiles.-
B81: Garantia | C81: Mínima de Un (1) año
B86: Especificidades Item N° 4
B88: Descripción técnica
C90: DISPOSITIVO SIMULADOR DE AUTOELEVADOR CON TECNOLOGIA TIPO OCULUS RIFT: Incluye Casco de realidad Virtual, volante y pedalera Visor: Un visor suave y cómodo con una óptica personalizada que ofrece una fidelidad visual extraordinaria y un amplio campo de visión. Controladores: Touch Touch es un par de controladores bajo seguimiento que permiten la presencia intuitiva de las manos en la realidad virtual (Sensación de las manos virtuales son las tuyas propias) Sensores: necesarios para realizar un seguimiento de las constelaciones de LED infrarrojos para trasladar los movimientos a la realidad virtual tanto si el individuo esta de pie como sentado Auriculares: Sistema de audio integrado para generar inmersión en la realidad virtual Resolución: 2.560 x 1440 píxeles por ojo Frecuencia de Refresco: 80 Hz Procesador: No tiene Conectividad Inalámbrica: No tiene Puertos: USB Almacenamiento: No tiene Sonido: Estéreo Passtrough+ Tracking: tipo Oculus Insight Más valija diseñada para contener y almacenar los equipos en buen estado
C91: Cantidad de extrusores: 2
...

Sheet  NotaPedido
A1: NOTA DE PEDIDO | J1: N° | K1: 015/2021
A3: JURISDICCIÓN: | D3: ='Necesidades Trimestrales'!C4 -> 70 - MINISTERIO DE CIENCIA E INNOVACION TECNOLOGICA
A4: SAF: | D4: ='Necesidades Trimestrales'!C5 -> 20 - MINISTERIO DE CIENCIA E INNOVACION TECNOLOGICA
A5: UNIDAD EJECUTORA: | D5: SECRETARIA DE CIENCIA Y TECNOLOGIA
A6: DEPENDENCIA SOLICITANTE: | D6: DIRECCION PROVINCIAL DE GESTION ADMINISTRATIVA Y RECURSOS HUMANOS
A7: PERIODO UTILIZACIÓN: | D7: ='Necesidades Trimestrales'!C7 & "° Trimestre - Año " & 'Necesidades Trimestrales'!C6 -> 2° Trimestre - Año 2021
A8: OBJETO: | D8: ADQUISICION DE EQUIPOS, DESTINADAS AL CENTRO DEL CONOCIMIENTO PARA LAS AULAS DE FORMACIÓN, DEPENDIENTE DEL MINISTERIO DE CIENCIA E INNOVACION TECNOLOGICA.-
A10: Ítem | B10: Codigo Item | C10: DESCRIPCIÓN | H10: Adjunta Detalle Técnico | I10: Unidad Medida | J10: Precio Unitario Estimado | K10: Cantidad Solicitada
A12: 1 | B12: ='Necesidades Trimestrales'!B10 -> 4.3.5-9163.80 | C12: ='Necesidades Trimestrales'!E10 -> EQUIPOS DIDACTICOS TECNICOS; NOMBRE: LENTES, TIPO: REALIDAD VIRTUAL | H12: SI | I12: ='Necesidades Trimestrales'!F10 -> UNIDAD | J12: ='Necesidades Trimestrales'!H10 -> 198036.7 | K12: 3
A13: 2 | B13: ='Necesidades Trimestrales'!B11 -> 4.3.5-9163.80 | C13: ='Necesidades Trimestrales'!E11 -> EQUIPOS DIDACTICOS TECNICOS; NOMBRE: LENTES, TIPO: REALIDAD VIRTUAL | H13: SI | I13: ='Necesidades Trimestrales'!F11 -> UNIDAD | J13: ='Necesidades Trimestrales'!H11 -> 92202 | K13: 4
A14: 3 | B14: ='Necesidades Trimestrales'!B12 -> 4.3.6-9604.3 | C14: ='Necesidades Trimestrales'!E12 -> TABLETA PC; RESOLUCION: 1280 X 800 PXL, PANTALLA: 9,4 pulg, MEMORIA: 32 Gb, MEMORIA RAM: 32 Gb | H14: SI | I14: ='Necesidades Trimestrales'!F12 -> UNIDAD | J14: ='Necesidades Trimestrales'!H12 -> 55055 | K14: 6
A15: 4 | B15: ='Necesidades Trimestrales'!B13 -> 4.3.5-9163.90 | C15: ='Necesidades Trimestrales'!E13 -> EQUIPOS DIDACTICOS TECNICOS; NOMBRE: KIT EXPERIMENTAL , TIPO: SEGÚN PLIEGO | H15: SI | I15: ='Necesidades Trimestrales'!F13 -> UNIDAD | J15: ='Necesidades Trimestrales'!H13 -> 748264 | K15: 1
A16: Costo total estimado: PESOS DOS MILLONES CUARENTA Y UN MIL QUINIENTOS DOCE CON 10/100.- | J16: 2041512.1

Sheet Autor Gastar
A1: EJERCICIO: | D1: ='Necesidades Trimestrales'!C6 -> 2021 | P1: AUTORIZACION PARA GASTAR
A4: JURISDICCIÓN: | G4: =' NotaPedido'!D3 -> 70 - MINISTERIO DE CIENCIA E INNOVACION TECNOLOGICA
A5: SAF: | G5: =' NotaPedido'!D4 -> 20 - MINISTERIO DE CIENCIA E INNOVACION TECNOLOGICA
A6: UNIDAD EJECUTORA: | G6: =' NotaPedido'!D5 -> SECRETARIA DE CIENCIA Y TECNOLOGIA
A7: DEPENDENCIA SOLICITANTE: | G7: =' NotaPedido'!D6 -> DIRECCION PROVINCIAL DE GESTION ADMINISTRATIVA Y RECURSOS HUMANOS
A8: AUTORIZACIÓN:
A9: Señor Jefe de Servicio Administrativo Financiero:
A10: ="Autorizo la realización de los trámites correspondientes, a fin de proveer a este Organismo los bienes y/o servicios que se detallan en Nota de Pedido N° " & ' NotaPedido'!K1&", afectando la erogación resultante a los créditos presupuestarios aprobados a favor de esta Unidad Ejecutora, conforme al siguiente detalle:" -> Autorizo la realización de los trámites correspondientes, a fin de proveer a este Organismo los bienes y/o servicios que se detallan en Nota de Pedido N° 015/2021, afectando la erogación resultante a los créditos presupuestarios aprobados a favor de esta Unidad Ejecutora, conforme al siguiente detalle:
A12: IMPUTACIÓN PRESUPUESTARIA
A13: CÓDIGO | O13: DENOMINACIÓN DE LA PARTIDA PRESUPUESTARIA | Q13: IMPORTE
A14: PR | B14: SB | C14: PY | D14: AC | E14: OB | F14: UG | G14: FIN | H14: FUN | I14: I | J14: P | K14: P | L14: SubP | M14: M | N14: FF
A15: 2 | B15: 0 | C15: 0 | D15: 1 | E15: 0 | F15: 4901 | G15: 3 | H15: 350 | I15: =LEFT('Necesidades Trimestrales'!D13,1) -> 4 | J15: =MID('Necesidades Trimestrales'!D13,3,1) -> 3 | K15: =RIGHT('Necesidades Trimestrales'!D13,1) -> 5 | L15: 0 | M15: 1 | N15: 1.1 | O15: EQUIPOS EDUCACIONAL Y RECREATIVO | Q15: 1711182.1
A16: 2 | B16: 0 | C16: 0 | D16: 1 | E16: 0 | F16: 4901 | G16: 3 | H16: 350 | I16: 4 | J16: 3 | K16: 6 | L16: 0 | M16: 1 | N16: 1.1 | O16: EQUIPOS PARA COMPUTACION | Q16: 330330
A21: TOTAL DE PESOS: DOS MILLONES CUARENTA Y UN MIL QUINIENTOS DOCE CON 10/100.- | Q21: =SUM(Q15:Q20) -> 2041512.1
A23: JUSTIFICACIÓN:
A24: ADQUISICION DE EQUIPOS, DESTINADAS AL CENTRO DEL CONOCIMIENTO PARA LAS AULAS DE FORMACIÓN, DEPENDIENTE DEL MINISTERIO DE CIENCIA E INNOVACION TECNOLOGICA.-
