Workbook

Sheet SAF 011
A1: 2021
B2: Pedido de Necesidades Trimestrales
A4: JURISDICCION: | C4: 040 - MINISTERIO DE SALUD
A5: SAF N°: | C5: 011 - DIRECCION PROVINCIAL DE ADMINISTRACION - MINISTERIO DE SALUD
A6: EJERCICIO: | C6: 2021
A7: TRIMESTRE: | C7: CUARTO
A9: ID | B9: CODIGO ITEM | C9: RUBRO DE COMPRA | D9: I.P.P. | E9: DESCRIPCION | F9: UNIDAD DE MEDIDA | G9: SECRETARIA DE ADMINISTRACION | H9: TOTAL S.A. | I9: SMPyPS | J9: TOTAL SMPyPS | K9: DIR. LAB. CENTRAL | L9: TOTAL DE LAB CENTRAL | M9: BCO DE SANGRE | N9: TOTAL BANCO DE SANGRE | O9: APS | P9: TOTAL A.P.S. | Q9: DIR DE CANCER | R9: TOTAL DE DIR DE CANCER | S9: FARMACIA | T9: TOTAL FARMACIA | U9: ODONTOLOGIA | V9: TOTAL DE ODONTOLOG | W9: SAME | X9: TOTAL DE SAME | Y9: HPTAL MALBRAN | Z9: TOTAL HPTAL MALBRAN | AA9: MATERNIDAD E INFANCIA | AB9: TOTAL MATERNIDAD E INFANCIA | AC9: SASP | AD9: TOTAL SASP | AE9: SALUD Y MEDIO AMBIENTE | AF9: TOTAL SALUD Y MEDIO AMBIENTE | AG9: VECTORES Y ZOONOSIS | AH9: TOTAL DE VECT Y ZOON | AI9: SUMAR | AJ9: TOTAL SUMAR | AK9: CUR | AL9: TOTAL CUR | AM9: SPyGS | AN9: TOTAL SPyGS | AO9: SALUD MENTAL | AP9: TOTAL SALUD MENTAL | AQ9: AREAS Y DPAS | AR9: TOTAL DPAS | AS9: CANTIDAD TOTAL | AT9: PRECIO UNITARIO ESTIMADO | AU9: IMPORTE TOTAL ESTIMADO | AV9: ESPECIFICACION TECNICA | AX9: 256 | AY9: 252 | AZ9: 295 | BA9: 265 | BB9: 259
A10: 1 | C10: COMBUSTIBLES Y LUBRICANTES | D10: 2.5.6 | E10: ACEITES LUBRICANTES; USO: TURBINA ODONTOLOGICA, PRESENTACION: SPRAY X 250 mL, NORMA: SAE 30 | F10: UNIDAD | U10: 15 | V10: =+U10*AT10 -> 22500 | AS10: =+G10+I10+K10+M10+O10+Q10+S10+U10+W10+Y10++AA10+AC10+AE10+AG10+AI10+AK10+AM10+AO10+AQ10 -> 15 | AT10: 1500 | AU10: =+AS10*AT10 -> 22500 | AX10: =+AU10 -> 22500
A11: 2 | C11: PROD. MEDICO/FARMACEUTICOS/LAB | D11: 2.5.2 | E11: ACIDO GRABADOR ODONTOLOG.; ESTADO: GEL, PRESENTACION: JERINGA X 12 GR | F11: UNIDAD | U11: 30 | V11: =+U11*AT11 -> 26550 | AS11: =+G11+I11+K11+M11+O11+Q11+S11+U11+W11+Y11++AA11+AC11+AE11+AG11+AI11+AK11+AM11+AO11+AQ11 -> 30 | AT11: 885 | AU11: =+AS11*AT11 -> 26550 | AY11: 26550
A12: 3 | C12: PROD. MEDICO/FARMACEUTICOS/LAB | D12: 2.5.2 | E12: ADHESIVOS P/ODONTOLOGIA; TIPO: ADHESIVO+PRIMER, USO: ODONTOLOGICO, PRESENTACION: FRASCO X 4,5 mm | F12: UNIDAD | U12: 10 | V12: =+U12*AT12 -> 14900 | AS12: =+G12+I12+K12+M12+O12+Q12+S12+U12+W12+Y12++AA12+AC12+AE12+AG12+AI12+AK12+AM12+AO12+AQ12 -> 10 | AT12: 1490 | AU12: =+AS12*AT12 -> 14900 | AY12: 14900
A13: 4 | C13: PROD. MEDICO/FARMACEUTICOS/LAB | D13: 2.9.5 | E13: AGUJAS QUIRURGICAS; TIPO: ODONTOLOGICA, ESPECIFICACION: CORTA DE 21 mm, PRESENTACION: ENVASE X 100 UN | F13: CAJA | U13: 1 | V13: =+U13*AT13 -> 930 | AS13: =+G13+I13+K13+M13+O13+Q13+S13+U13+W13+Y13++AA13+AC13+AE13+AG13+AI13+AK13+AM13+AO13+AQ13 -> 1 | AT13: 930 | AU13: =+AS13*AT13 -> 930 | AZ13: =+AU13 -> 930
A14: 5 | C14: PROD. MEDICO/FARMACEUTICOS/LAB | D14: 2.9.5 | E14: ALAMBRE DE ACERO D. 0,7 MM, DESCARTABLE: SI, PRESENTACION: ROLLO X 500 GR | F14: UNIDAD | U14: 5 | V14: =+U14*AT14 -> 37250 | AS14: =+G14+I14+K14+M14+O14+Q14+S14+U14+W14+Y14++AA14+AC14+AE14+AG14+AI14+AK14+AM14+AO14+AQ14 -> 5 | AT14: 7450 | AU14: =+AS14*AT14 -> 37250 | AZ14: =+AU14 -> 37250
A15: 6 | C15: PROD. MEDICO/FARMACEUTICOS/LAB | D15: 2.9.5 | E15: ALAMBRE DE ACERO D. 0,8 MM; DESCARTABLE: SI, PRESENTACION: ROLLO X 100 GR | F15: UNIDAD | U15: 5 | V15: =+U15*AT15 -> 4400 | AS15: =+G15+I15+K15+M15+O15+Q15+S15+U15+W15+Y15++AA15+AC15+AE15+AG15+AI15+AK15+AM15+AO15+AQ15 -> 5 | AT15: 880 | AU15: =+AS15*AT15 -> 4400 | AZ15: =+AU15 -> 4400
A16: 7 | C16: PROD. MEDICO/FARMACEUTICOS/LAB | D16: 2.9.5 | E16: ALAMBRE DE ACERO D. 0,9 MM, DESCARTABLE: SI, PRESENTACION: ROLLO X 500 GR | F16: UNIDAD | U16: 5 | V16: =+U16*AT16 -> 37250 | AS16: =+G16+I16+K16+M16+O16+Q16+S16+U16+W16+Y16++AA16+AC16+AE16+AG16+AI16+AK16+AM16+AO16+AQ16 -> 5 | AT16: 7450 | AU16: =+AS16*AT16 -> 37250 | AZ16: =+AU16 -> 37250
A17: 8 | C17: PROD. MEDICO/FARMACEUTICOS/LAB | D17: 2.9.5 | E17: ALAMBRE DE ACERO D.1 MM, DESCARTABLE: SI, PRESENTACION: ROLLO X 50 GR | F17: UNIDAD | U17: 1 | V17: =+U17*AT17 -> 880 | AS17: =+G17+I17+K17+M17+O17+Q17+S17+U17+W17+Y17++AA17+AC17+AE17+AG17+AI17+AK17+AM17+AO17+AQ17 -> 1 | AT17: 880 | AU17: =+AS17*AT17 -> 880 | AZ17: =+AU17 -> 880
A18: 9 | C18: PROD. MEDICO/FARMACEUTICOS/LAB | D18: 2.9.5 | E18: ALGODONES; TIPO: ROLLO P/ODONTOLOGIA, PRESENTACION: ENVASE X 500 UN | F18: BOLSA | U18: 1000 | V18: =+U18*AT18 -> 655000 | AS18: =+G18+I18+K18+M18+O18+Q18+S18+U18+W18+Y18++AA18+AC18+AE18+AG18+AI18+AK18+AM18+AO18+AQ18 -> 1000 | AT18: 655 | AU18: =+AS18*AT18 -> 655000 | AZ18: =+AU18 -> 655000
A19: 10 | C19: PROD. MEDICO/FARMACEUTICOS/LAB | D19: 2.9.5 | E19: ALICATE UNIVERSAL, DESCARTABLE: NO, PRESENTACION: UNIDAD | F19: UNIDAD | U19: 50 | V19: =+U19*AT19 -> 72500 | AS19: =+G19+I19+K19+M19+O19+Q19+S19+U19+W19+Y19++AA19+AC19+AE19+AG19+AI19+AK19+AM19+AO19+AQ19 -> 50 | AT19: 1450 | AU19: =+AS19*AT19 -> 72500 | AZ19: =+AU19 -> 72500
A20: 11 | C20: PROD. MEDICO/FARMACEUTICOS/LAB | D20: 2.5.2 | E20: ANESTESICOS LOCALES; TIPO: ANESTESIA ODONTOLOGICA, DROGA GENERICA: CLORHIDRATO DE CARTICAINA 4%, FORMA FARMACEUTICA: ANESTUBOS, PRESENTACION: ENVASE X 50 ANESTUBOS | F20: CAJA | U20: 870 | V20: =+U20*AT20 -> 2923200 | AS20: =+G20+I20+K20+M20+O20+Q20+S20+U20+W20+Y20++AA20+AC20+AE20+AG20+AI20+AK20+AM20+AO20+AQ20 -> 870 | AT20: 3360 | AU20: =+AS20*AT20 -> 2923200 | AY20: 2923200
A21: 12 | C21: PROD. MEDICO/FARMACEUTICOS/LAB | D21: 2.5.2 | E21: ANTISEPTICOS LOCALES P/PERSONA; TIPO: ANTISEPTICO, DROGA GENERICA: EUGENOL, FORMA FARMACEUTICA: LIQUIDO, PRESENTACION: FRASCO X 10 mL | F21: UNIDAD | U21: 10 | V21: =+U21*AT21 -> 3000 | AS21: =+G21+I21+K21+M21+O21+Q21+S21+U21+W21+Y21++AA21+AC21+AE21+AG21+AI21+AK21+AM21+AO21+AQ21 -> 10 | AT21: 300 | AU21: =+AS21*AT21 -> 3000 | AY21: 3000
A22: 13 | C22: PROD. MEDICO/FARMACEUTICOS/LAB | D22: 2.5.2 | E22: ANTISEPTICOS LOCALES P/PERSONA; TIPO: MONODROGA, DROGA GENERICA: IODOFORMO, FORMA FARMACEUTICA: POLVO, PRESENTACION: FRASCO X 20 GR | F22: UNIDAD | U22: 10 | V22: =+U22*AT22 -> 11900 | AS22: =+G22+I22+K22+M22+O22+Q22+S22+U22+W22+Y22++AA22+AC22+AE22+AG22+AI22+AK22+AM22+AO22+AQ22 -> 10 | AT22: 1190 | AU22: =+AS22*AT22 -> 11900 | AY22: 11900
A23: 14 | C23: PROD. MEDICO/FARMACEUTICOS/LAB | D23: 2.9.5 | E23: ATACADOR P/CONOS GUTA-PERCHA, PRESENTACION: UNIDAD, DESCARTABLE: NO | F23: UNIDAD | U23: 30 | V23: =+U23*AT23 -> 8970 | AS23: =+G23+I23+K23+M23+O23+Q23+S23+U23+W23+Y23++AA23+AC23+AE23+AG23+AI23+AK23+AM23+AO23+AQ23 -> 30 | AT23: 299 | AU23: =+AS23*AT23 -> 8970 | AZ23: =+AU23 -> 8970
A24: 15 | C24: PROD. MEDICO/FARMACEUTICOS/LAB | D24: 2.9.5 | E24: BANDEJA METALICA PARA EL INSTRUMENTAL, DESCARTABLE: NO, PRESENTACION: UNIDAD | F24: UNIDAD | U24: 300 | V24: =+U24*AT24 -> 126000 | AS24: =+G24+I24+K24+M24+O24+Q24+S24+U24+W24+Y24++AA24+AC24+AE24+AG24+AI24+AK24+AM24+AO24+AQ24 -> 300 | AT24: 420 | AU24: =+AS24*AT24 -> 126000 | AZ24: =+AU24 -> 126000
A25: 16 | C25: PROD. MEDICO/FARMACEUTICOS/LAB | D25: 2.9.5 | E25: BARRA ALTO BRILLO P/PULIR, DESCARTABLE: NO, PRESENTACION: UNIDAD | F25: UNIDAD | U25: 30 | V25: =+U25*AT25 -> 8970 | AS25: =+G25+I25+K25+M25+O25+Q25+S25+U25+W25+Y25++AA25+AC25+AE25+AG25+AI25+AK25+AM25+AO25+AQ25 -> 30 | AT25: 299 | AU25: =+AS25*AT25 -> 8970 | AZ25: =+AU25 -> 8970
A26: 17 | C26: PROD. MEDICO/FARMACEUTICOS/LAB | D26: 2.9.5 | E26: BROCHITA P/ LIMPIEZA, DESCARTABLE: SI, PRESENTACION: UNIDAD | F26: UNIDAD | U26: 50 | V26: =+U26*AT26 -> 3112 | AS26: =+G26+I26+K26+M26+O26+Q26+S26+U26+W26+Y26++AA26+AC26+AE26+AG26+AI26+AK26+AM26+AO26+AQ26 -> 50 | AT26: 62.24 | AU26: =+AS26*AT26 -> 3112 | AZ26: =+AU26 -> 3112
A27: 18 | C27: PROD. MEDICO/FARMACEUTICOS/LAB | D27: 2.9.5 | E27: CADENAS P/BABEROS; MATERIAL : 147 dBV/mPa , USO: ODONTOLOGIA, MATERIAL: METAL | F27: UNIDAD | U27: 200 | V27: =+U27*AT27 -> 39800 | AS27: =+G27+I27+K27+M27+O27+Q27+S27+U27+W27+Y27++AA27+AC27+AE27+AG27+AI27+AK27+AM27+AO27+AQ27 -> 200 | AT27: 199 | AU27: =+AS27*AT27 -> 39800 | AZ27: =+AU27 -> 39800
A28: 19 | C28: PROD. MEDICO/FARMACEUTICOS/LAB | D28: 2.5.2 | E28: CEMENTOS QUIRURGICOS; TIPO: GROSSMAN, USO: ODONTOLOGIA, PRESENTACION: ENVASE X 20 GR | F28: CAJA | U28: 10 | V28: =+U28*AT28 -> 4400 | AS28: =+G28+I28+K28+M28+O28+Q28+S28+U28+W28+Y28++AA28+AC28+AE28+AG28+AI28+AK28+AM28+AO28+AQ28 -> 10 | AT28: 440 | AU28: =+AS28*AT28 -> 4400 | AY28: 4400
A29: 20 | C29: PROD. MEDICO/FARMACEUTICOS/LAB | D29: 2.5.2 | E29: CEMENTOS QUIRURGICOS; TIPO: HIDROXIDO DE CALCIO FRAGUABLE, USO: ODONTOLOGIA, PRESENTACION: AVIO 13 GRS/11 GRS HIDCAL | F29: CAJA | U29: 10 | V29: =+U29*AT29 -> 23000 | AS29: =+G29+I29+K29+M29+O29+Q29+S29+U29+W29+Y29++AA29+AC29+AE29+AG29+AI29+AK29+AM29+AO29+AQ29 -> 10 | AT29: 2300 | AU29: =+AS29*AT29 -> 23000 | AY29: 23000
A30: 21 | C30: PROD. MEDICO/FARMACEUTICOS/LAB | D30: 2.5.2 | E30: CEMENTOS QUIRURGICOS; TIPO: OXIDO DE ZINC Y EUGENOL REFORZ, USO: ODONTOLOGICO, PRESENTACION: AVIO 38 GRS/15 ML | F30: CAJA | U30: 10 | V30: =+U30*AT30 -> 18500 | AS30: =+G30+I30+K30+M30+O30+Q30+S30+U30+W30+Y30++AA30+AC30+AE30+AG30+AI30+AK30+AM30+AO30+AQ30 -> 10 | AT30: 1850 | AU30: =+AS30*AT30 -> 18500 | AY30: 18500
A31: 22 | C31: PROD. MEDICO/FARMACEUTICOS/LAB | D31: 2.9.5 | E31: CEPILLO LIMPIAFRESA, DESCARTABLE: NO, PRESENTACION: UNIDAD | F31: UNIDAD | U31: 20 | V31: =+U31*AT31 -> 5000 | AS31: =+G31+I31+K31+M31+O31+Q31+S31+U31+W31+Y31++AA31+AC31+AE31+AG31+AI31+AK31+AM31+AO31+AQ31 -> 20 | AT31: 250 | AU31: =+AS31*AT31 -> 5000 | AZ31: =+AU31 -> 5000
A32: 23 | C32: PROD. MEDICO/FARMACEUTICOS/LAB | D32: 2.5.9 | E32: CERAS ROSAS P/ODONTOLOGIA; MATERIAL: UTILITY EN LAMINA, USO: ODONTOLOGICO, PRESENTACION: ENVASE X 1 Kg | F32: CAJA | U32: 5 | V32: =+U32*AT32 -> 12250 | AS32: =+G32+I32+K32+M32+O32+Q32+S32+U32+W32+Y32++AA32+AC32+AE32+AG32+AI32+AK32+AM32+AO32+AQ32 -> 5 | AT32: 2450 | AU32: =+AS32*AT32 -> 12250 | BB32: 12250
A33: 24 | C33: PROD. MEDICO/FARMACEUTICOS/LAB | D33: 2.5.2 | E33: COMPOSITE TIPO ULTRAFILL; COLOR: A2, POLIMERIZACION: FOTOPOLIMERIZACION, TAMAÑO PARTICULA: HIBRIDO, FORMA DE PRESENTACION: JERINGA, PRESENTACION: ENVASE X 4 GR | F33: UNIDAD | U33: 50 | V33: =+U33*AT33 -> 64500 | AS33: =+G33+I33+K33+M33+O33+Q33+S33+U33+W33+Y33++AA33+AC33+AE33+AG33+AI33+AK33+AM33+AO33+AQ33 -> 50 | AT33: 1290 | AU33: =+AS33*AT33 -> 64500 | AY33: 64500
A34: 25 | C34: PROD. MEDICO/FARMACEUTICOS/LAB | D34: 2.5.2 | E34: COMPOSITE TIPO ULTRAFILL; COLOR: A3, POLIMERIZACION: FOTOPOLIMERIZACION, TAMAÑO PARTICULA: HIBRIDO, FORMA DE PRESENTACION: JERINGA, PRESENTACION: ENVASE X 4 GR | F34: UNIDAD | U34: 50 | V34: =+U34*AT34 -> 64500 | AS34: =+G34+I34+K34+M34+O34+Q34+S34+U34+W34+Y34++AA34+AC34+AE34+AG34+AI34+AK34+AM34+AO34+AQ34 -> 50 | AT34: 1290 | AU34: =+AS34*AT34 -> 64500 | AY34: 64500
A35: 26 | C35: PROD. MEDICO/FARMACEUTICOS/LAB | D35: 2.5.2 | E35: COMPOSITE TIPO ULTRAFILL; COLOR: A3,5, POLIMERIZACION: FOTOPOLIMERIZACION, TAMAÑO PARTICULA: HIBRIDO, FORMA DE PRESENTACION: JERINGA, PRESENTACION: ENVASE X 4 GR | F35: UNIDAD | U35: 10 | V35: =+U35*AT35 -> 12900 | AS35: =+G35+I35+K35+M35+O35+Q35+S35+U35+W35+Y35++AA35+AC35+AE35+AG35+AI35+AK35+AM35+AO35+AQ35 -> 10 | AT35: 1290 | AU35: =+AS35*AT35 -> 12900 | AY35: 12900
A36: 27 | C36: PROD. MEDICO/FARMACEUTICOS/LAB | D36: 2.9.5 | E36: COMPRESA P/PLATINA AZUL, DESCARTABLE: SI, PRESENTACION: CAJA X 500 UN | F36: CAJA | U36: 200 | V36: =+U36*AT36 -> 585000 | AS36: =+G36+I36+K36+M36+O36+Q36+S36+U36+W36+Y36++AA36+AC36+AE36+AG36+AI36+AK36+AM36+AO36+AQ36 -> 200 | AT36: 2925 | AU36: =+AS36*AT36 -> 585000 | AZ36: =+AU36 -> 585000
A37: 28 | C37: PROD. MEDICO/FARMACEUTICOS/LAB | D37: 2.9.5 | E37: CONO DE FIELTRO Nº 4, DESCARTABLE: SI, PRESENTACION: UNIDAD | F37: UNIDAD | U37: 10 | V37: =+U37*AT37 -> 5500 | AS37: =+G37+I37+K37+M37+O37+Q37+S37+U37+W37+Y37++AA37+AC37+AE37+AG37+AI37+AK37+AM37+AO37+AQ37 -> 10 | AT37: 550 | AU37: =+AS37*AT37 -> 5500 | AZ37: =+AU37 -> 5500
A38: 29 | C38: PROD. MEDICO/FARMACEUTICOS/LAB | D38: 2.9.5 | E38: CONO GUTAPERCHA 1ªSERIE, DESCARTABLE: SI, PRESENTACION: CAJA X 100 | F38: CAJA | U38: 30 | V38: =+U38*AT38 -> 21900 | AS38: =+G38+I38+K38+M38+O38+Q38+S38+U38+W38+Y38++AA38+AC38+AE38+AG38+AI38+AK38+AM38+AO38+AQ38 -> 30 | AT38: 730 | AU38: =+AS38*AT38 -> 21900 | AZ38: =+AU38 -> 21900
A39: 30 | C39: PROD. MEDICO/FARMACEUTICOS/LAB | D39: 2.9.5 | E39: CONO GUTAPERCHA 2ªSERIE, DESCARTABLE: SI, PRESENTACION: CAJA X 100 | F39: CAJA | U39: 30 | V39: =+U39*AT39 -> 21900 | AS39: =+G39+I39+K39+M39+O39+Q39+S39+U39+W39+Y39++AA39+AC39+AE39+AG39+AI39+AK39+AM39+AO39+AQ39 -> 30 | AT39: 730 | AU39: =+AS39*AT39 -> 21900 | AZ39: =+AU39 -> 21900
A40: 31 | C40: PROD. MEDICO/FARMACEUTICOS/LAB | D40: 2.9.5 | E40: CUCHARITAS DE BLACK DOBLES, DESCARTABLE: NO, PRESENTACION: UNIDAD | F40: UNIDAD | U40: 100 | V40: =+U40*AT40 -> 29850 | AS40: =+G40+I40+K40+M40+O40+Q40+S40+U40+W40+Y40++AA40+AC40+AE40+AG40+AI40+AK40+AM40+AO40+AQ40 -> 100 | AT40: 298.5 | AU40: =+AS40*AT40 -> 29850 | AZ40: =+AU40 -> 29850
A41: 32 | C41: PROD. MEDICO/FARMACEUTICOS/LAB | D41: 2.9.5 | E41: CURETA DE GRACEY, DESCARTABLE: NO, PRESENTACION: UNIDAD | F41: UNIDAD | U41: 100 | V41: =+U41*AT41 -> 175000 | AS41: =+G41+I41+K41+M41+O41+Q41+S41+U41+W41+Y41++AA41+AC41+AE41+AG41+AI41+AK41+AM41+AO41+AQ41 -> 100 | AT41: 1750 | AU41: =+AS41*AT41 -> 175000 | AZ41: =+AU41 -> 175000
A42: 33 | C42: PROD. MEDICO/FARMACEUTICOS/LAB | D42: 2.9.5 | E42: DISCO P/ PULIR, DESCARTABLE: NO, PRESENTACION: UNIDAD | F42: UNIDAD | U42: 50 | V42: =+U42*AT42 -> 10000 | AS42: =+G42+I42+K42+M42+O42+Q42+S42+U42+W42+Y42++AA42+AC42+AE42+AG42+AI42+AK42+AM42+AO42+AQ42 -> 50 | AT42: 200 | AU42: =+AS42*AT42 -> 10000 | AZ42: =+AU42 -> 10000
...

Sheet NP
A1: NOTA DE PEDIDO | J1: N° | K1: 16/2021
A3: JURISDICCIÓN: | D3: 040 - MINISTERIO DE SALUD
A4: SAF: | D4: 011 - DIRECCION PROVINCIAL DE ADMINISTRACION DEL MINISTERIO DE SALUD
A5: UNIDAD EJECUTORA: | D5: 470 - DIRECCION PROVINCIAL DE ODONTOLOGIA
A6: DEPENDENCIA SOLICITANTE: | D6: 470 - DIRECCION PROVINCIAL DE ODONTOLOGIA
A7: PERIODO UTILIZACIÓN: | D7: 4TO TRIMESTRE
A8: OBJETO: | D8: ADQ. DEL RUBRO INSUMOS PARA ODONTOLOGIA
A10: Ítem | B10: Codigo Item | C10: DESCRIPCIÓN | H10: Adjunta Detalle Técnico | I10: Unidad Medida | J10: Precio Unitario Estimado | K10: Cantidad Solicitada
A12: 1 | C12: ='SAF 011'!E10 -> ACEITES LUBRICANTES; USO: TURBINA ODONTOLOGICA, PRESENTACION: SPRAY X 250 mL, NORMA: SAE 30 | H12: NO | I12: ='SAF 011'!F10 -> UNIDAD | J12: ='SAF 011'!AT10 -> 1500 | K12: ='SAF 011'!U10 -> 15 | M12: =+J12*K12 -> 22500
A13: 2 | C13: ='SAF 011'!E11 -> ACIDO GRABADOR ODONTOLOG.; ESTADO: GEL, PRESENTACION: JERINGA X 12 GR | H13: NO | I13: ='SAF 011'!F11 -> UNIDAD | J13: ='SAF 011'!AT11 -> 885 | K13: ='SAF 011'!U11 -> 30 | M13: =+J13*K13 -> 26550
A14: 3 | C14: ='SAF 011'!E12 -> ADHESIVOS P/ODONTOLOGIA; TIPO: ADHESIVO+PRIMER, USO: ODONTOLOGICO, PRESENTACION: FRASCO X 4,5 mm | H14: NO | I14: ='SAF 011'!F12 -> UNIDAD | J14: ='SAF 011'!AT12 -> 1490 | K14: ='SAF 011'!U12 -> 10 | M14: =+J14*K14 -> 14900
A15: 4 | C15: ='SAF 011'!E13 -> AGUJAS QUIRURGICAS; TIPO: ODONTOLOGICA, ESPECIFICACION: CORTA DE 21 mm, PRESENTACION: ENVASE X 100 UN | H15: NO | I15: ='SAF 011'!F13 -> CAJA | J15: ='SAF 011'!AT13 -> 930 | K15: ='SAF 011'!U13 -> 1 | M15: =+J15*K15 -> 930
A16: 5 | C16: ='SAF 011'!E14 -> ALAMBRE DE ACERO D. 0,7 MM, DESCARTABLE: SI, PRESENTACION: ROLLO X 500 GR | H16: NO | I16: ='SAF 011'!F14 -> UNIDAD | J16: ='SAF 011'!AT14 -> 7450 | K16: ='SAF 011'!U14 -> 5 | M16: =+J16*K16 -> 37250
A17: 6 | C17: ='SAF 011'!E15 -> ALAMBRE DE ACERO D. 0,8 MM; DESCARTABLE: SI, PRESENTACION: ROLLO X 100 GR | H17: NO | I17: ='SAF 011'!F15 -> UNIDAD | J17: ='SAF 011'!AT15 -> 880 | K17: ='SAF 011'!U15 -> 5 | M17: =+J17*K17 -> 4400
A18: 7 | C18: ='SAF 011'!E16 -> ALAMBRE DE ACERO D. 0,9 MM, DESCARTABLE: SI, PRESENTACION: ROLLO X 500 GR | H18: NO | I18: ='SAF 011'!F16 -> UNIDAD | J18: ='SAF 011'!AT16 -> 7450 | K18: ='SAF 011'!U16 -> 5 | M18: =+J18*K18 -> 37250
A19: 8 | C19: ='SAF 011'!E17 -> ALAMBRE DE ACERO D.1 MM, DESCARTABLE: SI, PRESENTACION: ROLLO X 50 GR | H19: NO | I19: ='SAF 011'!F17 -> UNIDAD | J19: ='SAF 011'!AT17 -> 880 | K19: ='SAF 011'!U17 -> 1 | M19: =+J19*K19 -> 880
A20: 9 | C20: ='SAF 011'!E18 -> ALGODONES; TIPO: ROLLO P/ODONTOLOGIA, PRESENTACION: ENVASE X 500 UN | H20: NO | I20: ='SAF 011'!F18 -> BOLSA | J20: ='SAF 011'!AT18 -> 655 | K20: ='SAF 011'!U18 -> 1000 | M20: =+J20*K20 -> 655000
A21: 10 | C21: ='SAF 011'!E19 -> ALICATE UNIVERSAL, DESCARTABLE: NO, PRESENTACION: UNIDAD | H21: NO | I21: ='SAF 011'!F19 -> UNIDAD | J21: ='SAF 011'!AT19 -> 1450 | K21: ='SAF 011'!U19 -> 50 | M21: =+J21*K21 -> 72500
A22: 11 | C22: ='SAF 011'!E20 -> ANESTESICOS LOCALES; TIPO: ANESTESIA ODONTOLOGICA, DROGA GENERICA: CLORHIDRATO DE CARTICAINA 4%, FORMA FARMACEUTICA: ANESTUBOS, PRESENTACION: ENVASE X 50 ANESTUBOS | H22: NO | I22: ='SAF 011'!F20 -> CAJA | J22: ='SAF 011'!AT20 -> 3360 | K22: ='SAF 011'!U20 -> 870 | M22: =+J22*K22 -> 2923200
A23: 12 | C23: ='SAF 011'!E21 -> ANTISEPTICOS LOCALES P/PERSONA; TIPO: ANTISEPTICO, DROGA GENERICA: EUGENOL, FORMA FARMACEUTICA: LIQUIDO, PRESENTACION: FRASCO X 10 mL | H23: NO | I23: ='SAF 011'!F21 -> UNIDAD | J23: ='SAF 011'!AT21 -> 300 | K23: ='SAF 011'!U21 -> 10 | M23: =+J23*K23 -> 3000
... A159: 148 | C159: ='SAF 011'!E157 -> YESO EN POLVO; USO: ODONTOLOGICO, TIPO: TALLER, PRESENTACION: BOLSA, PESO: 25 Kg | H159: NO | I159: ='SAF 011'!F157 -> BOLSA | J159: ='SAF 011'!AT157 -> 3690 | K159: ='SAF 011'!U157 -> 40 | M159: =+J159*K159 -> 147600
M160: =+J160*K160 -> 0
A161: Costo total estimado: | C161: DIEZ MILLONES TRESCIENTOS SETENTA Y OCHO MIL NOVECIENTOS NOVENTA Y CUATRO CON 50/100.- | J161: =+M161 -> 10378994 | M161: =SUM(M12:M160) -> 10378994

Sheet APG
A1: EJERCICIO: | D1: 2021 | P1: AUTORIZACION PARA GASTAR
A4: JURISDICCIÓN: | G4: =NP!D3 -> 040 - MINISTERIO DE SALUD
A5: SAF: | G5: =NP!D4 -> 011 - DIRECCION PROVINCIAL DE ADMINISTRACION DEL MINISTERIO DE SALUD
A6: UNIDAD EJECUTORA: | G6: =NP!D5 -> 470 - DIRECCION PROVINCIAL DE ODONTOLOGIA
A7: DEPENDENCIA SOLICITANTE: | G7: =NP!D6 -> 470 - DIRECCION PROVINCIAL DE ODONTOLOGIA
A8: AUTORIZACIÓN:
A9: Señor Director de Administración o Titular del Servicio Administrativo Financiero:
A10: Autorizo la realización de los trámites correspondientes, a fin de proveer a este Organismo los bienes que se detallan en Nota de Pedido N° 16/2021 afectando la erogación resultante a los créditos presupuestarios aprobados a favor de esta Unidad Ejecutora, conforme al siguiente detalle:
A12: IMPUTACIÓN PRESUPUESTARIA
A13: CÓDIGO | O13: DENOMINACIÓN DE LA PARTIDA PRESUPUESTARIA | Q13: IMPORTE
A14: PR | B14: SB | C14: PY | D14: AC | E14: OB | F14: UG | G14: FIN | H14: FUN | I14: I | J14: P | K14: P | L14: SubP | M14: M | N14: FF
A15: 29 | D15: 1 | F15: 4901 | G15: 3 | H15: 1 | I15: 2 | J15: 5 | K15: 2 | M15: 1 | N15: 1.1 | O15: PRODUCTOS FARMACEUTICOS Y MEDICINALES | Q15: ='SAF 011'!AY158 -> 3249120
A16: 29 | D16: 1 | F16: 4901 | G16: 3 | H16: 1 | I16: 2 | J16: 5 | K16: 6 | M16: 1 | N16: 1.1 | O16: COMBUSTIBLES Y LUBRICANTES | Q16: ='SAF 011'!AX158 -> 22500
A17: 29 | D17: 1 | F17: 4901 | G17: 3 | H17: 1 | I17: 2 | J17: 5 | K17: 9 | M17: 1 | N17: 1.1 | O17: OTROS N.E.P | Q17: ='SAF 011'!BB158 -> 357050
A18: 29 | D18: 1 | F18: 4901 | G18: 3 | H18: 1 | I18: 2 | J18: 6 | K18: 5 | M18: 1 | N18: 1.1 | O18: CEMENTO, CAL Y YESO | Q18: ='SAF 011'!BA158 -> 306400
A19: 29 | D19: 1 | F19: 4901 | G19: 3 | H19: 1 | I19: 2 | J19: 9 | K19: 5 | M19: 1 | N19: 1.1 | O19: UTILES MENORES MEDIDOS, QUIRURGICOS Y DE LABORATORIO | Q19: ='SAF 011'!AZ158 -> 6443924.5
A26: TOTAL DE PESOS: | F26: =NP!C161 -> DIEZ MILLONES TRESCIENTOS SETENTA Y OCHO MIL NOVECIENTOS NOVENTA Y CUATRO CON 50/100.- | Q26: =SUM(Q15:Q25) -> 10378995
A28: JUSTIFICACIÓN:
A29: =NP!D8 -> ADQ. DEL RUBRO INSUMOS PARA ODONTOLOGIA

Sheet RR.HH.
B1: DIRECCION PROVINCIAL DE ODONTOLOGIA
A3: CAPS / HOSPITALES | B3: PROFESIONALES | C3: HORARIOS | D3: PRESTACIONES | E3: SILLONES | F3: ESTADO | G3: APA. DE RAYO | H3: OBSERVACIONES
A4: CAPS JESUS DE NAZARET | B4: VALLICA ANABELLA | C4: TM | D4: OPERATORIA | E4: 1 | G4: 1
B5: BLANCO ADRIANA | C5: TT | D5: OPERATORIA
A6: CAPS APOLO | B6: ROBLES MARIA GIMENA | C6: TT | D6: ODONTOLOGIA GRAL. | E6: 1
B7: VILLAFAÑEZ EMILIO | C7: TM | D7: ODONTOLOGIA GRAL.
B8: MESA LILIANA | C8: TM | D8: ODONTOLOGIA GRAL.
A9: CAPS SAN JOSE OBRERO | B9: TAPIA SERGIO | C9: TM | D9: ODONTOLOGIA GRAL. | E9: 1
B10: SECO AGUSTIN | C10: TT | D10: ODONTOLOGIA GRAL.
A11: CAPS EVA PERON | B11: MOYANO DANIEL | C11: TM | D11: ODONTOLOGIA GRAL. | E11: 1
B12: AREVALO JULIA | C12: TT | D12: ODONTOLOGIA GRAL.
A13: CAPS 500 VIVIENDAS | B13: LOBOS ALEJANDRO | C13: TT | D13: ODONTOLOGIA GRAL. | E13: 1
B14: CAROSELLA ANTONELA | C14: TM | D14: ODONTOLOGIA GRAL.
B15: FADEL MARIA SOLEDAD | C15: TT | D15: ODONTOLOGIA GRAL.
A16: CAPS TERESA DE CALCUTA | B16: MORENO FERNANDO | C16: TT | D16: ODONTOLOGIA GRAL. | E16: 1 | F16: CAPS QUE PASA A LA MUNICIPALIDAD | G16: PASARIA AL EDGARDO ACUÑA | H16: EQUIPAMIENTO MUNICIPAL
A17: HOGAR ESCUELA | E17: 1 | H17: EQUPAMIENTO DE EDUCACION
A19: ESCUELA 271 PROV. STGO. DEL ESTERO PASO AL EDGARDO ACUÑA | B19: MIRANDA RUTH | C19: TM | D19: ODONTOLOGIA GRAL. | E19: 1
A20: CAPS LA CRUZ NEGRA | B20: OVEJERO ANA GABRIELA | C20: TM | D20: ODONTOLOGIA GRAL. | E20: 1
B21: BURGOS LUCIANA | C21: TT | D21: ODONTOLOGIA GRAL.
A22: CAPS BANDA DE VALERA | B22: VALVERDI GIMENA | C22: TM | D22: ODONTOLOGIA GRAL. | E22: 1
B23: DINARO ALDO | C23: TT | D23: ODONTOLOGIA GRAL.
A24: CAPS NUEVA CONETA | B24: UNZAGA MARIANO | C24: TT | D24: CIRUGIA | E24: 1
B25: MARTINEZ JAVIER | C25: TM L,M,V | D25: ODONTOLOGIA GRAL.
A26: CAPS LIBERTADOR ll | B26: ZURITA VIRGINIA | C26: TT | D26: OPERATORIA | E26: 1 | G26: 1
B27: AVALOS BERRONDO GABRIEL | C27: TT | D27: EXODONCIA
B28: NAVARRO LOSSO SILVINA | C28: TM | D28: OPERATORIA
B29: FERNANDEZ CINTIA | C29: TM | D29: EXODONCIA
A30: CAPS ALEM | B30: ALSINA LUCIA | C30: TM | D30: EXODONCIA | E30: 1 | G30: 1
B31: GOMEZ PAOLA | C31: TT | D31: ODONTOLOGIA GRAL.
A32: CAPS SAN MARTIN | B32: PERDIGON ELENA | C32: TT | D32: ODONTOLOGIA GRAL. | E32: 1 | G32: 1
B33: APARICIO GONZALO | C33: TM | D33: EXODONCIA
A34: CAPS CARLOS BRAVO | B34: SOLA MARIANA | C34: TM | D34: ODONTOPEDIATRIA | E34: 4 | F34: 2 NO FUNCIONAN | G34: 1
B35: MORETA LEANDRO | C35: TT | D35: ODONTOLOGIA GRAL. | F35: 1 FUNCIONA | H35: EQUIPAMIENTO MUNICIPAL
B36: MACEDO IGNACIO | C36: TM | D36: ODONTOLOGIA GRAL. | F36: 1 CON VARIOS DESPERFECTOS
B37: CARO HORACIO | C37: TT | D37: ODONTOLOGIA GRAL.
A38: CAPS EDGARDO ACUÑA | B38: GARRIGA GUSTAVO | C38: TM | D38: ODONTOLOGIA GRAL. | E38: 4 | F38: 1 FUNCIONA | G38: 1 | H38: SILLON MUNICIPAL
B39: MIRANDA RUTH | C39: TM | D39: ODONTOLOGIA GRAL.
B40: OLMOS PABLO | C40: TM | D40: ODONTOLOGIA GRAL. | F40: 3 CON VARIOS DESPERFECTOS | H40: RX PROVINCIA
A41: CAPS 920 | B41: PEÑARANDA KAREN | C41: TM | D41: ODONTOLOGIA GRAL. | E41: 1 | G41: 1
B42: DE MARCO MARIA INES | C42: TT( ART.25) | D42: LARGO TRAMIENTO POR HIJO CON C.A.
...
