Workbook

Sheet Necesidades Trimestrales
B2: Pedido de Necesidades Trimestrales
A4: JURISDICCION: | C4: 040 - Ministerio de Salud
A5: SAF N°: | C5: 011 - Direccion Provincial de Administracion - MS
A6: EJERCICIO: | C6: 2022
A7: TRIMESTRE: | C7: 4
A9: ID | B9: CODIGO ITEM | C9: RUBRO DE COMPRA | D9: I.P.P. | E9: DESCRIPCION | F9: UNIDAD DE MEDIDA | G9: CANT. DPFeI | H9: TOTAL DPFeI | I9: CANT. DPMIA | J9: TOTAL DPMIA | K9: CANT. DPSAME | L9: TOTAL DPSAME | M9: CANT. TOTAL | N9: PRECIO UNITARIO ESTIMADO | O9: IMPORTE TOTAL ESTIMADO
A10: 1 | B10: 2.5.2-1875.133 | C10: PROD. MEDICO/FARMACEUTICOS/LAB | D10: 252 | E10: ANTIASMATICO BRONCODILATADOR; TIPO: MONODROGA, DROGA GENERICA: N-ACETIL CISTEINA 600 MGR, FORMA FARMACEUTICA: TABLETA EFERVESCENTE, PRESENTACION: UNIDAD | F10: UNIDAD | G10: 500 | H10: =+G10*N10 -> 17620 | J10: =+I10*N10 -> 0 | L10: =+K10*N10 -> 0 | M10: =+G10+I10+K10 -> 500 | N10: 35.24 | O10: =+M10*N10 -> 17620
A11: 2 | B11: 2.5.2-1829.25 | C11: PROD. MEDICO/FARMACEUTICOS/LAB | D11: 252 | E11: ANTIVIRALES; TIPO: MONODROGA, DROGA GENERICA: ACICLOVIR 5 %, FORMA FARMACEUTICA: CREMA, PRESENTACION: ENVASE X 5 GR | F11: UNIDAD | G11: 100 | H11: =+G11*N11 -> 28500 | J11: =+I11*N11 -> 0 | L11: =+K11*N11 -> 0 | M11: =+G11+I11+K11 -> 100 | N11: 285 | O11: =+M11*N11 -> 28500
A12: 3 | B12: 2.5.2-1875.74 | C12: PROD. MEDICO/FARMACEUTICOS/LAB | D12: 252 | E12: ANTIASMATICO BRONCODILATADOR; TIPO: MONODROGA, DROGA GENERICA: AMINOFILINA 240MGR, FORMA FARMACEUTICA: AMPOLLA, PRESENTACION: ENVASE X 10 ML | F12: AMPOLLA | G12: 1000 | H12: =+G12*N12 -> 86000 | J12: =+I12*N12 -> 0 | L12: =+K12*N12 -> 0 | M12: =+G12+I12+K12 -> 1000 | N12: 86 | O12: =+M12*N12 -> 86000
A13: 4 | B13: 2.9.5-427.33 | C13: PROD. MEDICO/FARMACEUTICOS/LAB | D13: 252 | E13: APOSITOS; TIPO: HIDROCOLOIDE, TAMAÑO: 15 X 17,5 Cm | F13: UNIDAD | G13: 50 | H13: =+G13*N13 -> 56000 | J13: =+I13*N13 -> 0 | L13: =+K13*N13 -> 0 | M13: =+G13+I13+K13 -> 50 | N13: 1120 | O13: =+M13*N13 -> 56000
A14: 5 | B14: 2.9.5-427.39 | C14: PROD. MEDICO/FARMACEUTICOS/LAB | D14: 252 | E14: APOSITOS; TIPO: HIDROCOLOIDE, TAMAÑO: 10 X 10 Cm | F14: UNIDAD | G14: 100 | H14: =+G14*N14 -> 58000 | J14: =+I14*N14 -> 0 | L14: =+K14*N14 -> 0 | M14: =+G14+I14+K14 -> 100 | N14: 580 | O14: =+M14*N14 -> 58000
A15: 6 | B15: 2.5.2-1855.23 | C15: PROD. MEDICO/FARMACEUTICOS/LAB | D15: 252 | E15: CORTICOESTEROIDES; TIPO: MONODROGA, DROGA GENERICA: BETAMETASONA, FORMA FARMACEUTICA: CREMA, PRESENTACION: 15 GR | F15: UNIDAD | G15: 1000 | H15: =+G15*N15 -> 280000 | J15: =+I15*N15 -> 0 | L15: =+K15*N15 -> 0 | M15: =+G15+I15+K15 -> 1000 | N15: 280 | O15: =+M15*N15 -> 280000
A16: 7 | B16: 2.5.2-1855.83 | C16: PROD. MEDICO/FARMACEUTICOS/LAB | D16: 252 | E16: CORTICOESTEROIDES; TIPO: ASOCIACION, DROGA GENERICA: BETAMETASONA ACETATO+FOSFATO, FORMA FARMACEUTICA: AMPOLLA, PRESENTACION: ENVASE X 2 mL | F16: AMPOLLA | G16: 10000 | H16: =+G16*N16 -> 2950000 | J16: =+I16*N16 -> 0 | L16: =+K16*N16 -> 0 | M16: =+G16+I16+K16 -> 10000 | N16: 295 | O16: =+M16*N16 -> 2950000
A17: 8 | B17: 2.5.2-1875.134 | C17: PROD. MEDICO/FARMACEUTICOS/LAB | D17: 252 | E17: ANTIASMATICO BRONCODILATADOR; TIPO: MONODROGA, DROGA GENERICA: BUDESONIDE 200 µGR, FORMA FARMACEUTICA: AEROSOL, PRESENTACION: 100 DOSIS | F17: UNIDAD | G17: 2000 | H17: =+G17*N17 -> 1500000 | J17: =+I17*N17 -> 0 | L17: =+K17*N17 -> 0 | M17: =+G17+I17+K17 -> 2000 | N17: 750 | O17: =+M17*N17 -> 1500000
A18: 9 | B18: 2.5.2-2476.50 | C18: PROD. MEDICO/FARMACEUTICOS/LAB | D18: 252 | E18: ANTIALERGICOS-ANTIHISTAMINICOS; TIPO: MONODROGA, DROGA GENERICA: BUDESONIDA 1 MG/ML, FORMA FARMACEUTICA: GOTAS, PRESENTACION: ENVASE X 20 mL | F18: UNIDAD | G18: 300 | H18: =+G18*N18 -> 98100 | J18: =+I18*N18 -> 0 | L18: =+K18*N18 -> 0 | M18: =+G18+I18+K18 -> 300 | N18: 327 | O18: =+M18*N18 -> 98100
A19: 10 | B19: 2.5.2-1823.67 | C19: PROD. MEDICO/FARMACEUTICOS/LAB | D19: 252 | E19: ANTIMICOTICOS; TIPO: MONODROGA, DROGA GENERICA: CLOTRIMAZOL 1%, FORMA FARMACEUTICA: CREMA POR 20 GR, PRESENTACION: UNIDAD | F19: UNIDAD | G19: 1000 | H19: =+G19*N19 -> 280000 | J19: =+I19*N19 -> 0 | L19: =+K19*N19 -> 0 | M19: =+G19+I19+K19 -> 1000 | N19: 280 | O19: =+M19*N19 -> 280000
A20: 11 | B20: 2.5.2-1855.7 | C20: PROD. MEDICO/FARMACEUTICOS/LAB | D20: 252 | E20: CORTICOESTEROIDES; TIPO: MONODROGA, DROGA GENERICA: DEXAMETASONA, FORMA FARMACEUTICA: AMPOLLA, PRESENTACION: 8 mGr | F20: AMPOLLA | G20: 120000 | H20: =+G20*N20 -> 5400000 | J20: =+I20*N20 -> 0 | K20: 700 | L20: =+K20*N20 -> 31500 | M20: =+G20+I20+K20 -> 120700 | N20: 45 | O20: =+M20*N20 -> 5431500
A21: 12 | B21: 2.5.2-2476.74 | C21: PROD. MEDICO/FARMACEUTICOS/LAB | D21: 252 | E21: ANTIALERGICOS-ANTIHISTAMINICOS; TIPO: MONODROGA, DROGA GENERICA: DIFENHIDRAMINA 250 MG, FORMA FARMACEUTICA: JARABE, PRESENTACION: FRASCO X 120 mL | F21: FRASCO | G21: 15000 | H21: =+G21*N21 -> 2985000 | J21: =+I21*N21 -> 0 | K21: 100 | L21: =+K21*N21 -> 19900 | M21: =+G21+I21+K21 -> 15100 | N21: 199 | O21: =+M21*N21 -> 3004900
A22: 13 | B22: 2.5.2-2476.36 | C22: PROD. MEDICO/FARMACEUTICOS/LAB | D22: 252 | E22: ANTIALERGICOS-ANTIHISTAMINICOS; TIPO: MONODROGA, DROGA GENERICA: DIFENHIDRAMINA, FORMA FARMACEUTICA: COMPRIMIDO, PRESENTACION: 50 mGr | F22: COMPRIMIDO | G22: 50000 | H22: =+G22*N22 -> 232500 | J22: =+I22*N22 -> 0 | L22: =+K22*N22 -> 0 | M22: =+G22+I22+K22 -> 50000 | N22: 4.65 | O22: =+M22*N22 -> 232500
A23: 14 | B23: 2.5.2-2476.44 | C23: PROD. MEDICO/FARMACEUTICOS/LAB | D23: 252 | E23: ANTIALERGICOS-ANTIHISTAMINICOS; TIPO: MONODROGA, DROGA GENERICA: DIFENHIDRAMINA, FORMA FARMACEUTICA: AMPOLLA, PRESENTACION: 10 mGr | F23: AMPOLLA | G23: 50000 | H23: =+G23*N23 -> 2750000 | J23: =+I23*N23 -> 0 | K23: 300 | L23: =+K23*N23 -> 16500 | M23: =+G23+I23+K23 -> 50300 | N23: 55 | O23: =+M23*N23 -> 2766500
A24: 15 | B24: 2.5.2-1853.4 | C24: PROD. MEDICO/FARMACEUTICOS/LAB | D24: 252 | E24: OCITOCICOS; TIPO: MONODROGA, DROGA GENERICA: ERGONOVINA, PRESENTACION: 0.2 mGr, FORMA FARMACEUTICA: AMPOLLAS | F24: AMPOLLA | G24: 2000 | H24: =+G24*N24 -> 82000 | J24: =+I24*N24 -> 0 | L24: =+K24*N24 -> 0 | M24: =+G24+I24+K24 -> 2000 | N24: 41 | O24: =+M24*N24 -> 82000
A25: 16 | B25: 2.5.2-1855.18 | C25: PROD. MEDICO/FARMACEUTICOS/LAB | D25: 252 | E25: CORTICOESTEROIDES; TIPO: MONODROGA, DROGA GENERICA: BETAMETASONA, FORMA FARMACEUTICA: GOTAS, PRESENTACION: 15 mL | F25: UNIDAD | H25: =+G25*N25 -> 0 | J25: =+I25*N25 -> 0 | K25: 60 | L25: =+K25*N25 -> 20400 | M25: =+G25+I25+K25 -> 60 | N25: 340 | O25: =+M25*N25 -> 20400
A26: 17 | B26: 2.5.2-1855.47 | C26: PROD. MEDICO/FARMACEUTICOS/LAB | D26: 252 | E26: CORTICOESTEROIDES; TIPO: MONODROGA, DROGA GENERICA: HIDROCORTISONA, FORMA FARMACEUTICA: AMPOLLA/FRASCO, PRESENTACION: 100 mGr | F26: AMPOLLA | G26: 6000 | H26: =+G26*N26 -> 720000 | J26: =+I26*N26 -> 0 | K26: 500 | L26: =+K26*N26 -> 60000 | M26: =+G26+I26+K26 -> 6500 | N26: 120 | O26: =+M26*N26 -> 780000
A27: 18 | B27: 2.5.2-1855.77 | C27: PROD. MEDICO/FARMACEUTICOS/LAB | D27: 252 | E27: CORTICOESTEROIDES; TIPO: MONODROGA, DROGA GENERICA: HIDROCORTISONA, FORMA FARMACEUTICA: FRASCO AMPOLLA, PRESENTACION: ENVASE X 500 mGr | F27: AMPOLLA | G27: 10000 | H27: =+G27*N27 -> 2220000 | J27: =+I27*N27 -> 0 | K27: 500 | L27: =+K27*N27 -> 111000 | M27: =+G27+I27+K27 -> 10500 | N27: 222 | O27: =+M27*N27 -> 2331000
A28: 19 | B28: 2.5.2-1875.9 | C28: PROD. MEDICO/FARMACEUTICOS/LAB | D28: 252 | E28: ANTIASMATICO BRONCODILATADOR; TIPO: MONODROGA, DROGA GENERICA: BROMURO DE IPRATROPIO, FORMA FARMACEUTICA: SOLUCION, PRESENTACION: 20 mL | F28: GOTERO | G28: 2000 | H28: =+G28*N28 -> 196000 | J28: =+I28*N28 -> 0 | L28: =+K28*N28 -> 0 | M28: =+G28+I28+K28 -> 2000 | N28: 98 | O28: =+M28*N28 -> 196000
A29: 20 | B29: 2.5.2-1902.10 | C29: PROD. MEDICO/FARMACEUTICOS/LAB | D29: 252 | E29: DROGAS UTERINAS; TIPO: MONODROGA, DROGA GENERICA: ISOXUPRINA 10 mGr, FORMA FARMACEUTICA: AMPOLLA, PRESENTACION: UNIDAD | F29: AMPOLLA | G29: 2000 | H29: =+G29*N29 -> 90000 | J29: =+I29*N29 -> 0 | L29: =+K29*N29 -> 0 | M29: =+G29+I29+K29 -> 2000 | N29: 45 | O29: =+M29*N29 -> 90000
A30: 21 | B30: 2.5.2-1823.24 | C30: PROD. MEDICO/FARMACEUTICOS/LAB | D30: 252 | E30: ANTIMICOTICOS; TIPO: MONODROGA, FORMA FARMACEUTICA: CREMA, PRESENTACION: 15 GR, DROGA GENERICA: KETOCONAZOL | F30: UNIDAD | G30: 1000 | H30: =+G30*N30 -> 250000 | J30: =+I30*N30 -> 0 | L30: =+K30*N30 -> 0 | M30: =+G30+I30+K30 -> 1000 | N30: 250 | O30: =+M30*N30 -> 250000
A31: 22 | B31: 2.5.2-2476.12 | C31: PROD. MEDICO/FARMACEUTICOS/LAB | D31: 252 | E31: ANTIALERGICOS-ANTIHISTAMINICOS; TIPO: MONODROGA, DROGA GENERICA: LORATADINA, FORMA FARMACEUTICA: COMPRIMIDO, PRESENTACION: 10 mGr | F31: COMPRIMIDO | G31: 60000 | H31: =+G31*N31 -> 206400 | J31: =+I31*N31 -> 0 | L31: =+K31*N31 -> 0 | M31: =+G31+I31+K31 -> 60000 | N31: 3.44 | O31: =+M31*N31 -> 206400
A32: 23 | B32: 2.5.2-2476.3 | C32: PROD. MEDICO/FARMACEUTICOS/LAB | D32: 252 | E32: ANTIALERGICOS-ANTIHISTAMINICOS; TIPO: ASOCIACION, DROGA GENERICA: LORATADINA, FORMA FARMACEUTICA: JARABE, PRESENTACION: 60 mL | F32: FRASCO | G32: 6000 | H32: =+G32*N32 -> 1080000 | J32: =+I32*N32 -> 0 | L32: =+K32*N32 -> 0 | M32: =+G32+I32+K32 -> 6000 | N32: 180 | O32: =+M32*N32 -> 1080000
A33: 24 | B33: 2.5.2-2200.4 | C33: PROD. MEDICO/FARMACEUTICOS/LAB | D33: 252 | E33: CORTICOIDES; DROGA GENERICA: MEPREDNISONA, FORMA FARMACEUTICA: COMPRIMIDO, PRESENTACION: 4 mGr, TIPO: MONODROGA | F33: COMPRIMIDO | G33: 1000 | H33: =+G33*N33 -> 9800 | J33: =+I33*N33 -> 0 | L33: =+K33*N33 -> 0 | M33: =+G33+I33+K33 -> 1000 | N33: 9.8 | O33: =+M33*N33 -> 9800
A34: 25 | B34: 2.5.2-2200.41 | C34: PROD. MEDICO/FARMACEUTICOS/LAB | D34: 252 | E34: CORTICOIDES; DROGA GENÉRICA: MEPREDNISONA 4 ML/MG, FORMA FARMACEÚTICA: GOTAS | F34: GOTERO | G34: 6000 | H34: =+G34*N34 -> 1890000 | J34: =+I34*N34 -> 0 | L34: =+K34*N34 -> 0 | M34: =+G34+I34+K34 -> 6000 | N34: 315 | O34: =+M34*N34 -> 1890000
A35: 26 | B35: 2.5.2-2200.19 | C35: PROD. MEDICO/FARMACEUTICOS/LAB | D35: 252 | E35: CORTICOIDES; DROGA GENERICA: MEPREDNISONA, FORMA FARMACEUTICA: COMPRIMIDO, PRESENTACION: 40 mGr, TIPO: MONODROGA | F35: COMPRIMIDO | G35: 2000 | H35: =+G35*N35 -> 110000 | J35: =+I35*N35 -> 0 | L35: =+K35*N35 -> 0 | M35: =+G35+I35+K35 -> 2000 | N35: 55 | O35: =+M35*N35 -> 110000
A36: 27 | B36: 2.5.2-1855.105 | C36: PROD. MEDICO/FARMACEUTICOS/LAB | D36: 252 | E36: CORTICOESTEROIDES; TIPO: MONODROGA, DROGA GENERICA: MEPREDNISONA 8 mGr, FORMA FARMACEUTICA: COMPRIMIDO, PRESENTACION: UNIDAD | F36: COMPRIMIDO | G36: 1000 | H36: =+G36*N36 -> 17350 | J36: =+I36*N36 -> 0 | L36: =+K36*N36 -> 0 | M36: =+G36+I36+K36 -> 1000 | N36: 17.35 | O36: =+M36*N36 -> 17350
A37: 28 | B37: 2.5.2-1821.487 | C37: PROD. MEDICO/FARMACEUTICOS/LAB | D37: 252 | E37: ANTIBIOTICOS P/PERSONAS; TIPO: MONODROGA, DROGA GENERICA: METRONIDAZOL, FORMA FARMACEUTICA: OVULO, PRESENTACION: UNIDAD | F37: UNIDAD | G37: 3000 | H37: =+G37*N37 -> 141720 | J37: =+I37*N37 -> 0 | L37: =+K37*N37 -> 0 | M37: =+G37+I37+K37 -> 3000 | N37: 47.24 | O37: =+M37*N37 -> 141720
A38: 29 | B38: 2.5.2-1851.29 | C38: PROD. MEDICO/FARMACEUTICOS/LAB | D38: 252 | E38: GENITOURINARIO; TIPO: MONODROGA, DROGA GENÉRICA: NISTATINA, FORMA FARMACEÚTICA: COMPRIMIDO VAGINAL, PRESENTACIÓN: 100000 UI | F38: COMPRIMIDO | G38: 1000 | H38: =+G38*N38 -> 33500 | J38: =+I38*N38 -> 0 | L38: =+K38*N38 -> 0 | M38: =+G38+I38+K38 -> 1000 | N38: 33.5 | O38: =+M38*N38 -> 33500
A39: 30 | B39: 2.5.2-1723.122 | C39: PROD. MEDICO/FARMACEUTICOS/LAB | D39: 252 | E39: ANTISEPTICOS LOCALES P/PERSONA; TIPO: MONODROGA, DROGA GENERICA: NITROFURAZONA, FORMA FARMACEUTICA: APOSITO, PRESENTACION: ENVASE X 20 UN | F39: CAJA | G39: 500 | H39: =+G39*N39 -> 415000 | J39: =+I39*N39 -> 0 | L39: =+K39*N39 -> 0 | M39: =+G39+I39+K39 -> 500 | N39: 830 | O39: =+M39*N39 -> 415000
A40: 31 | B40: 2.5.2-1853.2 | C40: PROD. MEDICO/FARMACEUTICOS/LAB | D40: 252 | E40: OCITOCICOS; TIPO: MONODROGA, DROGA GENERICA: OXITOCINA SINTÉTICA, PRESENTACION: 10 UI, FORMA FARMACEUTICA: AMPOLLA | F40: AMPOLLA | G40: 6000 | H40: =+G40*N40 -> 216000 | J40: =+I40*N40 -> 0 | L40: =+K40*N40 -> 0 | M40: =+G40+I40+K40 -> 6000 | N40: 36 | O40: =+M40*N40 -> 216000
A41: 32 | B41: 2.5.2-1875.55 | C41: PROD. MEDICO/FARMACEUTICOS/LAB | D41: 252 | E41: ANTIASMATICO BRONCODILATADOR; TIPO: MONODROGA, DROGA GENERICA: SALBUTAMOL, FORMA FARMACEUTICA: AEROSOL, PRESENTACION: 250 DOSIS | F41: UNIDAD | G41: 4000 | H41: =+G41*N41 -> 6320000 | I41: 3000 | J41: =+I41*N41 -> 4740000 | K41: 100 | L41: =+K41*N41 -> 158000 | M41: =+G41+I41+K41 -> 7100 | N41: 1580 | O41: =+M41*N41 -> 11218000
A42: 33 | B42: 2.5.2-1875.11 | C42: PROD. MEDICO/FARMACEUTICOS/LAB | D42: 252 | E42: ANTIASMATICO BRONCODILATADOR; TIPO: MONODROGA, PRESENTACION: 20 mL, FORMA FARMACEUTICA: GOTAS, DROGA GENERICA: SALBUTAMOL | F42: GOTERO | G42: 1000 | H42: =+G42*N42 -> 95000 | J42: =+I42*N42 -> 0 | L42: =+K42*N42 -> 0 | M42: =+G42+I42+K42 -> 1000 | N42: 95 | O42: =+M42*N42 -> 95000
A43: 34 | B43: 2.5.2-1883.189 | C43: PROD. MEDICO/FARMACEUTICOS/LAB | D43: 252 | E43: ANESTÉSICOS LOCALES; TIPO: ANALGÉSICO LOCAL Y ANTIBACTERIANO, DROGA GENÉRICA: LIDOCAÍNA + SULFADIAZINA + VITAMINA A, FORMA FARMACEÚTICA: CREMA, PRESENTACIÓN: ENVASE X 100 GR | F43: UNIDAD | G43: 1000 | H43: =+G43*N43 -> 1120000 | J43: =+I43*N43 -> 0 | K43: 30 | L43: =+K43*N43 -> 33600 | M43: =+G43+I43+K43 -> 1030 | N43: 1120 | O43: =+M43*N43 -> 1153600
...

Sheet NP DPFeI
A1: NOTA DE PEDIDO | J1: N° | K1: xxx/2022
A3: JURISDICCIÓN: | C3: ='Necesidades Trimestrales'!C4 -> 040 - Ministerio de Salud
A4: SAF: | C4: ='Necesidades Trimestrales'!C5 -> 011 - Direccion Provincial de Administracion - MS
A5: UNIDAD EJECUTORA: | C5: 469 - Direccion Provincial de Farmacia e Insumos
A6: DEPENDENCIA SOLICITANTE: | C6: 469 - Direccion Provincial de Farmacia e Insumos
A7: PERIODO UTILIZACIÓN: | C7: Cuatrimestral
A8: OBJETO: | C8: Adquisición de TERAPIA DERMATOLOGICA/SISTEMA GENITOURINARIO Y HORMONAS SEXUALES /HORMONAS SISTEMICAS /CORTICOIDES SISTEMICOS/RESPIRATORIO/ANTIHISTAMINICOS
A10: Ítem | B10: CODIGO ITEM | C10: DESCRIPCIÓN | H10: Adjunta Detalle Técnico | I10: Unidad Medida | J10: Precio Unitario Estimado | K10: Cantidad Solicitada
A12: 1 | B12: =+'Necesidades Trimestrales'!B10 -> 2.5.2-1875.133 | C12: =+'Necesidades Trimestrales'!E10 -> ANTIASMATICO BRONCODILATADOR; TIPO: MONODROGA, DROGA GENERICA: N-ACETIL CISTEINA 600 MGR, FORMA FARMACEUTICA: TABLETA EFERVESCENTE, PRESENTACION: UNIDAD | H12: NO | I12: =+'Necesidades Trimestrales'!F10 -> UNIDAD | J12: =+'Necesidades Trimestrales'!N10 -> 35.24 | K12: =+'Necesidades Trimestrales'!G10 -> 500
A13: 2 | B13: =+'Necesidades Trimestrales'!B11 -> 2.5.2-1829.25 | C13: =+'Necesidades Trimestrales'!E11 -> ANTIVIRALES; TIPO: MONODROGA, DROGA GENERICA: ACICLOVIR 5 %, FORMA FARMACEUTICA: CREMA, PRESENTACION: ENVASE X 5 GR | H13: NO | I13: =+'Necesidades Trimestrales'!F11 -> UNIDAD | J13: =+'Necesidades Trimestrales'!N11 -> 285 | K13: =+'Necesidades Trimestrales'!G11 -> 100
A14: 3 | B14: =+'Necesidades Trimestrales'!B12 -> 2.5.2-1875.74 | C14: =+'Necesidades Trimestrales'!E12 -> ANTIASMATICO BRONCODILATADOR; TIPO: MONODROGA, DROGA GENERICA: AMINOFILINA 240MGR, FORMA FARMACEUTICA: AMPOLLA, PRESENTACION: ENVASE X 10 ML | H14: NO | I14: =+'Necesidades Trimestrales'!F12 -> AMPOLLA | J14: =+'Necesidades Trimestrales'!N12 -> 86 | K14: =+'Necesidades Trimestrales'!G12 -> 1000
A15: 4 | B15: =+'Necesidades Trimestrales'!B13 -> 2.9.5-427.33 | C15: =+'Necesidades Trimestrales'!E13 -> APOSITOS; TIPO: HIDROCOLOIDE, TAMAÑO: 15 X 17,5 Cm | H15: NO | I15: =+'Necesidades Trimestrales'!F13 -> UNIDAD | J15: =+'Necesidades Trimestrales'!N13 -> 1120 | K15: =+'Necesidades Trimestrales'!G13 -> 50
A16: 5 | B16: =+'Necesidades Trimestrales'!B14 -> 2.9.5-427.39 | C16: =+'Necesidades Trimestrales'!E14 -> APOSITOS; TIPO: HIDROCOLOIDE, TAMAÑO: 10 X 10 Cm | H16: NO | I16: =+'Necesidades Trimestrales'!F14 -> UNIDAD | J16: =+'Necesidades Trimestrales'!N14 -> 580 | K16: =+'Necesidades Trimestrales'!G14 -> 100
A17: 6 | B17: =+'Necesidades Trimestrales'!B15 -> 2.5.2-1855.23 | C17: =+'Necesidades Trimestrales'!E15 -> CORTICOESTEROIDES; TIPO: MONODROGA, DROGA GENERICA: BETAMETASONA, FORMA FARMACEUTICA: CREMA, PRESENTACION: 15 GR | H17: NO | I17: =+'Necesidades Trimestrales'!F15 -> UNIDAD | J17: =+'Necesidades Trimestrales'!N15 -> 280 | K17: =+'Necesidades Trimestrales'!G15 -> 1000
A18: 7 | B18: =+'Necesidades Trimestrales'!B16 -> 2.5.2-1855.83 | C18: =+'Necesidades Trimestrales'!E16 -> CORTICOESTEROIDES; TIPO: ASOCIACION, DROGA GENERICA: BETAMETASONA ACETATO+FOSFATO, FORMA FARMACEUTICA: AMPOLLA, PRESENTACION: ENVASE X 2 mL | H18: NO | I18: =+'Necesidades Trimestrales'!F16 -> AMPOLLA | J18: =+'Necesidades Trimestrales'!N16 -> 295 | K18: =+'Necesidades Trimestrales'!G16 -> 10000
A19: 8 | B19: =+'Necesidades Trimestrales'!B17 -> 2.5.2-1875.134 | C19: =+'Necesidades Trimestrales'!E17 -> ANTIASMATICO BRONCODILATADOR; TIPO: MONODROGA, DROGA GENERICA: BUDESONIDE 200 µGR, FORMA FARMACEUTICA: AEROSOL, PRESENTACION: 100 DOSIS | H19: NO | I19: =+'Necesidades Trimestrales'!F17 -> UNIDAD | J19: =+'Necesidades Trimestrales'!N17 -> 750 | K19: =+'Necesidades Trimestrales'!G17 -> 2000
A20: 9 | B20: =+'Necesidades Trimestrales'!B18 -> 2.5.2-2476.50 | C20: =+'Necesidades Trimestrales'!E18 -> ANTIALERGICOS-ANTIHISTAMINICOS; TIPO: MONODROGA, DROGA GENERICA: BUDESONIDA 1 MG/ML, FORMA FARMACEUTICA: GOTAS, PRESENTACION: ENVASE X 20 mL | H20: NO | I20: =+'Necesidades Trimestrales'!F18 -> UNIDAD | J20: =+'Necesidades Trimestrales'!N18 -> 327 | K20: =+'Necesidades Trimestrales'!G18 -> 300
A21: 10 | B21: =+'Necesidades Trimestrales'!B19 -> 2.5.2-1823.67 | C21: =+'Necesidades Trimestrales'!E19 -> ANTIMICOTICOS; TIPO: MONODROGA, DROGA GENERICA: CLOTRIMAZOL 1%, FORMA FARMACEUTICA: CREMA POR 20 GR, PRESENTACION: UNIDAD | H21: NO | I21: =+'Necesidades Trimestrales'!F19 -> UNIDAD | J21: =+'Necesidades Trimestrales'!N19 -> 280 | K21: =+'Necesidades Trimestrales'!G19 -> 1000
A22: 11 | B22: =+'Necesidades Trimestrales'!B20 -> 2.5.2-1855.7 | C22: =+'Necesidades Trimestrales'!E20 -> CORTICOESTEROIDES; TIPO: MONODROGA, DROGA GENERICA: DEXAMETASONA, FORMA FARMACEUTICA: AMPOLLA, PRESENTACION: 8 mGr | H22: NO | I22: =+'Necesidades Trimestrales'!F20 -> AMPOLLA | J22: =+'Necesidades Trimestrales'!N20 -> 45 | K22: =+'Necesidades Trimestrales'!G20 -> 120000
A23: 12 | B23: =+'Necesidades Trimestrales'!B21 -> 2.5.2-2476.74 | C23: =+'Necesidades Trimestrales'!E21 -> ANTIALERGICOS-ANTIHISTAMINICOS; TIPO: MONODROGA, DROGA GENERICA: DIFENHIDRAMINA 250 MG, FORMA FARMACEUTICA: JARABE, PRESENTACION: FRASCO X 120 mL | H23: NO | I23: =+'Necesidades Trimestrales'!F21 -> FRASCO | J23: =+'Necesidades Trimestrales'!N21 -> 199 | K23: =+'Necesidades Trimestrales'!G21 -> 15000
... A26: 15 | B26: =+'Necesidades Trimestrales'!B24 -> 2.5.2-1853.4 | C26: =+'Necesidades Trimestrales'!E24 -> OCITOCICOS; TIPO: MONODROGA, DROGA GENERICA: ERGONOVINA, PRESENTACION: 0.2 mGr, FORMA FARMACEUTICA: AMPOLLAS | H26: NO | I26: =+'Necesidades Trimestrales'!F24 -> AMPOLLA | J26: =+'Necesidades Trimestrales'!N24 -> 41 | K26: =+'Necesidades Trimestrales'!G24 -> 2000
A27: 16 | B27: =+'Necesidades Trimestrales'!B26 -> 2.5.2-1855.47 | C27: =+'Necesidades Trimestrales'!E26 -> CORTICOESTEROIDES; TIPO: MONODROGA, DROGA GENERICA: HIDROCORTISONA, FORMA FARMACEUTICA: AMPOLLA/FRASCO, PRESENTACION: 100 mGr | H27: NO | I27: =+'Necesidades Trimestrales'!F26 -> AMPOLLA | J27: =+'Necesidades Trimestrales'!N26 -> 120 | K27: =+'Necesidades Trimestrales'!G26 -> 6000
A28: 17 | B28: =+'Necesidades Trimestrales'!B27 -> 2.5.2-1855.77 | C28: =+'Necesidades Trimestrales'!E27 -> CORTICOESTEROIDES; TIPO: MONODROGA, DROGA GENERICA: HIDROCORTISONA, FORMA FARMACEUTICA: FRASCO AMPOLLA, PRESENTACION: ENVASE X 500 mGr | H28: NO | I28: =+'Necesidades Trimestrales'!F27 -> AMPOLLA | J28: =+'Necesidades Trimestrales'!N27 -> 222 | K28: =+'Necesidades Trimestrales'!G27 -> 10000
A29: 18 | B29: =+'Necesidades Trimestrales'!B28 -> 2.5.2-1875.9 | C29: =+'Necesidades Trimestrales'!E28 -> ANTIASMATICO BRONCODILATADOR; TIPO: MONODROGA, DROGA GENERICA: BROMURO DE IPRATROPIO, FORMA FARMACEUTICA: SOLUCION, PRESENTACION: 20 mL | H29: NO | I29: =+'Necesidades Trimestrales'!F28 -> GOTERO | J29: =+'Necesidades Trimestrales'!N28 -> 98 | K29: =+'Necesidades Trimestrales'!G28 -> 2000
A30: 19 | B30: =+'Necesidades Trimestrales'!B29 -> 2.5.2-1902.10 | C30: =+'Necesidades Trimestrales'!E29 -> DROGAS UTERINAS; TIPO: MONODROGA, DROGA GENERICA: ISOXUPRINA 10 mGr, FORMA FARMACEUTICA: AMPOLLA, PRESENTACION: UNIDAD | H30: NO | I30: =+'Necesidades Trimestrales'!F29 -> AMPOLLA | J30: =+'Necesidades Trimestrales'!N29 -> 45 | K30: =+'Necesidades Trimestrales'!G29 -> 2000
A31: 20 | B31: =+'Necesidades Trimestrales'!B30 -> 2.5.2-1823.24 | C31: =+'Necesidades Trimestrales'!E30 -> ANTIMICOTICOS; TIPO: MONODROGA, FORMA FARMACEUTICA: CREMA, PRESENTACION: 15 GR, DROGA GENERICA: KETOCONAZOL | H31: NO | I31: =+'Necesidades Trimestrales'!F30 -> UNIDAD | J31: =+'Necesidades Trimestrales'!N30 -> 250 | K31: =+'Necesidades Trimestrales'!G30 -> 1000
A32: 21 | B32: =+'Necesidades Trimestrales'!B31 -> 2.5.2-2476.12 | C32: =+'Necesidades Trimestrales'!E31 -> ANTIALERGICOS-ANTIHISTAMINICOS; TIPO: MONODROGA, DROGA GENERICA: LORATADINA, FORMA FARMACEUTICA: COMPRIMIDO, PRESENTACION: 10 mGr | H32: NO | I32: =+'Necesidades Trimestrales'!F31 -> COMPRIMIDO | J32: =+'Necesidades Trimestrales'!N31 -> 3.44 | K32: =+'Necesidades Trimestrales'!G31 -> 60000
A33: 22 | B33: =+'Necesidades Trimestrales'!B32 -> 2.5.2-2476.3 | C33: =+'Necesidades Trimestrales'!E32 -> ANTIALERGICOS-ANTIHISTAMINICOS; TIPO: ASOCIACION, DROGA GENERICA: LORATADINA, FORMA FARMACEUTICA: JARABE, PRESENTACION: 60 mL | H33: NO | I33: =+'Necesidades Trimestrales'!F32 -> FRASCO | J33: =+'Necesidades Trimestrales'!N32 -> 180 | K33: =+'Necesidades Trimestrales'!G32 -> 6000
A34: 23 | B34: =+'Necesidades Trimestrales'!B33 -> 2.5.2-2200.4 | C34: =+'Necesidades Trimestrales'!E33 -> CORTICOIDES; DROGA GENERICA: MEPREDNISONA, FORMA FARMACEUTICA: COMPRIMIDO, PRESENTACION: 4 mGr, TIPO: MONODROGA | H34: NO | I34: =+'Necesidades Trimestrales'!F33 -> COMPRIMIDO | J34: =+'Necesidades Trimestrales'!N33 -> 9.8 | K34: =+'Necesidades Trimestrales'!G33 -> 1000
A35: 24 | B35: =+'Necesidades Trimestrales'!B34 -> 2.5.2-2200.41 | C35: =+'Necesidades Trimestrales'!E34 -> CORTICOIDES; DROGA GENÉRICA: MEPREDNISONA 4 ML/MG, FORMA FARMACEÚTICA: GOTAS | H35: SI | I35: =+'Necesidades Trimestrales'!F34 -> GOTERO | J35: =+'Necesidades Trimestrales'!N34 -> 315 | K35: =+'Necesidades Trimestrales'!G34 -> 6000
A36: 25 | B36: =+'Necesidades Trimestrales'!B35 -> 2.5.2-2200.19 | C36: =+'Necesidades Trimestrales'!E35 -> CORTICOIDES; DROGA GENERICA: MEPREDNISONA, FORMA FARMACEUTICA: COMPRIMIDO, PRESENTACION: 40 mGr, TIPO: MONODROGA | H36: NO | I36: =+'Necesidades Trimestrales'!F35 -> COMPRIMIDO | J36: =+'Necesidades Trimestrales'!N35 -> 55 | K36: =+'Necesidades Trimestrales'!G35 -> 2000
A37: 26 | B37: =+'Necesidades Trimestrales'!B36 -> 2.5.2-1855.105 | C37: =+'Necesidades Trimestrales'!E36 -> CORTICOESTEROIDES; TIPO: MONODROGA, DROGA GENERICA: MEPREDNISONA 8 mGr, FORMA FARMACEUTICA: COMPRIMIDO, PRESENTACION: UNIDAD | H37: NO | I37: =+'Necesidades Trimestrales'!F36 -> COMPRIMIDO | J37: =+'Necesidades Trimestrales'!N36 -> 17.35 | K37: =+'Necesidades Trimestrales'!G36 -> 1000
A38: 27 | B38: =+'Necesidades Trimestrales'!B37 -> 2.5.2-1821.487 | C38: =+'Necesidades Trimestrales'!E37 -> ANTIBIOTICOS P/PERSONAS; TIPO: MONODROGA, DROGA GENERICA: METRONIDAZOL, FORMA FARMACEUTICA: OVULO, PRESENTACION: UNIDAD | H38: NO | I38: =+'Necesidades Trimestrales'!F37 -> UNIDAD | J38: =+'Necesidades Trimestrales'!N37 -> 47.24 | K38: =+'Necesidades Trimestrales'!G37 -> 3000
... A45: 34 | B45: =+'Necesidades Trimestrales'!B44 -> 2.5.2-2481.3 | C45: =+'Necesidades Trimestrales'!E44 -> LAXANTES; TIPO: MONODROGA, DROGA GENERICA: VASELINA, FORMA FARMACEUTICA: SOLIDO, PRESENTACION: 1000 GR | H45: NO | I45: =+'Necesidades Trimestrales'!F44 -> UNIDAD | J45: =+'Necesidades Trimestrales'!N44 -> 1260 | K45: =+'Necesidades Trimestrales'!G44 -> 50
A46: Costo total estimado: PESOS TREINTA Y UN MILLONES NOVECIENTOS NOVENTA Y SIETE MIL CUATROCIENTOS NOVENTA con 00/100. | J46: =SUMPRODUCT(J12:J45,K12:K45) -> 31997490

Sheet AGP DPFeI
A1: EJERCICIO: | D1: ='Necesidades Trimestrales'!C6 -> 2022 | P1: AUTORIZACION PARA GASTAR
A4: JURISDICCIÓN: | G4: ='NP DPFeI'!C3 -> 040 - Ministerio de Salud
A5: SAF: | G5: ='NP DPFeI'!C4 -> 011 - Direccion Provincial de Administracion - MS
A6: UNIDAD EJECUTORA: | G6: ='NP DPFeI'!C5 -> 469 - Direccion Provincial de Farmacia e Insumos
A7: DEPENDENCIA SOLICITANTE: | G7: ='NP DPFeI'!C6 -> 469 - Direccion Provincial de Farmacia e Insumos
A8: AUTORIZACIÓN:
A9: Señor Jefe de Servicio Administrativo Financiero:
A10: ="Autorizo la realización de los trámites correspondientes, a fin de proveer a este Organismo los bienes y/o servicios que se detallan en Nota de Pedido N° " & 'NP DPFeI'!K1&", afectando la erogación resultante a los créditos presupuestarios aprobados a favor de esta Unidad Ejecutora, conforme al siguiente detalle:" -> Autorizo la realización de los trámites correspondientes, a fin de proveer a este Organismo los bienes y/o servicios que se detallan en Nota de Pedido N° xxx/2022, afectando la erogación resultante a los créditos presupuestarios aprobados a favor de esta Unidad Ejecutora, conforme al siguiente detalle:
A12: IMPUTACIÓN PRESUPUESTARIA
A13: CÓDIGO | O13: DENOMINACIÓN DE LA PARTIDA PRESUPUESTARIA | Q13: IMPORTE
A14: PR | B14: SB | C14: PY | D14: AC | E14: OB | F14: UG | G14: FIN | H14: FUN | I14: I | J14: P | K14: P | L14: SubP | M14: M | N14: FF
A15: 30 | D15: 1 | F15: 4901 | G15: 3 | H15: 1 | I15: 2 | J15: 5 | K15: 2 | M15: 1 | N15: 1.1 | O15: Productos Farmacéuticos y Medicinales | Q15: =+'NP DPFeI'!J46 -> 31997490
A23: TOTAL DE PESOS: PESOS TREINTA Y UN MILLONES NOVECIENTOS NOVENTA Y SIETE MIL CUATROCIENTOS NOVENTA con 00/100. | Q23: =SUM(Q15:Q22) -> 31997490
A25: JUSTIFICACIÓN:
A26: ='NP DPFeI'!C8 -> Adquisición de TERAPIA DERMATOLOGICA/SISTEMA GENITOURINARIO Y HORMONAS SEXUALES /HORMONAS SISTEMICAS /CORTICOIDES SISTEMICOS/RESPIRATORIO/ANTIHISTAMINICOS

Sheet NP DPMIyA
A1: NOTA DE PEDIDO | J1: N° | K1: xxx/2022
A3: JURISDICCIÓN: | C3: ='Necesidades Trimestrales'!C4 -> 040 - Ministerio de Salud
A4: SAF: | C4: ='Necesidades Trimestrales'!C5 -> 011 - Direccion Provincial de Administracion - MS
A5: UNIDAD EJECUTORA: | C5: 162 - Direccion Provincial Maternidad, Infancia y Adolescencia
A6: DEPENDENCIA SOLICITANTE: | C6: 162 - Direccion Provincial Maternidad, Infancia y Adolescencia
A7: PERIODO UTILIZACIÓN: | C7: Cuatrimestral
A8: OBJETO: | C8: Adquisición de TERAPIA DERMATOLOGICA/SISTEMA GENITOURINARIO Y HORMONAS SEXUALES /HORMONAS SISTEMICAS /CORTICOIDES SISTEMICOS/RESPIRATORIO/ANTIHISTAMINICOS
A10: Ítem | B10: CODIGO ITEM | C10: DESCRIPCIÓN | H10: Adjunta Detalle Técnico | I10: Unidad Medida | J10: Precio Unitario Estimado | K10: Cantidad Solicitada
A12: 1 | B12: =+'Necesidades Trimestrales'!B41 -> 2.5.2-1875.55 | C12: =+'Necesidades Trimestrales'!E41 -> ANTIASMATICO BRONCODILATADOR; TIPO: MONODROGA, DROGA GENERICA: SALBUTAMOL, FORMA FARMACEUTICA: AEROSOL, PRESENTACION: 250 DOSIS | H12: SI | I12: =+'Necesidades Trimestrales'!F41 -> UNIDAD | J12: =+'Necesidades Trimestrales'!N41 -> 1580 | K12: ='Necesidades Trimestrales'!I41 -> 3000
A13: Costo total estimado: PESOS CUATRO MILLONES SETECIENTOS CUARENTA MIL con 00/100. | J13: =SUMPRODUCT(J12:J12,K12:K12) -> 4740000

Sheet AGP DPMIyA
A1: EJERCICIO: | D1: ='Necesidades Trimestrales'!C6 -> 2022 | P1: AUTORIZACION PARA GASTAR
A4: JURISDICCIÓN: | G4: ='NP DPMIyA'!C3 -> 040 - Ministerio de Salud
A5: SAF: | G5: ='NP DPMIyA'!C4 -> 011 - Direccion Provincial de Administracion - MS
A6: UNIDAD EJECUTORA: | G6: ='NP DPMIyA'!C5 -> 162 - Direccion Provincial Maternidad, Infancia y Adolescencia
A7: DEPENDENCIA SOLICITANTE: | G7: ='NP DPMIyA'!C6 -> 162 - Direccion Provincial Maternidad, Infancia y Adolescencia
A8: AUTORIZACIÓN:
A9: Señor Jefe de Servicio Administrativo Financiero:
A10: ="Autorizo la realización de los trámites correspondientes, a fin de proveer a este Organismo los bienes y/o servicios que se detallan en Nota de Pedido N° " & 'NP DPMIyA'!K1&", afectando la erogación resultante a los créditos presupuestarios aprobados a favor de esta Unidad Ejecutora, conforme al siguiente detalle:" -> Autorizo la realización de los trámites correspondientes, a fin de proveer a este Organismo los bienes y/o servicios que se detallan en Nota de Pedido N° xxx/2022, afectando la erogación resultante a los créditos presupuestarios aprobados a favor de esta Unidad Ejecutora, conforme al siguiente detalle:
A12: IMPUTACIÓN PRESUPUESTARIA
A13: CÓDIGO | O13: DENOMINACIÓN DE LA PARTIDA PRESUPUESTARIA | Q13: IMPORTE
A14: PR | B14: SB | C14: PY | D14: AC | E14: OB | F14: UG | G14: FIN | H14: FUN | I14: I | J14: P | K14: P | L14: SubP | M14: M | N14: FF
A15: 20 | D15: 3 | F15: 4901 | G15: 3 | H15: 1 | I15: 2 | J15: 5 | K15: 2 | M15: 1 | N15: 1.1 | O15: Productos Farmacéuticos y Medicinales | Q15: =+'NP DPMIyA'!J13 -> 4740000
A23: TOTAL DE PESOS: CUATRO MILLONES SETECIENTOS CUARENTA MIL con 00/100. | Q23: =SUM(Q15:Q22) -> 4740000
A25: JUSTIFICACIÓN:
A26: ='NP DPMIyA'!C8 -> Adquisición de TERAPIA DERMATOLOGICA/SISTEMA GENITOURINARIO Y HORMONAS SEXUALES /HORMONAS SISTEMICAS /CORTICOIDES SISTEMICOS/RESPIRATORIO/ANTIHISTAMINICOS

Sheet NP DPSAME
A1: NOTA DE PEDIDO | J1: N° | K1: xxx/2022
A3: JURISDICCIÓN: | C3: ='Necesidades Trimestrales'!C4 -> 040 - Ministerio de Salud
A4: SAF: | C4: ='Necesidades Trimestrales'!C5 -> 011 - Direccion Provincial de Administracion - MS
A5: UNIDAD EJECUTORA: | C5: 748 - Direccion Provincial Sistema de Atencion Medica de Emergencia
A6: DEPENDENCIA SOLICITANTE: | C6: 748 - Direccion Provincial Sistema de Atencion Medica de Emergencia
A7: PERIODO UTILIZACIÓN: | C7: Cuatrimestral
A8: OBJETO: | C8: Adquisición de TERAPIA DERMATOLOGICA/SISTEMA GENITOURINARIO Y HORMONAS SEXUALES /HORMONAS SISTEMICAS /CORTICOIDES SISTEMICOS/RESPIRATORIO/ANTIHISTAMINICOS
A10: Ítem | B10: CODIGO ITEM | C10: DESCRIPCIÓN | H10: Adjunta Detalle Técnico | I10: Unidad Medida | J10: Precio Unitario Estimado | K10: Cantidad Solicitada
A12: 1 | B12: =+'Necesidades Trimestrales'!B20 -> 2.5.2-1855.7 | C12: =+'Necesidades Trimestrales'!E20 -> CORTICOESTEROIDES; TIPO: MONODROGA, DROGA GENERICA: DEXAMETASONA, FORMA FARMACEUTICA: AMPOLLA, PRESENTACION: 8 mGr | H12: NO | I12: =+'Necesidades Trimestrales'!F20 -> AMPOLLA | J12: =+'Necesidades Trimestrales'!N20 -> 45 | K12: ='Necesidades Trimestrales'!K20 -> 700
A13: 2 | B13: =+'Necesidades Trimestrales'!B21 -> 2.5.2-2476.74 | C13: =+'Necesidades Trimestrales'!E21 -> ANTIALERGICOS-ANTIHISTAMINICOS; TIPO: MONODROGA, DROGA GENERICA: DIFENHIDRAMINA 250 MG, FORMA FARMACEUTICA: JARABE, PRESENTACION: FRASCO X 120 mL | H13: NO | I13: =+'Necesidades Trimestrales'!F21 -> FRASCO | J13: =+'Necesidades Trimestrales'!N21 -> 199 | K13: ='Necesidades Trimestrales'!K21 -> 100
A14: 3 | B14: =+'Necesidades Trimestrales'!B23 -> 2.5.2-2476.44 | C14: =+'Necesidades Trimestrales'!E23 -> ANTIALERGICOS-ANTIHISTAMINICOS; TIPO: MONODROGA, DROGA GENERICA: DIFENHIDRAMINA, FORMA FARMACEUTICA: AMPOLLA, PRESENTACION: 10 mGr | H14: NO | I14: =+'Necesidades Trimestrales'!F23 -> AMPOLLA | J14: =+'Necesidades Trimestrales'!N23 -> 55 | K14: ='Necesidades Trimestrales'!K23 -> 300
A15: 4 | B15: =+'Necesidades Trimestrales'!B25 -> 2.5.2-1855.18 | C15: =+'Necesidades Trimestrales'!E25 -> CORTICOESTEROIDES; TIPO: MONODROGA, DROGA GENERICA: BETAMETASONA, FORMA FARMACEUTICA: GOTAS, PRESENTACION: 15 mL | H15: SI | I15: =+'Necesidades Trimestrales'!F25 -> UNIDAD | J15: =+'Necesidades Trimestrales'!N25 -> 340 | K15: ='Necesidades Trimestrales'!K25 -> 60
A16: 5 | B16: =+'Necesidades Trimestrales'!B26 -> 2.5.2-1855.47 | C16: =+'Necesidades Trimestrales'!E26 -> CORTICOESTEROIDES; TIPO: MONODROGA, DROGA GENERICA: HIDROCORTISONA, FORMA FARMACEUTICA: AMPOLLA/FRASCO, PRESENTACION: 100 mGr | H16: NO | I16: =+'Necesidades Trimestrales'!F26 -> AMPOLLA | J16: =+'Necesidades Trimestrales'!N26 -> 120 | K16: ='Necesidades Trimestrales'!K26 -> 500
A17: 6 | B17: =+'Necesidades Trimestrales'!B27 -> 2.5.2-1855.77 | C17: =+'Necesidades Trimestrales'!E27 -> CORTICOESTEROIDES; TIPO: MONODROGA, DROGA GENERICA: HIDROCORTISONA, FORMA FARMACEUTICA: FRASCO AMPOLLA, PRESENTACION: ENVASE X 500 mGr | H17: NO | I17: =+'Necesidades Trimestrales'!F27 -> AMPOLLA | J17: =+'Necesidades Trimestrales'!N27 -> 222 | K17: ='Necesidades Trimestrales'!K27 -> 500
A18: 7 | B18: =+'Necesidades Trimestrales'!B41 -> 2.5.2-1875.55 | C18: =+'Necesidades Trimestrales'!E41 -> ANTIASMATICO BRONCODILATADOR; TIPO: MONODROGA, DROGA GENERICA: SALBUTAMOL, FORMA FARMACEUTICA: AEROSOL, PRESENTACION: 250 DOSIS | H18: SI | I18: =+'Necesidades Trimestrales'!F41 -> UNIDAD | J18: =+'Necesidades Trimestrales'!N41 -> 1580 | K18: ='Necesidades Trimestrales'!K41 -> 100
A19: 8 | B19: =+'Necesidades Trimestrales'!B43 -> 2.5.2-1883.189 | C19: =+'Necesidades Trimestrales'!E43 -> ANESTÉSICOS LOCALES; TIPO: ANALGÉSICO LOCAL Y ANTIBACTERIANO, DROGA GENÉRICA: LIDOCAÍNA + SULFADIAZINA + VITAMINA A, FORMA FARMACEÚTICA: CREMA, PRESENTACIÓN: ENVASE X 100 GR | H19: NO | I19: =+'Necesidades Trimestrales'!F43 -> UNIDAD | J19: =+'Necesidades Trimestrales'!N43 -> 1120 | K19: ='Necesidades Trimestrales'!K43 -> 30
A20: Costo total estimado: PESOS CUATROCIENTOS CINCUENTA MIL NOVECIENTOS con 00/100. | J20: =SUMPRODUCT(J12:J19,K12:K19) -> 450900

Sheet AGP DPSAME
A1: EJERCICIO: | D1: ='Necesidades Trimestrales'!C6 -> 2022 | P1: AUTORIZACION PARA GASTAR
A4: JURISDICCIÓN: | G4: ='NP DPSAME'!C3 -> 040 - Ministerio de Salud
A5: SAF: | G5: ='NP DPSAME'!C4 -> 011 - Direccion Provincial de Administracion - MS
A6: UNIDAD EJECUTORA: | G6: ='NP DPSAME'!C5 -> 748 - Direccion Provincial Sistema de Atencion Medica de Emergencia
A7: DEPENDENCIA SOLICITANTE: | G7: ='NP DPSAME'!C6 -> 748 - Direccion Provincial Sistema de Atencion Medica de Emergencia
A8: AUTORIZACIÓN:
A9: Señor Jefe de Servicio Administrativo Financiero:
A10: ="Autorizo la realización de los trámites correspondientes, a fin de proveer a este Organismo los bienes y/o servicios que se detallan en Nota de Pedido N° " & 'NP DPSAME'!K1&", afectando la erogación resultante a los créditos presupuestarios aprobados a favor de esta Unidad Ejecutora, conforme al siguiente detalle:" -> Autorizo la realización de los trámites correspondientes, a fin de proveer a este Organismo los bienes y/o servicios que se detallan en Nota de Pedido N° xxx/2022, afectando la erogación resultante a los créditos presupuestarios aprobados a favor de esta Unidad Ejecutora, conforme al siguiente detalle:
A12: IMPUTACIÓN PRESUPUESTARIA
A13: CÓDIGO | O13: DENOMINACIÓN DE LA PARTIDA PRESUPUESTARIA | Q13: IMPORTE
A14: PR | B14: SB | C14: PY | D14: AC | E14: OB | F14: UG | G14: FIN | H14: FUN | I14: I | J14: P | K14: P | L14: SubP | M14: M | N14: FF
A15: 31 | D15: 1 | F15: 4901 | G15: 3 | H15: 1 | I15: 2 | J15: 5 | K15: 2 | M15: 1 | N15: 1.1 | O15: Productos Farmacéuticos y Medicinales | Q15: =+'NP DPSAME'!J20 -> 450900
A23: TOTAL DE PESOS: QUINIENTOS SIETE MIL NOVECIENTOS con 00/100. | Q23: =SUM(Q15:Q22) -> 450900
A25: JUSTIFICACIÓN:
A26: ='NP DPSAME'!C8 -> Adquisición de TERAPIA DERMATOLOGICA/SISTEMA GENITOURINARIO Y HORMONAS SEXUALES /HORMONAS SISTEMICAS /CORTICOIDES SISTEMICOS/RESPIRATORIO/ANTIHISTAMINICOS
