Workbook

Sheet Necesidades Trimestrales
B2: Pedido de Necesidades Trimestrales
A4: JURISDICCION: | C4: 70 - MINISTERIO DE CIENCIA E INNOVACION TECNOLOGICA
A5: SAF N°: | C5: 20 - MINISTERIO DE CIENCIA E INNOVACION TECNOLOGICA
A6: EJERCICIO: | C6: 2021
A7: TRIMESTRE: | C7: 2
A9: ID | B9: CODIGO ITEM | C9: RUBRO DE COMPRA | D9: I.P.P. | E9: DESCRIPCION | F9: UNIDAD DE MEDIDA | G9: CANTIDAD | H9: PRECIO UNITARIO ESTIMADO | I9: IMPORTE TOTAL ESTIMADO
A10: 1 | B10: 4.3.6-6160.208 | C10: INFORMATICA | D10: =LEFT(B10,5) -> 4.3.6 | E10: COMPUTADORAS; TIPO: NOTEBOOK, CODIGO ETAP: PC-008, VERSION ETAP: 22.0 | F10: UNIDAD | G10: 20 | H10: 95000 | I10: =G10*H10 -> 1900000
A11: 2 | B11: 4.3.6-9604.3 | C11: INFORMATICA | D11: =LEFT(B11,5) -> 4.3.6 | E11: TABLETA PC; RESOLUCION: 1280 X 800 PXL, PANTALLA: 9,4 pulg, MEMORIA: 32 Gb, MEMORIA RAM: 32 Gb | F11: UNIDAD | G11: 10 | H11: 28000 | I11: =G11*H11 -> 280000
A12: 3 | B12: 4.3.6-9181.33 | C12: EQUIPO DE OFICINA Y MUEBLES | D12: =LEFT(B12,5) -> 4.3.6 | E12: ESCANERS; TIPO: 3D PORTATIL, RESOLUCION: SIN VALOR mm, ALIMENTACION: USB | F12: UNIDAD | G12: 2 | H12: 130000 | I12: =G12*H12 -> 260000
A13: 4 | B13: 4.3.6-9707.8 | C13: EQUIPOS | D13: =LEFT(B13,5) -> 4.3.6 | E13: IMPRESORA 3D; TIPO: DE PRECISION, DIMENSION: 200 X 200 X 200 mm, RESOLUCION: 0,1 mm, PRECISION: 0,1 mm, ESPESOR CAPA: 1,75 mm | F13: UNIDAD | G13: 5 | H13: 65000 | I13: =G13*H13 -> 325000
A14: 5 | B14: 4.3.6-9707.15 | C14: EQUIPOS | D14: =LEFT(B14,5) -> 4.3.6 | E14: IMPRESORA 3D; TIPO: FDM, DIMENSION: 150 X 200 X 200 mm, RESOLUCION: 100 Mn, PRECISION: 0,1 mm, ESPESOR CAPA: 1,2 mm | F14: UNIDAD | G14: 10 | H14: 42200 | I14: =G14*H14 -> 422000
A15: 6 | B15: 4.3.6-9707.16 | C15: EQUIPOS | D15: =LEFT(B15,5) -> 4.3.6 | E15: IMPRESORA 3D; TIPO: FDM, DIMENSION: 100 X 100 X 125 mm, RESOLUCION: 100 Mn, PRECISION: 0,1 mm, ESPESOR CAPA: 1,2 mm | F15: UNIDAD | G15: 20 | H15: 5900 | I15: =G15*H15 -> 118000
A16: 7 | B16: 4.3.5-1589.80 | C16: EQUIPOS | D16: =LEFT(B16,5) -> 4.3.5 | E16: PANTALLAS DE PROYECCION; DIMENSION: 100 pulg, ALTURA: REGULABLE, TIPO: MANUAL, MATERIAL: TELA | F16: UNIDAD | G16: 3 | H16: 8500 | I16: =G16*H16 -> 25500
B18: Especificidades Item N° 1:
B20: Descripción técnica
C21: Procesador i3. 1tb de almacenamiento. 120 disco solido. 4 memoria RAM.
B22: Plazos y lugares de entrega
C23: El plazo de entrega no podrá ser superior a los diez (10) días hábiles a partir de la fecha de recepción de la respectiva Orden de Compra en el domicilio especial electrónico constituido, en virtud del método de contratación. La entrega de dichos bienes se realizará en el Ministerio de Ciencia e Innovación Tecnologica, sito en Avenida Republica de Venezuela S/N° - CAPE- Pabellón N° 26 San Fernando del Valle de Catamarca. Se presentará Remito que deberá cumplimentar lo dispuesto por la R.G. AFIP 1415/03, sin excepción.
B25: Calidad Minima esperada
B27: Mantenimiento: Treinta (30) Días Hábiles.-
B29: Garantia: Garantía del fabricante minima de un (1) año.
B33: Especificidades Item N° 2:
B35: Descripción técnica
C36: Sistema operativo: Android. Con procesador de 2GHz. ○ Resolución de pantalla de 1280px x 800px. Con lector microSD. 32 gb de almacenamiento ○ Memoria expandible. ○Sistema de altavoces.
B37: Plazos y lugares de entrega
C38: El plazo de entrega no podrá ser superior a los diez (10) días hábiles a partir de la fecha de recepción de la respectiva Orden de Compra en el domicilio especial electrónico constituido, en virtud del método de contratación. La entrega de dichos bienes se realizará en el Ministerio de Ciencia e Innovación Tecnologica, sito en Avenida Republica de Venezuela S/N° - CAPE- Pabellón N° 26 San Fernando del Valle de Catamarca. Se presentará Remito que deberá cumplimentar lo dispuesto por la R.G. AFIP 1415/03, sin excepción.
B40: Calidad Minima esperada
B42: Mantenimiento: Treinta (30) Días Hábiles.-
B44: Garantia: Garantía del fabricante minima de un (1) año.
B49: Especificidades Item N° 3:
B51: Descripción técnica
C52: Sistemas operativos compatibles: Windows de 64 bits 8 o posteriores. Volumen de escaneo: Min: 0.2m x 0.2m x 0.2m Max: 2m x 2m x 2m. Dimensiones: 12,9 (c) x 17,8 (h) x 3,3 (d) cm ○ Rango de operación: Min: 0.2m Max: 1,6 m. Profundidad de la imagen: 640 (w) x 480 (h) px. Color de la imagen: 1920 (w) x 1080 (h) px. Campo de visión: Horizontal: 45 ° Vertical: 57,5 ° Diagonal: 69 °. Resolución espacial x / y @ 0,5 m: 0,9 mm ○ Resolución de profundidad @ 0,5 m: 1mm. Temperatura de funcionamiento: 10-40 ° C. Interfaz de datos: USB 3.0. Longitud del cable USB: 6 pies ○ Rendimiento de imagen máximo: 30 fps . Debe escanear a color.
B53: Plazos y lugares de entrega
C54: El plazo de entrega no podrá ser superior a los diez (10) días hábiles a partir de la fecha de recepción de la respectiva Orden de Compra en el domicilio especial electrónico constituido, en virtud del método de contratación. La entrega de dichos bienes se realizará en el Ministerio de Ciencia e Innovación Tecnologica, sito en Avenida Republica de Venezuela S/N° - CAPE- Pabellón N° 26 San Fernando del Valle de Catamarca. Se presentará Remito que deberá cumplimentar lo dispuesto por la R.G. AFIP 1415/03, sin excepción.
B56: Calidad Minima esperada
B58: Mantenimiento: Treinta (30) Días Hábiles.-
B60: Garantia: Garantía del fabricante minima de un (1) año.
B64: Especificidades Item N°4:
B66: Descripción técnica
C67: Volumen de Impresión: 200x200x400 mm. Extrusores: 1 ○ Temperaturas de trabajo de Extrusor: Hasta 255 grados. Temperatura Cama Caliente: hasta 120 grados. Precisión de posicionamiento: 0.0125mm XY / 0.0012mm Z. Sensor inductivo para Autonivelación Z. Sensor de filamento detectando falta del mismo el equipo se pause automáticamente. Filamento: Diámetro 1.75mm. Distintos tipos de Filamento como PLA, ABS, sCold, Flexible, PET, PETG, Nylon y más. Pantalla led
...

Sheet  NotaPedido
A1: NOTA DE PEDIDO | J1: N° | K1: 008/2021
A3: JURISDICCIÓN: | D3: 70 - MINISTERIO DE CIENCIA E INNOVACION TECNOLOGICA
A4: SAF: | D4: 20 - MINISTERIO DE CIENCIA E INNOVACION TECNOLOGICA
A5: UNIDAD EJECUTORA: | D5: MINISTERIO DE CIENCIA E INNOVACION TECNOLOGICA
A6: DEPENDENCIA SOLICITANTE: | D6: SECRETARIA DE INNOVACION
A7: PERIODO UTILIZACIÓN: | D7: 2 TRIMESTRE 2021
A8: OBJETO: | D8: ADQUISICIÓN DE EQUIPOS INFORMATICOS DESTINADO A LA CREACIÓN DEL CENTRO DE INNOVACIÓN ITINERANTE.
A10: Ítem | B10: Codigo Item | C10: DESCRIPCIÓN | H10: Adjunta Detalle Técnico | I10: Unidad Medida | J10: Precio Unitario Estimado | K10: Cantidad Solicitada
A12: 1 | B12: 4.3.6-6160.208 | C12: COMPUTADORAS; TIPO: NOTEBOOK, CODIGO ETAP: PC-008, VERSION ETAP: 22.0 | D12: COMPUTADORAS; TIPO: NOTEBOOK, CODIGO ETAP: PC-008, VERSION ETAP: 22.0 | E12: COMPUTADORAS; TIPO: NOTEBOOK, CODIGO ETAP: PC-008, VERSION ETAP: 22.0 | F12: COMPUTADORAS; TIPO: NOTEBOOK, CODIGO ETAP: PC-008, VERSION ETAP: 22.0 | G12: COMPUTADORAS; TIPO: NOTEBOOK, CODIGO ETAP: PC-008, VERSION ETAP: 22.0 | H12: SI | I12: UNIDAD | J12: 95000 | K12: 20
A13: 2 | B13: 4.3.6-9604.3 | C13: TABLETA PC; RESOLUCION: 1280 X 800 PXL, PANTALLA: 9,4 pulg, MEMORIA: 32 Gb, MEMORIA RAM: 32 Gb | D13: TABLETA PC; RESOLUCION: 1280 X 800 PXL, PANTALLA: 9,4 pulg, MEMORIA: 32 Gb, MEMORIA RAM: 32 Gb | E13: TABLETA PC; RESOLUCION: 1280 X 800 PXL, PANTALLA: 9,4 pulg, MEMORIA: 32 Gb, MEMORIA RAM: 32 Gb | F13: TABLETA PC; RESOLUCION: 1280 X 800 PXL, PANTALLA: 9,4 pulg, MEMORIA: 32 Gb, MEMORIA RAM: 32 Gb | G13: TABLETA PC; RESOLUCION: 1280 X 800 PXL, PANTALLA: 9,4 pulg, MEMORIA: 32 Gb, MEMORIA RAM: 32 Gb | H13: SI | I13: UNIDAD | J13: 28000 | K13: 10
A14: 3 | B14: 4.3.6-9707.8 | C14: ESCANERS; TIPO: 3D PORTATIL, RESOLUCION: SIN VALOR mm, ALIMENTACION: USB | D14: ESCANERS; TIPO: 3D PORTATIL, RESOLUCION: SIN VALOR mm, ALIMENTACION: USB | E14: ESCANERS; TIPO: 3D PORTATIL, RESOLUCION: SIN VALOR mm, ALIMENTACION: USB | F14: ESCANERS; TIPO: 3D PORTATIL, RESOLUCION: SIN VALOR mm, ALIMENTACION: USB | G14: ESCANERS; TIPO: 3D PORTATIL, RESOLUCION: SIN VALOR mm, ALIMENTACION: USB | H14: SI | I14: UNIDAD | J14: 130000 | K14: 2
A15: 4 | B15: 4.3.6-9707.8 | C15: IMPRESORA 3D; TIPO: DE PRECISION, DIMENSION: 200 X 200 X 200 mm, RESOLUCION: 0,1 mm, PRECISION: 0,1 mm, ESPESOR CAPA: 1,75 mm | D15: IMPRESORA 3D; TIPO: DE PRECISION, DIMENSION: 200 X 200 X 200 mm, RESOLUCION: 0,1 mm, PRECISION: 0,1 mm, ESPESOR CAPA: 1,75 mm | E15: IMPRESORA 3D; TIPO: DE PRECISION, DIMENSION: 200 X 200 X 200 mm, RESOLUCION: 0,1 mm, PRECISION: 0,1 mm, ESPESOR CAPA: 1,75 mm | F15: IMPRESORA 3D; TIPO: DE PRECISION, DIMENSION: 200 X 200 X 200 mm, RESOLUCION: 0,1 mm, PRECISION: 0,1 mm, ESPESOR CAPA: 1,75 mm | G15: IMPRESORA 3D; TIPO: DE PRECISION, DIMENSION: 200 X 200 X 200 mm, RESOLUCION: 0,1 mm, PRECISION: 0,1 mm, ESPESOR CAPA: 1,75 mm | H15: SI | I15: UNIDAD | J15: 65000 | K15: 5
A16: 5 | B16: 4.3.6-9707.15 | C16: IMPRESORA 3D; TIPO: FDM, DIMENSION: 150 X 200 X 200 mm, RESOLUCION: 100 Mn, PRECISION: 0,1 mm, ESPESOR CAPA: 1,2 mm | D16: IMPRESORA 3D; TIPO: FDM, DIMENSION: 150 X 200 X 200 mm, RESOLUCION: 100 Mn, PRECISION: 0,1 mm, ESPESOR CAPA: 1,2 mm | E16: IMPRESORA 3D; TIPO: FDM, DIMENSION: 150 X 200 X 200 mm, RESOLUCION: 100 Mn, PRECISION: 0,1 mm, ESPESOR CAPA: 1,2 mm | F16: IMPRESORA 3D; TIPO: FDM, DIMENSION: 150 X 200 X 200 mm, RESOLUCION: 100 Mn, PRECISION: 0,1 mm, ESPESOR CAPA: 1,2 mm | G16: IMPRESORA 3D; TIPO: FDM, DIMENSION: 150 X 200 X 200 mm, RESOLUCION: 100 Mn, PRECISION: 0,1 mm, ESPESOR CAPA: 1,2 mm | H16: SI | I16: UNIDAD | J16: 42200 | K16: 10
A17: 6 | B17: 4.3.6-9707.16 | C17: IMPRESORA 3D; TIPO: FDM, DIMENSION: 100 X 100 X 125 mm, RESOLUCION: 100 Mn, PRECISION: 0,1 mm, ESPESOR CAPA: 1,2 mm | D17: IMPRESORA 3D; TIPO: FDM, DIMENSION: 100 X 100 X 125 mm, RESOLUCION: 100 Mn, PRECISION: 0,1 mm, ESPESOR CAPA: 1,2 mm | E17: IMPRESORA 3D; TIPO: FDM, DIMENSION: 100 X 100 X 125 mm, RESOLUCION: 100 Mn, PRECISION: 0,1 mm, ESPESOR CAPA: 1,2 mm | F17: IMPRESORA 3D; TIPO: FDM, DIMENSION: 100 X 100 X 125 mm, RESOLUCION: 100 Mn, PRECISION: 0,1 mm, ESPESOR CAPA: 1,2 mm | G17: IMPRESORA 3D; TIPO: FDM, DIMENSION: 100 X 100 X 125 mm, RESOLUCION: 100 Mn, PRECISION: 0,1 mm, ESPESOR CAPA: 1,2 mm | H17: SI | I17: UNIDAD | J17: 5900 | K17: 20
A18: 7 | B18: 4.3.5-1589.80 | C18: PANTALLAS DE PROYECCION; DIMENSION: 100 pulg, ALTURA: REGULABLE, TIPO: MANUAL, MATERIAL: TELA | D18: PANTALLAS DE PROYECCION; DIMENSION: 100 pulg, ALTURA: REGULABLE, TIPO: MANUAL, MATERIAL: TELA | E18: PANTALLAS DE PROYECCION; DIMENSION: 100 pulg, ALTURA: REGULABLE, TIPO: MANUAL, MATERIAL: TELA | F18: PANTALLAS DE PROYECCION; DIMENSION: 100 pulg, ALTURA: REGULABLE, TIPO: MANUAL, MATERIAL: TELA | G18: PANTALLAS DE PROYECCION; DIMENSION: 100 pulg, ALTURA: REGULABLE, TIPO: MANUAL, MATERIAL: TELA | H18: NO | I18: UNIDAD | J18: 8500 | K18: 3
A19: Costo total estimado: PESOS TRES MILLONES TRESCIENTOS TREINTA MIL QUINIENTOS CON 00/100.- | J19: =SUMPRODUCT(J12:J18,K12:K18) -> 3330500

Sheet Autor Gastar
A1: EJERCICIO: | D1: ='Necesidades Trimestrales'!C6 -> 2021 | P1: AUTORIZACION PARA GASTAR
A4: JURISDICCIÓN: | G4: =' NotaPedido'!D3 -> 70 - MINISTERIO DE CIENCIA E INNOVACION TECNOLOGICA
A5: SAF: | G5: =' NotaPedido'!D4 -> 20 - MINISTERIO DE CIENCIA E INNOVACION TECNOLOGICA
A6: UNIDAD EJECUTORA: | G6: =' NotaPedido'!D5 -> MINISTERIO DE CIENCIA E INNOVACION TECNOLOGICA
A7: DEPENDENCIA SOLICITANTE: | G7: =' NotaPedido'!D6 -> SECRETARIA DE INNOVACION
A8: AUTORIZACIÓN:
A9: Señor Jefe de Servicio Administrativo Financiero:
A10: ="Autorizo la realización de los trámites correspondientes, a fin de proveer a este Organismo los bienes y/o servicios que se detallan en Nota de Pedido N° " & ' NotaPedido'!K1&", afectando la erogación resultante a los créditos presupuestarios aprobados a favor de esta Unidad Ejecutora, conforme al siguiente detalle:" -> Autorizo la realización de los trámites correspondientes, a fin de proveer a este Organismo los bienes y/o servicios que se detallan en Nota de Pedido N° 008/2021, afectando la erogación resultante a los créditos presupuestarios aprobados a favor de esta Unidad Ejecutora, conforme al siguiente detalle:
A12: IMPUTACIÓN PRESUPUESTARIA
A13: CÓDIGO | O13: DENOMINACIÓN DE LA PARTIDA PRESUPUESTARIA | Q13: IMPORTE
A14: PR | B14: SB | C14: PY | D14: AC | E14: OB | F14: UG | G14: FIN | H14: FUN | I14: I | J14: P | K14: P | L14: SubP | M14: M | N14: FF
A15: 3 | B15: 0 | C15: 0 | D15: 1 | E15: 0 | F15: 4901 | G15: 3 | H15: 5 | I15: 4 | J15: 3 | K15: 6 | L15: 0 | M15: 1 | N15: 1.1 | O15: Equipos para Computacion | Q15: 3305000
A16: 3 | B16: 0 | C16: 0 | D16: 1 | E16: 0 | F16: 4901 | G16: 3 | H16: 2 | I16: 4 | J16: 3 | K16: 5 | L16: 0 | M16: 1 | N16: 1.1 | O16: Equipo Educacional y Recreativo | Q16: 25500
A22: PESOS: TRES MILLONES TRESCIENTOS TREINTA MIL QUINIENTOS CON 00/100.- | Q22: =SUM(Q15:Q21) -> 3330500
A24: JUSTIFICACIÓN:
A25: ADQUISICIÓN DE EQUIPOS INFORMÁTICOS DESTINADO A LA CREACIÓN DEL CENTRO DE INNOVACIÓN ITINERANTE.-
