Workbook

Sheet Necesidades Trimestrales
B2: Pedido de Necesidades Trimestrales
A4: JURISDICCION: | C4: 40 - Ministerio de Salud
A5: SAF N°: | C5: 23 - Hospital Interzonal San Juan Bautista
A6: EJERCICIO: | C6: 2022
A7: TRIMESTRE: | C7: 3
A9: ID | B9: CODIGO ITEM | C9: RUBRO DE COMPRA | D9: I.P.P. | E9: DESCRIPCION | F9: UNIDAD DE MEDIDA | G9: CANTIDAD | H9: PRECIO UNITARIO ESTIMADO | I9: IMPORTE TOTAL ESTIMADO
A10: 1 | B10: 2.1.1-439.60 | C10: ALIMENTOS | D10: =LEFT(B10,5) -> 2.1.1 | E10: ACEITES COMESTIBLES; TIPO: MEZCLA, PRESENTACION: ENVASE X 900 CM3, MATERIAL ENVASE: PLASTICO 1 (PET), ELEM. TRANSPORTE: SIN, MATERIAL ELEM. TRANSPORTE : SIN, LIBRE DE GLUTEN: SI | F10: UNIDAD | G10: 800 | H10: 370 | I10: =G10*H10 -> 296000
A11: 2 | B11: 2.1.1-435.38 | C11: ALIMENTOS | D11: =LEFT(B11,5) -> 2.1.1 | E11: ARROZ; TIPO GRANO: DOBLE, TIPO: BLANCO, PROCESO: PARBOLIZADO, PRESENTACION: ENVASE X 1 Kg, MATERIAL ENVASE: CARTON, CERTIFICADO FORESTAL (GFS): SIN, ELEM. TRANSPORTE: SIN, MATERIAL ELEM. TRANSPORTE: SIN | F11: UNIDAD | G11: 500 | H11: 260 | I11: =G11*H11 -> 130000
A12: 3 | B12: 2.1.1-435.50 | C12: ALIMENTOS | D12: =LEFT(B12,5) -> 2.1.1 | E12: ARROZ; TIPO GRANO: ENTERO, TIPO: BLANCO, PROCESO: FORTIFICADO, PRESENTACION: ENVASE X 1 Kg, MATERIAL ENVASE: PLASTICO 1 (PET), CERTIFICADO FORESTAL (GFS): SIN, ELEM. TRANSPORTE: SIN, MATERIAL ELEM. TRANSPORTE: SIN, LIBRE DE GLUTEN: NO | F12: UNIDAD | G12: 50 | H12: 125 | I12: =G12*H12 -> 6250
A13: 4 | B13: 2.1.1-2124.3 | C13: ALIMENTOS | D13: =LEFT(B13,5) -> 2.1.1 | E13: AVENAS; TIPO: ARROLLADA, ESTADO: NATURAL, PRESENTACION: BOLSA, PESO: 1 Kg | F13: UNIDAD | G13: 15 | H13: 376 | I13: =G13*H13 -> 5640
A14: 5 | B14: 2.1.1-481.38 | C14: ALIMENTOS | D14: =LEFT(B14,5) -> 2.1.1 | E14: AZUCARES; TIPO: "A" COMUN, ESTADO: MOLIDA, PESO: 1 Kg, MATERIAL ENVASE: PLASTICO, CERTIFICADO FORESTAL (GFS): SIN, ELEM. TRANSPORTE: SIN, MATERIAL ELEM. TRANSPORTE: SIN | F14: UNIDAD | G14: 1200 | H14: 120 | I14: =G14*H14 -> 144000
A15: 6 | B15: 2.1.1-709.6 | C15: ALIMENTOS | D15: 2.1.1 | E15: CAFE; ESTADO: MOLIDO, ENVASE: PAQUETE, PROCESO: TORRADO C/AZUCAR, CONTENIDO: 500 GR, TIPO: SIN VALOR, PRESENTACION: ENVASE X 500 GR | F15: UNIDAD | G15: 10 | H15: 1250 | I15: =G15*H15 -> 12500
A16: 7 | B16: 2.1.1-2615.15 | C16: ALIMENTOS | D16: 2.1.1 | E16: CACAO; TIPO: INSTANTANEO, PRESENTACION: ENVASE X 800 GR, FORMA DE PRESENTACION: POLVO, MATERIAL ENVASE: CARTON, CERTICADO FORESTAL (GFS): CON, LIBRE DE GLUTEN: SI | F16: UNIDAD | G16: 5 | H16: 882 | I16: =G16*H16 -> 4410
A17: 8 | B17: 2.1.1-5917.8 | C17: ALIMENTOS | D17: =LEFT(B17,5) -> 2.1.1 | E17: CEREALES; TIPO: TRIGO BURGOL, PRESENTACION: ENVASE X 1 Kg | F17: UNIDAD | G17: 15 | H17: 334 | I17: =G17*H17 -> 5010
A18: 9 | B18: 2.1.1-597.41 | C18: ALIMENTOS | D18: =LEFT(B18,5) -> 2.1.1 | E18: CONSERVAS DE FRUTAS; VARIEDAD: COCTEL, ENVASE: LATA, PESO: 800 GR, ELEM. TRANSPORTE: SIN, MATERIAL ELEM. TRANSPORTE: SIN, LIBRE DE GLUTEN: NO | F18: UNIDAD | G18: 300 | H18: 422 | I18: =G18*H18 -> 126600
A19: 10 | B19: 2.1.1-597.43 | C19: ALIMENTOS | D19: =LEFT(B19,5) -> 2.1.1 | E19: CONSERVAS DE FRUTAS; VARIEDAD: COCTEL, ENVASE: LATA, PESO: 820 GR, ELEM. TRANSPORTE: SIN, MATERIAL ELEM. TRANSPORTE: SIN, LIBRE DE GLUTEN: SI | F19: UNIDAD | G19: 300 | H19: 660 | I19: =G19*H19 -> 198000
A20: 11 | B20: 2.1.1-708.43 | C20: ALIMENTOS | D20: =LEFT(B20,5) -> 2.1.1 | E20: CONSERVAS PESCADO Y FRUTOS MAR; TIPO: ATUN, ESTADO: AL NATURAL, PESO: 170 GR, ENVASE: LATA, ELEM. TRANSPORTE: SIN, MATERIAL ELEM. TRANSPORTE: SIN | F20: UNIDAD | G20: 150 | H20: 185 | I20: =G20*H20 -> 27750
A21: 12 | B21: 2.1.1-455.16 | C21: ALIMENTOS | D21: =LEFT(B21,5) -> 2.1.1 | E21: DULCE DE LECHE; ENVASE: DE CARTON, CAPACIDAD: 5000 GR, TIPO: DE REPOSTERIA, PRESENTACION: ENVASE DE CARTON X 5 Kg | F21: UNIDAD | G21: 5 | H21: 1990 | I21: =G21*H21 -> 9950
A22: 13 | B22: 2.1.1-2113.21 | C22: ALIMENTOS | D22: =LEFT(B22,5) -> 2.1.1 | E22: DULCES; TIPO: BATATA A LA VAINILLA, PRESENTACION: LATA, PESO: 5 Kg | F22: UNIDAD | G22: 20 | H22: 1990 | I22: =G22*H22 -> 39800
A23: 14 | B23: 2.1.1-2113.2 | C23: ALIMENTOS | D23: =LEFT(B23,5) -> 2.1.1 | E23: DULCES; TIPO: DE MEMBRILLO, PRESENTACION: LATA, PESO: 5 Kg | F23: UNIDAD | G23: 20 | H23: 2200 | I23: =G23*H23 -> 44000
A24: 15 | B24: 2.1.1-595.2 | C24: ALIMENTOS | D24: =LEFT(B24,5) -> 2.1.1 | E24: EDULCORANTES; PRESENTACION: LIQUIDO, ENVASE: BOTELLA PLASTICA, CONTENIDO: 500 CM3 | F24: UNIDAD | G24: 150 | H24: 310 | I24: =G24*H24 -> 46500
A25: 16 | B25: 2.1.1-489.66 | C25: ALIMENTOS | D25: =LEFT(B25,5) -> 2.1.1 | E25: ESPECIAS; TIPO: OREGANO, PRESENTACION: BOLSA DE 1 Kg | F25: UNIDAD | G25: 9 | H25: 700 | I25: =G25*H25 -> 6300
A26: 17 | B26: 2.1.1-489.68 | C26: ALIMENTOS | D26: =LEFT(B26,5) -> 2.1.1 | E26: ESPECIAS; PRESENTACION: BOLSA DE 1 Kg, TIPO: AJI MOLIDO | F26: UNIDAD | G26: 4 | H26: 700 | I26: =G26*H26 -> 2800
A27: 18 | B27: 2.1.1-489.119 | C27: ALIMENTOS | D27: =LEFT(B27,5) -> 2.1.1 | E27: ESPECIAS; TIPO: COMINO, PRESENTACION: BOLSA X 1 Kg | F27: UNIDAD | G27: 2 | H27: 700 | I27: =G27*H27 -> 1400
A28: 19 | B28: 2.1.1-489.53 | C28: ALIMENTOS | D28: =LEFT(B28,5) -> 2.1.1 | E28: ESPECIAS; TIPO: NUEZ MOSCADA, PRESENTACION: POLVO | F28: KG | G28: 3 | H28: 2500 | I28: =G28*H28 -> 7500
... A56: 47 | B56: 2.1.1-6547.88 | C56: ALIMENTOS | D56: =LEFT(B56,5) -> 2.1.1 | E56: LEGUMBRES; VARIEDAD: LENTEJA, ESTADO: SECO, PRESENTACION: BOLSA, PESO: 450 GR, MATERIAL ENVASE: PLASTICO, ELEM. TRANSPORTE: SIN, MATERIAL ELEM. TRANSPORTE: SIN, LIBRE DE GLUTEN: SI | F56: UNIDAD | G56: 10 | H56: 158 | I56: =G56*H56 -> 1580
A57: 48 | B57: 2.1.1-6547.56 | C57: ALIMENTOS | D57: 2.1.1 | E57: LEGUMBRES; VARIEDAD: POROTO BLANCO OVAL, ESTADO: SECO, PRESENTACION: BOLSA, PESO: 500 GR | F57: UNIDAD | G57: 40 | H57: 280 | I57: =G57*H57 -> 11200
A58: 49 | B58: 2.1.1-2616.9 | C58: ALIMENTOS | D58: 2.1.1 | E58: MAIZ; TIPO: BLANCO PISADO, PRESENTACION: ENVASE X 500 GR, FORMA DE PRESENTACION: SIN VALOR | F58: UNIDAD | G58: 60 | H58: 135 | I58: =G58*H58 -> 8100
A59: 50 | B59: 2.1.1-6547.57 | C59: ALIMENTOS | D59: =LEFT(B59,5) -> 2.1.1 | E59: LEGUMBRES; VARIEDAD: LENTEJAS SECAS, ESTADO: SECO, PRESENTACION: BOLSA, PESO: 500 GR | F59: UNIDAD | G59: 40 | H59: 240 | I59: =G59*H59 -> 9600
A60: 51 | B60: 2.1.1-706.6 | C60: ALIMENTOS | D60: =LEFT(B60,5) -> 2.1.1 | E60: MATE COCIDO; ENVASE: CAJA CARTON, PRESENTACION: ENSOBRADO, SAQUITOS P/CAJA: 100 UN, PESO X SAQ.: 3 GR | F60: UNIDAD | G60: 300 | H60: 310 | I60: =G60*H60 -> 93000
A61: 52 | B61: 2.1.1-517.86 | C61: ALIMENTOS | D61: =LEFT(B61,5) -> 2.1.1 | E61: POSTRES; ESTADO PREPARACION: CON COCCION, TIPO: POLVO, ENVASE: CAJA DE CARTON, PESO: 80 GR, SABOR: VAINILLA, LIBRE DE GLUTEN: SI | F61: UNIDAD | G61: 120 | H61: 120 | I61: =G61*H61 -> 14400
A62: 53 | B62: 2.1.1-514.2 | C62: ALIMENTOS | D62: =LEFT(B62,5) -> 2.1.1 | E62: SAL DE MESA; CONSISTENCIA: FINA, PESO: 500 GR, TIPO: SIN VALOR, ENVASE: PAQUETE | F62: UNIDAD | G62: 100 | H62: 45 | I62: =G62*H62 -> 4500
A63: 54 | B63: 2.1.1-514.11 | C63: ALIMENTOS | D63: 2.1.1 | E63: SAL DE MESA; CONSISTENCIA: GRUESA, PESO: 50 Kg, TIPO: SIN VALOR, ENVASE: BOLSA | F63: UNIDAD | G63: 15 | H63: 1620 | I63: =G63*H63 -> 24300
A64: 55 | B64: 2.1.1-514.15 | C64: ALIMENTOS | D64: =LEFT(B64,5) -> 2.1.1 | E64: SAL DE MESA; CONSISTENCIA: GRUESA, ENVASE: BOLSA, PESO: 1 Kg, TIPO: SIN VALOR | F64: UNIDAD | G64: 15 | H64: 90 | I64: =G64*H64 -> 1350
A65: 56 | B65: 2.1.1-2126.13 | C65: ALIMENTOS | D65: =LEFT(B65,5) -> 2.1.1 | E65: SEMOLAS; TIPO: VITINA, PRESENTACION: BOLSA, PESO: 500 GR, MATERIAL ENVASE: PLASTICO 1 (PET), CERTICADO FORESTAL (GFS): SIN, LIBRE DE GLUTEN: NO | F65: UNIDAD | G65: 20 | H65: 229 | I65: =G65*H65 -> 4580
A66: 57 | B66: 2.1.1-511.8 | C66: ALIMENTOS | D66: =LEFT(B66,5) -> 2.1.1 | E66: TE; SAQUITOS 2G P/CAJA: 50, PESO: SIN VALOR, TIPO: SIN VALOR, PRESENTACION: EN SAQUITOS | F66: UNIDAD | G66: 700 | H66: 180 | I66: =G66*H66 -> 126000
A67: 58 | B67: 2.1.1-6546.336 | C67: ALIMENTOS | D67: =LEFT(B67,5) -> 2.1.1 | E67: VERDURAS Y HORTALIZAS; VARIEDAD: CHOCLO, ESTADO: CREMOSO, PRESENTACION: LATA, PESO: 350 GR, ELEM. TRANSPORTE: SIN, MATERIAL ELEM. TRANSPORTE: SIN, LIBRE DE GLUTEN: NO | F67: UNIDAD | G67: 200 | H67: 84 | I67: =G67*H67 -> 16800
A68: 59 | B68: 2.1.1-6546.269 | C68: ALIMENTOS | D68: =LEFT(B68,5) -> 2.1.1 | E68: VERDURAS Y HORTALIZAS; VARIEDAD: CHOCLO, ESTADO: GRANO, PRESENTACION: LATA, PESO: 350 GR | F68: UNIDAD | G68: 200 | H68: 133 | I68: =G68*H68 -> 26600
A69: 60 | B69: 2.1.1-6546.183 | C69: ALIMENTOS | D69: =LEFT(B69,5) -> 2.1.1 | E69: VERDURAS Y HORTALIZAS; VARIEDAD: TOMATE PERITA, ESTADO: NATURAL, PRESENTACION: LATA, PESO: 380 GR | F69: UNIDAD | G69: 300 | H69: 88.25 | I69: =G69*H69 -> 26475
A70: 61 | B70: 2.1.1-6546.81 | C70: ALIMENTOS | D70: =LEFT(B70,5) -> 2.1.1 | E70: VERDURAS Y HORTALIZAS; VARIEDAD: TOMATE, ESTADO: PURE NATURAL, PRESENTACION: CAJA, PESO: 500 GR | F70: UNIDAD | G70: 300 | H70: 77 | I70: =G70*H70 -> 23100
...

Sheet NotaPedido
A1: NOTA DE PEDIDO 81 | J1: N° | K1: DOCFI-2022-01256692-CAT-DASIS#HSJB
A3: JURISDICCIÓN: | D3: ='Necesidades Trimestrales'!C4 -> 40 - Ministerio de Salud
A4: SAF: | D4: ='Necesidades Trimestrales'!C5 -> 23 - Hospital Interzonal San Juan Bautista
A5: UNIDAD EJECUTORA: | D5: 168 - Direccion Asistencial
A6: DEPENDENCIA SOLICITANTE: | D6: Servicio de Nutricion
A7: PERIODO UTILIZACIÓN: | D7: 3° TRIMESTRE - AÑO 2022
A8: OBJETO: | D8: Adquisición de Alimentos no perecederos
A10: Ítem | B10: Codigo Item | C10: DESCRIPCIÓN | H10: Adjunta Detalle Técnico | I10: Unidad Medida | J10: Precio Unitario Estimado | K10: Cantidad Solicitada
A12: 1 | B12: ='Necesidades Trimestrales'!B10 -> 2.1.1-439.60 | C12: ='Necesidades Trimestrales'!E10 -> ACEITES COMESTIBLES; TIPO: MEZCLA, PRESENTACION: ENVASE X 900 CM3, MATERIAL ENVASE: PLASTICO 1 (PET), ELEM. TRANSPORTE: SIN, MATERIAL ELEM. TRANSPORTE : SIN, LIBRE DE GLUTEN: SI | H12: NO | I12: ='Necesidades Trimestrales'!F10 -> UNIDAD | J12: ='Necesidades Trimestrales'!H10 -> 370 | K12: ='Necesidades Trimestrales'!G10 -> 800
A13: 2 | B13: ='Necesidades Trimestrales'!B11 -> 2.1.1-435.38 | C13: ='Necesidades Trimestrales'!E11 -> ARROZ; TIPO GRANO: DOBLE, TIPO: BLANCO, PROCESO: PARBOLIZADO, PRESENTACION: ENVASE X 1 Kg, MATERIAL ENVASE: CARTON, CERTIFICADO FORESTAL (GFS): SIN, ELEM. TRANSPORTE: SIN, MATERIAL ELEM. TRANSPORTE: SIN | H13: NO | I13: ='Necesidades Trimestrales'!F11 -> UNIDAD | J13: ='Necesidades Trimestrales'!H11 -> 260 | K13: ='Necesidades Trimestrales'!G11 -> 500
A14: 3 | B14: ='Necesidades Trimestrales'!B12 -> 2.1.1-435.50 | C14: ='Necesidades Trimestrales'!E12 -> ARROZ; TIPO GRANO: ENTERO, TIPO: BLANCO, PROCESO: FORTIFICADO, PRESENTACION: ENVASE X 1 Kg, MATERIAL ENVASE: PLASTICO 1 (PET), CERTIFICADO FORESTAL (GFS): SIN, ELEM. TRANSPORTE: SIN, MATERIAL ELEM. TRANSPORTE: SIN, LIBRE DE GLUTEN: NO | H14: NO | I14: ='Necesidades Trimestrales'!F12 -> UNIDAD | J14: ='Necesidades Trimestrales'!H12 -> 125 | K14: ='Necesidades Trimestrales'!G12 -> 50
A15: 4 | B15: ='Necesidades Trimestrales'!B13 -> 2.1.1-2124.3 | C15: ='Necesidades Trimestrales'!E13 -> AVENAS; TIPO: ARROLLADA, ESTADO: NATURAL, PRESENTACION: BOLSA, PESO: 1 Kg | H15: NO | I15: ='Necesidades Trimestrales'!F13 -> UNIDAD | J15: ='Necesidades Trimestrales'!H13 -> 376 | K15: ='Necesidades Trimestrales'!G13 -> 15
A16: 5 | B16: ='Necesidades Trimestrales'!B14 -> 2.1.1-481.38 | C16: ='Necesidades Trimestrales'!E14 -> AZUCARES; TIPO: "A" COMUN, ESTADO: MOLIDA, PESO: 1 Kg, MATERIAL ENVASE: PLASTICO, CERTIFICADO FORESTAL (GFS): SIN, ELEM. TRANSPORTE: SIN, MATERIAL ELEM. TRANSPORTE: SIN | H16: NO | I16: ='Necesidades Trimestrales'!F14 -> UNIDAD | J16: ='Necesidades Trimestrales'!H14 -> 120 | K16: ='Necesidades Trimestrales'!G14 -> 1200
A17: 6 | B17: ='Necesidades Trimestrales'!B15 -> 2.1.1-709.6 | C17: ='Necesidades Trimestrales'!E15 -> CAFE; ESTADO: MOLIDO, ENVASE: PAQUETE, PROCESO: TORRADO C/AZUCAR, CONTENIDO: 500 GR, TIPO: SIN VALOR, PRESENTACION: ENVASE X 500 GR | H17: NO | I17: ='Necesidades Trimestrales'!F15 -> UNIDAD | J17: ='Necesidades Trimestrales'!H15 -> 1250 | K17: ='Necesidades Trimestrales'!G15 -> 10
A18: 7 | B18: ='Necesidades Trimestrales'!B16 -> 2.1.1-2615.15 | C18: ='Necesidades Trimestrales'!E16 -> CACAO; TIPO: INSTANTANEO, PRESENTACION: ENVASE X 800 GR, FORMA DE PRESENTACION: POLVO, MATERIAL ENVASE: CARTON, CERTICADO FORESTAL (GFS): CON, LIBRE DE GLUTEN: SI | H18: NO | I18: ='Necesidades Trimestrales'!F16 -> UNIDAD | J18: ='Necesidades Trimestrales'!H16 -> 882 | K18: ='Necesidades Trimestrales'!G16 -> 5
A19: 8 | B19: ='Necesidades Trimestrales'!B17 -> 2.1.1-5917.8 | C19: ='Necesidades Trimestrales'!E17 -> CEREALES; TIPO: TRIGO BURGOL, PRESENTACION: ENVASE X 1 Kg | H19: NO | I19: ='Necesidades Trimestrales'!F17 -> UNIDAD | J19: ='Necesidades Trimestrales'!H17 -> 334 | K19: ='Necesidades Trimestrales'!G17 -> 15
A20: 9 | B20: ='Necesidades Trimestrales'!B18 -> 2.1.1-597.41 | C20: ='Necesidades Trimestrales'!E18 -> CONSERVAS DE FRUTAS; VARIEDAD: COCTEL, ENVASE: LATA, PESO: 800 GR, ELEM. TRANSPORTE: SIN, MATERIAL ELEM. TRANSPORTE: SIN, LIBRE DE GLUTEN: NO | H20: NO | I20: ='Necesidades Trimestrales'!F18 -> UNIDAD | J20: ='Necesidades Trimestrales'!H18 -> 422 | K20: ='Necesidades Trimestrales'!G18 -> 300
A21: 10 | B21: ='Necesidades Trimestrales'!B19 -> 2.1.1-597.43 | C21: ='Necesidades Trimestrales'!E19 -> CONSERVAS DE FRUTAS; VARIEDAD: COCTEL, ENVASE: LATA, PESO: 820 GR, ELEM. TRANSPORTE: SIN, MATERIAL ELEM. TRANSPORTE: SIN, LIBRE DE GLUTEN: SI | H21: NO | I21: ='Necesidades Trimestrales'!F19 -> UNIDAD | J21: ='Necesidades Trimestrales'!H19 -> 660 | K21: ='Necesidades Trimestrales'!G19 -> 300
A22: 11 | B22: ='Necesidades Trimestrales'!B20 -> 2.1.1-708.43 | C22: ='Necesidades Trimestrales'!E20 -> CONSERVAS PESCADO Y FRUTOS MAR; TIPO: ATUN, ESTADO: AL NATURAL, PESO: 170 GR, ENVASE: LATA, ELEM. TRANSPORTE: SIN, MATERIAL ELEM. TRANSPORTE: SIN | H22: NO | I22: ='Necesidades Trimestrales'!F20 -> UNIDAD | J22: ='Necesidades Trimestrales'!H20 -> 185 | K22: ='Necesidades Trimestrales'!G20 -> 150
A23: 12 | B23: ='Necesidades Trimestrales'!B21 -> 2.1.1-455.16 | C23: ='Necesidades Trimestrales'!E21 -> DULCE DE LECHE; ENVASE: DE CARTON, CAPACIDAD: 5000 GR, TIPO: DE REPOSTERIA, PRESENTACION: ENVASE DE CARTON X 5 Kg | H23: NO | I23: ='Necesidades Trimestrales'!F21 -> UNIDAD | J23: ='Necesidades Trimestrales'!H21 -> 1990 | K23: ='Necesidades Trimestrales'!G21 -> 5
A24: 13 | B24: ='Necesidades Trimestrales'!B22 -> 2.1.1-2113.21 | C24: ='Necesidades Trimestrales'!E22 -> DULCES; TIPO: BATATA A LA VAINILLA, PRESENTACION: LATA, PESO: 5 Kg | H24: NO | I24: ='Necesidades Trimestrales'!F22 -> UNIDAD | J24: ='Necesidades Trimestrales'!H22 -> 1990 | K24: ='Necesidades Trimestrales'!G22 -> 20
A25: 14 | B25: ='Necesidades Trimestrales'!B23 -> 2.1.1-2113.2 | C25: ='Necesidades Trimestrales'!E23 -> DULCES; TIPO: DE MEMBRILLO, PRESENTACION: LATA, PESO: 5 Kg | H25: NO | I25: ='Necesidades Trimestrales'!F23 -> UNIDAD | J25: ='Necesidades Trimestrales'!H23 -> 2200 | K25: ='Necesidades Trimestrales'!G23 -> 20 | P25: 1335
A26: 15 | B26: ='Necesidades Trimestrales'!B24 -> 2.1.1-595.2 | C26: ='Necesidades Trimestrales'!E24 -> EDULCORANTES; PRESENTACION: LIQUIDO, ENVASE: BOTELLA PLASTICA, CONTENIDO: 500 CM3 | H26: NO | I26: ='Necesidades Trimestrales'!F24 -> UNIDAD | J26: ='Necesidades Trimestrales'!H24 -> 310 | K26: ='Necesidades Trimestrales'!G24 -> 150
A27: 16 | B27: ='Necesidades Trimestrales'!B25 -> 2.1.1-489.66 | C27: ='Necesidades Trimestrales'!E25 -> ESPECIAS; TIPO: OREGANO, PRESENTACION: BOLSA DE 1 Kg | H27: NO | I27: ='Necesidades Trimestrales'!F25 -> UNIDAD | J27: ='Necesidades Trimestrales'!H25 -> 700 | K27: ='Necesidades Trimestrales'!G25 -> 9
A28: 17 | B28: ='Necesidades Trimestrales'!B26 -> 2.1.1-489.68 | C28: ='Necesidades Trimestrales'!E26 -> ESPECIAS; PRESENTACION: BOLSA DE 1 Kg, TIPO: AJI MOLIDO | H28: NO | I28: ='Necesidades Trimestrales'!F26 -> UNIDAD | J28: ='Necesidades Trimestrales'!H26 -> 700 | K28: ='Necesidades Trimestrales'!G26 -> 4
A29: 18 | B29: ='Necesidades Trimestrales'!B27 -> 2.1.1-489.119 | C29: ='Necesidades Trimestrales'!E27 -> ESPECIAS; TIPO: COMINO, PRESENTACION: BOLSA X 1 Kg | H29: NO | I29: ='Necesidades Trimestrales'!F27 -> UNIDAD | J29: ='Necesidades Trimestrales'!H27 -> 700 | K29: ='Necesidades Trimestrales'!G27 -> 2
A30: 19 | B30: ='Necesidades Trimestrales'!B28 -> 2.1.1-489.53 | C30: ='Necesidades Trimestrales'!E28 -> ESPECIAS; TIPO: NUEZ MOSCADA, PRESENTACION: POLVO | H30: NO | I30: ='Necesidades Trimestrales'!F28 -> KG | J30: ='Necesidades Trimestrales'!H28 -> 2500 | K30: ='Necesidades Trimestrales'!G28 -> 3
A31: 20 | B31: ='Necesidades Trimestrales'!B29 -> 2.1.1-489.67 | C31: ='Necesidades Trimestrales'!E29 -> ESPECIAS; TIPO: PIMENTON, PRESENTACION: BOLSA DE 1 Kg | H31: NO | I31: ='Necesidades Trimestrales'!F29 -> UNIDAD | J31: ='Necesidades Trimestrales'!H29 -> 700 | K31: ='Necesidades Trimestrales'!G29 -> 9
A32: 21 | B32: ='Necesidades Trimestrales'!B30 -> 2.1.1-489.132 | C32: ='Necesidades Trimestrales'!E30 -> ESPECIAS; TIPO: PIMIENTA BLANCA, PRESENTACION: ENVASE X 1 Kg | H32: NO | I32: ='Necesidades Trimestrales'!F30 -> UNIDAD | J32: ='Necesidades Trimestrales'!H30 -> 700 | K32: ='Necesidades Trimestrales'!G30 -> 3
A33: 22 | B33: ='Necesidades Trimestrales'!B31 -> 2.1.1-613.9 | C33: ='Necesidades Trimestrales'!E31 -> FECULA DE MAIZ; ENVASE: BOLSA, PESO: 500 GR, LIBRE DE GLUTEN: SI | H33: NO | I33: ='Necesidades Trimestrales'!F31 -> UNIDAD | J33: ='Necesidades Trimestrales'!H31 -> 160 | K33: ='Necesidades Trimestrales'!G31 -> 50
A34: 23 | B34: ='Necesidades Trimestrales'!B32 -> 2.1.1-2868.56 | C34: ='Necesidades Trimestrales'!E32 -> FIDEOS SECOS; VARIEDAD: CABELLO DE ANGEL, RELLENO: SIN, PRESENTACION: ENVASE X 500 GR, MATERIAL ENVASE: PVC, ELEM. TRANSPORTE: CAJA, MATERIAL ELEM. TRANSPORTE: CARTON, CERTIFICADO FORESTAL (GFS): SIN, LIBRE DE GLUTEN: NO | H34: NO | I34: ='Necesidades Trimestrales'!F32 -> UNIDAD | J34: ='Necesidades Trimestrales'!H32 -> 136 | K34: ='Necesidades Trimestrales'!G32 -> 50
A35: 24 | B35: ='Necesidades Trimestrales'!B33 -> 2.1.1-2868.71 | C35: ='Necesidades Trimestrales'!E33 -> FIDEOS SECOS; VARIEDAD: GUISERO, RELLENO: SIN, PRESENTACION: ENVASE X 500 GR, MATERIAL ENVASE: PLASTICO 1 (PET), ELEM. TRANSPORTE: SIN, MATERIAL ELEM. TRANSPORTE: SIN, CERTIFICADO FORESTAL (GFS): SIN, LIBRE DE GLUTEN: NO | H35: NO | I35: ='Necesidades Trimestrales'!F33 -> UNIDAD | J35: ='Necesidades Trimestrales'!H33 -> 80 | K35: ='Necesidades Trimestrales'!G33 -> 50
A36: 25 | B36: ='Necesidades Trimestrales'!B34 -> 2.1.1-2868.59 | C36: ='Necesidades Trimestrales'!E34 -> FIDEOS SECOS; VARIEDAD: MOSTACHOLES, RELLENO: SIN, PRESENTACION: ENVASE X 500 GR, MATERIAL ENVASE: PVC, ELEM. TRANSPORTE: CAJA, MATERIAL ELEM. TRANSPORTE: CARTON, CERTIFICADO FORESTAL (GFS): SIN, LIBRE DE GLUTEN: NO | H36: NO | I36: ='Necesidades Trimestrales'!F34 -> UNIDAD | J36: ='Necesidades Trimestrales'!H34 -> 80 | K36: ='Necesidades Trimestrales'!G34 -> 50
A37: 26 | B37: ='Necesidades Trimestrales'!B35 -> 2.1.1-2868.58 | C37: ='Necesidades Trimestrales'!E35 -> FIDEOS SECOS; VARIEDAD: MUNICION, RELLENO: SIN, PRESENTACION: ENVASE X 500 GR, MATERIAL ENVASE: PVC, ELEM. TRANSPORTE: CAJA, MATERIAL ELEM. TRANSPORTE: CARTON, CERTIFICADO FORESTAL (GFS): SIN, LIBRE DE GLUTEN: NO | H37: NO | I37: ='Necesidades Trimestrales'!F35 -> UNIDAD | J37: ='Necesidades Trimestrales'!H35 -> 80 | K37: ='Necesidades Trimestrales'!G35 -> 30
... A75: 64 | B75: ='Necesidades Trimestrales'!B73 -> 2.1.1-454.25 | C75: ='Necesidades Trimestrales'!E73 -> YERBAS; PALO: CON, PESO: 1 Kg, MATERIAL ENVASE : PAPEL, CERTIFICADO FORESTAL (GFS): CON, ELEM. TRANSPORTE: SIN, MATERIAL ELEM. TRANSPORTE: SIN, LIBRE DE GLUTEN: SI | H75: NO | I75: ='Necesidades Trimestrales'!F73 -> UNIDAD | J75: ='Necesidades Trimestrales'!H73 -> 450 | K75: ='Necesidades Trimestrales'!G73 -> 10
A76: Costo total estimado: PESOS DOS MILLONES CUATROCIENTOS CUARENTA Y OCHO MIL CUATROCIENTOS OCHENTA Y NUEVE CON 21/100.--- | J76: =SUMPRODUCT(J12:J75,K12:K75) -> 2448489.2

Sheet Autor Gastar
A1: EJERCICIO: | D1: ='Necesidades Trimestrales'!C6 -> 2022 | P1: AUTORIZACION PARA GASTAR
A4: JURISDICCIÓN: | G4: =NotaPedido!D3 -> 40 - Ministerio de Salud
A5: SAF: | G5: =NotaPedido!D4 -> 23 - Hospital Interzonal San Juan Bautista
A6: UNIDAD EJECUTORA: | G6: =NotaPedido!D5 -> 168 - Direccion Asistencial
A7: DEPENDENCIA SOLICITANTE: | G7: =NotaPedido!D6 -> Servicio de Nutricion
A8: AUTORIZACIÓN:
A9: Señor Jefe de Servicio Administrativo Financiero:
A10: ="Autorizo la realización de los trámites correspondientes, a fin de proveer a este Organismo los bienes y/o servicios que se detallan en Nota de Pedido N° "&NotaPedido!K1&", afectando la erogación resultante a los créditos presupuestarios aprobados a favor de esta Unidad Ejecutora, conforme al siguiente detalle:" -> Autorizo la realización de los trámites correspondientes, a fin de proveer a este Organismo los bienes y/o servicios que se detallan en Nota de Pedido N° DOCFI-2022-01256692-CAT-DASIS#HSJB, afectando la erogación resultante a los créditos presupuestarios aprobados a favor de esta Unidad Ejecutora, conforme al siguiente detalle:
A12: IMPUTACIÓN PRESUPUESTARIA
A13: CÓDIGO | O13: DENOMINACIÓN DE LA PARTIDA PRESUPUESTARIA | Q13: IMPORTE
A14: PR | B14: SB | C14: PY | D14: AC | E14: OB | F14: UG | G14: FIN | H14: FUN | I14: I | J14: P | K14: P | L14: SubP | M14: M | N14: FF
A15: 33 | D15: 2 | F15: 4901 | G15: 3 | H15: 3.1 | I15: 2 | J15: 1 | K15: 1 | M15: 1 | N15: 1.1 | O15: Alimentos para personas | Q15: 2448489.2
A21: TOTAL DE PESOS: DOS MILLONES CUATROCIENTOS CUARENTA Y OCHO MIL CUATROCIENTOS OCHENTA Y NUEVE CON 21/100.-- | Q21: =SUM(Q15:Q20) -> 2448489.2
A23: JUSTIFICACIÓN:
A24: ="Para la "&NotaPedido!D8&" para ser destinados al "&NotaPedido!D6&" del HISJB del Ministerio de Salud." -> Para la Adquisición de Alimentos no perecederos para ser destinados al Servicio de Nutricion del HISJB del Ministerio de Salud.
