Workbook

Sheet Necesidades Trimestrales (2)
A1: 2021
B2: Pedido de Necesidades Trimestrales
A4: JURISDICCION: | C4: 40 - MINISTERIO DE SALUD
A5: SAF N°: | C5: 11 - DIRECCION PROVINCIAL DE ADMINISTRACION - MINISTERIO DE SALUD
A6: EJERCICIO: | C6: 2021
A7: TRIMESTRE: | C7: TERCER TRIMESTRE
A9: ID | B9: CODIGO ITEM | C9: RUBRO DE COMPRA | D9: I.P.P. | E9: DESCRIPCION | F9: UNIDAD DE MEDIDA | G9: DIR DE ADM | H9: TOTAL DIR ADM | I9: SEC PREV | J9: TOTAL SEC PREVEN | K9: DIR. LAB. CENTRAL | L9: TOTAL DE LAB CENTRAL | M9: BCO DE SANGRE | N9: TOTAL BANCO DE SANGRE | O9: ATENCION PRIMARIA | P9: TOTAL ATENCION PRI | Q9: DIR DE CANCER | R9: TOTAL DE DIR DE CANCER | S9: FARMACIA | T9: TOTAL FARMACIA | U9: ODONTOLOGIA | V9: TOTAL DE ODONTOLOG | W9: SAME | X9: TOTAL DE SAME | Y9: MALBRAN | Z9: HOSPITAL MALBRAN | AA9: maternidade e infancia | AB9: total maternidad | AC9: SEC DE ASIST EN SALUD PUB | AD9: TOTAL SEC EN ASIS EN SAL | AE9: SALUD Y MEDIO AMBIENTE | AF9: TOTAL SALUD Y MEDIO AMBIENTE | AG9: VECTORES Y ZOONOSIS | AH9: TOTAL DE VECT Y ZOON | AI9: SUMAR | AJ9: TOTAL SUMAR | AK9: CUR | AL9: TOTAL CUR | AM9: PLANIFICACION | AN9: TOTAL PLANIFICA | AO9: SALUD MENTAL | AP9: TOTAL SALUD MENTAL | AQ9: AREAS Y DPAS | AR9: TOTAL DPAS | AS9: CANTIDAD TOTAL | AT9: PRECIO UNITARIO ESTIMADO | AU9: IMPORTE TOTAL ESTIMADO
A10: 1 | C10: PRODUCTOS MEDICOS/FARMACEUTICOS/LAB. | D10: 2.5.2 | E10: ACETATO DE LEUPODROLIDE FORMA FAMACEUTICA: 1 AMPOLLA, PRESENTACION 7,5 MG | F10: AMPOLLA | Q10: 5 | R10: =+Q10*AT10 -> 27060 | AS10: =+Q10 -> 5 | AT10: 5412 | AU10: =+AS10*AT10 -> 27060
A11: 2 | C11: PRODUCTOS MEDICOS/FARMACEUTICOS/LAB. | D11: 2.5.2 | E11: ANASTRAZOL 1 MG * 28 COMPRIMIDOS | F11: CAJAS | Q11: 20 | R11: =+Q11*AT11 -> 11600 | AS11: =+Q11 -> 20 | AT11: 580 | AU11: =+AS11*AT11 -> 11600
A12: 3 | C12: PRODUCTOS MEDICOS/FARMACEUTICOS/LAB. | D12: 2.5.2 | E12: AZACITIDINA 100 MG * 1 AMPOLLA | F12: AMPOLLA | Q12: 14 | R12: =+Q12*AT12 -> 2643858 | AS12: =+Q12 -> 14 | AT12: 188847 | AU12: =+AS12*AT12 -> 2643858
A13: 4 | C13: PRODUCTOS MEDICOS/FARMACEUTICOS/LAB. | D13: 2.5.2 | E13: BEVACIZUMAB 100 MG 1 AMPOLLA | F13: AMPOLLA | Q13: 10 | R13: =+Q13*AT13 -> 700000 | AS13: =+Q13 -> 10 | AT13: 70000 | AU13: =+AS13*AT13 -> 700000
A14: 5 | C14: PRODUCTOS MEDICOS/FARMACEUTICOS/LAB. | D14: 2.5.2 | E14: BEVACIZUMAB 400 MG 1 AMPOLLA, PRESENTACION : VIAL x 16 ML. PRESENTACION . X 1 FRASC AMPOLLA | F14: AMPOLLA | Q14: 10 | R14: =+Q14*AT14 -> 1447640 | AS14: =+Q14 -> 10 | AT14: 144764 | AU14: =+AS14*AT14 -> 1447640
A15: 6 | C15: PRODUCTOS MEDICOS/FARMACEUTICOS/LAB. | D15: 2.5.2 | E15: BLEOMICINA 15 MG* 1 AMPOLLA | F15: AMPOLLA | Q15: 15 | R15: =+Q15*AT15 -> 38700 | AS15: =+Q15 -> 15 | AT15: 2580 | AU15: =+AS15*AT15 -> 38700
A16: 7 | C16: PRODUCTOS MEDICOS/FARMACEUTICOS/LAB. | D16: 2.5.2 | E16: BORTEZOMID, FORMA FARMACEUTICA: 1 AMPOLLA, PRESENTACION: ENVASE X 3,5 MG X UNIDAD | F16: AMPOLLA | Q16: 4 | R16: =+Q16*AT16 -> 21680 | AS16: =+Q16 -> 4 | AT16: 5420 | AU16: =+AS16*AT16 -> 21680
A17: 8 | C17: PRODUCTOS MEDICOS/FARMACEUTICOS/LAB. | D17: 2.5.2 | E17: CAPECITABINA, FORMA FARMACEUTICA: 120 COMPRIMIDOS, PRESENTACION POR 500 MG | F17: CAJAS | Q17: 5 | R17: =+Q17*AT17 -> 42780 | AS17: =+Q17 -> 5 | AT17: 8556 | AU17: =+AS17*AT17 -> 42780
A18: 9 | C18: PRODUCTOS MEDICOS/FARMACEUTICOS/LAB. | D18: 2.5.2 | E18: ='[1]Nota de PyE'!$C$33 -> CARBOPLATINO POR 1 AMPOLLA, PRESENTACION: 150 mGr, | F18: AMPOLLA | Q18: 20 | R18: =+Q18*AT18 -> 21700 | AS18: =+Q18 -> 20 | AT18: 1085 | AU18: =+AS18*AT18 -> 21700
A19: 10 | C19: PRODUCTOS MEDICOS/FARMACEUTICOS/LAB. | D19: 2.5.2 | E19: CARBOPLATINO X 1 AMPOLLA, PRESENTACION: 450 mGr, | F19: AMPOLLA | Q19: 30 | R19: =+Q19*AT19 -> 166050 | AS19: =+Q19 -> 30 | AT19: 5535 | AU19: =+AS19*AT19 -> 166050
A20: 11 | C20: PRODUCTOS MEDICOS/FARMACEUTICOS/LAB. | D20: 2.5.2 | E20: ='[1]Nota de PyE'!$C$13 -> CICLOFOSFAMIDA, FORMA FARMACEUTICA: 1 AMPOLLA, PRESENTACION: 1 GR | F20: AMPOLLA | Q20: 50 | R20: =+Q20*AT20 -> 50000 | AS20: =+Q20 -> 50 | AT20: 1000 | AU20: =+AS20*AT20 -> 50000
A21: 12 | C21: PRODUCTOS MEDICOS/FARMACEUTICOS/LAB. | D21: 2.5.2 | E21: CICLOFOSFAMIDA, FORMA FARMACEUTICA: 5 AMPOLLA, PRESENTACION: 200 MG | F21: AMPOLLA | Q21: 50 | R21: =+Q21*AT21 -> 300000 | AS21: =+Q21 -> 50 | AT21: 6000 | AU21: =+AS21*AT21 -> 300000
A22: 13 | C22: PRODUCTOS MEDICOS/FARMACEUTICOS/LAB. | D22: 2.5.2 | E22: ='[1]Nota de PyE'!$C$19 -> CISPLATINO 50 MG X 1 FRASCO-AMP. | F22: AMPOLLA | Q22: 30 | R22: =+Q22*AT22 -> 35940 | AS22: =+Q22 -> 30 | AT22: 1198 | AU22: =+AS22*AT22 -> 35940
A23: 14 | C23: PRODUCTOS MEDICOS/FARMACEUTICOS/LAB. | D23: 2.5.2 | E23: CITARABINA 100MG X 1FRASCP-AMP. | F23: AMPOLLA | Q23: 50 | R23: =+Q23*AT23 -> 50000 | AS23: =+Q23 -> 50 | AT23: 1000 | AU23: =+AS23*AT23 -> 50000
A24: 15 | C24: PRODUCTOS MEDICOS/FARMACEUTICOS/LAB. | D24: 2.5.2 | E24: CITARABINA, PRESENTACION : 1 GR, FORMA FARAMACEUTICA: 1 AMPOLLA | F24: AMPOLLA | Q24: 20 | R24: =+Q24*AT24 -> 21000 | AS24: =+Q24 -> 20 | AT24: 1050 | AU24: =+AS24*AT24 -> 21000
A25: 16 | C25: PRODUCTOS MEDICOS/FARMACEUTICOS/LAB. | D25: 2.5.2 | E25: DACARBAZINA 100 MG * 1 AMPOLLA | F25: AMPOLLA | Q25: 30 | R25: =+Q25*AT25 -> 37950 | AS25: =+Q25 -> 30 | AT25: 1265 | AU25: =+AS25*AT25 -> 37950
A26: 17 | C26: PRODUCTOS MEDICOS/FARMACEUTICOS/LAB. | D26: 2.5.2 | E26: DACARBAZINA 200 MG * 1 AMPOLLA | F26: AMPOLLA | Q26: 30 | R26: =+Q26*AT26 -> 121890 | AS26: =+Q26 -> 30 | AT26: 4063 | AU26: =+AS26*AT26 -> 121890
A27: 18 | C27: PRODUCTOS MEDICOS/FARMACEUTICOS/LAB. | D27: 2.5.2 | E27: DASATINIB, 100 MG X 30 COMPR. | F27: CAJAS | Q27: 5 | R27: =+Q27*AT27 -> 53995 | AS27: =+Q27 -> 5 | AT27: 10799 | AU27: =+AS27*AT27 -> 53995
A28: 19 | C28: PRODUCTOS MEDICOS/FARMACEUTICOS/LAB. | D28: 2.5.2 | E28: DAUNORRUBICINA 20 MG * 1 AMPOLLA | F28: AMPOLLA | Q28: 50 | R28: =+Q28*AT28 -> 225000 | AS28: =+Q28 -> 50 | AT28: 4500 | AU28: =+AS28*AT28 -> 225000
A29: 20 | C29: PRODUCTOS MEDICOS/FARMACEUTICOS/LAB. | D29: 2.5.2 | E29: DOXORRUBICINA LIPOSOMAL, VIAL, AMPOLLA X 50 MG | F29: AMPOLLA | Q29: 20 | R29: =+Q29*AT29 -> 500000 | AS29: =+Q29 -> 20 | AT29: 25000 | AU29: =+AS29*AT29 -> 500000
A30: 21 | C30: PRODUCTOS MEDICOS/FARMACEUTICOS/LAB. | D30: 2.5.2 | E30: EPIRUBICINA 50 MG * 1 AMPOLLA | F30: AMPOLLA | Q30: 20 | R30: =+Q30*AT30 -> 90000 | AS30: =+Q30 -> 20 | AT30: 4500 | AU30: =+AS30*AT30 -> 90000
A31: 22 | C31: PRODUCTOS MEDICOS/FARMACEUTICOS/LAB. | D31: 2.5.2 | E31: ='[1]Nota de PyE'!$C$17 -> ETOPOSIDO, FORMA FARMACEUTICA: 1 AMPOLLA , PRESENTACION: 100 mGr | F31: AMPOLLA | Q31: 20 | R31: =+Q31*AT31 -> 8000 | AS31: =+Q31 -> 20 | AT31: 400 | AU31: =+AS31*AT31 -> 8000
A32: 23 | C32: PRODUCTOS MEDICOS/FARMACEUTICOS/LAB. | D32: 2.5.2 | E32: FILGASTRIM , 300 MCG, FRASCO AMPOLLA, PRESENTACION X 1 | F32: AMPOLLA | Q32: 300 | R32: =+Q32*AT32 -> 209700 | AS32: =+Q32 -> 300 | AT32: 699 | AU32: =+AS32*AT32 -> 209700
A33: 24 | C33: PRODUCTOS MEDICOS/FARMACEUTICOS/LAB. | D33: 2.5.2 | E33: FLUDARABINA 50MG * 1 AMPOLLA | F33: AMPOLLA | Q33: 20 | R33: =+Q33*AT33 -> 110000 | AS33: =+Q33 -> 20 | AT33: 5500 | AU33: =+AS33*AT33 -> 110000
A34: 25 | C34: PRODUCTOS MEDICOS/FARMACEUTICOS/LAB. | D34: 2.5.2 | E34: FLUOROURACILO 500MG * 5 AMPOLLA | F34: AMPOLLA | Q34: 30 | R34: =+Q34*AT34 -> 39000 | AS34: =+Q34 -> 30 | AT34: 1300 | AU34: =+AS34*AT34 -> 39000
A35: 26 | C35: PRODUCTOS MEDICOS/FARMACEUTICOS/LAB. | D35: 2.5.2 | E35: FOLINATO DE CALCIO, 50 MG, 1 FRASCO- AMPOLLA | F35: AMPOLLA | Q35: 20 | R35: =+Q35*AT35 -> 8520 | AS35: =+Q35 -> 20 | AT35: 426 | AU35: =+AS35*AT35 -> 8520
A36: 27 | C36: PRODUCTOS MEDICOS/FARMACEUTICOS/LAB. | D36: 2.5.2 | E36: FULVESTRANT POR 250 MGR, X 2 AMPOLLAS | F36: AMPOLLA | Q36: 4 | R36: =+Q36*AT36 -> 88000 | AS36: =+Q36 -> 4 | AT36: 22000 | AU36: =+AS36*AT36 -> 88000
A37: 28 | C37: PRODUCTOS MEDICOS/FARMACEUTICOS/LAB. | D37: 2.5.2 | E37: GEMNCITABINA 1000 MG 1 FRASCO AMPOLLA | F37: AMPOLLA | Q37: 50 | R37: =+Q37*AT37 -> 150000 | AS37: =+Q37 -> 50 | AT37: 3000 | AU37: =+AS37*AT37 -> 150000
A38: 29 | C38: PRODUCTOS MEDICOS/FARMACEUTICOS/LAB. | D38: 2.5.2 | E38: GOSORELIN, 3.6 MG, AMPOLLA X 1 | F38: AMPOLLA | Q38: 10 | R38: =+Q38*AT38 -> 500000 | AS38: =+Q38 -> 10 | AT38: 50000 | AU38: =+AS38*AT38 -> 500000
A39: 30 | C39: PRODUCTOS MEDICOS/FARMACEUTICOS/LAB. | D39: 2.5.2 | E39: HIDROXUREA, 500 MGR. CAPSULA X 100 | F39: CAJAS | Q39: 10 | R39: =+Q39*AT39 -> 29580 | AS39: =+Q39 -> 10 | AT39: 2958 | AU39: =+AS39*AT39 -> 29580
A40: 31 | C40: PRODUCTOS MEDICOS/FARMACEUTICOS/LAB. | D40: 2.5.2 | E40: IDARRUBICINA 10 MG * 1 AMPOLLA | F40: AMPOLLA | Q40: 20 | R40: =+Q40*AT40 -> 70000 | AS40: =+Q40 -> 20 | AT40: 3500 | AU40: =+AS40*AT40 -> 70000
A41: 32 | C41: PRODUCTOS MEDICOS/FARMACEUTICOS/LAB. | D41: 2.5.2 | E41: ='[1]Nota de PyE'!$C$58 -> IFOSFAMIDA 1 GR X 1 AMPOLLA | F41: AMPOLLA | Q41: 30 | R41: =+Q41*AT41 -> 450000 | AS41: =+Q41 -> 30 | AT41: 15000 | AU41: =+AS41*AT41 -> 450000
A42: 33 | C42: PRODUCTOS MEDICOS/FARMACEUTICOS/LAB. | D42: 2.5.2 | E42: IMATINIB, FORMA FARMACEUTICA: COMPRIMIDO POR 400 MG. PRESENTACION ENVASE X 30. | F42: CAJAS | Q42: 30 | R42: =+Q42*AT42 -> 165690 | AS42: =+Q42 -> 30 | AT42: 5523 | AU42: =+AS42*AT42 -> 165690
...

Sheet NP
A1: NOTA DE PEDIDO | J1: N° | K1: _09/21
A3: JURISDICCIÓN: | D3: 040 - Ministerio de Salud
A4: SAF: | D4: 011 - Direccion Provincial de Administración - Ministerio de Salud
A5: UNIDAD EJECUTORA: | D5: 159 - DIR. PROVINCIAL DE CANCER
A6: DEPENDENCIA SOLICITANTE: | D6: 159 - DIR. PROVINCIAL DE CANCER
A7: PERIODO UTILIZACIÓN: | D7: 3° TRIMESTRE
A8: OBJETO: | D8: Adquisicion del RUBRO MEDICAMENTOS ONCOLOGICOS
A10: Ítem | B10: Codigo Item | C10: DESCRIPCIÓN | H10: Adjunta Detalle Técnico | I10: Unidad Medida | J10: Precio Unitario Estimado | K10: Cantidad Solicitada
A12: 1 | C12: ='Necesidades Trimestrales (2)'!E10 -> ACETATO DE LEUPODROLIDE FORMA FAMACEUTICA: 1 AMPOLLA, PRESENTACION 7,5 MG | H12: SI | I12: ='Necesidades Trimestrales (2)'!F10 -> AMPOLLA | J12: ='Necesidades Trimestrales (2)'!AT10 -> 5412 | K12: ='Necesidades Trimestrales (2)'!AS10 -> 5 | L12: =+J12*K12 -> 27060 | M12: =+J12*K12 -> 27060
A13: 2 | C13: ='Necesidades Trimestrales (2)'!E11 -> ANASTRAZOL 1 MG * 28 COMPRIMIDOS | H13: SI | I13: ='Necesidades Trimestrales (2)'!F11 -> CAJAS | J13: ='Necesidades Trimestrales (2)'!AT11 -> 580 | K13: ='Necesidades Trimestrales (2)'!AS11 -> 20 | L13: =+J13*K13 -> 11600 | M13: =+J13*K13 -> 11600
A14: 3 | C14: ='Necesidades Trimestrales (2)'!E12 -> AZACITIDINA 100 MG * 1 AMPOLLA | H14: SI | I14: ='Necesidades Trimestrales (2)'!F12 -> AMPOLLA | J14: ='Necesidades Trimestrales (2)'!AT12 -> 188847 | K14: ='Necesidades Trimestrales (2)'!AS12 -> 14 | L14: =+J14*K14 -> 2643858 | M14: =+J14*K14 -> 2643858
A15: 4 | C15: ='Necesidades Trimestrales (2)'!E13 -> BEVACIZUMAB 100 MG 1 AMPOLLA | H15: SI | I15: ='Necesidades Trimestrales (2)'!F13 -> AMPOLLA | J15: ='Necesidades Trimestrales (2)'!AT13 -> 70000 | K15: ='Necesidades Trimestrales (2)'!AS13 -> 10 | L15: =+J15*K15 -> 700000 | M15: =+J15*K15 -> 700000
A16: 5 | C16: ='Necesidades Trimestrales (2)'!E14 -> BEVACIZUMAB 400 MG 1 AMPOLLA, PRESENTACION : VIAL x 16 ML. PRESENTACION . X 1 FRASC AMPOLLA | H16: SI | I16: ='Necesidades Trimestrales (2)'!F14 -> AMPOLLA | J16: ='Necesidades Trimestrales (2)'!AT14 -> 144764 | K16: ='Necesidades Trimestrales (2)'!AS14 -> 10 | L16: =+J16*K16 -> 1447640 | M16: =+J16*K16 -> 1447640
A17: 6 | C17: ='Necesidades Trimestrales (2)'!E15 -> BLEOMICINA 15 MG* 1 AMPOLLA | H17: SI | I17: ='Necesidades Trimestrales (2)'!F15 -> AMPOLLA | J17: ='Necesidades Trimestrales (2)'!AT15 -> 2580 | K17: ='Necesidades Trimestrales (2)'!AS15 -> 15 | L17: =+J17*K17 -> 38700 | M17: =+J17*K17 -> 38700
A18: 7 | C18: ='Necesidades Trimestrales (2)'!E16 -> BORTEZOMID, FORMA FARMACEUTICA: 1 AMPOLLA, PRESENTACION: ENVASE X 3,5 MG X UNIDAD | H18: SI | I18: ='Necesidades Trimestrales (2)'!F16 -> AMPOLLA | J18: ='Necesidades Trimestrales (2)'!AT16 -> 5420 | K18: ='Necesidades Trimestrales (2)'!AS16 -> 4 | L18: =+J18*K18 -> 21680 | M18: =+J18*K18 -> 21680
A19: 8 | C19: ='Necesidades Trimestrales (2)'!E17 -> CAPECITABINA, FORMA FARMACEUTICA: 120 COMPRIMIDOS, PRESENTACION POR 500 MG | H19: SI | I19: ='Necesidades Trimestrales (2)'!F17 -> CAJAS | J19: ='Necesidades Trimestrales (2)'!AT17 -> 8556 | K19: ='Necesidades Trimestrales (2)'!AS17 -> 5 | L19: =+J19*K19 -> 42780 | M19: =+J19*K19 -> 42780
A20: 9 | C20: ='Necesidades Trimestrales (2)'!E18 -> CARBOPLATINO POR 1 AMPOLLA, PRESENTACION: 150 mGr, | H20: SI | I20: ='Necesidades Trimestrales (2)'!F18 -> AMPOLLA | J20: ='Necesidades Trimestrales (2)'!AT18 -> 1085 | K20: ='Necesidades Trimestrales (2)'!AS18 -> 20 | L20: =+J20*K20 -> 21700 | M20: =+J20*K20 -> 21700
A21: 10 | C21: ='Necesidades Trimestrales (2)'!E19 -> CARBOPLATINO X 1 AMPOLLA, PRESENTACION: 450 mGr, | H21: SI | I21: ='Necesidades Trimestrales (2)'!F19 -> AMPOLLA | J21: ='Necesidades Trimestrales (2)'!AT19 -> 5535 | K21: ='Necesidades Trimestrales (2)'!AS19 -> 30 | L21: =+J21*K21 -> 166050 | M21: =+J21*K21 -> 166050
A22: 11 | C22: ='Necesidades Trimestrales (2)'!E20 -> CICLOFOSFAMIDA, FORMA FARMACEUTICA: 1 AMPOLLA, PRESENTACION: 1 GR | H22: SI | I22: ='Necesidades Trimestrales (2)'!F20 -> AMPOLLA | J22: ='Necesidades Trimestrales (2)'!AT20 -> 1000 | K22: ='Necesidades Trimestrales (2)'!AS20 -> 50 | L22: =+J22*K22 -> 50000 | M22: =+J22*K22 -> 50000
A23: 12 | C23: ='Necesidades Trimestrales (2)'!E21 -> CICLOFOSFAMIDA, FORMA FARMACEUTICA: 5 AMPOLLA, PRESENTACION: 200 MG | H23: SI | I23: ='Necesidades Trimestrales (2)'!F21 -> AMPOLLA | J23: ='Necesidades Trimestrales (2)'!AT21 -> 6000 | K23: ='Necesidades Trimestrales (2)'!AS21 -> 50 | L23: =+J23*K23 -> 300000 | M23: =+J23*K23 -> 300000
... A70: 59 | C70: ='Necesidades Trimestrales (2)'!E68 -> VINORELBINE, FORMA FARMACEUTICA, AMPOLLA, PRESENTACION 50 MG. | H70: SI | I70: ='Necesidades Trimestrales (2)'!F68 -> AMPOLLA | J70: ='Necesidades Trimestrales (2)'!AT68 -> 6000 | K70: ='Necesidades Trimestrales (2)'!AS68 -> 30 | L70: =+J70*K70 -> 180000 | M70: =+J70*K70 -> 180000
A72: Costo total estimado: VEINTITRES MILLONES SEISCIENTOS CATORCE MIL DOSCIENTOS CINCUENTA Y CINCO con 00/100 | J72: =SUM(L11:L70) -> 23614255 | M72: =SUM(M12:M71) -> 23614255

Sheet APG
A1: EJERCICIO: | D1: 2021 | P1: AUTORIZACION PARA GASTAR
A4: JURISDICCIÓN: | G4: =NP!D3 -> 040 - Ministerio de Salud
A5: SAF: | G5: =NP!D4 -> 011 - Direccion Provincial de Administración - Ministerio de Salud
A6: UNIDAD EJECUTORA: | G6: =NP!D5 -> 159 - DIR. PROVINCIAL DE CANCER
A7: DEPENDENCIA SOLICITANTE: | G7: =NP!D6 -> 159 - DIR. PROVINCIAL DE CANCER
A8: AUTORIZACIÓN:
A9: Señor Jefe de Servicio Administrativo Financiero:
A10: Autorizo la realización de los trámites correspondientes, a fin de proveer a este Organismo los bienes que se detallan en Nota de pedido y Entrega N°09 /2021, afectando la erogación resultante a los créditos presupuestarios aprobados a favor de esta Unidad Ejecutora, conforme al siguiente detalle:
A12: IMPUTACIÓN PRESUPUESTARIA
A13: CÓDIGO | O13: DENOMINACIÓN DE LA PARTIDA PRESUPUESTARIA | Q13: IMPORTE
A14: PR | B14: SB | C14: PY | D14: AC | E14: OB | F14: UG | G14: FIN | H14: FUN | I14: I | J14: P | K14: P | L14: SubP | M14: M | N14: FF
A15: 44 | D15: 1 | F15: 4901 | G15: 3 | H15: 1 | I15: 2 | J15: 5 | K15: 2 | M15: 1 | N15: 1.1 | O15: Productos Farmacéuticos y Medicinales | Q15: =NP!M72 -> 23614255
A23: TOTAL DE PESOS: VEINTITRES MILLONES SEISCIENTOS CATORCE MIL DOSCIENTOS CINCUENTA Y CINCO con 00/100 | Q23: =SUM(Q15:Q22) -> 23614255
A25: JUSTIFICACIÓN:
A26: =NP!D8 -> Adquisicion del RUBRO MEDICAMENTOS ONCOLOGICOS
