Workbook

Sheet Necesidades Trimestrales (2)
B2: Pedido de Necesidades Trimestrales
A4: JURISDICCION: | C4: 70 - MINISTERIO DE CIENCIA E INNOVACION TECNOLOGICA
A5: SAF N°: | C5: 20 - MINISTERIO DE CIENCIA E INNOVACION TECNOLOGICA
A6: EJERCICIO: | C6: 2021
A7: TRIMESTRE: | C7: 4
A9: ID | B9: CODIGO ITEM | C9: RUBRO DE COMPRA | D9: I.P.P. | E9: DESCRIPCION | F9: UNIDAD DE MEDIDA | G9: CANTIDAD | H9: PRECIO UNITARIO ESTIMADO | I9: IMPORTE TOTAL ESTIMADO
A10: 1 | B10: 4.3.5-9163.80 | C10: EQUIPO | D10: =LEFT(B10,5) -> 4.3.5 | E10: EQUIPOS DIDACTICOS TECNICOS; NOMBRE: LENTES, TIPO: REALIDAD VIRTUAL | F10: UNIDAD | G10: 10 | H10: 185000 | I10: =H10*G10 -> 1850000
A11: 2 | B11: 4.3.5-9163.90 | C11: EQUIPO | D11: =LEFT(B11,5) -> 4.3.5 | E11: EQUIPOS DIDACTICOS TECNICOS; NOMBRE: KIT EXPERIMENTAL , TIPO: SEGÚN PLIEGO | F11: UNIDAD | G11: 10 | H11: 214326 | I11: =H11*G11 -> 2143260 | K11: 435 | L11: =I10+I11+I12+I13+I14+I15+I21+I22+I27+I29+I30+I31+I32+I33+I34 -> 14487944
A12: 3 | B12: 4.3.5-9163.90 | C12: EQUIPO | D12: =LEFT(B12,5) -> 4.3.5 | E12: EQUIPOS DIDACTICOS TECNICOS; NOMBRE: KIT EXPERIMENTAL , TIPO: SEGÚN PLIEGO | F12: UNIDAD | G12: 4 | H12: 268000 | I12: =H12*G12 -> 1072000 | K12: 432 | L12: =I18 -> 320000
A13: 4 | B13: 4.3.5-9163.90 | C13: EQUIPO | D13: =LEFT(B13,5) -> 4.3.5 | E13: EQUIPOS DIDACTICOS TECNICOS; NOMBRE: KIT EXPERIMENTAL , TIPO: SEGÚN PLIEGO | F13: UNIDAD | G13: 40 | H13: 2020 | I13: =H13*G13 -> 80800 | K13: 437 | L13: =I23+I25+I26+I28 -> 2034000
A14: 5 | B14: 4.3.5-9163.64 | C14: EQUIPO | D14: =LEFT(B14,5) -> 4.3.5 | E14: EQUIPOS DIDACTICOS TECNICOS; NOMBRE: SISTEMA DE SONIDO, TIPO: ESTEREO | F14: UNIDAD | G14: 5 | H14: 65000 | I14: =H14*G14 -> 325000 | K14: 436 | L14: =I24 -> 1040000
A15: 6 | B15: 4.3.5-9138.2 | C15: EQUIPO | D15: =LEFT(B15,5) -> 4.3.5 | E15: PIZARRAS INTERACTIVAS; DIMENSION: 170 X 120 X 12 Cm, SOFTWARE: SMART BOARD, RESOLUCION: 6000 X 6000 | F15: UNIDAD | G15: 3 | H15: 1391961.2 | I15: =H15*G15 -> 4175883.6 | L15: =SUM(L11:L14) -> 17881944
E16: Costo total estimado:EQUIPOS | I16: =SUM(I10:I15) -> 9646943.6
A18: 7 | B18: 4.3.2-8803.25 | C18: TRANSPORTE Y DEPOSITO | D18: =LEFT(B18,5) -> 4.3.2 | E18: AERONAVES; TIPO: NO TRIPULADA, ENVERGADURA: 80 Cm, POTENCIA: SIN, VELOCIDAD MAXIMA: 50 Km/h | F18: UNIDAD | G18: 1 | H18: 320000 | I18: =H18*G18 -> 320000 | N18: =SUM(N10:N17) -> 0
A19: Costo total estimado: TRANSPORTE Y DEPOSITO | I19: =SUM(I18:I18) -> 320000
A21: 8 | B21: 4.3.5-8922.8 | C21: ARTICULOS DEL HOGAR | D21: =LEFT(B21,5) -> 4.3.5 | E21: JUEGOS DE SALON; TIPO: CONSOLA DE VIDEOJUEGOS | F21: UNIDAD | G21: 3 | H21: 255000 | I21: =H21*G21 -> 765000
A22: 9 | B22: 4.3.5-9163.64 | C22: EQUIPOS | D22: =LEFT(B22,5) -> 4.3.5 | E22: EQUIPOS DIDACTICOS TECNICOS; NOMBRE: SISTEMA DE SONIDO, TIPO: ESTEREO | F22: UNIDAD | G22: 4 | H22: 17000 | I22: =G22*H22 -> 68000
A23: 10 | B23: 4.3.7-46.128 | C23: EQUIPO DE OFICINA Y MUEBLES | D23: =LEFT(B23,5) -> 4.3.7 | E23: SILLONES EJECUTIVOS; TAPIZADO: ECOCUERO, ALTURA: REGULABLE, GIRATORIO: SI, MATERIAL: ACERO Y PLASTICO | F23: UNIDAD | G23: 6 | H23: 45000 | I23: =G23*H23 -> 270000
A24: 11 | B24: 4.3.6-9707.20 | C24: EQUIPOS | D24: =LEFT(B24,5) -> 4.3.6 | E24: IMPRESORA 3D; TIPO: FDM, DIMENSION: 220 X 220 X 260 MM, RESOLUCION: SEGÚN PLIEGO, PRECISION: SEGÚN PLIEGO, ESPESOR CAPA: SEGÚN PLIEGO | F24: UNIDAD | G24: 16 | H24: 65000 | I24: =G24*H24 -> 1040000
A25: 12 | B25: 4.3.7-45.517 | C25: EQUIPO DE OFICINA Y MUEBLES | D25: =LEFT(B25,5) -> 4.3.7 | E25: SILLAS; MATERIAL ESTRUCTURA: METAL, TAPIZADO: SIN, ALTURA: 77 Cm, GIRATORIA: NO | F25: UNIDAD | G25: 80 | H25: 14500 | I25: =G25*H25 -> 1160000
A26: 13 | B26: 4.3.7-1362.52 | C26: EQUIPO DE OFICINA Y MUEBLES | D26: =LEFT(B26,5) -> 4.3.7 | E26: MESAS CURVAS; CURVA: CIRCULAR, DIMENSION: DIAMETRO 120 Cm, MATERIAL: METAL, TERMINACION: FIBRA DE VIDRIO | F26: UNIDAD | G26: 16 | H26: 34500 | I26: =G26*H26 -> 552000
A27: 14 | B27: 4.3.5-241.105 | C27: ARTICULOS DEL HOGAR | D27: =LEFT(B27,5) -> 4.3.5 | E27: TELEVISORES; PANTALLA: SMART LED FULL HD 60 pulg, NORMA: MULTINORMA, CANTIDAD DE CANALES: INDEFINIDO, APAGADO: CON, VISION MULTICANAL: CON | F27: UNIDAD | G27: 4 | H27: 110000 | I27: =G27*H27 -> 440000
A28: 15 | B28: 4.3.7-56.26 | C28: EQUIPO DE OFICINA Y MUEBLES | D28: =LEFT(B28,5) -> 4.3.7 | E28: MESAS P/TELEVISORES; MATERIAL: AGLOMERADO, TAMAÑO: 110 X 110 X 60 Cm, PATAS: CON RUEDAS, ESTANTE: 2 | F28: UNIDAD | G28: 4 | H28: 13000 | I28: =G28*H28 -> 52000
A29: 16 | B29: 4.3.5-9163.90 | C29: EQUIPOS | D29: =LEFT(B29,5) -> 4.3.5 | E29: EQUIPOS DIDACTICOS TECNICOS; NOMBRE: KIT EXPERIMENTAL , TIPO: SEGÚN PLIEGO | F29: UNIDAD | G29: 80 | H29: 2600 | I29: =G29*H29 -> 208000
A30: 17 | B30: 4.3.5-9163.90 | C30: EQUIPOS | D30: =LEFT(B30,5) -> 4.3.5 | E30: EQUIPOS DIDACTICOS TECNICOS; NOMBRE: KIT EXPERIMENTAL , TIPO: SEGÚN PLIEGO | F30: UNIDAD | G30: 80 | H30: 20000 | I30: =G30*H30 -> 1600000 | K30: 2
A31: 18 | B31: 4.3.5-9163.76 | C31: EQUIPOS | D31: =LEFT(B31,5) -> 4.3.5 | E31: EQUIPOS DIDACTICOS TECNICOS; NOMBRE: ROBOT DIDACTICO, TIPO: 4 EJES | F31: UNIDAD | G31: 8 | H31: 16000 | I31: =G31*H31 -> 128000
A32: 19 | B32: 4.3.5-9163.90 | C32: EQUIPOS | D32: =LEFT(B32,5) -> 4.3.5 | E32: EQUIPOS DIDACTICOS TECNICOS; NOMBRE: KIT EXPERIMENTAL , TIPO: SEGÚN PLIEGO | F32: UNIDAD | G32: 8 | H32: 125000 | I32: =G32*H32 -> 1000000
A33: 20 | B33: 4.3.5-9163.90 | C33: EQUIPOS | D33: =LEFT(B33,5) -> 4.3.5 | E33: EQUIPOS DIDACTICOS TECNICOS; NOMBRE: KIT EXPERIMENTAL , TIPO: SEGÚN PLIEGO | F33: UNIDAD | G33: 8 | H33: 69000 | I33: =G33*H33 -> 552000
A34: 21 | B34: 4.3.5-9163.90 | C34: EQUIPOS | D34: =LEFT(B34,5) -> 4.3.5 | E34: EQUIPOS DIDACTICOS TECNICOS; NOMBRE: KIT EXPERIMENTAL , TIPO: SEGÚN PLIEGO | F34: UNIDAD | G34: 8 | H34: 10000 | I34: =G34*H34 -> 80000
A35: Costo total estimado: PROYECTO LABORATORIO DE ROBOTICA | I35: =SUM(I21:I34) -> 7915000
I37: =I16+I19+I35 -> 17881944
B39: Especificidades Item N° 1:
B40: Descripción técnica
C41: Lentes ajustables OLED de 1.600 x 1.400 píxeles. Debe contar con sensores externos de movimiento. Tasa de refresco de 60Hz. Dimensiones Aproximadas: 190x105x115mm. Peso: 468 gramos. Sonido integrado en correas de ajuste. Conexiones: micro-USB y minijack para auriculares externos. Sistema operativo basado en Android. Bluetooth integrado.
B42: Plazos y lugares de entrega
C43: El plazo de entrega no podrá ser superior a los quince (15) días hábiles a partir de la fecha de recepción de la respectiva Orden de Compra en el domicilio especial electrónico constituido, en virtud del método de contratación. La entrega de dichos bienes se realizará en el Ministerio de Ciencia e Innovación Tecnologica, sito en Avenida Belgrano N° 1494 - CAPE- Pabellón N° 26 San Fernando del Valle de Catamarca. Se presentará Remito que deberá cumplimentar lo dispuesto por la R.G. AFIP 1415/03, sin excepción.
B45: Calidad Minima esperada
B47: Mantenimiento:
C48: Cuarenta y Cinco (45) dias habiles
B49: Garantia
...

Sheet  NotaPedido
A1: NOTA DE PEDIDO | J1: N° | K1: 047/2021
A3: JURISDICCIÓN: | D3: 70 - MINISTERIO DE CIENCIA E INNOVACION TECNOLOGICA
A4: SAF: | D4: 20 - MINISTERIO DE CIENCIA E INNOVACION TECNOLOGICA
A5: UNIDAD EJECUTORA: | D5: SECRETARIA DE INNOVACION TECNOLOGICA
A6: DEPENDENCIA SOLICITANTE: | D6: DIRECCION PROVINCIAL DE GESTION ADMINISTRATIVA RECURSOS HUMANOS
A7: PERIODO UTILIZACIÓN: | D7: 4° TRIMESTRE 2021
A8: OBJETO: | D8: ADQUISICIÓN DE DIVERSOS EQUIPOS DESTINADO A LA SECRETARIA INNOVACIÓN TECNOLOGICA Y AL LABORATORIO DE ROBOTICA DEPENDIENTE DEL MINISTERIO DE CIENCIA E INNOVACIÓN TECNOLOGICA.-
A10: Ítem | B10: Codigo Item | C10: DESCRIPCIÓN | H10: Adjunta Detalle Técnico | I10: Unidad Medida | J10: Precio Unitario Estimado | K10: Cantidad Solicitada
A12: 1 | B12: 4.3.5-9163.80 | C12: EQUIPOS DIDACTICOS TECNICOS; NOMBRE: LENTES, TIPO: REALIDAD VIRTUAL | D12: EQUIPOS DIDACTICOS TECNICOS; NOMBRE: LENTES, TIPO: REALIDAD VIRTUAL | E12: EQUIPOS DIDACTICOS TECNICOS; NOMBRE: LENTES, TIPO: REALIDAD VIRTUAL | F12: EQUIPOS DIDACTICOS TECNICOS; NOMBRE: LENTES, TIPO: REALIDAD VIRTUAL | G12: EQUIPOS DIDACTICOS TECNICOS; NOMBRE: LENTES, TIPO: REALIDAD VIRTUAL | H12: SI | I12: UNIDAD | J12: ='Necesidades Trimestrales (2)'!H10 -> 185000 | K12: 5 | P12: =K12*J12 -> 925000
A13: 2 | B13: 4.3.5-9163.90 | C13: EQUIPOS DIDACTICOS TECNICOS; NOMBRE: KIT EXPERIMENTAL , TIPO: SEGÚN PLIEGO | D13: EQUIPOS DIDACTICOS TECNICOS; NOMBRE: KIT EXPERIMENTAL , TIPO: SEGÚN PLIEGO | E13: EQUIPOS DIDACTICOS TECNICOS; NOMBRE: KIT EXPERIMENTAL , TIPO: SEGÚN PLIEGO | F13: EQUIPOS DIDACTICOS TECNICOS; NOMBRE: KIT EXPERIMENTAL , TIPO: SEGÚN PLIEGO | G13: EQUIPOS DIDACTICOS TECNICOS; NOMBRE: KIT EXPERIMENTAL , TIPO: SEGÚN PLIEGO | H13: SI | I13: UNIDAD | J13: ='Necesidades Trimestrales (2)'!H11 -> 214326 | K13: 10 | P13: =K13*J13 -> 2143260
A14: 3 | B14: 4.3.5-9163.90 | C14: EQUIPOS DIDACTICOS TECNICOS; NOMBRE: KIT EXPERIMENTAL , TIPO: SEGÚN PLIEGO | D14: EQUIPOS DIDACTICOS TECNICOS; NOMBRE: KIT EXPERIMENTAL , TIPO: SEGÚN PLIEGO | E14: EQUIPOS DIDACTICOS TECNICOS; NOMBRE: KIT EXPERIMENTAL , TIPO: SEGÚN PLIEGO | F14: EQUIPOS DIDACTICOS TECNICOS; NOMBRE: KIT EXPERIMENTAL , TIPO: SEGÚN PLIEGO | G14: EQUIPOS DIDACTICOS TECNICOS; NOMBRE: KIT EXPERIMENTAL , TIPO: SEGÚN PLIEGO | H14: SI | I14: UNIDAD | J14: ='Necesidades Trimestrales (2)'!H12 -> 268000 | K14: 4 | P14: =K14*J14 -> 1072000
A15: 4 | B15: 4.3.5-9163.90 | C15: EQUIPOS DIDACTICOS TECNICOS; NOMBRE: KIT EXPERIMENTAL , TIPO: SEGÚN PLIEGO | D15: EQUIPOS DIDACTICOS TECNICOS; NOMBRE: KIT EXPERIMENTAL , TIPO: SEGÚN PLIEGO | E15: EQUIPOS DIDACTICOS TECNICOS; NOMBRE: KIT EXPERIMENTAL , TIPO: SEGÚN PLIEGO | F15: EQUIPOS DIDACTICOS TECNICOS; NOMBRE: KIT EXPERIMENTAL , TIPO: SEGÚN PLIEGO | G15: EQUIPOS DIDACTICOS TECNICOS; NOMBRE: KIT EXPERIMENTAL , TIPO: SEGÚN PLIEGO | H15: SI | I15: UNIDAD | J15: ='Necesidades Trimestrales (2)'!H13 -> 2020 | K15: 20 | P15: =K15*J15 -> 40400
A16: 5 | B16: 4.3.5-9163.64 | C16: EQUIPOS DIDACTICOS TECNICOS; NOMBRE: SISTEMA DE SONIDO, TIPO: ESTEREO | D16: EQUIPOS DIDACTICOS TECNICOS; NOMBRE: SISTEMA DE SONIDO, TIPO: ESTEREO | E16: EQUIPOS DIDACTICOS TECNICOS; NOMBRE: SISTEMA DE SONIDO, TIPO: ESTEREO | F16: EQUIPOS DIDACTICOS TECNICOS; NOMBRE: SISTEMA DE SONIDO, TIPO: ESTEREO | G16: EQUIPOS DIDACTICOS TECNICOS; NOMBRE: SISTEMA DE SONIDO, TIPO: ESTEREO | H16: SI | I16: UNIDAD | J16: ='Necesidades Trimestrales (2)'!H14 -> 65000 | K16: 3 | P16: =K16*J16 -> 195000
A17: 6 | B17: 4.3.5-9138.2 | C17: PIZARRAS INTERACTIVAS; DIMENSION: 170 X 120 X 12 Cm, SOFTWARE: SMART BOARD, RESOLUCION: 6000 X 6000 | D17: PIZARRAS INTERACTIVAS; DIMENSION: 170 X 120 X 12 Cm, SOFTWARE: SMART BOARD, RESOLUCION: 6000 X 6000 | E17: PIZARRAS INTERACTIVAS; DIMENSION: 170 X 120 X 12 Cm, SOFTWARE: SMART BOARD, RESOLUCION: 6000 X 6000 | F17: PIZARRAS INTERACTIVAS; DIMENSION: 170 X 120 X 12 Cm, SOFTWARE: SMART BOARD, RESOLUCION: 6000 X 6000 | G17: PIZARRAS INTERACTIVAS; DIMENSION: 170 X 120 X 12 Cm, SOFTWARE: SMART BOARD, RESOLUCION: 6000 X 6000 | H17: SI | I17: UNIDAD | J17: ='Necesidades Trimestrales (2)'!H15 -> 1391961.2 | K17: 1 | P17: =K17*J17 -> 1391961.2
A18: 7 | B18: 4.3.2-8803.25 | C18: AERONAVES; TIPO: NO TRIPULADA, ENVERGADURA: 80 Cm, POTENCIA: SIN, VELOCIDAD MAXIMA: 50 Km/h | D18: AERONAVES; TIPO: NO TRIPULADA, ENVERGADURA: 80 Cm, POTENCIA: SIN, VELOCIDAD MAXIMA: 50 Km/h | E18: AERONAVES; TIPO: NO TRIPULADA, ENVERGADURA: 80 Cm, POTENCIA: SIN, VELOCIDAD MAXIMA: 50 Km/h | F18: AERONAVES; TIPO: NO TRIPULADA, ENVERGADURA: 80 Cm, POTENCIA: SIN, VELOCIDAD MAXIMA: 50 Km/h | G18: AERONAVES; TIPO: NO TRIPULADA, ENVERGADURA: 80 Cm, POTENCIA: SIN, VELOCIDAD MAXIMA: 50 Km/h | H18: SI | I18: UNIDAD | J18: 320000 | K18: 1 | P18: =K18*J18 -> 320000
A19: 8 | B19: ='Necesidades Trimestrales (2)'!B21 -> 4.3.5-8922.8 | C19: ='Necesidades Trimestrales (2)'!E21 -> JUEGOS DE SALON; TIPO: CONSOLA DE VIDEOJUEGOS | H19: SI | I19: UNIDAD | J19: ='Necesidades Trimestrales (2)'!H21 -> 255000 | K19: ='Necesidades Trimestrales (2)'!G21 -> 3 | P19: =K19*J19 -> 765000
A20: 9 | B20: ='Necesidades Trimestrales (2)'!B22 -> 4.3.5-9163.64 | C20: ='Necesidades Trimestrales (2)'!E22 -> EQUIPOS DIDACTICOS TECNICOS; NOMBRE: SISTEMA DE SONIDO, TIPO: ESTEREO | H20: SI | I20: UNIDAD | J20: ='Necesidades Trimestrales (2)'!H22 -> 17000 | K20: ='Necesidades Trimestrales (2)'!G22 -> 4 | P20: =K20*J20 -> 68000
A21: 10 | B21: ='Necesidades Trimestrales (2)'!B23 -> 4.3.7-46.128 | C21: ='Necesidades Trimestrales (2)'!E23 -> SILLONES EJECUTIVOS; TAPIZADO: ECOCUERO, ALTURA: REGULABLE, GIRATORIO: SI, MATERIAL: ACERO Y PLASTICO | H21: SI | I21: UNIDAD | J21: ='Necesidades Trimestrales (2)'!H23 -> 45000 | K21: ='Necesidades Trimestrales (2)'!G23 -> 6 | P21: =K21*J21 -> 270000
A22: 11 | B22: ='Necesidades Trimestrales (2)'!B24 -> 4.3.6-9707.20 | C22: ='Necesidades Trimestrales (2)'!E24 -> IMPRESORA 3D; TIPO: FDM, DIMENSION: 220 X 220 X 260 MM, RESOLUCION: SEGÚN PLIEGO, PRECISION: SEGÚN PLIEGO, ESPESOR CAPA: SEGÚN PLIEGO | H22: SI | I22: UNIDAD | J22: ='Necesidades Trimestrales (2)'!H24 -> 65000 | K22: ='Necesidades Trimestrales (2)'!G24 -> 16 | P22: =K22*J22 -> 1040000 | Q22: 432 | R22: =P18 -> 320000
A23: 12 | B23: ='Necesidades Trimestrales (2)'!B25 -> 4.3.7-45.517 | C23: ='Necesidades Trimestrales (2)'!E25 -> SILLAS; MATERIAL ESTRUCTURA: METAL, TAPIZADO: SIN, ALTURA: 77 Cm, GIRATORIA: NO | H23: SI | I23: UNIDAD | J23: ='Necesidades Trimestrales (2)'!H25 -> 14500 | K23: ='Necesidades Trimestrales (2)'!G25 -> 80 | P23: =K23*J23 -> 1160000 | Q23: 435 | R23: =P12+P13+P14+P15+P16+P17+P19+P20+P25+P27+P28+P29+P30 -> 9016621.2
A24: 13 | B24: ='Necesidades Trimestrales (2)'!B26 -> 4.3.7-1362.52 | C24: ='Necesidades Trimestrales (2)'!E26 -> MESAS CURVAS; CURVA: CIRCULAR, DIMENSION: DIAMETRO 120 Cm, MATERIAL: METAL, TERMINACION: FIBRA DE VIDRIO | H24: SI | I24: UNIDAD | J24: ='Necesidades Trimestrales (2)'!H26 -> 34500 | K24: ='Necesidades Trimestrales (2)'!G26 -> 16 | P24: =K24*J24 -> 552000 | Q24: 436 | R24: =P22 -> 1040000
A25: 14 | B25: ='Necesidades Trimestrales (2)'!B27 -> 4.3.5-241.105 | C25: ='Necesidades Trimestrales (2)'!E27 -> TELEVISORES; PANTALLA: SMART LED FULL HD 60 pulg, NORMA: MULTINORMA, CANTIDAD DE CANALES: INDEFINIDO, APAGADO: CON, VISION MULTICANAL: CON | H25: SI | I25: UNIDAD | J25: ='Necesidades Trimestrales (2)'!H27 -> 110000 | K25: ='Necesidades Trimestrales (2)'!G27 -> 4 | P25: =K25*J25 -> 440000 | Q25: 437 | R25: =P21+P23+P24+P26 -> 2034000
A26: 15 | B26: ='Necesidades Trimestrales (2)'!B28 -> 4.3.7-56.26 | C26: ='Necesidades Trimestrales (2)'!E28 -> MESAS P/TELEVISORES; MATERIAL: AGLOMERADO, TAMAÑO: 110 X 110 X 60 Cm, PATAS: CON RUEDAS, ESTANTE: 2 | H26: SI | I26: UNIDAD | J26: ='Necesidades Trimestrales (2)'!H28 -> 13000 | K26: ='Necesidades Trimestrales (2)'!G28 -> 4 | P26: =K26*J26 -> 52000 | R26: =SUM(R22:R25) -> 12410621
A27: 16 | B27: ='Necesidades Trimestrales (2)'!B29 -> 4.3.5-9163.90 | C27: ='Necesidades Trimestrales (2)'!E29 -> EQUIPOS DIDACTICOS TECNICOS; NOMBRE: KIT EXPERIMENTAL , TIPO: SEGÚN PLIEGO | H27: SI | I27: UNIDAD | J27: ='Necesidades Trimestrales (2)'!H29 -> 2600 | K27: 80 | P27: =K27*J27 -> 208000
A28: 17 | B28: ='Necesidades Trimestrales (2)'!B30 -> 4.3.5-9163.90 | C28: ='Necesidades Trimestrales (2)'!E30 -> EQUIPOS DIDACTICOS TECNICOS; NOMBRE: KIT EXPERIMENTAL , TIPO: SEGÚN PLIEGO | H28: SI | I28: UNIDAD | J28: ='Necesidades Trimestrales (2)'!H30 -> 20000 | K28: 78 | P28: =K28*J28 -> 1560000
A29: 18 | B29: ='Necesidades Trimestrales (2)'!B31 -> 4.3.5-9163.76 | C29: ='Necesidades Trimestrales (2)'!E31 -> EQUIPOS DIDACTICOS TECNICOS; NOMBRE: ROBOT DIDACTICO, TIPO: 4 EJES | H29: SI | I29: UNIDAD | J29: ='Necesidades Trimestrales (2)'!H31 -> 16000 | K29: 8 | P29: =K29*J29 -> 128000
A30: 19 | B30: ='Necesidades Trimestrales (2)'!B34 -> 4.3.5-9163.90 | C30: ='Necesidades Trimestrales (2)'!E34 -> EQUIPOS DIDACTICOS TECNICOS; NOMBRE: KIT EXPERIMENTAL , TIPO: SEGÚN PLIEGO | H30: SI | I30: UNIDAD | J30: ='Necesidades Trimestrales (2)'!H34 -> 10000 | K30: 8 | P30: =K30*J30 -> 80000
A31: Costo total estimado: PESOS DOCE MILLONES CUATROCIENTOS MIL SEISCIENTOS VEINTIUNO CON 21/100.- | J31: =SUMPRODUCT(J12:J30,K12:K30) -> 12410621

Sheet Autor Gastar
A1: EJERCICIO: | D1: 2021 | P1: AUTORIZACION PARA GASTAR
A4: JURISDICCIÓN: | G4: =' NotaPedido'!D3 -> 70 - MINISTERIO DE CIENCIA E INNOVACION TECNOLOGICA
A5: SAF: | G5: =' NotaPedido'!D4 -> 20 - MINISTERIO DE CIENCIA E INNOVACION TECNOLOGICA
A6: UNIDAD EJECUTORA: | G6: =' NotaPedido'!D5 -> SECRETARIA DE INNOVACION TECNOLOGICA
A7: DEPENDENCIA SOLICITANTE: | G7: =' NotaPedido'!D6 -> DIRECCION PROVINCIAL DE GESTION ADMINISTRATIVA RECURSOS HUMANOS
A8: AUTORIZACIÓN:
A9: Señor Jefe de Servicio Administrativo Financiero:
A10: ="Autorizo la realización de los trámites correspondientes, a fin de proveer a este Organismo los bienes y/o servicios que se detallan en Nota de Pedido N° " & ' NotaPedido'!K1&", afectando la erogación resultante a los créditos presupuestarios aprobados a favor de esta Unidad Ejecutora, conforme al siguiente detalle:" -> Autorizo la realización de los trámites correspondientes, a fin de proveer a este Organismo los bienes y/o servicios que se detallan en Nota de Pedido N° 047/2021, afectando la erogación resultante a los créditos presupuestarios aprobados a favor de esta Unidad Ejecutora, conforme al siguiente detalle:
A12: IMPUTACIÓN PRESUPUESTARIA
A13: CÓDIGO | O13: DENOMINACIÓN DE LA PARTIDA PRESUPUESTARIA | Q13: IMPORTE
A14: PR | B14: SB | C14: PY | D14: AC | E14: OB | F14: UG | G14: FIN | H14: FUN | I14: I | J14: P | K14: P | L14: SubP | M14: M | N14: FF
A15: 3 | B15: 0 | C15: 0 | D15: 1 | E15: 0 | F15: 4901 | G15: 3 | H15: 5 | I15: 4 | J15: 3 | K15: 2 | L15: 0 | M15: 1 | N15: 1.1 | O15: Equipo de Transporte, Tracción y Elevación | Q15: 320000
A16: 3 | B16: 0 | C16: 0 | D16: 1 | E16: 0 | F16: 4901 | G16: 3 | H16: 5 | I16: 4 | J16: 3 | K16: 5 | L16: 0 | M16: 1 | N16: 1.1 | O16: Equipo Educacional y Recreativo | Q16: 9016621.2
A17: 3 | B17: 0 | C17: 0 | D17: 1 | E17: 0 | F17: 4901 | G17: 3 | H17: 5 | I17: 4 | J17: 3 | K17: 6 | L17: 0 | M17: 1 | N17: 1.1 | O17: Equipos para Computación | Q17: 1040000
A18: 3 | B18: 0 | C18: 0 | D18: 1 | E18: 0 | F18: 4901 | G18: 3 | H18: 5 | I18: 4 | J18: 3 | K18: 7 | L18: 0 | M18: 1 | N18: 1.1 | O18: Equipos de Oficina y Muebles | Q18: 2034000
A22: PESOS: DOCE MILLONES CUATROCIENTOS MIL SEISCIENTOS VEINTIUNO CON 21/100.- | Q22: =SUM(Q15:Q21) -> 12410621
A24: JUSTIFICACIÓN:
A25: ADQUISICIÓN DE DIVERSOS EQUIPOS DESTINADO A LA SECRETARIA INNOVACIÓN TECNOLOGICA Y AL LABORATORIO DE ROBOTICA DEPENDIENTE DEL MINISTERIO DE CIENCIA E INNOVACIÓN TECNOLOGICA.-

Sheet Nota de Pedido
A1: NOTA DE PEDIDO | J1: N° | K1: 048/2021
A3: JURISDICCIÓN: | D3: 70 - MINISTERIO DE CIENCIA E INNOVACION TECNOLOGICA
A4: SAF: | D4: 20 - MINISTERIO DE CIENCIA E INNOVACION TECNOLOGICA
A5: UNIDAD EJECUTORA: | D5: SECRETARIA DE CIENCIA Y TECNOLOGIA
A6: DEPENDENCIA SOLICITANTE: | D6: DIRECCION PROVINCIAL DE GESTION ADMINISTRATIVA RECURSOS HUMANOS
A7: PERIODO UTILIZACIÓN: | D7: 4° TRIMESTRE 2021
A8: OBJETO: | D8: ADQUISICIÓN DE DIVERSOS EQUIPOS DESTINADO A LA SECRETARIA DE CIENCIA Y TECNNOLOGIA Y AL LABORATORIO DE ROBOTICA DEPENDIENTE DEL MINISTERIO DE CIENCIA E INNOVACIÓN TECNOLOGICA.-
A10: Ítem | B10: Codigo Item | C10: DESCRIPCIÓN | H10: Adjunta Detalle Técnico | I10: Unidad Medida | J10: Precio Unitario Estimado | K10: Cantidad Solicitada
A12: 1 | B12: 4.3.5-9163.80 | C12: EQUIPOS DIDACTICOS TECNICOS; NOMBRE: LENTES, TIPO: REALIDAD VIRTUAL | D12: EQUIPOS DIDACTICOS TECNICOS; NOMBRE: LENTES, TIPO: REALIDAD VIRTUAL | E12: EQUIPOS DIDACTICOS TECNICOS; NOMBRE: LENTES, TIPO: REALIDAD VIRTUAL | F12: EQUIPOS DIDACTICOS TECNICOS; NOMBRE: LENTES, TIPO: REALIDAD VIRTUAL | G12: EQUIPOS DIDACTICOS TECNICOS; NOMBRE: LENTES, TIPO: REALIDAD VIRTUAL | H12: SI | I12: UNIDAD | J12: 185000 | K12: 5
A13: 2 | B13: 4.3.5-9163.90 | C13: EQUIPOS DIDACTICOS TECNICOS; NOMBRE: KIT EXPERIMENTAL , TIPO: SEGÚN PLIEGO | D13: EQUIPOS DIDACTICOS TECNICOS; NOMBRE: KIT EXPERIMENTAL , TIPO: SEGÚN PLIEGO | E13: EQUIPOS DIDACTICOS TECNICOS; NOMBRE: KIT EXPERIMENTAL , TIPO: SEGÚN PLIEGO | F13: EQUIPOS DIDACTICOS TECNICOS; NOMBRE: KIT EXPERIMENTAL , TIPO: SEGÚN PLIEGO | G13: EQUIPOS DIDACTICOS TECNICOS; NOMBRE: KIT EXPERIMENTAL , TIPO: SEGÚN PLIEGO | H13: SI | I13: UNIDAD | J13: 2020 | K13: 20
A14: 3 | B14: 4.3.5-9163.64 | C14: EQUIPOS DIDACTICOS TECNICOS; NOMBRE: SISTEMA DE SONIDO, TIPO: ESTEREO | D14: EQUIPOS DIDACTICOS TECNICOS; NOMBRE: SISTEMA DE SONIDO, TIPO: ESTEREO | E14: EQUIPOS DIDACTICOS TECNICOS; NOMBRE: SISTEMA DE SONIDO, TIPO: ESTEREO | F14: EQUIPOS DIDACTICOS TECNICOS; NOMBRE: SISTEMA DE SONIDO, TIPO: ESTEREO | G14: EQUIPOS DIDACTICOS TECNICOS; NOMBRE: SISTEMA DE SONIDO, TIPO: ESTEREO | H14: SI | I14: UNIDAD | J14: 65000 | K14: 2
A15: 4 | B15: 4.3.5-9138.2 | C15: PIZARRAS INTERACTIVAS; DIMENSION: 170 X 120 X 12 Cm, SOFTWARE: SMART BOARD, RESOLUCION: 6000 X 6000 | D15: PIZARRAS INTERACTIVAS; DIMENSION: 170 X 120 X 12 Cm, SOFTWARE: SMART BOARD, RESOLUCION: 6000 X 6000 | E15: PIZARRAS INTERACTIVAS; DIMENSION: 170 X 120 X 12 Cm, SOFTWARE: SMART BOARD, RESOLUCION: 6000 X 6000 | F15: PIZARRAS INTERACTIVAS; DIMENSION: 170 X 120 X 12 Cm, SOFTWARE: SMART BOARD, RESOLUCION: 6000 X 6000 | G15: PIZARRAS INTERACTIVAS; DIMENSION: 170 X 120 X 12 Cm, SOFTWARE: SMART BOARD, RESOLUCION: 6000 X 6000 | H15: SI | I15: UNIDAD | J15: 1391961.2 | K15: 2
A16: 5 | B16: 4.3.5-9163.90 | C16: EQUIPOS DIDACTICOS TECNICOS; NOMBRE: KIT EXPERIMENTAL , TIPO: SEGÚN PLIEGO | H16: SI | I16: UNIDAD | J16: 20000 | K16: 2
A17: 6 | B17: 4.3.5-9163.90 | C17: EQUIPOS DIDACTICOS TECNICOS; NOMBRE: KIT EXPERIMENTAL , TIPO: SEGÚN PLIEGO | H17: SI | I17: UNIDAD | J17: 125000 | K17: 8
A18: 7 | B18: 4.3.5-9163.90 | C18: EQUIPOS DIDACTICOS TECNICOS; NOMBRE: KIT EXPERIMENTAL , TIPO: SEGÚN PLIEGO | H18: SI | I18: UNIDAD | J18: 69000 | K18: 8
A19: Costo total estimado: PESOS CINCO MILLONES CUATROCIENTOS SETENTA Y UN MIL TRESCIENTOS VEINTIDOS CON 42/100.- | J19: =SUMPRODUCT(J12:J18,K12:K18) -> 5471322.4

Sheet Autor Gastar 
A1: EJERCICIO: | D1: 2021 | P1: AUTORIZACION PARA GASTAR
A4: JURISDICCIÓN: | G4: =' NotaPedido'!D3 -> 70 - MINISTERIO DE CIENCIA E INNOVACION TECNOLOGICA
A5: SAF: | G5: =' NotaPedido'!D4 -> 20 - MINISTERIO DE CIENCIA E INNOVACION TECNOLOGICA
A6: UNIDAD EJECUTORA: | G6: SECRETARIA DE CIENCIA Y TECNOLOGIA
A7: DEPENDENCIA SOLICITANTE: | G7: =' NotaPedido'!D6 -> DIRECCION PROVINCIAL DE GESTION ADMINISTRATIVA RECURSOS HUMANOS
A8: AUTORIZACIÓN:
A9: Señor Jefe de Servicio Administrativo Financiero:
A10: Autorizo la realización de los trámites correspondientes, a fin de proveer a este Organismo los bienes y/o servicios que se detallan en Nota de Pedido N° 048/2021, afectando la erogación resultante a los créditos presupuestarios aprobados a favor de esta Unidad Ejecutora, conforme al siguiente detalle:
A12: IMPUTACIÓN PRESUPUESTARIA
A13: CÓDIGO | O13: DENOMINACIÓN DE LA PARTIDA PRESUPUESTARIA | Q13: IMPORTE
A14: PR | B14: SB | C14: PY | D14: AC | E14: OB | F14: UG | G14: FIN | H14: FUN | I14: I | J14: P | K14: P | L14: SubP | M14: M | N14: FF
A15: 2 | B15: 0 | C15: 0 | D15: 1 | E15: 0 | F15: 4901 | G15: 3 | H15: 5 | I15: 4 | J15: 3 | K15: 5 | L15: 0 | M15: 1 | N15: 1.1 | O15: Equipo Educacional y Recreativo | Q15: 5471322.4
A20: PESOS: CINCO MILLONES CUATROCIENTOS SETENTA Y UN MIL TRESCIENTOS VEINTIDOS CON 42/100.- | Q20: =SUM(Q15:Q19) -> 5471322.4
A22: JUSTIFICACIÓN:
A23: ADQUISICIÓN DE DIVERSOS EQUIPOS DESTINADO A LA SECRETARIA SECRETARIA DE CIENCIA Y TECNOLOGIA DEPENDIENTE DEL MINISTERIO DE CIENCIA E INNOVACIÓN TECNOLOGICA.-
