Workbook

Sheet Necesidades Trimestrales
B2: Pedido de Necesidades Trimestrales
A4: JURISDICCION: | C4: 040 - Ministerio de Salud
A5: SAF N°: | C5: 28-Maternidad Provincial 25 de Mayo
A6: EJERCICIO: | C6: 2022
A7: TRIMESTRE: | C7: 3
A9: ID | B9: CODIGO ITEM | C9: RUBRO DE COMPRA | D9: I.P.P. | E9: DESCRIPCION | F9: UNIDAD DE MEDIDA | G9: CANTIDAD | H9: PRECIO UNITARIO ESTIMADO | I9: IMPORTE TOTAL ESTIMADO
A10: 1 | B10: 2.9.5-3020.3 | C10: PROD. MEDICO/FARMACEUTICOS/LAB | D10: 295 | E10: BOLSAS P/COLOSTOMIA; TIPO: DESCARTABLE ADHESIVA P/ ADULTOS, DIAMETRO DE ARO: SIN ARO | F10: UNIDAD | G10: 100 | H10: 225 | I10: =+G10*H10 -> 22500 | J10: 2.9.5-3020.3 | K10: BOLSAS P/COLOSTOMIA; TIPO: DESCARTABLE ADHESIVA P/ ADULTOS, DIAMETRO DE ARO: SIN ARO | L10: UNIDAD | M10: 225 | N10: 1
A11: 2 | B11: 2.9.5-3020.8 | C11: PROD. MEDICO/FARMACEUTICOS/LAB | D11: 295 | E11: BOLSAS P/COLOSTOMIA; TIPO: DESCARTABLE ADHESIVA PEDIATRICA, DIAMETRO: REGULABLE | F11: UNIDAD | G11: 30 | H11: 415 | I11: =+G11*H11 -> 12450 | J11: 2.9.5-3020.8 | K11: BOLSAS P/COLOSTOMIA; TIPO: DESCARTABLE ADHESIVA PEDIATRICA, DIAMETRO: REGULABLE | L11: UNIDAD | M11: 415 | N11: 2
A12: 3 | B12: 2.9.5-4198.93 | C12: PROD. MEDICO/FARMACEUTICOS/LAB | D12: 295 | E12: ELEMENTOS DESC. P/CIRUGIAS; TIPO: CAMPO QUIRURGICO 60 X 45 Cm, PRESENTACION: UNIDAD | F12: UNIDAD | G12: 10 | H12: 870 | I12: =+G12*H12 -> 8700 | J12: 2.9.5-4198.93 | K12: ELEMENTOS DESC. P/CIRUGIAS; TIPO: CAMPO QUIRURGICO 60 X 45 Cm, PRESENTACION: UNIDAD | L12: UNIDAD | M12: 870 | N12: 3
A13: 4 | B13: 2.9.5-2161.473 | C13: PROD. MEDICO/FARMACEUTICOS/LAB | D13: 295 | E13: CATETERES/SONDAS; NUMERO: 7 FR X 26 CM, TIPO: DOBLE J COOK | F13: UNIDAD | G13: 12 | H13: 13500 | I13: =+G13*H13 -> 162000 | J13: 2.9.5-2161.473 | K13: CATETERES/SONDAS; NUMERO: 7 FR X 26 CM, TIPO: DOBLE J COOK | L13: UNIDAD | M13: 13500 | N13: 4
A14: 5 | B14: 2.9.5-2161.587 | C14: PROD. MEDICO/FARMACEUTICOS/LAB | D14: 295 | E14: CATETERES/SONDAS; NUMERO: 2,0 FR X 15 CM, TIPO: EPICUTANEO PEDIATRICO | F14: UNIDAD | G14: 60 | H14: 9646 | I14: =+G14*H14 -> 578760 | J14: 2.9.5-2161.587 | K14: CATETERES/SONDAS; NUMERO: 2,0 FR X 15 CM, TIPO: EPICUTANEO PEDIATRICO | L14: UNIDAD | M14: 9646 | N14: 5
A15: 6 | B15: 2.9.5-2161.588 | C15: PROD. MEDICO/FARMACEUTICOS/LAB | D15: 295 | E15: CATETERES/SONDAS; NUMERO: 2,0 FR X 30 CM, TIPO: EPICUTANEO PEDIATRICO | F15: UNIDAD | G15: 60 | H15: 10500 | I15: =+G15*H15 -> 630000 | J15: 2.9.5-2161.588 | K15: CATETERES/SONDAS; NUMERO: 2,0 FR X 30 CM, TIPO: EPICUTANEO PEDIATRICO | L15: UNIDAD | M15: 10500 | N15: 6
A16: 7 | B16: 2.9.5-2161.589 | C16: PROD. MEDICO/FARMACEUTICOS/LAB | D16: 295 | E16: CATETERES/SONDAS; NUMERO: 1,8 FR X 15 CM , TIPO: EPICUTANEO PREMATURO | F16: UNIDAD | G16: 60 | H16: 9646 | I16: =+G16*H16 -> 578760 | J16: 2.9.5-2161.589 | K16: CATETERES/SONDAS; NUMERO: 1,8 FR X 15 CM , TIPO: EPICUTANEO PREMATURO | L16: UNIDAD | M16: 9646 | N16: 7
A17: 8 | B17: 2.9.5-2161.391 | C17: PROD. MEDICO/FARMACEUTICOS/LAB | D17: 295 | E17: CATETERES/SONDAS; NUMERO: 1,8 FR X 30 CM , TIPO: EPICUTANEO PREMATURO | F17: UNIDAD | G17: 60 | H17: 10500 | I17: =+G17*H17 -> 630000 | J17: 2.9.5-2161.391 | K17: CATETERES/SONDAS; NUMERO: 1,8 FR X 30 CM , TIPO: EPICUTANEO PREMATURO | L17: UNIDAD | M17: 10500 | N17: 8
A18: 9 | B18: 2.9.5-2161.594 | C18: PROD. MEDICO/FARMACEUTICOS/LAB | D18: 295 | E18: CATETERES/SONDAS NUMERO 2 FR X 30 CM TIPO PICC PERCUTANEO CON INTRODUCTOR PELABLE | F18: UNIDAD | G18: 30 | H18: 19315 | I18: =+G18*H18 -> 579450 | J18: 2.9.5-2161.594 | K18: CATETERES/SONDAS NUMERO 2 FR X 30 CM TIPO PICC PERCUTANEO CON INTRODUCTOR PELABLE | L18: UNIDAD | M18: 19315 | N18: 9
A19: 10 | B19: 2.9.5-2161.595 | C19: PROD. MEDICO/FARMACEUTICOS/LAB | D19: 295 | E19: CATETERES/SONDAS NUMERO 3 FR X 50 CM TIPO PICC PERCUTANEO CON INTRODUCTOR PELABLE | F19: UNIDAD | G19: 10 | H19: 16600 | I19: =+G19*H19 -> 166000 | J19: 2.9.5-2161.595 | K19: CATETERES/SONDAS NUMERO 3 FR X 50 CM TIPO PICC PERCUTANEO CON INTRODUCTOR PELABLE | L19: UNIDAD | M19: 16600 | N19: 10
A20: 11 | B20: 2.9.5-2161.567 | C20: PROD. MEDICO/FARMACEUTICOS/LAB | D20: 295 | E20: CATETERES/SONDAS; NUMERO: 4 FR X 65 CM, TIPO: PICC PERCUTANEO CON INTRODUCTOR PELABLE | F20: UNIDAD | G20: 10 | H20: 16600 | I20: =+G20*H20 -> 166000 | J20: 2.9.5-2161.567 | K20: CATETERES/SONDAS; NUMERO: 4 FR X 65 CM, TIPO: PICC PERCUTANEO CON INTRODUCTOR PELABLE | L20: UNIDAD | M20: 16600 | N20: 11
A21: 12 | B21: 2.9.5-2161.83 | C21: PROD. MEDICO/FARMACEUTICOS/LAB | D21: 295 | E21: CATETERES/SONDAS; NUMERO: 2,5, TIPO: UMBILICAL ARTERIAL, PRESENTACION: UNIDAD | F21: UNIDAD | G21: 100 | H21: 1950 | I21: =+G21*H21 -> 195000 | J21: 2.9.5-2161.83 | K21: CATETERES/SONDAS; NUMERO: 2,5, TIPO: UMBILICAL ARTERIAL, PRESENTACION: UNIDAD | L21: UNIDAD | M21: 1950 | N21: 12
... A29: 20 | B29: 2.9.5-6700.2 | C29: PROD. MEDICO/FARMACEUTICOS/LAB | D29: 295 | E29: TROCAR DE PUNCION; USO: PUNCION TORAXICO, TIPO: N°8, CAMISA: SIN | F29: UNIDAD | G29: 30 | H29: 1350 | I29: =+G29*H29 -> 40500 | J29: 2.9.5-6700.2 | K29: TROCAR DE PUNCION; USO: PUNCION TORAXICO, TIPO: N°8, CAMISA: SIN | L29: UNIDAD | M29: 1350 | N29: 20
B32: Especificidades: ITEMS 2-
C33: TIPO COLOPLAST -BOLSA PARA OSTOMIA-MODELO ALTERNA 8002
B35: Lugar de Entrega: SERVICIO DE FARMACIA- DE 08:00 A 13:00HS., DEBIENDO CORRER LOS GASTOS DE FLETES, ACARREO, CARGA, DESCARGA Y SEGURO A CARGO DEL ADJUDICATARIO. HERNAN DE PÉDRAZA 1650- SAN FERNANDO DEL VALLE DE CATAMARCA
B37: Plazo de entrega: | E37: 10(diez) dias habiles
B39: Calidad Minima esperada:
B40: Mantenimiento: | E40: 30(treinta) dias habiles
B45: Especificidades: ITEMS 3
E46: TIPO STERIDRAPE 1050 | G46: TIPO STERIDRAPE 1050
B48: Lugar de Entrega: SERVICIO DE FARMACIA- DE 08:00 A 13:00HS., DEBIENDO CORRER LOS GASTOS DE FLETES, ACARREO, CARGA, DESCARGA Y SEGURO A CARGO DEL ADJUDICATARIO. HERNAN DE PÉDRAZA 1650- SAN FERNANDO DEL VALLE DE CATAMARCA
B53: Plazo de entrega: 10(diez) dias habiles
B55: Calidad Minima esperada:
B56: Mantenimiento: 30(treinta) dias habiles
B58: Especificidades:ITEMS 4-
E59: Tipo COOK | G59: tipo COOK
B60: Lugar de Entrega: SERVICIO DE FARMACIA- DE 08:00 A 13:00HS., DEBIENDO CORRER LOS GASTOS DE FLETES, ACARREO, CARGA, DESCARGA Y SEGURO A CARGO DEL ADJUDICATARIO. HERNAN DE PÉDRAZA 1650- SAN FERNANDO DEL VALLE DE CATAMARCA
B63: Plazo de entrega: 10(diez) dias habiles
B65: Calidad Minima esperada:
B66: Mantenimiento: 30(treinta) dias habiles
B68: Especificidades: ITEMS DEL 5 AL 8 - DEL 12 AL 17 | G68: TIPO SILMAG
E69: TIPO SILMAG
B71: Lugar de Entrega: SERVICIO DE FARMACIA- DE 08:00 A 13:00HS., DEBIENDO CORRER LOS GASTOS DE FLETES, ACARREO, CARGA, DESCARGA Y SEGURO A CARGO DEL ADJUDICATARIO. HERNAN DE PÉDRAZA 1650- SAN FERNANDO DEL VALLE DE CATAMARCA
...

Sheet  NotaPedido
A1: NOTA DE PEDIDO | J1: N° | K1: xxx/2022
A3: JURISDICCIÓN: | D3: ='Necesidades Trimestrales'!C4 -> 040 - Ministerio de Salud
A4: SAF: | D4: ='Necesidades Trimestrales'!C5 -> 28-Maternidad Provincial 25 de Mayo
A5: UNIDAD EJECUTORA: | D5: 169-Direccion Asistencial
A6: DEPENDENCIA SOLICITANTE: | D6: Servicio de Farmacia
A7: PERIODO UTILIZACIÓN: | D7: Semestral
A8: OBJETO: | D8: Adquisición de Descartable Complejo
A10: Ítem | B10: Codigo Item | C10: DESCRIPCIÓN | H10: Adjunta Detalle Técnico | I10: Unidad Medida | J10: Precio Unitario Estimado | K10: Cantidad Solicitada
A12: 1 | B12: =+'Necesidades Trimestrales'!B10 -> 2.9.5-3020.3 | C12: =+'Necesidades Trimestrales'!E10 -> BOLSAS P/COLOSTOMIA; TIPO: DESCARTABLE ADHESIVA P/ ADULTOS, DIAMETRO DE ARO: SIN ARO | H12: NO | I12: =+'Necesidades Trimestrales'!F10 -> UNIDAD | J12: =+'Necesidades Trimestrales'!H10 -> 225 | K12: =+'Necesidades Trimestrales'!G10 -> 100 | L12: BOLSAS P/COLOSTOMIA; TIPO: DESCARTABLE ADHESIVA P/ ADULTOS, DIAMETRO DE ARO: SIN ARO
A13: 2 | B13: =+'Necesidades Trimestrales'!B11 -> 2.9.5-3020.8 | C13: =+'Necesidades Trimestrales'!E11 -> BOLSAS P/COLOSTOMIA; TIPO: DESCARTABLE ADHESIVA PEDIATRICA, DIAMETRO: REGULABLE | H13: SI | I13: =+'Necesidades Trimestrales'!F11 -> UNIDAD | J13: =+'Necesidades Trimestrales'!H11 -> 415 | K13: =+'Necesidades Trimestrales'!G11 -> 30 | L13: BOLSAS P/COLOSTOMIA; TIPO: DESCARTABLE ADHESIVA PEDIATRICA, DIAMETRO: REGULABLE
A14: 3 | B14: =+'Necesidades Trimestrales'!B12 -> 2.9.5-4198.93 | C14: =+'Necesidades Trimestrales'!E12 -> ELEMENTOS DESC. P/CIRUGIAS; TIPO: CAMPO QUIRURGICO 60 X 45 Cm, PRESENTACION: UNIDAD | H14: SI | I14: =+'Necesidades Trimestrales'!F12 -> UNIDAD | J14: =+'Necesidades Trimestrales'!H12 -> 870 | K14: =+'Necesidades Trimestrales'!G12 -> 10 | L14: ELEMENTOS DESC. P/CIRUGIAS; TIPO: CAMPO QUIRURGICO 60 X 45 Cm, PRESENTACION: UNIDAD
A15: 4 | B15: =+'Necesidades Trimestrales'!B13 -> 2.9.5-2161.473 | C15: =+'Necesidades Trimestrales'!E13 -> CATETERES/SONDAS; NUMERO: 7 FR X 26 CM, TIPO: DOBLE J COOK | H15: SI | I15: =+'Necesidades Trimestrales'!F13 -> UNIDAD | J15: =+'Necesidades Trimestrales'!H13 -> 13500 | K15: =+'Necesidades Trimestrales'!G13 -> 12 | L15: CATETERES/SONDAS; NUMERO: 7 FR X 26 CM, TIPO: DOBLE J COOK
A16: 5 | B16: =+'Necesidades Trimestrales'!B14 -> 2.9.5-2161.587 | C16: =+'Necesidades Trimestrales'!E14 -> CATETERES/SONDAS; NUMERO: 2,0 FR X 15 CM, TIPO: EPICUTANEO PEDIATRICO | H16: SI | I16: =+'Necesidades Trimestrales'!F14 -> UNIDAD | J16: =+'Necesidades Trimestrales'!H14 -> 9646 | K16: =+'Necesidades Trimestrales'!G14 -> 60 | L16: CATETERES/SONDAS; NUMERO: 2,0 FR X 15 CM, TIPO: EPICUTANEO PEDIATRICO
A17: 6 | B17: =+'Necesidades Trimestrales'!B15 -> 2.9.5-2161.588 | C17: =+'Necesidades Trimestrales'!E15 -> CATETERES/SONDAS; NUMERO: 2,0 FR X 30 CM, TIPO: EPICUTANEO PEDIATRICO | H17: SI | I17: =+'Necesidades Trimestrales'!F15 -> UNIDAD | J17: =+'Necesidades Trimestrales'!H15 -> 10500 | K17: =+'Necesidades Trimestrales'!G15 -> 60 | L17: CATETERES/SONDAS; NUMERO: 2,0 FR X 30 CM, TIPO: EPICUTANEO PEDIATRICO
A18: 7 | B18: =+'Necesidades Trimestrales'!B16 -> 2.9.5-2161.589 | C18: =+'Necesidades Trimestrales'!E16 -> CATETERES/SONDAS; NUMERO: 1,8 FR X 15 CM , TIPO: EPICUTANEO PREMATURO | H18: SI | I18: =+'Necesidades Trimestrales'!F16 -> UNIDAD | J18: =+'Necesidades Trimestrales'!H16 -> 9646 | K18: =+'Necesidades Trimestrales'!G16 -> 60 | L18: CATETERES/SONDAS; NUMERO: 1,8 FR X 15 CM , TIPO: EPICUTANEO PREMATURO
A19: 8 | B19: =+'Necesidades Trimestrales'!B17 -> 2.9.5-2161.391 | C19: =+'Necesidades Trimestrales'!E17 -> CATETERES/SONDAS; NUMERO: 1,8 FR X 30 CM , TIPO: EPICUTANEO PREMATURO | H19: SI | I19: =+'Necesidades Trimestrales'!F17 -> UNIDAD | J19: =+'Necesidades Trimestrales'!H17 -> 10500 | K19: =+'Necesidades Trimestrales'!G17 -> 60 | L19: CATETERES/SONDAS; NUMERO: 1,8 FR X 30 CM , TIPO: EPICUTANEO PREMATURO
A20: 9 | B20: =+'Necesidades Trimestrales'!B18 -> 2.9.5-2161.594 | C20: =+'Necesidades Trimestrales'!E18 -> CATETERES/SONDAS NUMERO 2 FR X 30 CM TIPO PICC PERCUTANEO CON INTRODUCTOR PELABLE | H20: NO | I20: =+'Necesidades Trimestrales'!F18 -> UNIDAD | J20: =+'Necesidades Trimestrales'!H18 -> 19315 | K20: =+'Necesidades Trimestrales'!G18 -> 30 | L20: CATETERES/SONDAS NUMERO 2 FR X 30 CM TIPO PICC PERCUTANEO CON INTRODUCTOR PELABLE
A21: 10 | B21: =+'Necesidades Trimestrales'!B19 -> 2.9.5-2161.595 | C21: =+'Necesidades Trimestrales'!E19 -> CATETERES/SONDAS NUMERO 3 FR X 50 CM TIPO PICC PERCUTANEO CON INTRODUCTOR PELABLE | H21: NO | I21: =+'Necesidades Trimestrales'!F19 -> UNIDAD | J21: =+'Necesidades Trimestrales'!H19 -> 16600 | K21: =+'Necesidades Trimestrales'!G19 -> 10 | L21: CATETERES/SONDAS NUMERO 3 FR X 50 CM TIPO PICC PERCUTANEO CON INTRODUCTOR PELABLE
A22: 11 | B22: =+'Necesidades Trimestrales'!B20 -> 2.9.5-2161.567 | C22: =+'Necesidades Trimestrales'!E20 -> CATETERES/SONDAS; NUMERO: 4 FR X 65 CM, TIPO: PICC PERCUTANEO CON INTRODUCTOR PELABLE | H22: NO | I22: =+'Necesidades Trimestrales'!F20 -> UNIDAD | J22: =+'Necesidades Trimestrales'!H20 -> 16600 | K22: =+'Necesidades Trimestrales'!G20 -> 10 | L22: CATETERES/SONDAS; NUMERO: 4 FR X 65 CM, TIPO: PICC PERCUTANEO CON INTRODUCTOR PELABLE
A23: 12 | B23: =+'Necesidades Trimestrales'!B21 -> 2.9.5-2161.83 | C23: =+'Necesidades Trimestrales'!E21 -> CATETERES/SONDAS; NUMERO: 2,5, TIPO: UMBILICAL ARTERIAL, PRESENTACION: UNIDAD | H23: SI | I23: =+'Necesidades Trimestrales'!F21 -> UNIDAD | J23: =+'Necesidades Trimestrales'!H21 -> 1950 | K23: =+'Necesidades Trimestrales'!G21 -> 100 | L23: CATETERES/SONDAS; NUMERO: 2,5, TIPO: UMBILICAL ARTERIAL, PRESENTACION: UNIDAD
... A31: 20 | B31: =+'Necesidades Trimestrales'!B29 -> 2.9.5-6700.2 | C31: =+'Necesidades Trimestrales'!E29 -> TROCAR DE PUNCION; USO: PUNCION TORAXICO, TIPO: N°8, CAMISA: SIN | H31: NO | I31: =+'Necesidades Trimestrales'!F29 -> UNIDAD | J31: =+'Necesidades Trimestrales'!H29 -> 1350 | K31: =+'Necesidades Trimestrales'!G29 -> 30 | L31: TROCAR DE PUNCION; USO: PUNCION TORAXICO, TIPO: N°8, CAMISA: SIN
A32: Costo total estimado: CINCO MILLONES DOSCIENTOS SESENTA MIL SESICIENTOS VEINTE CON 00/100. | J32: =SUMPRODUCT(J12:J31,K12:K31) -> 5260620

Sheet Autor Gastar
A1: EJERCICIO: | D1: ='Necesidades Trimestrales'!C6 -> 2022 | P1: AUTORIZACION PARA GASTAR
A4: JURISDICCIÓN: | G4: =' NotaPedido'!D3 -> 040 - Ministerio de Salud
A5: SAF: | G5: =' NotaPedido'!D4 -> 28-Maternidad Provincial 25 de Mayo
A6: UNIDAD EJECUTORA: | G6: =' NotaPedido'!D5 -> 169-Direccion Asistencial
A7: DEPENDENCIA SOLICITANTE: | G7: =' NotaPedido'!D6 -> Servicio de Farmacia
A8: AUTORIZACIÓN:
A9: Señor Jefe de Servicio Administrativo Financiero:
A10: ="Autorizo la realización de los trámites correspondientes, a fin de proveer a este Organismo los bienes y/o servicios que se detallan en Nota de Pedido N° " & ' NotaPedido'!K1&", afectando la erogación resultante a los créditos presupuestarios aprobados a favor de esta Unidad Ejecutora, conforme al siguiente detalle:" -> Autorizo la realización de los trámites correspondientes, a fin de proveer a este Organismo los bienes y/o servicios que se detallan en Nota de Pedido N° xxx/2022, afectando la erogación resultante a los créditos presupuestarios aprobados a favor de esta Unidad Ejecutora, conforme al siguiente detalle:
A12: IMPUTACIÓN PRESUPUESTARIA
A13: CÓDIGO | O13: DENOMINACIÓN DE LA PARTIDA PRESUPUESTARIA | Q13: IMPORTE
A14: PR | B14: SB | C14: PY | D14: AC | E14: OB | F14: UG | G14: FIN | H14: FUN | I14: I | J14: P | K14: P | L14: SubP | M14: M | N14: FF
A15: 42 | D15: 2 | F15: 4901 | G15: 3 | H15: 1 | I15: 2 | J15: 9 | K15: 5 | M15: 1 | N15: 1.1 | O15: Útiles Menores Médico, Quirúrgico y de Laboratorio | Q15: 5260620
A22: TOTAL DE PESOS: CINCO MILLONES DOSCIENTOS SESENTA MIL SESICIENTOS VEINTE CON 00/100. | Q22: =SUM(Q15:Q21) -> 5260620
A24: JUSTIFICACIÓN:
A25: Para la adquisición de Descartables Complejos destinados al Servicio de Farmacia de la Maternidad Provincial 25 de Mayo.
