Workbook

Sheet Necesidades Trimestrales (2)
A1: 2021
B2: Pedido de Necesidades Trimestrales
A4: JURISDICCION: | C4: 40 - MINISTERIO DE SALUD
A5: SAF N°: | C5: 11 - DIRE PROV DE ADMINISTRACION - MINISTERIO DE SALUD
A6: EJERCICIO: | C6: 2021
A7: TRIMESTRE: | C7: TERCER TRIMESTRE
A9: ID | B9: CODIGO ITEM | C9: RUBRO DE COMPRA | D9: I.P.P. | E9: DESCRIPCION | F9: UNIDAD DE MEDIDA | G9: DIR DE ADM | H9: TOTAL DIR ADM | I9: SEC PREV | J9: TOTAL SEC PREVEN | K9: DIR. LAB. CENTRAL | L9: TOTAL DE LAB CENTRAL | M9: BCO DE SANGRE | N9: TOTAL BANCO DE SANGRE | O9: ATENCION PRIMARIA | P9: TOTAL ATENCION PRI | Q9: DIR DE CANCER | R9: TOTAL DE DIR DE CANCER | S9: FARMACIA | T9: TOTAL FARMACIA | U9: ODONTOLOGIA | V9: TOTAL DE ODONTOLOG | W9: SAME | X9: TOTAL DE SAME | Y9: MALBRAN | Z9: HOSPITAL MALBRAN | AA9: maternidade e infancia | AB9: total maternidad | AC9: SEC DE ASIST EN SALUD PUB | AD9: TOTAL SEC EN ASIS EN SAL | AE9: SALUD Y MEDIO AMBIENTE | AF9: TOTAL SALUD Y MEDIO AMBIENTE | AG9: VECTORES Y ZOONOSIS | AH9: TOTAL DE VECT Y ZOON | AI9: SUMAR | AJ9: TOTAL SUMAR | AK9: CUR | AL9: TOTAL CUR | AM9: PLANIFICACION | AN9: TOTAL PLANIFICA | AO9: SALUD MENTAL | AP9: TOTAL SALUD MENTAL | AQ9: AREAS Y DPAS | AR9: TOTAL DPAS | AS9: CANTIDAD TOTAL | AT9: PRECIO UNITARIO ESTIMADO | AU9: IMPORTE TOTAL ESTIMADO
A10: 1 | C10: PROD. MEDICO/FARMACEUTICOS/LAB | D10: 295 | E10: Aguja descartable 25x8 (21Gx1) X 100 Tipo TERUMO | F10: CAJA | K10: 600 | L10: =+K10*AT10 -> 1228800 | AS10: =+AQ10+AO10+AM10+AK10+AI10+AG10+AE10+AC10+AA10+Y10+W10+U10+S10+Q10+O10+M10+K10+I10 -> 600 | AT10: 2048 | AU10: =+AS10*AT10 -> 1228800
A11: 2 | C11: PROD. MEDICO/FARMACEUTICOS/LAB | D11: 295 | E11: APOSITOS; TIPO: POST EXTRACCION SANGUINEA, hipoalergenica TAMAÑO: 40 X 40 mm | F11: CAJA | M11: 50 | N11: =+M11*AT11 -> 35100 | AS11: =+AQ11+AO11+AM11+AK11+AI11+AG11+AE11+AC11+AA11+Y11+W11+U11+S11+Q11+O11+M11+K11+I11 -> 50 | AT11: 702 | AU11: =+AS11*AT11 -> 35100
A12: 3 | C12: PROD. MEDICO/FARMACEUTICOS/LAB | D12: 295 | E12: BOLSAS DE SANGRE TRIPLE KS TIPO GRIFOLS | F12: UNIDAD | M12: =1950*2 -> 3900 | N12: =+M12*AT12 -> 5031000 | AS12: =+AQ12+AO12+AM12+AK12+AI12+AG12+AE12+AC12+AA12+Y12+W12+U12+S12+Q12+O12+M12+K12+I12 -> 3900 | AT12: 1290 | AU12: =+AS12*AT12 -> 5031000
A13: 4 | C13: PROD. MEDICO/FARMACEUTICOS/LAB | D13: 295 | E13: CEPILLO LIMPIA PIPETA DE CERDA NATURAL DE 10 MM | F13: UNIDAD | M13: 10 | N13: =+M13*AT13 -> 1250 | AS13: =+AQ13+AO13+AM13+AK13+AI13+AG13+AE13+AC13+AA13+Y13+W13+U13+S13+Q13+O13+M13+K13+I13 -> 10 | AT13: 125 | AU13: =+AS13*AT13 -> 1250
A14: 5 | C14: PROD. MEDICO/FARMACEUTICOS/LAB | D14: 295 | E14: Cepillo para Pipeta Serologica Tipo ARGA | F14: unidad | K14: 20 | L14: =+K14*AT14 -> 6440 | AS14: =+AQ14+AO14+AM14+AK14+AI14+AG14+AE14+AC14+AA14+Y14+W14+U14+S14+Q14+O14+M14+K14+I14 -> 20 | AT14: 322 | AU14: =+AS14*AT14 -> 6440
A15: 6 | C15: PROD. MEDICO/FARMACEUTICOS/LAB | D15: 295 | E15: Cepillo para Tubo de Khan y Hemolisis Tipo ARGA | F15: unidad | K15: 50 | L15: =+K15*AT15 -> 12200 | AS15: =+AQ15+AO15+AM15+AK15+AI15+AG15+AE15+AC15+AA15+Y15+W15+U15+S15+Q15+O15+M15+K15+I15 -> 50 | AT15: 244 | AU15: =+AS15*AT15 -> 12200
A16: 7 | C16: PROD. MEDICO/FARMACEUTICOS/LAB | D16: 295 | E16: CLOT CATCHER X250 UN. TIPO ROCHE | F16: caja | K16: 50 | L16: =+K16*AT16 -> 79600 | AS16: =+AQ16+AO16+AM16+AK16+AI16+AG16+AE16+AC16+AA16+Y16+W16+U16+S16+Q16+O16+M16+K16+I16 -> 50 | AT16: 1592 | AU16: =+AS16*AT16 -> 79600
A17: 8 | C17: PROD. MEDICO/FARMACEUTICOS/LAB | D17: 293 | E17: COBAS LAMPARA HALOGENA Tipo ROCHE C311 | F17: UNIDAD | K17: 6 | L17: =+K17*AT17 -> 389898 | AS17: =+AQ17+AO17+AM17+AK17+AI17+AG17+AE17+AC17+AA17+Y17+W17+U17+S17+Q17+O17+M17+K17+I17 -> 6 | AT17: 64983 | AU17: =+AS17*AT17 -> 389898
A18: 9 | C18: PROD. MEDICO/FARMACEUTICOS/LAB | D18: 295 | E18: Cubetas Serie X 500 Un. Tipo TECO GMBH (Alemania) | F18: CAJA | K18: 30 | L18: =+K18*AT18 -> 308430 | AS18: =+AQ18+AO18+AM18+AK18+AI18+AG18+AE18+AC18+AA18+Y18+W18+U18+S18+Q18+O18+M18+K18+I18 -> 30 | AT18: 10281 | AU18: =+AS18*AT18 -> 308430
A19: 10 | C19: PROD. MEDICO/FARMACEUTICOS/LAB | D19: 295 | E19: Cubreobjetos HDA 20x20 MM x 200 U Tipo KINDER | F19: CAJA | K19: 500 | L19: =+K19*AT19 -> 120000 | AS19: =+AQ19+AO19+AM19+AK19+AI19+AG19+AE19+AC19+AA19+Y19+W19+U19+S19+Q19+O19+M19+K19+I19 -> 500 | AT19: 240 | AU19: =+AS19*AT19 -> 120000
A20: 11 | C20: PROD. MEDICO/FARMACEUTICOS/LAB | D20: 295 | E20: DESCARTADOR PARA AGUJA P/500 AGUJAS, MODELO E-500 | F20: UNIDAD | M20: 200 | N20: =+M20*AT20 -> 39000 | AS20: =+AQ20+AO20+AM20+AK20+AI20+AG20+AE20+AC20+AA20+Y20+W20+U20+S20+Q20+O20+M20+K20+I20 -> 200 | AT20: 195 | AU20: =+AS20*AT20 -> 39000
A21: 12 | C21: PROD. MEDICO/FARMACEUTICOS/LAB | D21: 234 | E21: ETIQUETAS PARA IMPRESORA ZEBRA X1800 UNIDAD. TIPO ITECRA | F21: CAJA | K21: 60 | L21: =+K21*AT21 -> 67080 | AS21: =+AQ21+AO21+AM21+AK21+AI21+AG21+AE21+AC21+AA21+Y21+W21+U21+S21+Q21+O21+M21+K21+I21 -> 60 | AT21: 1118 | AU21: =+AS21*AT21 -> 67080
A22: 13 | C22: PROD. MEDICO/FARMACEUTICOS/LAB | D22: 295 | E22: Frasco de Bioseguridad Triple envase Tipo SISTEG M6 | F22: unidad | K22: 100 | L22: =+K22*AT22 -> 478000 | AS22: =+AQ22+AO22+AM22+AK22+AI22+AG22+AE22+AC22+AA22+Y22+W22+U22+S22+Q22+O22+M22+K22+I22 -> 100 | AT22: 4780 | AU22: =+AS22*AT22 -> 478000
A23: 14 | C23: PROD. MEDICO/FARMACEUTICOS/LAB | D23: 295 | E23: Gas calibracion OSMETECH Optti | F23: unidad | K23: 5 | L23: =+K23*AT23 -> 19500 | AS23: =+AQ23+AO23+AM23+AK23+AI23+AG23+AE23+AC23+AA23+Y23+W23+U23+S23+Q23+O23+M23+K23+I23 -> 5 | AT23: 3900 | AU23: =+AS23*AT23 -> 19500
A24: 15 | C24: PROD. MEDICO/FARMACEUTICOS/LAB | D24: 295 | E24: Gradilla alambre / plastico 24 Tubos 30 MM Tipo ARGA | F24: unidad | K24: 20 | L24: =+K24*AT24 -> 16200 | AS24: =+AQ24+AO24+AM24+AK24+AI24+AG24+AE24+AC24+AA24+Y24+W24+U24+S24+Q24+O24+M24+K24+I24 -> 20 | AT24: 810 | AU24: =+AS24*AT24 -> 16200
A25: 16 | C25: PROD. MEDICO/FARMACEUTICOS/LAB | D25: 295 | E25: Gradilla alambre / plastico 48 Tubos 30 MM Tipo ARGA | F25: unidad | K25: 20 | L25: =+K25*AT25 -> 17000 | AS25: =+AQ25+AO25+AM25+AK25+AI25+AG25+AE25+AC25+AA25+Y25+W25+U25+S25+Q25+O25+M25+K25+I25 -> 20 | AT25: 850 | AU25: =+AS25*AT25 -> 17000
A26: 17 | C26: PROD. MEDICO/FARMACEUTICOS/LAB | D26: 295 | E26: Gradilla PP resistente 80ºC 80 Tubos Eppendorf Tipo DELTALAB | F26: unidad | K26: 50 | L26: =+K26*AT26 -> 105000 | AS26: =+AQ26+AO26+AM26+AK26+AI26+AG26+AE26+AC26+AA26+Y26+W26+U26+S26+Q26+O26+M26+K26+I26 -> 50 | AT26: 2100 | AU26: =+AS26*AT26 -> 105000
A27: 18 | C27: PROD. MEDICO/FARMACEUTICOS/LAB | D27: 295 | E27: GUIA V20 C/RUEDITA *SANGRE* | F27: UNIDAD | M27: 600 | N27: =+M27*AT27 -> 55200 | AS27: =+AQ27+AO27+AM27+AK27+AI27+AG27+AE27+AC27+AA27+Y27+W27+U27+S27+Q27+O27+M27+K27+I27 -> 600 | AT27: 92 | AU27: =+AS27*AT27 -> 55200
A28: 19 | C28: PROD. MEDICO/FARMACEUTICOS/LAB | D28: 295 | E28: HISOPOS NASOFARINGEOS | F28: UNIDAD | K28: 50000 | L28: =+K28*AT28 -> 4600000 | AS28: =+AQ28+AO28+AM28+AK28+AI28+AG28+AE28+AC28+AA28+Y28+W28+U28+S28+Q28+O28+M28+K28+I28 -> 50000 | AT28: 92 | AU28: =+AS28*AT28 -> 4600000
A29: 20 | C29: PROD. MEDICO/FARMACEUTICOS/LAB | D29: 295 | E29: JERINGAS CON HEPARINA PARA GASES 3 ml TIPO ROCHE | F29: UNIDAD | K29: 8000 | L29: =+K29*AT29 -> 630400 | AS29: =+AQ29+AO29+AM29+AK29+AI29+AG29+AE29+AC29+AA29+Y29+W29+U29+S29+Q29+O29+M29+K29+I29 -> 8000 | AT29: 78.8 | AU29: =+AS29*AT29 -> 630400
A30: 21 | C30: PROD. MEDICO/FARMACEUTICOS/LAB | D30: 293 | E30: lampara para METROLAB A6 W10 | F30: UNIDAD | K30: 20 | L30: =+K30*AT30 -> 32500 | AS30: =+AQ30+AO30+AM30+AK30+AI30+AG30+AE30+AC30+AA30+Y30+W30+U30+S30+Q30+O30+M30+K30+I30 -> 20 | AT30: 1625 | AU30: =+AS30*AT30 -> 32500
A31: 22 | C31: PROD. MEDICO/FARMACEUTICOS/LAB | D31: 295 | E31: MICROPIPETA REGULABLE 100 A 1000 UL TIPO SOCOREX | F31: UNIDAD | K31: 10 | L31: =+K31*AT31 -> 705760 | M31: 0 | N31: =+AT31*M31 -> 0 | AS31: =+AQ31+AO31+AM31+AK31+AI31+AG31+AE31+AC31+AA31+Y31+W31+U31+S31+Q31+O31+M31+K31+I31 -> 10 | AT31: 70576 | AU31: =+AS31*AT31 -> 705760
A32: 23 | C32: PROD. MEDICO/FARMACEUTICOS/LAB | D32: 295 | E32: MICROPIPETAS REGULABLES; CAPACIDAD: 10-100 µL, DIVISIONES: CADA 1 µL, MATERIAL: PLASTICO | F32: UNIDAD | M32: 2 | N32: =+M32*AT32 -> 100700 | AS32: =+AQ32+AO32+AM32+AK32+AI32+AG32+AE32+AC32+AA32+Y32+W32+U32+S32+Q32+O32+M32+K32+I32 -> 2 | AT32: 50350 | AU32: =+AS32*AT32 -> 100700
A33: 24 | C33: PROD. MEDICO/FARMACEUTICOS/LAB | D33: 295 | E33: Microtubo Eppendorf Autoclavable 1,5 Ml Tipo DELTALAB | F33: unidad | K33: 80000 | L33: =+K33*AT33 -> 320000 | AS33: =+AQ33+AO33+AM33+AK33+AI33+AG33+AE33+AC33+AA33+Y33+W33+U33+S33+Q33+O33+M33+K33+I33 -> 80000 | AT33: 4 | AU33: =+AS33*AT33 -> 320000
A34: 25 | C34: PROD. MEDICO/FARMACEUTICOS/LAB | D34: 295 | E34: PLACA PARA VDRL CON POCILLO PROFUNDO 12HOYOS | F34: UNIDAD | M34: 5 | N34: =+M34*AT34 -> 6100 | AS34: =+AQ34+AO34+AM34+AK34+AI34+AG34+AE34+AC34+AA34+Y34+W34+U34+S34+Q34+O34+M34+K34+I34 -> 5 | AT34: 1220 | AU34: =+AS34*AT34 -> 6100
A35: 26 | C35: PROD. MEDICO/FARMACEUTICOS/LAB | D35: 295 | E35: Portaobjetos borde sin pulir 50 U Tipo BREMEN | F35: CAJA | K35: 500 | L35: =+K35*AT35 -> 93500 | AS35: =+AQ35+AO35+AM35+AK35+AI35+AG35+AE35+AC35+AA35+Y35+W35+U35+S35+Q35+O35+M35+K35+I35 -> 500 | AT35: 187 | AU35: =+AS35*AT35 -> 93500
A36: 27 | C36: PROD. MEDICO/FARMACEUTICOS/LAB | D36: 234 | E36: ROLLO DE PAPEL IMPRESORA COBAS B221 TIPO ROCHE X 6 UN. | F36: CAJA | K36: 5 | L36: =+K36*AT36 -> 19650 | AS36: =+AQ36+AO36+AM36+AK36+AI36+AG36+AE36+AC36+AA36+Y36+W36+U36+S36+Q36+O36+M36+K36+I36 -> 5 | AT36: 3930 | AU36: =+AS36*AT36 -> 19650
A37: 28 | C37: PROD. MEDICO/FARMACEUTICOS/LAB | D37: 234 | E37: Rollo de papel para Counter Liso para Desfribilador 50 MM Tipo CARDIO CHARTS | F37: rollo | K37: 200 | L37: =+K37*AT37 -> 26200 | AS37: =+AQ37+AO37+AM37+AK37+AI37+AG37+AE37+AC37+AA37+Y37+W37+U37+S37+Q37+O37+M37+K37+I37 -> 200 | AT37: 131 | AU37: =+AS37*AT37 -> 26200
A38: 29 | C38: PROD. MEDICO/FARMACEUTICOS/LAB | D38: 234 | E38: rollo de papel para MINIVIDAS x5 unidades | F38: pack | K38: 5 | L38: =+K38*AT38 -> 19500 | AS38: =+AQ38+AO38+AM38+AK38+AI38+AG38+AE38+AC38+AA38+Y38+W38+U38+S38+Q38+O38+M38+K38+I38 -> 5 | AT38: 3900 | AU38: =+AS38*AT38 -> 19500
A39: 30 | C39: PROD. MEDICO/FARMACEUTICOS/LAB | D39: 295 | E39: TIPS AMARILLO 5 A 200 µl, SIN CORONA X 1000 UN TIPO DELTALAB | F39: BOLSA | M39: 5 | N39: =+M39*AT39 -> 14325 | AS39: =+AQ39+AO39+AM39+AK39+AI39+AG39+AE39+AC39+AA39+Y39+W39+U39+S39+Q39+O39+M39+K39+I39 -> 5 | AT39: 2865 | AU39: =+AS39*AT39 -> 14325
A40: 31 | C40: PROD. MEDICO/FARMACEUTICOS/LAB | D40: 295 | E40: TIPS AMARILLO 5 A 200 µl, CON CORONA X 1000 UN TIPO DELTALAB | F40: BOLSA | M40: 2 | N40: =+M40*AT40 -> 3080 | AS40: =+AQ40+AO40+AM40+AK40+AI40+AG40+AE40+AC40+AA40+Y40+W40+U40+S40+Q40+O40+M40+K40+I40 -> 2 | AT40: 1540 | AU40: =+AS40*AT40 -> 3080
A41: 32 | C41: PROD. MEDICO/FARMACEUTICOS/LAB | D41: 295 | E41: TIPS AZUL 100-1000 UL AUTOCLAVABLE - CON CORONA BOLSA POR 1000 UNIDADES TIPO DELTALAB | F41: BOLSA | M41: 2 | N41: =+M41*AT41 -> 4408 | AS41: =+AQ41+AO41+AM41+AK41+AI41+AG41+AE41+AC41+AA41+Y41+W41+U41+S41+Q41+O41+M41+K41+I41 -> 2 | AT41: 2204 | AU41: =+AS41*AT41 -> 4408
A42: 33 | C42: PROD. MEDICO/FARMACEUTICOS/LAB | D42: 295 | E42: Tubo con citrato tapa celeste para coagulograma 1 ml | F42: unidad | K42: 3000 | L42: =+K42*AT42 -> 45000 | AS42: =+AQ42+AO42+AM42+AK42+AI42+AG42+AE42+AC42+AA42+Y42+W42+U42+S42+Q42+O42+M42+K42+I42 -> 3000 | AT42: 15 | AU42: =+AS42*AT42 -> 45000
...

Sheet NP LAB
A1: NOTA DE PEDIDO | J1: N° | K1: _33/21
A3: JURISDICCIÓN: | D3: 040 - Ministerio de Salud
A4: SAF: | D4: 011 - Direccion Provincial de Administración - Ministerio de Salud
A5: UNIDAD EJECUTORA: | D5: 468 - DIRECCION PROVINCIAL DE LABORATORIO
A6: DEPENDENCIA SOLICITANTE: | D6: 468 - DIRECCION PROVINCIAL DE LABORATORIO
A7: PERIODO UTILIZACIÓN: | D7: 3° TRIMESTRE
A8: OBJETO: | D8: Adquisicion del RUBRO DESCARTABLES PARA LABORATORIO
A10: Ítem | B10: Codigo Item | C10: DESCRIPCIÓN | H10: Adjunta Detalle Técnico | I10: Unidad Medida | J10: Precio Unitario Estimado | K10: Cantidad Solicitada
A12: 1 | C12: ='Necesidades Trimestrales (2)'!E10 -> Aguja descartable 25x8 (21Gx1) X 100 Tipo TERUMO | H12: NO | I12: ='Necesidades Trimestrales (2)'!F10 -> CAJA | J12: ='Necesidades Trimestrales (2)'!AT10 -> 2048 | K12: 600 | L12: =+J12*K12 -> 1228800 | M12: =+J12*K12 -> 1228800
A13: 2 | C13: ='Necesidades Trimestrales (2)'!E14 -> Cepillo para Pipeta Serologica Tipo ARGA | H13: NO | I13: ='Necesidades Trimestrales (2)'!F14 -> unidad | J13: ='Necesidades Trimestrales (2)'!AT14 -> 322 | K13: ='Necesidades Trimestrales (2)'!AS14 -> 20 | L13: =+J13*K13 -> 6440 | M13: =+J13*K13 -> 6440
A14: 3 | C14: ='Necesidades Trimestrales (2)'!E15 -> Cepillo para Tubo de Khan y Hemolisis Tipo ARGA | H14: NO | I14: ='Necesidades Trimestrales (2)'!F15 -> unidad | J14: ='Necesidades Trimestrales (2)'!AT15 -> 244 | K14: ='Necesidades Trimestrales (2)'!AS15 -> 50 | L14: =+J14*K14 -> 12200 | M14: =+J14*K14 -> 12200
A15: 4 | C15: ='Necesidades Trimestrales (2)'!E16 -> CLOT CATCHER X250 UN. TIPO ROCHE | H15: NO | I15: ='Necesidades Trimestrales (2)'!F16 -> caja | J15: ='Necesidades Trimestrales (2)'!AT16 -> 1592 | K15: ='Necesidades Trimestrales (2)'!AS16 -> 50 | L15: =+J15*K15 -> 79600 | M15: =+J15*K15 -> 79600
A16: 5 | C16: ='Necesidades Trimestrales (2)'!E17 -> COBAS LAMPARA HALOGENA Tipo ROCHE C311 | H16: NO | I16: ='Necesidades Trimestrales (2)'!F17 -> UNIDAD | J16: ='Necesidades Trimestrales (2)'!AT17 -> 64983 | K16: ='Necesidades Trimestrales (2)'!AS17 -> 6 | L16: =+J16*K16 -> 389898 | M16: =+J16*K16 -> 389898
A17: 6 | C17: ='Necesidades Trimestrales (2)'!E18 -> Cubetas Serie X 500 Un. Tipo TECO GMBH (Alemania) | H17: NO | I17: ='Necesidades Trimestrales (2)'!F18 -> CAJA | J17: ='Necesidades Trimestrales (2)'!AT18 -> 10281 | K17: ='Necesidades Trimestrales (2)'!AS18 -> 30 | L17: =+J17*K17 -> 308430 | M17: =+J17*K17 -> 308430
A18: 7 | C18: ='Necesidades Trimestrales (2)'!E19 -> Cubreobjetos HDA 20x20 MM x 200 U Tipo KINDER | H18: NO | I18: ='Necesidades Trimestrales (2)'!F19 -> CAJA | J18: ='Necesidades Trimestrales (2)'!AT19 -> 240 | K18: ='Necesidades Trimestrales (2)'!AS19 -> 500 | L18: =+J18*K18 -> 120000 | M18: =+J18*K18 -> 120000
A19: 8 | C19: ='Necesidades Trimestrales (2)'!E21 -> ETIQUETAS PARA IMPRESORA ZEBRA X1800 UNIDAD. TIPO ITECRA | H19: NO | I19: ='Necesidades Trimestrales (2)'!F21 -> CAJA | J19: ='Necesidades Trimestrales (2)'!AT21 -> 1118 | K19: ='Necesidades Trimestrales (2)'!AS21 -> 60 | L19: =+J19*K19 -> 67080 | M19: =+J19*K19 -> 67080
A20: 9 | C20: ='Necesidades Trimestrales (2)'!E22 -> Frasco de Bioseguridad Triple envase Tipo SISTEG M6 | H20: NO | I20: ='Necesidades Trimestrales (2)'!F22 -> unidad | J20: ='Necesidades Trimestrales (2)'!AT22 -> 4780 | K20: ='Necesidades Trimestrales (2)'!AS22 -> 100 | L20: =+J20*K20 -> 478000 | M20: =+J20*K20 -> 478000
A21: 10 | C21: ='Necesidades Trimestrales (2)'!E23 -> Gas calibracion OSMETECH Optti | H21: NO | I21: ='Necesidades Trimestrales (2)'!F23 -> unidad | J21: ='Necesidades Trimestrales (2)'!AT23 -> 3900 | K21: ='Necesidades Trimestrales (2)'!AS23 -> 5 | L21: =+J21*K21 -> 19500 | M21: =+J21*K21 -> 19500
A22: 11 | C22: ='Necesidades Trimestrales (2)'!E24 -> Gradilla alambre / plastico 24 Tubos 30 MM Tipo ARGA | H22: NO | I22: ='Necesidades Trimestrales (2)'!F24 -> unidad | J22: ='Necesidades Trimestrales (2)'!AT24 -> 810 | K22: ='Necesidades Trimestrales (2)'!AS24 -> 20 | L22: =+J22*K22 -> 16200 | M22: =+J22*K22 -> 16200
A23: 12 | C23: ='Necesidades Trimestrales (2)'!E25 -> Gradilla alambre / plastico 48 Tubos 30 MM Tipo ARGA | H23: NO | I23: ='Necesidades Trimestrales (2)'!F25 -> unidad | J23: ='Necesidades Trimestrales (2)'!AT25 -> 850 | K23: ='Necesidades Trimestrales (2)'!AS25 -> 20 | L23: =+J23*K23 -> 17000 | M23: =+J23*K23 -> 17000
A24: 13 | C24: ='Necesidades Trimestrales (2)'!E26 -> Gradilla PP resistente 80ºC 80 Tubos Eppendorf Tipo DELTALAB | H24: NO | I24: ='Necesidades Trimestrales (2)'!F26 -> unidad | J24: ='Necesidades Trimestrales (2)'!AT26 -> 2100 | K24: ='Necesidades Trimestrales (2)'!AS26 -> 50 | L24: =+J24*K24 -> 105000 | M24: =+J24*K24 -> 105000
A25: 14 | C25: ='Necesidades Trimestrales (2)'!E28 -> HISOPOS NASOFARINGEOS | H25: NO | I25: ='Necesidades Trimestrales (2)'!F28 -> UNIDAD | J25: ='Necesidades Trimestrales (2)'!AT28 -> 92 | K25: ='Necesidades Trimestrales (2)'!AS28 -> 50000 | L25: =+J25*K25 -> 4600000 | M25: =+J25*K25 -> 4600000
A26: 15 | C26: ='Necesidades Trimestrales (2)'!E29 -> JERINGAS CON HEPARINA PARA GASES 3 ml TIPO ROCHE | H26: NO | I26: ='Necesidades Trimestrales (2)'!F29 -> UNIDAD | J26: ='Necesidades Trimestrales (2)'!AT29 -> 78.8 | K26: ='Necesidades Trimestrales (2)'!AS29 -> 8000 | L26: =+J26*K26 -> 630400 | M26: =+J26*K26 -> 630400
A27: 16 | C27: ='Necesidades Trimestrales (2)'!E30 -> lampara para METROLAB A6 W10 | H27: NO | I27: ='Necesidades Trimestrales (2)'!F30 -> UNIDAD | J27: ='Necesidades Trimestrales (2)'!AT30 -> 1625 | K27: ='Necesidades Trimestrales (2)'!AS30 -> 20 | L27: =+J27*K27 -> 32500 | M27: =+J27*K27 -> 32500
A28: 17 | C28: ='Necesidades Trimestrales (2)'!E31 -> MICROPIPETA REGULABLE 100 A 1000 UL TIPO SOCOREX | H28: NO | I28: ='Necesidades Trimestrales (2)'!F31 -> UNIDAD | J28: ='Necesidades Trimestrales (2)'!AT31 -> 70576 | K28: 10 | L28: =+J28*K28 -> 705760 | M28: =+J28*K28 -> 705760
A29: 18 | C29: ='Necesidades Trimestrales (2)'!E33 -> Microtubo Eppendorf Autoclavable 1,5 Ml Tipo DELTALAB | H29: NO | I29: ='Necesidades Trimestrales (2)'!F33 -> unidad | J29: ='Necesidades Trimestrales (2)'!AT33 -> 4 | K29: ='Necesidades Trimestrales (2)'!AS33 -> 80000 | L29: =+J29*K29 -> 320000 | M29: =+J29*K29 -> 320000
A30: 19 | C30: ='Necesidades Trimestrales (2)'!E35 -> Portaobjetos borde sin pulir 50 U Tipo BREMEN | H30: NO | I30: ='Necesidades Trimestrales (2)'!F35 -> CAJA | J30: ='Necesidades Trimestrales (2)'!AT35 -> 187 | K30: ='Necesidades Trimestrales (2)'!AS35 -> 500 | L30: =+J30*K30 -> 93500 | M30: =+J30*K30 -> 93500
A31: 20 | C31: ='Necesidades Trimestrales (2)'!E36 -> ROLLO DE PAPEL IMPRESORA COBAS B221 TIPO ROCHE X 6 UN. | H31: NO | I31: ='Necesidades Trimestrales (2)'!F36 -> CAJA | J31: ='Necesidades Trimestrales (2)'!AT36 -> 3930 | K31: ='Necesidades Trimestrales (2)'!AS36 -> 5 | L31: =+J31*K31 -> 19650 | M31: =+J31*K31 -> 19650
A32: 21 | C32: ='Necesidades Trimestrales (2)'!E37 -> Rollo de papel para Counter Liso para Desfribilador 50 MM Tipo CARDIO CHARTS | H32: NO | I32: ='Necesidades Trimestrales (2)'!F37 -> rollo | J32: ='Necesidades Trimestrales (2)'!AT37 -> 131 | K32: ='Necesidades Trimestrales (2)'!AS37 -> 200 | L32: =+J32*K32 -> 26200 | M32: =+J32*K32 -> 26200
A33: 22 | C33: ='Necesidades Trimestrales (2)'!E38 -> rollo de papel para MINIVIDAS x5 unidades | H33: NO | I33: ='Necesidades Trimestrales (2)'!F38 -> pack | J33: ='Necesidades Trimestrales (2)'!AT38 -> 3900 | K33: ='Necesidades Trimestrales (2)'!AS38 -> 5 | L33: =+J33*K33 -> 19500 | M33: =+J33*K33 -> 19500
A34: 23 | C34: ='Necesidades Trimestrales (2)'!E42 -> Tubo con citrato tapa celeste para coagulograma 1 ml | H34: NO | I34: ='Necesidades Trimestrales (2)'!F42 -> unidad | J34: ='Necesidades Trimestrales (2)'!AT42 -> 15 | K34: ='Necesidades Trimestrales (2)'!AS42 -> 3000 | L34: =+J34*K34 -> 45000 | M34: =+J34*K34 -> 45000
A35: 24 | C35: ='Necesidades Trimestrales (2)'!E43 -> Tubo con Edta 0.6 ml | H35: NO | I35: ='Necesidades Trimestrales (2)'!F43 -> unidad | J35: ='Necesidades Trimestrales (2)'!AT43 -> 37 | K35: ='Necesidades Trimestrales (2)'!AS43 -> 8000 | L35: =+J35*K35 -> 296000 | M35: =+J35*K35 -> 296000
A36: 25 | C36: ='Necesidades Trimestrales (2)'!E44 -> Tubo para suero con gel tapa Amarilla 5 ML | H36: NO | I36: ='Necesidades Trimestrales (2)'!F44 -> unidad | J36: ='Necesidades Trimestrales (2)'!AT44 -> 35 | K36: ='Necesidades Trimestrales (2)'!AS44 -> 20000 | L36: =+J36*K36 -> 700000 | M36: =+J36*K36 -> 700000
M37: =+J37*K37 -> 0
A38: Costo total estimado: DIEZ MILLONES TRESCIENTOS TREINTA Y SEIS MIL SEISCIENTOS CINCUENTA Y OCHO con 00/100 | J38: =SUM(L12:L36) -> 10336658 | M38: =SUM(M12:M37) -> 10336658

Sheet APG LAB
A1: EJERCICIO: | D1: 2021 | P1: AUTORIZACION PARA GASTAR
A4: JURISDICCIÓN: | G4: ='NP LAB'!D3 -> 040 - Ministerio de Salud
A5: SAF: | G5: ='NP LAB'!D4 -> 011 - Direccion Provincial de Administración - Ministerio de Salud
A6: UNIDAD EJECUTORA: | G6: ='NP LAB'!D5 -> 468 - DIRECCION PROVINCIAL DE LABORATORIO
A7: DEPENDENCIA SOLICITANTE: | G7: ='NP LAB'!D6 -> 468 - DIRECCION PROVINCIAL DE LABORATORIO
A8: AUTORIZACIÓN:
A9: Señor Jefe de Servicio Administrativo Financiero:
A10: Autorizo la realización de los trámites correspondientes, a fin de proveer a este Organismo los bienes que se detallan en Nota de pedido y Entrega N° 33/2021, afectando la erogación resultante a los créditos presupuestarios aprobados a favor de esta Unidad Ejecutora, conforme al siguiente detalle:
A12: IMPUTACIÓN PRESUPUESTARIA
A13: CÓDIGO | O13: DENOMINACIÓN DE LA PARTIDA PRESUPUESTARIA | Q13: IMPORTE
A14: PR | B14: SB | C14: PY | D14: AC | E14: OB | F14: UG | G14: FIN | H14: FUN | I14: I | J14: P | K14: P | L14: SubP | M14: M | N14: FF
A15: 62 | D15: 1 | F15: 4901 | G15: 3 | H15: 1 | I15: 2 | J15: 9 | K15: 5 | M15: 1 | N15: 1.1 | O15: UTILES MENORES MEDICOS, QUIRURGICOS Y DE LABORATORIO | Q15: ='NP LAB'!M38-Q16-Q17 -> 9781830
A16: 62 | D16: 1 | F16: 4901 | G16: 3 | H16: 1 | I16: 2 | J16: 3 | K16: 4 | M16: 1 | N16: 1.1 | O16: Productos de Papel y Cartón | Q16: =+'NP LAB'!L31+'NP LAB'!L32+'NP LAB'!L33+'NP LAB'!M19 -> 132430
A17: 62 | D17: 1 | F17: 4901 | G17: 3 | H17: 1 | I17: 2 | J17: 9 | K17: 3 | M17: 1 | N17: 1.1 | O17: Útiles y Materiales Eléctricos | Q17: =+'NP LAB'!L16+'NP LAB'!L27 -> 422398
A23: TOTAL DE PESOS: DIEZ MILLONES TRESCIENTOS TREINTA Y SEIS MIL SEISCIENTOS CINCUENTA Y OCHO con 00/100 | Q23: =SUM(Q15:Q22) -> 10336658
A25: JUSTIFICACIÓN:
A26: ='NP LAB'!D8 -> Adquisicion del RUBRO DESCARTABLES PARA LABORATORIO

Sheet NP BCO SANGRE
A1: NOTA DE PEDIDO | J1: N° | K1: _20/21
A3: JURISDICCIÓN: | D3: 040 - Ministerio de Salud
A4: SAF: | D4: 011 - Direccion Provincial de Administración - Ministerio de Salud
A5: UNIDAD EJECUTORA: | D5: 747 - DIRECCION PROVINCIAL BANCO DE SANGRE
A6: DEPENDENCIA SOLICITANTE: | D6: 747 - DIRECCION PROVINCIAL BANCO DE SANGRE
A7: PERIODO UTILIZACIÓN: | D7: 3° TRIMESTRE
A8: OBJETO: | D8: Adquisicion del RUBRO DESCARTABLES PARA LABORATORIO
A10: Ítem | B10: Codigo Item | C10: DESCRIPCIÓN | H10: Adjunta Detalle Técnico | I10: Unidad Medida | J10: Precio Unitario Estimado | K10: Cantidad Solicitada
A12: 1 | C12: ='Necesidades Trimestrales (2)'!E11 -> APOSITOS; TIPO: POST EXTRACCION SANGUINEA, hipoalergenica TAMAÑO: 40 X 40 mm | H12: NO | I12: ='Necesidades Trimestrales (2)'!F11 -> CAJA | J12: ='Necesidades Trimestrales (2)'!AT11 -> 702 | K12: 50 | M12: =+J12*K12 -> 35100
A13: 2 | C13: ='Necesidades Trimestrales (2)'!E12 -> BOLSAS DE SANGRE TRIPLE KS TIPO GRIFOLS | H13: NO | I13: ='Necesidades Trimestrales (2)'!F12 -> UNIDAD | J13: ='Necesidades Trimestrales (2)'!AT12 -> 1290 | K13: ='Necesidades Trimestrales (2)'!AS12 -> 3900 | M13: =+J13*K13 -> 5031000
A14: 3 | C14: ='Necesidades Trimestrales (2)'!E13 -> CEPILLO LIMPIA PIPETA DE CERDA NATURAL DE 10 MM | H14: NO | I14: ='Necesidades Trimestrales (2)'!F13 -> UNIDAD | J14: ='Necesidades Trimestrales (2)'!AT13 -> 125 | K14: ='Necesidades Trimestrales (2)'!AS13 -> 10 | M14: =+J14*K14 -> 1250
A15: 4 | C15: ='Necesidades Trimestrales (2)'!E20 -> DESCARTADOR PARA AGUJA P/500 AGUJAS, MODELO E-500 | H15: NO | I15: ='Necesidades Trimestrales (2)'!F20 -> UNIDAD | J15: ='Necesidades Trimestrales (2)'!AT20 -> 195 | K15: 200 | M15: =+J15*K15 -> 39000
A16: 5 | C16: ='Necesidades Trimestrales (2)'!E27 -> GUIA V20 C/RUEDITA *SANGRE* | H16: NO | I16: ='Necesidades Trimestrales (2)'!F27 -> UNIDAD | J16: ='Necesidades Trimestrales (2)'!AT27 -> 92 | K16: ='Necesidades Trimestrales (2)'!AS27 -> 600 | M16: =+J16*K16 -> 55200
A17: 6 | C17: ='Necesidades Trimestrales (2)'!E32 -> MICROPIPETAS REGULABLES; CAPACIDAD: 10-100 µL, DIVISIONES: CADA 1 µL, MATERIAL: PLASTICO | H17: NO | I17: ='Necesidades Trimestrales (2)'!F32 -> UNIDAD | J17: ='Necesidades Trimestrales (2)'!AT32 -> 50350 | K17: ='Necesidades Trimestrales (2)'!AS32 -> 2 | M17: =+J17*K17 -> 100700
A18: 7 | C18: ='Necesidades Trimestrales (2)'!E34 -> PLACA PARA VDRL CON POCILLO PROFUNDO 12HOYOS | H18: NO | I18: ='Necesidades Trimestrales (2)'!F34 -> UNIDAD | J18: ='Necesidades Trimestrales (2)'!AT34 -> 1220 | K18: ='Necesidades Trimestrales (2)'!AS34 -> 5 | M18: =+J18*K18 -> 6100
A19: 8 | C19: ='Necesidades Trimestrales (2)'!E39 -> TIPS AMARILLO 5 A 200 µl, SIN CORONA X 1000 UN TIPO DELTALAB | H19: NO | I19: BOLSA | J19: ='Necesidades Trimestrales (2)'!AT39 -> 2865 | K19: 5 | M19: =+J19*K19 -> 14325
A20: 9 | C20: ='Necesidades Trimestrales (2)'!E40 -> TIPS AMARILLO 5 A 200 µl, CON CORONA X 1000 UN TIPO DELTALAB | H20: NO | I20: ='Necesidades Trimestrales (2)'!F40 -> BOLSA | J20: ='Necesidades Trimestrales (2)'!AT40 -> 1540 | K20: ='Necesidades Trimestrales (2)'!AS40 -> 2 | M20: =+J20*K20 -> 3080
A21: 10 | C21: ='Necesidades Trimestrales (2)'!E41 -> TIPS AZUL 100-1000 UL AUTOCLAVABLE - CON CORONA BOLSA POR 1000 UNIDADES TIPO DELTALAB | H21: NO | I21: ='Necesidades Trimestrales (2)'!F41 -> BOLSA | J21: ='Necesidades Trimestrales (2)'!AT41 -> 2204 | K21: ='Necesidades Trimestrales (2)'!AS41 -> 2 | M21: =+J21*K21 -> 4408
A22: 11 | C22: ='Necesidades Trimestrales (2)'!E45 -> TUBOS DE ENSAYO; TIPO: CONICO P/CENTRIFUGA, MATERIAL: POLIPROPILENO, DIMENSION: 0,5 A 15 mL, ACCESORIO: SIN VALOR, ACCESORIOS: SIN VALOR A ROSCA 15ML NO ETERIL, BOLSA X 100 UNID TIPO BIOLIX | H22: NO | I22: BOLSA | J22: ='Necesidades Trimestrales (2)'!AT45 -> 13700 | K22: ='Necesidades Trimestrales (2)'!AS45 -> 2 | M22: =+J22*K22 -> 27400
A23: 12 | C23: ='Necesidades Trimestrales (2)'!E46 -> TUBOS DE ENSAYO; TIPO: EPPENDORF, MATERIAL: PLASTICO, DIMENSION: 1.5 mL, ACCESORIOS: SIN, ACCESORIO: SIN | H23: NO | I23: UNIDAD | J23: ='Necesidades Trimestrales (2)'!AT46 -> 5353 | K23: ='Necesidades Trimestrales (2)'!AS46 -> 10 | M23: =+J23*K23 -> 53530
A24: 13 | C24: ='Necesidades Trimestrales (2)'!E47 -> TUBOS DE ENSAYO; TIPO: VACUTAINER UN, MATERIAL: VIDRIO, DIMENSION: 10 mL, ACCESORIOS: SIN, ACCESORIO: SIN | H24: NO | I24: UNIDAD | J24: ='Necesidades Trimestrales (2)'!AT47 -> 13000 | K24: ='Necesidades Trimestrales (2)'!AS47 -> 2 | M24: =+J24*K24 -> 26000
A25: 14 | C25: ='Necesidades Trimestrales (2)'!E48 -> TUBOS DE HEMOLISIS; MATERIAL: VIDRIO, PRESENTACION: CAJA, DIMENSION: 100 X 13 DIAM. EXT., MEDIDAS: 100 X 13 DIAM. EXT., FORMA DE PRESENTACION: SOLIDO, ESTADO: SOLIDO | H25: NO | I25: ='Necesidades Trimestrales (2)'!F48 -> UNIDAD | J25: ='Necesidades Trimestrales (2)'!AT48 -> 72 | K25: ='Necesidades Trimestrales (2)'!AS48 -> 1000 | M25: =+J25*K25 -> 72000
A26: 15 | C26: ='Necesidades Trimestrales (2)'!E49 -> TUBOS VACUTAINER P/SUERO DE 4ML, TAPA ROJA C/ETIQUETA CODIGO 367812 (1000 TUBOS) | H26: NO | I26: CAJA | J26: ='Necesidades Trimestrales (2)'!AT49 -> 3558 | K26: ='Necesidades Trimestrales (2)'!AS49 -> 10 | M26: =+J26*K26 -> 35580
A28: Costo total estimado: CINCO MILLONES QUINIENTOS CUATRO MIL SEISCIENTOS SETENTA Y TRES con 00/100 | J28: =+M28 -> 5504673 | M28: =SUM(M12:M27) -> 5504673

Sheet APG BCO SANGRE
A1: EJERCICIO: | D1: 2021 | P1: AUTORIZACION PARA GASTAR
A4: JURISDICCIÓN: | G4: ='NP BCO SANGRE'!D3 -> 040 - Ministerio de Salud
A5: SAF: | G5: ='NP BCO SANGRE'!D4 -> 011 - Direccion Provincial de Administración - Ministerio de Salud
A6: UNIDAD EJECUTORA: | G6: ='NP BCO SANGRE'!D5 -> 747 - DIRECCION PROVINCIAL BANCO DE SANGRE
A7: DEPENDENCIA SOLICITANTE: | G7: ='NP BCO SANGRE'!D6 -> 747 - DIRECCION PROVINCIAL BANCO DE SANGRE
A8: AUTORIZACIÓN:
A9: Señor Jefe de Servicio Administrativo Financiero:
A10: Autorizo la realización de los trámites correspondientes, a fin de proveer a este Organismo los bienes que se detallan en Nota de pedido y Entrega N° 20/2021, afectando la erogación resultante a los créditos presupuestarios aprobados a favor de esta Unidad Ejecutora, conforme al siguiente detalle:
A12: IMPUTACIÓN PRESUPUESTARIA
A13: CÓDIGO | O13: DENOMINACIÓN DE LA PARTIDA PRESUPUESTARIA | Q13: IMPORTE
A14: PR | B14: SB | C14: PY | D14: AC | E14: OB | F14: UG | G14: FIN | H14: FUN | I14: I | J14: P | K14: P | L14: SubP | M14: M | N14: FF
A15: 27 | D15: 1 | F15: 4901 | G15: 3 | H15: 1 | I15: 2 | J15: 9 | K15: 5 | M15: 1 | N15: 1.1 | O15: UTILES MENORES MEDICOS, QUIRURGICOS Y DE LABORATORIO | Q15: ='NP BCO SANGRE'!M28 -> 5504673
A23: TOTAL DE PESOS: CINCO MILLONES QUINIENTOS CUATRO MIL SEISCIENTOS SETENTA Y TRES con 00/100 | Q23: =SUM(Q15:Q22) -> 5504673
A25: JUSTIFICACIÓN:
A26: ='NP BCO SANGRE'!D8 -> Adquisicion del RUBRO DESCARTABLES PARA LABORATORIO
