Workbook

Sheet Necesidades Trimestrales
B2: Pedido de Necesidades Trimestrales
A4: JURISDICCION: | C4: 040 - Ministerio de Salud
A5: SAF N°: | C5: 11/ 23/ 24 o 28- "…......."
A6: EJERCICIO: | C6: 2022
A7: TRIMESTRE: | C7: 3
A9: ID | B9: CODIGO ITEM | C9: RUBRO DE COMPRA | D9: I.P.P. | E9: DESCRIPCION | F9: UNIDAD DE MEDIDA | G9: CANTIDAD | H9: PRECIO UNITARIO ESTIMADO | I9: IMPORTE TOTAL ESTIMADO
A10: 1 | B10: 2.5.2-3259.11 | C10: PROD. MEDICO/FARMACEUTICOS/LAB | D10: 252 | E10: DIGESTIVOS; TIPO: MONODROGA, DROGA GENERICA: ACIDO URSODESOXICOLICO, FORMA FARMACEUTICA: COMPRIMIDO, PRESENTACION: 150 MGR | F10: COMPRIMIDO | H10: 58.5 | I10: =+G10*H10 -> 0
A11: 2 | B11: 2.5.2-3259.14 | C11: PROD. MEDICO/FARMACEUTICOS/LAB | D11: 252 | E11: DIGESTIVOS; TIPO: MONODROGA, DROGA GENERICA: ACIDO URSODEOXICOLICO, FORMA FARMACEUTICA: COMPRIMIDO, PRESENTACION: 300 MGR | F11: COMPRIMIDO | H11: 146.93 | I11: =+G11*H11 -> 0
A12: 3 | B12: 2.5.2-1841.33 | C12: PROD. MEDICO/FARMACEUTICOS/LAB | D12: 252 | E12: ANTIACIDOS; TIPO: ASOCIACION, DROGA GENERICA: HIDROX. ALUM. + HIDROX. MAG., FORMA FARMACEUTICA: SUSPENSION, PRESENTACION: ENVASE X 160 ML | F12: FRASCO | H12: 260 | I12: =+G12*H12 -> 0
A13: 4 | B13: 2.5.2-1843.63 | C13: PROD. MEDICO/FARMACEUTICOS/LAB | D13: 252 | E13: ANTIESPASMODICOS; TIPO: MONODROGA, DROGA GENERICA: ATROPINA 1%, FORMA FARMACEUTICA: AMPOLLA, PRESENTACION: ENVASE X 1 mL | F13: AMPOLLA | H13: 50.4 | I13: =+G13*H13 -> 0
A14: 5 | B14: 2.5.2-1843.51 | C14: PROD. MEDICO/FARMACEUTICOS/LAB | D14: 252 | E14: ANTIESPASMODICOS; TIPO: MONODROGA, DROGA GENERICA: HIOSCINA N-BUTILBROMURO 20 MG, FORMA FARMACEUTICA: AMPOLLA, PRESENTACION: 1 ML | F14: AMPOLLA | H14: 65 | I14: =+G14*H14 -> 0
A15: 6 | B15: 2.5.2-1843.1 | C15: PROD. MEDICO/FARMACEUTICOS/LAB | D15: 252 | E15: ANTIESPASMODICOS; TIPO: MONODROGA, PRESENTACION: 10 mGr, FORMA FARMACEUTICA: COMPRIMIDO, DROGA GENERICA: HIOSCINA N-BUTILBROMURO | F15: COMPRIMIDO | H15: 11 | I15: =+G15*H15 -> 0
A16: 7 | B16: 2.5.2-1724.57 | C16: PROD. MEDICO/FARMACEUTICOS/LAB | D16: 252 | E16: ANALGESICOS ; TIPO: ASOCIACION, DROGA GENERICA: DIPIRONA+ HIOSCINA, FORMA FARMACEUTICA: AMPOLLA, PRESENTACION: AMPOLLA X 5 mL | F16: AMPOLLA | H16: 92 | I16: =+G16*H16 -> 0
A17: 8 | B17: 2.5.2-1903.66 | C17: PROD. MEDICO/FARMACEUTICOS/LAB | D17: 252 | E17: RECONSTITUYENTE GENERAL; TIPO: MONODROGA, DROGA GENERICA: CALCIO CARBONATO, FORMA FARMACEUTICA: COMPRIMIDO, PRESENTACION: 1250 mGr | F17: COMPRIMIDO | H17: 6.3 | I17: =+G17*H17 -> 0
A18: 9 | B18: 2.5.2-8078.68 | C18: QUIMICOS | D18: 252 | E18: EXCIPIENTES; TIPO: MONODROGA, PRESENTACION: ENVASE X 1 Kg, COMPUESTO: CARBON ACTIVADO, CONCENTRACION/PUREZA: 100 % | F18: UNIDAD | H18: 1800 | I18: =+G18*H18 -> 0
A19: 10 | B19: 2.5.2-1903.89 | C19: PROD. MEDICO/FARMACEUTICOS/LAB | D19: 252 | E19: RECONSTITUYENTE GENERAL; TIPO: MONODROGA, DROGA GENERICA: CALCIO CARBONATO, FORMA FARMACEUTICA: COMPRIMIDO, PRESENTACION: 500 mGr | F19: COMPRIMIDO | H19: 5.98 | I19: =+G19*H19 -> 0
A20: 11 | B20: 2.5.2-1723.176 | C20: PROD. MEDICO/FARMACEUTICOS/LAB | D20: 252 | E20: ANTISEPTICOS LOCALES P/PERSONA; TIPO: MONODROGA, DROGA GENERICA: CLORHEXIDINA DIGLUCONATO 0,12 %, FORMA FARMACEUTICA: LIQUIDO, PRESENTACION: ENVASE X 200 ML | F20: FRASCO | H20: 1288 | I20: =+G20*H20 -> 0
A21: 12 | B21: 2.5.2-1901.7 | C21: PROD. MEDICO/FARMACEUTICOS/LAB | D21: 252 | E21: VITAMINAS; FORMA FARMACEUTICA: AMPOLLA, PRESENTACION: 2 mL, TIPO: MONODROGA, DROGA GENERICA: VITAMINA B | F21: AMPOLLA | H21: 110 | I21: =+G21*H21 -> 0
... A44: 35 | B44: 2.5.2-6910.13 | C44: PROD. MEDICO/FARMACEUTICOS/LAB | D44: 252 | E44: ANTIEMETICOS; TIPO: MONODROGA, DROGA GENERICA: ONDANSETRON X 8 mGr, FORMA FARMACEUTICA: AMPOLLA, PRESENTACION: ENVASE X 1 UN | F44: AMPOLLA | H44: 106.8 | I44: =+G44*H44 -> 0
A45: 36 | B45: 2.5.2-3603.13 | C45: PROD. MEDICO/FARMACEUTICOS/LAB | D45: 252 | E45: EVACUANTES INTESTINALES; TIPO: ASOCIACION, DROGA GENERICA: FOSFATO MONOSODICO-BISODICO, FORMA FARMACEUTICA: SOLUCION, PRESENTACION: ENVASE X 45 mL | F45: FRASCO | H45: 1833.02
A46: 37 | B46: 2.5.2-3603.1 | C46: PROD. MEDICO/FARMACEUTICOS/LAB | D46: 252 | E46: EVACUANTES INTESTINALES; DROGA GENERICA: FOSFATO MONOSODICO-BISODICO, FORMA FARMACEUTICA: SOLUCION, PRESENTACION: 135 mL, TIPO: ASOCIACION | F46: FRASCO | H46: 1057.25
A47: 38 | B47: 2.5.2-2481.13 | C47: PROD. MEDICO/FARMACEUTICOS/LAB | D47: 252 | E47: LAXANTES; TIPO: MONODROGA, DROGA GENERICA: PICOSULFATO SODICO, FORMA FARMACEUTICA: GOTAS, PRESENTACION: 15 mL | F47: GOTERO | H47: 885.68 | I47: =+G47*H47 -> 0
A48: 39 | B48: 2.5.2-1901.127 | C48: PROD. MEDICO/FARMACEUTICOS/LAB | D48: 252 | E48: VITAMINAS; TIPO: ASOCIACION, DROGA GENERICA: VIT.A +D+C, FORMA FARMACEUTICA: GOTA, PRESENTACION: 30 ML | F48: FRASCO | H48: 210 | I48: =+G48*H48 -> 0
A49: 40 | B49: 2.5.2-1841.17 | C49: PROD. MEDICO/FARMACEUTICOS/LAB | D49: 252 | E49: ANTIACIDOS; TIPO: MONODROGA, DROGA GENERICA: RANITIDINA, FORMA FARMACEUTICA: AMPOLLA, PRESENTACION: UNIDAD | F49: AMPOLLA | H49: 47.5 | I49: =+G49*H49 -> 0
A50: 41 | B50: 2.5.2-1903.85 | C50: PROD. MEDICO/FARMACEUTICOS/LAB | D50: 252 | E50: RECONSTITUYENTE GENERAL; TIPO: ASOCIACION, DROGA GENERICA: SALES DE REHIDRATACION, FORMA FARMACEUTICA: POLVO, PRESENTACION: SOBRE X 27,9 GR | F50: UNIDAD | H50: 88 | I50: =+G50*H50 -> 0
A51: 42 | B51: 2.5.2-1841.13 | C51: PROD. MEDICO/FARMACEUTICOS/LAB | D51: 252 | E51: ANTIACIDOS; TIPO: MONODROGA, DROGA GENERICA: SUCRALFATO, FORMA FARMACEUTICA: SOLUCION, PRESENTACION: ENVASE X 200 mL | F51: FRASCO | H51: 830 | I51: =+G51*H51 -> 0
A52: 43 | B52: 2.5.2-5520.5 | C52: PROD. MEDICO/FARMACEUTICOS/LAB | D52: 252 | E52: VASELINA; TIPO: LIQUIDA, PRESENTACION: ENVASE X 1000 mL | F52: FRASCO | H52: 980 | I52: =+G52*H52 -> 0
A53: 44 | B53: 2.5.2-1901.128 | C53: PROD. MEDICO/FARMACEUTICOS/LAB | D53: 252 | E53: VITAMINAS; TIPO: MONODROGA, DROGA GENERICA: VITAMINA C 200 MG/ML, FORMA FARMACEUTICA: AMPOLLA, PRESENTACION: 5 ML | F53: AMPOLLA | H53: 65 | I53: =+G53*H53 -> 0
A54: 45 | B54: 2.5.2-1901.129 | C54: PROD. MEDICO/FARMACEUTICOS/LAB | D54: 252 | E54: VITAMINAS; TIPO: MONODROGA, DROGA GENERICA: VITAMINA C, FORMA FARMACEUTICA: COMPRIMIDOS, PRESENTACION: 10 COMPRIMIDOS | F54: CAJA | H54: 882.5 | I54: =+G54*H54 -> 0
A55: 46 | B55: 2.5.2-1901.130 | C55: PROD. MEDICO/FARMACEUTICOS/LAB | D55: 252 | E55: VITAMINAS; TIPO: MONODROGA, DROGA GENERICA: VITAMINA D3 2000 UI/ML, FORMA FARMACEUTICA: SOLUCION, PRESENTACION: 2 ML | F55: FRASCO | H55: 958 | I55: =+G55*H55 -> 0
B58: Especificidades: ITEMS N 12 : VITAMINAS; FORMA FARMACEUTICA: AMPOLLA, PRESENTACION: 2 mL, TIPO: BECOZYM NF AMPOLLAS
B59: Lugar de Entrega: …........................... DE XX:00 AXX:00HS., DEBIENDO CORRER LOS GASTOS DE FLETES, ACARREO, CARGA, DESCARGA Y SEGURO A CARGO DEL ADJUDICATARIO.
B61: Plazo de entrega: XXXX
B63: Calidad Minima esperada:
B64: Mantenimiento: 45 dias habiles
B65: Especificidades Item N° 13:
B66: Descripción técnica: TIPO: BECOZYM NF Comprimido
B68: Especificidades Item N° 11:
B69: Descripción técnica: COLUTORIO TIPO ELUDRIL CLASSIC X 200 ML
B71: Especificidades Item N° 21:
...

Sheet  NotaPedido
A1: NOTA DE PEDIDO | J1: N° | K1: xxx/2022
A3: JURISDICCIÓN: | D3: ='Necesidades Trimestrales'!C4 -> 040 - Ministerio de Salud
A4: SAF: | D4: ='Necesidades Trimestrales'!C5 -> 11/ 23/ 24 o 28- "…......."
A5: UNIDAD EJECUTORA: | D5: XXXX
A6: DEPENDENCIA SOLICITANTE: | D6: XXXX
A7: PERIODO UTILIZACIÓN: | D7: Semestral
A8: OBJETO: | D8: Adquisición de TRACTO ALIMENTARIO Y METABOLISMO / VITAMINAS Y OTROS /ANTIDIABETICOS E INSULINAS
A10: Ítem | B10: Codigo Item | C10: DESCRIPCIÓN | H10: Adjunta Detalle Técnico | I10: Unidad Medida | J10: Precio Unitario Estimado | K10: Cantidad Solicitada
A12: 1 | B12: ='Necesidades Trimestrales'!B10 -> 2.5.2-3259.11 | C12: ='Necesidades Trimestrales'!E10 -> DIGESTIVOS; TIPO: MONODROGA, DROGA GENERICA: ACIDO URSODESOXICOLICO, FORMA FARMACEUTICA: COMPRIMIDO, PRESENTACION: 150 MGR | H12: NO | I12: ='Necesidades Trimestrales'!F10 -> COMPRIMIDO | J12: ='Necesidades Trimestrales'!H10 -> 58.5 | K12: =+'Necesidades Trimestrales'!G10 -> 0
A13: 2 | B13: ='Necesidades Trimestrales'!B11 -> 2.5.2-3259.14 | C13: ='Necesidades Trimestrales'!E11 -> DIGESTIVOS; TIPO: MONODROGA, DROGA GENERICA: ACIDO URSODEOXICOLICO, FORMA FARMACEUTICA: COMPRIMIDO, PRESENTACION: 300 MGR | H13: NO | I13: ='Necesidades Trimestrales'!F11 -> COMPRIMIDO | J13: ='Necesidades Trimestrales'!H11 -> 146.93 | K13: =+'Necesidades Trimestrales'!G11 -> 0
A14: 3 | B14: ='Necesidades Trimestrales'!B12 -> 2.5.2-1841.33 | C14: ='Necesidades Trimestrales'!E12 -> ANTIACIDOS; TIPO: ASOCIACION, DROGA GENERICA: HIDROX. ALUM. + HIDROX. MAG., FORMA FARMACEUTICA: SUSPENSION, PRESENTACION: ENVASE X 160 ML | H14: NO | I14: ='Necesidades Trimestrales'!F12 -> FRASCO | J14: ='Necesidades Trimestrales'!H12 -> 260 | K14: =+'Necesidades Trimestrales'!G12 -> 0
A15: 4 | B15: ='Necesidades Trimestrales'!B13 -> 2.5.2-1843.63 | C15: ='Necesidades Trimestrales'!E13 -> ANTIESPASMODICOS; TIPO: MONODROGA, DROGA GENERICA: ATROPINA 1%, FORMA FARMACEUTICA: AMPOLLA, PRESENTACION: ENVASE X 1 mL | H15: NO | I15: ='Necesidades Trimestrales'!F13 -> AMPOLLA | J15: ='Necesidades Trimestrales'!H13 -> 50.4 | K15: =+'Necesidades Trimestrales'!G13 -> 0
A16: 5 | B16: ='Necesidades Trimestrales'!B14 -> 2.5.2-1843.51 | C16: ='Necesidades Trimestrales'!E14 -> ANTIESPASMODICOS; TIPO: MONODROGA, DROGA GENERICA: HIOSCINA N-BUTILBROMURO 20 MG, FORMA FARMACEUTICA: AMPOLLA, PRESENTACION: 1 ML | H16: NO | I16: ='Necesidades Trimestrales'!F14 -> AMPOLLA | J16: ='Necesidades Trimestrales'!H14 -> 65 | K16: =+'Necesidades Trimestrales'!G14 -> 0
A17: 6 | B17: ='Necesidades Trimestrales'!B15 -> 2.5.2-1843.1 | C17: ='Necesidades Trimestrales'!E15 -> ANTIESPASMODICOS; TIPO: MONODROGA, PRESENTACION: 10 mGr, FORMA FARMACEUTICA: COMPRIMIDO, DROGA GENERICA: HIOSCINA N-BUTILBROMURO | H17: NO | I17: ='Necesidades Trimestrales'!F15 -> COMPRIMIDO | J17: ='Necesidades Trimestrales'!H15 -> 11 | K17: =+'Necesidades Trimestrales'!G15 -> 0
A18: 7 | B18: ='Necesidades Trimestrales'!B16 -> 2.5.2-1724.57 | C18: ='Necesidades Trimestrales'!E16 -> ANALGESICOS ; TIPO: ASOCIACION, DROGA GENERICA: DIPIRONA+ HIOSCINA, FORMA FARMACEUTICA: AMPOLLA, PRESENTACION: AMPOLLA X 5 mL | H18: NO | I18: ='Necesidades Trimestrales'!F16 -> AMPOLLA | J18: ='Necesidades Trimestrales'!H16 -> 92 | K18: =+'Necesidades Trimestrales'!G16 -> 0
A19: 8 | B19: ='Necesidades Trimestrales'!B17 -> 2.5.2-1903.66 | C19: ='Necesidades Trimestrales'!E17 -> RECONSTITUYENTE GENERAL; TIPO: MONODROGA, DROGA GENERICA: CALCIO CARBONATO, FORMA FARMACEUTICA: COMPRIMIDO, PRESENTACION: 1250 mGr | H19: NO | I19: ='Necesidades Trimestrales'!F17 -> COMPRIMIDO | J19: ='Necesidades Trimestrales'!H17 -> 6.3 | K19: =+'Necesidades Trimestrales'!G17 -> 0
A20: 9 | B20: ='Necesidades Trimestrales'!B18 -> 2.5.2-8078.68 | C20: ='Necesidades Trimestrales'!E18 -> EXCIPIENTES; TIPO: MONODROGA, PRESENTACION: ENVASE X 1 Kg, COMPUESTO: CARBON ACTIVADO, CONCENTRACION/PUREZA: 100 % | H20: NO | I20: ='Necesidades Trimestrales'!F18 -> UNIDAD | J20: ='Necesidades Trimestrales'!H18 -> 1800 | K20: =+'Necesidades Trimestrales'!G18 -> 0
A21: 10 | B21: ='Necesidades Trimestrales'!B19 -> 2.5.2-1903.89 | C21: ='Necesidades Trimestrales'!E19 -> RECONSTITUYENTE GENERAL; TIPO: MONODROGA, DROGA GENERICA: CALCIO CARBONATO, FORMA FARMACEUTICA: COMPRIMIDO, PRESENTACION: 500 mGr | H21: NO | I21: ='Necesidades Trimestrales'!F19 -> COMPRIMIDO | J21: ='Necesidades Trimestrales'!H19 -> 5.98 | K21: =+'Necesidades Trimestrales'!G19 -> 0
A22: 11 | B22: ='Necesidades Trimestrales'!B20 -> 2.5.2-1723.176 | C22: ='Necesidades Trimestrales'!E20 -> ANTISEPTICOS LOCALES P/PERSONA; TIPO: MONODROGA, DROGA GENERICA: CLORHEXIDINA DIGLUCONATO 0,12 %, FORMA FARMACEUTICA: LIQUIDO, PRESENTACION: ENVASE X 200 ML | H22: SI | I22: ='Necesidades Trimestrales'!F20 -> FRASCO | J22: ='Necesidades Trimestrales'!H20 -> 1288 | K22: =+'Necesidades Trimestrales'!G20 -> 0
A23: 12 | B23: ='Necesidades Trimestrales'!B21 -> 2.5.2-1901.7 | C23: ='Necesidades Trimestrales'!E21 -> VITAMINAS; FORMA FARMACEUTICA: AMPOLLA, PRESENTACION: 2 mL, TIPO: MONODROGA, DROGA GENERICA: VITAMINA B | H23: SI | I23: ='Necesidades Trimestrales'!F21 -> AMPOLLA | J23: ='Necesidades Trimestrales'!H21 -> 110 | K23: =+'Necesidades Trimestrales'!G21 -> 0
... A46: 35 | B46: ='Necesidades Trimestrales'!B44 -> 2.5.2-6910.13 | C46: ='Necesidades Trimestrales'!E44 -> ANTIEMETICOS; TIPO: MONODROGA, DROGA GENERICA: ONDANSETRON X 8 mGr, FORMA FARMACEUTICA: AMPOLLA, PRESENTACION: ENVASE X 1 UN | H46: NO | I46: ='Necesidades Trimestrales'!F44 -> AMPOLLA | J46: ='Necesidades Trimestrales'!H44 -> 106.8 | K46: =+'Necesidades Trimestrales'!G44 -> 0
A47: 36 | B47: ='Necesidades Trimestrales'!B47 -> 2.5.2-2481.13 | C47: ='Necesidades Trimestrales'!E47 -> LAXANTES; TIPO: MONODROGA, DROGA GENERICA: PICOSULFATO SODICO, FORMA FARMACEUTICA: GOTAS, PRESENTACION: 15 mL | H47: NO | I47: ='Necesidades Trimestrales'!F47 -> GOTERO | J47: ='Necesidades Trimestrales'!H47 -> 885.68 | K47: =+'Necesidades Trimestrales'!G47 -> 0
A48: 37 | B48: ='Necesidades Trimestrales'!B48 -> 2.5.2-1901.127 | C48: ='Necesidades Trimestrales'!E48 -> VITAMINAS; TIPO: ASOCIACION, DROGA GENERICA: VIT.A +D+C, FORMA FARMACEUTICA: GOTA, PRESENTACION: 30 ML | H48: NO | I48: ='Necesidades Trimestrales'!F48 -> FRASCO | J48: ='Necesidades Trimestrales'!H48 -> 210 | K48: =+'Necesidades Trimestrales'!G48 -> 0
A49: 38 | B49: ='Necesidades Trimestrales'!B49 -> 2.5.2-1841.17 | C49: ='Necesidades Trimestrales'!E49 -> ANTIACIDOS; TIPO: MONODROGA, DROGA GENERICA: RANITIDINA, FORMA FARMACEUTICA: AMPOLLA, PRESENTACION: UNIDAD | H49: NO | I49: ='Necesidades Trimestrales'!F49 -> AMPOLLA | J49: ='Necesidades Trimestrales'!H49 -> 47.5 | K49: =+'Necesidades Trimestrales'!G49 -> 0
A50: 39 | B50: ='Necesidades Trimestrales'!B50 -> 2.5.2-1903.85 | C50: ='Necesidades Trimestrales'!E50 -> RECONSTITUYENTE GENERAL; TIPO: ASOCIACION, DROGA GENERICA: SALES DE REHIDRATACION, FORMA FARMACEUTICA: POLVO, PRESENTACION: SOBRE X 27,9 GR | H50: NO | I50: ='Necesidades Trimestrales'!F50 -> UNIDAD | J50: ='Necesidades Trimestrales'!H50 -> 88 | K50: =+'Necesidades Trimestrales'!G50 -> 0
A51: 40 | B51: ='Necesidades Trimestrales'!B51 -> 2.5.2-1841.13 | C51: ='Necesidades Trimestrales'!E51 -> ANTIACIDOS; TIPO: MONODROGA, DROGA GENERICA: SUCRALFATO, FORMA FARMACEUTICA: SOLUCION, PRESENTACION: ENVASE X 200 mL | H51: NO | I51: ='Necesidades Trimestrales'!F51 -> FRASCO | J51: ='Necesidades Trimestrales'!H51 -> 830 | K51: =+'Necesidades Trimestrales'!G51 -> 0
A52: 41 | B52: ='Necesidades Trimestrales'!B52 -> 2.5.2-5520.5 | C52: ='Necesidades Trimestrales'!E52 -> VASELINA; TIPO: LIQUIDA, PRESENTACION: ENVASE X 1000 mL | H52: NO | I52: ='Necesidades Trimestrales'!F52 -> FRASCO | J52: ='Necesidades Trimestrales'!H52 -> 980 | K52: =+'Necesidades Trimestrales'!G52 -> 0
A53: 42 | B53: ='Necesidades Trimestrales'!B53 -> 2.5.2-1901.128 | C53: ='Necesidades Trimestrales'!E53 -> VITAMINAS; TIPO: MONODROGA, DROGA GENERICA: VITAMINA C 200 MG/ML, FORMA FARMACEUTICA: AMPOLLA, PRESENTACION: 5 ML | H53: NO | I53: ='Necesidades Trimestrales'!F53 -> AMPOLLA | J53: ='Necesidades Trimestrales'!H53 -> 65 | K53: =+'Necesidades Trimestrales'!G53 -> 0
A54: 43 | B54: ='Necesidades Trimestrales'!B54 -> 2.5.2-1901.129 | C54: ='Necesidades Trimestrales'!E54 -> VITAMINAS; TIPO: MONODROGA, DROGA GENERICA: VITAMINA C, FORMA FARMACEUTICA: COMPRIMIDOS, PRESENTACION: 10 COMPRIMIDOS | H54: SI | I54: ='Necesidades Trimestrales'!F54 -> CAJA | J54: ='Necesidades Trimestrales'!H54 -> 882.5 | K54: =+'Necesidades Trimestrales'!G54 -> 0
A55: 44 | B55: ='Necesidades Trimestrales'!B55 -> 2.5.2-1901.130 | C55: ='Necesidades Trimestrales'!E55 -> VITAMINAS; TIPO: MONODROGA, DROGA GENERICA: VITAMINA D3 2000 UI/ML, FORMA FARMACEUTICA: SOLUCION, PRESENTACION: 2 ML | H55: NO | I55: ='Necesidades Trimestrales'!F55 -> FRASCO | J55: ='Necesidades Trimestrales'!H55 -> 958 | K55: =+'Necesidades Trimestrales'!G55 -> 0
A56: Costo total estimado: xxxxxxxxxxxxxxxxxxxx con 00/100. | J56: =SUMPRODUCT(J12:J55,K12:K55) -> 0

Sheet Autor Gastar
A1: EJERCICIO: | D1: ='Necesidades Trimestrales'!C6 -> 2022 | P1: AUTORIZACION PARA GASTAR
A4: JURISDICCIÓN: | G4: =' NotaPedido'!D3 -> 040 - Ministerio de Salud
A5: SAF: | G5: =' NotaPedido'!D4 -> 11/ 23/ 24 o 28- "…......."
A6: UNIDAD EJECUTORA: | G6: =' NotaPedido'!D5 -> XXXX
A7: DEPENDENCIA SOLICITANTE: | G7: =' NotaPedido'!D6 -> XXXX
A8: AUTORIZACIÓN:
A9: Señor Jefe de Servicio Administrativo Financiero:
A10: ="Autorizo la realización de los trámites correspondientes, a fin de proveer a este Organismo los bienes y/o servicios que se detallan en Nota de Pedido N° " & ' NotaPedido'!K1&", afectando la erogación resultante a los créditos presupuestarios aprobados a favor de esta Unidad Ejecutora, conforme al siguiente detalle:" -> Autorizo la realización de los trámites correspondientes, a fin de proveer a este Organismo los bienes y/o servicios que se detallan en Nota de Pedido N° xxx/2022, afectando la erogación resultante a los créditos presupuestarios aprobados a favor de esta Unidad Ejecutora, conforme al siguiente detalle:
A12: IMPUTACIÓN PRESUPUESTARIA
A13: CÓDIGO | O13: DENOMINACIÓN DE LA PARTIDA PRESUPUESTARIA | Q13: IMPORTE
A14: PR | B14: SB | C14: PY | D14: AC | E14: OB | F14: UG | G14: FIN | H14: FUN | I14: I | J14: P | K14: P | L14: SubP | M14: M | N14: FF
F15: 4901 | G15: 3 | H15: 310 | I15: 2 | J15: 5 | K15: 2 | M15: 1 | N15: 1.1 | O15: Product. Farmaceut. Y Medicinales
A23: TOTAL DE PESOS: xxxxxxxxxxxxxxx con 00/100. | Q23: =SUM(Q15:Q22) -> 0
A25: JUSTIFICACIÓN:
A26: Para la adquisición de .... … destinados al servico de …... del Hospital …...............
