Workbook

Sheet INFORMATICA
B2: Pedido de Necesidades Trimestrales
A4: JURISDICCION: | C4: 12 - Ministerio de Trabajo
A5: SAF N°: | C5: 22 - SECRETARIA DE ADMINISTRACION - MINISTERIO DE TRABAJO Y RECURSOS HUMANOS
A6: EJERCICIO: | C6: 2021
A7: TRIMESTRE: | C7: 4
A9: ID | B9: CODIGO ITEM | C9: RUBRO DE COMPRA | D9: I.P.P. | E9: DESCRIPCION | F9: UNIDAD DE MEDIDA | G9: CANTIDAD | H9: PRECIO UNITARIO ESTIMADO | I9: IMPORTE TOTAL ESTIMADO
A10: 1 | B10: 4.3.6-3351.2 | C10: INFORMATICA | D10: 2.9.6 | E10: KIT PERIFERICOS P/PC; COMPONENTES: TECLADO Y MOUSE | F10: UNIDAD | G10: 40 | H10: 1326 | I10: =+H10*G10 -> 53040
A11: 2 | B11: 2.9.6-1583.28 | C11: INFORMATICA | D11: =+LEFT(B11,5) -> 2.9.6 | E11: TECLADOS; TECLAS: 104, EXPANDIDO: SIN VALOR, CONEXIÓN: USB, JOYSTICK: SIN, ERGONOMICO: SIN VALOR, TIPO DE CONEXION: USB, TIPO: SIN VALOR | F11: UNIDAD | G11: 20 | H11: 719 | I11: =+H11*G11 -> 14380
A12: 3 | B12: 2.9.6-1576.27 | C12: INFORMATICA | D12: =+LEFT(B12,5) -> 2.9.6 | E12: MOUSE; TIPO: OPTICO C/RUEDA SCROLL, CANTIDAD DE BOTONES: 2, TIPO DE CONEXION: USB | F12: UNIDAD | G12: 20 | H12: 329 | I12: =+H12*G12 -> 6580
A13: 4 | B13: 2.9.6-6417.17 | C13: REPUESTOS | D13: =+LEFT(B13,5) -> 2.9.6 | E13: REP.Y ACC.P/COMPUTADORA; MARCA EQUIPO: GENERICO, MODELO EQUIPO: GENERICO, TIPO: ESCRITORIO, ELEMENTO: FUENTE DE ALIMENTACION | F13: UNIDAD | G13: 40 | H13: 1683 | I13: =+H13*G13 -> 67320
A14: 5 | B14: 2.9.3-4210.39 | C14: ELECTRICIDAD Y TELEFONIA | D14: =+LEFT(B14,5) -> 2.9.3 | E14: CABLES CONECTORES; FUNCION: HDMI, REVESTIMIENTO: GOMA, TRANSMISION: DIGITAL | F14: UNIDAD | G14: 10 | H14: 300 | I14: =+H14*G14 -> 3000
A15: 6 | B15: 2.9.3-5901.24 | C15: ELECTRICIDAD Y TELEFONIA | D15: =+LEFT(B15,5) -> 2.9.3 | E15: CABLES P/VIDEO; LARGO: 2 M, CONECTOR EXTREMO 1: VGA MACHO, CONECTOR EXTREMO 2: VGA MACHO | F15: UNIDAD | G15: 10 | H15: 450 | I15: =+H15*G15 -> 4500
A16: 7 | B16: 2.9.2-9597.5 | C16: LIBRERIA,PAP. Y UTILES OFICINA | D16: 2.9.6 | E16: MEMORIAS USB; CAPACIDAD: 32 Gb, TIPO: PEN DRIVE | F16: UNIDAD | G16: 10 | H16: 747 | I16: =+H16*G16 -> 7470
A17: 8 | B17: 4.3.6-6160.4 | C17: INFORMATICA | D17: =+LEFT(B17,5) -> 4.3.6 | E17: COMPUTADORAS; CODIGO ETAP: PC-004, TIPO: DE ESCRITORIO AVANZADA, VERSION ETAP: VERANO 2001( V 6.0 ) | F17: UNIDAD | G17: 14 | H17: 80000 | I17: =+H17*G17 -> 1120000
A18: 9 | B18: 4.3.6-9181.30 | C18: EQUIPO DE OFICINA Y MUEBLES | D18: =+LEFT(B18,5) -> 4.3.6 | E18: ESCANERS; TIPO: ESCRITORIO, RESOLUCION: 1200 X 1200 DPI, ALIMENTACION: 220 V | F18: UNIDAD | G18: 2 | H18: 95000 | I18: =+H18*G18 -> 190000
A19: 10 | B19: 4.3.5-1615.82 | C19: EQUIPOS | D19: =+LEFT(B19,5) -> 4.3.5 | E19: PROYECTORES; PANTALLA: SIN, RESOLUCION: 1920 X 1080 PXL, LENTE: ZOOM ENFOQUE | F19: UNIDAD | G19: 1 | H19: 46900 | I19: =+H19*G19 -> 46900
A20: COSTO ESTIMADO TOTAL: UN MILLON QUINIENTOS TRECE MIL CIENTO NOVENTA CON 00/100 | I20: =SUM(I10:I19) -> 1513190
B23: Especificidades Ítem N° 01:
B25: Descripción técnica
C26: Kits teclado y mouse USB. Teclado con teclas numéricas. Mouse Óptico. SIMILAR Marca Logitech o Genius.
B28: Especificidades Ítem N° 02:
B30: Descripción técnica
C31: Teclados QWERTY. Con teclado numérico. Tipo de teclado: membrana. Tecla cilíndrica. Con conector USB. Similar a teclado Genius KB-116.
B33: Especificidades Ítem N° 03:
B35: Descripción técnica
C36: Mouses USB. Rueda de desplazamiento. 2 botones. Con sensor óptico. Resolución de 1000dpi. Similar a Genius DX-110.
B38: Especificidades Ítem N° 04:
B40: Descripción técnica
C41: Fuentes de alimentación para PC. Potencia de salida de 600W. Fuente de tipo ATX. Refrigeración por aire.
B42: Especificidades Ítem N° 05:
B44: Descripción técnica
C45: Cables HDMI. V1.4. longitud de cable 1.5m.
B47: Especificidades Ítem N° 06:
B49: Descripción técnica
C50: Cables para monitor VGA.
B52: Especificidades Ítem N° 07:
B54: Descripción técnica
C55: Pendrives USB 3.0. Capacidad 32GB
B57: Especificidades Ítem N° 08:
B59: Descripción técnica
...

Sheet  NotaPedido
A1: NOTA DE PEDIDO
A3: JURISDICCIÓN: | D3: =+INFORMATICA!C4 -> 12 - Ministerio de Trabajo
A4: SAF: | D4: =+INFORMATICA!C5 -> 22 - SECRETARIA DE ADMINISTRACION - MINISTERIO DE TRABAJO Y RECURSOS HUMANOS
A5: UNIDAD EJECUTORA: | D5: Ministerio de Trabajo y Recursos Humanos
A6: DEPENDENCIA SOLICITANTE: | D6: Ministerio de Trabajo y Recursos Humanos
A7: PERIODO UTILIZACIÓN: | D7: 5 años
A8: OBJETO: | D8: Adquisición de Computadoras mas los implementos informaticos para este Ministerio.
A10: Ítem | B10: Codigo Item | C10: DESCRIPCIÓN | H10: Adjunta Detalle Técnico | I10: Unidad Medida | J10: Precio Unitario Estimado | K10: Cantidad Solicitada
A12: =+INFORMATICA!A10 -> 1 | B12: =+INFORMATICA!B10 -> 4.3.6-3351.2 | C12: =+INFORMATICA!E10 -> KIT PERIFERICOS P/PC; COMPONENTES: TECLADO Y MOUSE | H12: SI | I12: =+INFORMATICA!F10 -> UNIDAD | J12: =+INFORMATICA!H10 -> 1326 | K12: =+INFORMATICA!G10 -> 40 | M12: =J12*K12 -> 53040
A13: =+INFORMATICA!A11 -> 2 | B13: =+INFORMATICA!B11 -> 2.9.6-1583.28 | C13: =+INFORMATICA!E11 -> TECLADOS; TECLAS: 104, EXPANDIDO: SIN VALOR, CONEXIÓN: USB, JOYSTICK: SIN, ERGONOMICO: SIN VALOR, TIPO DE CONEXION: USB, TIPO: SIN VALOR | H13: SI | I13: =+INFORMATICA!F11 -> UNIDAD | J13: =+INFORMATICA!H11 -> 719 | K13: =+INFORMATICA!G11 -> 20 | M13: =J13*K13 -> 14380
A14: =+INFORMATICA!A12 -> 3 | B14: =+INFORMATICA!B12 -> 2.9.6-1576.27 | C14: =+INFORMATICA!E12 -> MOUSE; TIPO: OPTICO C/RUEDA SCROLL, CANTIDAD DE BOTONES: 2, TIPO DE CONEXION: USB | H14: SI | I14: =+INFORMATICA!F12 -> UNIDAD | J14: =+INFORMATICA!H12 -> 329 | K14: =+INFORMATICA!G12 -> 20 | M14: =J14*K14 -> 6580
A15: =+INFORMATICA!A13 -> 4 | B15: =+INFORMATICA!B13 -> 2.9.6-6417.17 | C15: =+INFORMATICA!E13 -> REP.Y ACC.P/COMPUTADORA; MARCA EQUIPO: GENERICO, MODELO EQUIPO: GENERICO, TIPO: ESCRITORIO, ELEMENTO: FUENTE DE ALIMENTACION | H15: SI | I15: =+INFORMATICA!F13 -> UNIDAD | J15: =+INFORMATICA!H13 -> 1683 | K15: =+INFORMATICA!G13 -> 40 | M15: =J15*K15 -> 67320
A16: =+INFORMATICA!A14 -> 5 | B16: =+INFORMATICA!B14 -> 2.9.3-4210.39 | C16: =+INFORMATICA!E14 -> CABLES CONECTORES; FUNCION: HDMI, REVESTIMIENTO: GOMA, TRANSMISION: DIGITAL | H16: SI | I16: =+INFORMATICA!F14 -> UNIDAD | J16: =+INFORMATICA!H14 -> 300 | K16: =+INFORMATICA!G14 -> 10 | M16: =J16*K16 -> 3000
A17: =+INFORMATICA!A15 -> 6 | B17: =+INFORMATICA!B15 -> 2.9.3-5901.24 | C17: =+INFORMATICA!E15 -> CABLES P/VIDEO; LARGO: 2 M, CONECTOR EXTREMO 1: VGA MACHO, CONECTOR EXTREMO 2: VGA MACHO | H17: SI | I17: =+INFORMATICA!F15 -> UNIDAD | J17: =+INFORMATICA!H15 -> 450 | K17: =+INFORMATICA!G15 -> 10 | M17: =J17*K17 -> 4500
A18: =+INFORMATICA!A16 -> 7 | B18: =+INFORMATICA!B16 -> 2.9.2-9597.5 | C18: =+INFORMATICA!E16 -> MEMORIAS USB; CAPACIDAD: 32 Gb, TIPO: PEN DRIVE | H18: SI | I18: =+INFORMATICA!F16 -> UNIDAD | J18: =+INFORMATICA!H16 -> 747 | K18: =+INFORMATICA!G16 -> 10 | M18: =J18*K18 -> 7470
A19: =+INFORMATICA!A17 -> 8 | B19: =+INFORMATICA!B17 -> 4.3.6-6160.4 | C19: =+INFORMATICA!E17 -> COMPUTADORAS; CODIGO ETAP: PC-004, TIPO: DE ESCRITORIO AVANZADA, VERSION ETAP: VERANO 2001( V 6.0 ) | H19: SI | I19: =+INFORMATICA!F17 -> UNIDAD | J19: =+INFORMATICA!H17 -> 80000 | K19: =+INFORMATICA!G17 -> 14 | M19: =J19*K19 -> 1120000
A20: =+INFORMATICA!A18 -> 9 | B20: =+INFORMATICA!B18 -> 4.3.6-9181.30 | C20: =+INFORMATICA!E18 -> ESCANERS; TIPO: ESCRITORIO, RESOLUCION: 1200 X 1200 DPI, ALIMENTACION: 220 V | H20: SI | I20: =+INFORMATICA!F18 -> UNIDAD | J20: =+INFORMATICA!H18 -> 95000 | K20: =+INFORMATICA!G18 -> 2 | M20: =J20*K20 -> 190000
A21: =+INFORMATICA!A19 -> 10 | B21: =+INFORMATICA!B19 -> 4.3.5-1615.82 | C21: =+INFORMATICA!E19 -> PROYECTORES; PANTALLA: SIN, RESOLUCION: 1920 X 1080 PXL, LENTE: ZOOM ENFOQUE | H21: SI | I21: =+INFORMATICA!F19 -> UNIDAD | J21: =+INFORMATICA!H19 -> 46900 | K21: =+INFORMATICA!G19 -> 1 | M21: =J21*K21 -> 46900
A22: =+INFORMATICA!A20 -> COSTO ESTIMADO TOTAL: UN MILLON QUINIENTOS TRECE MIL CIENTO NOVENTA CON 00/100 | J22: =+INFORMATICA!I20 -> 1513190 | M22: =SUM(M12:M21) -> 1513190

Sheet Autor Gastar
A1: EJERCICIO: | D1: =+INFORMATICA!C6 -> 2021 | P1: AUTORIZACION PARA GASTAR
A4: JURISDICCIÓN: | G4: =' NotaPedido'!D3 -> 12 - Ministerio de Trabajo
A5: SAF: | G5: =' NotaPedido'!D4 -> 22 - SECRETARIA DE ADMINISTRACION - MINISTERIO DE TRABAJO Y RECURSOS HUMANOS
A6: UNIDAD EJECUTORA: | G6: Ministerio de Trabajo y Recursos Humanos
A7: DEPENDENCIA SOLICITANTE: | G7: =' NotaPedido'!D6 -> Ministerio de Trabajo y Recursos Humanos
A8: AUTORIZACIÓN:
A9: Señor Jefe de Servicio Administrativo Financiero:
A10: Autorizo la realización de los trámites correspondientes, a fin de proveer a este Organismo los bienes y/o servicios que se detallan en Nota de Pedido, afectando la erogación resultante a los créditos presupuestarios aprobados a favor de esta Unidad Ejecutora, conforme al siguiente detalle
A12: IMPUTACIÓN PRESUPUESTARIA
A13: CÓDIGO | O13: DENOMINACIÓN DE LA PARTIDA PRESUPUESTARIA | Q13: IMPORTE
A14: PR | B14: SB | C14: PY | D14: AC | E14: OB | F14: UG | G14: FIN | H14: FUN | I14: I | J14: P | K14: P | L14: SubP | M14: M | N14: FF
A15: 6 | B15: 0 | C15: 0 | D15: 3 | E15: 0 | F15: 4901 | G15: 1 | H15: 8 | I15: 2 | J15: 9 | K15: 3 | L15: 0 | M15: 1 | N15: 1.1 | O15: Útiles y Materiales Eléctricos | Q15: =+INFORMATICA!I14+INFORMATICA!I15 -> 7500
A16: 1 | B16: 0 | C16: 0 | D16: 1 | E16: 0 | F16: 4901 | G16: 3 | H16: 6 | I16: 2 | J16: 9 | K16: 6 | L16: 0 | M16: 1 | N16: 1.1 | O16: Repuestos y Accesorios | Q16: 18790
A17: 2 | B17: 0 | C17: 0 | D17: 1 | E17: 0 | F17: 4901 | G17: 3 | H17: 6 | I17: 2 | J17: 9 | K17: 6 | L17: 0 | M17: 1 | N17: 1.1 | O17: Repuestos y Accesorios | Q17: 91000
A18: 3 | B18: 0 | C18: 0 | D18: 1 | E18: 0 | F18: 4901 | G18: 1 | H18: 3 | I18: 2 | J18: 9 | K18: 6 | L18: 0 | M18: 1 | N18: 1.1 | O18: Repuestos y Accesorios | Q18: 39000
A19: 1 | B19: 0 | C19: 0 | D19: 1 | E19: 0 | F19: 4901 | G19: 3 | H19: 6 | I19: 4 | J19: 3 | K19: 5 | L19: 0 | M19: 1 | N19: 1.1 | O19: Equipo Educacional y Recreativo | Q19: =+INFORMATICA!I19 -> 46900
A20: 1 | B20: 0 | C20: 0 | D20: 1 | E20: 0 | F20: 4901 | G20: 3 | H20: 6 | I20: 4 | J20: 3 | K20: 6 | L20: 0 | M20: 1 | N20: 1.1 | O20: Equipos para Computación | Q20: =+INFORMATICA!I18+INFORMATICA!I17 -> 1310000
A21: =+' NotaPedido'!A22:I22 -> COSTO ESTIMADO TOTAL: UN MILLON QUINIENTOS TRECE MIL CIENTO NOVENTA CON 00/100 | Q21: =SUM(Q15:Q20) -> 1513190
A23: JUSTIFICACIÓN:
A24: =' NotaPedido'!D8 -> Adquisición de Computadoras mas los implementos informaticos para este Ministerio.
