Workbook

Sheet Necesidades Trimestrales
B2: Pedido de Necesidades Trimestrales
A4: JURISDICCION: | C4: 90 - Ministerio de Seguridad
A5: SAF N°: | C5: 7 - Direccion de Administracion de la Policia de la Provincia de Catamarca
A6: EJERCICIO: | C6: 2021
A7: TRIMESTRE: | C7: 1
A9: ID | B9: CODIGO ITEM | C9: RUBRO DE COMPRA | D9: I.P.P. | E9: DESCRIPCION | F9: UNIDAD DE MEDIDA | G9: CANTIDAD | H9: PRECIO UNITARIO ESTIMADO | I9: IMPORTE TOTAL ESTIMADO
A10: 01 | B10: 2.1.1-481.38 | C10: ALIMENTOS | D10: 2.1.1 | E10: AZUCARES; TIPO: "A" COMUN, ESTADO: MOLIDA, PESO: 1 Kg, MATERIAL ENVASE: PLASTICO, CERTIFICADO FORESTAL (GFS): SIN, ELEM. TRANSPORTE: SIN, MATERIAL ELEM. TRANSPORTE: SIN | F10: BOLSA | G10: 2000 | H10: 89 | I10: =(G10*H10) -> 178000
A11: 02 | B11: 2.1.1-454.25 | C11: ALIMENTOS | D11: 2.1.1 | E11: YERBAS; PALO: CON, PESO: 1 Kg, MATERIAL ENVASE : PAPEL, CERTIFICADO FORESTAL (GFS): CON, ELEM. TRANSPORTE: SIN, MATERIAL ELEM. TRANSPORTE: SIN, LIBRE DE GLUTEN: SI | F11: PAQUETE | G11: 400 | H11: 490 | I11: =(G11*H11) -> 196000
A12: 03 | B12: 2.1.1-489.136 | C12: ALIMENTOS | D12: 2.1.1 | E12: ESPECIAS; TIPO: PIMENTON EXTRA DULCE, PRESENTACION: BOLSA X 1 Kg | F12: BOLSA | G12: 60 | H12: 990 | I12: =(G12*H12) -> 59400
A13: 04 | B13: 2.1.1-489.66 | C13: ALIMENTOS | D13: 2.1.1 | E13: ESPECIAS; TIPO: OREGANO, PRESENTACION: BOLSA DE 1 Kg | F13: BOLSA | G13: 30 | H13: 1900 | I13: =(G13*H13) -> 57000
A14: 05 | B14: 2.1.1-489.109 | C14: ALIMENTOS | D14: 2.1.1 | E14: ESPECIAS; TIPO: PROVENZAL, PRESENTACION: PAQUETE X 1 Kg | F14: PAQUETE | G14: 30 | H14: 1900 | I14: =(G14*H14) -> 57000
A15: 06 | B15: 2.1.1-489.165 | C15: ALIMENTOS | D15: 2.1.1 | E15: ESPECIAS; TIPO: PIMIENTA BLANCA MOLIDA, PRESENTACION: ENVASE X 1 Kg, LIBRE DE GLUTEN: NO | F15: UNIDAD | G15: 20 | H15: 1900 | I15: =(G15*H15) -> 38000
A16: 07 | B16: 2.1.1-489.119 | C16: ALIMENTOS | D16: 2.1.1 | E16: ESPECIAS; TIPO: COMINO, PRESENTACION: BOLSA X 1 Kg | F16: BOLSA | G16: 20 | H16: 1100 | I16: =(G16*H16) -> 22000
A17: 08 | B17: 2.1.1-489.68 | C17: ALIMENTOS | D17: 2.1.1 | E17: ESPECIAS; PRESENTACION: BOLSA DE 1 Kg, TIPO: AJI MOLIDO | F17: BOLSA | G17: 20 | H17: 1490 | I17: =(G17*H17) -> 29800
A18: 09 | B18: 2.1.1-439.67 | C18: ALIMENTOS | D18: 2.1.1 | E18: ACEITES COMESTIBLES; TIPO: GIRASOL, PRESENTACION: ENVASE X 900 CM3, MATERIAL ENVASE: PLASTICO 1 (PET), ELEM. TRANSPORTE: SIN, MATERIAL ELEM. TRANSPORTE : SIN, LIBRE DE GLUTEN: NO | F18: BOTELLA | G18: 400 | H18: 198 | I18: =(G18*H18) -> 79200
A19: 10 | B19: 2.1.1-708.23 | C19: ALIMENTOS | D19: 2.1.1 | E19: CONSERVAS PESCADO Y FRUTOS MAR; ESTADO: AL NATURAL, PESO: 380 GR, ENVASE: LATA, TIPO: CABALLA, ESPECIE: CABALLA | F19: LATA | G19: 200 | H19: 215 | I19: =(G19*H19) -> 43000 | L19: =40*12 -> 480
A20: 11 | B20: 2.1.1-2868.56 | C20: ALIMENTOS | D20: 2.1.1 | E20: FIDEOS SECOS; VARIEDAD: CABELLO DE ANGEL, RELLENO: SIN, PRESENTACION: ENVASE X 500 GR, MATERIAL ENVASE: PVC, ELEM. TRANSPORTE: CAJA, MATERIAL ELEM. TRANSPORTE: CARTON, CERTIFICADO FORESTAL (GFS): SIN, LIBRE DE GLUTEN: NO | F20: PAQUETE | G20: 960 | H20: =L20 -> 65.833333 | I20: =(G20*H20) -> 63200 | L20: =790/12 -> 65.833333
A21: 12 | B21: 2.1.1-2868.61 | C21: ALIMENTOS | D21: 2.1.1 | E21: FIDEOS SECOS; VARIEDAD: MOÑOS BLANCOS, RELLENO: SIN, PRESENTACION: ENVASE X 500 GR, MATERIAL ENVASE: PLASTICO 1 (PET), ELEM. TRANSPORTE: CAJA, MATERIAL ELEM. TRANSPORTE: SIN, CERTIFICADO FORESTAL (GFS): SIN, LIBRE DE GLUTEN: NO | F21: PAQUETE | G21: 960 | H21: =L20 -> 65.833333 | I21: =(G21*H21) -> 63200
A22: 13 | B22: 2.1.1-2868.59 | C22: ALIMENTOS | D22: 2.1.1 | E22: FIDEOS SECOS; VARIEDAD: MOSTACHOLES, RELLENO: SIN, PRESENTACION: ENVASE X 500 GR, MATERIAL ENVASE: PVC, ELEM. TRANSPORTE: CAJA, MATERIAL ELEM. TRANSPORTE: CARTON, CERTIFICADO FORESTAL (GFS): SIN, LIBRE DE GLUTEN: NO | F22: PAQUETE | G22: 960 | H22: =L20 -> 65.833333 | I22: =(G22*H22) -> 63200
A23: 14 | B23: 2.1.1-2868.58 | C23: ALIMENTOS | D23: 2.1.1 | E23: FIDEOS SECOS; VARIEDAD: MUNICION, RELLENO: SIN, PRESENTACION: ENVASE X 500 GR, MATERIAL ENVASE: PVC, ELEM. TRANSPORTE: CAJA, MATERIAL ELEM. TRANSPORTE: CARTON, CERTIFICADO FORESTAL (GFS): SIN, LIBRE DE GLUTEN: NO | F23: PAQUETE | G23: 960 | H23: =L20 -> 65.833333 | I23: =(G23*H23) -> 63200
A24: 15 | B24: 2.1.1-2868.65 | C24: ALIMENTOS | D24: 2.1.1 | E24: FIDEOS SECOS; VARIEDAD: SPAGHETTI VERDES, RELLENO: SIN, PRESENTACION: ENVASE X 5 Kg, MATERIAL ENVASE: PLASTICO 1 (PET), ELEM. TRANSPORTE: SIN, MATERIAL ELEM. TRANSPORTE: SIN, CERTIFICADO FORESTAL (GFS): SIN, LIBRE DE GLUTEN: NO | F24: PAQUETE | G24: 960 | H24: =L20 -> 65.833333 | I24: =(G24*H24) -> 63200
A25: 16 | B25: 2.1.1-2868.85 | C25: ALIMENTOS | D25: 2.1.1 | E25: FIDEOS SECOS; VARIEDAD: TAGLIATELLE, RELLENO: SIN, PRESENTACION: ENVASE X 500 GR, MATERIAL ENVASE: POLIETILENO, ELEM. TRANSPORTE: SIN, MATERIAL ELEM. TRANSPORTE: SIN, CERTIFICADO FORESTAL (GFS): SIN, LIBRE DE GLUTEN: NO | F25: PAQUETE | G25: 960 | H25: =L20 -> 65.833333 | I25: =(G25*H25) -> 63200
A26: 17 | B26: 2.1.1-2868.45 | C26: ALIMENTOS | D26: 2.1.1 | E26: FIDEOS SECOS; VARIEDAD: TALLARINES AMARILLOS, RELLENO: SIN, PRESENTACION: ENVASE X 5 Kg, MATERIAL ENVASE: CARTON, ELEM. TRANSPORTE: SIN, MATERIAL ELEM. TRANSPORTE: SIN, CERTIFICADO FORESTAL (GFS): CON, LIBRE DE GLUTEN: NO | F26: PAQUETE | G26: 960 | H26: =L20 -> 65.833333 | I26: =(G26*H26) -> 63200
A27: 18 | B27: 2.1.1-2868.53 | C27: ALIMENTOS | D27: 2.1.1 | E27: FIDEOS SECOS; VARIEDAD: TIRABUZON, RELLENO: SIN, PRESENTACION: ENVASE X 500 GR, MATERIAL ENVASE: PLASTICO 1 (PET), ELEM. TRANSPORTE: SIN, MATERIAL ELEM. TRANSPORTE: SIN, CERTIFICADO FORESTAL (GFS): SIN, LIBRE DE GLUTEN: NO | F27: PAQUETE | G27: 960 | H27: =L20 -> 65.833333 | I27: =(G27*H27) -> 63200
A28: 19 | B28: 2.1.1-435.60 | C28: ALIMENTOS | D28: 2.1.1 | E28: ARROZ; TIPO GRANO: LARGO-FINO, TIPO: BLANCO, PROCESO: SIN CASCARA, PRESENTACION: BOLSA X 1 Kg, MATERIAL ENVASE: PLASTICO, CERTIFICADO FORESTAL (GFS): SIN, ELEM. TRANSPORTE: SIN, MATERIAL ELEM. TRANSPORTE: SIN, LIBRE DE GLUTEN: SI | F28: BOLSA | G28: 400 | H28: 145 | I28: =(G28*H28) -> 58000
A29: 20 | B29: 2.1.1-482.69 | C29: ALIMENTOS | D29: 2.1.1 | E29: HARINAS; TIPO: MAIZ, PRESENTACION: ENVASE X 1 Kg, MATERIAL ENVASE: PAPEL, CERTICADO FORESTAL (GFS): SIN, ELEM. TRANSPORTE: SIN, MATERIAL ELEM. TRANSPORTE: SIN, LIBRE DE GLUTEN: NO | F29: PAQUETE | G29: 162 | H29: 99 | I29: =(G29*H29) -> 16038
A30: 21 | B30: 2.1.1-2616.6 | C30: ALIMENTOS | D30: 2.1.1 | E30: MAIZ; TIPO: BLANCO, PRESENTACION: PAQUETE X 1 Kg, FORMA DE PRESENTACION: PISADO | F30: PAQUETE | G30: 100 | H30: 170 | I30: =(G30*H30) -> 17000
A31: 22 | B31: 2.1.1-6547.56 | C31: ALIMENTOS | D31: 2.1.1 | E31: LEGUMBRES; VARIEDAD: POROTO BLANCO OVAL, ESTADO: SECO, PRESENTACION: BOLSA, PESO: 500 GR | F31: BOLSA | G31: 60 | H31: 195 | I31: =(G31*H31) -> 11700
A32: 23 | B32: 2.1.1-514.15 | C32: ALIMENTOS | D32: 2.1.1 | E32: SAL DE MESA; CONSISTENCIA: GRUESA, ENVASE: BOLSA, PESO: 1 Kg, TIPO: SIN VALOR | F32: BOLSA | G32: 160 | H32: 140 | I32: =(G32*H32) -> 22400
A33: 24 | B33: 2.1.1-514.17 | C33: ALIMENTOS | D33: 2.1.1 | E33: SAL DE MESA; CONSISTENCIA: FINA, ENVASE: BOLSA, PESO: 1 Kg, TIPO: SIN VALOR | F33: BOLSA | G33: 80 | H33: 120 | I33: =(G33*H33) -> 9600
A34: 25 | B34: 2.1.1-482.77 | C34: ALIMENTOS | D34: 2.1.1 | E34: HARINAS; TIPO: DE TRIGO 0000, PRESENTACION: ENVASE X 1 Kg, MATERIAL ENVASE: PAPEL, CERTICADO FORESTAL (GFS): SIN, ELEM. TRANSPORTE: SIN, MATERIAL ELEM. TRANSPORTE: SIN, LIBRE DE GLUTEN: NO | F34: PAQUETE | G34: 160 | H34: 115 | I34: =(G34*H34) -> 18400
A35: 26 | B35: 2.1.1-482.81 | C35: ALIMENTOS | D35: 2.1.1 | E35: HARINAS; TIPO: LEUDANTE, PRESENTACION: ENVASE X 1 Kg, MATERIAL ENVASE: PAPEL, CERTICADO FORESTAL (GFS): SIN, ELEM. TRANSPORTE: SIN, MATERIAL ELEM. TRANSPORTE: SIN, LIBRE DE GLUTEN: NO | F35: PAQUETE | G35: 300 | H35: 120 | I35: =(G35*H35) -> 36000
A36: 27 | B36: 2.1.1-6546.4 | C36: ALIMENTOS | D36: 2.1.1 | E36: VERDURAS Y HORTALIZAS; VARIEDAD: TOMATE PERITA, ESTADO: TRITURADO, PRESENTACION: BOTELLA, PESO: 950 GR | F36: BOTELLA | G36: 200 | H36: 198 | I36: =(G36*H36) -> 39600
A37: 28 | B37: 2.1.1-509.10 | C37: ALIMENTOS | D37: 2.1.1 | E37: PURE; TIPO: DE TOMATE, ENVASE: CAJA DE CARTON, PESO: 530 GR | F37: CAJA | G37: 400 | H37: 79 | I37: =(G37*H37) -> 31600
A38: 29 | B38: 2.1.1-519.27 | C38: ALIMENTOS | D38: 2.1.1 | E38: VINAGRES; TIPO: VINO, PRESENTACION: ENVASE X 1 L, MATERIAL ENVASE: PLASTICO 1 (PET), LIBRE DE GLUTEN: NO | F38: BOTELLA | G38: 100 | H38: 115 | I38: =(G38*H38) -> 11500
A39: 30 | B39: 2.1.1-709.6 | C39: ALIMENTOS | D39: 2.1.1 | E39: CAFE; ESTADO: MOLIDO, ENVASE: PAQUETE, PROCESO: TORRADO C/AZUCAR, CONTENIDO: 500 GR, TIPO: SIN VALOR, PRESENTACION: ENVASE X 500 GR | F39: PAQUETE | G39: 80 | H39: 475 | I39: =(G39*H39) -> 38000
... A73: 64 | B73: 2.1.1-6539.157 | C73: ALIMENTOS | D73: 2.1.1 | E73: FRUTAS; VARIEDAD: PERA, ESTADO: NATURAL, PRESENTACION: ENVASE X 20 Kg | F73: CAJON | G73: 20 | H73: 3200 | I73: =(G73*H73) -> 64000
I74: =SUM(I10:I73) -> 4950118
B75: Especificidades de todos los Items.
B77: Descripción técnica
...

Sheet  NotaPedido
A1: NOTA DE PEDIDO | J1: N° | K1: 02/2021
A3: JURISDICCIÓN: | D3: ='Necesidades Trimestrales'!C4 -> 90 - Ministerio de Seguridad
A4: SAF: | D4: ='Necesidades Trimestrales'!C5 -> 7 - Direccion de Administracion de la Policia de la Provincia de Catamarca
A5: UNIDAD EJECUTORA: | D5: Policia de la Provincia de Catamarca
A6: DEPENDENCIA SOLICITANTE: | D6: Escuela de Cadetes "Tte. Gral. Juan Domingo Peron" la Provincia de Catamarca
A7: PERIODO UTILIZACIÓN: | D7: 1º Trimestre Año 2021
A8: OBJETO: | D8: Adquisición de alimentos para personas .
A10: Ítem | B10: Codigo Item | C10: DESCRIPCIÓN | H10: Adjunta Detalle Técnico | I10: Unidad Medida | J10: Precio Unitario Estimado | K10: Cantidad Solicitada
A12: 01 | B12: ='Necesidades Trimestrales'!B10 -> 2.1.1-481.38 | C12: ='Necesidades Trimestrales'!E10 -> AZUCARES; TIPO: "A" COMUN, ESTADO: MOLIDA, PESO: 1 Kg, MATERIAL ENVASE: PLASTICO, CERTIFICADO FORESTAL (GFS): SIN, ELEM. TRANSPORTE: SIN, MATERIAL ELEM. TRANSPORTE: SIN | H12: NO | I12: ='Necesidades Trimestrales'!F10 -> BOLSA | J12: ='Necesidades Trimestrales'!H10 -> 89 | K12: ='Necesidades Trimestrales'!G10 -> 2000
A13: 02 | B13: ='Necesidades Trimestrales'!B11 -> 2.1.1-454.25 | C13: ='Necesidades Trimestrales'!E11 -> YERBAS; PALO: CON, PESO: 1 Kg, MATERIAL ENVASE : PAPEL, CERTIFICADO FORESTAL (GFS): CON, ELEM. TRANSPORTE: SIN, MATERIAL ELEM. TRANSPORTE: SIN, LIBRE DE GLUTEN: SI | H13: NO | I13: ='Necesidades Trimestrales'!F11 -> PAQUETE | J13: ='Necesidades Trimestrales'!H11 -> 490 | K13: ='Necesidades Trimestrales'!G11 -> 400
A14: 03 | B14: ='Necesidades Trimestrales'!B12 -> 2.1.1-489.136 | C14: ='Necesidades Trimestrales'!E12 -> ESPECIAS; TIPO: PIMENTON EXTRA DULCE, PRESENTACION: BOLSA X 1 Kg | H14: NO | I14: ='Necesidades Trimestrales'!F12 -> BOLSA | J14: ='Necesidades Trimestrales'!H12 -> 990 | K14: ='Necesidades Trimestrales'!G12 -> 60
A15: 04 | B15: ='Necesidades Trimestrales'!B13 -> 2.1.1-489.66 | C15: ='Necesidades Trimestrales'!E13 -> ESPECIAS; TIPO: OREGANO, PRESENTACION: BOLSA DE 1 Kg | H15: NO | I15: ='Necesidades Trimestrales'!F13 -> BOLSA | J15: ='Necesidades Trimestrales'!H13 -> 1900 | K15: ='Necesidades Trimestrales'!G13 -> 30
A16: 05 | B16: ='Necesidades Trimestrales'!B14 -> 2.1.1-489.109 | C16: ='Necesidades Trimestrales'!E14 -> ESPECIAS; TIPO: PROVENZAL, PRESENTACION: PAQUETE X 1 Kg | H16: NO | I16: ='Necesidades Trimestrales'!F14 -> PAQUETE | J16: ='Necesidades Trimestrales'!H14 -> 1900 | K16: ='Necesidades Trimestrales'!G14 -> 30
A17: 06 | B17: ='Necesidades Trimestrales'!B15 -> 2.1.1-489.165 | C17: ='Necesidades Trimestrales'!E15 -> ESPECIAS; TIPO: PIMIENTA BLANCA MOLIDA, PRESENTACION: ENVASE X 1 Kg, LIBRE DE GLUTEN: NO | H17: NO | I17: ='Necesidades Trimestrales'!F15 -> UNIDAD | J17: ='Necesidades Trimestrales'!H15 -> 1900 | K17: ='Necesidades Trimestrales'!G15 -> 20
A18: 07 | B18: ='Necesidades Trimestrales'!B16 -> 2.1.1-489.119 | C18: ='Necesidades Trimestrales'!E16 -> ESPECIAS; TIPO: COMINO, PRESENTACION: BOLSA X 1 Kg | H18: NO | I18: ='Necesidades Trimestrales'!F16 -> BOLSA | J18: ='Necesidades Trimestrales'!H16 -> 1100 | K18: ='Necesidades Trimestrales'!G16 -> 20
A19: 08 | B19: ='Necesidades Trimestrales'!B17 -> 2.1.1-489.68 | C19: ='Necesidades Trimestrales'!E17 -> ESPECIAS; PRESENTACION: BOLSA DE 1 Kg, TIPO: AJI MOLIDO | H19: NO | I19: ='Necesidades Trimestrales'!F17 -> BOLSA | J19: ='Necesidades Trimestrales'!H17 -> 1490 | K19: ='Necesidades Trimestrales'!G17 -> 20
A20: 09 | B20: ='Necesidades Trimestrales'!B18 -> 2.1.1-439.67 | C20: ='Necesidades Trimestrales'!E18 -> ACEITES COMESTIBLES; TIPO: GIRASOL, PRESENTACION: ENVASE X 900 CM3, MATERIAL ENVASE: PLASTICO 1 (PET), ELEM. TRANSPORTE: SIN, MATERIAL ELEM. TRANSPORTE : SIN, LIBRE DE GLUTEN: NO | H20: NO | I20: ='Necesidades Trimestrales'!F18 -> BOTELLA | J20: ='Necesidades Trimestrales'!H18 -> 198 | K20: ='Necesidades Trimestrales'!G18 -> 400
A21: 10 | B21: ='Necesidades Trimestrales'!B19 -> 2.1.1-708.23 | C21: ='Necesidades Trimestrales'!E19 -> CONSERVAS PESCADO Y FRUTOS MAR; ESTADO: AL NATURAL, PESO: 380 GR, ENVASE: LATA, TIPO: CABALLA, ESPECIE: CABALLA | H21: NO | I21: ='Necesidades Trimestrales'!F19 -> LATA | J21: ='Necesidades Trimestrales'!H19 -> 215 | K21: ='Necesidades Trimestrales'!G19 -> 200
A22: 11 | B22: ='Necesidades Trimestrales'!B20 -> 2.1.1-2868.56 | C22: ='Necesidades Trimestrales'!E20 -> FIDEOS SECOS; VARIEDAD: CABELLO DE ANGEL, RELLENO: SIN, PRESENTACION: ENVASE X 500 GR, MATERIAL ENVASE: PVC, ELEM. TRANSPORTE: CAJA, MATERIAL ELEM. TRANSPORTE: CARTON, CERTIFICADO FORESTAL (GFS): SIN, LIBRE DE GLUTEN: NO | H22: NO | I22: ='Necesidades Trimestrales'!F20 -> PAQUETE | J22: ='Necesidades Trimestrales'!H20 -> 65.833333 | K22: ='Necesidades Trimestrales'!G20 -> 960
A23: 12 | B23: ='Necesidades Trimestrales'!B21 -> 2.1.1-2868.61 | C23: ='Necesidades Trimestrales'!E21 -> FIDEOS SECOS; VARIEDAD: MOÑOS BLANCOS, RELLENO: SIN, PRESENTACION: ENVASE X 500 GR, MATERIAL ENVASE: PLASTICO 1 (PET), ELEM. TRANSPORTE: CAJA, MATERIAL ELEM. TRANSPORTE: SIN, CERTIFICADO FORESTAL (GFS): SIN, LIBRE DE GLUTEN: NO | H23: NO | I23: ='Necesidades Trimestrales'!F21 -> PAQUETE | J23: ='Necesidades Trimestrales'!H21 -> 65.833333 | K23: ='Necesidades Trimestrales'!G21 -> 960
... A75: 64 | B75: ='Necesidades Trimestrales'!B73 -> 2.1.1-6539.157 | C75: ='Necesidades Trimestrales'!E73 -> FRUTAS; VARIEDAD: PERA, ESTADO: NATURAL, PRESENTACION: ENVASE X 20 Kg | H75: NO | I75: ='Necesidades Trimestrales'!F73 -> CAJON | J75: ='Necesidades Trimestrales'!H73 -> 3200 | K75: ='Necesidades Trimestrales'!G73 -> 20
A76: Costo total estimado: PESOS CUATRO MILLONES NOVECIENTOS CINCUENTA MIL CIENTO DIECIOCHO CON 00/100 | J76: =SUMPRODUCT(+J12:J75,K12:K75) -> 4950118

Sheet Autor Gastar
A1: EJERCICIO: | D1: ='Necesidades Trimestrales'!C6 -> 2021 | P1: AUTORIZACION PARA GASTAR
A4: JURISDICCIÓN: | G4: =' NotaPedido'!D3 -> 90 - Ministerio de Seguridad
A5: SAF: | G5: =' NotaPedido'!D4 -> 7 - Direccion de Administracion de la Policia de la Provincia de Catamarca
A6: UNIDAD EJECUTORA: | G6: =' NotaPedido'!D5 -> Policia de la Provincia de Catamarca
A7: DEPENDENCIA SOLICITANTE: | G7: =' NotaPedido'!D6 -> Escuela de Cadetes "Tte. Gral. Juan Domingo Peron" la Provincia de Catamarca
A8: AUTORIZACIÓN:
A9: Señor Jefe de Servicio Administrativo Financiero:
A10: ="Autorizo la realización de los trámites correspondientes, a fin de proveer a este Organismo los bienes y/o servicios que se detallan en Nota de Pedido N° " & ' NotaPedido'!K1&", afectando la erogación resultante a los créditos presupuestarios aprobados a favor de esta Unidad Ejecutora, conforme al siguiente detalle:" -> Autorizo la realización de los trámites correspondientes, a fin de proveer a este Organismo los bienes y/o servicios que se detallan en Nota de Pedido N° 02/2021, afectando la erogación resultante a los créditos presupuestarios aprobados a favor de esta Unidad Ejecutora, conforme al siguiente detalle:
A12: IMPUTACIÓN PRESUPUESTARIA
A13: CÓDIGO | O13: DENOMINACIÓN DE LA PARTIDA PRESUPUESTARIA | Q13: IMPORTE
A14: PR | B14: SB | C14: PY | D14: AC | E14: OB | F14: UG | G14: FIN | H14: FUN | I14: I | J14: P | K14: P | L14: SubP | M14: M | N14: FF
A15: 16 | B15: 0 | C15: 0 | D15: 2 | E15: 0 | F15: 10 | G15: 2 | H15: 1 | I15: 2 | J15: 1 | K15: 1 | L15: 0 | M15: 1 | N15: 1.1 | O15: ALIMENTOS PARA PERSONAS | Q15: =' NotaPedido'!J76 -> 4950118
A16: TOTAL DE PESOS: | Q16: =SUM(Q15:Q15) -> 4950118
A17: CUATRO MILLONES NOVECIENTOS CINCUENTA MIL CIENTO DIECIOCHO CON 00/100
A18: JUSTIFICACIÓN:
A19: Adquisición de alimentos para personas destinada a Realizar las Racciones Diarias.-
