Workbook

Sheet Necesidades Trimestrales
B2: Pedido de Necesidades Trimestrales
A4: JURISDICCION: | C4: 90 - Ministerio de Seguridad
A5: SAF N°: | C5: 7- Dirección Provincial de Administración de la Policía de la Provincia de Catamarca
A6: EJERCICIO: | C6: 2022
A7: TRIMESTRE: | C7: 2
A9: ID | B9: CODIGO ITEM | C9: RUBRO DE COMPRA | D9: I.P.P. | E9: DESCRIPCION | F9: UNIDAD DE MEDIDA | G9: CANTIDAD | H9: PRECIO UNITARIO ESTIMADO | I9: IMPORTE TOTAL ESTIMADO
A10: 1 | B10: 2.4.4-6818.744 | C10: REPUESTOS | D10: 2.4.4. | E10: NEUMATICOS; VEHICULO: CAMIONETA, CONSTRUCCION: RADIAL, ARMADO: S/CAMARA, MEDIDA: 235/70R16 | F10: UNIDAD | G10: 180 | H10: 59020 | I10: =G10*H10 -> 10623600
A11: 2 | B11: 2.4.4-6818.530 | C11: REPUESTOS | D11: 2.4.4. | E11: NEUMATICOS; VEHICULO: CAMIONETA, CONSTRUCCION: RADIAL, ARMADO: S/CAMARA, MEDIDA: 245/70R16 | F11: UNIDAD | G11: 30 | H11: 56550 | I11: =G11*H11 -> 1696500
A12: 3 | B12: 2.4.4-6818.244 | C12: REPUESTOS | D12: 2.4.4. | E12: NEUMATICOS; VEHICULO: AUTOMOVIL, CONSTRUCCION: RADIAL, ARMADO: S/CAMARA, MEDIDA: 205/55R16 | F12: UNIDAD | G12: 2 | H12: 49000 | I12: =G12*H12 -> 98000
A13: 4 | B13: 2.4.4-6818.97 | C13: REPUESTOS | D13: 2.4.4. | E13: NEUMATICOS; VEHICULO: AUTOMOVIL, ARMADO: S/CAMARA, MEDIDA: 175/70R14, CONSTRUCCION: RADIAL | F13: UNIDAD | G13: 6 | H13: 28500 | I13: =G13*H13 -> 171000
A14: 5 | B14: 2.4.4-6818.97 | C14: REPUESTOS | D14: 2.4.4. | E14: NEUMATICOS; VEHICULO: AUTOMOVIL, ARMADO: S/CAMARA, MEDIDA: 175/70R14, CONSTRUCCION: RADIAL | F14: UNIDAD | G14: 2 | H14: 28500 | I14: =G14*H14 -> 57000
A15: 6 | B15: 2.4.4-6818.77 | C15: REPUESTOS | D15: 2.4.4. | E15: NEUMATICOS; VEHICULO: AUTOMOVIL, ARMADO: C/CAMARA, MEDIDA: 175/70R13, CONSTRUCCION: CONVENCIONAL | F15: UNIDAD | G15: 2 | H15: 21190 | I15: =G15*H15 -> 42380
A16: 7 | B16: 2.4.4-6818.89 | C16: REPUESTOS | D16: 2.4.4. | E16: NEUMATICOS; VEHICULO: AUTOMOVIL, CONSTRUCCION: CONVENCIONAL, ARMADO: C/CAMARA, MEDIDA: 185/60R14 | F16: UNIDAD | G16: 10 | H16: 29100 | I16: =G16*H16 -> 291000
A17: 8 | B17: 2.4.4-6818.891 | C17: REPUESTOS | D17: 2.4.4. | E17: NEUMATICOS; VEHICULO: MINIBUS, CONSTRUCCION: RADIAL, ARMADO: SIN CAMARA, MEDIDA: 195/75R16 | F17: UNIDAD | G17: 6 | H17: 54600 | I17: =G17*H17 -> 327600
A18: 9 | B18: 2.4.4-6818.810 | C18: REPUESTOS | D18: 2.4.4. | E18: NEUMATICOS; VEHICULO: MINIBUS, CONSTRUCCION: RADIAL, ARMADO: S/CAMARA, MEDIDA: 225/75R16 | F18: UNIDAD | G18: 10 | H18: 64090 | I18: =G18*H18 -> 640900
A19: 10 | B19: 2.4.4-6818.989 | C19: REPUESTOS | D19: 2.4.4. | E19: NEUMATICOS; VEHICULO: CAMIONETA, CONSTRUCCION: RADIAL, ARMADO: S/CAMARA, MEDIDA: 225/70 R17 | F19: UNIDAD | G19: 80 | H19: 91455 | I19: =G19*H19 -> 7316400
A20: 11 | B20: 2.4.4-6818.1032 | C20: REPUESTOS | D20: 2.4.4 | E20: NEUMATICOS; VEHICULO: CAMION, CONSTRUCCION: RADIAL, ARMADO: S/CAMARA, MEDIDA: SEGUN PLIEGO | F20: UNIDAD | G20: 2 | H20: 105000 | I20: =G20*H20 -> 210000
A21: 12 | B21: 2.4.4-6818.1032 | C21: REPUESTOS | D21: 2.4.4. | E21: NEUMATICOS; VEHICULO: CAMION, CONSTRUCCION: RADIAL, ARMADO: S/CAMARA, MEDIDA: SEGUN PLIEGO | F21: UNIDAD | G21: 2 | H21: 137800 | I21: =G21*H21 -> 275600
... A37: 28 | B37: 2.4.4-6818.203 | C37: REPUESTOS | D37: 2.4.4. | E37: NEUMATICOS; VEHICULO: CUATRICICLO, CONSTRUCCION: RADIAL, ARMADO: S/CAMARA, MEDIDA: 25 X 10-12 | F37: UNIDAD | G37: 4 | H37: 54000 | I37: =G37*H37 -> 216000
I38: =SUM(I10:I37) -> 26849275
B40: Especificidades
B41: Item N° : 01
C42: Descripción técnica | D42: MARCA TOYOTA/VOLKSWAGEN. MODELO: HILUX/AMAROK ELEMENTO: NEUMATICO MED. 235/70/16 CANTIDAD: 90/AMAROK- 90/HILUX
B43: Item N° : 02
C44: Descripción técnica | D44: MARCA CHEVROLET MODELO: S-10 ELEMENTO: NEUMATICOS MED. 245/70/16
B45: Item N° : 03
C46: Descripción técnica | D46: MARCA TOYOTA MODELO: COROLA ELEMENTO: NEUMATICOS MED. 205/55/16
B47: Item N° : 04
C48: Descripción técnica | D48: MARCA TOYOTA MODELO: ETIOS ELEMENTO: NEUMATICO MED. 175/70/14
B49: Item N° : 05
C50: Descripción técnica | D50: MARCA FIAT MODELO: FIORINO ELEMENTO: NEUMATICO MED. 175/70/14
B51: Item N° : 06
C52: Descripción técnica | D52: MARCA CHEVROLET MODELO: CORSA ELEMENTO: NEUMATICO MED. 175/70/13
B53: Item N° : 07
C54: Descripción técnica | D54: MARCA CITROEN MODELO: BERLINGO ELEMENTO: NEUMATICO MED. 185/60/14
B55: Item N° : 08
C56: Descripción técnica | D56: MARCA: FORD MODELO: TRANSIT ELEMENTO: NEUMATICO PARA COMBI MED.195/75/16
B57: Item N° : 09
C58: Descripción técnica | D58: MARCA: MERCEDEZ BENZ MODELO: SPLINTER ELEMENTO: NEUMATICO PARA MINIBUS MED.225/75/16
B59: Item N° : 10
...

Sheet  NotaPedido
A1: NOTA DE PEDIDO | J1: N° | K1: 32/2020
A3: JURISDICCIÓN: | D3: ='Necesidades Trimestrales'!C4 -> 90 - Ministerio de Seguridad
A4: SAF: | D4: ='Necesidades Trimestrales'!C5 -> 7- Dirección Provincial de Administración de la Policía de la Provincia de Catamarca
A5: UNIDAD EJECUTORA: | D5: Jefatura de Policía de la Provincia de Catamarca
A6: DEPENDENCIA SOLICITANTE: | D6: División Transporte- Dpto. Logistica (D-4)
A7: PERIODO UTILIZACIÓN: | D7: ='Necesidades Trimestrales'!C7 & "° Trimestre - Año " & 'Necesidades Trimestrales'!C6 -> 2° Trimestre - Año 2022
A8: OBJETO: | D8: Adquisición de CUBIERTAS destinadas a las Unidades Moviles de la Policia de Catamarca.-
A10: Ítem | B10: Codigo Item | C10: DESCRIPCIÓN | H10: Adjunta Detalle Técnico | I10: Unidad Medida | J10: Precio Unitario Estimado | K10: Cantidad Solicitada
A12: 1 | B12: ='Necesidades Trimestrales'!B10 -> 2.4.4-6818.744 | C12: ='Necesidades Trimestrales'!E10 -> NEUMATICOS; VEHICULO: CAMIONETA, CONSTRUCCION: RADIAL, ARMADO: S/CAMARA, MEDIDA: 235/70R16 | H12: SI | I12: UNIDAD | J12: ='Necesidades Trimestrales'!H10 -> 59020 | K12: ='Necesidades Trimestrales'!G10 -> 180
A13: 2 | B13: ='Necesidades Trimestrales'!B11 -> 2.4.4-6818.530 | C13: ='Necesidades Trimestrales'!E11 -> NEUMATICOS; VEHICULO: CAMIONETA, CONSTRUCCION: RADIAL, ARMADO: S/CAMARA, MEDIDA: 245/70R16 | H13: SI | I13: UNIDAD | J13: ='Necesidades Trimestrales'!H11 -> 56550 | K13: ='Necesidades Trimestrales'!G11 -> 30
A14: 3 | B14: ='Necesidades Trimestrales'!B12 -> 2.4.4-6818.244 | C14: ='Necesidades Trimestrales'!E12 -> NEUMATICOS; VEHICULO: AUTOMOVIL, CONSTRUCCION: RADIAL, ARMADO: S/CAMARA, MEDIDA: 205/55R16 | H14: SI | I14: UNIDAD | J14: ='Necesidades Trimestrales'!H12 -> 49000 | K14: ='Necesidades Trimestrales'!G12 -> 2
A15: 4 | B15: ='Necesidades Trimestrales'!B13 -> 2.4.4-6818.97 | C15: ='Necesidades Trimestrales'!E13 -> NEUMATICOS; VEHICULO: AUTOMOVIL, ARMADO: S/CAMARA, MEDIDA: 175/70R14, CONSTRUCCION: RADIAL | H15: SI | I15: UNIDAD | J15: ='Necesidades Trimestrales'!H13 -> 28500 | K15: ='Necesidades Trimestrales'!G13 -> 6
A16: 5 | B16: ='Necesidades Trimestrales'!B14 -> 2.4.4-6818.97 | C16: ='Necesidades Trimestrales'!E14 -> NEUMATICOS; VEHICULO: AUTOMOVIL, ARMADO: S/CAMARA, MEDIDA: 175/70R14, CONSTRUCCION: RADIAL | H16: SI | I16: UNIDAD | J16: ='Necesidades Trimestrales'!H14 -> 28500 | K16: ='Necesidades Trimestrales'!G14 -> 2
A17: 6 | B17: ='Necesidades Trimestrales'!B15 -> 2.4.4-6818.77 | C17: ='Necesidades Trimestrales'!E15 -> NEUMATICOS; VEHICULO: AUTOMOVIL, ARMADO: C/CAMARA, MEDIDA: 175/70R13, CONSTRUCCION: CONVENCIONAL | H17: SI | I17: UNIDAD | J17: ='Necesidades Trimestrales'!H15 -> 21190 | K17: ='Necesidades Trimestrales'!G15 -> 2
A18: 7 | B18: ='Necesidades Trimestrales'!B16 -> 2.4.4-6818.89 | C18: ='Necesidades Trimestrales'!E16 -> NEUMATICOS; VEHICULO: AUTOMOVIL, CONSTRUCCION: CONVENCIONAL, ARMADO: C/CAMARA, MEDIDA: 185/60R14 | H18: SI | I18: UNIDAD | J18: ='Necesidades Trimestrales'!H16 -> 29100 | K18: ='Necesidades Trimestrales'!G16 -> 10
A19: 8 | B19: ='Necesidades Trimestrales'!#REF! -> #REF! | C19: ='Necesidades Trimestrales'!#REF! -> #REF! | H19: SI | I19: UNIDAD | J19: ='Necesidades Trimestrales'!#REF! -> #REF! | K19: ='Necesidades Trimestrales'!#REF! -> #REF!
A20: 9 | B20: ='Necesidades Trimestrales'!B17 -> 2.4.4-6818.891 | C20: ='Necesidades Trimestrales'!E17 -> NEUMATICOS; VEHICULO: MINIBUS, CONSTRUCCION: RADIAL, ARMADO: SIN CAMARA, MEDIDA: 195/75R16 | H20: SI | I20: UNIDAD | J20: ='Necesidades Trimestrales'!H17 -> 54600 | K20: ='Necesidades Trimestrales'!G17 -> 6
A21: 10 | B21: ='Necesidades Trimestrales'!B18 -> 2.4.4-6818.810 | C21: ='Necesidades Trimestrales'!E18 -> NEUMATICOS; VEHICULO: MINIBUS, CONSTRUCCION: RADIAL, ARMADO: S/CAMARA, MEDIDA: 225/75R16 | H21: SI | I21: UNIDAD | J21: ='Necesidades Trimestrales'!H18 -> 64090 | K21: ='Necesidades Trimestrales'!G18 -> 10
A22: 11 | B22: ='Necesidades Trimestrales'!B19 -> 2.4.4-6818.989 | C22: ='Necesidades Trimestrales'!E19 -> NEUMATICOS; VEHICULO: CAMIONETA, CONSTRUCCION: RADIAL, ARMADO: S/CAMARA, MEDIDA: 225/70 R17 | H22: SI | I22: UNIDAD | J22: ='Necesidades Trimestrales'!H19 -> 91455 | K22: ='Necesidades Trimestrales'!G19 -> 80
A23: 12 | B23: ='Necesidades Trimestrales'!B20 -> 2.4.4-6818.1032 | C23: ='Necesidades Trimestrales'!E20 -> NEUMATICOS; VEHICULO: CAMION, CONSTRUCCION: RADIAL, ARMADO: S/CAMARA, MEDIDA: SEGUN PLIEGO | H23: SI | I23: UNIDAD | J23: ='Necesidades Trimestrales'!H20 -> 105000 | K23: ='Necesidades Trimestrales'!G20 -> 2
A24: 13 | B24: ='Necesidades Trimestrales'!B21 -> 2.4.4-6818.1032 | C24: ='Necesidades Trimestrales'!E21 -> NEUMATICOS; VEHICULO: CAMION, CONSTRUCCION: RADIAL, ARMADO: S/CAMARA, MEDIDA: SEGUN PLIEGO | H24: SI | I24: UNIDAD | J24: ='Necesidades Trimestrales'!H21 -> 137800 | K24: ='Necesidades Trimestrales'!G21 -> 2
A25: 14 | B25: ='Necesidades Trimestrales'!#REF! -> #REF! | C25: ='Necesidades Trimestrales'!#REF! -> #REF! | H25: SI | I25: UNIDAD | J25: ='Necesidades Trimestrales'!#REF! -> #REF! | K25: ='Necesidades Trimestrales'!#REF! -> #REF!
A26: 15 | B26: ='Necesidades Trimestrales'!B33 -> 2.4.4-6818.631 | C26: ='Necesidades Trimestrales'!E33 -> NEUMATICOS; VEHICULO: MOTO, CONSTRUCCION: RADIAL, ARMADO: C/CAMARA, MEDIDA: 90/90-21 | H26: SI | I26: UNIDAD | J26: ='Necesidades Trimestrales'!H33 -> 18500 | K26: ='Necesidades Trimestrales'!G33 -> 40
A27: 16 | B27: ='Necesidades Trimestrales'!#REF! -> #REF! | C27: ='Necesidades Trimestrales'!#REF! -> #REF! | H27: SI | I27: UNIDAD | J27: ='Necesidades Trimestrales'!#REF! -> #REF! | K27: ='Necesidades Trimestrales'!#REF! -> #REF!
A28: 17 | B28: ='Necesidades Trimestrales'!#REF! -> #REF! | C28: ='Necesidades Trimestrales'!#REF! -> #REF! | H28: SI | I28: UNIDAD | J28: ='Necesidades Trimestrales'!#REF! -> #REF! | K28: ='Necesidades Trimestrales'!#REF! -> #REF!
A29: 18 | B29: ='Necesidades Trimestrales'!#REF! -> #REF! | C29: ='Necesidades Trimestrales'!#REF! -> #REF! | H29: SI | I29: UNIDAD | J29: ='Necesidades Trimestrales'!#REF! -> #REF! | K29: ='Necesidades Trimestrales'!#REF! -> #REF!
A30: Costo total estimado: Pesos . | D30: Trece Millones Quinientos Cuatro Mil Doscientos Cuatro con 00/100. | J30: =SUMPRODUCT(J12:J29,K12:K29) -> #REF!

Sheet Autor Gastar
A1: EJERCICIO: | D1: ='[1]Necesidades Trimestrales'!C6 -> 2021 | P1: AUTORIZACION PARA GASTAR
A4: JURISDICCIÓN: | G4: =' NotaPedido'!D3 -> 90 - Ministerio de Seguridad
A5: SAF: | G5: =' NotaPedido'!D4 -> 7- Dirección Provincial de Administración de la Policía de la Provincia de Catamarca
A6: UNIDAD EJECUTORA: | G6: =' NotaPedido'!D5 -> Jefatura de Policía de la Provincia de Catamarca
A7: DEPENDENCIA SOLICITANTE: | G7: =' NotaPedido'!D6 -> División Transporte- Dpto. Logistica (D-4)
A8: AUTORIZACIÓN:
A9: Señor Jefe de Servicio Administrativo Financiero:
A10: ="Autorizo la realización de los trámites correspondientes, a fin de proveer a este Organismo los bienes y/o servicios que se detallan en Nota de Pedido N° " & ' NotaPedido'!K1&", afectando la erogación resultante a los créditos presupuestarios aprobados a favor de esta Unidad Ejecutora, conforme al siguiente detalle:" -> Autorizo la realización de los trámites correspondientes, a fin de proveer a este Organismo los bienes y/o servicios que se detallan en Nota de Pedido N° 32/2020, afectando la erogación resultante a los créditos presupuestarios aprobados a favor de esta Unidad Ejecutora, conforme al siguiente detalle:
A12: IMPUTACIÓN PRESUPUESTARIA
A13: CÓDIGO | O13: DENOMINACIÓN DE LA PARTIDA PRESUPUESTARIA | Q13: IMPORTE
A14: PR | B14: SB | C14: PY | D14: AC | E14: OB | F14: UG | G14: FIN | H14: FUN | I14: I | J14: P | K14: P | L14: SubP | M14: M | N14: FF
A15: 16 | B15: 0 | C15: 0 | D15: 1 | E15: 0 | F15: 10 | G15: 2 | H15: 1 | I15: 2 | J15: 4 | K15: 4 | L15: 0 | M15: 1 | N15: 1.1 | O15: CUBIERTAS Y CAMARAS DE AIRE | Q15: ='Necesidades Trimestrales'!I38 -> 26849275
A16: TOTAL DE PESOS | Q16: =+Q15 -> 26849275
E17: =' NotaPedido'!D30 -> Trece Millones Quinientos Cuatro Mil Doscientos Cuatro con 00/100.
A18: JUSTIFICACIÓN:
A19: =' NotaPedido'!D8 -> Adquisición de CUBIERTAS destinadas a las Unidades Moviles de la Policia de Catamarca.-
