Workbook

Sheet Necesidades Trimestrales
B2: Pedido de Necesidades Trimestrales
A4: JURISDICCION: | C4: 45- Ministerio de Desarrollo Social.-
A5: SAF N°: | C5: 25- Direccion Provincial de Gestion Administracion y RRHH
A6: EJERCICIO: | C6: 2022
A7: TRIMESTRE: | C7: 1
A9: ID | B9: CODIGO ITEM | C9: RUBRO DE COMPRA | D9: I.P.P. | E9: DESCRIPCION | F9: UNIDAD DE MEDIDA | G9: CANTIDAD | H9: PRECIO UNITARIO ESTIMADO | I9: IMPORTE TOTAL ESTIMADO
A10: 1 | B10: 2.1.1-705.93 | C10: ALIMENTOS | D10: 2.1.1 | E10: LECHE; ESTADO: POLVO, TIPO: ENTERA, PROCESO: PASTEURIZADA, AGREGADO: VITAMINAS A Y D, PRESENTACION: ENVASE X 800 GR, MATERIAL ENVASE: CARTON, ELEM. TRANSPORTE: SIN, MATERIAL ELEM. TRANSPORTE: SIN, CERTIFICADO FORESTAL (GFS): SIN, LIBRE DE GLUTEN: SI | F10: UNIDAD | G10: 100000 | H10: 619 | I10: =+G10*H10 -> 61900000 | J10: LECHE; ESTADO: POLVO, TIPO: ENTERA, PROCESO: PASTEURIZADA, AGREGADO: VITAMINAS A Y D, PRESENTACION: ENVASE X 800 GR, MATERIAL ENVASE: CARTON, ELEM. TRANSPORTE: SIN, MATERIAL ELEM. TRANSPORTE: SIN, CERTIFICADO FORESTAL (GFS): SIN, LIBRE DE GLUTEN: SI | K10: =E10=J10 -> TRUE
A11: 2 | B11: 2.1.1-439.67 | C11: ALIMENTOS | D11: =LEFT(B11,5) -> 2.1.1 | E11: ACEITES COMESTIBLES; TIPO: GIRASOL, PRESENTACION: ENVASE X 900 CM3, MATERIAL ENVASE: PLASTICO 1 (PET), ELEM. TRANSPORTE: SIN, MATERIAL ELEM. TRANSPORTE : SIN, LIBRE DE GLUTEN: NO | F11: UNIDAD | G11: 100000 | H11: 214 | I11: =+G11*H11 -> 21400000 | J11: ACEITES COMESTIBLES; TIPO: GIRASOL, PRESENTACION: ENVASE X 900 CM3, MATERIAL ENVASE: PLASTICO 1 (PET), ELEM. TRANSPORTE: SIN, MATERIAL ELEM. TRANSPORTE : SIN, LIBRE DE GLUTEN: NO | K11: =E11=J11 -> TRUE
A12: 3 | B12: 2.1.1-454.25 | C12: ALIMENTOS | D12: =LEFT(B12,5) -> 2.1.1 | E12: YERBAS; PALO: CON, PESO: 1 Kg, MATERIAL ENVASE : PAPEL, CERTIFICADO FORESTAL (GFS): CON, ELEM. TRANSPORTE: SIN, MATERIAL ELEM. TRANSPORTE: SIN, LIBRE DE GLUTEN: SI | F12: UNIDAD | G12: 100000 | H12: 400 | I12: =+G12*H12 -> 40000000 | J12: YERBAS; PALO: CON, PESO: 1 Kg, MATERIAL ENVASE : PAPEL, CERTIFICADO FORESTAL (GFS): CON, ELEM. TRANSPORTE: SIN, MATERIAL ELEM. TRANSPORTE: SIN, LIBRE DE GLUTEN: SI | K12: =E12=J12 -> TRUE
A13: 4 | B13: 2.1.1-6547.84 | C13: ALIMENTOS | D13: =LEFT(B13,5) -> 2.1.1 | E13: LEGUMBRES; VARIEDAD: ARVEJAS, ESTADO: CONSERVA, PRESENTACION: LATA, PESO: 350 GR, MATERIAL ENVASE: METAL, ELEM. TRANSPORTE: SIN, MATERIAL ELEM. TRANSPORTE: SIN, LIBRE DE GLUTEN: NO | F13: UNIDAD | G13: 100000 | H13: 47 | I13: =+G13*H13 -> 4700000 | J13: LEGUMBRES; VARIEDAD: ARVEJAS, ESTADO: CONSERVA, PRESENTACION: LATA, PESO: 350 GR, MATERIAL ENVASE: METAL, ELEM. TRANSPORTE: SIN, MATERIAL ELEM. TRANSPORTE: SIN, LIBRE DE GLUTEN: NO | K13: =E13=J13 -> TRUE
A14: 5 | B14: 2.1.1-435.60 | C14: ALIMENTOS | D14: 2.1.1 | E14: ARROZ; TIPO GRANO: LARGO-FINO, TIPO: BLANCO, PROCESO: SIN CASCARA, PRESENTACION: BOLSA X 1 Kg, MATERIAL ENVASE: PLASTICO, CERTIFICADO FORESTAL (GFS): SIN, ELEM. TRANSPORTE: SIN, MATERIAL ELEM. TRANSPORTE: SIN, LIBRE DE GLUTEN: SI | F14: UNIDAD | G14: 100000 | H14: 108 | I14: =+G14*H14 -> 10800000 | J14: ARROZ; TIPO GRANO: LARGO-FINO, TIPO: BLANCO, PROCESO: SIN CASCARA, PRESENTACION: BOLSA X 1 Kg, MATERIAL ENVASE: PLASTICO, CERTIFICADO FORESTAL (GFS): SIN, ELEM. TRANSPORTE: SIN, MATERIAL ELEM. TRANSPORTE: SIN, LIBRE DE GLUTEN: SI | K14: =E14=J14 -> TRUE
A15: 6 | B15: 2.1.1-482.70 | C15: ALIMENTOS | D15: =LEFT(B15,5) -> 2.1.1 | E15: HARINAS; TIPO: 000, PRESENTACION: ENVASE X 1 Kg, MATERIAL ENVASE: PAPEL, CERTICADO FORESTAL (GFS): SI, ELEM. TRANSPORTE: SIN, MATERIAL ELEM. TRANSPORTE: SIN, LIBRE DE GLUTEN: NO | F15: UNIDAD | G15: 100000 | H15: 94 | I15: =+G15*H15 -> 9400000 | J15: HARINAS; TIPO: 000, PRESENTACION: ENVASE X 1 Kg, MATERIAL ENVASE: PAPEL, CERTICADO FORESTAL (GFS): SI, ELEM. TRANSPORTE: SIN, MATERIAL ELEM. TRANSPORTE: SIN, LIBRE DE GLUTEN: NO | K15: =E15=J15 -> TRUE
A16: 7 | B16: 2.1.1-6546.260 | C16: ALIMENTOS | D16: =LEFT(B16,5) -> 2.1.1 | E16: VERDURAS Y HORTALIZAS; VARIEDAD: TOMATE, ESTADO: PURE, PRESENTACION: TETRABRIK, PESO: 520 GR | F16: UNIDAD | G16: 100000 | H16: 65 | I16: =+G16*H16 -> 6500000 | J16: VERDURAS Y HORTALIZAS; VARIEDAD: TOMATE, ESTADO: PURE, PRESENTACION: TETRABRIK, PESO: 520 GR | K16: =E16=J16 -> TRUE
A17: 8 | B17: 2.1.1-481.38 | C17: ALIMENTOS | D17: =LEFT(B17,5) -> 2.1.1 | E17: AZUCARES; TIPO: "A" COMUN, ESTADO: MOLIDA, PESO: 1 Kg, MATERIAL ENVASE: PLASTICO, CERTIFICADO FORESTAL (GFS): SIN, ELEM. TRANSPORTE: SIN, MATERIAL ELEM. TRANSPORTE: SIN | F17: UNIDAD | G17: 100000 | H17: 94 | I17: =+G17*H17 -> 9400000 | J17: AZUCARES; TIPO: "A" COMUN, ESTADO: MOLIDA, PESO: 1 Kg, MATERIAL ENVASE: PLASTICO, CERTIFICADO FORESTAL (GFS): SIN, ELEM. TRANSPORTE: SIN, MATERIAL ELEM. TRANSPORTE: SIN | K17: =E17=J17 -> TRUE
A18: 9 | B18: 2.1.1-2868.54 | C18: ALIMENTOS | D18: 2.1.1 | E18: FIDEOS SECOS; VARIEDAD: SOPERO, RELLENO: SIN, PRESENTACION: ENVASE X 500 GR, MATERIAL ENVASE: PLASTICO 1 (PET), ELEM. TRANSPORTE: SIN, MATERIAL ELEM. TRANSPORTE: SIN, CERTIFICADO FORESTAL (GFS): SIN, LIBRE DE GLUTEN: NO | F18: UNIDAD | G18: 100000 | H18: 59 | I18: =+G18*H18 -> 5900000 | J18: FIDEOS SECOS; VARIEDAD: SOPERO, RELLENO: SIN, PRESENTACION: ENVASE X 500 GR, MATERIAL ENVASE: PLASTICO 1 (PET), ELEM. TRANSPORTE: SIN, MATERIAL ELEM. TRANSPORTE: SIN, CERTIFICADO FORESTAL (GFS): SIN, LIBRE DE GLUTEN: NO | K18: =E18=J18 -> TRUE
A19: 10 | B19: 2.1.1-2868.55 | C19: ALIMENTOS | D19: 2.1.1 | E19: FIDEOS SECOS; VARIEDAD: TALLARIN, RELLENO: SIN, PRESENTACION: ENVASE X 500 GR, MATERIAL ENVASE: PLASTICO 1 (PET), ELEM. TRANSPORTE: SIN, MATERIAL ELEM. TRANSPORTE: SIN, CERTIFICADO FORESTAL (GFS): SIN, LIBRE DE GLUTEN: NO | F19: UNIDAD | G19: 100000 | H19: 59 | I19: =+G19*H19 -> 5900000 | J19: FIDEOS SECOS; VARIEDAD: TALLARIN, RELLENO: SIN, PRESENTACION: ENVASE X 500 GR, MATERIAL ENVASE: PLASTICO 1 (PET), ELEM. TRANSPORTE: SIN, MATERIAL ELEM. TRANSPORTE: SIN, CERTIFICADO FORESTAL (GFS): SIN, LIBRE DE GLUTEN: NO | K19: =E19=J19 -> TRUE
A20: 11 | B20: 2.1.1-2868.71 | C20: ALIMENTOS | D20: 2.1.1 | E20: FIDEOS SECOS; VARIEDAD: GUISERO, RELLENO: SIN, PRESENTACION: ENVASE X 500 GR, MATERIAL ENVASE: PLASTICO 1 (PET), ELEM. TRANSPORTE: SIN, MATERIAL ELEM. TRANSPORTE: SIN, CERTIFICADO FORESTAL (GFS): SIN, LIBRE DE GLUTEN: NO | F20: UNIDAD | G20: 100000 | H20: 59 | I20: =+G22*H20 -> 5900000 | J20: FIDEOS SECOS; VARIEDAD: GUISERO, RELLENO: SIN, PRESENTACION: ENVASE X 500 GR, MATERIAL ENVASE: PLASTICO 1 (PET), ELEM. TRANSPORTE: SIN, MATERIAL ELEM. TRANSPORTE: SIN, CERTIFICADO FORESTAL (GFS): SIN, LIBRE DE GLUTEN: NO | K20: =E20=J20 -> TRUE
A21: 12 | B21: 2.1.1-6547.83 | C21: ALIMENTOS | D21: 2.1.1 | E21: LEGUMBRES; VARIEDAD: POROTOS PALLARES, ESTADO: EN CONSERVA, PRESENTACION: LATA, PESO: 350 GR, MATERIAL ENVASE: METAL, ELEM. TRANSPORTE: SIN, MATERIAL ELEM. TRANSPORTE: SIN | F21: UNIDAD | G21: 100000 | H21: 51.8 | I21: =+G23*H21 -> 5180000 | J21: LEGUMBRES; VARIEDAD: POROTOS PALLARES, ESTADO: EN CONSERVA, PRESENTACION: LATA, PESO: 350 GR, MATERIAL ENVASE: METAL, ELEM. TRANSPORTE: SIN, MATERIAL ELEM. TRANSPORTE: SIN | K21: =E21=J21 -> TRUE
A22: 13 | B22: 2.1.1-482.89 | C22: ALIMENTOS | D22: 2.1.1 | E22: HARINAS.TIPO: MAIZ PRECOCIDA O DE COCCION RAPIDA. PRESENTACION: ENVASE 500 GR. LIBRE DE GLUTEN:SI | F22: UNIDAD | G22: 100000 | H22: 108 | I22: =+G22*H22 -> 10800000 | J22: HARINAS; TIPO: MAIZ PRECOCIDA O DE COCCION RAPIDA. PRESENTACION: ENVASE POR 500 GR. LIBRE DE GLUTEN: SI | K22: =E22=J22 -> FALSE
A23: 14 | B23: 2.1.1-6547.80 | C23: ALIMENTOS | D23: 2.1.1 | E23: LEGUMBRES; VARIEDAD: LENTEJA, ESTADO: SECO, PRESENTACION: SIN VALOR, PESO: ENVASE X 400 GR | F23: UNIDAD | G23: 100000 | H23: 115 | I23: =+G23*H23 -> 11500000 | J23: LEGUMBRES; VARIEDAD: LENTEJA, ESTADO: SECO, PRESENTACION: SIN VALOR, PESO: ENVASE X 400 GR | K23: =E23=J23 -> TRUE
B27: Especificidades Item N° 1:
B29: Descripción técnica
B31: Plazos y lugares de entrega
C32: PRIMERA ENTREGA (50.000 UNIDADES): DENTRO DE LOS 5 (CINCO) DIAS HABILES DE NOTIFICADA LA ORDEN DE COMPRA. - SEGUNDA ENTREGA (50.000 UNIDADES): A LOS 30 (TREINTA) DIAS HABILES DE NOTIFICADA LA ORDEN DE COMPRA.-
C33: Lugar y Forma de Entrega: Se Entregara en el Area Industrial El Pantanillo Deposito perteneciente al Ministerio de Desarrollo Social y Deporte- San Fernando del Valle de Catamarca (CP 4700) , corriendo los gastos de flete, acarreo, carga, descarga y seguros por cuenta del adjudicatario.-
B34: Calidad Minima esperada
C35: MEDIA
B36: Mantenimiento
C37: 60DIAS
B38: Garantia
C39: S/E
B42: Especificidades Item N° 2:
B44: Descripción técnica
B46: Plazos y lugares de entrega
C47: PRIMERA ENTREGA (50.000 UNIDADES): DENTRO DE LOS 5 (CINCO) DIAS HABILES DE NOTIFICADA LA ORDEN DE COMPRA. - SEGUNDA ENTREGA (50.000 UNIDADES): A LOS 30 (TREINTA) DIAS HABILES DE NOTIFICADA LA ORDEN DE COMPRA.-
C48: Lugar y Forma de Entrega: Se Entregara en el Area Industrial El Pantanillo Deposito perteneciente al Ministerio de Desarrollo Social y Deporte- San Fernando del Valle de Catamarca (CP 4700) , corriendo los gastos de flete, acarreo, carga, descarga y seguros por cuenta del adjudicatario.-
B49: Calidad Minima esperada
C50: MEDIA
B51: Mantenimiento
C52: 60DIAS
...

Sheet  NotaPedido
A1: NOTA DE PEDIDO | J1: N° | K1: 120/2022
A3: JURISDICCIÓN: | D3: ='Necesidades Trimestrales'!C4 -> 45- Ministerio de Desarrollo Social.-
A4: SAF: | D4: ='Necesidades Trimestrales'!C5 -> 25- Direccion Provincial de Gestion Administracion y RRHH
A5: UNIDAD EJECUTORA: | D5: 16- Direccion Provincial de Accion Social Directa
A6: DEPENDENCIA SOLICITANTE: | D6: 02- Programa Vivir Mejor PRO.VI.ME.
A7: PERIODO UTILIZACIÓN: | D7: ='Necesidades Trimestrales'!C7 & "° Trimestre - Año " & 'Necesidades Trimestrales'!C6 -> 1° Trimestre - Año 2022
A8: OBJETO: | D8: Adquisición de Alimentos que seran destinadas a personas de escasos recursos, en el armado de modulos alimentarios, en el Marco del Programa Vivir Mejor
A10: Ítem | B10: Codigo Item | C10: DESCRIPCIÓN | H10: Adjunta Detalle Técnico | I10: Unidad Medida | J10: Precio Unitario Estimado | K10: Cantidad Solicitada
A12: 1 | B12: ='Necesidades Trimestrales'!B10 -> 2.1.1-705.93 | C12: ='Necesidades Trimestrales'!E10 -> LECHE; ESTADO: POLVO, TIPO: ENTERA, PROCESO: PASTEURIZADA, AGREGADO: VITAMINAS A Y D, PRESENTACION: ENVASE X 800 GR, MATERIAL ENVASE: CARTON, ELEM. TRANSPORTE: SIN, MATERIAL ELEM. TRANSPORTE: SIN, CERTIFICADO FORESTAL (GFS): SIN, LIBRE DE GLUTEN: SI | H12: SI | I12: ='Necesidades Trimestrales'!F10 -> UNIDAD | J12: =+'Necesidades Trimestrales'!H10 -> 619 | K12: 100000 | M12: 619 | N12: 100000 | O12: =M12*N12 -> 61900000
A13: 2 | B13: ='Necesidades Trimestrales'!B11 -> 2.1.1-439.67 | C13: ='Necesidades Trimestrales'!E11 -> ACEITES COMESTIBLES; TIPO: GIRASOL, PRESENTACION: ENVASE X 900 CM3, MATERIAL ENVASE: PLASTICO 1 (PET), ELEM. TRANSPORTE: SIN, MATERIAL ELEM. TRANSPORTE : SIN, LIBRE DE GLUTEN: NO | H13: SI | I13: ='Necesidades Trimestrales'!F11 -> UNIDAD | J13: =+'Necesidades Trimestrales'!H11 -> 214 | K13: 100000 | M13: 214 | N13: 100000 | O13: =M13*N13 -> 21400000
A14: 3 | B14: ='Necesidades Trimestrales'!B12 -> 2.1.1-454.25 | C14: ='Necesidades Trimestrales'!E12 -> YERBAS; PALO: CON, PESO: 1 Kg, MATERIAL ENVASE : PAPEL, CERTIFICADO FORESTAL (GFS): CON, ELEM. TRANSPORTE: SIN, MATERIAL ELEM. TRANSPORTE: SIN, LIBRE DE GLUTEN: SI | H14: SI | I14: ='Necesidades Trimestrales'!F12 -> UNIDAD | J14: =+'Necesidades Trimestrales'!H12 -> 400 | K14: 100000 | M14: 400 | N14: 100000 | O14: =M14*N14 -> 40000000
A15: 4 | B15: ='Necesidades Trimestrales'!B13 -> 2.1.1-6547.84 | C15: ='Necesidades Trimestrales'!E13 -> LEGUMBRES; VARIEDAD: ARVEJAS, ESTADO: CONSERVA, PRESENTACION: LATA, PESO: 350 GR, MATERIAL ENVASE: METAL, ELEM. TRANSPORTE: SIN, MATERIAL ELEM. TRANSPORTE: SIN, LIBRE DE GLUTEN: NO | H15: SI | I15: ='Necesidades Trimestrales'!F13 -> UNIDAD | J15: =+'Necesidades Trimestrales'!H13 -> 47 | K15: 100000 | M15: 47 | N15: 100000 | O15: =M15*N15 -> 4700000
A16: 5 | B16: ='Necesidades Trimestrales'!B14 -> 2.1.1-435.60 | C16: ='Necesidades Trimestrales'!E14 -> ARROZ; TIPO GRANO: LARGO-FINO, TIPO: BLANCO, PROCESO: SIN CASCARA, PRESENTACION: BOLSA X 1 Kg, MATERIAL ENVASE: PLASTICO, CERTIFICADO FORESTAL (GFS): SIN, ELEM. TRANSPORTE: SIN, MATERIAL ELEM. TRANSPORTE: SIN, LIBRE DE GLUTEN: SI | H16: SI | I16: ='Necesidades Trimestrales'!F14 -> UNIDAD | J16: =+'Necesidades Trimestrales'!H14 -> 108 | K16: 100000 | M16: 108 | N16: 100000 | O16: =M16*N16 -> 10800000
A17: 6 | B17: ='Necesidades Trimestrales'!B15 -> 2.1.1-482.70 | C17: ='Necesidades Trimestrales'!E15 -> HARINAS; TIPO: 000, PRESENTACION: ENVASE X 1 Kg, MATERIAL ENVASE: PAPEL, CERTICADO FORESTAL (GFS): SI, ELEM. TRANSPORTE: SIN, MATERIAL ELEM. TRANSPORTE: SIN, LIBRE DE GLUTEN: NO | H17: SI | I17: ='Necesidades Trimestrales'!F15 -> UNIDAD | J17: =+'Necesidades Trimestrales'!H15 -> 94 | K17: 100000 | M17: 94 | N17: 100000 | O17: =M17*N17 -> 9400000
A18: 7 | B18: ='Necesidades Trimestrales'!B16 -> 2.1.1-6546.260 | C18: ='Necesidades Trimestrales'!E16 -> VERDURAS Y HORTALIZAS; VARIEDAD: TOMATE, ESTADO: PURE, PRESENTACION: TETRABRIK, PESO: 520 GR | H18: SI | I18: UNIDAD | J18: =+'Necesidades Trimestrales'!H16 -> 65 | K18: 100000 | M18: 65 | N18: 100000 | O18: =M18*N18 -> 6500000
A19: 8 | B19: ='Necesidades Trimestrales'!B17 -> 2.1.1-481.38 | C19: ='Necesidades Trimestrales'!E17 -> AZUCARES; TIPO: "A" COMUN, ESTADO: MOLIDA, PESO: 1 Kg, MATERIAL ENVASE: PLASTICO, CERTIFICADO FORESTAL (GFS): SIN, ELEM. TRANSPORTE: SIN, MATERIAL ELEM. TRANSPORTE: SIN | H19: SI | I19: UNIDAD | J19: =+'Necesidades Trimestrales'!H17 -> 94 | K19: 100000 | M19: 94 | N19: 100000 | O19: =M19*N19 -> 9400000
A20: 9 | B20: ='Necesidades Trimestrales'!B18 -> 2.1.1-2868.54 | C20: ='Necesidades Trimestrales'!E18 -> FIDEOS SECOS; VARIEDAD: SOPERO, RELLENO: SIN, PRESENTACION: ENVASE X 500 GR, MATERIAL ENVASE: PLASTICO 1 (PET), ELEM. TRANSPORTE: SIN, MATERIAL ELEM. TRANSPORTE: SIN, CERTIFICADO FORESTAL (GFS): SIN, LIBRE DE GLUTEN: NO | H20: SI | I20: UNIDAD | J20: =+'Necesidades Trimestrales'!H18 -> 59 | K20: 100000 | M20: 59 | N20: 100000 | O20: =M20*N20 -> 5900000
A21: 10 | B21: ='Necesidades Trimestrales'!B19 -> 2.1.1-2868.55 | C21: ='Necesidades Trimestrales'!E19 -> FIDEOS SECOS; VARIEDAD: TALLARIN, RELLENO: SIN, PRESENTACION: ENVASE X 500 GR, MATERIAL ENVASE: PLASTICO 1 (PET), ELEM. TRANSPORTE: SIN, MATERIAL ELEM. TRANSPORTE: SIN, CERTIFICADO FORESTAL (GFS): SIN, LIBRE DE GLUTEN: NO | H21: SI | I21: UNIDAD | J21: =+'Necesidades Trimestrales'!H19 -> 59 | K21: 100000 | M21: 59 | N21: 100000 | O21: =M21*N21 -> 5900000
A22: 11 | B22: ='Necesidades Trimestrales'!B20 -> 2.1.1-2868.71 | C22: ='Necesidades Trimestrales'!E20 -> FIDEOS SECOS; VARIEDAD: GUISERO, RELLENO: SIN, PRESENTACION: ENVASE X 500 GR, MATERIAL ENVASE: PLASTICO 1 (PET), ELEM. TRANSPORTE: SIN, MATERIAL ELEM. TRANSPORTE: SIN, CERTIFICADO FORESTAL (GFS): SIN, LIBRE DE GLUTEN: NO | H22: SI | I22: UNIDAD | J22: =+'Necesidades Trimestrales'!H20 -> 59 | K22: 100000 | M22: 59 | N22: 100000 | O22: =M22*N22 -> 5900000
A23: 12 | B23: =+'Necesidades Trimestrales'!B21 -> 2.1.1-6547.83 | C23: =+'Necesidades Trimestrales'!E21 -> LEGUMBRES; VARIEDAD: POROTOS PALLARES, ESTADO: EN CONSERVA, PRESENTACION: LATA, PESO: 350 GR, MATERIAL ENVASE: METAL, ELEM. TRANSPORTE: SIN, MATERIAL ELEM. TRANSPORTE: SIN | H23: SI | I23: UNIDAD | J23: =+'Necesidades Trimestrales'!H21 -> 51.8 | K23: 100000 | M23: 51.8 | N23: 100000 | O23: =M23*N23 -> 5180000
A24: 13 | B24: =+'Necesidades Trimestrales'!B22 -> 2.1.1-482.89 | C24: =+'Necesidades Trimestrales'!E22 -> HARINAS.TIPO: MAIZ PRECOCIDA O DE COCCION RAPIDA. PRESENTACION: ENVASE 500 GR. LIBRE DE GLUTEN:SI | H24: SI | I24: UNIDAD | J24: =+'Necesidades Trimestrales'!H22 -> 108 | K24: 100000 | M24: 108 | N24: 100000 | O24: =M24*N24 -> 10800000
A25: 14 | B25: =+'Necesidades Trimestrales'!B23 -> 2.1.1-6547.80 | C25: =+'Necesidades Trimestrales'!E23 -> LEGUMBRES; VARIEDAD: LENTEJA, ESTADO: SECO, PRESENTACION: SIN VALOR, PESO: ENVASE X 400 GR | H25: SI | I25: UNIDAD | J25: =+'Necesidades Trimestrales'!H23 -> 115 | K25: 100000 | M25: 115 | N25: 100000 | O25: =M25*N25 -> 11500000
A26: Costo total estimado:DOSCIENTOS NUEVE MILLONES DOSCIENTOS OCHENTA MIL CON 00/100.- | J26: =+J12*K12+J13*K13+J14*K14+J15*K15+J16*K16+J17*K17+J18*K18+J19*K19+J20*K20+J21*K21+J22*K22+J23*K23+J24*K24+J25*K25 -> 209280000

Sheet Autor Gastar
A1: EJERCICIO: | D1: ='Necesidades Trimestrales'!C6 -> 2022 | P1: AUTORIZACION PARA GASTAR
A4: JURISDICCIÓN: | G4: =' NotaPedido'!D3 -> 45- Ministerio de Desarrollo Social.-
A5: SAF: | G5: =' NotaPedido'!D4 -> 25- Direccion Provincial de Gestion Administracion y RRHH
A6: UNIDAD EJECUTORA: | G6: 16- Direccion Provincial de Accion Social Directa
A7: DEPENDENCIA SOLICITANTE: | G7: 02- PRO.VI.ME. Programa Vivir Mejor
A8: AUTORIZACIÓN:
A9: Señor Jefe de Servicio Administrativo Financiero:
A10: ="Autorizo la realización de los trámites correspondientes, a fin de proveer a este Organismo los bienes y/o servicios que se detallan en Nota de Pedido N° " & ' NotaPedido'!K1&", afectando la erogación resultante a los créditos presupuestarios aprobados a favor de esta Unidad Ejecutora, conforme al siguiente detalle:" -> Autorizo la realización de los trámites correspondientes, a fin de proveer a este Organismo los bienes y/o servicios que se detallan en Nota de Pedido N° 120/2022, afectando la erogación resultante a los créditos presupuestarios aprobados a favor de esta Unidad Ejecutora, conforme al siguiente detalle:
A12: IMPUTACIÓN PRESUPUESTARIA
A13: CÓDIGO | O13: DENOMINACIÓN DE LA PARTIDA PRESUPUESTARIA | Q13: IMPORTE
A14: PR | B14: SB | C14: PY | D14: AC | E14: OB | F14: UG | G14: FIN | H14: FUN | I14: I | J14: P | K14: P | L14: SubP | M14: M | N14: FF
A15: 16 | D15: 2 | F15: 4901 | G15: 3 | H15: 2 | I15: =LEFT('[1]Necesidades Trimestrales'!D10,1) -> 2 | J15: 1 | K15: 1 | M15: 1 | N15: 1.1 | O15: Alimentos para Personas | Q15: 209280000
A23: TOTAL DE PESOS: DOSCIENTOS NUEVE MILLONES DOSCIENTOS OCHENTA MIL CON 00/100.- | Q23: =SUM(Q15:Q22) -> 209280000
A25: JUSTIFICACIÓN:
A26: Adquisición de Alimentos que seran destinadas a personas de escasos recursos, en el armado de modulos alimentarios, en el Marco del Programa Vivir Mejor
