Workbook

Sheet Necesidades Trimestrales (2)
A1: 2021
B2: Pedido de Necesidades Trimestrales
A4: JURISDICCION: | C4: 40 - MINISTERIO DE SALUD
A5: SAF N°: | C5: 11 - DIRECCION PROVINCIAL DE ADMINISTRACION - MINISTERIO DE SALUD
A6: EJERCICIO: | C6: 2021
A7: TRIMESTRE: | C7: CUARTO TRIMESTRE
A9: ID | B9: CODIGO ITEM | C9: RUBRO DE COMPRA | D9: I.P.P. | E9: DESCRIPCION | F9: UNIDAD DE MEDIDA | G9: DIR DE ADM | H9: TOTAL DIR ADM | I9: SEC PREV | J9: TOTAL SEC PREVEN | K9: DIR. LAB. CENTRAL | L9: TOTAL DE LAB CENTRAL | M9: BCO DE SANGRE | N9: TOTAL BANCO DE SANGRE | O9: ATENCION PRIMARIA | P9: TOTAL ATENCION PRI | Q9: DIR DE CANCER | R9: TOTAL DE DIR DE CANCER | S9: FARMACIA | T9: TOTAL FARMACIA | U9: ODONTOLOGIA | V9: TOTAL DE ODONTOLOG | W9: SAME | X9: TOTAL DE SAME | Y9: MALBRAN | Z9: HOSPITAL MALBRAN | AA9: maternidade e infancia | AB9: total maternidad | AC9: SEC DE ASIST EN SALUD PUB | AD9: TOTAL SEC EN ASIS EN SAL | AE9: SALUD Y MEDIO AMBIENTE | AF9: TOTAL SALUD Y MEDIO AMBIENTE | AG9: VECTORES Y ZOONOSIS | AH9: TOTAL DE VECT Y ZOON | AI9: SUMAR | AJ9: TOTAL SUMAR | AK9: CUR | AL9: TOTAL CUR | AM9: PLANIFICACION | AN9: TOTAL PLANIFICA | AO9: SALUD MENTAL | AP9: TOTAL SALUD MENTAL | AQ9: AREAS Y DPAS | AR9: TOTAL DPAS | AS9: CANTIDAD TOTAL | AT9: PRECIO UNITARIO ESTIMADO | AU9: IMPORTE TOTAL ESTIMADO
A10: 1 | B10: 2.5.6-798.7 | C10: COMBUSTIBLES Y LUBRICANTES | D10: 2.5.6 | E10: GAS EN GARRAFA, CAPACIDAD: 45 KG. | F10: UNIDAD | H10: =+G10*AR10 -> 0 | I10: 0 | J10: =+I10*AT10 -> 0 | Y10: 400 | Z10: =+Y10*AT10 -> 2400000 | AS10: =+AQ10+AO10+AM10+AK10+AI10+AG10+AE10+AC10+AA10+Y10+W10+U10+S10+Q10+O10+M10+K10+I10 -> 400 | AT10: 6000 | AU10: =+AS10*AT10 -> 2400000
A11: 1 | B11: 2.5.6-793.31 | C11: COMBUSTIBLES Y LUBRICANTES | D11: 2.5.6 | E11: GAS OIL; PRESENTACION: POR LITRO, USO: MOTORES DIESEL,COMERCIALIZACION: GRADO 3, DESTINO: DPTO. S.F.V. DE CATAMARCA | F11: LITROS | H11: =+G11*AR11 -> 0 | I11: 2500 | J11: =+I11*AT11 -> 269250 | M11: 200 | N11: =+M11*AT11 -> 21540 | O11: 1112 | P11: =+O11*AT11 -> 119762.4 | Q11: =99000/AT11 -> 919.22006 | R11: =+Q11*AT11 -> 99000 | W11: 15837 | X11: =+W11*AT11 -> 1705644.9 | Y11: 1000 | Z11: =+Y11*AT11 -> 107700 | AA11: 3650 | AB11: =+AA11*AT11 -> 393105 | AC11: 2200 | AD11: =+AC11*AT11 -> 236940 | AE11: 5275 | AF11: =+AE11*AT11 -> 568117.5 | AG11: 2534 | AH11: =+AG11*AT11 -> 272911.8 | AK11: 2500 | AL11: =+AK11*AT11 -> 269250 | AN11: =+AM11*AT11 -> 0 | AO11: 900 | AP11: =+AO11*AT11 -> 96930 | AQ11: =+AR11/AT11 -> 101280.41 | AR11: =900000+900000+400000+500000+380000+500000+600000+500000+866900+1537000+900000+1764000+600000+200000+360000 -> 10907900 | AS11: =+'NP DPAS'!K12 -> 27855 | AT11: 107.7 | AU11: =+AS11*AT11 -> 2999983.5
B14: ITEM 1 Y 2 DETALLE TECNICO Y ESPECIFICACIONES | C14: Se Entregarán Fraccionado bajo la forma de vales de 2000 Lts. cada uno y cuando la cantidad adjudicada no permita la confección de dicho vale, para completar se emitirá uno por una cantidad menor hasta completar la cantidad solicitada
B15: SE ADJUNTA ANEXO CON LOS DOMINIOS Y MATRICULA DE LOS VEHICULOS PARA LO CUAL SE SOLICITA EL COMBUSTIBLE
B17: Plazos de entrega | C17: cinco (5) dias
B19: Lugar de Entrega: | C19: DIR. PROV. DE ADMINISTRACION - MS - CHACABUCO N° 169 - en el horario de 8:00hs a 12:00hs de lunes a viernes
B21: Calidad Minima esperada
B23: Mantenimiento | C23: cuarenta y cinco (45) días

Sheet ANEXO DE MATRICULAS Y DOMINIO
A1: DIRECCION PROVINCIAL ASISTENCIA SANITARIA NIVEL I Y II
A3: Area Programatica Nº1
A5: Vehiculo | B5: Dominio | C5: Nº de Motor | D5: Nº Chasis | E5: Año
A6: Renault Master - Ambulancia.- | B6: GEU-277 | C6: G9UA724C030714 | D6: 93YADCUE57J787157 | E6: 2007
A7: Renault Master- Ambulancia.- | B7: GUV-922 | C7: G9UA724C035587 | D7: 93YADCUE58J896449 | E7: 2008
A8: Renault Master-PH3 DCI 120 L1H2 Ambulancia.- | B8: KNI-753 | C8: G9UA754C268409 | D8: 93YADCUE6CJ897389 | E8: 2011
A9: Ford F-100 4x2 XL PLUS 3,9 D - Ambulacia.- | B9: ILC-099 | C9: 36071580 | D9: 9EFFF22C99B859146 | E9: 2010
A10: Renault Master PH3 DCI 120 L1H2 - Ambulancia.- | B10: LAD-136 | C10: G9UA754C270571 | D10: 93YADCUE6CJ969873 | E10: 2012
A11: Fiat Ducato. Ambulancia.- | B11: NHW-650 | C11: 7173538 | D11: 93W245G84D2112772 | E11: 2013
A12: Mercedez Benz Sprinter Furgon.- | B12: GWJ-779 | C12: 61198170074458 | D12: 8AC90036628A984192 | E12: 2008
A13: Renault Master MASTER PH3 DCI 120 - Ambulancia.- | B13: LAD-135 | C13: G9UA650C244170 | D13: 93YADC1E6CJ140233 | E13: 2012
A14: Renault Master DCI 120 - Ambulancia.- | B14: GJP-880 | C14: G9UA724C026899 | D14: 93YADCUH56J706159 | E14: 2007
A15: Chevrolet S-10. Camioneta.- | B15: GWJ-742 | C15: M1A304122 | D15: 9BG124AJ08C11312 | E15: 2008
A16: Chevrolet Zafira. Camioneta.- | B16: HUD-575 | C16: 1N0006130 | D16: 9BGTT75F09C131088 | E16: 2008
A17: Fiat Ducato Amxicargo 2,3 JTD. Ambulancia.- | B17: AA-842-EL | C17: 7250765 | D17: 93W245G84H2160838 | E17: 2016
A18: Fiat Ducato Amxicargo 2,3 JTD. Ambulancia.- | B18: AA-842-EI | C18: 7250728 | D18: 93W245G84H2160833 | E18: 2016
A19: Toyota Hilux 4x4 c/s DX 2,4 TDI M/T. Ambulancia | B19: AA-793-NE | C19: 2GD-0137533 | D19: 8AJFB8CB5H1550878 | E19: 2017
A20: Renault Master- Ambulancia.- | B20: AE-041-BD | C20: M9TB870C262154 | D20: 93YMAFESCLJ213469 | E20: 2020
A22: Area Programatica Nº2
A24: Vehiculo | B24: Dominio | C24: Nº de Motor | D24: Nº Chasis | E24: Año
A25: Fiat Ducato Maxi cargo 2,3 JTD Furgon. Ambulancia.- | B25: AA-842-EH | C25: 7250726 | D25: 93W245G84H2160832 | E25: 2016
A26: Fiat Ducato Maxi cargo 2,3 JTD Furgon. Ambulancia.- | B26: AA-842-EF | C26: 7250640 | D26: 93W245G84H2160831 | E26: 2016
A27: Fiat Ducato 2,3. Ambulancia.- | B27: NSE-229 | C27: 7166125 | D27: 93W245G74D2109008 | E27: 2014
A28: Renault Master DCI120. Ambulancia - | B28: GUO-325 | C28: G9UA7240035511 | D28: 93YADCUE58J896313 | E28: 2007
A29: Renault Master DCI120 - Ambulancia .- | B29: GJS-713 | C29: G9UA724C030282 | D29: 93YADCUE57J787718 | E29: 2007
A30: Fiat iveco Daily. Ambulancia.- | B30: S/P | C30: 37344067044 | D30: 93ZC4980158318123 | E30: 2005
A31: Ford Ranger XLC/C 4x4 2,8. Camioneta.- | B31: FYK-918 | C31: B61618215 | D31: 8AFER13FX4J326463 | E31: 2007
A33: Area Programatica Nº3
A35: Vehiculo | B35: Dominio | C35: Nº de Motor | D35: Nº Chasis | E35: Año
A36: Chevrolet S10 2,8 TDI - Camioneta.- | B36: GDD-914 | C36: M1A282868 | D36: 9BG138AJ07C413213 | E36: 2007
A37: Renautl Master 2,5 D - Ambulancia.- | B37: GJC-299 | C37: J9UA724C030522 | D37: 93YADCUE57J787225 | E37: 2007
A38: Fiat Ducato Maxi cargo 2,3. Ambulancia | B38: AA-702-MN | C38: 7251288 | D38: 93W245G74H2161118 | E38: 2016
A39: Ford Transit 2,2 L 125 T350 TA C/AA - Ambulancia.- | B39: MNW-258 | C39: CYRCDTT22471 | D39: WFOXXPTTFDTT22471 | E39: 2013
A40: Mercedez Benz Sprinter - Ambulancia.- | B40: DCA-098 | C40: 10520880 | D40: 8AC690311YA537631 | E40: 1998
A41: Chevrolet S10 2,8 T.I- Ambulancia.- | B41: ESH-451 | C41: 40704192268 | D41: 986124AC05C410447 | E41: 2014
A46: Vehiculo | B46: Dominio | C46: Nº de Motor | D46: Nº Chasis | E46: Año
A47: Chevrolet S10 2,8 TDI SID 4x2 - Ambulancia.- | B47: GDD-918 | C47: M1A282927 | D47: 9BG1384J07C413214 | E47: 2007
A48: Renault Master DCI 120- Ambulancia.- | B48: GEU-279 | C48: G9UA724C030527 | D48: 93YADCUE7J787131 | E48: 2007
A49: Chevrolet S10 2,8 TDI - Ambulancia.- | B49: ESH-453 | C49: 40704192255 | D49: 9BG124ACOSC410400 | E49: 1999
A50: Mercedez Benz Sprinter - Ambulancia.- | B50: DCA-097 | C50: 632999105118976 | D50: 8AC690311 | E50: 2000
...

Sheet NP DPAS
A1: NOTA DE PEDIDO | J1: N° | K1: 23/2021
A3: JURISDICCIÓN: | D3: 040 - Ministerio de Salud
A4: SAF: | D4: 011 - Direccion Provincial de Administración - Ministerio de Salud
A5: UNIDAD EJECUTORA: | D5: 476 - DIRECCION PROVINCIAL DE ASISTENCIA SANITARIA NIVEL I Y II
A6: DEPENDENCIA SOLICITANTE: | D6: 476 - DIRECCION PROVINCIAL DE ASISTENCIA SANITARIA NIVEL I Y II
A7: PERIODO UTILIZACIÓN: | D7: 4° TRIMESTRE
A8: OBJETO: | D8: Adquisicion del RUBRO COMBUSTIBLES
A10: Ítem | B10: Codigo Item | C10: DESCRIPCIÓN | H10: Adjunta Detalle Técnico | I10: Unidad Medida | J10: Precio Unitario Estimado | K10: Cantidad Solicitada
A12: 1 | B12: ='Necesidades Trimestrales (2)'!B11 -> 2.5.6-793.31 | C12: ='Necesidades Trimestrales (2)'!E11 -> GAS OIL; PRESENTACION: POR LITRO, USO: MOTORES DIESEL,COMERCIALIZACION: GRADO 3, DESTINO: DPTO. S.F.V. DE CATAMARCA | H12: NO | I12: ='Necesidades Trimestrales (2)'!F11 -> LITROS | J12: =+'Necesidades Trimestrales (2)'!AT11 -> 107.7 | K12: 27855
A13: Costo total estimado: DOS MILLONES NOVECIENTOS NOVENTA Y NUEVE MIL NOVECIENTOS OCHENTA Y TRES CON 50/100.- | J13: =+K12*J12 -> 2999983.5 | M13: =SUM(M12:M12) -> 0

Sheet APG DPAS
A1: EJERCICIO: | D1: 2021 | P1: AUTORIZACION PARA GASTAR
A4: JURISDICCIÓN: | G4: ='NP DPAS'!D3 -> 040 - Ministerio de Salud
A5: SAF: | G5: ='NP DPAS'!D4 -> 011 - Direccion Provincial de Administración - Ministerio de Salud
A6: UNIDAD EJECUTORA: | G6: ='NP DPAS'!D5 -> 476 - DIRECCION PROVINCIAL DE ASISTENCIA SANITARIA NIVEL I Y II
A7: DEPENDENCIA SOLICITANTE: | G7: ='NP DPAS'!D6 -> 476 - DIRECCION PROVINCIAL DE ASISTENCIA SANITARIA NIVEL I Y II
A8: AUTORIZACIÓN:
A9: Señor Jefe de Servicio Administrativo Financiero:
A10: Autorizo la realización de los trámites correspondientes, a fin de proveer a este Organismo los bienes que se detallan en Nota de pedido y Entrega N° 23/2021, afectando la erogación resultante a los créditos presupuestarios aprobados a favor de esta Unidad Ejecutora, conforme al siguiente detalle:
A12: IMPUTACIÓN PRESUPUESTARIA
A13: CÓDIGO | O13: DENOMINACIÓN DE LA PARTIDA PRESUPUESTARIA | Q13: IMPORTE
A14: PR | B14: SB | C14: PY | D14: AC | E14: OB | F14: UG | G14: FIN | H14: FUN | I14: I | J14: P | K14: P | L14: SubP | M14: M | N14: FF
A15: 21 | D15: 1 | F15: 4901 | G15: 3 | H15: 1 | I15: 2 | J15: 5 | K15: 6 | M15: 1 | N15: 1.1 | O15: COMBUSTIBLES Y LUBRICANTES | Q15: =+'Necesidades Trimestrales (2)'!#REF! -> #REF!
A22: TOTAL DE PESOS: DOS MILLONES NOVECIENTOS NOVENTA Y NUEVE MIL NOVECIENTOS OCHENTA Y TRES CON 50/100.- | Q22: =SUM(Q15:Q21) -> #REF!
A24: JUSTIFICACIÓN:
A25: ='NP DPAS'!D8 -> Adquisicion del RUBRO COMBUSTIBLES
