Workbook
Name A: 'Necesidades Trimestrales'!$C$73

Sheet Necesidades Trimestrales
B2: Pedido de Necesidades Trimestrales
A4: JURISDICCION: | C4: 40 - Ministerio de Salud
A5: SAF N°: | C5: 28 - MATERNIDAD
A6: EJERCICIO: | C6: 1° Trimestre -Año 2021
A7: TRIMESTRE: | C7: 1
A9: ID | B9: CODIGO ITEM | C9: RUBRO DE COMPRA | D9: I.P.P. | E9: DESCRIPCION | F9: UNIDAD DE MEDIDA | G9: CANTIDAD | H9: PRECIO UNITARIO ESTIMADO | I9: IMPORTE TOTAL ESTIMADO
A10: 1 | B10: 2.5.1-9043.2 | C10: QUIMICOS | D10: =LEFT(B10,5) -> 2.5.1 | E10: ACEITES Y GRASAS; COMPUESTO QUIMICO: ACEITE DE INMERSION, ESTADO: LIQUIDO, CALIDAD: PRO ANALISIS, CONCENTRACION/PUREZA: 99,9 %, PRESENTACION: ENVASE X 100 mL | F10: FRASCO | G10: 1 | H10: 1505.9 | I10: =H10*G10 -> 1505.9
A11: 2 | B11: 2.5.1-9016.200 | C11: QUIMICOS | D11: =LEFT(B11,5) -> 2.5.1 | E11: MEDIOS DE CULTIVO Y SUPLEMENTO; NOMBRE DEL PRODUCTO: AGAR BASE SANGRE, ESTADO: SOLIDO, PRESENTACION: ENVASE X 500 mL | F11: FRASCO | G11: 1 | H11: 11963.6 | I11: =H11*G11 -> 11963.6
A12: 3 | B12: 2.5.1-9016.279 | C12: QUIMICOS | D12: =LEFT(B12,5) -> 2.5.1 | E12: MEDIOS DE CULTIVO Y SUPLEMENTO; NOMBRE DEL PRODUCTO: AGAR BILIS ESCULINA, ESTADO: SOLIDO, PRESENTACION: ENVASE X 100 GR | F12: FRASCO | G12: 1 | H12: 14326.4 | I12: =H12*G12 -> 14326.4
A13: 4 | B13: 2.5.1-9016.214 | C13: QUIMICOS | D13: =LEFT(B13,5) -> 2.5.1 | E13: MEDIOS DE CULTIVO Y SUPLEMENTO; NOMBRE DEL PRODUCTO: AGAR CITRATO DE SIMMONS, ESTADO: SOLIDO, PRESENTACION: ENVASE X 100 GR | F13: FRASCO | G13: 1 | H13: 4181.1 | I13: =H13*G13 -> 4181.1
A14: 5 | B14: 2.5.1-9016.383 | C14: QUIMICOS | D14: =LEFT(B14,5) -> 2.5.1 | E14: MEDIOS DE CULTIVO Y SUPLEMENTO; NOMBRE DEL PRODUCTO: AGAR C.L.D.E, ESTADO: SOLIDO, PRESENTACION: ENVASE X 500 GR | F14: FRASCO | G14: 1 | H14: 10201.4 | I14: =H14*G14 -> 10201.4
A15: 6 | B15: 2.5.1-9016.227 | C15: QUIMICOS | D15: =LEFT(B15,5) -> 2.5.1 | E15: MEDIOS DE CULTIVO Y SUPLEMENTO; NOMBRE DEL PRODUCTO: AGAR EOSINA-AZUL METILENO-LACT, ESTADO: SOLIDO, PRESENTACION: ENVASE X 500 GR | F15: FRASCO | G15: 1 | H15: 10297.1 | I15: =H15*G15 -> 10297.1
A16: 7 | B16: 2.5.1-9016.181 | C16: QUIMICOS | D16: =LEFT(B16,5) -> 2.5.1 | E16: MEDIOS DE CULTIVO Y SUPLEMENTO; NOMBRE DEL PRODUCTO: AGAR MANITOL SALADO, ESTADO: SOLIDO, PRESENTACION: ENVASE X 100 GR | F16: FRASCO | G16: 1 | H16: 2101 | I16: =H16*G16 -> 2101
A17: 8 | B17: 2.5.1-9016.222 | C17: QUIMICOS | D17: =LEFT(B17,5) -> 2.5.1 | E17: MEDIOS DE CULTIVO Y SUPLEMENTO; NOMBRE DEL PRODUCTO: AGAR MULLER HILTON, ESTADO: SOLIDO, PRESENTACION: ENVASE X 500 GR | F17: FRASCO | G17: 1 | H17: 13578.4 | I17: =H17*G17 -> 13578.4
A18: 9 | B18: 2.5.1-9052.1667 | C18: QUIMICOS | D18: =LEFT(B18,5) -> 2.5.1 | E18: REACTIVOS P/LAB. TEC. MANUAL ; NOMBRE: BAM CON UREA MEDIO, USO: BACTERIOLOGIA, PRESENTACION: ENVASE X 500 GR | F18: FRASCO | G18: 1 | H18: 5365.8 | I18: =H18*G18 -> 5365.8
A19: 10 | B19: 2.5.1-9016.191 | C19: QUIMICOS | D19: =LEFT(B19,5) -> 2.5.1 | E19: MEDIOS DE CULTIVO Y SUPLEMENTO; NOMBRE DEL PRODUCTO: AGAR LISINA HIERRO, ESTADO: SOLIDO, PRESENTACION: ENVASE X 100 GR | F19: FRASCO | G19: 1 | H19: 5869.6 | I19: =H19*G19 -> 5869.6
A20: 11 | B20: 2.5.1-9016.236 | C20: QUIMICOS | D20: =LEFT(B20,5) -> 2.5.1 | E20: MEDIOS DE CULTIVO Y SUPLEMENTO; NOMBRE DEL PRODUCTO: AGAR HIERRO TRIPLE AZUCAR, ESTADO: SOLIDO, PRESENTACION: ENVASE X 100 GR | F20: FRASCO | G20: 1 | H20: 3144.9 | I20: =H20*G20 -> 3144.9
A21: 12 | B21: 2.5.1-9016.106 | C21: QUIMICOS | D21: =LEFT(B21,5) -> 2.5.1 | E21: MEDIOS DE CULTIVO Y SUPLEMENTO; NOMBRE DEL PRODUCTO: AGAR SIM, ESTADO: SOLIDO, PRESENTACION: ENVASE X 100 GR | F21: FRASCO | G21: 1 | H21: 6322.8 | I21: =H21*G21 -> 6322.8
... A133: 124 | B133: 2.5.1-8988.229 | C133: QUIMICOS | D133: =LEFT(B133,5) -> 2.5.1 | E133: REACTIVOS P/EQUIPO; EQUIPO: AUTOANA. X QUIMIOLUMINISCENCIA, MARCA EQUIPO: ROCHE, NOMBRE DEL PRODUCTO: KIT P/CUANT. HORMONA CORTISOL, PRESENTACION: ENVASE X 100 DETERM. | F133: UNIDAD | G133: 1 | H133: 12963 | I133: =H133*G133 -> 12963
B142: Especificidades Item N° 58:
B144: Descripción técnica | C144: ANTIBIOTICOS; COMPUESTO QUIMICO: RIFAMPICINA, ESTADO: DISCO, CALIDAD: PRO ANALISIS, PRESENTACION: ENVASE X 50 UN 5 UG
B146: Plazos y lugares de entrega
C147: 10 DIAS DESDE LA RECEPCIONDE LA ORDEN DE COMPRA
C148: LABORATORIO DE LA MATERNIDAD PROVINCIAL 25 DE MAYO - H DE PEDRAZA 1500
B149: Calidad Minima esperada
C150: LIOFILCHEM
B151: Mantenimiento
C152: 30 DIAS HABILES
B153: Garantia
B158: Especificidades Item N° 102:
B160: Descripción técnica
C161: REACTIVOS P/EQUIPO; EQUIPO: ANALIZADOR MULTIPARAMETRICO, MARCA EQUIPO: COBAS ROCHE, NOMBRE DEL PRODUCTO: DET. DE ACIDO URICO, PRESENTACION: 400 determinasiones
B162: Plazos y lugares de entrega
C163: 10 DIAS DESDE LA RECEPCIONDE LA ORDEN DE COMPRA
C164: LABORATORIO DE LA MATERNIDAD PROVINCIAL 25 DE MAYO - H DE PEDRAZA 1500
B165: Calidad Minima esperada
C166: ROCHE
B167: Mantenimiento
C168: 30 DIAS HABILES
B169: Garantia
...

Sheet  NotaPedido
A1: NOTA DE PEDIDO | H1: N° | I1: 29/2021
A3: JURISDICCIÓN: | D3: 40- Ministerio de Salud
A4: SAF: | D4: 28- Maternidad Provincial
A5: UNIDAD EJECUTORA: | D5: Servicio de Laboratorio-(Bacteriología-Hemoterapia)-Serv. De Odontología-Direc.de Mantenimiento-
A6: DEPENDENCIA SOLICITANTE: | D6: Servicio de Laboratorio-(Bacteriología-Hemoterapia)-Serv. De Odontología-Direc.de Mantenimiento-
A7: PERIODO UTILIZACIÓN: | D7: 1 ° Trimestre -Año 2021
A8: OBJETO: | D8: ADQUISICION DE COMPUESTOS QUIMICOS
A10: Ítem | B10: Codigo Item | C10: DESCRIPCIÓN | F10: Adjunta Detalle Técnico | G10: Unidad Medida | H10: Precio Unitario Estimado | I10: Cantidad Solicitada
A12: 1 | B12: ='Necesidades Trimestrales'!B10 -> 2.5.1-9043.2 | C12: ='Necesidades Trimestrales'!E10 -> ACEITES Y GRASAS; COMPUESTO QUIMICO: ACEITE DE INMERSION, ESTADO: LIQUIDO, CALIDAD: PRO ANALISIS, CONCENTRACION/PUREZA: 99,9 %, PRESENTACION: ENVASE X 100 mL | F12: NO | G12: ='Necesidades Trimestrales'!F10 -> FRASCO | H12: ='Necesidades Trimestrales'!H10 -> 1505.9 | I12: ='Necesidades Trimestrales'!G10 -> 1
A13: 2 | B13: ='Necesidades Trimestrales'!B11 -> 2.5.1-9016.200 | C13: ='Necesidades Trimestrales'!E11 -> MEDIOS DE CULTIVO Y SUPLEMENTO; NOMBRE DEL PRODUCTO: AGAR BASE SANGRE, ESTADO: SOLIDO, PRESENTACION: ENVASE X 500 mL | F13: NO | G13: ='Necesidades Trimestrales'!F11 -> FRASCO | H13: ='Necesidades Trimestrales'!H11 -> 11963.6 | I13: ='Necesidades Trimestrales'!G11 -> 1
A14: 3 | B14: ='Necesidades Trimestrales'!B12 -> 2.5.1-9016.279 | C14: ='Necesidades Trimestrales'!E12 -> MEDIOS DE CULTIVO Y SUPLEMENTO; NOMBRE DEL PRODUCTO: AGAR BILIS ESCULINA, ESTADO: SOLIDO, PRESENTACION: ENVASE X 100 GR | F14: NO | G14: ='Necesidades Trimestrales'!F12 -> FRASCO | H14: ='Necesidades Trimestrales'!H12 -> 14326.4 | I14: ='Necesidades Trimestrales'!G12 -> 1
A15: 4 | B15: ='Necesidades Trimestrales'!B13 -> 2.5.1-9016.214 | C15: ='Necesidades Trimestrales'!E13 -> MEDIOS DE CULTIVO Y SUPLEMENTO; NOMBRE DEL PRODUCTO: AGAR CITRATO DE SIMMONS, ESTADO: SOLIDO, PRESENTACION: ENVASE X 100 GR | F15: NO | G15: ='Necesidades Trimestrales'!F13 -> FRASCO | H15: ='Necesidades Trimestrales'!H13 -> 4181.1 | I15: ='Necesidades Trimestrales'!G13 -> 1
A16: 5 | B16: ='Necesidades Trimestrales'!B14 -> 2.5.1-9016.383 | C16: ='Necesidades Trimestrales'!E14 -> MEDIOS DE CULTIVO Y SUPLEMENTO; NOMBRE DEL PRODUCTO: AGAR C.L.D.E, ESTADO: SOLIDO, PRESENTACION: ENVASE X 500 GR | F16: NO | G16: ='Necesidades Trimestrales'!F14 -> FRASCO | H16: ='Necesidades Trimestrales'!H14 -> 10201.4 | I16: ='Necesidades Trimestrales'!G14 -> 1
A17: 6 | B17: ='Necesidades Trimestrales'!B15 -> 2.5.1-9016.227 | C17: ='Necesidades Trimestrales'!E15 -> MEDIOS DE CULTIVO Y SUPLEMENTO; NOMBRE DEL PRODUCTO: AGAR EOSINA-AZUL METILENO-LACT, ESTADO: SOLIDO, PRESENTACION: ENVASE X 500 GR | F17: NO | G17: ='Necesidades Trimestrales'!F15 -> FRASCO | H17: ='Necesidades Trimestrales'!H15 -> 10297.1 | I17: ='Necesidades Trimestrales'!G15 -> 1
A18: 7 | B18: ='Necesidades Trimestrales'!B16 -> 2.5.1-9016.181 | C18: ='Necesidades Trimestrales'!E16 -> MEDIOS DE CULTIVO Y SUPLEMENTO; NOMBRE DEL PRODUCTO: AGAR MANITOL SALADO, ESTADO: SOLIDO, PRESENTACION: ENVASE X 100 GR | F18: NO | G18: ='Necesidades Trimestrales'!F16 -> FRASCO | H18: ='Necesidades Trimestrales'!H16 -> 2101 | I18: ='Necesidades Trimestrales'!G16 -> 1
A19: 8 | B19: ='Necesidades Trimestrales'!B17 -> 2.5.1-9016.222 | C19: ='Necesidades Trimestrales'!E17 -> MEDIOS DE CULTIVO Y SUPLEMENTO; NOMBRE DEL PRODUCTO: AGAR MULLER HILTON, ESTADO: SOLIDO, PRESENTACION: ENVASE X 500 GR | F19: NO | G19: ='Necesidades Trimestrales'!F17 -> FRASCO | H19: ='Necesidades Trimestrales'!H17 -> 13578.4 | I19: ='Necesidades Trimestrales'!G17 -> 1
A20: 9 | B20: ='Necesidades Trimestrales'!B18 -> 2.5.1-9052.1667 | C20: ='Necesidades Trimestrales'!E18 -> REACTIVOS P/LAB. TEC. MANUAL ; NOMBRE: BAM CON UREA MEDIO, USO: BACTERIOLOGIA, PRESENTACION: ENVASE X 500 GR | F20: NO | G20: ='Necesidades Trimestrales'!F18 -> FRASCO | H20: ='Necesidades Trimestrales'!H18 -> 5365.8 | I20: ='Necesidades Trimestrales'!G18 -> 1
A21: 10 | B21: ='Necesidades Trimestrales'!B19 -> 2.5.1-9016.191 | C21: ='Necesidades Trimestrales'!E19 -> MEDIOS DE CULTIVO Y SUPLEMENTO; NOMBRE DEL PRODUCTO: AGAR LISINA HIERRO, ESTADO: SOLIDO, PRESENTACION: ENVASE X 100 GR | F21: NO | G21: ='Necesidades Trimestrales'!F19 -> FRASCO | H21: ='Necesidades Trimestrales'!H19 -> 5869.6 | I21: ='Necesidades Trimestrales'!G19 -> 1
A22: 11 | B22: ='Necesidades Trimestrales'!B20 -> 2.5.1-9016.236 | C22: ='Necesidades Trimestrales'!E20 -> MEDIOS DE CULTIVO Y SUPLEMENTO; NOMBRE DEL PRODUCTO: AGAR HIERRO TRIPLE AZUCAR, ESTADO: SOLIDO, PRESENTACION: ENVASE X 100 GR | F22: NO | G22: ='Necesidades Trimestrales'!F20 -> FRASCO | H22: ='Necesidades Trimestrales'!H20 -> 3144.9 | I22: ='Necesidades Trimestrales'!G20 -> 1
A23: 12 | B23: ='Necesidades Trimestrales'!B21 -> 2.5.1-9016.106 | C23: ='Necesidades Trimestrales'!E21 -> MEDIOS DE CULTIVO Y SUPLEMENTO; NOMBRE DEL PRODUCTO: AGAR SIM, ESTADO: SOLIDO, PRESENTACION: ENVASE X 100 GR | F23: NO | G23: ='Necesidades Trimestrales'!F21 -> FRASCO | H23: ='Necesidades Trimestrales'!H21 -> 6322.8 | I23: ='Necesidades Trimestrales'!G21 -> 1
... A135: 124 | B135: ='Necesidades Trimestrales'!B133 -> 2.5.1-8988.229 | C135: ='Necesidades Trimestrales'!E133 -> REACTIVOS P/EQUIPO; EQUIPO: AUTOANA. X QUIMIOLUMINISCENCIA, MARCA EQUIPO: ROCHE, NOMBRE DEL PRODUCTO: KIT P/CUANT. HORMONA CORTISOL, PRESENTACION: ENVASE X 100 DETERM. | F135: NO | G135: ='Necesidades Trimestrales'!F133 -> UNIDAD | H135: ='Necesidades Trimestrales'!H133 -> 12963 | I135: ='Necesidades Trimestrales'!G133 -> 1
A136: Costo total: DOS MILLONES NOVECIENTOS CINCUENTA Y UN MIL TRESCIENTOS TREINTA Y DOS CON 66/100 CENTAVOS. | I136: {=SUMPRODUCT(H12:H135*I12:I135)} -> 2951332.7

Sheet Autor Gastar
A1: EJERCICIO: | D1: 2021 | P1: AUTORIZACION PARA GASTAR
A4: JURISDICCIÓN: | G4: 40- Ministerio de Salud
A5: SAF: | G5: 28- Maternidad Provincial
A6: UNIDAD EJECUTORA: | G6: Servicio de Laboratorio-(Bacteriología-Hemoterapia)-Serv. De Odontología-Direc.de Mantenimiento-
A7: DEPENDENCIA SOLICITANTE: | G7: Servicio de Laboratorio(Bacteriología)-Serv. De Odontología-Direc.de Mantenimiento
A8: AUTORIZACIÓN:
A9: Señor Jefe de Servicio Administrativo Financiero:
A10: Autorizo la realización de los trámites correspondientes, a fin de proveer a este Organismo los bienes y/o servicios que se detallan en Nota de Pedido N° 29/2021 , afectando la erogación resultante a los créditos presupuestarios aprobados a favor de esta Unidad Ejecutora, conforme al siguiente detalle:"
A12: IMPUTACIÓN PRESUPUESTARIA
A13: CÓDIGO | O13: DENOMINACIÓN DE LA PARTIDA PRESUPUESTARIA | Q13: IMPORTE
A14: PR | B14: SB | C14: PY | D14: AC | E14: OB | F14: UG | G14: FIN | H14: FUN | I14: I | J14: P | K14: P | L14: SubP | M14: M | N14: FF
A15: 42 | D15: 2 | F15: 4901 | G15: 3 | H15: 1 | I15: 2 | J15: 5 | K15: 1 | M15: 1 | N15: 1.1 | O15: Compuestos Quimicos | Q15: 2950125.2
A16: 42 | D16: 2 | F16: 4901 | G16: 3 | H16: 1 | I16: 2 | J16: 5 | K16: 6 | M16: 1 | N16: 1.1 | O16: Combustibles y lubricantes | Q16: 1207.5
A19: TOTAL DE PESOS: DOS MILLONES NOVECIENTOS CINCUENTA Y UN MIL TRESCIENTOS TREINTA Y DOS CON 66/100 CENTAVOS. | Q19: =SUM(Q15:Q18) -> 2951332.7
A21: JUSTIFICACIÓN:
A22: Para la adquisición de Compuestos Químicos, para ser destinados al Servicio de Laboratorio-Sector Bacteriología, Serv. De Odontología y Direc. De Mantenimiento de la Maternidad Provincial 25 de Mayo.-
