Workbook

Sheet Necesidades Trimestrales
E2: Pedido de Necesidades Trimestrales
A4: JURISDICCION: | E4: 40-Ministerio de Salud
A5: SAF N°: | E5: 28- Maternidad Provincial 25 de Mayo
A6: EJERCICIO: | E6: 2022
A7: TRIMESTRE: | E7: 3°
A9: ID | B9: CODIGO ITEM | C9: RUBRO DE COMPRA | D9: I.P.P. | E9: DESCRIPCION | F9: UNIDAD DE MEDIDA | G9: CANTIDAD | H9: PRECIO UNITARIO ESTIMADO | I9: IMPORTE TOTAL ESTIMADO
A10: 1 | B10: 2.9.5-441.319 | C10: PROD. MEDICO/FARMACEUTICOS/LAB | D10: 295 | E10: AGUJAS QUIRURGICAS; TIPO: BUTTERFLY, ESPECIFICACION: 25G, PRESENTACION: UNIDAD | F10: UNIDAD | G10: 50 | H10: 12 | I10: =+H10*G10 -> 600
A11: 2 | B11: 2.9.5-441.469 | C11: PROD. MEDICO/FARMACEUTICOS/LAB | D11: 295 | E11: AGUJAS QUIRURGICAS; TIPO: BUTTERFLY, ESPECIFICACION: 27, PRESENTACION: ENVASE ESTERIL | F11: UNIDAD | G11: 50 | H11: 12 | I11: =+H11*G11 -> 600
A12: 3 | B12: 2.9.5-427.31 | C12: PROD. MEDICO/FARMACEUTICOS/LAB | D12: 295 | E12: APOSITOS; TIPO: P/SUJECION DE CATETER, TAMAÑO: 10 X 12 Cm | F12: UNIDAD | G12: 180 | H12: 67 | I12: =+H12*G12 -> 12060
A13: 4 | B13: 2.9.5-427.84 | C13: PROD. MEDICO/FARMACEUTICOS/LAB | D13: 295 | E13: APOSITOS; TIPO: P/SUJECION DE CATETER, TAMAÑO: 6 X 7 Cm | F13: UNIDAD | G13: 950 | H13: 37.5 | I13: =+H13*G13 -> 35625
A14: 5 | B14: 2.9.5-2161.7 | C14: PROD. MEDICO/FARMACEUTICOS/LAB | D14: 295 | E14: CATÉTER INTRAVENOSO Nº 14; TIPO: INTRAVENOSO/CANALIZACIÓN | F14: UNIDAD | G14: 50 | H14: 45 | I14: =+H14*G14 -> 2250
A15: 6 | B15: 2.9.5-2161.2 | C15: PROD. MEDICO/FARMACEUTICOS/LAB | D15: 295 | E15: CATÉTER INTRAVENOSO Nº 18; TIPO: INTRAVENOSO/CANALIZACIÓN | F15: UNIDAD | G15: 1000 | H15: 85 | I15: =+H15*G15 -> 85000
A16: 7 | B16: 2.9.5-2161.557 | C16: PROD. MEDICO/FARMACEUTICOS/LAB | D16: 295 | E16: CATÉTER INTRAVENOSO Nº 20; TIPO: INTRAVENOSO/CANALIZACIÓN | F16: UNIDAD | G16: 1000 | H16: 85 | I16: =+H16*G16 -> 85000
A17: 8 | B17: 2.9.5-2161.10 | C17: PROD. MEDICO/FARMACEUTICOS/LAB | D17: 295 | E17: CATÉTER INTRAVENOSO Nº 24; TIPO: INTRAVENOSO/CANALIZACIÓN | F17: UNIDAD | G17: 1400 | H17: 85 | I17: =+H17*G17 -> 119000
A18: 9 | B18: 2.9.5-2161.412 | C18: PROD. MEDICO/FARMACEUTICOS/LAB | D18: 295 | E18: CATETERES/SONDAS; NUMERO: 26 G, TIPO: CANALIZACION | F18: UNIDAD | G18: 300 | H18: 85 | I18: =+H18*G18 -> 25500
A19: 10 | B19: 2.9.5-2204.57 | C19: PROD. MEDICO/FARMACEUTICOS/LAB | D19: 295 | E19: GUÍA DE SUERO; USO: ADMINISTRACIÓN FRACC. SANGRE; TIPO: MACROGOTERO Y FILTRO TIPO V-104 | F19: UNIDAD | G19: 100 | H19: 2004 | I19: =+H19*G19 -> 200400
A20: 11 | B20: 2.9.5-2204.30 | C20: PROD. MEDICO/FARMACEUTICOS/LAB | D20: 295 | E20: GUÍAS DE SUERO; USO: PARA TRANFUSIÓN DE PLASMA Y SANGRE; AGUJA: SIN; MODELO: V20; TIPO: CONTÍNUO; CON CONEXIÓN ROLLER LUER SLIP | F20: UNIDAD | G20: 600 | H20: 68.5 | I20: =+H20*G20 -> 41100
A21: 12 | B21: 2.9.5-2204.55 | C21: PROD. MEDICO/FARMACEUTICOS/LAB | D21: 295 | E21: GUIAS DE SUERO; USO: ADMINISTRACION DE SOLUCIONES, AGUJA: SIN, MODELO: P/EQUIPO, TIPO: PARA BOMBA INFUSORA | F21: UNIDAD | G21: 500 | H21: 255 | I21: =+H21*G21 -> 127500
... A30: 21 | B30: 2.9.5-2226.33 | C30: PROD. MEDICO/FARMACEUTICOS/LAB | D30: 295 | E30: CONECTORES P/MEDICINA; USO: SIST. INYECCION INTERMITENTE, CONECTOR: ESTANDAR | F30: UNIDAD | G30: 600 | H30: 22 | I30: =+H30*G30 -> 13200
B34: Especificidades Item N° : 11
B36: Descripción técnica: EQUIPO PARA TRANFUSION DE PLASMA Y SANGRE SIN AGUJA TIPO BIOM B-18
B38: Plazos de entrega: | C38: 10(DIEZ) DIAS HABILES
B40: Lugar de entrega: | C40: Servio de Farmacia - MATERNIDAD PROVINCIAL 25 DE MAYO- HERNANDO. DE PEDRAZA 1650
B42: Calidad Minima esperada
B44: Mantenimiento | D44: 30( TREINTA) DIAS HABILES
B46: Garantia
B50: Especificidades Item N° : 12
B52: Descripción técnica:
C53: GUIA PARA BOMBA SILICONADA TIPO PLASTIMED 1000
B56: Plazos de entrega: | C56: 10(DIEZ) DIAS HABILES
B58: Lugar de entrega: | C58: Servio de Farmacia - MATERNIDAD PROVINCIAL 25 DE MAYO- HERNANDO. DE PEDRAZA 1650
B60: Calidad Minima esperada
B62: Mantenimiento | E62: 30(TREINTA) DIAS HABILES
B64: Garantia
B72: Especificidades Item N° : 13
B74: Descripción técnica:
C75: LLAVE DE TRES VIAS- TIPO MCM, BRAUN
B78: Plazos de entrega: | C78: 10(DIEZ) DIAS HABILES
B80: Lugar de entrega: | C80: Servio de Farmacia - MATERNIDAD PROVINCIAL 25 DE MAYO- HERNANDO. DE PEDRAZA 1650
B82: Calidad Minima esperada
...

Sheet  NotaPedido
A1: NOTA DE PEDIDO | K1: N° /2022
A3: JURISDICCIÓN: | D3: 40- Ministerio de Salud
A4: SAF: | D4: 28- Maternidad Provincial 25 de Mayo
A5: UNIDAD EJECUTORA: | D5: 169- Direccion Asistencial
A6: DEPENDENCIA SOLICITANTE: | D6: Servicio de Farmacia
A7: PERIODO UTILIZACIÓN: | D7: SEMESTRAL
A8: OBJETO: | D8: Adquisición de Productos Medicos para DESCARTABLE COMUN
A10: Ítem | B10: Codigo Item | C10: DESCRIPCIÓN | H10: Adjunta Detalle Técnico | I10: Unidad Medida | J10: Precio Unitario Estimado | K10: Cantidad Solicitada
A12: ='Necesidades Trimestrales'!A10 -> 1 | B12: =+'Necesidades Trimestrales'!B10 -> 2.9.5-441.319 | C12: =+'Necesidades Trimestrales'!E10 -> AGUJAS QUIRURGICAS; TIPO: BUTTERFLY, ESPECIFICACION: 25G, PRESENTACION: UNIDAD | H12: NO | I12: =+'Necesidades Trimestrales'!F10 -> UNIDAD | J12: =+'Necesidades Trimestrales'!H10 -> 12 | K12: =+'Necesidades Trimestrales'!G10 -> 50
A13: ='Necesidades Trimestrales'!A11 -> 2 | B13: =+'Necesidades Trimestrales'!B11 -> 2.9.5-441.469 | C13: =+'Necesidades Trimestrales'!E11 -> AGUJAS QUIRURGICAS; TIPO: BUTTERFLY, ESPECIFICACION: 27, PRESENTACION: ENVASE ESTERIL | H13: NO | I13: =+'Necesidades Trimestrales'!F11 -> UNIDAD | J13: =+'Necesidades Trimestrales'!H11 -> 12 | K13: =+'Necesidades Trimestrales'!G11 -> 50
A14: ='Necesidades Trimestrales'!A12 -> 3 | B14: =+'Necesidades Trimestrales'!B12 -> 2.9.5-427.31 | C14: =+'Necesidades Trimestrales'!E12 -> APOSITOS; TIPO: P/SUJECION DE CATETER, TAMAÑO: 10 X 12 Cm | H14: NO | I14: =+'Necesidades Trimestrales'!F12 -> UNIDAD | J14: =+'Necesidades Trimestrales'!H12 -> 67 | K14: =+'Necesidades Trimestrales'!G12 -> 180
A15: ='Necesidades Trimestrales'!A13 -> 4 | B15: =+'Necesidades Trimestrales'!B13 -> 2.9.5-427.84 | C15: =+'Necesidades Trimestrales'!E13 -> APOSITOS; TIPO: P/SUJECION DE CATETER, TAMAÑO: 6 X 7 Cm | H15: NO | I15: =+'Necesidades Trimestrales'!F13 -> UNIDAD | J15: =+'Necesidades Trimestrales'!H13 -> 37.5 | K15: =+'Necesidades Trimestrales'!G13 -> 950
A16: ='Necesidades Trimestrales'!A14 -> 5 | B16: =+'Necesidades Trimestrales'!B14 -> 2.9.5-2161.7 | C16: =+'Necesidades Trimestrales'!E14 -> CATÉTER INTRAVENOSO Nº 14; TIPO: INTRAVENOSO/CANALIZACIÓN | H16: NO | I16: =+'Necesidades Trimestrales'!F14 -> UNIDAD | J16: =+'Necesidades Trimestrales'!H14 -> 45 | K16: =+'Necesidades Trimestrales'!G14 -> 50
A17: ='Necesidades Trimestrales'!A15 -> 6 | B17: =+'Necesidades Trimestrales'!B15 -> 2.9.5-2161.2 | C17: =+'Necesidades Trimestrales'!E15 -> CATÉTER INTRAVENOSO Nº 18; TIPO: INTRAVENOSO/CANALIZACIÓN | H17: NO | I17: =+'Necesidades Trimestrales'!F15 -> UNIDAD | J17: =+'Necesidades Trimestrales'!H15 -> 85 | K17: =+'Necesidades Trimestrales'!G15 -> 1000
A18: ='Necesidades Trimestrales'!A16 -> 7 | B18: =+'Necesidades Trimestrales'!B16 -> 2.9.5-2161.557 | C18: =+'Necesidades Trimestrales'!E16 -> CATÉTER INTRAVENOSO Nº 20; TIPO: INTRAVENOSO/CANALIZACIÓN | H18: NO | I18: =+'Necesidades Trimestrales'!F16 -> UNIDAD | J18: =+'Necesidades Trimestrales'!H16 -> 85 | K18: =+'Necesidades Trimestrales'!G16 -> 1000
A19: ='Necesidades Trimestrales'!A17 -> 8 | B19: =+'Necesidades Trimestrales'!B17 -> 2.9.5-2161.10 | C19: =+'Necesidades Trimestrales'!E17 -> CATÉTER INTRAVENOSO Nº 24; TIPO: INTRAVENOSO/CANALIZACIÓN | H19: NO | I19: =+'Necesidades Trimestrales'!F17 -> UNIDAD | J19: =+'Necesidades Trimestrales'!H17 -> 85 | K19: =+'Necesidades Trimestrales'!G17 -> 1400
A20: ='Necesidades Trimestrales'!A18 -> 9 | B20: =+'Necesidades Trimestrales'!B18 -> 2.9.5-2161.412 | C20: =+'Necesidades Trimestrales'!E18 -> CATETERES/SONDAS; NUMERO: 26 G, TIPO: CANALIZACION | H20: NO | I20: =+'Necesidades Trimestrales'!F18 -> UNIDAD | J20: =+'Necesidades Trimestrales'!H18 -> 85 | K20: =+'Necesidades Trimestrales'!G18 -> 300
A21: ='Necesidades Trimestrales'!A19 -> 10 | B21: =+'Necesidades Trimestrales'!B19 -> 2.9.5-2204.57 | C21: =+'Necesidades Trimestrales'!E19 -> GUÍA DE SUERO; USO: ADMINISTRACIÓN FRACC. SANGRE; TIPO: MACROGOTERO Y FILTRO TIPO V-104 | H21: NO | I21: =+'Necesidades Trimestrales'!F19 -> UNIDAD | J21: =+'Necesidades Trimestrales'!H19 -> 2004 | K21: =+'Necesidades Trimestrales'!G19 -> 100
A22: ='Necesidades Trimestrales'!A20 -> 11 | B22: =+'Necesidades Trimestrales'!B20 -> 2.9.5-2204.30 | C22: =+'Necesidades Trimestrales'!E20 -> GUÍAS DE SUERO; USO: PARA TRANFUSIÓN DE PLASMA Y SANGRE; AGUJA: SIN; MODELO: V20; TIPO: CONTÍNUO; CON CONEXIÓN ROLLER LUER SLIP | H22: SI | I22: =+'Necesidades Trimestrales'!F20 -> UNIDAD | J22: =+'Necesidades Trimestrales'!H20 -> 68.5 | K22: =+'Necesidades Trimestrales'!G20 -> 600
A23: ='Necesidades Trimestrales'!A21 -> 12 | B23: =+'Necesidades Trimestrales'!B21 -> 2.9.5-2204.55 | C23: =+'Necesidades Trimestrales'!E21 -> GUIAS DE SUERO; USO: ADMINISTRACION DE SOLUCIONES, AGUJA: SIN, MODELO: P/EQUIPO, TIPO: PARA BOMBA INFUSORA | H23: SI | I23: =+'Necesidades Trimestrales'!F21 -> UNIDAD | J23: =+'Necesidades Trimestrales'!H21 -> 255 | K23: =+'Necesidades Trimestrales'!G21 -> 500
... A32: ='Necesidades Trimestrales'!A30 -> 21 | B32: =+'Necesidades Trimestrales'!B30 -> 2.9.5-2226.33 | C32: =+'Necesidades Trimestrales'!E30 -> CONECTORES P/MEDICINA; USO: SIST. INYECCION INTERMITENTE, CONECTOR: ESTANDAR | H32: SI | I32: =+'Necesidades Trimestrales'!F30 -> UNIDAD | J32: =+'Necesidades Trimestrales'!H30 -> 22 | K32: =+'Necesidades Trimestrales'!G30 -> 600
A33: Costo total estimado: UN MILLON SETENTA Y TRES MIL OCHOCIENTOS TREINTA Y CINCO CON 00/100 | J33: =SUMPRODUCT(J12:J32*K12:K32) -> 1073835

Sheet Autor Gastar
A1: EJERCICIO: | D1: 2022 | P1: AUTORIZACION PARA GASTAR
A4: JURISDICCIÓN: | G4: =' NotaPedido'!D3 -> 40- Ministerio de Salud
A5: SAF: | G5: =' NotaPedido'!D4 -> 28- Maternidad Provincial 25 de Mayo
A6: UNIDAD EJECUTORA: | G6: =' NotaPedido'!D5 -> 169- Direccion Asistencial
A7: DEPENDENCIA SOLICITANTE: | G7: =' NotaPedido'!D6 -> Servicio de Farmacia
A8: AUTORIZACIÓN:
A9: Señor Jefe de Servicio Administrativo Financiero:
A10: "Autorizo la realización de los trámites correspondientes, a fin de proveer a este Organismo los bienes y/o servicios que se detallan en Nota de Pedido N° /2022 , afectando la erogación resultante a los créditos presupuestarios aprobados a favor de esta Unidad Ejecutora, conforme al siguiente detalle:"
A12: IMPUTACIÓN PRESUPUESTARIA
A13: CÓDIGO | O13: DENOMINACIÓN DE LA PARTIDA PRESUPUESTARIA | Q13: IMPORTE
A14: PR | B14: SB | C14: PY | D14: AC | E14: OB | F14: UG | G14: FIN | H14: FUN | I14: I | J14: P | K14: P | L14: SubP | M14: M | N14: FF
A15: 42 | D15: 2 | F15: 4901 | G15: 3 | H15: 1 | I15: 2 | J15: 9 | K15: 5 | M15: 1 | N15: 1.1 | O15: Utiles menores medico, Quirurgico y de Laboratorio | Q15: 1073835
A18: TOTAL DE PESOS: UN MILLON SETENTA Y TRES MIL OCHOCIENTOS TREINTA Y CINCO CON 00/100 | Q18: =SUM(Q15:Q16) -> 1073835
A20: JUSTIFICACIÓN:
A21: Para la adquisición de Adquisición de Productos Medicos para DESCARTABLE COMUN, para ser destinados Servicio de Farmacia, de la Maternidad Provincial 25 de Mayo.-
