Workbook

Sheet Necesidades Trimestrales
B2: Pedido de Necesidades Trimestrales
A4: JURISDICCION: | C4: 40 - Ministerio de Salud
A5: SAF N°: | C5: 23 - Hospital Interzonal San Juan Bautista
A6: EJERCICIO: | C6: 2021
A7: TRIMESTRE: | C7: 3
A9: ID | B9: CODIGO ITEM | C9: RUBRO DE COMPRA | D9: I.P.P. | E9: DESCRIPCION | F9: UNIDAD DE MEDIDA | G9: CANTIDAD | H9: PRECIO UNITARIO ESTIMADO | I9: IMPORTE TOTAL ESTIMADO
A10: 1 | C10: Ut. Menores med. Quirúrg. Y de Lab. | D10: 2.9.5 | E10: Aguja ESPINAL 21 G 3 1/2 PUNTA LAPIZ | F10: UNIDAD | G10: 400 | H10: 520 | I10: =G10*H10 -> 208000 | J10: =I10+I11+I12+I13+I14+I15+I16+I17+I18+I19+I20+I21+I22+I23+I24+I25+I26+I27+I28+I29+#REF!+I30+I31+#REF!+#REF!+#REF!+I32+I33+I35+I36+I37+I38+#REF!+I39+I40+#REF!+I44+I45+I46+I47+I48+I49+I50+#REF!+I51+I52+I53+I54+I55+I58+I59 -> #REF! | K10: 295
A11: 2 | C11: Ut. Menores med. Quirúrg. Y de Lab. | D11: 2.9.5 | E11: AGUJA ESPINAL 25G 31/2 PUNTA LAPIZ | F11: UNIDAD | G11: 400 | H11: 520 | I11: =G11*H11 -> 208000 | J11: =#REF! -> #REF! | K11: 296
A12: 3 | C12: Ut. Menores med. Quirúrg. Y de Lab. | D12: 2.9.5 | E12: Aguja ESPINAL 26 G 31/2 | F12: UNIDAD | G12: 400 | H12: 520 | I12: =G12*H12 -> 208000 | J12: =#REF!+I41+I42+I43 -> #REF! | K12: 259
A13: 4 | C13: Ut. Menores med. Quirúrg. Y de Lab. | D13: 2.9.5 | E13: Aguja ESPINAL 27 G 3 1/2 | F13: UNIDAD | G13: 400 | H13: 520 | I13: =G13*H13 -> 208000 | J13: =I34+I57 -> 612800 | K13: 251
A14: 5 | C14: Ut. Menores med. Quirúrg. Y de Lab. | D14: 2.9.5 | E14: AGUJA ESPINAL 27G 3 1/2 PUNTA LAPIZ | F14: UNIDAD | G14: 400 | H14: 520 | I14: =G14*H14 -> 208000 | J14: =I56 -> 45000 | K14: 221
A15: 6 | C15: Ut. Menores med. Quirúrg. Y de Lab. | D15: 2.9.5 | E15: Aguja espinal para obesos 25 G punta lapiz | F15: UNIDAD | G15: 50 | H15: 620 | I15: =G15*H15 -> 31000 | J15: =SUM(J10:J14) -> #REF!
A16: 7 | C16: Ut. Menores med. Quirúrg. Y de Lab. | D16: 2.9.5 | E16: Aguja espinal para obesos 27 G | F16: UNIDAD | G16: 50 | H16: 620 | I16: =G16*H16 -> 31000
A17: 8 | C17: Ut. Menores med. Quirúrg. Y de Lab. | D17: 2.9.5 | E17: AGUJA PUNTA CURVA HUBER Nº 20 X 25 MM | F17: UNIDAD | G17: 60 | H17: 182 | I17: =G17*H17 -> 10920
A18: 9 | C18: Ut. Menores med. Quirúrg. Y de Lab. | D18: 2.9.5 | E18: AGUJA PUNTA CURVA HUBER Nº 21 X 25 MM | F18: UNIDAD | G18: 60 | H18: 182 | I18: =G18*H18 -> 10920
A19: 10 | C19: Ut. Menores med. Quirúrg. Y de Lab. | D19: 2.9.5 | E19: AGUJA PUNTA CURVA HUBER Nº 22 X 25 MM | F19: UNIDAD | G19: 60 | H19: 182 | I19: =G19*H19 -> 10920
A20: 11 | C20: Ut. Menores med. Quirúrg. Y de Lab. | D20: 2.9.5 | E20: AGUJA TROCAR X 1 - 30/12 | F20: UNIDAD | G20: 5000 | H20: 1.32 | I20: =G20*H20 -> 6600
A21: 12 | C21: Ut. Menores Med. Quirurg. Y de Laboratorio | D21: 2.9.5 | E21: BUTERFLY Nº 19 | F21: UNIDAD | G21: 1200 | H21: 14.5 | I21: =G21*H21 -> 17400
A22: 13 | C22: Ut. Menores Med. Quirurg. Y de Laboratorio | D22: 2.9.5 | E22: BUTERFLY Nº 21 | F22: UNIDAD | G22: 1200 | H22: 14.5 | I22: =G22*H22 -> 17400
A23: 14 | C23: Ut. Menores Med. Quirurg. Y de Lab. | D23: 2.9.5 | E23: Camisolin P/Cirugia de tela verde brin con puño caña larga | F23: UNIDAD | G23: 80 | H23: 1990 | I23: =G23*H23 -> 159200
A24: 15 | C24: Ut. Menores med. Quirúrg. Y de Lab. | D24: 2.9.5 | E24: CATETER DOBLE J 4.8 FRENCH X 46 CM TIPO COOK | F24: UNIDAD | G24: 6 | H24: 6870 | I24: =G24*H24 -> 41220
A25: 16 | C25: Ut. Menores med. Quirúrg. Y de Lab. | D25: 2.9.5 | E25: CATETER DOBLE J 7 FRENCH X 46 CM TIPO COOK | F25: UNIDAD | G25: 6 | H25: 7800 | I25: =G25*H25 -> 46800
A26: 17 | C26: Ut. Menores Med. Quirurg. Y de Lab. | D26: 2.9.5 | E26: CEPILLO P/LAVAR TUBOS GRANDES X 1 | F26: UNIDAD | G26: 3 | H26: 290 | I26: =G26*H26 -> 870
A27: 18 | C27: Ut. Menores Med. Quirurg. Y de Lab. | D27: 2.9.5 | E27: CEPILLO P/LAVAR TUBOS MEDIANOS X 1 | F27: UNIDAD | G27: 3 | H27: 310 | I27: =G27*H27 -> 930
... A59: 50 | C59: Ut. Men. Med. Quirurg. Y de Laborator. | D59: 2.9.5 | E59: TUBO DE LATEX 5 X 8 MM X METRO | F59: UNIDAD | G59: 50 | H59: 99 | I59: =G59*H59 -> 4950
H60: =SUM(I10:I59) -> 6299096.6
B61: Especificidades Item N° 1 al 46, 49 y 50:
B63: Descripción técnica
C64: La totalidad de los insumos debera tener un vencimiento minimo de un año. Las firmas comerciales deberan poseer Habilitación Sanitaria emitida por las autoridades sanitarias provinciales competentes en caso de empresas locales y para empresa no locales Habilitación de transito interjurisdiccional por autoridad sanitaria nacional (ANMAT). Empresas importadoras de productos médicos, disposición del registro de sus productos. Establecimientos elaboradores de productos médicos certificado de Buenas Prácticas de Fabricación (BPF). Como así también toda otra documentación obligatoria en virtud del rubro que se pretende contratar con el Estado Provincial (Rubricado por personal). idóneo).
B65: Plazos y lugares de entrega
C66: 20 dias corridos - Servicio de Farmacia del HISJB
B68: Calidad Minima esperada
B70: Mantenimiento
C71: 45 dias habiles
B72: Garantia
B77: Especificidades Item N° 47:
B79: Descripción técnica
C80: La totalidad de los insumos debera tener un vencimiento minimo de un año. Las firmas comerciales deberan poseer Habilitación Sanitaria emitida por las autoridades sanitarias provinciales competentes en caso de empresas locales y para empresa no locales Habilitación de transito interjurisdiccional por autoridad sanitaria nacional (ANMAT). Empresas importadoras de productos médicos, disposición del registro de sus productos. Establecimientos elaboradores de productos médicos certificado de Buenas Prácticas de Fabricación (BPF). Como así también toda otra documentación obligatoria en virtud del rubro que se pretende contratar con el Estado Provincial (Rubricado por personal). idóneo). Entiendase el ancho del rollo de tela de 1,50 mts - se solicita doble ancho.
B81: Plazos y lugares de entrega
C82: 20 dias corridos - Servicio de Farmacia del HISJB
...

Sheet NotaPedido
A1: NOTA DE PEDIDO | J1: N° | K1: 054 - 2021
A3: JURISDICCIÓN: | D3: ='Necesidades Trimestrales'!C4 -> 40 - Ministerio de Salud
A4: SAF: | D4: ='Necesidades Trimestrales'!C5 -> 23 - Hospital Interzonal San Juan Bautista
A5: UNIDAD EJECUTORA: | D5: 168 - Direccion Asistencial
A6: DEPENDENCIA SOLICITANTE: | D6: Servicio de Farmacia
A7: PERIODO UTILIZACIÓN: | D7: ='Necesidades Trimestrales'!C7 & "° Trimestre - Año " & 'Necesidades Trimestrales'!C6 -> 3° Trimestre - Año 2021
A8: OBJETO: | D8: Adquisición de Descartables
A10: Ítem | B10: Codigo Item | C10: DESCRIPCIÓN | H10: Adjunta Detalle Técnico | I10: Unidad Medida | J10: Precio Unitario Estimado | K10: Cantidad Solicitada
A12: 1 | B12: ='Necesidades Trimestrales'!B10 -> 0 | C12: ='Necesidades Trimestrales'!E10 -> Aguja ESPINAL 21 G 3 1/2 PUNTA LAPIZ | H12: NO | I12: ='Necesidades Trimestrales'!F10 -> UNIDAD | J12: ='Necesidades Trimestrales'!H10 -> 520 | K12: ='Necesidades Trimestrales'!G10 -> 400 | L12: =J12*K12 -> 208000
A13: 2 | B13: ='Necesidades Trimestrales'!B11 -> 0 | C13: ='Necesidades Trimestrales'!E11 -> AGUJA ESPINAL 25G 31/2 PUNTA LAPIZ | H13: NO | I13: ='Necesidades Trimestrales'!F11 -> UNIDAD | J13: ='Necesidades Trimestrales'!H11 -> 520 | K13: ='Necesidades Trimestrales'!G11 -> 400 | L13: =J13*K13 -> 208000
A14: 3 | B14: ='Necesidades Trimestrales'!B12 -> 0 | C14: ='Necesidades Trimestrales'!E12 -> Aguja ESPINAL 26 G 31/2 | H14: NO | I14: ='Necesidades Trimestrales'!F12 -> UNIDAD | J14: ='Necesidades Trimestrales'!H12 -> 520 | K14: ='Necesidades Trimestrales'!G12 -> 400 | L14: =J14*K14 -> 208000
A15: 4 | B15: ='Necesidades Trimestrales'!B13 -> 0 | C15: ='Necesidades Trimestrales'!E13 -> Aguja ESPINAL 27 G 3 1/2 | H15: NO | I15: ='Necesidades Trimestrales'!F13 -> UNIDAD | J15: ='Necesidades Trimestrales'!H13 -> 520 | K15: ='Necesidades Trimestrales'!G13 -> 400 | L15: =J15*K15 -> 208000
A16: 5 | B16: ='Necesidades Trimestrales'!B14 -> 0 | C16: ='Necesidades Trimestrales'!E14 -> AGUJA ESPINAL 27G 3 1/2 PUNTA LAPIZ | H16: NO | I16: ='Necesidades Trimestrales'!F14 -> UNIDAD | J16: ='Necesidades Trimestrales'!H14 -> 520 | K16: ='Necesidades Trimestrales'!G14 -> 400 | L16: =J16*K16 -> 208000
A17: 6 | B17: ='Necesidades Trimestrales'!B15 -> 0 | C17: ='Necesidades Trimestrales'!E15 -> Aguja espinal para obesos 25 G punta lapiz | H17: NO | I17: ='Necesidades Trimestrales'!F15 -> UNIDAD | J17: ='Necesidades Trimestrales'!H15 -> 620 | K17: ='Necesidades Trimestrales'!G15 -> 50 | L17: =J17*K17 -> 31000
A18: 7 | B18: ='Necesidades Trimestrales'!B16 -> 0 | C18: ='Necesidades Trimestrales'!E16 -> Aguja espinal para obesos 27 G | H18: NO | I18: ='Necesidades Trimestrales'!F16 -> UNIDAD | J18: ='Necesidades Trimestrales'!H16 -> 620 | K18: ='Necesidades Trimestrales'!G16 -> 50 | L18: =J18*K18 -> 31000
A19: 8 | B19: ='Necesidades Trimestrales'!B17 -> 0 | C19: ='Necesidades Trimestrales'!E17 -> AGUJA PUNTA CURVA HUBER Nº 20 X 25 MM | H19: NO | I19: ='Necesidades Trimestrales'!F17 -> UNIDAD | J19: ='Necesidades Trimestrales'!H17 -> 182 | K19: ='Necesidades Trimestrales'!G17 -> 60 | L19: =J19*K19 -> 10920
A20: 9 | B20: ='Necesidades Trimestrales'!B18 -> 0 | C20: ='Necesidades Trimestrales'!E18 -> AGUJA PUNTA CURVA HUBER Nº 21 X 25 MM | H20: NO | I20: ='Necesidades Trimestrales'!F18 -> UNIDAD | J20: ='Necesidades Trimestrales'!H18 -> 182 | K20: ='Necesidades Trimestrales'!G18 -> 60 | L20: =J20*K20 -> 10920
A21: 10 | B21: ='Necesidades Trimestrales'!B19 -> 0 | C21: ='Necesidades Trimestrales'!E19 -> AGUJA PUNTA CURVA HUBER Nº 22 X 25 MM | H21: NO | I21: ='Necesidades Trimestrales'!F19 -> UNIDAD | J21: ='Necesidades Trimestrales'!H19 -> 182 | K21: ='Necesidades Trimestrales'!G19 -> 60 | L21: =J21*K21 -> 10920
A22: 11 | B22: ='Necesidades Trimestrales'!B20 -> 0 | C22: ='Necesidades Trimestrales'!E20 -> AGUJA TROCAR X 1 - 30/12 | H22: NO | I22: ='Necesidades Trimestrales'!F20 -> UNIDAD | J22: ='Necesidades Trimestrales'!H20 -> 1.32 | K22: ='Necesidades Trimestrales'!G20 -> 5000 | L22: =J22*K22 -> 6600
A23: 12 | B23: ='Necesidades Trimestrales'!B21 -> 0 | C23: ='Necesidades Trimestrales'!E21 -> BUTERFLY Nº 19 | H23: NO | I23: ='Necesidades Trimestrales'!F21 -> UNIDAD | J23: ='Necesidades Trimestrales'!H21 -> 14.5 | K23: ='Necesidades Trimestrales'!G21 -> 1200 | L23: =J23*K23 -> 17400
... A61: 50 | B61: ='Necesidades Trimestrales'!B59 -> 0 | C61: ='Necesidades Trimestrales'!E59 -> TUBO DE LATEX 5 X 8 MM X METRO | H61: NO | I61: ='Necesidades Trimestrales'!F59 -> UNIDAD | J61: ='Necesidades Trimestrales'!H59 -> 99 | K61: ='Necesidades Trimestrales'!G59 -> 50 | L61: =J61*K61 -> 4950
A62: Costo total estimado: SEIS MILLONES DOSCIENTOS NOVENTA Y NUEVE MIL NOVENTA Y SEIS CON 60/100.- | J62: =SUMPRODUCT(J12:J61,K12:K61) -> 6299096.6 | L62: =SUM(L12:L61) -> 6299096.6

Sheet Autor Gastar
A1: EJERCICIO: | D1: ='Necesidades Trimestrales'!C6 -> 2021 | P1: AUTORIZACION PARA GASTAR
A4: JURISDICCIÓN: | G4: =NotaPedido!D3 -> 40 - Ministerio de Salud
A5: SAF: | G5: =NotaPedido!D4 -> 23 - Hospital Interzonal San Juan Bautista
A6: UNIDAD EJECUTORA: | G6: =NotaPedido!D5 -> 168 - Direccion Asistencial
A7: DEPENDENCIA SOLICITANTE: | G7: Servicio de Farmacia
A8: AUTORIZACIÓN:
A9: Señor Jefe de Servicio Administrativo Financiero:
A10: ="Autorizo la realización de los trámites correspondientes, a fin de proveer a este Organismo los bienes y/o servicios que se detallan en Nota de Pedido N° " & NotaPedido!K1&", afectando la erogación resultante a los créditos presupuestarios aprobados a favor de esta Unidad Ejecutora, conforme al siguiente detalle:" -> Autorizo la realización de los trámites correspondientes, a fin de proveer a este Organismo los bienes y/o servicios que se detallan en Nota de Pedido N° 054 - 2021, afectando la erogación resultante a los créditos presupuestarios aprobados a favor de esta Unidad Ejecutora, conforme al siguiente detalle:
A12: IMPUTACIÓN PRESUPUESTARIA
A13: CÓDIGO | O13: DENOMINACIÓN DE LA PARTIDA PRESUPUESTARIA | Q13: IMPORTE
A14: PR | B14: SB | C14: PY | D14: AC | E14: OB | F14: UG | G14: FIN | H14: FUN | I14: I | J14: P | K14: P | L14: SubP | M14: M | N14: FF
A15: 33 | D15: 2 | F15: 4901 | G15: 3 | H15: 3.1 | I15: 2 | J15: 2 | K15: 1 | M15: 1 | N15: 1.1 | O15: Hilados y Telas | Q15: ='Necesidades Trimestrales'!J14 -> 45000
A16: 33 | D16: 2 | F16: 4901 | G16: 3 | H16: 3.1 | I16: 2 | J16: 3 | K16: 4 | M16: 1 | N16: 1.1 | O16: Productos de Papel y Cartón | Q16: 188280
A17: 33 | D17: 2 | F17: 4901 | G17: 3 | H17: 3.1 | I17: 2 | J17: 5 | K17: 1 | M17: 1 | N17: 1.1 | O17: Compuestos Quimicos | Q17: ='Necesidades Trimestrales'!J13 -> 612800
A18: 33 | D18: 2 | F18: 4901 | G18: 3 | H18: 3.1 | I18: 2 | J18: 5 | K18: 9 | M18: 1 | N18: 1.1 | O18: Otros NEP | Q18: 355224
A19: 33 | D19: 2 | F19: 4901 | G19: 3 | H19: 3.1 | I19: 2 | J19: 9 | K19: 5 | M19: 1 | N19: 1.1 | O19: Utiles Menores Med. Quir. y de Lab. | Q19: 5097792.6
A24: TOTAL DE PESOS: SEIS MILLONES DOSCIENTOS NOVENTA Y NUEVE MIL NOVENTA Y SEIS CON 60/100.- | Q24: =SUM(Q15:Q23) -> 6299096.6
A26: JUSTIFICACIÓN:
A27: ="Para la "& NotaPedido!D8 &" para ser destinados al " & NotaPedido!D6 &" del HISJB del Ministerio de Salud." -> Para la Adquisición de Descartables para ser destinados al Servicio de Farmacia del HISJB del Ministerio de Salud.
