Workbook

Sheet ALIMENTOS PERECEDEROS
B2: Pedido de carne - 2 Meses
A4: JURISDICCION: | C4: 40-Ministerio de Salud
A5: SAF N°: | C5: 28- Maternidad Provincial 25 de Mayo
A6: EJERCICIO: | C6: 2021
A7: TRIMESTRE: | C7: 4°
A9: ID | B9: CODIGO ITEM | C9: RUBRO | D9: I.P.P. | E9: DESCRIPCION | F9: UNIDAD DE MEDIDA | G9: CANTIDAD | H9: PRECIO UNITARIO ESTIMADO | I9: IMPORTE TOTAL ESTIMADO
A10: 1 | B10: 2.1.1-541.29 | C10: ALIMENTOS | D10: =LEFT(B10,5) -> 2.1.1 | E10: CARNES; CORTE: PECETO, ESPECIE: VACUNA, TIPO: VACUNA | F10: KG | G10: 70 | H10: 1476 | I10: =H10*G10 -> 103320
A11: 2 | B11: 2.1.1-541.20 | C11: ALIMENTOS | D11: =LEFT(B11,5) -> 2.1.1 | E11: CARNES; CORTE: TAPA DE NALGA, ESPECIE: VACUNA, TIPO: VACUNA | F11: KG | G11: 70 | H11: 1368 | I11: =H11*G11 -> 95760
A12: 3 | B12: 2.1.1-541.33 | C12: ALIMENTOS | D12: =LEFT(B12,5) -> 2.1.1 | E12: CARNES; ESPECIE: VACUNA, CORTE: BOLA DE LOMO, TIPO: VACUNA | F12: KG | G12: 75 | H12: 1092 | I12: =H12*G12 -> 81900
A13: 4 | B13: 2.1.1-541.49 | C13: ALIMENTOS | D13: =LEFT(B13,5) -> 2.1.1 | E13: CARNES; ESPECIE: VACUNA, CORTE: NALGA, TIPO: VACUNA | F13: KG | G13: 250 | H13: 1236 | I13: =H13*G13 -> 309000
C17: Especificidades Item N° 01
E18: PECETO
C19: Descripción técnica
C22: Entrega y Forma de Pago: | D22: Las entregas se realizarán a requerimiento de acuerdo a las Solicitudes de Provisión que se realicen. Se estima emitir una cantidad aproximada de 3 (Tres) Solicitudes de Provisión de (1/3 aprox.) de la cantidad solicitada, en un plazo de 3 (Tres) meses: 1° Solic.de Provisión: aprox.a los 3 dias hábiles de la firma del instrumento contractual. 2° Solic.de Provisión: al mes de la firma del instrumento contractual. Y 3° Solic.de Provisión: a los dos meses de la firma del instrumento contractual. Plazo de cumplimiento de cada Solicitud de Provisión: desde los 2 días hábiles de notificada la misma, según necesidades del Organismo solicitante. Forma de Pago: Se solicita Pagos parciales por cada Solicitud de Provisión emitida, una vez finalizada la entrega de las cantidades contenidas en la misma.
C24: Lugares de entrega: | D24: SECTOR DE NUTRICION-MATERNIDAD PROVINCIAL 25 DE MAYO , HERNANDO DE PEDRAZA N° 1650.
C25: Horario: | E25: 8.00 a 9.30 Hs (AM)
C27: Calidad Minima esperada | E27: según condiciones establecidas en nota
C29: Mantenimiento
D30: 30 dias
C31: Garantia
C34: Especificidades Item N° 02
E35: TAPA DE NALGA
C36: Descripción técnica
C39: Entrega y Forma de Pago: | D39: Las entregas se realizarán a requerimiento de acuerdo, a las Solicitudes de Provisión que se realicen. Se estima emitir una cantidad aproximada de 3 (Tres) Solicitudes de Provisión de (1/3 aprox.) de la cantidad solicitada, en un plazo de 3 (Tres) meses: 1° Solic.de Provisión: aprox.a los 3 dias hábiles de la firma del instrumento contractual. 2° Solic.de Provisión: al mes de la firma del instrumento contractual. Y 3° Solic.de Provisión: a los dos meses de la firma del instrumento contractual. Plazo de cumplimiento de cada Solicitud de Provisión: desde los 2 días hábiles de notificada la misma, según necesidades del Organismo solicitante. Forma de Pago: Se solicita Pagos parciales por cada Solicitud de Provisión emitida, una vez finalizada la entrega de las cantidades contenidas en la misma.
C41: Lugares de entrega: | D41: SECTOR DE NUTRICION-MATERNIDAD PROVINCIAL 25 DE MAYO , HERNANDO DE PEDRAZA N° 1650.
C42: Horario: | E42: 8.00 a 9.30 Hs (AM)
C44: Calidad Minima esperada | E44: según condiciones establecidas en nota
C46: Mantenimiento
D47: 30 dias
C48: Garantia
C52: Especificidades Item N° 03
E53: BOLA DE LOMO
C54: Descripción técnica
D55: Bola de lomo entera. Debe venir en vehiculo refrigerado aprobado por Senasa. El proveedor debe presentar la documentacion del vehiculo habilitada.
C57: Entrega y Forma de Pago: | D57: Las entregas se realizarán a requerimiento de acuerdo, a las Solicitudes de Provisión que se realicen. Se estima emitir una cantidad aproximada de 3 (Tres) Solicitudes de Provisión de (1/3 aprox.) de la cantidad solicitada, en un plazo de 3 (Tres) meses: 1° Solic.de Provisión: aprox.a los 3 dias hábiles de la firma del instrumento contractual. 2° Solic.de Provisión: al mes de la firma del instrumento contractual. Y 3° Solic.de Provisión: a los dos meses de la firma del instrumento contractual. Plazo de cumplimiento de cada Solicitud de Provisión: desde los 2 días hábiles de notificada la misma, según necesidades del Organismo solicitante. Forma de Pago: Se solicita Pagos parciales por cada Solicitud de Provisión emitida, una vez finalizada la entrega de las cantidades contenidas en la misma.
C59: Lugares de entrega: | D59: SECTOR DE NUTRICION-MATERNIDAD PROVINCIAL 25 DE MAYO , HERNANDO DE PEDRAZA N° 1650.
C60: Horario: | E60: 8.00 a 9.30 Hs (AM)
C62: Calidad Minima esperada | E62: según condiciones establecidas en nota
C64: Mantenimiento
D65: 30 dias
...

Sheet  NotaPedido
A1: NOTA DE PEDIDO | J1: N° | K1: 159/2021
A3: JURISDICCIÓN: | D3: ='ALIMENTOS PERECEDEROS'!C4 -> 40-Ministerio de Salud
A4: SAF: | D4: ='ALIMENTOS PERECEDEROS'!C5 -> 28- Maternidad Provincial 25 de Mayo
A5: UNIDAD EJECUTORA: | D5: 169-Direccion Asistencial
A6: DEPENDENCIA SOLICITANTE: | D6: Servicio de Nutricion
A7: PERIODO UTILIZACIÓN: | D7: ='ALIMENTOS PERECEDEROS'!C7 & "° Trimestre - Año " & 'ALIMENTOS PERECEDEROS'!C6 -> 4°° Trimestre - Año 2021
A8: OBJETO: | D8: Adquisicion de alimentos perecedero para el servicio de nutricion
A10: Ítem | B10: Codigo Item | C10: DESCRIPCIÓN | H10: Adjunta Detalle Técnico | I10: Unidad Medida | J10: Precio Unitario Estimado | K10: Cantidad Solicitada
A12: ='ALIMENTOS PERECEDEROS'!A10 -> 1 | B12: ='ALIMENTOS PERECEDEROS'!B10 -> 2.1.1-541.29 | C12: ='ALIMENTOS PERECEDEROS'!E10 -> CARNES; CORTE: PECETO, ESPECIE: VACUNA, TIPO: VACUNA | H12: NO | I12: ='ALIMENTOS PERECEDEROS'!F10 -> KG | J12: ='ALIMENTOS PERECEDEROS'!H10 -> 1476 | K12: ='ALIMENTOS PERECEDEROS'!G10 -> 70
A13: ='ALIMENTOS PERECEDEROS'!A11 -> 2 | B13: ='ALIMENTOS PERECEDEROS'!B11 -> 2.1.1-541.20 | C13: ='ALIMENTOS PERECEDEROS'!E11 -> CARNES; CORTE: TAPA DE NALGA, ESPECIE: VACUNA, TIPO: VACUNA | H13: NO | I13: ='ALIMENTOS PERECEDEROS'!F11 -> KG | J13: ='ALIMENTOS PERECEDEROS'!H11 -> 1368 | K13: ='ALIMENTOS PERECEDEROS'!G11 -> 70
A14: ='ALIMENTOS PERECEDEROS'!A12 -> 3 | B14: ='ALIMENTOS PERECEDEROS'!B12 -> 2.1.1-541.33 | C14: ='ALIMENTOS PERECEDEROS'!E12 -> CARNES; ESPECIE: VACUNA, CORTE: BOLA DE LOMO, TIPO: VACUNA | H14: NO | I14: ='ALIMENTOS PERECEDEROS'!F12 -> KG | J14: ='ALIMENTOS PERECEDEROS'!H12 -> 1092 | K14: ='ALIMENTOS PERECEDEROS'!G12 -> 75
A15: ='ALIMENTOS PERECEDEROS'!A13 -> 4 | B15: ='ALIMENTOS PERECEDEROS'!B13 -> 2.1.1-541.49 | C15: ='ALIMENTOS PERECEDEROS'!E13 -> CARNES; ESPECIE: VACUNA, CORTE: NALGA, TIPO: VACUNA | H15: NO | I15: ='ALIMENTOS PERECEDEROS'!F13 -> KG | J15: ='ALIMENTOS PERECEDEROS'!H13 -> 1236 | K15: ='ALIMENTOS PERECEDEROS'!G13 -> 250
A16: Costo total estimado: QUINIENTOS OCHENTA Y NUEVE MIL NOVECIENTOS OCHENTA CON 00/100 | J16: =SUMPRODUCT(J12:J15,K12:K15) -> 589980

Sheet Autor Gastar
A1: EJERCICIO: | D1: ='ALIMENTOS PERECEDEROS'!C6 -> 2021 | P1: AUTORIZACION PARA GASTAR
A4: JURISDICCIÓN: | G4: =' NotaPedido'!D3 -> 40-Ministerio de Salud
A5: SAF: | G5: =' NotaPedido'!D4 -> 28- Maternidad Provincial 25 de Mayo
A6: UNIDAD EJECUTORA: | G6: =' NotaPedido'!D5 -> 169-Direccion Asistencial
A7: DEPENDENCIA SOLICITANTE: | G7: =' NotaPedido'!D6 -> Servicio de Nutricion
A8: AUTORIZACIÓN:
A9: Señor Jefe de Servicio Administrativo Financiero:
A10: ="Autorizo la realización de los trámites correspondientes, a fin de proveer a este Organismo los bienes y/o servicios que se detallan en Nota de Pedido N° " & ' NotaPedido'!K1&", afectando la erogación resultante a los créditos presupuestarios aprobados a favor de esta Unidad Ejecutora, conforme al siguiente detalle:" -> Autorizo la realización de los trámites correspondientes, a fin de proveer a este Organismo los bienes y/o servicios que se detallan en Nota de Pedido N° 159/2021, afectando la erogación resultante a los créditos presupuestarios aprobados a favor de esta Unidad Ejecutora, conforme al siguiente detalle:
A12: IMPUTACIÓN PRESUPUESTARIA
A13: CÓDIGO | O13: DENOMINACIÓN DE LA PARTIDA PRESUPUESTARIA | Q13: IMPORTE
A14: PR | B14: SB | C14: PY | D14: AC | E14: OB | F14: UG | G14: FIN | H14: FUN | I14: I | J14: P | K14: P | L14: SubP | M14: M | N14: FF
A15: 42 | D15: 2 | F15: 4901 | G15: 3 | H15: 1 | I15: 2 | J15: 1 | K15: 1 | N15: 1.1 | O15: Alimentos para Personas | Q15: 589980
A19: TOTAL DE PESOS: QUINIENTOS OCHENTA Y NUEVE MIL NOVECIENTOS OCHENTA CON 00/100 | Q19: =SUM(Q15:Q18) -> 589980
A21: JUSTIFICACIÓN:
A22: Para la adquisición de de alimentos perecedero para ser destinados al Servicio de Nutrición de la Maternidad Provincial 25 de Mayo del Ministerio de Salud.
