Workbook

Sheet SAF 011 - NECESIDAD TRIMESTRAL
A1: 2022
B2: Pedido de Necesidades Trimestrales
A4: JURISDICCION: | C4: 040 - MINISTERIO DE SALUD
A5: SAF N°: | C5: 011 - DIRECCION PROVINCIAL DE ADMINISTRACION - MINISTERIO DE SALUD
A6: EJERCICIO: | C6: 2022
A7: TRIMESTRE: | C7: TERCERO
A9: ID | B9: CODIGO ITEM | C9: RUBRO DE COMPRA | D9: I.P.P. | E9: DESCRIPCION | F9: UNIDAD DE MEDIDA | G9: SECRETARIA DE ADMINISTRACION | H9: TOTAL S.A. | I9: SMPyPS | J9: TOTAL SMPyPS | K9: DIR. LAB. CENTRAL | L9: TOTAL DE LAB CENTRAL | M9: BCO DE SANGRE | N9: TOTAL BANCO DE SANGRE | O9: APS | P9: TOTAL A.P.S. | Q9: DIR DE CANCER | R9: TOTAL DE DIR DE CANCER | S9: FARMACIA | T9: TOTAL FARMACIA | U9: ODONTOLOGIA | V9: TOTAL DE ODONTOLOG | W9: SAME | X9: TOTAL SAME | Y9: HPTAL MALBRAN | Z9: TOTAL HPTAL MALBRAN | AA9: MATERNIDAD E INFANCIA | AB9: TOTAL MATERNIDAD E INFANCIA | AC9: SASP | AD9: TOTAL SASP | AE9: SALUD Y MEDIO AMBIENTE | AF9: TOTAL SALUD Y MEDIO AMBIENTE | AG9: VECTORES Y ZOONOSIS | AH9: TOTAL DE VECT Y ZOON | AI9: CRONICAS | AJ9: TOTAL CRONICAS | AK9: CUR | AL9: TOTAL CUR | AM9: SPyGS | AN9: TOTAL SPyGS | AO9: SALUD MENTAL | AP9: TOTAL SALUD MENTAL | AQ9: AREAS Y DPAS | AR9: TOTAL DPAS | AS9: EPIDEMIOLOGIA | AT9: TOTAL EPIDEMIOLOGIA | AU9: MS | AV9: TOTAL MS | AW9: CANTIDAD TOTAL | AX9: PRECIO UNITARIO ESTIMADO | AY9: IMPORTE TOTAL ESTIMADO | AZ9: ESPECIFICACION TECNICA | BA9: IPP | BC9: RUBRO S/CATALOGO
A10: 1 | B10: 4.3.3-5415.6 | C10: PROD. MEDICO/FARMACEUTICOS/LAB | D10: 4.3.3 | E10: BALANZAS P/PERSONAS; TIPO: ADULTO, PRECISION: 100 GR, ACCESORIO: ALTIMETRO, CAPACIDAD: 250 Kg | F10: UNIDAD | AU10: 10 | AV10: =+AU10*AX10 -> 1800000 | AW10: =+AQ10+AO10+AM10+AK10+AI10+AG10+AE10+AC10+AA10+Y10+W10+U10+S10+Q10+O10+M10+K10+I10+AS10+G10+AU10 -> 10 | AX10: 180000 | AY10: =+AW10*AX10 -> 1800000 | AZ10: Balanza tipo: mecánica, con estructura totalmente metálica recubierta con pintura epoxi, plataforma de apoyo en caucho antideslizante. Con Altímetro Incluido. Sistema de fácil lectura a barra y cursores. Escala graduada en relieve en acero inoxidable. Dispositivo de traba de brazo. Asientos y cuchillas de acero. Patas regulables. Garantía mínima de 2 años, aprobado por ANMAT. | BA10: 433 | BB10: Balanza tipo: mecánica, con estructura totalmente metálica recubierta con pintura epoxi, plataforma de apoyo en caucho antideslizante. Con Altímetro Incluido. Sistema de fácil lectura a barra y cursores. Escala graduada en relieve en acero inoxidable. Dispositivo de traba de brazo. Asientos y cuchillas de acero. Patas regulables. Garantía mínima de 2 años, aprobado por ANMAT. | BC10: PROD. MEDICO/FARMACEUTICOS/LAB
A11: 2 | B11: 4.3.3-5415.3 | C11: PROD. MEDICO/FARMACEUTICOS/LAB | D11: 4.3.3 | E11: BALANZAS P/PERSONAS; TIPO: P/ADULTOS, PRECISION: 100 GR, ACCESORIO: ALTIMETRO, CAPACIDAD: 150 Kg | F11: UNIDAD | AU11: 10 | AV11: =+AU11*AX11 -> 1100000 | AW11: =+AQ11+AO11+AM11+AK11+AI11+AG11+AE11+AC11+AA11+Y11+W11+U11+S11+Q11+O11+M11+K11+I11+AS11+G11+AU11 -> 10 | AX11: 110000 | AY11: =+AW11*AX11 -> 1100000 | AZ11: Balanza tipo: mecánica, con estructura totalmente metálica recubierta con pintura epoxi, plataforma de apoyo en caucho antideslizante. Con Altímetro Incluido. Sistema de fácil lectura a barra y cursores. Escala graduada en relieve en acero inoxidable. Dispositivo de traba de brazo. Asientos y cuchillas de acero. Patas regulables. Garantía mínima de 2 años, aprobado por ANMAT. | BA11: 433 | BB11: Balanza tipo: mecánica, con estructura totalmente metálica recubierta con pintura epoxi, plataforma de apoyo en caucho antideslizante. Con Altímetro Incluido. Sistema de fácil lectura a barra y cursores. Escala graduada en relieve en acero inoxidable. Dispositivo de traba de brazo. Asientos y cuchillas de acero. Patas regulables. Garantía mínima de 2 años, aprobado por ANMAT. | BC11: PROD. MEDICO/FARMACEUTICOS/LAB
A12: 3 | B12: 4.3.3-5415.7 | C12: PROD. MEDICO/FARMACEUTICOS/LAB | D12: 4.3.3 | E12: BALANZAS P/PERSONAS; TIPO: PEDIATRICA, PRECISION: 100 GR, ACCESORIO: ESCALIMETRO, CAPACIDAD: 50 Kg | F12: UNIDAD | AU12: 10 | AV12: =+AU12*AX12 -> 1100000 | AW12: =+AQ12+AO12+AM12+AK12+AI12+AG12+AE12+AC12+AA12+Y12+W12+U12+S12+Q12+O12+M12+K12+I12+AS12+G12+AU12 -> 10 | AX12: 110000 | AY12: =+AW12*AX12 -> 1100000 | AZ12: Balanza tipo: mecánica, con estructura totalmente metálica recubierta con pintura epoxi, plataforma de apoyo en caucho antideslizante. Con Altímetro Incluido. Sistema de fácil lectura a barra y cursores. Escala graduada en relieve en acero inoxidable. Dispositivo de traba de brazo. Asientos y cuchillas de acero. Patas regulables. Garantía mínima de 2 años, aprobado por ANMAT. | BA12: 433 | BB12: Balanza tipo: mecánica, con estructura totalmente metálica recubierta con pintura epoxi, plataforma de apoyo en caucho antideslizante. Con Altímetro Incluido. Sistema de fácil lectura a barra y cursores. Escala graduada en relieve en acero inoxidable. Dispositivo de traba de brazo. Asientos y cuchillas de acero. Patas regulables. Garantía mínima de 2 años, aprobado por ANMAT. | BC12: PROD. MEDICO/FARMACEUTICOS/LAB
A13: 4 | B13: 2.9.5-8239.1 | C13: PROD. MEDICO/FARMACEUTICOS/LAB | D13: 2.9.5 | E13: CHATAS; MATERIAL: PVC | F13: UNIDAD | AU13: 100 | AV13: =+AU13*AX13 -> 80000 | AW13: =+AQ13+AO13+AM13+AK13+AI13+AG13+AE13+AC13+AA13+Y13+W13+U13+S13+Q13+O13+M13+K13+I13+AS13+G13+AU13 -> 100 | AX13: 800 | AY13: =+AW13*AX13 -> 80000 | BA13: no dice nada 295 o 299 | BC13: PROD. MEDICO/FARMACEUTICOS/LAB
A14: 5 | B14: 2.9.5-5041.6 | C14: PROD. MEDICO/FARMACEUTICOS/LAB | D14: 2.9.5 | E14: COLLARES CERVICALES; MATERIAL: PLASTICO, TALLE: SIN VALOR, USO: INMOBILIZADORES LATERALES DE C | F14: UNIDAD | AU14: 100 | AV14: =+AU14*AX14 -> 230000 | AW14: =+AQ14+AO14+AM14+AK14+AI14+AG14+AE14+AC14+AA14+Y14+W14+U14+S14+Q14+O14+M14+K14+I14+AS14+G14+AU14 -> 100 | AX14: 2300 | AY14: =+AW14*AX14 -> 230000 | AZ14: Inmovilizador filadelfia en dos piezas, ajustables entre si con velcro - Talle S: 20 unid. - Talle M: 20 unid. - Talle L: 20 unid. - Talle XL: 20 unid. - Talle Pediatrico: 20 unid. Que cumpla con las siguientes caracteristicas mínimas: Hipoalergénico, Anatómico, Regulable, Material: por ej. Polietilendo expandido de celdas cerradas, Disponible en tamaño pediatrico, chico, mediano, grande y extra grande de acuerdo a los talles solicitados. | BA14: ver en 433 sale collar p/traumatología | BB14: Que cumpla con las siguientes caracteristicas mínimas: Hipoalergénico, Anatómico, Regulable, Material: por ej. Polietilendo expandido de celdas cerradas, Disponible en tamaño chico, mediano y grande, de acuerdo a los talles solicitados. | BC14: PROD. MEDICO/FARMACEUTICOS/LAB
A15: 6 | B15: 2.9.5-4208.17 | C15: PROD. MEDICO/FARMACEUTICOS/LAB | D15: 2.9.5 | E15: ELEMENTOS P/RADIOLOGIA; TIPO: DELANTAL PLOMADO, PRESENTACION: UNIDAD | F15: UNIDAD | AU15: 50 | AV15: =+AU15*AX15 -> 2100000 | AW15: =+AQ15+AO15+AM15+AK15+AI15+AG15+AE15+AC15+AA15+Y15+W15+U15+S15+Q15+O15+M15+K15+I15+AS15+G15+AU15 -> 50 | AX15: 42000 | AY15: =+AW15*AX15 -> 2100000 | AZ15: Tamaño adulto, recubierto con tela de avión, cierre mediante correas, con protector de tiroides y 0,5mm de plomo de blindaje | BA15: ver en 433 sale guardapolvo plomado | BB15: Por precio y tipo de bien, debería ser inventariado. Solicitar el Alta (Los incriptos en rubro Indument.nunca van a ofertar este tipo de bien!!) Tamaño adulto, recubierto con tela de avión, cierre mediante correas, con protector de tiroides y 0,5mm de plomo de blindaje | BC15: INDUMENT TEXTIL Y CONFECCIONES
A16: 7 | B16: 4.3.3-7798.1 | C16: PROD. MEDICO/FARMACEUTICOS/LAB | D16: 4.3.3 | E16: DETECTORES DE LATIDOS; USO: P/LATIDOS FETALES, ALIMENTACION: ELECTRICA-BATERIA, FRECUENCIA: 1,1- 2,1 MHZ, INTENSIDAD: 10 MW/CM2, CORRIENTE: 10 MW/CM2 | F16: UNIDAD | AU16: 15 | AV16: =+AU16*AX16 -> 259500 | AW16: =+AQ16+AO16+AM16+AK16+AI16+AG16+AE16+AC16+AA16+Y16+W16+U16+S16+Q16+O16+M16+K16+I16+AS16+G16+AU16 -> 15 | AX16: 17300 | AY16: =+AW16*AX16 -> 259500 | AZ16: Consta de emisor/receptor de señal ultrasónica, procesador, pantalla mínima LCD, altavoz y fuente de alimentación; ser de fácil uso y portátil; Mostrar la frecuencia cardíaca, con una medición precisa y de sonido nítido. Con funciones mínimas como: toma en tiempo real, promedio y conteo manual. Con salida de audio externa, bajo consumo y función de apagado automático. | BA16: 433 | BB16: Consta de emisor/receptor de señal ultrasónica, procesador, pantalla mínima LCD, altavoz y fuente de alimentación; ser de fácil uso y portátil; Mostrar la frecuencia cardíaca, con una medición precisa y de sonido nítido. Con funciones mínimas como: toma en tiempo real, promedio y conteo manual. Con salida de audio externa, bajo consumo y función de apagado automático. | BC16: PROD. MEDICO/FARMACEUTICOS/LAB
A17: 8 | B17: 4.3.3-2049.4 | C17: PROD. MEDICO/FARMACEUTICOS/LAB | D17: 4.3.3 | E17: ESTETOSCOPIOS; TIPO: VIA AURICULAR, CAMPANA: DOBLE | F17: UNIDAD | AU17: 140 | AV17: =+AU17*AX17 -> 770000 | AW17: =+AQ17+AO17+AM17+AK17+AI17+AG17+AE17+AC17+AA17+Y17+W17+U17+S17+Q17+O17+M17+K17+I17+AS17+G17+AU17 -> 140 | AX17: 5500 | AY17: =+AW17*AX17 -> 770000 | AZ17: modelo con doble cabezal (campana + diafragma: uso adulto y pediátrico), tubo auditivo de acero inoxidable con curvatura anatómica, olivas de goma y garantía minima de 1 año. 70 unid para uso en adultos y 70 unid. Para uso pediatrico | BA17: 433 | BB17: Ver si se puede solicitar un solo ítem, aclarando: modelo con doble cabezal (campana + diafragma: uso adulto y pediátrico), tubo auditivo de acero inoxidable con curvatura anatómica, olivas de goma y garantía minima de 1 año. | BC17: PROD. MEDICO/FARMACEUTICOS/LAB
A18: 9 | B18: 2.9.5-8874.9 | C18: PROD. MEDICO/FARMACEUTICOS/LAB | D18: 2.9.5 | E18: INSTRUMENTAL MEDICO; DESCRIPCION: TABLA LARGA DE INMOVILIZACION, DESCARTABLE: NO, MATERIAL: POLIETILENO, ELEMENTO: TABLA LARGA DE INMOVILIZACION | F18: UNIDAD | AU18: 10 | AV18: =+AU18*AX18 -> 320000 | AW18: =+AQ18+AO18+AM18+AK18+AI18+AG18+AE18+AC18+AA18+Y18+W18+U18+S18+Q18+O18+M18+K18+I18+AS18+G18+AU18 -> 10 | AX18: 32000 | AY18: =+AW18*AX18 -> 320000 | AZ18: Construída ergonómicamente en HDPE (Polietileno de Alta Densidad, lavable antiestático de alta resistencia) sin costuras p/evitar el alojamiento de gérmenes patógenos, acabado delicado, impermeable y atóxico con exclusivos calados p/inmovilizador cervical, pectorales, abdomen y piernas en forma independiente. incluye juegos de cinturones de fijacion, con velcro, colores según codigos internacionales. | BA18: ver si no corresponde en 433 por el tipo de bien y su precio. Determinar colores y uso. Ver característica de traslúcida (traslúcida a RX, CT y MRI). | BB18: Construída ergonómicamente en HDPE (Polietileno de Alta Densidad, lavable antiestático de alta resistencia) sin costuras p/evitar el alojamiento de gérmenes patógenos, acabado delicado, impermeable y atóxico con exclusivos calados p/inmovilizador cervical, pectorales, abdomen y piernas en forma independiente | BC18: PROD. MEDICO/FARMACEUTICOS/LAB
A19: 10 | B19: 2.9.5-8874.10 | C19: PROD. MEDICO/FARMACEUTICOS/LAB | D19: 2.9.5 | E19: INSTRUMENTAL MEDICO; DESCRIPCION: TABLA PEDIATRICA, DESCARTABLE: NO, MATERIAL: MADERA, ELEMENTO: TABLA PEDIATRICA | F19: UNIDAD | AU19: 2 | AV19: =+AU19*AX19 -> 56000 | AW19: =+AQ19+AO19+AM19+AK19+AI19+AG19+AE19+AC19+AA19+Y19+W19+U19+S19+Q19+O19+M19+K19+I19+AS19+G19+AU19 -> 2 | AX19: 28000 | AY19: =+AW19*AX19 -> 56000 | AZ19: Multilaminado fenólico standard, con un mínimo de 5 capas compensadas, con calados (para inmovilizador cervical y piernas en forma individual), terminación plastificado en barniz marino, con tres juegos de cinturones de fijación con velcro. | BA19: ver si no corresponde en 433 por el tipo de bien y su precio. Ver característica de traslúcida (traslúcida a RX, CT y MRI). | BB19: Multilaminado fenólico standard, con un mínimo de 5 capas compensadas, con calados (para inmovilizador cervical y piernas en forma individual), terminación plastificado en barniz marino, con tres juegos de cinturones de fijación. | BC19: PROD. MEDICO/FARMACEUTICOS/LAB
A20: 11 | B20: 2.9.5-8234.1 | C20: PROD. MEDICO/FARMACEUTICOS/LAB | D20: 2.9.5 | E20: ORINALES; MATERIAL: MATERIAL PVC | F20: UNIDAD | AU20: 100 | AV20: =+AU20*AX20 -> 50000 | AW20: =+AQ20+AO20+AM20+AK20+AI20+AG20+AE20+AC20+AA20+Y20+W20+U20+S20+Q20+O20+M20+K20+I20+AS20+G20+AU20 -> 100 | AX20: 500 | AY20: =+AW20*AX20 -> 50000 | AZ20: 50 unid. uso masculino - 50 unid. Uso femenino | BA20: no dice nada 295 o 299 | BB20: Ver si son solo uso masculino, femenino o ambos. Aclarar | BC20: PROD. MEDICO/FARMACEUTICOS/LAB
A21: 12 | B21: 4.3.3-5079.5 | C21: EQUIPOS | D21: 4.3.3 | E21: OTOSCOPIOS; TIPO: DE BOLSILLO C/LAMPARA, CANULAS: SIN, ALIMENTACION: A PILA | F21: UNIDAD | AU21: 14 | AV21: =+AU21*AX21 -> 102200 | AW21: =+AQ21+AO21+AM21+AK21+AI21+AG21+AE21+AC21+AA21+Y21+W21+U21+S21+Q21+O21+M21+K21+I21+AS21+G21+AU21 -> 14 | AX21: 7300 | AY21: =+AW21*AX21 -> 102200 | AZ21: Tecnología LED y Fibra Optica, Aumento mínimo de 3x, cabezal giratorio, rueda de lentes con 18 lentes mínimo. | BA21: 433 | BB21: Tecnología LED y Fibra Optica, Aumento mínimo de 3x, cabezal giratorio, rueda de lentes con 18 lentes mínimo. | BC21: EQUIPOS
A22: 13 | B22: 4.3.3-3999.3 | C22: PROD. MEDICO/FARMACEUTICOS/LAB | D22: 4.3.3 | E22: OXIMETROS DE BOLSILLOS; RANGO: 0 - 100 %, TEMPERATURA DE TRABAJO: 0 A 50 °C, ALIMENTACION: 2 BATERIAS, PESO: 50 A 70 GR | F22: UNIDAD | AU22: 25 | AV22: =+AU22*AX22 -> 112500 | AW22: =+AQ22+AO22+AM22+AK22+AI22+AG22+AE22+AC22+AA22+Y22+W22+U22+S22+Q22+O22+M22+K22+I22+AS22+G22+AU22 -> 25 | AX22: 4500 | AY22: =+AW22*AX22 -> 112500 | AZ22: Oximetro de pulso adulto/ pediatrico. Alimentación con 2 pilas, debe contar con aprobación de ANMAT | BA22: 433 | BB22: Alimentación con 2 pilas, debe contar con aprobación de ANMAT | BC22: PROD. MEDICO/FARMACEUTICOS/LAB
A23: 14 | B23: 4.3.3-7819.1 | C23: PROD. MEDICO/FARMACEUTICOS/LAB | D23: 4.3.3 | E23: PEDIOMETROS; RANGO: 0 A 1 M, RESOLUCION: 0,5 Cm, MATERIAL: ALUMINIO Y PLASTICO | F23: UNIDAD | AU23: 7 | AV23: =+AU23*AX23 -> 86100 | AW23: =+AQ23+AO23+AM23+AK23+AI23+AG23+AE23+AC23+AA23+Y23+W23+U23+S23+Q23+O23+M23+K23+I23+AS23+G23+AU23 -> 7 | AX23: 12300 | AY23: =+AW23*AX23 -> 86100 | AZ23: Para uso pedíatrico, con una varilla metálica milimetrada, y aletas plásticas fija que pueden sujetarse cómodamente. | BA23: no sale esa IPP | BB23: Para uso pedíatrico, con una varilla metálica milimetrada, y aletas plásticas fija que pueden sujetarse cómodamente. | BC23: PROD. MEDICO/FARMACEUTICOS/LAB
A24: 15 | B24: 4.3.3-4853.2 | C24: EQUIPOS | D24: 4.3.3 | E24: PIES DE SUEROS; RUEDAS: CON, MATERIAL: ACERO INOXIDABLE | F24: UNIDAD | AU24: 200 | AV24: =+AU24*AX24 -> 1300000 | AW24: =+AQ24+AO24+AM24+AK24+AI24+AG24+AE24+AC24+AA24+Y24+W24+U24+S24+Q24+O24+M24+K24+I24+AS24+G24+AU24 -> 200 | AX24: 6500 | AY24: =+AW24*AX24 -> 1300000 | AZ24: Altura mínima regulable de 180cm, con base rodante de 5 ramas con ruedas de plástico de alta resistencia y alto impacto inyectadas. Caño y estructura en acero inoxidable, con 2 ganchos minimo. | BA24: 433 | BB24: Altura mínima regulable de 180cm, con base rodante de 5 ramas con ruedas de plástico de alta resistencia y alto impacto inyectadas. Caño y estructura en acero inoxidable. | BC24: EQUIPOS
A25: 16 | B25: 4.3.3-130.13 | C25: PROD. MEDICO/FARMACEUTICOS/LAB | D25: 4.3.3 | E25: TENSIOMETROS ARTERIALES; RANGO DE PRESION: +/- 3 mm hg, RANGO PULSACIONES: SIN, ALIMENTACION: SIN, TIPO: ANEROIDE | F25: UNIDAD | AU25: 70 | AV25: =+AU25*AX25 -> 161000 | AW25: =+AQ25+AO25+AM25+AK25+AI25+AG25+AE25+AC25+AA25+Y25+W25+U25+S25+Q25+O25+M25+K25+I25+AS25+G25+AU25 -> 70 | AX25: 2300 | AY25: =+AW25*AX25 -> 161000 | AZ25: Tensiómetro manual anaeroide (analógico), con manómetro circular de facil lectura, brazalete uso adulto, con estetoscopio de campana simple y olivas de plástico incluido. | BA25: 433 | BB25: Tensiómetro manual anaeroide (analógico), con manómetro circular de facil lectura, brazalete uso adulto, con estetoscopio de campana simple y olivas de plástico incluido. | BC25: PROD. MEDICO/FARMACEUTICOS/LAB
A26: 17 | B26: 4.3.3-130.13 | C26: PROD. MEDICO/FARMACEUTICOS/LAB | D26: 4.3.3 | E26: TENSIOMETROS ARTERIALES; RANGO DE PRESION: +/- 3 mm hg, RANGO PULSACIONES: SIN, ALIMENTACION: SIN, TIPO: ANEROIDE | F26: UNIDAD | AU26: 70 | AV26: =+AU26*AX26 -> 189000 | AW26: =+AQ26+AO26+AM26+AK26+AI26+AG26+AE26+AC26+AA26+Y26+W26+U26+S26+Q26+O26+M26+K26+I26+AS26+G26+AU26 -> 70 | AX26: 2700 | AY26: =+AW26*AX26 -> 189000 | AZ26: Tensiómetro manual anaeroide (analógico), con manómetro circular de facil lectura, brazalete uso pediátrico, con estetoscopio de campana simple y olivas de plástico incluido. | BA26: 433 | BB26: Tensiómetro manual anaeroide (analógico), con manómetro circular de facil lectura, brazalete uso pediátrico, con estetoscopio de campana simple y olivas de plástico incluido. | BC26: PROD. MEDICO/FARMACEUTICOS/LAB
A27: 18 | B27: 4.3.3-130.13 | C27: PROD. MEDICO/FARMACEUTICOS/LAB | D27: 4.3.3 | E27: TENSIOMETROS ARTERIALES; RANGO DE PRESION: +/- 3 mm hg, RANGO PULSACIONES: SIN, ALIMENTACION: SIN, TIPO: ANEROIDE | F27: UNIDAD | AU27: 70 | AV27: =+AU27*AX27 -> 336000 | AW27: =+AQ27+AO27+AM27+AK27+AI27+AG27+AE27+AC27+AA27+Y27+W27+U27+S27+Q27+O27+M27+K27+I27+AS27+G27+AU27 -> 70 | AX27: 4800 | AY27: =+AW27*AX27 -> 336000 | AZ27: Tensiómetro manual anaeroide (analógico), con manómetro circular de facil lectura, brazalete uso adulto obesos (de 32 a 42cm de diámetro aproximado), con estetoscopio de campana simple y olivas de plástico incluido. | BA27: 433 | BB27: Tensiómetro manual anaeroide (analógico), con manómetro circular de facil lectura, brazalete uso adulto obesos (de 32 a 42cm de diámetro aproximado), con estetoscopio de campana simple y olivas de plástico incluido. | BC27: PROD. MEDICO/FARMACEUTICOS/LAB
A28: 19 | B28: 4.3.3-3675.100 | C28: PROD. MEDICO/FARMACEUTICOS/LAB | D28: 4.3.9 | E28: TERMOMETROS; TIPO: DIGITAL, ESCALA: GRADO CENTIGRADO, RANGO DE TEMPERATURA: -5 A 50 °C | F28: UNIDAD | AU28: 70 | AV28: =+AU28*AX28 -> 59500 | AW28: =+AQ28+AO28+AM28+AK28+AI28+AG28+AE28+AC28+AA28+Y28+W28+U28+S28+Q28+O28+M28+K28+I28+AS28+G28+AU28 -> 70 | AX28: 850 | AY28: =+AW28*AX28 -> 59500 | BA28: 439 | BC28: PROD. MEDICO/FARMACEUTICOS/LAB
A29: 20 | B29: 4.3.3-4212.4 | C29: PROD. MEDICO/FARMACEUTICOS/LAB | D29: 4.3.3 | E29: TUBOS DE OXIGENO; TIPO: CAPACIDAD 6 M3 | F29: UNIDAD | AU29: 70 | AV29: =+AU29*AX29 -> 2254000 | AW29: =+AQ29+AO29+AM29+AK29+AI29+AG29+AE29+AC29+AA29+Y29+W29+U29+S29+Q29+O29+M29+K29+I29+AS29+G29+AU29 -> 70 | AX29: 32200 | AY29: =+AW29*AX29 -> 2254000 | AZ29: De uso medicinal, provisto de una válvula de reducción medicinal con regulador de flujo y manómetro. Industria Nacional. Material acero. Color blanco. Con prueba hidráulica aprobada por 5 años. Incluye soporte | BA29: 433 o 439 | BB29: De uso medicinal, provisto de una válvula de reducción medicinal con regulador de flujo y manómetro. Industria Nacional. Material acero. Color blanco. Con prueba hidráulica aprobada por 5 años. | BC29: PROD. MEDICO/FARMACEUTICOS/LAB
E30: TOTAL RUBRO EQUIPOS Y UTILES MEDICOS MENORES | AY30: =+SUM(AY10:AY29) -> 12465800
C33: ESPECIFICADES Y DETALLE TECNICO: | BB33: ACLARACIONES SIEMPRE A MODO DE EJEMPLO Y/O SUGERENCIA. CONTEMPLAR TODAS LAS CUESTIONES NECESARIAS PARA PODER IDENTIFICAR CORRECTAMENTE EL BIEN SOLICITADO. NO OLVIDAR CONTEMPLAR LA GARANTIA MINIMA DE LOS MISMOS, ASÍ COMO LAS CERTIFICACIONES Y/O APROBACIONES (de la ANMAT) CORRESPONDIENTES PARA SU USO.
C35: Plazos de entrega: | D35: veinte (20) dias habiles
C37: Lugar de Entrega: | D37: MINISTERIO DE SALUD - CHACABUCO N° 169 - en el horario de 8:00hs a 12:00hs de lunes a viernes
C39: Calidad Minima esperada:
C41: Garantia: | D41: un (1) año
C43: Mantenimiento: | D43: cuarenta y cinco (45) días
C47: ESPECIFICIDADES ITEM 1
C48: =AZ10 -> Balanza tipo: mecánica, con estructura totalmente metálica recubierta con pintura epoxi, plataforma de apoyo en caucho antideslizante. Con Altímetro Incluido. Sistema de fácil lectura a barra y cursores. Escala graduada en relieve en acero inoxidable. Dispositivo de traba de brazo. Asientos y cuchillas de acero. Patas regulables. Garantía mínima de 2 años, aprobado por ANMAT.
C50: ESPECIFICIDADES ITEM 2
C51: =AZ11 -> Balanza tipo: mecánica, con estructura totalmente metálica recubierta con pintura epoxi, plataforma de apoyo en caucho antideslizante. Con Altímetro Incluido. Sistema de fácil lectura a barra y cursores. Escala graduada en relieve en acero inoxidable. Dispositivo de traba de brazo. Asientos y cuchillas de acero. Patas regulables. Garantía mínima de 2 años, aprobado por ANMAT.
C53: ESPECIFICIDADES ITEM 3
C54: =AZ12 -> Balanza tipo: mecánica, con estructura totalmente metálica recubierta con pintura epoxi, plataforma de apoyo en caucho antideslizante. Con Altímetro Incluido. Sistema de fácil lectura a barra y cursores. Escala graduada en relieve en acero inoxidable. Dispositivo de traba de brazo. Asientos y cuchillas de acero. Patas regulables. Garantía mínima de 2 años, aprobado por ANMAT.
...

Sheet NP
A1: NOTA DE PEDIDO | J1: N° | K1: 08/2022
A3: JURISDICCIÓN: | D3: 040 - MINISTERIO DE SALUD
A4: SAF: | D4: 011 - DIRECCION PROVINCIAL DE ADMINISTRACION DEL MINISTERIO DE SALUD
A5: UNIDAD EJECUTORA: | D5: 352 - MINISTERIO DE SALUD
A6: DEPENDENCIA SOLICITANTE: | D6: 352 - MINISTERIO DE SALUD
A7: PERIODO UTILIZACIÓN: | D7: CINCO (5) AÑOS
A8: OBJETO: | D8: ADQUISICION DE EQUIPOS Y UTILES MEDICOS MENORES CON DESTINO A HOSPITALES DE LA PROVINCIA
A10: Ítem | B10: Codigo Item | C10: DESCRIPCIÓN | H10: Adjunta Detalle Técnico | I10: Unidad Medida | J10: Precio Unitario Estimado | K10: Cantidad Solicitada
N11: 295 | O11: 433 | P11: 439
A12: 1 | B12: ='SAF 011 - NECESIDAD TRIMESTRAL'!B10 -> 4.3.3-5415.6 | C12: ='SAF 011 - NECESIDAD TRIMESTRAL'!E10 -> BALANZAS P/PERSONAS; TIPO: ADULTO, PRECISION: 100 GR, ACCESORIO: ALTIMETRO, CAPACIDAD: 250 Kg | H12: SI | I12: ='SAF 011 - NECESIDAD TRIMESTRAL'!F10 -> UNIDAD | J12: ='SAF 011 - NECESIDAD TRIMESTRAL'!AX10 -> 180000 | K12: ='SAF 011 - NECESIDAD TRIMESTRAL'!AU10 -> 10 | O12: =+K12*J12 -> 1800000
A13: 2 | B13: ='SAF 011 - NECESIDAD TRIMESTRAL'!B11 -> 4.3.3-5415.3 | C13: ='SAF 011 - NECESIDAD TRIMESTRAL'!E11 -> BALANZAS P/PERSONAS; TIPO: P/ADULTOS, PRECISION: 100 GR, ACCESORIO: ALTIMETRO, CAPACIDAD: 150 Kg | H13: SI | I13: ='SAF 011 - NECESIDAD TRIMESTRAL'!F11 -> UNIDAD | J13: ='SAF 011 - NECESIDAD TRIMESTRAL'!AX11 -> 110000 | K13: ='SAF 011 - NECESIDAD TRIMESTRAL'!AU11 -> 10 | O13: =+K13*J13 -> 1100000
A14: 3 | B14: ='SAF 011 - NECESIDAD TRIMESTRAL'!B12 -> 4.3.3-5415.7 | C14: ='SAF 011 - NECESIDAD TRIMESTRAL'!E12 -> BALANZAS P/PERSONAS; TIPO: PEDIATRICA, PRECISION: 100 GR, ACCESORIO: ESCALIMETRO, CAPACIDAD: 50 Kg | H14: SI | I14: ='SAF 011 - NECESIDAD TRIMESTRAL'!F12 -> UNIDAD | J14: ='SAF 011 - NECESIDAD TRIMESTRAL'!AX12 -> 110000 | K14: ='SAF 011 - NECESIDAD TRIMESTRAL'!AU12 -> 10 | O14: =+K14*J14 -> 1100000
A15: 4 | B15: ='SAF 011 - NECESIDAD TRIMESTRAL'!B13 -> 2.9.5-8239.1 | C15: ='SAF 011 - NECESIDAD TRIMESTRAL'!E13 -> CHATAS; MATERIAL: PVC | H15: SI | I15: ='SAF 011 - NECESIDAD TRIMESTRAL'!F13 -> UNIDAD | J15: ='SAF 011 - NECESIDAD TRIMESTRAL'!AX13 -> 800 | K15: ='SAF 011 - NECESIDAD TRIMESTRAL'!AU13 -> 100 | N15: =+J15*K15 -> 80000
A16: 5 | B16: ='SAF 011 - NECESIDAD TRIMESTRAL'!B14 -> 2.9.5-5041.6 | C16: ='SAF 011 - NECESIDAD TRIMESTRAL'!E14 -> COLLARES CERVICALES; MATERIAL: PLASTICO, TALLE: SIN VALOR, USO: INMOBILIZADORES LATERALES DE C | H16: NO | I16: ='SAF 011 - NECESIDAD TRIMESTRAL'!F14 -> UNIDAD | J16: ='SAF 011 - NECESIDAD TRIMESTRAL'!AX14 -> 2300 | K16: ='SAF 011 - NECESIDAD TRIMESTRAL'!AU14 -> 100 | N16: =+J16*K16 -> 230000
A17: 6 | B17: ='SAF 011 - NECESIDAD TRIMESTRAL'!B15 -> 2.9.5-4208.17 | C17: ='SAF 011 - NECESIDAD TRIMESTRAL'!E15 -> ELEMENTOS P/RADIOLOGIA; TIPO: DELANTAL PLOMADO, PRESENTACION: UNIDAD | H17: SI | I17: ='SAF 011 - NECESIDAD TRIMESTRAL'!F15 -> UNIDAD | J17: ='SAF 011 - NECESIDAD TRIMESTRAL'!AX15 -> 42000 | K17: ='SAF 011 - NECESIDAD TRIMESTRAL'!AU15 -> 50 | N17: =+J17*K17 -> 2100000
A18: 7 | B18: ='SAF 011 - NECESIDAD TRIMESTRAL'!B16 -> 4.3.3-7798.1 | C18: ='SAF 011 - NECESIDAD TRIMESTRAL'!E16 -> DETECTORES DE LATIDOS; USO: P/LATIDOS FETALES, ALIMENTACION: ELECTRICA-BATERIA, FRECUENCIA: 1,1- 2,1 MHZ, INTENSIDAD: 10 MW/CM2, CORRIENTE: 10 MW/CM2 | H18: SI | I18: ='SAF 011 - NECESIDAD TRIMESTRAL'!F16 -> UNIDAD | J18: ='SAF 011 - NECESIDAD TRIMESTRAL'!AX16 -> 17300 | K18: ='SAF 011 - NECESIDAD TRIMESTRAL'!AU16 -> 15 | O18: =+K18*J18 -> 259500
A19: 8 | B19: ='SAF 011 - NECESIDAD TRIMESTRAL'!B17 -> 4.3.3-2049.4 | C19: ='SAF 011 - NECESIDAD TRIMESTRAL'!E17 -> ESTETOSCOPIOS; TIPO: VIA AURICULAR, CAMPANA: DOBLE | H19: SI | I19: ='SAF 011 - NECESIDAD TRIMESTRAL'!F17 -> UNIDAD | J19: ='SAF 011 - NECESIDAD TRIMESTRAL'!AX17 -> 5500 | K19: ='SAF 011 - NECESIDAD TRIMESTRAL'!AU17 -> 140 | O19: =+K19*J19 -> 770000
A20: 9 | B20: ='SAF 011 - NECESIDAD TRIMESTRAL'!B18 -> 2.9.5-8874.9 | C20: ='SAF 011 - NECESIDAD TRIMESTRAL'!E18 -> INSTRUMENTAL MEDICO; DESCRIPCION: TABLA LARGA DE INMOVILIZACION, DESCARTABLE: NO, MATERIAL: POLIETILENO, ELEMENTO: TABLA LARGA DE INMOVILIZACION | H20: SI | I20: ='SAF 011 - NECESIDAD TRIMESTRAL'!F18 -> UNIDAD | J20: ='SAF 011 - NECESIDAD TRIMESTRAL'!AX18 -> 32000 | K20: ='SAF 011 - NECESIDAD TRIMESTRAL'!AU18 -> 10 | O20: =+K20*J20 -> 320000
A21: 10 | B21: ='SAF 011 - NECESIDAD TRIMESTRAL'!B19 -> 2.9.5-8874.10 | C21: ='SAF 011 - NECESIDAD TRIMESTRAL'!E19 -> INSTRUMENTAL MEDICO; DESCRIPCION: TABLA PEDIATRICA, DESCARTABLE: NO, MATERIAL: MADERA, ELEMENTO: TABLA PEDIATRICA | H21: SI | I21: ='SAF 011 - NECESIDAD TRIMESTRAL'!F19 -> UNIDAD | J21: ='SAF 011 - NECESIDAD TRIMESTRAL'!AX19 -> 28000 | K21: ='SAF 011 - NECESIDAD TRIMESTRAL'!AU19 -> 2 | N21: =+J21*K21 -> 56000
A22: 11 | B22: ='SAF 011 - NECESIDAD TRIMESTRAL'!B20 -> 2.9.5-8234.1 | C22: ='SAF 011 - NECESIDAD TRIMESTRAL'!E20 -> ORINALES; MATERIAL: MATERIAL PVC | H22: SI | I22: ='SAF 011 - NECESIDAD TRIMESTRAL'!F20 -> UNIDAD | J22: ='SAF 011 - NECESIDAD TRIMESTRAL'!AX20 -> 500 | K22: ='SAF 011 - NECESIDAD TRIMESTRAL'!AU20 -> 100 | N22: =+J22*K22 -> 50000
A23: 12 | B23: ='SAF 011 - NECESIDAD TRIMESTRAL'!B21 -> 4.3.3-5079.5 | C23: ='SAF 011 - NECESIDAD TRIMESTRAL'!E21 -> OTOSCOPIOS; TIPO: DE BOLSILLO C/LAMPARA, CANULAS: SIN, ALIMENTACION: A PILA | H23: SI | I23: ='SAF 011 - NECESIDAD TRIMESTRAL'!F21 -> UNIDAD | J23: ='SAF 011 - NECESIDAD TRIMESTRAL'!AX21 -> 7300 | K23: ='SAF 011 - NECESIDAD TRIMESTRAL'!AU21 -> 14 | N23: =+J23*K23 -> 102200
A24: 13 | B24: ='SAF 011 - NECESIDAD TRIMESTRAL'!B22 -> 4.3.3-3999.3 | C24: ='SAF 011 - NECESIDAD TRIMESTRAL'!E22 -> OXIMETROS DE BOLSILLOS; RANGO: 0 - 100 %, TEMPERATURA DE TRABAJO: 0 A 50 °C, ALIMENTACION: 2 BATERIAS, PESO: 50 A 70 GR | H24: SI | I24: ='SAF 011 - NECESIDAD TRIMESTRAL'!F22 -> UNIDAD | J24: ='SAF 011 - NECESIDAD TRIMESTRAL'!AX22 -> 4500 | K24: ='SAF 011 - NECESIDAD TRIMESTRAL'!AU22 -> 25 | O24: =+K24*J24 -> 112500
A25: 14 | B25: ='SAF 011 - NECESIDAD TRIMESTRAL'!B23 -> 4.3.3-7819.1 | C25: ='SAF 011 - NECESIDAD TRIMESTRAL'!E23 -> PEDIOMETROS; RANGO: 0 A 1 M, RESOLUCION: 0,5 Cm, MATERIAL: ALUMINIO Y PLASTICO | H25: SI | I25: ='SAF 011 - NECESIDAD TRIMESTRAL'!F23 -> UNIDAD | J25: ='SAF 011 - NECESIDAD TRIMESTRAL'!AX23 -> 12300 | K25: ='SAF 011 - NECESIDAD TRIMESTRAL'!AU23 -> 7 | O25: =+K25*J25 -> 86100
A26: 15 | B26: ='SAF 011 - NECESIDAD TRIMESTRAL'!B24 -> 4.3.3-4853.2 | C26: ='SAF 011 - NECESIDAD TRIMESTRAL'!E24 -> PIES DE SUEROS; RUEDAS: CON, MATERIAL: ACERO INOXIDABLE | H26: SI | I26: ='SAF 011 - NECESIDAD TRIMESTRAL'!F24 -> UNIDAD | J26: ='SAF 011 - NECESIDAD TRIMESTRAL'!AX24 -> 6500 | K26: ='SAF 011 - NECESIDAD TRIMESTRAL'!AU24 -> 200 | O26: =+K26*J26 -> 1300000
A27: 16 | B27: ='SAF 011 - NECESIDAD TRIMESTRAL'!B25 -> 4.3.3-130.13 | C27: ='SAF 011 - NECESIDAD TRIMESTRAL'!E25 -> TENSIOMETROS ARTERIALES; RANGO DE PRESION: +/- 3 mm hg, RANGO PULSACIONES: SIN, ALIMENTACION: SIN, TIPO: ANEROIDE | H27: SI | I27: ='SAF 011 - NECESIDAD TRIMESTRAL'!F25 -> UNIDAD | J27: ='SAF 011 - NECESIDAD TRIMESTRAL'!AX25 -> 2300 | K27: ='SAF 011 - NECESIDAD TRIMESTRAL'!AU25 -> 70 | O27: =+K27*J27 -> 161000
A28: 17 | B28: ='SAF 011 - NECESIDAD TRIMESTRAL'!B26 -> 4.3.3-130.13 | C28: ='SAF 011 - NECESIDAD TRIMESTRAL'!E26 -> TENSIOMETROS ARTERIALES; RANGO DE PRESION: +/- 3 mm hg, RANGO PULSACIONES: SIN, ALIMENTACION: SIN, TIPO: ANEROIDE | H28: SI | I28: ='SAF 011 - NECESIDAD TRIMESTRAL'!F26 -> UNIDAD | J28: ='SAF 011 - NECESIDAD TRIMESTRAL'!AX26 -> 2700 | K28: ='SAF 011 - NECESIDAD TRIMESTRAL'!AU26 -> 70 | O28: =+K28*J28 -> 189000
A29: 18 | B29: ='SAF 011 - NECESIDAD TRIMESTRAL'!B27 -> 4.3.3-130.13 | C29: ='SAF 011 - NECESIDAD TRIMESTRAL'!E27 -> TENSIOMETROS ARTERIALES; RANGO DE PRESION: +/- 3 mm hg, RANGO PULSACIONES: SIN, ALIMENTACION: SIN, TIPO: ANEROIDE | H29: SI | I29: ='SAF 011 - NECESIDAD TRIMESTRAL'!F27 -> UNIDAD | J29: ='SAF 011 - NECESIDAD TRIMESTRAL'!AX27 -> 4800 | K29: ='SAF 011 - NECESIDAD TRIMESTRAL'!AU27 -> 70 | O29: =+K29*J29 -> 336000
A30: 19 | B30: ='SAF 011 - NECESIDAD TRIMESTRAL'!B28 -> 4.3.3-3675.100 | C30: ='SAF 011 - NECESIDAD TRIMESTRAL'!E28 -> TERMOMETROS; TIPO: DIGITAL, ESCALA: GRADO CENTIGRADO, RANGO DE TEMPERATURA: -5 A 50 °C | H30: NO | I30: ='SAF 011 - NECESIDAD TRIMESTRAL'!F28 -> UNIDAD | J30: ='SAF 011 - NECESIDAD TRIMESTRAL'!AX28 -> 850 | K30: ='SAF 011 - NECESIDAD TRIMESTRAL'!AU28 -> 70 | P30: =+J30*K30 -> 59500
A31: 20 | B31: ='SAF 011 - NECESIDAD TRIMESTRAL'!B29 -> 4.3.3-4212.4 | C31: ='SAF 011 - NECESIDAD TRIMESTRAL'!E29 -> TUBOS DE OXIGENO; TIPO: CAPACIDAD 6 M3 | H31: SI | I31: ='SAF 011 - NECESIDAD TRIMESTRAL'!F29 -> UNIDAD | J31: ='SAF 011 - NECESIDAD TRIMESTRAL'!AX29 -> 32200 | K31: ='SAF 011 - NECESIDAD TRIMESTRAL'!AU29 -> 70 | O31: =+K31*J31 -> 2254000
A33: Costo total estimado: PESOS DOCE MILLONES CUATROCIENTOS SESENTA Y CINCO MIL OCHOCIENTOS CON 00/100.- | J33: =SUMPRODUCT(J12:J31,K12:K31) -> 12465800 | N33: =SUM(N12:N32) -> 2618200 | O33: =SUM(O12:O32) -> 9788100 | P33: =SUM(P12:P32) -> 59500 | Q33: =SUM(M33:P33) -> 12465800

Sheet APG
A1: EJERCICIO: | D1: 2022 | P1: AUTORIZACION PARA GASTAR
A4: JURISDICCIÓN: | G4: =NP!D3 -> 040 - MINISTERIO DE SALUD
A5: SAF: | G5: =NP!D4 -> 011 - DIRECCION PROVINCIAL DE ADMINISTRACION DEL MINISTERIO DE SALUD
A6: UNIDAD EJECUTORA: | G6: =NP!D5 -> 352 - MINISTERIO DE SALUD
A7: DEPENDENCIA SOLICITANTE: | G7: =NP!D6 -> 352 - MINISTERIO DE SALUD
A8: AUTORIZACIÓN:
A9: Señor Director de Administración o Titular del Servicio Administrativo Financiero:
A10: Autorizo la realización de los trámites correspondientes, a fin de proveer a este Organismo los bienes, servicios o ejecución de obras públicas que se detallan en Nota de Pedido N° 08/2022 , afectando la erogación resultante a los créditos presupuestarios aprobados a favor de esta Unidad Ejecutora, conforme al siguiente detalle:
A12: IMPUTACIÓN PRESUPUESTARIA
A13: CÓDIGO | O13: DENOMINACIÓN DE LA PARTIDA PRESUPUESTARIA | Q13: IMPORTE
A14: PR | B14: SB | C14: PY | D14: AC | E14: OB | F14: UG | G14: FIN | H14: FUN | I14: I | J14: P | K14: P | L14: SubP | M14: M | N14: FF
A15: 1 | D15: 1 | F15: 4901 | G15: 3 | H15: 1 | I15: 2 | J15: 9 | K15: 5 | M15: 1 | N15: 1.1 | O15: UTILES MENORES MEDICOS QUIRURGICOS Y DE LABORATORIO | Q15: =NP!N33 -> 2618200
A16: 1 | D16: 1 | F16: 4901 | G16: 3 | H16: 1 | I16: 4 | J16: 3 | K16: 3 | M16: 1 | N16: 1.1 | O16: EQUIPOS SANITARIOS Y DE LABORATORIO | Q16: =NP!O33 -> 9788100
A17: 1 | D17: 1 | F17: 4901 | G17: 3 | H17: 1 | I17: 4 | J17: 3 | K17: 9 | M17: 1 | N17: 1.1 | O17: OTROS N.E.P. | Q17: =NP!P33 -> 59500
A37: TOTAL DE PESOS: DOCE MILLONES CUATROCIENTOS SESENTA Y CINCO MIL OCHOCIENTOS CON 00/100.- | Q37: =SUM(Q15:Q36) -> 12465800
A39: JUSTIFICACIÓN:
A40: =NP!D8 -> ADQUISICION DE EQUIPOS Y UTILES MEDICOS MENORES CON DESTINO A HOSPITALES DE LA PROVINCIA
