Workbook

Sheet LIMPIEZA NT
B2: Pedido de Necesidades Trimestrales
A4: JURISDICCION: | C4: 40 - Ministerio de Salud
A5: SAF N°: | C5: 23 - Hospital Interzonal San Juan Bautista
A6: EJERCICIO: | C6: 2021
A7: TRIMESTRE: | C7: 2
A9: ID | B9: CODIGO ITEM | C9: RUBRO DE COMPRA | D9: I.P.P. | E9: DESCRIPCION | F9: UNIDAD DE MEDIDA | G9: CANTIDAD | H9: PRECIO UNITARIO ESTIMADO | I9: IMPORTE TOTAL ESTIMADO
A10: 1 | B10: 2.9.1-6951.28 | C10: ELEMENTOS DE LIMPIEZA | D10: =LEFT(B10,5) -> 2.9.1 | E10: LIMPIADORES; TIPO: LAVANDINA, PRESENTACION: ENVASE X 1 L | F10: UNIDAD | G10: 300 | H10: 76.5 | I10: =G10*H10 -> 22950
A11: 2 | B11: 2.9.1-564.23 | C11: ELEMENTOS DE LIMPIEZA | D11: =LEFT(B11,5) -> 2.9.1 | E11: BALDES DE PLASTICO; CAPACIDAD: 12 L, TIPO DE PLASTICO: POLIPROPILENO | F11: UNIDAD | G11: 50 | H11: 284 | I11: =G11*H11 -> 14200
A12: 3 | B12: 2.9.1-6950.8 | C12: ELEMENTOS DE LIMPIEZA | D12: =LEFT(B12,5) -> 2.9.1 | E12: LUSTRADORES; TIPO: CERA DE LUSTRAR LIQUIDA, PRESENTACION: ENVASE X 5 L | F12: UNIDAD | G12: 50 | H12: 740 | I12: =G12*H12 -> 37000
A13: 4 | B13: 2.9.1-6951.185 | C13: ELEMENTOS DE LIMPIEZA | D13: =LEFT(B13,5) -> 2.9.1 | E13: LIMPIADORES; TIPO: HIPOCLORITO, PRESENTACION: ENVASE X 5 L | F13: UNIDAD | G13: 200 | H13: 330 | I13: =G13*H13 -> 66000
A14: 5 | B14: 2.9.1-6951.290 | C14: ELEMENTOS DE LIMPIEZA | D14: =LEFT(B14,5) -> 2.9.1 | E14: LIMPIADORES; TIPO: DETERGENTE ENZIMATICO, PRESENTACION: ENVASE X 5 L, BIODEGRADABLE: SI | F14: UNIDAD | G14: 60 | H14: 435 | I14: =G14*H14 -> 26100
A15: 6 | B15: 2.9.1-6951.157 | C15: ELEMENTOS DE LIMPIEZA | D15: =LEFT(B15,5) -> 2.9.1 | E15: LIMPIADORES; TIPO: DESODORANTE LIQUIDO , PRESENTACION: BIDON X 5 L | F15: UNIDAD | G15: 720 | H15: 210 | I15: =G15*H15 -> 151200
A16: 7 | B16: 2.9.1-544.82 | C16: ELEMENTOS DE LIMPIEZA | D16: =LEFT(B16,5) -> 2.9.1 | E16: DESODORANTES DE AMBIENTE; FORMATO: AEROSOL, FRAGANCIA: ORIGINAL, PRESENTACION: ENVASE X 360 CM3, LIBRE DE CFC: SI | F16: UNIDAD | G16: 120 | H16: 150 | I16: =G16*H16 -> 18000
A17: 8 | B17: 2.5.4-505.13 | C17: ELEMENTOS DE LIMPIEZA | D17: =LEFT(B17,5) -> 2.5.4 | E17: DESINFECTANTES; CAPACIDAD: 5 L, USO P/CONTROL: BACTERIAS, PRINCIPIO ACTIVO: SAL AMONIO CUATERNARIO, PRESENTACION: ENVASE X 5 L, CONTROL: BACTERIAS | F17: UNIDAD | G17: 70 | H17: 1100 | I17: =G17*H17 -> 77000
A18: 9 | B18: 2.9.1-4784.54 | C18: ELEMENTOS DE LIMPIEZA | D18: =LEFT(B18,5) -> 2.9.1 | E18: LIMPIADORES MULTIUSO; COMPUESTOS BIODEGRADABLES: SI, PRESENTACION: ENVASE X 5 L, TIPO: SECUESTRANTE D/POLVO P/LAMPAZO | F18: UNIDAD | G18: 15 | H18: 1995 | I18: =G18*H18 -> 29925
A19: 10 | B19: 2.9.1-6960.20 | C19: ELEMENTOS DE LIMPIEZA | D19: =LEFT(B19,5) -> 2.9.1 | E19: ELEM. LIMPIEZA P/INDUMENTARIA; TIPO: JABON EN POLVO, PRESENTACION: ENVASE X 3 Kg | F19: UNIDAD | G19: 200 | H19: 435 | I19: =G19*H19 -> 87000
A20: 11 | B20: 2.9.1-761.7 | C20: ELEMENTOS DE LIMPIEZA | D20: =LEFT(B20,5) -> 2.9.1 | E20: GUANTES P/LIMPIEZA; MATERIAL: LATEX C/FELPA INTERIOR, TAMAÑO: CHICO | F20: PAR | G20: 180 | H20: 175 | I20: =G20*H20 -> 31500
A21: 12 | B21: 2.9.1-761.6 | C21: ELEMENTOS DE LIMPIEZA | D21: =LEFT(B21,5) -> 2.9.1 | E21: GUANTES P/LIMPIEZA; TAMAÑO: MEDIANO, MATERIAL: LATEX C/FELPA INTERIOR | F21: PAR | G21: 150 | H21: 175 | I21: =G21*H21 -> 26250
... A52: 43 | B52: 2.9.5-4558.7 | C52: PROD. MEDICO/FARMACEUTICOS/LAB | D52: =LEFT(B52,5) -> 2.9.5 | E52: BOLSAS DE RESIDUOS PATOLOGICOS; COLOR: ROJO, MEDIDA: 50 X 70 Cm, ESPESOR: 120 Mn, TIPO: PARA INCINERACION | F52: UNIDAD | G52: 4500 | H52: 7.17 | I52: =G52*H52 -> 32265
B55: Plazo de Entrega: 10 dias - Lugar de Entrega: Servicio de Deposito Central - Av. Illia Esq. Mariano Moreno
B56: Mantenimiento de Oferta: 30 dias hábiles.
B59: Especificidades Item N° 1:
B61: Descripción técnica
C62: AGUA LAVANDINA CONCENTRADA X 55 GRS. DE CLORO ACTIVO EN ENVASE DE 1 LITRO, ETIQUETADO. TIPO: X5.-
B63: Plazos y lugares de entrega
B66: Calidad Minima esperada
B68: Mantenimiento
B70: Garantia
B74: Especificidades Item N° 3:
B76: Descripción técnica
C77: CERA PARA PISOS COLOR ROJO, ENVASE DE 5 LITROS, ETIQUETADO.-
B78: Plazos y lugares de entrega
B81: Calidad Minima esperada
B83: Mantenimiento
B85: Garantia
B89: Especificidades Item N° 4:
B91: Descripción técnica
C92: HIPOCLORITO DE SODIO 100 GRS. DE CLORO ACTIVO X LITRO EN ENVASE DE 5 LITROS ETIQUETADO, PRIMERA MARCA.-
B93: Plazos y lugares de entrega
B96: Calidad Minima esperada
...

Sheet LIMPIEZA NPYE
A1: NOTA DE PEDIDO | J1: N° | K1: 009/2021
A3: JURISDICCIÓN: | D3: ='LIMPIEZA NT'!C4 -> 40 - Ministerio de Salud
A4: SAF: | D4: ='LIMPIEZA NT'!C5 -> 23 - Hospital Interzonal San Juan Bautista
A5: UNIDAD EJECUTORA: | D5: 237 - Direccion de Mantenimiento / 168 - Direccion Asistencial
A6: DEPENDENCIA SOLICITANTE: | D6: Servicio de Depósito Central y Servicio Control de Infecciones
A7: PERIODO UTILIZACIÓN: | D7: ='LIMPIEZA NT'!C7 & "° Trimestre - Año " & 'LIMPIEZA NT'!C6 -> 2° Trimestre - Año 2021
A8: OBJETO: | D8: Adquisición de Elementos de Limpieza
A10: Ítem | B10: Codigo Item | C10: DESCRIPCIÓN | H10: Adjunta Detalle Técnico | I10: Unidad Medida | J10: Precio Unitario Estimado | K10: Cantidad Solicitada
A12: 1 | B12: ='LIMPIEZA NT'!B10 -> 2.9.1-6951.28 | C12: ='LIMPIEZA NT'!E10 -> LIMPIADORES; TIPO: LAVANDINA, PRESENTACION: ENVASE X 1 L | H12: NO | I12: ='LIMPIEZA NT'!F10 -> UNIDAD | J12: ='LIMPIEZA NT'!H10 -> 76.5 | K12: ='LIMPIEZA NT'!G10 -> 300
A13: 2 | B13: ='LIMPIEZA NT'!B11 -> 2.9.1-564.23 | C13: ='LIMPIEZA NT'!E11 -> BALDES DE PLASTICO; CAPACIDAD: 12 L, TIPO DE PLASTICO: POLIPROPILENO | H13: NO | I13: ='LIMPIEZA NT'!F11 -> UNIDAD | J13: ='LIMPIEZA NT'!H11 -> 284 | K13: ='LIMPIEZA NT'!G11 -> 50
A14: 3 | B14: ='LIMPIEZA NT'!B12 -> 2.9.1-6950.8 | C14: ='LIMPIEZA NT'!E12 -> LUSTRADORES; TIPO: CERA DE LUSTRAR LIQUIDA, PRESENTACION: ENVASE X 5 L | H14: NO | I14: ='LIMPIEZA NT'!F12 -> UNIDAD | J14: ='LIMPIEZA NT'!H12 -> 740 | K14: ='LIMPIEZA NT'!G12 -> 50
A15: 4 | B15: ='LIMPIEZA NT'!B13 -> 2.9.1-6951.185 | C15: ='LIMPIEZA NT'!E13 -> LIMPIADORES; TIPO: HIPOCLORITO, PRESENTACION: ENVASE X 5 L | H15: NO | I15: ='LIMPIEZA NT'!F13 -> UNIDAD | J15: ='LIMPIEZA NT'!H13 -> 330 | K15: ='LIMPIEZA NT'!G13 -> 200
A16: 5 | B16: ='LIMPIEZA NT'!B14 -> 2.9.1-6951.290 | C16: ='LIMPIEZA NT'!E14 -> LIMPIADORES; TIPO: DETERGENTE ENZIMATICO, PRESENTACION: ENVASE X 5 L, BIODEGRADABLE: SI | H16: NO | I16: ='LIMPIEZA NT'!F14 -> UNIDAD | J16: ='LIMPIEZA NT'!H14 -> 435 | K16: ='LIMPIEZA NT'!G14 -> 60
A17: 6 | B17: ='LIMPIEZA NT'!B15 -> 2.9.1-6951.157 | C17: ='LIMPIEZA NT'!E15 -> LIMPIADORES; TIPO: DESODORANTE LIQUIDO , PRESENTACION: BIDON X 5 L | H17: NO | I17: ='LIMPIEZA NT'!F15 -> UNIDAD | J17: ='LIMPIEZA NT'!H15 -> 210 | K17: ='LIMPIEZA NT'!G15 -> 720
A18: 7 | B18: ='LIMPIEZA NT'!B16 -> 2.9.1-544.82 | C18: ='LIMPIEZA NT'!E16 -> DESODORANTES DE AMBIENTE; FORMATO: AEROSOL, FRAGANCIA: ORIGINAL, PRESENTACION: ENVASE X 360 CM3, LIBRE DE CFC: SI | H18: NO | I18: ='LIMPIEZA NT'!F16 -> UNIDAD | J18: ='LIMPIEZA NT'!H16 -> 150 | K18: ='LIMPIEZA NT'!G16 -> 120
A19: 8 | B19: ='LIMPIEZA NT'!B17 -> 2.5.4-505.13 | C19: ='LIMPIEZA NT'!E17 -> DESINFECTANTES; CAPACIDAD: 5 L, USO P/CONTROL: BACTERIAS, PRINCIPIO ACTIVO: SAL AMONIO CUATERNARIO, PRESENTACION: ENVASE X 5 L, CONTROL: BACTERIAS | H19: NO | I19: ='LIMPIEZA NT'!F17 -> UNIDAD | J19: ='LIMPIEZA NT'!H17 -> 1100 | K19: ='LIMPIEZA NT'!G17 -> 70
A20: 9 | B20: ='LIMPIEZA NT'!B18 -> 2.9.1-4784.54 | C20: ='LIMPIEZA NT'!E18 -> LIMPIADORES MULTIUSO; COMPUESTOS BIODEGRADABLES: SI, PRESENTACION: ENVASE X 5 L, TIPO: SECUESTRANTE D/POLVO P/LAMPAZO | H20: NO | I20: ='LIMPIEZA NT'!F18 -> UNIDAD | J20: ='LIMPIEZA NT'!H18 -> 1995 | K20: ='LIMPIEZA NT'!G18 -> 15
A21: 10 | B21: ='LIMPIEZA NT'!B19 -> 2.9.1-6960.20 | C21: ='LIMPIEZA NT'!E19 -> ELEM. LIMPIEZA P/INDUMENTARIA; TIPO: JABON EN POLVO, PRESENTACION: ENVASE X 3 Kg | H21: NO | I21: ='LIMPIEZA NT'!F19 -> UNIDAD | J21: ='LIMPIEZA NT'!H19 -> 435 | K21: ='LIMPIEZA NT'!G19 -> 200
A22: 11 | B22: ='LIMPIEZA NT'!B20 -> 2.9.1-761.7 | C22: ='LIMPIEZA NT'!E20 -> GUANTES P/LIMPIEZA; MATERIAL: LATEX C/FELPA INTERIOR, TAMAÑO: CHICO | H22: NO | I22: ='LIMPIEZA NT'!F20 -> PAR | J22: ='LIMPIEZA NT'!H20 -> 175 | K22: ='LIMPIEZA NT'!G20 -> 180
A23: 12 | B23: ='LIMPIEZA NT'!B21 -> 2.9.1-761.6 | C23: ='LIMPIEZA NT'!E21 -> GUANTES P/LIMPIEZA; TAMAÑO: MEDIANO, MATERIAL: LATEX C/FELPA INTERIOR | H23: NO | I23: ='LIMPIEZA NT'!F21 -> PAR | J23: ='LIMPIEZA NT'!H21 -> 175 | K23: ='LIMPIEZA NT'!G21 -> 150
... A54: 43 | B54: ='LIMPIEZA NT'!B52 -> 2.9.5-4558.7 | C54: ='LIMPIEZA NT'!E52 -> BOLSAS DE RESIDUOS PATOLOGICOS; COLOR: ROJO, MEDIDA: 50 X 70 Cm, ESPESOR: 120 Mn, TIPO: PARA INCINERACION | H54: NO | I54: ='LIMPIEZA NT'!F52 -> UNIDAD | J54: ='LIMPIEZA NT'!H52 -> 7.17 | K54: ='LIMPIEZA NT'!G52 -> 4500
A55: Costo total estimado: un millon novecientos sesenta y ocho mil setecientos ochenta y nueve con 55/100.----------------- | J55: =SUMPRODUCT(J12:J54,K12:K54) -> 1968789.5

Sheet LIMPIEZA APG
A1: EJERCICIO: | D1: ='LIMPIEZA NT'!C6 -> 2021 | P1: AUTORIZACION PARA GASTAR
A4: JURISDICCIÓN: | G4: ='LIMPIEZA NPYE'!D3 -> 40 - Ministerio de Salud
A5: SAF: | G5: ='LIMPIEZA NPYE'!D4 -> 23 - Hospital Interzonal San Juan Bautista
A6: UNIDAD EJECUTORA: | G6: ='LIMPIEZA NPYE'!D5 -> 237 - Direccion de Mantenimiento / 168 - Direccion Asistencial
A7: DEPENDENCIA SOLICITANTE: | G7: ='LIMPIEZA NPYE'!D6 -> Servicio de Depósito Central y Servicio Control de Infecciones
A8: AUTORIZACIÓN:
A9: Señor Jefe de Servicio Administrativo Financiero:
A10: ="Autorizo la realización de los trámites correspondientes, a fin de proveer a este Organismo los bienes y/o servicios que se detallan en Nota de Pedido N° " & 'LIMPIEZA NPYE'!K1&", afectando la erogación resultante a los créditos presupuestarios aprobados a favor de esta Unidad Ejecutora, conforme al siguiente detalle:" -> Autorizo la realización de los trámites correspondientes, a fin de proveer a este Organismo los bienes y/o servicios que se detallan en Nota de Pedido N° 009/2021, afectando la erogación resultante a los créditos presupuestarios aprobados a favor de esta Unidad Ejecutora, conforme al siguiente detalle:
A12: IMPUTACIÓN PRESUPUESTARIA
A13: CÓDIGO | O13: DENOMINACIÓN DE LA PARTIDA PRESUPUESTARIA | Q13: IMPORTE
A14: PR | B14: SB | C14: PY | D14: AC | E14: OB | F14: UG | G14: FIN | H14: FUN | I14: I | J14: P | K14: P | L14: SubP | M14: M | N14: FF
A15: 33 | D15: 4 | F15: 4901 | G15: 3 | H15: 3.1 | I15: 2 | J15: 1 | K15: 5 | M15: 1 | N15: 1.1 | O15: Madera, corcho y sus manufact. | Q15: 7560
A16: 33 | D16: 4 | F16: 4901 | G16: 3 | H16: 3.1 | I16: 2 | J16: 3 | K16: 4 | M16: 1 | N16: 1.1 | O16: Productos de Papel y Cartón | Q16: 431700
A17: 33 | D17: 4 | F17: 4901 | G17: 3 | H17: 3.1 | I17: 2 | J17: 5 | K17: 4 | M17: 1 | N17: 1.1 | O17: Insecticidas, Fumigantes y Otros | Q17: 77000
A18: 33 | D18: 4 | F18: 4901 | G18: 3 | H18: 3.1 | I18: 2 | J18: 5 | K18: 8 | M18: 1 | N18: 1.1 | O18: Productos de Material Plástico | Q18: 353737.05
A19: 33 | D19: 4 | F19: 4901 | G19: 3 | H19: 3.1 | I19: 2 | J19: 7 | K19: 5 | M19: 1 | N19: 1.1 | O19: Herramientas Menores | Q19: 39000
A20: 33 | D20: 4 | F20: 4901 | G20: 3 | H20: 3.1 | I20: 2 | J20: 9 | K20: 1 | M20: 1 | N20: 1.1 | O20: Elementos de Limpieza | Q20: 1027527.5
A21: 33 | D21: 2 | F21: 4901 | G21: 3 | H21: 3.1 | I21: 2 | J21: 9 | K21: 5 | M21: 1 | N21: 1.1 | O21: Utiles Menores Medicos, Quirurgicos y de Laboratorio | Q21: 32265
A25: TOTAL DE PESOS: UN MILLON NOVECIENTOS SESENTA Y OCHO MIL SETECIENTOS OCHENTA Y NUEVE CON 55/100.- | Q25: =+SUM(Q15:Q24) -> 1968789.6
A27: JUSTIFICACIÓN:
A28: ="Para la "& 'LIMPIEZA NPYE'!D8 &" para ser destinados al " & 'LIMPIEZA NPYE'!D6 &" del HISJB del Ministerio de Salud." -> Para la Adquisición de Elementos de Limpieza para ser destinados al Servicio de Depósito Central y Servicio Control de Infecciones del HISJB del Ministerio de Salud.
