Workbook

Sheet Necesidades Trimestrales
B2: Pedido de Necesidades Trimestrales
A4: JURISDICCION: | C4: 040 - Ministerio de Salud
A5: SAF N°: | C5: 011 - Direccion Provincial de Administracion del Ministerio de Salud
A6: EJERCICIO: | C6: 2022
A7: TRIMESTRE: | C7: 2
A9: ID | B9: CODIGO ITEM | C9: RUBRO DE COMPRA | D9: I.P.P. | E9: DESCRIPCION | F9: UNIDAD DE MEDIDA | G9: FARMACIA | H9: TOTAL FARMACIA | I9: SAME | J9: TOTAL SAME | K9: D.P.M.I.A | L9: TOTAL D.P.M.I.A | M9: CANTIDAD | N9: PRECIO UNITARIO ESTIMADO | O9: IMPORTE TOTAL ESTIMADO
A10: 1 | C10: PROD. MEDICO/FARMACEUTICOS/LAB | D10: 295 | E10: AEROCAMARA C/ FUELLE ADULTO | F10: UNIDAD | G10: 500 | H10: =+G10*N10 -> 245000 | I10: 5 | J10: =+I10*N10 -> 2450 | L10: =+K10*N10 -> 0 | M10: =+G10+I10+K10 -> 505 | N10: 490 | O10: =+M10*N10 -> 247450
A11: 2 | C11: PROD. MEDICO/FARMACEUTICOS/LAB | D11: 295 | E11: AEROCAMARA CON MASCARA COMPLETA PEDIATRICA | F11: UNIDAD | G11: 1000 | H11: =+G11*N11 -> 490000 | I11: 5 | J11: =+I11*N11 -> 2450 | L11: =+K11*N11 -> 0 | M11: =+G11+I11+K11 -> 1005 | N11: 490 | O11: =+M11*N11 -> 492450
A12: 3 | C12: PROD. MEDICO/FARMACEUTICOS/LAB | D12: 295 | E12: BOLSA DE ASPIRACION X 1 LTS SIN VALVULA TIPO ECOVAC | F12: UNIDAD | G12: 50 | H12: =+G12*N12 -> 14000 | J12: =+I12*N12 -> 0 | L12: =+K12*N12 -> 0 | M12: =+G12+I12+K12 -> 50 | N12: 280 | O12: =+M12*N12 -> 14000
A13: 4 | C13: PROD. MEDICO/FARMACEUTICOS/LAB | D13: 295 | E13: CANULA NASAL DE ALTO FLUJO TIPO OPTIFLOW INFANTIL F&P OPT 316 | F13: UNIDAD | H13: =+G13*N13 -> 0 | I13: 5 | J13: =+I13*N13 -> 62500 | L13: =+K13*N13 -> 0 | M13: =+G13+I13+K13 -> 5 | N13: 12500 | O13: =+M13*N13 -> 62500
A14: 5 | C14: PROD. MEDICO/FARMACEUTICOS/LAB | D14: 295 | E14: CANULA NASAL DE ALTO FLUJO TIPO OPTIFLOW PEDIATRICA F&P OPT 318 | F14: UNIDAD | H14: =+G14*N14 -> 0 | I14: 5 | J14: =+I14*N14 -> 62500 | L14: =+K14*N14 -> 0 | M14: =+G14+I14+K14 -> 5 | N14: 12500 | O14: =+M14*N14 -> 62500
A15: 6 | C15: PROD. MEDICO/FARMACEUTICOS/LAB | D15: 295 | E15: CANULA NASAL PARA ALTO FLUJO TIPO GGM ADULTO 6 mm 4826R1V TAMANO L | F15: UNIDAD | H15: =+G15*N15 -> 0 | I15: 10 | J15: =+I15*N15 -> 76000 | L15: =+K15*N15 -> 0 | M15: =+G15+I15+K15 -> 10 | N15: 7600 | O15: =+M15*N15 -> 76000
A16: 7 | C16: PROD. MEDICO/FARMACEUTICOS/LAB | D16: 295 | E16: CANULA NASAL PARA OXIGENOTERAPIA PEDIATRICO | F16: UNIDAD | G16: 300 | H16: =+G16*N16 -> 37200 | J16: =+I16*N16 -> 0 | L16: =+K16*N16 -> 0 | M16: =+G16+I16+K16 -> 300 | N16: 124 | O16: =+M16*N16 -> 37200
A17: 8 | C17: PROD. MEDICO/FARMACEUTICOS/LAB | D17: 295 | E17: CIRCUITO ANESTESIA EXTENSIBLE ADULTO DESCARTABLE | F17: UNIDAD | H17: =+G17*N17 -> 0 | I17: 8 | J17: =+I17*N17 -> 7840 | L17: =+K17*N17 -> 0 | M17: =+G17+I17+K17 -> 8 | N17: 980 | O17: =+M17*N17 -> 7840
A18: 9 | C18: PROD. MEDICO/FARMACEUTICOS/LAB | D18: 295 | E18: FRASCO RECOLECTOR DE ASPIRACIONES QUIRURGICAS X 2 LITRO ( CANISTER ) | F18: UNIDAD | G18: 50 | H18: =+G18*N18 -> 210000 | J18: =+I18*N18 -> 0 | L18: =+K18*N18 -> 0 | M18: =+G18+I18+K18 -> 50 | N18: 4200 | O18: =+M18*N18 -> 210000
A19: 10 | C19: PROD. MEDICO/FARMACEUTICOS/LAB | D19: 295 | E19: HALO CEFALICO tipo <MEDIX> con tapa - MEDIANO : 200 mm de diametro x 180 mm de altura | F19: UNIDAD | H19: =+G19*N19 -> 0 | I19: 2 | J19: =+I19*N19 -> 35360 | L19: =+K19*N19 -> 0 | M19: =+G19+I19+K19 -> 2 | N19: 17680 | O19: =+M19*N19 -> 35360
A20: 11 | C20: PROD. MEDICO/FARMACEUTICOS/LAB | D20: 295 | E20: HALO CEFALICO tipo <MEDIX> con tapa GRANDE: 230 mm de diametro x 200 mm de altura | F20: UNIDAD | H20: =+G20*N20 -> 0 | I20: 2 | J20: =+I20*N20 -> 40690 | L20: =+K20*N20 -> 0 | M20: =+G20+I20+K20 -> 2 | N20: 20345 | O20: =+M20*N20 -> 40690
A21: 12 | C21: PROD. MEDICO/FARMACEUTICOS/LAB | D21: 295 | E21: MASCARA AMBU BORDE INFLABLE Nª1 / MASCARA ANESTESIA(INFANTIL) | F21: UNIDAD | G21: 50 | H21: =+G21*N21 -> 12600 | J21: =+I21*N21 -> 0 | L21: =+K21*N21 -> 0 | M21: =+G21+I21+K21 -> 50 | N21: 252 | O21: =+M21*N21 -> 12600
A22: 13 | C22: PROD. MEDICO/FARMACEUTICOS/LAB | D22: 295 | E22: MASCARA AMBU BORDE INFLABLE Nª3 /MASCARA ANESTESIA(INFANTIL) | F22: UNIDAD | G22: 50 | H22: =+G22*N22 -> 12600 | J22: =+I22*N22 -> 0 | L22: =+K22*N22 -> 0 | M22: =+G22+I22+K22 -> 50 | N22: 252 | O22: =+M22*N22 -> 12600
A23: 14 | C23: PROD. MEDICO/FARMACEUTICOS/LAB | D23: 295 | E23: MASCARA AMBU BORDE INFLABLE Nª4 /MASCARA ANESTESIA(INFANTIL) | F23: UNIDAD | G23: 50 | H23: =+G23*N23 -> 12600 | J23: =+I23*N23 -> 0 | L23: =+K23*N23 -> 0 | M23: =+G23+I23+K23 -> 50 | N23: 252 | O23: =+M23*N23 -> 12600
A24: 15 | C24: PROD. MEDICO/FARMACEUTICOS/LAB | D24: 295 | E24: MASCARA CON BOLSA RESERVORIO ADULTO | F24: UNIDAD | G24: 1500 | H24: =+G24*N24 -> 570000 | I24: 8 | J24: =+I24*N24 -> 3040 | L24: =+K24*N24 -> 0 | M24: =+G24+I24+K24 -> 1508 | N24: 380 | O24: =+M24*N24 -> 573040
A25: 16 | C25: PROD. MEDICO/FARMACEUTICOS/LAB | D25: 295 | E25: MASCARA CON BOLSA RESERVORIO PEDIATRICA | F25: UNIDAD | G25: 200 | H25: =+G25*N25 -> 76000 | I25: 5 | J25: =+I25*N25 -> 1900 | L25: =+K25*N25 -> 0 | M25: =+G25+I25+K25 -> 205 | N25: 380 | O25: =+M25*N25 -> 77900
A26: 17 | C26: PROD. MEDICO/FARMACEUTICOS/LAB | D26: 295 | E26: MASCARA DE OXIGENO CON REGULADORES | F26: UNIDAD | G26: 500 | H26: =+G26*N26 -> 180000 | J26: =+I26*N26 -> 0 | L26: =+K26*N26 -> 0 | M26: =+G26+I26+K26 -> 500 | N26: 360 | O26: =+M26*N26 -> 180000
A27: 18 | C27: PROD. MEDICO/FARMACEUTICOS/LAB | D27: 295 | E27: MASCARA PARA NEBULIZAR ADULTO COMPLETA MASCARA+PIPETA+TUBULADURA | F27: UNIDAD | G27: 500 | H27: =+G27*N27 -> 135000 | I27: 10 | J27: =+I27*N27 -> 2700 | L27: =+K27*N27 -> 0 | M27: =+G27+I27+K27 -> 510 | N27: 270 | O27: =+M27*N27 -> 137700
A28: 19 | C28: PROD. MEDICO/FARMACEUTICOS/LAB | D28: 295 | E28: MASCARA PARA NEBULIZAR PEDIATRICA COMPLETA MASCARA+PIPETA+TUBULADURA | F28: UNIDAD | H28: =+G28*N28 -> 0 | I28: 10 | J28: =+I28*N28 -> 2700 | L28: =+K28*N28 -> 0 | M28: =+G28+I28+K28 -> 10 | N28: 270 | O28: =+M28*N28 -> 2700
A29: 20 | C29: PROD. MEDICO/FARMACEUTICOS/LAB | D29: 295 | E29: MASCARAS ANESTESICA BORDE INFLABLE ADULTO Nº 5 | F29: UNIDAD | G29: 150 | H29: =+G29*N29 -> 48000 | J29: =+I29*N29 -> 0 | L29: =+K29*N29 -> 0 | M29: =+G29+I29+K29 -> 150 | N29: 320 | O29: =+M29*N29 -> 48000
A30: 21 | C30: PROD. MEDICO/FARMACEUTICOS/LAB | D30: 295 | E30: MASCARAS ANESTESICA BORDE INFLABLE ADULTO Nº 6 | F30: UNIDAD | G30: 150 | H30: =+G30*N30 -> 48000 | J30: =+I30*N30 -> 0 | L30: =+K30*N30 -> 0 | M30: =+G30+I30+K30 -> 150 | N30: 320 | O30: =+M30*N30 -> 48000
A31: 22 | C31: PROD. MEDICO/FARMACEUTICOS/LAB | D31: 295 | E31: RESUCITADOR MANUAL ADULTO DESCARTABLE | F31: UNIDAD | H31: =+G31*N31 -> 0 | I31: 5 | J31: =+I31*N31 -> 11500 | L31: =+K31*N31 -> 0 | M31: =+G31+I31+K31 -> 5 | N31: 2300 | O31: =+M31*N31 -> 11500
A32: 23 | C32: PROD. MEDICO/FARMACEUTICOS/LAB | D32: 295 | E32: RESUCITADOR MANUAL ADULTO REUTILIZABLE | F32: UNIDAD | G32: 20 | H32: =+G32*N32 -> 164000 | I32: 5 | J32: =+I32*N32 -> 41000 | K32: 10 | L32: =+K32*N32 -> 82000 | M32: =+G32+I32+K32 -> 35 | N32: 8200 | O32: =+M32*N32 -> 287000
A33: 24 | C33: PROD. MEDICO/FARMACEUTICOS/LAB | D33: 295 | E33: RESUCITADOR MANUAL NEONATAL REUTILIZABLE | F33: UNIDAD | H33: =+G33*N33 -> 0 | I33: 2 | J33: =+I33*N33 -> 16400 | K33: 20 | L33: =+K33*N33 -> 164000 | M33: =+G33+I33+K33 -> 22 | N33: 8200 | O33: =+M33*N33 -> 180400
A34: 25 | C34: PROD. MEDICO/FARMACEUTICOS/LAB | D34: 295 | E34: RESUCITADOR MANUAL PEDIATRICO REUTILIZABLE | F34: UNIDAD | G34: 20 | H34: =+G34*N34 -> 164000 | J34: =+I34*N34 -> 0 | K34: 20 | L34: =+K34*N34 -> 164000 | M34: =+G34+I34+K34 -> 40 | N34: 8200 | O34: =+M34*N34 -> 328000
A35: 26 | C35: PROD. MEDICO/FARMACEUTICOS/LAB | D35: 295 | E35: VARA ESCHMANN N° 6 mm | F35: UNIDAD | G35: 10 | H35: =+G35*N35 -> 79000 | J35: =+I35*N35 -> 0 | L35: =+K35*N35 -> 0 | M35: =+G35+I35+K35 -> 10 | N35: 7900 | O35: =+M35*N35 -> 79000
A36: 27 | C36: PROD. MEDICO/FARMACEUTICOS/LAB | D36: 295 | E36: VARA ESCHMANN N° 9 mm | F36: UNIDAD | G36: 10 | H36: =+G36*N36 -> 79000 | J36: =+I36*N36 -> 0 | L36: =+K36*N36 -> 0 | M36: =+G36+I36+K36 -> 10 | N36: 7900 | O36: =+M36*N36 -> 79000
A37: 28 | C37: PROD. MEDICO/FARMACEUTICOS/LAB | D37: 295 | E37: VARA ESCHMANN N°11 mm | F37: UNIDAD | G37: 10 | H37: =+G37*N37 -> 79000 | J37: =+I37*N37 -> 0 | L37: =+K37*N37 -> 0 | M37: =+G37+I37+K37 -> 10 | N37: 7900 | O37: =+M37*N37 -> 79000
A38: TOTAL RUBRO | H38: =SUM(H10:H37) -> 2656000 | J38: =SUM(J10:J34) -> 369030 | L38: =SUM(L10:L34) -> 410000 | O38: =SUM(O10:O37) -> 3435030
C41: DETALLE TECNICO Y ESPECIFICACIONES | D41: ANEXO 1-Para oferentes de la Provincia de Catamarca deberán presentar Habilitación Provincial para comercializar el producto que cotizan. 2-Para el resto de oferentes deberán presentar Certificado de Inscripción de ANMAT vigente al momento de la oferta, el mismo deberá ser correspondiente al objeto de la contratación y de encontrarse vencido adjuntar la solicitud de renovación. 3-No se aceptarán ofertas de productos no registrados y autorizada su venta por ANMAT. Se deberá especificar en cada ítem de la propuesta, marca y número de certificado otorgado por dicho ente regulador. 4-Los productos deberán tener un vencimiento posterior a doce (12) meses a partir de la fecha de su recepción.
C43: Plazos de entrega | D43: veinte (20) dias habiles
C45: Lugar de Entrega: | D45: ITEMS: 1 (500 unid), 2 (1000 unid), 3, 7, 9, 12 al 14, 15 (1500 unid), 16 (200 unid), 17, 18 (500 unid), 20, 21, 23 (20 unid), 25 (20 unid), 26, 27, 28 - DIR. PROV. DE FARMACIA E INSUMOS- CHACABUCO N° 169 - en el horario de 8:00hs a 12:00hs de lunes a viernes
D46: ITEMS: 23 (10 unid), 24 (20 unid), 25 (20 unid)- DIR. PROV. MATERNIDAD, INFANCIA Y ADOLESCENCIA - CHACABUCO N° 169 - en el horario de 8:00hs a 12:00hs de lunes a viernes
D47: ITEMS: 1 (5 unid), 2 (5 unid), 4 al 6, 8, 10, 11, 15 (8 unid), 16 (5 unid), 18 (10 unid), 19, 22, 23 (5 unid), 24 (2 unid) - DIR. PROV. SAME - CASEROS N° 864 - en el horario de 8:00hs a 12:00hs de lunes a viernes
...

Sheet NP FARMACIA
A1: NOTA DE PEDIDO | J1: N° | K1: 19/2022
A3: JURISDICCIÓN: | D3: ='Necesidades Trimestrales'!C4 -> 040 - Ministerio de Salud
A4: SAF: | D4: ='Necesidades Trimestrales'!C5 -> 011 - Direccion Provincial de Administracion del Ministerio de Salud
A5: UNIDAD EJECUTORA: | D5: 469 - DIRECCION PROVINCIAL DE FARMACIA E INSUMOS
A6: DEPENDENCIA SOLICITANTE: | D6: 469 - DIRECCION PROVINCIAL DE FARMACIA E INSUMOS
A7: PERIODO UTILIZACIÓN: | D7: SEMESTRAL
A8: OBJETO: | D8: ADQUISICION DE INSUMOS PARA TERAPIA RESPIRATORIA
A10: Ítem | B10: Codigo Item | C10: DESCRIPCIÓN | H10: Adjunta Detalle Técnico | I10: Unidad Medida | J10: Precio Unitario Estimado | K10: Cantidad Solicitada
A12: 1 | C12: =+'Necesidades Trimestrales'!E10 -> AEROCAMARA C/ FUELLE ADULTO | H12: NO | I12: =+'Necesidades Trimestrales'!F10 -> UNIDAD | J12: =+'Necesidades Trimestrales'!N10 -> 490 | K12: ='Necesidades Trimestrales'!G10 -> 500
A13: 2 | C13: =+'Necesidades Trimestrales'!E11 -> AEROCAMARA CON MASCARA COMPLETA PEDIATRICA | H13: NO | I13: =+'Necesidades Trimestrales'!F11 -> UNIDAD | J13: =+'Necesidades Trimestrales'!N11 -> 490 | K13: ='Necesidades Trimestrales'!G11 -> 1000
A14: 3 | C14: =+'Necesidades Trimestrales'!E12 -> BOLSA DE ASPIRACION X 1 LTS SIN VALVULA TIPO ECOVAC | H14: NO | I14: =+'Necesidades Trimestrales'!F12 -> UNIDAD | J14: =+'Necesidades Trimestrales'!N12 -> 280 | K14: ='Necesidades Trimestrales'!G12 -> 50
A15: 4 | C15: =+'Necesidades Trimestrales'!E16 -> CANULA NASAL PARA OXIGENOTERAPIA PEDIATRICO | H15: NO | I15: =+'Necesidades Trimestrales'!F16 -> UNIDAD | J15: =+'Necesidades Trimestrales'!N16 -> 124 | K15: ='Necesidades Trimestrales'!G16 -> 300
A16: 5 | C16: =+'Necesidades Trimestrales'!E18 -> FRASCO RECOLECTOR DE ASPIRACIONES QUIRURGICAS X 2 LITRO ( CANISTER ) | H16: NO | I16: =+'Necesidades Trimestrales'!F18 -> UNIDAD | J16: =+'Necesidades Trimestrales'!N18 -> 4200 | K16: ='Necesidades Trimestrales'!G18 -> 50
A17: 6 | C17: =+'Necesidades Trimestrales'!E21 -> MASCARA AMBU BORDE INFLABLE Nª1 / MASCARA ANESTESIA(INFANTIL) | H17: NO | I17: =+'Necesidades Trimestrales'!F21 -> UNIDAD | J17: =+'Necesidades Trimestrales'!N21 -> 252 | K17: ='Necesidades Trimestrales'!G21 -> 50
A18: 7 | C18: =+'Necesidades Trimestrales'!E22 -> MASCARA AMBU BORDE INFLABLE Nª3 /MASCARA ANESTESIA(INFANTIL) | H18: NO | I18: =+'Necesidades Trimestrales'!F22 -> UNIDAD | J18: =+'Necesidades Trimestrales'!N22 -> 252 | K18: ='Necesidades Trimestrales'!G22 -> 50
A19: 8 | C19: =+'Necesidades Trimestrales'!E23 -> MASCARA AMBU BORDE INFLABLE Nª4 /MASCARA ANESTESIA(INFANTIL) | H19: NO | I19: =+'Necesidades Trimestrales'!F23 -> UNIDAD | J19: =+'Necesidades Trimestrales'!N23 -> 252 | K19: ='Necesidades Trimestrales'!G23 -> 50
A20: 9 | C20: =+'Necesidades Trimestrales'!E24 -> MASCARA CON BOLSA RESERVORIO ADULTO | H20: NO | I20: =+'Necesidades Trimestrales'!F24 -> UNIDAD | J20: =+'Necesidades Trimestrales'!N24 -> 380 | K20: ='Necesidades Trimestrales'!G24 -> 1500
A21: 10 | C21: =+'Necesidades Trimestrales'!E25 -> MASCARA CON BOLSA RESERVORIO PEDIATRICA | H21: NO | I21: =+'Necesidades Trimestrales'!F25 -> UNIDAD | J21: =+'Necesidades Trimestrales'!N25 -> 380 | K21: ='Necesidades Trimestrales'!G25 -> 200
A22: 11 | C22: =+'Necesidades Trimestrales'!E26 -> MASCARA DE OXIGENO CON REGULADORES | H22: NO | I22: =+'Necesidades Trimestrales'!F26 -> UNIDAD | J22: =+'Necesidades Trimestrales'!N26 -> 360 | K22: ='Necesidades Trimestrales'!G26 -> 500
A23: 12 | C23: =+'Necesidades Trimestrales'!E27 -> MASCARA PARA NEBULIZAR ADULTO COMPLETA MASCARA+PIPETA+TUBULADURA | H23: NO | I23: =+'Necesidades Trimestrales'!F27 -> UNIDAD | J23: =+'Necesidades Trimestrales'!N27 -> 270 | K23: ='Necesidades Trimestrales'!G27 -> 500
A24: 13 | C24: =+'Necesidades Trimestrales'!E29 -> MASCARAS ANESTESICA BORDE INFLABLE ADULTO Nº 5 | H24: NO | I24: =+'Necesidades Trimestrales'!F29 -> UNIDAD | J24: =+'Necesidades Trimestrales'!N29 -> 320 | K24: ='Necesidades Trimestrales'!G29 -> 150
A25: 14 | C25: =+'Necesidades Trimestrales'!E30 -> MASCARAS ANESTESICA BORDE INFLABLE ADULTO Nº 6 | H25: NO | I25: =+'Necesidades Trimestrales'!F30 -> UNIDAD | J25: =+'Necesidades Trimestrales'!N30 -> 320 | K25: ='Necesidades Trimestrales'!G30 -> 150
A26: 15 | C26: =+'Necesidades Trimestrales'!E32 -> RESUCITADOR MANUAL ADULTO REUTILIZABLE | I26: =+'Necesidades Trimestrales'!F32 -> UNIDAD | J26: =+'Necesidades Trimestrales'!N32 -> 8200 | K26: ='Necesidades Trimestrales'!G32 -> 20
A27: 16 | C27: =+'Necesidades Trimestrales'!E34 -> RESUCITADOR MANUAL PEDIATRICO REUTILIZABLE | I27: =+'Necesidades Trimestrales'!F34 -> UNIDAD | J27: =+'Necesidades Trimestrales'!N34 -> 8200 | K27: ='Necesidades Trimestrales'!G34 -> 20
A28: 17 | C28: =+'Necesidades Trimestrales'!E35 -> VARA ESCHMANN N° 6 mm | H28: NO | I28: =+'Necesidades Trimestrales'!F35 -> UNIDAD | J28: =+'Necesidades Trimestrales'!N35 -> 7900 | K28: ='Necesidades Trimestrales'!G35 -> 10
A29: 18 | C29: =+'Necesidades Trimestrales'!E36 -> VARA ESCHMANN N° 9 mm | H29: NO | I29: =+'Necesidades Trimestrales'!F36 -> UNIDAD | J29: =+'Necesidades Trimestrales'!N36 -> 7900 | K29: ='Necesidades Trimestrales'!G36 -> 10
A30: 19 | C30: =+'Necesidades Trimestrales'!E37 -> VARA ESCHMANN N°11 mm | H30: NO | I30: =+'Necesidades Trimestrales'!F37 -> UNIDAD | J30: =+'Necesidades Trimestrales'!N37 -> 7900 | K30: ='Necesidades Trimestrales'!G37 -> 10
A32: Costo total estimado: PESOS DOS MILLONES SEISCIENTOS CINCUENTA Y SEIS MIL con 00/100. | J32: =SUMPRODUCT(J12:J30,K12:K30) -> 2656000

Sheet APG FARMACIA
A1: EJERCICIO: | D1: ='Necesidades Trimestrales'!C6 -> 2022 | P1: AUTORIZACION PARA GASTAR
A4: JURISDICCIÓN: | G4: ='NP FARMACIA'!D3 -> 040 - Ministerio de Salud
A5: SAF: | G5: ='NP FARMACIA'!D4 -> 011 - Direccion Provincial de Administracion del Ministerio de Salud
A6: UNIDAD EJECUTORA: | G6: ='NP FARMACIA'!D5 -> 469 - DIRECCION PROVINCIAL DE FARMACIA E INSUMOS
A7: DEPENDENCIA SOLICITANTE: | G7: ='NP FARMACIA'!D6 -> 469 - DIRECCION PROVINCIAL DE FARMACIA E INSUMOS
A8: AUTORIZACIÓN:
A9: Señor Jefe de Servicio Administrativo Financiero:
A10: ="Autorizo la realización de los trámites correspondientes, a fin de proveer a este Organismo los bienes y/o servicios que se detallan en Nota de Pedido N° " & 'NP FARMACIA'!K1&", afectando la erogación resultante a los créditos presupuestarios aprobados a favor de esta Unidad Ejecutora, conforme al siguiente detalle:" -> Autorizo la realización de los trámites correspondientes, a fin de proveer a este Organismo los bienes y/o servicios que se detallan en Nota de Pedido N° 19/2022, afectando la erogación resultante a los créditos presupuestarios aprobados a favor de esta Unidad Ejecutora, conforme al siguiente detalle:
A12: IMPUTACIÓN PRESUPUESTARIA
A13: CÓDIGO | O13: DENOMINACIÓN DE LA PARTIDA PRESUPUESTARIA | Q13: IMPORTE
A14: PR | B14: SB | C14: PY | D14: AC | E14: OB | F14: UG | G14: FIN | H14: FUN | I14: I | J14: P | K14: P | L14: SubP | M14: M | N14: FF
A15: 30 | D15: 1 | F15: 4901 | G15: 3 | H15: 1 | I15: 2 | J15: 9 | K15: 5 | M15: 1 | N15: 1.1 | O15: UTILES MENORES MEDICOS, QUIRURGICOS Y DE LABORATORIO | Q15: ='NP FARMACIA'!J32 -> 2656000
A23: TOTAL DE PESOS: DOS MILLONES SEISCIENTOS CINCUENTA Y SEIS MIL con 00/100. | Q23: =SUM(Q15:Q22) -> 2656000
A25: JUSTIFICACIÓN:
A26: ='NP FARMACIA'!D8 -> ADQUISICION DE INSUMOS PARA TERAPIA RESPIRATORIA

Sheet NP SAME
A1: NOTA DE PEDIDO | J1: N° | K1: 16/2022
A3: JURISDICCIÓN: | D3: ='Necesidades Trimestrales'!C4 -> 040 - Ministerio de Salud
A4: SAF: | D4: ='Necesidades Trimestrales'!C5 -> 011 - Direccion Provincial de Administracion del Ministerio de Salud
A5: UNIDAD EJECUTORA: | D5: 748 - DIRECCION PROVINCIAL SISTEMA DE ATENCION MEDICA DE EMERGENCIA
A6: DEPENDENCIA SOLICITANTE: | D6: 748 - DIRECCION PROVINCIAL SISTEMA DE ATENCION MEDICA DE EMERGENCIA
A7: PERIODO UTILIZACIÓN: | D7: SEMESTRAL
A8: OBJETO: | D8: ADQUISICION DE INSUMOS PARA TERAPIA RESPIRATORIA
A10: Ítem | B10: Codigo Item | C10: DESCRIPCIÓN | H10: Adjunta Detalle Técnico | I10: Unidad Medida | J10: Precio Unitario Estimado | K10: Cantidad Solicitada
A12: 1 | C12: =+'Necesidades Trimestrales'!E10 -> AEROCAMARA C/ FUELLE ADULTO | H12: NO | I12: =+'Necesidades Trimestrales'!F10 -> UNIDAD | J12: =+'Necesidades Trimestrales'!N10 -> 490 | K12: ='Necesidades Trimestrales'!I10 -> 5
A13: 2 | C13: =+'Necesidades Trimestrales'!E11 -> AEROCAMARA CON MASCARA COMPLETA PEDIATRICA | H13: NO | I13: =+'Necesidades Trimestrales'!F11 -> UNIDAD | J13: =+'Necesidades Trimestrales'!N11 -> 490 | K13: ='Necesidades Trimestrales'!I11 -> 5
A14: 3 | C14: =+'Necesidades Trimestrales'!E13 -> CANULA NASAL DE ALTO FLUJO TIPO OPTIFLOW INFANTIL F&P OPT 316 | H14: NO | I14: =+'Necesidades Trimestrales'!F13 -> UNIDAD | J14: =+'Necesidades Trimestrales'!N13 -> 12500 | K14: ='Necesidades Trimestrales'!I13 -> 5
A15: 4 | C15: =+'Necesidades Trimestrales'!E14 -> CANULA NASAL DE ALTO FLUJO TIPO OPTIFLOW PEDIATRICA F&P OPT 318 | H15: NO | I15: =+'Necesidades Trimestrales'!F14 -> UNIDAD | J15: =+'Necesidades Trimestrales'!N14 -> 12500 | K15: ='Necesidades Trimestrales'!I14 -> 5
A16: 5 | C16: =+'Necesidades Trimestrales'!E15 -> CANULA NASAL PARA ALTO FLUJO TIPO GGM ADULTO 6 mm 4826R1V TAMANO L | H16: NO | I16: =+'Necesidades Trimestrales'!F15 -> UNIDAD | J16: =+'Necesidades Trimestrales'!N15 -> 7600 | K16: ='Necesidades Trimestrales'!I15 -> 10
A17: 6 | C17: =+'Necesidades Trimestrales'!E17 -> CIRCUITO ANESTESIA EXTENSIBLE ADULTO DESCARTABLE | H17: NO | I17: =+'Necesidades Trimestrales'!F17 -> UNIDAD | J17: =+'Necesidades Trimestrales'!N17 -> 980 | K17: ='Necesidades Trimestrales'!I17 -> 8
A18: 7 | C18: =+'Necesidades Trimestrales'!E19 -> HALO CEFALICO tipo <MEDIX> con tapa - MEDIANO : 200 mm de diametro x 180 mm de altura | H18: NO | I18: =+'Necesidades Trimestrales'!F19 -> UNIDAD | J18: =+'Necesidades Trimestrales'!N19 -> 17680 | K18: ='Necesidades Trimestrales'!I19 -> 2
A19: 8 | C19: =+'Necesidades Trimestrales'!E20 -> HALO CEFALICO tipo <MEDIX> con tapa GRANDE: 230 mm de diametro x 200 mm de altura | H19: NO | I19: =+'Necesidades Trimestrales'!F20 -> UNIDAD | J19: =+'Necesidades Trimestrales'!N20 -> 20345 | K19: ='Necesidades Trimestrales'!I20 -> 2
A20: 9 | C20: =+'Necesidades Trimestrales'!E24 -> MASCARA CON BOLSA RESERVORIO ADULTO | H20: NO | I20: =+'Necesidades Trimestrales'!F24 -> UNIDAD | J20: =+'Necesidades Trimestrales'!N24 -> 380 | K20: ='Necesidades Trimestrales'!I24 -> 8
A21: 10 | C21: =+'Necesidades Trimestrales'!E25 -> MASCARA CON BOLSA RESERVORIO PEDIATRICA | H21: NO | I21: =+'Necesidades Trimestrales'!F25 -> UNIDAD | J21: =+'Necesidades Trimestrales'!N25 -> 380 | K21: ='Necesidades Trimestrales'!I25 -> 5
A22: 11 | C22: =+'Necesidades Trimestrales'!E27 -> MASCARA PARA NEBULIZAR ADULTO COMPLETA MASCARA+PIPETA+TUBULADURA | H22: NO | I22: =+'Necesidades Trimestrales'!F27 -> UNIDAD | J22: =+'Necesidades Trimestrales'!N27 -> 270 | K22: ='Necesidades Trimestrales'!I27 -> 10
A23: 12 | C23: =+'Necesidades Trimestrales'!E28 -> MASCARA PARA NEBULIZAR PEDIATRICA COMPLETA MASCARA+PIPETA+TUBULADURA | H23: NO | I23: =+'Necesidades Trimestrales'!F28 -> UNIDAD | J23: =+'Necesidades Trimestrales'!N28 -> 270 | K23: ='Necesidades Trimestrales'!I28 -> 10
A24: 13 | C24: =+'Necesidades Trimestrales'!E31 -> RESUCITADOR MANUAL ADULTO DESCARTABLE | H24: NO | I24: =+'Necesidades Trimestrales'!F31 -> UNIDAD | J24: =+'Necesidades Trimestrales'!N31 -> 2300 | K24: ='Necesidades Trimestrales'!I31 -> 5
A25: 14 | C25: =+'Necesidades Trimestrales'!E32 -> RESUCITADOR MANUAL ADULTO REUTILIZABLE | H25: NO | I25: =+'Necesidades Trimestrales'!F32 -> UNIDAD | J25: =+'Necesidades Trimestrales'!N32 -> 8200 | K25: ='Necesidades Trimestrales'!I32 -> 5
A26: 15 | C26: =+'Necesidades Trimestrales'!E33 -> RESUCITADOR MANUAL NEONATAL REUTILIZABLE | H26: NO | I26: =+'Necesidades Trimestrales'!F33 -> UNIDAD | J26: =+'Necesidades Trimestrales'!N33 -> 8200 | K26: ='Necesidades Trimestrales'!I33 -> 2
A28: Costo total estimado: PESOS TRESCIENTOS SESENTA Y NUEVE MIL TREINTA con 00/100. | J28: =SUMPRODUCT(J12:J26,K12:K26) -> 369030

Sheet APG SAME
A1: EJERCICIO: | D1: ='Necesidades Trimestrales'!C6 -> 2022 | P1: AUTORIZACION PARA GASTAR
A4: JURISDICCIÓN: | G4: ='NP SAME'!D3 -> 040 - Ministerio de Salud
A5: SAF: | G5: ='NP SAME'!D4 -> 011 - Direccion Provincial de Administracion del Ministerio de Salud
A6: UNIDAD EJECUTORA: | G6: ='NP SAME'!D5 -> 748 - DIRECCION PROVINCIAL SISTEMA DE ATENCION MEDICA DE EMERGENCIA
A7: DEPENDENCIA SOLICITANTE: | G7: ='NP SAME'!D6 -> 748 - DIRECCION PROVINCIAL SISTEMA DE ATENCION MEDICA DE EMERGENCIA
A8: AUTORIZACIÓN:
A9: Señor Jefe de Servicio Administrativo Financiero:
A10: ="Autorizo la realización de los trámites correspondientes, a fin de proveer a este Organismo los bienes y/o servicios que se detallan en Nota de Pedido N° " & 'NP SAME'!K1&", afectando la erogación resultante a los créditos presupuestarios aprobados a favor de esta Unidad Ejecutora, conforme al siguiente detalle:" -> Autorizo la realización de los trámites correspondientes, a fin de proveer a este Organismo los bienes y/o servicios que se detallan en Nota de Pedido N° 16/2022, afectando la erogación resultante a los créditos presupuestarios aprobados a favor de esta Unidad Ejecutora, conforme al siguiente detalle:
A12: IMPUTACIÓN PRESUPUESTARIA
A13: CÓDIGO | O13: DENOMINACIÓN DE LA PARTIDA PRESUPUESTARIA | Q13: IMPORTE
A14: PR | B14: SB | C14: PY | D14: AC | E14: OB | F14: UG | G14: FIN | H14: FUN | I14: I | J14: P | K14: P | L14: SubP | M14: M | N14: FF
A15: 31 | D15: 1 | F15: 4901 | G15: 3 | H15: 1 | I15: 2 | J15: 9 | K15: 5 | M15: 1 | N15: 1.1 | O15: UTILES MENORES MEDICOS, QUIRURGICOS Y DE LABORATORIO | Q15: ='NP SAME'!J28 -> 369030
A23: TOTAL DE PESOS: TRESCIENTOS SESENTA Y NUEVE MIL TREINTA con 00/100. | Q23: =SUM(Q15:Q22) -> 369030
A25: JUSTIFICACIÓN:
A26: ='NP SAME'!D8 -> ADQUISICION DE INSUMOS PARA TERAPIA RESPIRATORIA

Sheet NP DPMIA
A1: NOTA DE PEDIDO | J1: N° | K1: 05/2022
A3: JURISDICCIÓN: | D3: ='Necesidades Trimestrales'!C4 -> 040 - Ministerio de Salud
A4: SAF: | D4: ='Necesidades Trimestrales'!C5 -> 011 - Direccion Provincial de Administracion del Ministerio de Salud
A5: UNIDAD EJECUTORA: | D5: 162 - DIRECCION PROVINCIAL MATERNIDAD, INFANCIA Y ADOLESCENCIA
A6: DEPENDENCIA SOLICITANTE: | D6: 162 - DIRECCION PROVINCIAL MATERNIDAD, INFANCIA Y ADOLESCENCIA
A7: PERIODO UTILIZACIÓN: | D7: SEMESTRAL
A8: OBJETO: | D8: ADQUISICION DE INSUMOS PARA TERAPIA RESPIRATORIA
A10: Ítem | B10: Codigo Item | C10: DESCRIPCIÓN | H10: Adjunta Detalle Técnico | I10: Unidad Medida | J10: Precio Unitario Estimado | K10: Cantidad Solicitada
A12: 1 | C12: =+'Necesidades Trimestrales'!E32 -> RESUCITADOR MANUAL ADULTO REUTILIZABLE | H12: NO | I12: =+'Necesidades Trimestrales'!F32 -> UNIDAD | J12: =+'Necesidades Trimestrales'!N32 -> 8200 | K12: ='Necesidades Trimestrales'!K32 -> 10
A13: 2 | C13: =+'Necesidades Trimestrales'!E33 -> RESUCITADOR MANUAL NEONATAL REUTILIZABLE | H13: NO | I13: =+'Necesidades Trimestrales'!F33 -> UNIDAD | J13: =+'Necesidades Trimestrales'!N33 -> 8200 | K13: ='Necesidades Trimestrales'!K33 -> 20
A14: 3 | C14: =+'Necesidades Trimestrales'!E34 -> RESUCITADOR MANUAL PEDIATRICO REUTILIZABLE | H14: NO | I14: =+'Necesidades Trimestrales'!F34 -> UNIDAD | J14: =+'Necesidades Trimestrales'!N34 -> 8200 | K14: ='Necesidades Trimestrales'!K34 -> 20
A16: Costo total estimado: PESOS CUATROCIENTOS DIEZ MIL con 00/100. | J16: =SUMPRODUCT(J12:J14,K12:K14) -> 410000

Sheet APG DPMIA
A1: EJERCICIO: | D1: ='Necesidades Trimestrales'!C6 -> 2022 | P1: AUTORIZACION PARA GASTAR
A4: JURISDICCIÓN: | G4: ='NP DPMIA'!D3 -> 040 - Ministerio de Salud
A5: SAF: | G5: ='NP DPMIA'!D4 -> 011 - Direccion Provincial de Administracion del Ministerio de Salud
A6: UNIDAD EJECUTORA: | G6: ='NP DPMIA'!D5 -> 162 - DIRECCION PROVINCIAL MATERNIDAD, INFANCIA Y ADOLESCENCIA
A7: DEPENDENCIA SOLICITANTE: | G7: ='NP DPMIA'!D6 -> 162 - DIRECCION PROVINCIAL MATERNIDAD, INFANCIA Y ADOLESCENCIA
A8: AUTORIZACIÓN:
A9: Señor Jefe de Servicio Administrativo Financiero:
A10: ="Autorizo la realización de los trámites correspondientes, a fin de proveer a este Organismo los bienes y/o servicios que se detallan en Nota de Pedido N° " & 'NP DPMIA'!K1&", afectando la erogación resultante a los créditos presupuestarios aprobados a favor de esta Unidad Ejecutora, conforme al siguiente detalle:" -> Autorizo la realización de los trámites correspondientes, a fin de proveer a este Organismo los bienes y/o servicios que se detallan en Nota de Pedido N° 05/2022, afectando la erogación resultante a los créditos presupuestarios aprobados a favor de esta Unidad Ejecutora, conforme al siguiente detalle:
A12: IMPUTACIÓN PRESUPUESTARIA
A13: CÓDIGO | O13: DENOMINACIÓN DE LA PARTIDA PRESUPUESTARIA | Q13: IMPORTE
A14: PR | B14: SB | C14: PY | D14: AC | E14: OB | F14: UG | G14: FIN | H14: FUN | I14: I | J14: P | K14: P | L14: SubP | M14: M | N14: FF
A15: 20 | D15: 1 | F15: 4901 | G15: 3 | H15: 1 | I15: 2 | J15: 9 | K15: 5 | M15: 1 | N15: 1.1 | O15: UTILES MENORES MEDICOS, QUIRURGICOS Y DE LABORATORIO | Q15: ='NP DPMIA'!J16 -> 410000
A23: TOTAL DE PESOS: CUATROCIENTOS DIEZ MIL con 00/100. | Q23: =SUM(Q15:Q22) -> 410000
A25: JUSTIFICACIÓN:
A26: ='NP DPMIA'!D8 -> ADQUISICION DE INSUMOS PARA TERAPIA RESPIRATORIA
