Workbook

Sheet Necesidades Trimestrales
B2: Pedido de Necesidades Trimestrales
A4: JURISDICCION: | C4: 40 - MINISTERIO DE SALUD
A5: SAF N°: | C5: 11 - DIRECCION PROVINCIAL DE ADMINISTRACION - MINISTERIO DE SALUD
A6: EJERCICIO: | C6: 2021
A7: TRIMESTRE: | C7: 1
A9: ID | B9: CODIGO ITEM | C9: RUBRO DE COMPRA | D9: I.P.P. | E9: DESCRIPCION | F9: UNIDAD DE MEDIDA | G9: CANTIDAD | H9: PRECIO UNITARIO ESTIMADO | I9: IMPORTE TOTAL ESTIMADO
A10: 1 | B10: 2.5.6-793.31 | C10: COMBUSTIBLES Y LUBRICANTES | D10: 256 | E10: GAS OIL; PRESENTACION: POR LITRO, USO: MOTORES DIESEL, COMERCIALIZACION: GRADO 3, DESTINO: DPTO. S.F.V. DE CATAMARCA | F10: LITROS | G10: =28583+3108-15000+1000+7000 -> 24691 | H10: 83.1 | I10: =G10*H10 -> 2051822.1
E11: TOTAL DEL RUBRO | I11: =SUM(I10:I10) -> 2051822.1
B14: Especificidades Item N° 1 :
B16: Descripción técnica
B18: Plazos y lugares de entrega
C19: INTERRELACIONES MUNICIPALES: 1333 LITROS | G19: 1333 | H19: =+G19*$H$10 -> 110772.3
C20: ODONTOLOGIA: 8775 LITROS | G20: =1775+7000 -> 8775 | H20: =+G20*$H$10 -> 729202.5
C21: PLAZO: 10 DIAS | H21: =+G21*$H$10 -> 0
H22: =+G22*$H$10 -> 0
H23: =+G23*$H$10 -> 0
H24: =+G24*$H$10 -> 0
B25: Calidad Minima esperada | H25: =+G25*$H$10 -> 0
H26: =+G26*$H$10 -> 0
B27: Mantenimiento | H27: =+G27*$H$10 -> 0
H28: =+G28*$H$10 -> 0
B29: Garantia | H29: =+G29*$H$10 -> 0
H30: =+G30*$H$10 -> 0
H31: =+G31*$H$10 -> 0
H32: =+G32*$H$10 -> 0
B33: Especificidades Item N°2 : | H33: =+G33*$H$10 -> 0
H34: =+G34*$H$10 -> 0
B35: Descripción técnica | H35: =+G35*$H$10 -> 0
C36: USO: CAMIONETA CHEVROLET S10 - AC-091-RR - RENAULT FURGON DE CARGA KANGU - OJM-N° 597 A CARGO DEL HOPITAL Dr. CARLOS MALBRAN | H36: =+G36*$H$10 -> 0
H37: =+G37*$H$10 -> 0
H38: =+G38*$H$10 -> 0
H39: =+G39*$H$10 -> 0
B40: Plazos y lugares de entrega | G40: 12033 | H40: =+G40*$H$10 -> 999942.3
C41: SALUD PUBLICA 12033 LITROS | G41: 1550 | H41: =+G41*$H$10 -> 128805
C42: BCO DE SANGRE 1550 LITROS | G42: 1000 | H42: =+G42*$H$10 -> 83100
C43: DIRECCION DE ADMINISTRACIÓN: 1000 LITROS
C44: PLAZO 10 DIAS
B47: Calidad Minima esperada
B49: Mantenimiento
B51: Garantia
...

Sheet  NotaPedido
A1: NOTA DE PEDIDO | J1: N° | K1: 0007/2021
A3: JURISDICCIÓN: | D3: ='Necesidades Trimestrales'!C4 -> 40 - MINISTERIO DE SALUD
A4: SAF: | D4: ='Necesidades Trimestrales'!C5 -> 11 - DIRECCION PROVINCIAL DE ADMINISTRACION - MINISTERIO DE SALUD
A5: UNIDAD EJECUTORA: | D5: MINISTERIO DE SALUD
A6: DEPENDENCIA SOLICITANTE: | D6: MINISTERIO DE SALUD
A7: PERIODO UTILIZACIÓN: | D7: ='Necesidades Trimestrales'!C7 & "° Trimestre - Año " & 'Necesidades Trimestrales'!C6 -> 1° Trimestre - Año 2021
A8: OBJETO:
A10: Ítem | B10: Codigo Item | C10: DESCRIPCIÓN | H10: Adjunta Detalle Técnico | I10: Unidad Medida | J10: Precio Unitario Estimado | K10: Cantidad Solicitada
A12: 2 | B12: ='Necesidades Trimestrales'!B10 -> 2.5.6-793.31 | C12: ='Necesidades Trimestrales'!E10 -> GAS OIL; PRESENTACION: POR LITRO, USO: MOTORES DIESEL, COMERCIALIZACION: GRADO 3, DESTINO: DPTO. S.F.V. DE CATAMARCA | H12: NO | I12: ='Necesidades Trimestrales'!F10 -> LITROS | J12: ='Necesidades Trimestrales'!H10 -> 83.1 | K12: ='Necesidades Trimestrales'!G10 -> 24691
A13: Costo total estimado: DOS MILLONES CINCUENTA Y UN MIL OCHOCIENTOS VEINTIDOS CON 10/00 | J13: =SUMPRODUCT(J12:J12,K12:K12) -> 2051822.1

Sheet Autor Gastar
A1: EJERCICIO: | D1: ='Necesidades Trimestrales'!C6 -> 2021 | P1: AUTORIZACION PARA GASTAR
A4: JURISDICCIÓN: | G4: =' NotaPedido'!D3 -> 40 - MINISTERIO DE SALUD
A5: SAF: | G5: =' NotaPedido'!D4 -> 11 - DIRECCION PROVINCIAL DE ADMINISTRACION - MINISTERIO DE SALUD
A6: UNIDAD EJECUTORA: | G6: MINISTERIO DE SALUD
A7: DEPENDENCIA SOLICITANTE: | G7: MINISTERIO DE SALUD
A8: AUTORIZACIÓN:
A9: Señor Jefe de Servicio Administrativo Financiero:
A10: ="Autorizo la realización de los trámites correspondientes, a fin de proveer a este Organismo los bienes y/o servicios que se detallan en Nota de Pedido N° " & ' NotaPedido'!K1&", afectando la erogación resultante a los créditos presupuestarios aprobados a favor de esta Unidad Ejecutora, conforme al siguiente detalle:" -> Autorizo la realización de los trámites correspondientes, a fin de proveer a este Organismo los bienes y/o servicios que se detallan en Nota de Pedido N° 0007/2021, afectando la erogación resultante a los créditos presupuestarios aprobados a favor de esta Unidad Ejecutora, conforme al siguiente detalle:
A12: IMPUTACIÓN PRESUPUESTARIA
A13: CÓDIGO | O13: DENOMINACIÓN DE LA PARTIDA PRESUPUESTARIA | Q13: IMPORTE
A14: PR | B14: SB | C14: PY | D14: AC | E14: OB | F14: UG | G14: FIN | H14: FUN | I14: I | J14: P | K14: P | L14: SubP | M14: M | N14: FF
A15: 50 | D15: 1 | F15: 4901 | G15: 3 | H15: 1 | I15: 2 | J15: 5 | K15: 6 | M15: 1 | N15: 1.1 | O15: COMBUSTIBLES Y LUBRICANTES | Q15: =+'Necesidades Trimestrales'!H19 -> 110772.3
A16: 29 | D16: 1 | F16: 4901 | G16: 3 | H16: 1 | I16: 2 | J16: 5 | K16: 6 | M16: 1 | N16: 1.1 | O16: COMBUSTIBLES Y LUBRICANTES | Q16: =+'Necesidades Trimestrales'!H20 -> 729202.5
A17: 3 | D17: 1 | F17: 4901 | G17: 3 | H17: 1 | I17: 2 | J17: 5 | K17: 6 | M17: 1 | N17: 1.1 | O17: COMBUSTIBLES Y LUBRICANTES | Q17: =+'Necesidades Trimestrales'!H40 -> 999942.3
A18: 27 | D18: 1 | F18: 4901 | G18: 3 | H18: 1 | I18: 2 | J18: 5 | K18: 6 | M18: 1 | N18: 1.1 | O18: COMBUSTIBLES Y LUBRICANTES | Q18: =+'Necesidades Trimestrales'!H41 -> 128805
A19: 34 | D19: 1 | F19: 4901 | G19: 3 | H19: 1 | I19: 2 | J19: 5 | K19: 6 | M19: 1 | N19: 1.1 | O19: COMBUSTIBLES Y LUBRICANTES | Q19: =+'Necesidades Trimestrales'!H42 -> 83100
A23: TOTAL DE PESOS: DOS MILLONES CINCUENTA Y UN MIL OCHOCIENTOS VEINTIDOS CON 10/00 | Q23: =SUM(Q15:Q22) -> 2051822.1
A25: JUSTIFICACIÓN:
A26: Para la adquisición de combustible, necesario para el desarrollo de las actividades del Ministerio de Salud
