Workbook

Sheet Necesidades Trimestrales
B2: Pedido de Necesidades Trimestrales
A4: JURISDICCION: | C4: 90 - Ministerio de Seguridad
A5: SAF N°: | C5: 7 - Direccion de Administracion de la Policia de la Provincia de Catamarca
A6: EJERCICIO: | C6: 2022
A7: TRIMESTRE: | C7: 4
A9: ID | B9: CODIGO ITEM | C9: RUBRO DE COMPRA | D9: I.P.P. | E9: DESCRIPCION | F9: UNIDAD DE MEDIDA | G9: CANTIDAD | H9: PRECIO UNITARIO ESTIMADO | I9: IMPORTE TOTAL ESTIMADO
A10: 1 | B10: 2.5.6-797.21 | C10: COMBUSTIBLES Y LUBRICANTES | D10: 2.5.6 | E10: NAFTA SUPER; TIPO: ULTRA GRADO 3, OCTANO: 98, PRESENTACION: POR LITRO, DESTINO: SIN VALOR | F10: LITROS EN VALES | G10: 32000 | H10: 190 | I10: =H10*G10 -> 6080000 | J10: =SUM(I10:I11) -> 21830000 | K10: =J10/2 -> 10915000
A11: 2 | B11: 2.5.6-793.31 | C11: COMBUSTIBLES Y LUBRICANTES | D11: 2.5.6 | E11: GAS OIL; PRESENTACION: POR LITRO, USO: MOTORES DIESEL, COMERCIALIZACION: GRADO 3, DESTINO: DPTO. S.F.V. DE CATAMARCA | F11: LITROS EN VALES | G11: 70000 | H11: 225 | I11: =H11*G11 -> 15750000 | J11: =+G10/2 -> 16000 | K11: =+G11/2 -> 35000
A12: 3 | B12: 2.5.6-797.21 | C12: COMBUSTIBLES Y LUBRICANTES | D12: 2.5.6 | E12: NAFTA SUPER; TIPO: ULTRA GRADO 3, OCTANO: 98, PRESENTACION: POR LITRO, DESTINO: SIN VALOR | F12: LITROS EN VALES | G12: 12000 | H12: 192 | I12: =H12*G12 -> 2304000 | J12: =SUM(I12:I13) -> 6163000
A13: 4 | B13: 2.5.6-793.35 | C13: COMBUSTIBLES Y LUBRICANTES | D13: 2.5.6 | E13: GAS OIL; PRESENTACION: POR LITRO, USO: MOTORES DIESEL, COMERCIALIZACION: GRADO 3, DESTINO: DPTO. LA PAZ | F13: LITROS EN VALES | G13: 17000 | H13: 227 | I13: =H13*G13 -> 3859000
A14: 5 | B14: 2.5.6-797.21 | C14: COMBUSTIBLES Y LUBRICANTES | D14: 2.5.6 | E14: NAFTA SUPER; TIPO: ULTRA GRADO 3, OCTANO: 98, PRESENTACION: POR LITRO, DESTINO: SIN VALOR | F14: LITROS EN VALES | G14: 12000 | H14: 192 | I14: =H14*G14 -> 2304000 | J14: =SUM(I14:I15) -> 6163000
A15: 6 | B15: 2.5.6-793.37 | C15: COMBUSTIBLES Y LUBRICANTES | D15: 2.5.6 | E15: GAS OIL; PRESENTACION: POR LITRO, USO: MOTORES DIESEL, COMERCIALIZACION: GRADO 3, DESTINO: DPTO. BELEN | F15: LITROS EN VALES | G15: 17000 | H15: 227 | I15: =H15*G15 -> 3859000
A16: 7 | B16: 2.5.6-797.21 | C16: COMBUSTIBLES Y LUBRICANTES | D16: 2.5.6 | E16: NAFTA SUPER; TIPO: ULTRA GRADO 3, OCTANO: 98, PRESENTACION: POR LITRO, DESTINO: SIN VALOR | F16: LITROS EN VALES | G16: 12000 | H16: 192 | I16: =H16*G16 -> 2304000 | J16: =SUM(I16:I17) -> 6163000
A17: 8 | B17: 2.5.6-793.45 | C17: COMBUSTIBLES Y LUBRICANTES | D17: 2.5.6 | E17: GAS OIL; PRESENTACION: POR LITRO, USO: MOTORES DIESEL, COMERCIALIZACION: GRADO 3, DESTINO: DPTO. ANDALGALA | F17: LITROS EN VALES | G17: 17000 | H17: 227 | I17: =H17*G17 -> 3859000
A18: 9 | B18: 2.5.6-797.21 | C18: COMBUSTIBLES Y LUBRICANTES | D18: 2.5.6 | E18: NAFTA SUPER; TIPO: ULTRA GRADO 3, OCTANO: 98, PRESENTACION: POR LITRO, DESTINO: SIN VALOR | F18: LITROS EN VALES | G18: 12000 | H18: 192 | I18: =H18*G18 -> 2304000 | J18: =SUM(I18:I19) -> 6163000
A19: 10 | B19: 2.5.6-793.36 | C19: COMBUSTIBLES Y LUBRICANTES | D19: 2.5.6 | E19: GAS OIL; PRESENTACION: POR LITRO, USO: MOTORES DIESEL, COMERCIALIZACION: GRADO 3, DESTINO: DPTO. TINOGASTA | F19: LITROS EN VALES | G19: 17000 | H19: 227 | I19: =H19*G19 -> 3859000
A20: 11 | B20: 2.5.6-797.21 | C20: COMBUSTIBLES Y LUBRICANTES | D20: 2.5.6 | E20: NAFTA SUPER; TIPO: ULTRA GRADO 3, OCTANO: 98, PRESENTACION: POR LITRO, DESTINO: SIN VALOR | F20: LITROS EN VALES | G20: 12000 | H20: 192 | I20: =H20*G20 -> 2304000 | J20: =SUM(I20:I21) -> 6163000
A21: 12 | B21: 2.5.6-793.39 | C21: COMBUSTIBLES Y LUBRICANTES | D21: 2.5.6 | E21: GAS OIL; PRESENTACION: POR LITRO, USO: MOTORES DIESEL, COMERCIALIZACION: GRADO 3, DESTINO: DPTO. EL ALTO | F21: LITROS EN VALES | G21: 17000 | H21: 227 | I21: =H21*G21 -> 3859000
A22: 13 | B22: 2.5.6-797.21 | C22: COMBUSTIBLES Y LUBRICANTES | D22: 2.5.6 | E22: NAFTA SUPER; TIPO: ULTRA GRADO 3, OCTANO: 98, PRESENTACION: POR LITRO, DESTINO: SIN VALOR | F22: LITROS EN VALES | G22: 12000 | H22: 192 | I22: =H22*G22 -> 2304000 | J22: =SUM(I22:I23) -> 6163000
A23: 14 | B23: 2.5.6-793.38 | C23: COMBUSTIBLES Y LUBRICANTES | D23: 2.5.6 | E23: GAS OIL; PRESENTACION: POR LITRO, USO: MOTORES DIESEL, COMERCIALIZACION: GRADO 3, DESTINO: DPTO. STA. MARIA | F23: LITROS EN VALES | G23: 17000 | H23: 227 | I23: =H23*G23 -> 3859000
A24: 15 | B24: 2.5.6-797.21 | C24: COMBUSTIBLES Y LUBRICANTES | D24: 2.5.6 | E24: NAFTA SUPER; TIPO: ULTRA GRADO 3, OCTANO: 98, PRESENTACION: POR LITRO, DESTINO: SIN VALOR | F24: LITROS EN VALES | G24: 12000 | H24: 192 | I24: =H24*G24 -> 2304000 | J24: =SUM(I24:I25) -> 6163000
A25: 16 | B25: 2.5.6-793.33 | C25: COMBUSTIBLES Y LUBRICANTES | D25: 2.5.6 | E25: GAS OIL; PRESENTACION: POR LITRO, USO: MOTORES DIESEL, COMERCIALIZACION: GRADO 3, DESTINO: DPTO. POMAN | F25: LITROS EN VALES | G25: 17000 | H25: 227 | I25: =H25*G25 -> 3859000
A26: 17 | B26: 2.5.6-7104.302 | C26: COMBUSTIBLES Y LUBRICANTES | D26: 2.5.6 | E26: ACEITES LUBRICANTES; USO: AUTOMOTOR, PRESENTACION: ENVASE X 205 L, NORMA: SAE 10 W 40 | F26: UNIDAD | G26: 2 | H26: 200000 | I26: =H26*G26 -> 400000 | J26: =SUM(I26:I31) -> 4988290
A27: 18 | B27: 2.5.6-7104.577 | C27: COMBUSTIBLES Y LUBRICANTES | D27: 2.5.6 | E27: ACEITES LUBRICANTES; DENOMINACION: SAE 5 W 30, USO: AUTOMOTOR, PRESENTACION: TAMBOR X 205 L, NORMA: SAE 5 W 30 | F27: UNIDAD | G27: 5 | H27: 504378 | I27: =H27*G27 -> 2521890
A28: 19 | B28: 2.5.6-7104.261 | C28: COMBUSTIBLES Y LUBRICANTES | D28: 2.5.6 | E28: ACEITES LUBRICANTES; USO: AUTOMOTOR, PRESENTACION: TAMBOR X 205 L | F28: UNIDAD | G28: 2 | H28: 282000 | I28: =H28*G28 -> 564000
A29: 20 | B29: 2.5.6-7104.578 | C29: COMBUSTIBLES Y LUBRICANTES | D29: 2.5.6 | E29: ACEITES LUBRICANTES; DENOMINACION: SAE 15 W 50, USO: AUTOMOTOR, PRESENTACION: TAMBOR X 205 L, NORMA: SAE 15 W 50 | F29: UNIDAD | G29: 2 | H29: 495600 | I29: =H29*G29 -> 991200
A30: 21 | B30: 2.5.6-7104.31 | C30: COMBUSTIBLES Y LUBRICANTES | D30: 2.5.6 | E30: ACEITES LUBRICANTES; DENOMINACION: SAE 20 W 50, USO: AUTOMOTOR, PRESENTACION: TAMBOR X 205 L, NORMA: SAE 20 W 50 | F30: UNIDAD | G30: 2 | H30: 252408 | I30: =H30*G30 -> 504816
A31: 22 | B31: 2.5.6-7104.414 | C31: COMBUSTIBLES Y LUBRICANTES | D31: 2.5.6 | E31: ACEITES LUBRICANTES; USO: REFRIGERANTE, PRESENTACION: ENVASE X 1 L, NORMA: 150 SUS/32 CST, COMERCIALIZACION: SIN | F31: UNIDAD | G31: 20 | H31: 319.2 | I31: =H31*G31 -> 6384
I32: =SUM(I10:I31) -> 69959290
B34: Especificidades:
B35: Descripción técnica ITEM 1 y 2:
C36: REQUISITO: Se debe contar con mas de una Boca de expendio para Actividad 1(CAPITAL) y 7 (INTERIOR - VALLE CENTRAL)
B37: Descripción técnica ITEM 1:
C38: DESTINO: DPTO S.F.V. DE CATAMARCA
B39: Descripción técnica ITEM 3:
C40: DESTINO: DPTO LA PAZ
B41: Descripción técnica ITEM 5:
C42: DESTINO: DPTO BELEN
B43: Descripción técnica ITEM 7:
C44: DESTINO: DPTO ANDALGALA
...

Sheet  NotaPedido
A1: NOTA DE PEDIDO | J1: N° | K1: 76/2021
A3: JURISDICCIÓN: | D3: ='Necesidades Trimestrales'!C4 -> 90 - Ministerio de Seguridad
A4: SAF: | D4: ='Necesidades Trimestrales'!C5 -> 7 - Direccion de Administracion de la Policia de la Provincia de Catamarca
A5: UNIDAD EJECUTORA: | D5: Policía de la Provincia de Catamarca
A6: DEPENDENCIA SOLICITANTE: | D6: División Transporte- Departamento Logística (D-4)
A7: PERIODO UTILIZACIÓN: | D7: 3er trimestre Año 2021.-
A8: OBJETO: | D8: Adquisición de Combustible destinados a los moviles de la Institucion Policial
A10: Ítem | B10: Codigo Item | C10: DESCRIPCIÓN | H10: Adjunta Detalle Técnico | I10: Unidad Medida | J10: Precio Unitario Estimado | K10: Cantidad Solicitada
A12: ='Necesidades Trimestrales'!A10 -> 1 | B12: ='Necesidades Trimestrales'!B10 -> 2.5.6-797.21 | C12: =('Necesidades Trimestrales'!E10) -> NAFTA SUPER; TIPO: ULTRA GRADO 3, OCTANO: 98, PRESENTACION: POR LITRO, DESTINO: SIN VALOR | H12: SI | I12: UNIDAD | J12: ='Necesidades Trimestrales'!H10 -> 190 | K12: ='Necesidades Trimestrales'!G10 -> 32000
A13: ='Necesidades Trimestrales'!A11 -> 2 | B13: ='Necesidades Trimestrales'!B11 -> 2.5.6-793.31 | C13: =('Necesidades Trimestrales'!E11) -> GAS OIL; PRESENTACION: POR LITRO, USO: MOTORES DIESEL, COMERCIALIZACION: GRADO 3, DESTINO: DPTO. S.F.V. DE CATAMARCA | H13: SI | I13: UNIDAD | J13: ='Necesidades Trimestrales'!H11 -> 225 | K13: ='Necesidades Trimestrales'!G11 -> 70000
A14: ='Necesidades Trimestrales'!A12 -> 3 | B14: ='Necesidades Trimestrales'!B12 -> 2.5.6-797.21 | C14: =('Necesidades Trimestrales'!E12) -> NAFTA SUPER; TIPO: ULTRA GRADO 3, OCTANO: 98, PRESENTACION: POR LITRO, DESTINO: SIN VALOR | H14: SI | I14: UNIDAD | J14: ='Necesidades Trimestrales'!H12 -> 192 | K14: ='Necesidades Trimestrales'!G12 -> 12000
A15: ='Necesidades Trimestrales'!A13 -> 4 | B15: ='Necesidades Trimestrales'!B13 -> 2.5.6-793.35 | C15: =('Necesidades Trimestrales'!E13) -> GAS OIL; PRESENTACION: POR LITRO, USO: MOTORES DIESEL, COMERCIALIZACION: GRADO 3, DESTINO: DPTO. LA PAZ | H15: SI | I15: UNIDAD | J15: ='Necesidades Trimestrales'!H13 -> 227 | K15: ='Necesidades Trimestrales'!G13 -> 17000
A16: ='Necesidades Trimestrales'!A14 -> 5 | B16: ='Necesidades Trimestrales'!B14 -> 2.5.6-797.21 | C16: =('Necesidades Trimestrales'!E14) -> NAFTA SUPER; TIPO: ULTRA GRADO 3, OCTANO: 98, PRESENTACION: POR LITRO, DESTINO: SIN VALOR | H16: SI | I16: UNIDAD | J16: ='Necesidades Trimestrales'!H14 -> 192 | K16: ='Necesidades Trimestrales'!G14 -> 12000
A17: ='Necesidades Trimestrales'!A15 -> 6 | B17: ='Necesidades Trimestrales'!B15 -> 2.5.6-793.37 | C17: =('Necesidades Trimestrales'!E15) -> GAS OIL; PRESENTACION: POR LITRO, USO: MOTORES DIESEL, COMERCIALIZACION: GRADO 3, DESTINO: DPTO. BELEN | H17: SI | I17: UNIDAD | J17: ='Necesidades Trimestrales'!H15 -> 227 | K17: ='Necesidades Trimestrales'!G15 -> 17000
A18: ='Necesidades Trimestrales'!A16 -> 7 | B18: ='Necesidades Trimestrales'!B16 -> 2.5.6-797.21 | C18: =('Necesidades Trimestrales'!E16) -> NAFTA SUPER; TIPO: ULTRA GRADO 3, OCTANO: 98, PRESENTACION: POR LITRO, DESTINO: SIN VALOR | H18: SI | I18: UNIDAD | J18: ='Necesidades Trimestrales'!H16 -> 192 | K18: ='Necesidades Trimestrales'!G16 -> 12000
A19: ='Necesidades Trimestrales'!A17 -> 8 | B19: ='Necesidades Trimestrales'!B17 -> 2.5.6-793.45 | C19: =('Necesidades Trimestrales'!E17) -> GAS OIL; PRESENTACION: POR LITRO, USO: MOTORES DIESEL, COMERCIALIZACION: GRADO 3, DESTINO: DPTO. ANDALGALA | H19: SI | I19: UNIDAD | J19: ='Necesidades Trimestrales'!H17 -> 227 | K19: ='Necesidades Trimestrales'!G17 -> 17000
A20: ='Necesidades Trimestrales'!A18 -> 9 | B20: ='Necesidades Trimestrales'!B18 -> 2.5.6-797.21 | C20: =('Necesidades Trimestrales'!E18) -> NAFTA SUPER; TIPO: ULTRA GRADO 3, OCTANO: 98, PRESENTACION: POR LITRO, DESTINO: SIN VALOR | H20: SI | I20: UNIDAD | J20: ='Necesidades Trimestrales'!H18 -> 192 | K20: ='Necesidades Trimestrales'!G18 -> 12000
A21: ='Necesidades Trimestrales'!A19 -> 10 | B21: ='Necesidades Trimestrales'!B19 -> 2.5.6-793.36 | C21: =('Necesidades Trimestrales'!E19) -> GAS OIL; PRESENTACION: POR LITRO, USO: MOTORES DIESEL, COMERCIALIZACION: GRADO 3, DESTINO: DPTO. TINOGASTA | H21: SI | I21: UNIDAD | J21: ='Necesidades Trimestrales'!H19 -> 227 | K21: ='Necesidades Trimestrales'!G19 -> 17000
A22: ='Necesidades Trimestrales'!A20 -> 11 | B22: ='Necesidades Trimestrales'!B20 -> 2.5.6-797.21 | C22: =('Necesidades Trimestrales'!E20) -> NAFTA SUPER; TIPO: ULTRA GRADO 3, OCTANO: 98, PRESENTACION: POR LITRO, DESTINO: SIN VALOR | H22: SI | I22: UNIDAD | J22: ='Necesidades Trimestrales'!H20 -> 192 | K22: ='Necesidades Trimestrales'!G20 -> 12000
A23: ='Necesidades Trimestrales'!A21 -> 12 | B23: ='Necesidades Trimestrales'!B21 -> 2.5.6-793.39 | C23: =('Necesidades Trimestrales'!E21) -> GAS OIL; PRESENTACION: POR LITRO, USO: MOTORES DIESEL, COMERCIALIZACION: GRADO 3, DESTINO: DPTO. EL ALTO | H23: SI | I23: UNIDAD | J23: ='Necesidades Trimestrales'!H21 -> 227 | K23: ='Necesidades Trimestrales'!G21 -> 17000
... A29: ='Necesidades Trimestrales'!A27 -> 18 | B29: ='Necesidades Trimestrales'!B27 -> 2.5.6-7104.577 | C29: =('Necesidades Trimestrales'!E27) -> ACEITES LUBRICANTES; DENOMINACION: SAE 5 W 30, USO: AUTOMOTOR, PRESENTACION: TAMBOR X 205 L, NORMA: SAE 5 W 30 | H29: SI | I29: UNIDAD | J29: ='Necesidades Trimestrales'!H27 -> 504378 | K29: ='Necesidades Trimestrales'!G27 -> 5
A30: ='Necesidades Trimestrales'!A30 -> 21 | B30: ='Necesidades Trimestrales'!B30 -> 2.5.6-7104.31 | C30: =('Necesidades Trimestrales'!E30) -> ACEITES LUBRICANTES; DENOMINACION: SAE 20 W 50, USO: AUTOMOTOR, PRESENTACION: TAMBOR X 205 L, NORMA: SAE 20 W 50 | H30: SI | I30: UNIDAD | J30: ='Necesidades Trimestrales'!H30 -> 252408 | K30: ='Necesidades Trimestrales'!G30 -> 2
A31: ='Necesidades Trimestrales'!#REF! -> #REF! | B31: ='Necesidades Trimestrales'!#REF! -> #REF! | C31: =('Necesidades Trimestrales'!#REF!) -> #REF! | H31: SI | I31: UNIDAD | J31: ='Necesidades Trimestrales'!#REF! -> #REF! | K31: ='Necesidades Trimestrales'!#REF! -> #REF!
A32: ='Necesidades Trimestrales'!#REF! -> #REF! | B32: ='Necesidades Trimestrales'!#REF! -> #REF! | C32: =('Necesidades Trimestrales'!#REF!) -> #REF! | H32: SI | I32: UNIDAD | J32: ='Necesidades Trimestrales'!#REF! -> #REF! | K32: ='Necesidades Trimestrales'!#REF! -> #REF!
A33: ='Necesidades Trimestrales'!A31 -> 22 | B33: ='Necesidades Trimestrales'!B31 -> 2.5.6-7104.414 | C33: =('Necesidades Trimestrales'!E31) -> ACEITES LUBRICANTES; USO: REFRIGERANTE, PRESENTACION: ENVASE X 1 L, NORMA: 150 SUS/32 CST, COMERCIALIZACION: SIN | H33: SI | I33: UNIDAD | J33: ='Necesidades Trimestrales'!H31 -> 319.2 | K33: ='Necesidades Trimestrales'!G31 -> 20
A34: Costo total estimado: | D34: Cuarenta y Nueve Millones Quinientos Sesenta y Cuatro Mil Setecientos Siete con 50/100.- | J34: =SUMPRODUCT(J12:J33,K12:K33) -> #REF!

Sheet Autor Gastar
A1: EJERCICIO: | D1: ='Necesidades Trimestrales'!C6 -> 2022 | P1: AUTORIZACION PARA GASTAR
A4: JURISDICCIÓN: | G4: =' NotaPedido'!D3 -> 90 - Ministerio de Seguridad
A5: SAF: | G5: =' NotaPedido'!D4 -> 7 - Direccion de Administracion de la Policia de la Provincia de Catamarca
A6: UNIDAD EJECUTORA: | G6: =' NotaPedido'!D5 -> Policía de la Provincia de Catamarca
A7: DEPENDENCIA SOLICITANTE: | G7: =' NotaPedido'!D6 -> División Transporte- Departamento Logística (D-4)
A8: AUTORIZACIÓN:
A9: Señor Jefe de Servicio Administrativo Financiero:
A10: ="Autorizo la realización de los trámites correspondientes, a fin de proveer a este Organismo los bienes y/o servicios que se detallan en Nota de Pedido N° " & ' NotaPedido'!K1&", afectando la erogación resultante a los créditos presupuestarios aprobados a favor de esta Unidad Ejecutora, conforme al siguiente detalle:" -> Autorizo la realización de los trámites correspondientes, a fin de proveer a este Organismo los bienes y/o servicios que se detallan en Nota de Pedido N° 76/2021, afectando la erogación resultante a los créditos presupuestarios aprobados a favor de esta Unidad Ejecutora, conforme al siguiente detalle:
A12: IMPUTACIÓN PRESUPUESTARIA
A13: CÓDIGO | O13: DENOMINACIÓN DE LA PARTIDA PRESUPUESTARIA | Q13: IMPORTE
A14: PR | B14: SB | C14: PY | D14: AC | E14: OB | F14: UG | G14: FIN | H14: FUN | I14: I | J14: P | K14: P | L14: SubP | M14: M | N14: FF
A15: 16 | B15: 0 | C15: 0 | D15: 1 | E15: 0 | F15: 10 | G15: 2 | H15: 1 | I15: 2 | J15: 5 | K15: 6 | L15: 0 | M15: 1 | N15: 1.1 | O15: COMBUSTIBLES Y LUBRICANTES | Q15: =' NotaPedido'!J34 -> #REF!
A16: TOTAL DE PESOS: | Q16: =Q15 -> #REF!
E17: =' NotaPedido'!D34 -> Cuarenta y Nueve Millones Quinientos Sesenta y Cuatro Mil Setecientos Siete con 50/100.-
A18: JUSTIFICACIÓN:
A19: =' NotaPedido'!D8 -> Adquisición de Combustible destinados a los moviles de la Institucion Policial
