Workbook

Sheet Necesidades Trimestrales (2)
A1: 2021
B2: Pedido de Necesidades Trimestrales
A4: JURISDICCION: | C4: 40 - MINISTERIO DE SALUD
A5: SAF N°: | C5: 11 - DIRE PROV DE ADMINISTRACION - MINISTERIO DE SALUD
A6: EJERCICIO: | C6: 2021
A7: TRIMESTRE: | C7: SEGUNDO TRIMESTRE
A9: ID | B9: CODIGO ITEM | C9: RUBRO DE COMPRA | D9: I.P.P. | E9: DESCRIPCION | F9: UNIDAD DE MEDIDA | G9: DIR. ADM. | H9: TOTAL DIR DE ADM | I9: DIR. LAB. CENTRAL | J9: TOTAL DE LAB CENTRAL | K9: BCO DE SANGRE | L9: TOTAL BANCO DE SANGRE | M9: ATENCION PRIMARIA | N9: TOTAL ATENCION PRI | O9: DIR DE CANCER | P9: TOTAL DE DIR DE CANCER | Q9: FARMACIA | R9: TOTAL FARMACIA | S9: ODONTOLOGIA | T9: TOTAL DE ODONTOLOG | U9: SAME | V9: TOTAL DE SAME | W9: MALBRAN | X9: HOSPITAL MALBRAN | Y9: maternidade e infancia | Z9: total maternidad | AA9: SEC DE ASIST EN SALUD PUB | AB9: TOTAL SEC EN ASIS EN SAL | AC9: SALUD Y MEDIO AMBIENTE | AD9: TOTAL SALUD Y MEDIO AMBIENTE | AE9: VECTORES Y ZOONOSIS | AF9: TOTAL DE VECT Y ZOON | AG9: SUMAR | AH9: TOTAL SUMAR | AI9: CUR | AJ9: TOTAL CUR | AK9: PLANIFICACION | AL9: TOTAL PLANIFICA | AM9: SALUD MENTAL | AN9: TOTAL SALUD MENTAL | AO9: AREAS Y DPAS | AP9: TOTAL DPAS | AQ9: CANTIDAD TOTAL | AR9: PRECIO UNITARIO ESTIMADO | AS9: IMPORTE TOTAL ESTIMADO
A10: 1 | B10: 2.5.6-793.31 | C10: COMBUSTIBLES Y LUBRICANTES | D10: 2.5.6 | E10: GAS OIL; PRESENTACION: POR LITRO, USO: MOTORES DIESEL,COMERCIALIZACION: GRADO 3, DESTINO: DPTO. S.F.V. DE CATAMARCA | F10: LITROS | K10: 200 | L10: =+K10*AR10 -> 18180 | M10: 1112 | N10: =+M10*AR10 -> 101080.8 | O10: 1400 | P10: =+O10*AR10 -> 127260 | U10: 15286 | V10: =+U10*AR10 -> 1389497.4 | Y10: 3893 | Z10: =+Y10*AR10 -> 353873.7 | AA10: =2200+360 -> 2560 | AB10: =+AA10*AR10 -> 232704 | AC10: 1995 | AD10: =+AC10*AR10 -> 181345.5 | AE10: 2534 | AF10: =+AE10*AR10 -> 230340.6 | AI10: 2000 | AJ10: =+AI10*AR10 -> 181800 | AK10: 4000 | AL10: =+AK10*AR10 -> 363600 | AM10: 900 | AN10: =+AM10*AR10 -> 81810 | AO10: =8800+2850+3000+3000+12000+1800+3500+5000+6000+8000+15375+6000+3000+6000+4000 -> 88325 | AP10: =+AO10*AR10 -> 8028742.5 | AQ10: =+'NP ATENCION PRIMARIA'!K12+'NP BCO DE SANGRE'!K12+'NP CANCER'!K12+'NP SAME'!K12+'NP MATERNO'!K12+'NP sasp'!K12+'NP salud y medio ambie'!K12+'NP zoonosis'!K12+'NP cur'!K12+'NP PLANIFICACION'!K12+'NP salud mental'!K12+'[1]NP asistencia sanitaria'!K12 -> 96500 | AR10: 90.9 | AS10: =+AQ10*AR10 -> 8771850
A11: 3 | B11: 2.5.6-797.39 | C11: COMBUSTIBLES Y LUBRICANTES | D11: 2.5.6 | E11: NAFTA SUPER; TIPO: SUPER, OCTANO: 95, PRESENTACION: POR LITRO, DESTINO: DPTO. S.F.V. DE CATAMARCA | F11: LITROS | AM11: 1000 | AN11: =+AM11*AR11 -> 93900 | AQ11: =+'NP salud mental'!K13 -> 770 | AR11: 93.9 | AS11: =+AQ11*AR11 -> 72303
E12: TOTAL DEL RUBRO COMBUSTIBLE | L12: =SUM(L10:L11) -> 18180 | N12: =SUM(N10:N11) -> 101080.8 | P12: =SUM(P10:P11) -> 127260 | V12: =SUM(V10:V11) -> 1389497.4 | X12: =SUM(X10:X11) -> 0 | Z12: =SUM(Z10:Z11) -> 353873.7 | AB12: =SUM(AB10:AB11) -> 232704 | AD12: =SUM(AD10:AD11) -> 181345.5 | AF12: =SUM(AF10:AF11) -> 230340.6 | AJ12: =SUM(AJ10:AJ11) -> 181800 | AL12: =SUM(AL10:AL11) -> 363600 | AN12: =SUM(AN10:AN11) -> 175710 | AP12: =SUM(AP10:AP11) -> 8028742.5 | AS12: =+'APG ATENCION PRIMARIA'!Q23+'APG BCO DE SANGRE'!Q23+'APG CANCER'!Q23+'APG SAME'!Q23+'APG MATERNO'!Q23+'APG sasp'!Q23+'APG salud y medio ambie'!Q23+'APG zoonosis'!Q23+'APG cur'!Q23+'APG PLANIFICACION'!Q23+'APG salud mental'!Q23+'APG asistencia sanitaria'!Q23 -> 8844153
B14: ITEM 1 Y 2
B15: Descripción técnica | C15: Se Entregarán Fraccionado bajo la forma de vales de 30 Lts. cada uno y cuando la cantidad adjudicada no permita la confección de dicho vale, para completar se emitirá uno por una cantidad menor hasta completar la cantidad solicitada
B17: Plazos de entrega | C17: cinco (5) dias habiles
B18: SE ADJUNTA ANEXO CON LOS DOMINIOS Y MATRICULA DE LOS VEHICULOS PARA LO CUAL SE SOLICITA EL COMBUSTIBLE
B20: Lugar de Entrega: | C20: DIR. PROV. DE AMINISTRACION - CHACABUCO N° 169 - en el horario de 8:00hs a 12:00hs de lunes a viernes
B24: Calidad Minima esperada
B26: Mantenimiento | C26: cuarenta y cinco (45) días

Sheet Anexo de matriculas y dominio 
A1: DIRECCION PROVINCIAL ASISTENCIA SANITARIA NIVEL I Y II
A3: Area Programatica Nº1
A5: Vehiculo | B5: Dominio | C5: Nº de Motor | D5: Nº Chasis | E5: Año
A6: Renault Master - Ambulancia.- | B6: GEU-277 | C6: G9UA724C030714 | D6: 93YADCUE57J787157 | E6: 2007
A7: Renault Master- Ambulancia.- | B7: GUV-922 | C7: G9UA724C035587 | D7: 93YADCUE58J896449 | E7: 2008
A8: Renault Master-PH3 DCI 120 L1H2 Ambulancia.- | B8: KNI-753 | C8: G9UA754C268409 | D8: 93YADCUE6CJ897389 | E8: 2011
A9: Ford F-100 4x2 XL PLUS 3,9 D - Ambulacia.- | B9: ILC-099 | C9: 36071580 | D9: 9EFFF22C99B859146 | E9: 2010
A10: Renault Master PH3 DCI 120 L1H2 - Ambulancia.- | B10: LAD-136 | C10: G9UA754C270571 | D10: 93YADCUE6CJ969873 | E10: 2012
A11: Fiat Ducato. Ambulancia.- | B11: NHW-650 | C11: 7173538 | D11: 93W245G84D2112772 | E11: 2013
A12: Mercedez Benz Sprinter Furgon.- | B12: GWJ-779 | C12: 61198170074458 | D12: 8AC90036628A984192 | E12: 2008
A13: Renault Master MASTER PH3 DCI 120 - Ambulancia.- | B13: LAD-135 | C13: G9UA650C244170 | D13: 93YADC1E6CJ140233 | E13: 2012
A14: Renault Master DCI 120 - Ambulancia.- | B14: GJP-880 | C14: G9UA724C026899 | D14: 93YADCUH56J706159 | E14: 2007
A15: Chevrolet S-10. Camioneta.- | B15: GWJ-742 | C15: M1A304122 | D15: 9BG124AJ08C11312 | E15: 2008
A16: Chevrolet Zafira. Camioneta.- | B16: HUD-575 | C16: 1N0006130 | D16: 9BGTT75F09C131088 | E16: 2008
A17: Fiat Ducato Amxicargo 2,3 JTD. Ambulancia.- | B17: AA-842-EL | C17: 7250765 | D17: 93W245G84H2160838 | E17: 2016
A18: Fiat Ducato Amxicargo 2,3 JTD. Ambulancia.- | B18: AA-842-EI | C18: 7250728 | D18: 93W245G84H2160833 | E18: 2016
A19: Toyota Hilux 4x4 c/s DX 2,4 TDI M/T. Ambulancia | B19: AA-793-NE | C19: 2GD-0137533 | D19: 8AJFB8CB5H1550878 | E19: 2017
A20: Renault Master- Ambulancia.- | B20: AE-041-BD | C20: M9TB870C262154 | D20: 93YMAFESCLJ213469 | E20: 2020
A22: Area Programatica Nº2
A24: Vehiculo | B24: Dominio | C24: Nº de Motor | D24: Nº Chasis | E24: Año
A25: Fiat Ducato Maxi cargo 2,3 JTD Furgon. Ambulancia.- | B25: AA-842-EH | C25: 7250726 | D25: 93W245G84H2160832 | E25: 2016
A26: Fiat Ducato Maxi cargo 2,3 JTD Furgon. Ambulancia.- | B26: AA-842-EF | C26: 7250640 | D26: 93W245G84H2160831 | E26: 2016
A27: Fiat Ducato 2,3. Ambulancia.- | B27: NSE-229 | C27: 7166125 | D27: 93W245G74D2109008 | E27: 2014
A28: Renault Master DCI120. Ambulancia - | B28: GUO-325 | C28: G9UA7240035511 | D28: 93YADCUE58J896313 | E28: 2007
A29: Renault Master DCI120 - Ambulancia .- | B29: GJS-713 | C29: G9UA724C030282 | D29: 93YADCUE57J787718 | E29: 2007
A30: Fiat iveco Daily. Ambulancia.- | B30: S/P | C30: 37344067044 | D30: 93ZC4980158318123 | E30: 2005
A31: Ford Ranger XLC/C 4x4 2,8. Camioneta.- | B31: FYK-918 | C31: B61618215 | D31: 8AFER13FX4J326463 | E31: 2007
A33: Area Programatica Nº3
A35: Vehiculo | B35: Dominio | C35: Nº de Motor | D35: Nº Chasis | E35: Año
A36: Chevrolet S10 2,8 TDI - Camioneta.- | B36: GDD-914 | C36: M1A282868 | D36: 9BG138AJ07C413213 | E36: 2007
A37: Renautl Master 2,5 D - Ambulancia.- | B37: GJC-299 | C37: J9UA724C030522 | D37: 93YADCUE57J787225 | E37: 2007
A38: Fiat Ducato Maxi cargo 2,3. Ambulancia | B38: AA-702-MN | C38: 7251288 | D38: 93W245G74H2161118 | E38: 2016
A39: Ford Transit 2,2 L 125 T350 TA C/AA - Ambulancia.- | B39: MNW-258 | C39: CYRCDTT22471 | D39: WFOXXPTTFDTT22471 | E39: 2013
A40: Mercedez Benz Sprinter - Ambulancia.- | B40: DCA-098 | C40: 10520880 | D40: 8AC690311YA537631 | E40: 1998
A41: Chevrolet S10 2,8 T.I- Ambulancia.- | B41: ESH-451 | C41: 40704192268 | D41: 986124AC05C410447 | E41: 2014
A46: Vehiculo | B46: Dominio | C46: Nº de Motor | D46: Nº Chasis | E46: Año
A47: Chevrolet S10 2,8 TDI SID 4x2 - Ambulancia.- | B47: GDD-918 | C47: M1A282927 | D47: 9BG1384J07C413214 | E47: 2007
A48: Renault Master DCI 120- Ambulancia.- | B48: GEU-279 | C48: G9UA724C030527 | D48: 93YADCUE7J787131 | E48: 2007
A49: Chevrolet S10 2,8 TDI - Ambulancia.- | B49: ESH-453 | C49: 40704192255 | D49: 9BG124ACOSC410400 | E49: 1999
A50: Mercedez Benz Sprinter - Ambulancia.- | B50: DCA-097 | C50: 632999105118976 | D50: 8AC690311 | E50: 2000
...

Sheet NP asistencia sanitaria
A1: NOTA DE PEDIDO | J1: N° | K1: 06/2021
A3: JURISDICCIÓN: | D3: 040 - Ministerio de Salud
A4: SAF: | D4: 011 - Direccion Provincial de Administración - Ministerio de Salud
A5: UNIDAD EJECUTORA: | D5: 476 - DIRECCION PROVINCIAL ASISTENCIA SANITARIA NIVEL I Y II
A6: DEPENDENCIA SOLICITANTE: | D6: 476 - DIRECCION PROVINCIAL ASISTENCIA SANITARIA NIVEL I Y II
A7: PERIODO UTILIZACIÓN: | D7: 2° TRIMESTRE
A8: OBJETO: | D8: Adquisición de Combustibles.
A10: Ítem | B10: Codigo Item | C10: DESCRIPCIÓN | H10: Adjunta Detalle Técnico | I10: Unidad Medida | J10: Precio Unitario Estimado | K10: Cantidad Solicitada
A12: 1 | B12: =+'Necesidades Trimestrales (2)'!B10 -> 2.5.6-793.31 | C12: =+'Necesidades Trimestrales (2)'!E10 -> GAS OIL; PRESENTACION: POR LITRO, USO: MOTORES DIESEL,COMERCIALIZACION: GRADO 3, DESTINO: DPTO. S.F.V. DE CATAMARCA | H12: no | I12: UNIDAD | J12: =+'Necesidades Trimestrales (2)'!AR10 -> 90.9 | K12: 68600 | M12: =+K12*J12 -> 6235740
M13: =+K13*J13 -> 0
M14: =+K14*J14 -> 0
M15: =+K15*J15 -> 0
A19: Costo total estimado: Seis Millones Doscientos Treinta y Cinco Mil Setecientos Cuarenta con 00/100 | J19: =SUM(M12:M15) -> 6235740

Sheet APG asistencia sanitaria
A1: EJERCICIO: | D1: 2021 | P1: AUTORIZACION PARA GASTAR
A4: JURISDICCIÓN: | G4: 040 - Ministerio de Salud
A5: SAF: | G5: 011- Dirección Provincial de Administración
A6: UNIDAD EJECUTORA: | G6: 476 - DIRECCION PROVINCIAL ASISTENCIA SANITARIA NIVEL I Y II
A7: DEPENDENCIA SOLICITANTE: | G7: 476 - DIRECCION PROVINCIAL ASISTENCIA SANITARIA NIVEL I Y II
A8: AUTORIZACIÓN:
A9: Señor Jefe de Servicio Administrativo Financiero:
A10: Autorizo la realización de los trámites correspondientes, a fin de proveer a este Organismo los bienes que se detallan en Nota de pedido y Entrega N°06/2021, afectando la erogación resultante a los créditos presupuestarios aprobados a favor de esta Unidad Ejecutora, conforme al siguiente detalle:
A12: IMPUTACIÓN PRESUPUESTARIA
A13: CÓDIGO | O13: DENOMINACIÓN DE LA PARTIDA PRESUPUESTARIA | Q13: IMPORTE
A14: PR | B14: SB | C14: PY | D14: AC | E14: OB | F14: UG | G14: FIN | H14: FUN | I14: I | J14: P | K14: P | L14: SubP | M14: M | N14: FF
A15: 21 | D15: 1 | F15: 4901 | G15: 3 | H15: 1 | I15: 2 | J15: 5 | K15: 6 | M15: 1 | N15: 1.1 | O15: Combustibles y Lubricantes | Q15: 6235740
A23: TOTAL DE PESOS: Seis Millones Doscientos Treinta y Cinco Mil Setecientos Cuarenta con 00/100 | Q23: =SUM(Q15:Q22) -> 6235740
A25: JUSTIFICACIÓN:
A26: Adquisición de Combustibles.

Sheet NP salud mental
A1: NOTA DE PEDIDO | J1: N° | K1: 04/2021
A3: JURISDICCIÓN: | D3: 040 - Ministerio de Salud
A4: SAF: | D4: 011 - Direccion Provincial de Administración - Ministerio de Salud
A5: UNIDAD EJECUTORA: | D5: 745- SECRETARIA DE SALUD MENTAL Y ADICCIONES
A6: DEPENDENCIA SOLICITANTE: | D6: 745- SECRETARIA DE SALUD MENTAL Y ADICCIONES
A7: PERIODO UTILIZACIÓN: | D7: 2° TRIMESTRE
A8: OBJETO: | D8: Adquisición de Combustibles.
A10: Ítem | B10: Codigo Item | C10: DESCRIPCIÓN | H10: Adjunta Detalle Técnico | I10: Unidad Medida | J10: Precio Unitario Estimado | K10: Cantidad Solicitada
A12: 1 | B12: =+'Necesidades Trimestrales (2)'!B10 -> 2.5.6-793.31 | C12: =+'[1]NP asistencia sanitaria'!C12:G12 -> GAS OIL; PRESENTACION: POR LITRO, USO: MOTORES DIESEL,COMERCIALIZACION: GRADO 3, DESTINO: DPTO. S.F.V. DE CATAMARCA | H12: no | I12: UNIDAD | J12: 90.9 | K12: 790 | M12: =+K12*J12 -> 71811
A13: 2 | B13: =+'Necesidades Trimestrales (2)'!B11 -> 2.5.6-797.39 | C13: =+'Necesidades Trimestrales (2)'!E11 -> NAFTA SUPER; TIPO: SUPER, OCTANO: 95, PRESENTACION: POR LITRO, DESTINO: DPTO. S.F.V. DE CATAMARCA | H13: no | I13: UNIDAD | J13: =+'Necesidades Trimestrales (2)'!AR11 -> 93.9 | K13: 770 | M13: =+K13*J13 -> 72303
M14: =+K14*J14 -> 0
M15: =+K15*J15 -> 0
A19: Costo total estimado: Ciento Cuarenta y Cuatro Mil Ciento Catorce con 00/100 | J19: =SUM(M12:M15) -> 144114

Sheet APG salud mental
A1: EJERCICIO: | D1: 2021 | P1: AUTORIZACION PARA GASTAR
A4: JURISDICCIÓN: | G4: 040 - Ministerio de Salud
A5: SAF: | G5: 011- Dirección Provincial de Administración
A6: UNIDAD EJECUTORA: | G6: 745- SECRETARIA DE SALUD MENTAL Y ADICCIONES
A7: DEPENDENCIA SOLICITANTE: | G7: 745- SECRETARIA DE SALUD MENTAL Y ADICCIONES
A8: AUTORIZACIÓN:
A9: Señor Jefe de Servicio Administrativo Financiero:
A10: Autorizo la realización de los trámites correspondientes, a fin de proveer a este Organismo los bienes que se detallan en Nota de pedido y Entrega N°04/2021, afectando la erogación resultante a los créditos presupuestarios aprobados a favor de esta Unidad Ejecutora, conforme al siguiente detalle:
A12: IMPUTACIÓN PRESUPUESTARIA
A13: CÓDIGO | O13: DENOMINACIÓN DE LA PARTIDA PRESUPUESTARIA | Q13: IMPORTE
A14: PR | B14: SB | C14: PY | D14: AC | E14: OB | F14: UG | G14: FIN | H14: FUN | I14: I | J14: P | K14: P | L14: SubP | M14: M | N14: FF
A15: 5 | D15: 1 | F15: 4901 | G15: 1 | H15: 3 | I15: 2 | J15: 5 | K15: 6 | M15: 1 | N15: 1.1 | O15: Combustibles y Lubricantes | Q15: 144114
A23: TOTAL DE PESOS: Ciento Cuarenta y Cuatro Mil Ciento Catorce con 00/100 | Q23: =SUM(Q15:Q22) -> 144114
A24: g
A25: JUSTIFICACIÓN:
A26: Adquisición de Combustibles.

Sheet NP PLANIFICACION
A1: NOTA DE PEDIDO | J1: N° | K1: 05/2021
A3: JURISDICCIÓN: | D3: 040 - Ministerio de Salud
A4: SAF: | D4: 011 - Direccion Provincial de Administración - Ministerio de Salud
A5: UNIDAD EJECUTORA: | D5: 382- SECRETARIA DE PLANIFICACION Y GESTION EN SALUD
A6: DEPENDENCIA SOLICITANTE: | D6: 382- SECRETARIA DE PLANIFICACION Y GESTION EN SALUD
A7: PERIODO UTILIZACIÓN: | D7: 2° TRIMESTRE
A8: OBJETO: | D8: Adquisición de Combustibles.
A10: Ítem | B10: Codigo Item | C10: DESCRIPCIÓN | H10: Adjunta Detalle Técnico | I10: Unidad Medida | J10: Precio Unitario Estimado | K10: Cantidad Solicitada
A12: 1 | B12: =+'NP salud mental'!B12 -> 2.5.6-793.31 | C12: =+'NP salud mental'!C12:G12 -> GAS OIL; PRESENTACION: POR LITRO, USO: MOTORES DIESEL,COMERCIALIZACION: GRADO 3, DESTINO: DPTO. S.F.V. DE CATAMARCA | H12: no | I12: UNIDAD | J12: =+'Necesidades Trimestrales (2)'!AR10 -> 90.9 | K12: 3100 | M12: =+K12*J12 -> 281790
M13: =+K13*J13 -> 0
M14: =+K14*J14 -> 0
M15: =+K15*J15 -> 0
A19: Costo total estimado: Doscientos Ochenta y Un Mil Setecientos Noventa con 00/100 | J19: =SUM(M12:M15) -> 281790

Sheet APG PLANIFICACION
A1: EJERCICIO: | D1: 2021 | P1: AUTORIZACION PARA GASTAR
A4: JURISDICCIÓN: | G4: 040 - Ministerio de Salud
A5: SAF: | G5: 011- Dirección Provincial de Administración
A6: UNIDAD EJECUTORA: | G6: 382- SECRETARIA DE PLANIFICACION Y GESTION EN SALUD
A7: DEPENDENCIA SOLICITANTE: | G7: 382- SECRETARIA DE PLANIFICACION Y GESTION EN SALUD
A8: AUTORIZACIÓN:
A9: Señor Jefe de Servicio Administrativo Financiero:
A10: Autorizo la realización de los trámites correspondientes, a fin de proveer a este Organismo los bienes que se detallan en Nota de pedido y Entrega N°05/2021, afectando la erogación resultante a los créditos presupuestarios aprobados a favor de esta Unidad Ejecutora, conforme al siguiente detalle:
A12: IMPUTACIÓN PRESUPUESTARIA
A13: CÓDIGO | O13: DENOMINACIÓN DE LA PARTIDA PRESUPUESTARIA | Q13: IMPORTE
A14: PR | B14: SB | C14: PY | D14: AC | E14: OB | F14: UG | G14: FIN | H14: FUN | I14: I | J14: P | K14: P | L14: SubP | M14: M | N14: FF
A15: 2 | D15: 1 | F15: 4901 | G15: 1 | H15: 3 | I15: 2 | J15: 5 | K15: 6 | M15: 1 | N15: 1.1 | O15: Combustibles y Lubricantes | Q15: 281790
A23: TOTAL DE PESOS: Doscientos Ochenta y Un Mil Setecientos Noventa con 00/100 | Q23: =SUM(Q15:Q22) -> 281790
A24: g
A25: JUSTIFICACIÓN:
A26: Adquisición de Combustibles.

Sheet NP cur
A1: NOTA DE PEDIDO | J1: N° | K1: 08/2021
A3: JURISDICCIÓN: | D3: 040 - Ministerio de Salud
A4: SAF: | D4: 011 - Direccion Provincial de Administración - Ministerio de Salud
A5: UNIDAD EJECUTORA: | D5: 160 - DIRECCION PROVINCIAL CENTRO UNICO DE REFERENCIA
A6: DEPENDENCIA SOLICITANTE: | D6: 160 - DIRECCION PROVINCIAL CENTRO UNICO DE REFERENCIA
A7: PERIODO UTILIZACIÓN: | D7: 2° TRIMESTRE
A8: OBJETO: | D8: Adquisición de Combustibles.
A10: Ítem | B10: Codigo Item | C10: DESCRIPCIÓN | H10: Adjunta Detalle Técnico | I10: Unidad Medida | J10: Precio Unitario Estimado | K10: Cantidad Solicitada
A12: 1 | B12: =+'Necesidades Trimestrales (2)'!B10 -> 2.5.6-793.31 | C12: =+'NP PLANIFICACION'!C12:G12 -> GAS OIL; PRESENTACION: POR LITRO, USO: MOTORES DIESEL,COMERCIALIZACION: GRADO 3, DESTINO: DPTO. S.F.V. DE CATAMARCA | H12: no | I12: UNIDAD | J12: =+'Necesidades Trimestrales (2)'!AR10 -> 90.9 | K12: 1550 | M12: =+K12*J12 -> 140895
M13: =+K13*J13 -> 0
M14: =+K14*J14 -> 0
M15: =+K15*J15 -> 0
A19: Costo total estimado: Ciento Cuarenta Mil Ochocientos Noventa y Cinco con 00/100 | J19: =SUM(M12:M15) -> 140895

Sheet APG cur
A1: EJERCICIO: | D1: 2021 | P1: AUTORIZACION PARA GASTAR
A4: JURISDICCIÓN: | G4: 040 - Ministerio de Salud
A5: SAF: | G5: 011- Dirección Provincial de Administración
A6: UNIDAD EJECUTORA: | G6: 160 - DIRECCION PROVINCIAL CENTRO UNICO DE REFERENCIA
A7: DEPENDENCIA SOLICITANTE: | G7: 160 - DIRECCION PROVINCIAL CENTRO UNICO DE REFERENCIA
A8: AUTORIZACIÓN:
A9: Señor Jefe de Servicio Administrativo Financiero:
A10: Autorizo la realización de los trámites correspondientes, a fin de proveer a este Organismo los bienes que se detallan en Nota de pedido y Entrega N°08/2021, afectando la erogación resultante a los créditos presupuestarios aprobados a favor de esta Unidad Ejecutora, conforme al siguiente detalle:
A12: IMPUTACIÓN PRESUPUESTARIA
A13: CÓDIGO | O13: DENOMINACIÓN DE LA PARTIDA PRESUPUESTARIA | Q13: IMPORTE
A14: PR | B14: SB | C14: PY | D14: AC | E14: OB | F14: UG | G14: FIN | H14: FUN | I14: I | J14: P | K14: P | L14: SubP | M14: M | N14: FF
A15: 35 | D15: 1 | F15: 4901 | G15: 3 | H15: 1 | I15: 2 | J15: 5 | K15: 6 | M15: 1 | N15: 1.1 | O15: Combustibles y Lubricantes | Q15: 80000
A16: 35 | D16: 2 | F16: 4901 | G16: 3 | H16: 1 | I16: 2 | J16: 5 | K16: 6 | M16: 1 | N16: 1.1 | O16: Combustibles y Lubricantes | Q16: =+Q23-Q15 -> 60895
A23: TOTAL DE PESOS: Ciento Cuarenta Mil Ochocientos Noventa y Cinco con 00/100 | Q23: 140895
A24: g
A25: JUSTIFICACIÓN:
A26: Adquisición de Combustibles.

Sheet NP zoonosis
A1: NOTA DE PEDIDO | J1: N° | K1: 04/2021
A3: JURISDICCIÓN: | D3: 040 - Ministerio de Salud
A4: SAF: | D4: 011 - Direccion Provincial de Administración - Ministerio de Salud
A5: UNIDAD EJECUTORA: | D5: 746 - DIRECCION PROVINCIAL DE VECTORES Y ZOONOSIS
A6: DEPENDENCIA SOLICITANTE: | D6: 746 - DIRECCION PROVINCIAL DE VECTORES Y ZOONOSIS
A7: PERIODO UTILIZACIÓN: | D7: 2° TRIMESTRE
A8: OBJETO: | D8: Adquisición de Combustibles.
A10: Ítem | B10: Codigo Item | C10: DESCRIPCIÓN | H10: Adjunta Detalle Técnico | I10: Unidad Medida | J10: Precio Unitario Estimado | K10: Cantidad Solicitada
A12: 1 | B12: =+'Necesidades Trimestrales (2)'!B10 -> 2.5.6-793.31 | C12: =+'NP cur'!C12:G12 -> GAS OIL; PRESENTACION: POR LITRO, USO: MOTORES DIESEL,COMERCIALIZACION: GRADO 3, DESTINO: DPTO. S.F.V. DE CATAMARCA | H12: no | I12: UNIDAD | J12: =+'Necesidades Trimestrales (2)'!AR10 -> 90.9 | K12: 1960 | M12: =+K12*J12 -> 178164
M13: =+K13*J13 -> 0
M14: =+K14*J14 -> 0
M15: =+K15*J15 -> 0
A19: Costo total estimado: Ciento Setenta y Ocho Mil Ciento Sesenta y Cuatro con 00/100 | J19: =SUM(M12:M15) -> 178164

Sheet APG zoonosis
A1: EJERCICIO: | D1: 2021 | P1: AUTORIZACION PARA GASTAR
A4: JURISDICCIÓN: | G4: 040 - Ministerio de Salud
A5: SAF: | G5: 011- Dirección Provincial de Administración
A6: UNIDAD EJECUTORA: | G6: 746 - DIRECCION PROVINCIAL DE VECTORES Y ZOONOSIS
A7: DEPENDENCIA SOLICITANTE: | G7: 746 - DIRECCION PROVINCIAL DE VECTORES Y ZOONOSIS
A8: AUTORIZACIÓN:
A9: Señor Jefe de Servicio Administrativo Financiero:
A10: Autorizo la realización de los trámites correspondientes, a fin de proveer a este Organismo los bienes que se detallan en Nota de pedido y Entrega N°04/2021, afectando la erogación resultante a los créditos presupuestarios aprobados a favor de esta Unidad Ejecutora, conforme al siguiente detalle:
A12: IMPUTACIÓN PRESUPUESTARIA
A13: CÓDIGO | O13: DENOMINACIÓN DE LA PARTIDA PRESUPUESTARIA | Q13: IMPORTE
A14: PR | B14: SB | C14: PY | D14: AC | E14: OB | F14: UG | G14: FIN | H14: FUN | I14: I | J14: P | K14: P | L14: SubP | M14: M | N14: FF
A15: 23 | D15: 1 | F15: 4901 | G15: 3 | H15: 1 | I15: 2 | J15: 5 | K15: 6 | M15: 1 | N15: 1.1 | O15: Combustibles y Lubricantes | Q15: 178164
A23: TOTAL DE PESOS: Ciento Setenta y Ocho Mil Ciento Sesenta y Cuatro con 00/100 | Q23: 178164
A24: g
A25: JUSTIFICACIÓN:
A26: Adquisición de Combustibles.

Sheet NP salud y medio ambie
A1: NOTA DE PEDIDO | J1: N° | K1: 05/2021
A3: JURISDICCIÓN: | D3: 040 - Ministerio de Salud
A4: SAF: | D4: 011 - Direccion Provincial de Administración - Ministerio de Salud
A5: UNIDAD EJECUTORA: | D5: 488 - DIRECCION PROVINCIAL DE SALUD Y MEDIO AMBIENTE
A6: DEPENDENCIA SOLICITANTE: | D6: 488 - DIRECCION PROVINCIAL DE SALUD Y MEDIO AMBIENTE
A7: PERIODO UTILIZACIÓN: | D7: 2° TRIMESTRE
A8: OBJETO: | D8: Adquisición de Combustibles.
A10: Ítem | B10: Codigo Item | C10: DESCRIPCIÓN | H10: Adjunta Detalle Técnico | I10: Unidad Medida | J10: Precio Unitario Estimado | K10: Cantidad Solicitada
A12: 1 | B12: =+'Necesidades Trimestrales (2)'!B10 -> 2.5.6-793.31 | C12: =+'NP zoonosis'!C12:G12 -> GAS OIL; PRESENTACION: POR LITRO, USO: MOTORES DIESEL,COMERCIALIZACION: GRADO 3, DESTINO: DPTO. S.F.V. DE CATAMARCA | H12: no | I12: UNIDAD | J12: =+'Necesidades Trimestrales (2)'!AR10 -> 90.9 | K12: 1540 | M12: =+K12*J12 -> 139986
M13: =+K13*J13 -> 0
M14: =+K14*J14 -> 0
M15: =+K15*J15 -> 0
A19: Costo total estimado: Ciento Treinta y Nueve Mil Novecientos Ochenta y Seis con 00/100 | J19: =SUM(M12:M15) -> 139986

Sheet APG salud y medio ambie
A1: EJERCICIO: | D1: 2021 | P1: AUTORIZACION PARA GASTAR
A4: JURISDICCIÓN: | G4: 040 - Ministerio de Salud
A5: SAF: | G5: 011- Dirección Provincial de Administración
A6: UNIDAD EJECUTORA: | G6: 488 - DIRECCION PROVINCIAL DE SALUD Y MEDIO AMBIENTE
A7: DEPENDENCIA SOLICITANTE: | G7: 488 - DIRECCION PROVINCIAL DE SALUD Y MEDIO AMBIENTE
A8: AUTORIZACIÓN:
A9: Señor Jefe de Servicio Administrativo Financiero:
A10: Autorizo la realización de los trámites correspondientes, a fin de proveer a este Organismo los bienes que se detallan en Nota de pedido y Entrega N°05/2021, afectando la erogación resultante a los créditos presupuestarios aprobados a favor de esta Unidad Ejecutora, conforme al siguiente detalle:
A12: IMPUTACIÓN PRESUPUESTARIA
A13: CÓDIGO | O13: DENOMINACIÓN DE LA PARTIDA PRESUPUESTARIA | Q13: IMPORTE
A14: PR | B14: SB | C14: PY | D14: AC | E14: OB | F14: UG | G14: FIN | H14: FUN | I14: I | J14: P | K14: P | L14: SubP | M14: M | N14: FF
A15: 22 | D15: 1 | F15: 4901 | G15: 4 | H15: 4 | I15: 2 | J15: 5 | K15: 6 | M15: 1 | N15: 1.1 | O15: Combustibles y Lubricantes | Q15: 139986
A23: TOTAL DE PESOS: Ciento Treinta y Nueve Mil Novecientos Ochenta y Seis con 00/100 | Q23: =SUM(Q15:Q22) -> 139986
A24: g
A25: JUSTIFICACIÓN:
A26: Adquisición de Combustibles.

Sheet NP sasp
A1: NOTA DE PEDIDO | J1: N° | K1: 06/2021
A3: JURISDICCIÓN: | D3: 040 - Ministerio de Salud
A4: SAF: | D4: 011 - Direccion Provincial de Administración - Ministerio de Salud
A5: UNIDAD EJECUTORA: | D5: 743 - Secretaria de Asistencia en Salud Publica
A6: DEPENDENCIA SOLICITANTE: | D6: 743 - Secretaria de Asistencia en Salud Publica
A7: PERIODO UTILIZACIÓN: | D7: 2° TRIMESTRE
A8: OBJETO: | D8: Adquisición de Combustibles.
A10: Ítem | B10: Codigo Item | C10: DESCRIPCIÓN | H10: Adjunta Detalle Técnico | I10: Unidad Medida | J10: Precio Unitario Estimado | K10: Cantidad Solicitada
A12: 1 | B12: =+'Necesidades Trimestrales (2)'!B10 -> 2.5.6-793.31 | C12: =+'NP salud y medio ambie'!C12:G12 -> GAS OIL; PRESENTACION: POR LITRO, USO: MOTORES DIESEL,COMERCIALIZACION: GRADO 3, DESTINO: DPTO. S.F.V. DE CATAMARCA | H12: no | I12: UNIDAD | J12: =+'Necesidades Trimestrales (2)'!AR10 -> 90.9 | K12: 1980 | M12: =+K12*J12 -> 179982
M13: =+K13*J13 -> 0
M14: =+K14*J14 -> 0
M15: =+K15*J15 -> 0
A19: Costo total estimado: Ciento Setenta y Nueve Mil Novecientos Ochenta y Dos con 00/100 | J19: =SUM(M12:M15) -> 179982

Sheet APG sasp
A1: EJERCICIO: | D1: 2021 | P1: AUTORIZACION PARA GASTAR
A4: JURISDICCIÓN: | G4: 040 - Ministerio de Salud
A5: SAF: | G5: 011- Dirección Provincial de Administración
A6: UNIDAD EJECUTORA: | G6: 743 - Secretaria de Asistencia en Salud Publica
A7: DEPENDENCIA SOLICITANTE: | G7: 743 - Secretaria de Asistencia en Salud Publica
A8: AUTORIZACIÓN:
A9: Señor Jefe de Servicio Administrativo Financiero:
A10: Autorizo la realización de los trámites correspondientes, a fin de proveer a este Organismo los bienes que se detallan en Nota de pedido y Entrega N°06/2021, afectando la erogación resultante a los créditos presupuestarios aprobados a favor de esta Unidad Ejecutora, conforme al siguiente detalle:
A12: IMPUTACIÓN PRESUPUESTARIA
A13: CÓDIGO | O13: DENOMINACIÓN DE LA PARTIDA PRESUPUESTARIA | Q13: IMPORTE
A14: PR | B14: SB | C14: PY | D14: AC | E14: OB | F14: UG | G14: FIN | H14: FUN | I14: I | J14: P | K14: P | L14: SubP | M14: M | N14: FF
A15: 3 | D15: 1 | F15: 4901 | G15: 1 | H15: 3 | I15: 2 | J15: 5 | K15: 6 | M15: 1 | N15: 1.1 | O15: Combustibles y Lubricantes | Q15: 179982
A23: TOTAL DE PESOS: Ciento Setenta y Nueve Mil Novecientos Ochenta y Dos con 00/100 | Q23: =SUM(Q15:Q22) -> 179982
A24: g
A25: JUSTIFICACIÓN:
A26: Adquisición de Combustibles.

Sheet NP MATERNO
A1: NOTA DE PEDIDO | J1: N° | K1: 04/2021
A3: JURISDICCIÓN: | D3: 040 - Ministerio de Salud
A4: SAF: | D4: 011 - Direccion Provincial de Administración - Ministerio de Salud
A5: UNIDAD EJECUTORA: | D5: 162 - DIR PROVINCIAL MATERNIDAD, INFANCIA Y ADOLESCENCIA
A6: DEPENDENCIA SOLICITANTE: | D6: 162 - DIR PROVINCIAL MATERNIDAD, INFANCIA Y ADOLESCENCIA
A7: PERIODO UTILIZACIÓN: | D7: 2° TRIMESTRE
A8: OBJETO: | D8: Adquisición de Combustibles.
A10: Ítem | B10: Codigo Item | C10: DESCRIPCIÓN | H10: Adjunta Detalle Técnico | I10: Unidad Medida | J10: Precio Unitario Estimado | K10: Cantidad Solicitada
A12: 1 | B12: =+'Necesidades Trimestrales (2)'!B10 -> 2.5.6-793.31 | C12: =+'NP sasp'!C12:G12 -> GAS OIL; PRESENTACION: POR LITRO, USO: MOTORES DIESEL,COMERCIALIZACION: GRADO 3, DESTINO: DPTO. S.F.V. DE CATAMARCA | H12: no | I12: UNIDAD | J12: =+'Necesidades Trimestrales (2)'!AR10 -> 90.9 | K12: 3020 | M12: =+K12*J12 -> 274518
M13: =+K13*J13 -> 0
M14: =+K14*J14 -> 0
M15: =+K15*J15 -> 0
A19: Costo total estimado: Doscientos Setenta y Cuatro Mil Quinientos Dieciocho con 00/100 | J19: =SUM(M12:M15) -> 274518

Sheet APG MATERNO
A1: EJERCICIO: | D1: 2021 | P1: AUTORIZACION PARA GASTAR
A4: JURISDICCIÓN: | G4: 040 - Ministerio de Salud
A5: SAF: | G5: 011- Dirección Provincial de Administración
A6: UNIDAD EJECUTORA: | G6: 162 - DIR PROVINCIAL MATERNIDAD, INFANCIA Y ADOLESCENCIA
A7: DEPENDENCIA SOLICITANTE: | G7: 162 - DIR PROVINCIAL MATERNIDAD, INFANCIA Y ADOLESCENCIA
A8: AUTORIZACIÓN:
A9: Señor Jefe de Servicio Administrativo Financiero:
A10: Autorizo la realización de los trámites correspondientes, a fin de proveer a este Organismo los bienes que se detallan en Nota de pedido y Entrega N°04/2021, afectando la erogación resultante a los créditos presupuestarios aprobados a favor de esta Unidad Ejecutora, conforme al siguiente detalle:
A12: IMPUTACIÓN PRESUPUESTARIA
A13: CÓDIGO | O13: DENOMINACIÓN DE LA PARTIDA PRESUPUESTARIA | Q13: IMPORTE
A14: PR | B14: SB | C14: PY | D14: AC | E14: OB | F14: UG | G14: FIN | H14: FUN | I14: I | J14: P | K14: P | L14: SubP | M14: M | N14: FF
A15: 20 | D15: 1 | F15: 4901 | G15: 3 | H15: 1 | I15: 2 | J15: 5 | K15: 6 | M15: 1 | N15: 1.1 | O15: Combustibles y Lubricantes | Q15: 274518
A23: TOTAL DE PESOS: Doscientos Setenta y Cuatro Mil Quinientos Dieciocho con 00/100 | Q23: =SUM(Q15:Q22) -> 274518
A25: JUSTIFICACIÓN:
A26: Adquisición de Combustibles.

Sheet NP SAME
A1: NOTA DE PEDIDO | J1: N° | K1: 09/2021
A3: JURISDICCIÓN: | D3: 040 - Ministerio de Salud
A4: SAF: | D4: 011 - Direccion Provincial de Administración - Ministerio de Salud
A5: UNIDAD EJECUTORA: | D5: 748 - DIRECCION PROVINCIAL DEL SISTEMA DE ATENCION MEDICA DE EMERGENCIA
A6: DEPENDENCIA SOLICITANTE: | D6: 748 - DIRECCION PROVINCIAL DEL SISTEMA DE ATENCION MEDICA DE EMERGENCIA
A7: PERIODO UTILIZACIÓN: | D7: 2° TRIMESTRE
A8: OBJETO: | D8: Adquisición de Combustibles.
A10: Ítem | B10: Codigo Item | C10: DESCRIPCIÓN | H10: Adjunta Detalle Técnico | I10: Unidad Medida | J10: Precio Unitario Estimado | K10: Cantidad Solicitada
A12: 1 | B12: =+'Necesidades Trimestrales (2)'!B10 -> 2.5.6-793.31 | C12: =+'NP MATERNO'!C12:G12 -> GAS OIL; PRESENTACION: POR LITRO, USO: MOTORES DIESEL,COMERCIALIZACION: GRADO 3, DESTINO: DPTO. S.F.V. DE CATAMARCA | H12: no | I12: UNIDAD | J12: =+'Necesidades Trimestrales (2)'!AR10 -> 90.9 | K12: 11870 | M12: =+K12*J12 -> 1078983
M13: =+K13*J13 -> 0
M14: =+K14*J14 -> 0
M15: =+K15*J15 -> 0
A19: Costo total estimado: Un Millon Setenta y Ocho Mil Novecientos Ochenta y Tres con 00/100 | J19: =SUM(M12:M15) -> 1078983

Sheet APG SAME
A1: EJERCICIO: | D1: 2021 | P1: AUTORIZACION PARA GASTAR
A4: JURISDICCIÓN: | G4: 040 - Ministerio de Salud
A5: SAF: | G5: 011- Dirección Provincial de Administración
A6: UNIDAD EJECUTORA: | G6: 748 - DIR PROVINCIAL DEL SISTEMA DE ATENCION MEDICA DE EMERGENCIA
A7: DEPENDENCIA SOLICITANTE: | G7: 748 - DIR PROVINCIAL DEL SISTEMA DE ATENCION MEDICA DE EMERGENCIA
A8: AUTORIZACIÓN:
A9: Señor Jefe de Servicio Administrativo Financiero:
A10: Autorizo la realización de los trámites correspondientes, a fin de proveer a este Organismo los bienes que se detallan en Nota de pedido y Entrega N°09/2021, afectando la erogación resultante a los créditos presupuestarios aprobados a favor de esta Unidad Ejecutora, conforme al siguiente detalle:
A12: IMPUTACIÓN PRESUPUESTARIA
A13: CÓDIGO | O13: DENOMINACIÓN DE LA PARTIDA PRESUPUESTARIA | Q13: IMPORTE
A14: PR | B14: SB | C14: PY | D14: AC | E14: OB | F14: UG | G14: FIN | H14: FUN | I14: I | J14: P | K14: P | L14: SubP | M14: M | N14: FF
A15: 31 | D15: 1 | F15: 4901 | G15: 3 | H15: 1 | I15: 2 | J15: 5 | K15: 6 | M15: 1 | N15: 1.1 | O15: Combustibles y Lubricantes | Q15: 1078983
A23: TOTAL DE PESOS: Un Millon Setenta y Ocho Mil Novecientos Ochenta y Tres con 00/100 | Q23: =SUM(Q15:Q22) -> 1078983
A25: JUSTIFICACIÓN:
A26: Adquisición de Combustibles.

Sheet NP CANCER
A1: NOTA DE PEDIDO | J1: N° | K1: 07/2021
A3: JURISDICCIÓN: | D3: 040 - Ministerio de Salud
A4: SAF: | D4: 011 - Direccion Provincial de Administración - Ministerio de Salud
A5: UNIDAD EJECUTORA: | D5: 159 - DIRECCION PROVINCIAL DE CANCER
A6: DEPENDENCIA SOLICITANTE: | D6: 159 - DIRECCION PROVINCIAL DE CANCER
A7: PERIODO UTILIZACIÓN: | D7: 2° TRIMESTRE
A8: OBJETO: | D8: Adquisición de Combustibles.
A10: Ítem | B10: Codigo Item | C10: DESCRIPCIÓN | H10: Adjunta Detalle Técnico | I10: Unidad Medida | J10: Precio Unitario Estimado | K10: Cantidad Solicitada
A12: 1 | B12: =+'Necesidades Trimestrales (2)'!B10 -> 2.5.6-793.31 | C12: =+'NP SAME'!C12:G12 -> GAS OIL; PRESENTACION: POR LITRO, USO: MOTORES DIESEL,COMERCIALIZACION: GRADO 3, DESTINO: DPTO. S.F.V. DE CATAMARCA | H12: no | I12: UNIDAD | J12: =+'Necesidades Trimestrales (2)'!AR10 -> 90.9 | K12: 1080 | M12: =+K12*J12 -> 98172
M13: =+K13*J13 -> 0
M14: =+K14*J14 -> 0
M15: =+K15*J15 -> 0
A19: Costo total estimado: Noventa y Ocho Mil Ciento Setenta y Dos con 00/100 | J19: =SUM(M12:M15) -> 98172

Sheet APG CANCER
A1: EJERCICIO: | D1: 2021 | P1: AUTORIZACION PARA GASTAR
A4: JURISDICCIÓN: | G4: 040 - Ministerio de Salud
A5: SAF: | G5: 011- Dirección Provincial de Administración
A6: UNIDAD EJECUTORA: | G6: 159 - DIRECCION PROVINCIAL DE CANCER
A7: DEPENDENCIA SOLICITANTE: | G7: 159 - DIRECCION PROVINCIAL DE CANCER
A8: AUTORIZACIÓN:
A9: Señor Jefe de Servicio Administrativo Financiero:
A10: Autorizo la realización de los trámites correspondientes, a fin de proveer a este Organismo los bienes que se detallan en Nota de pedido y Entrega N°07/2021, afectando la erogación resultante a los créditos presupuestarios aprobados a favor de esta Unidad Ejecutora, conforme al siguiente detalle:
A12: IMPUTACIÓN PRESUPUESTARIA
A13: CÓDIGO | O13: DENOMINACIÓN DE LA PARTIDA PRESUPUESTARIA | Q13: IMPORTE
A14: PR | B14: SB | C14: PY | D14: AC | E14: OB | F14: UG | G14: FIN | H14: FUN | I14: I | J14: P | K14: P | L14: SubP | M14: M | N14: FF
A15: 44 | D15: 1 | F15: 4901 | G15: 3 | H15: 1 | I15: 2 | J15: 5 | K15: 6 | M15: 1 | N15: 1.1 | O15: Combustibles y Lubricantes | Q15: 98172
A23: TOTAL DE PESOS: Noventa y Ocho Mil Ciento Setenta y Dos con 00/100 | Q23: =SUM(Q15:Q22) -> 98172
A25: JUSTIFICACIÓN:
A26: Adquisición de Combustibles.

Sheet NP BCO DE SANGRE
A1: NOTA DE PEDIDO | J1: N° | K1: 05/2021
A3: JURISDICCIÓN: | D3: 040 - Ministerio de Salud
A4: SAF: | D4: 011 - Direccion Provincial de Administración - Ministerio de Salud
A5: UNIDAD EJECUTORA: | D5: 747 - DIRECCION PROVINCIAL BANCO DE SANGRE
A6: DEPENDENCIA SOLICITANTE: | D6: 747 - DIRECCION PROVINCIAL BANCO DE SANGRE
A7: PERIODO UTILIZACIÓN: | D7: 2° TRIMESTRE
A8: OBJETO: | D8: Adquisición de Combustibles.
A10: Ítem | B10: Codigo Item | C10: DESCRIPCIÓN | H10: Adjunta Detalle Técnico | I10: Unidad Medida | J10: Precio Unitario Estimado | K10: Cantidad Solicitada
A12: 1 | B12: =+'Necesidades Trimestrales (2)'!B10 -> 2.5.6-793.31 | C12: =+'NP CANCER'!C12:G12 -> GAS OIL; PRESENTACION: POR LITRO, USO: MOTORES DIESEL,COMERCIALIZACION: GRADO 3, DESTINO: DPTO. S.F.V. DE CATAMARCA | H12: no | I12: UNIDAD | J12: =+'Necesidades Trimestrales (2)'!AR10 -> 90.9 | K12: 150 | M12: =+K12*J12 -> 13635
M13: =+K13*J13 -> 0
M14: =+K14*J14 -> 0
M15: =+K15*J15 -> 0
A19: Costo total estimado: Trece Mil Seiscientos Treinta y Cinco con 00/100 | J19: =SUM(M12:M15) -> 13635

Sheet APG BCO DE SANGRE
A1: EJERCICIO: | D1: 2021 | P1: AUTORIZACION PARA GASTAR
A4: JURISDICCIÓN: | G4: 040 - Ministerio de Salud
A5: SAF: | G5: 011- Dirección Provincial de Administración
A6: UNIDAD EJECUTORA: | G6: 747 - DIRECCION PROVINCIAL BANCO DE SANGRE
A7: DEPENDENCIA SOLICITANTE: | G7: 747 - DIRECCION PROVINCIAL BANCO DE SANGRE
A8: AUTORIZACIÓN:
A9: Señor Jefe de Servicio Administrativo Financiero:
A10: Autorizo la realización de los trámites correspondientes, a fin de proveer a este Organismo los bienes que se detallan en Nota de pedido y Entrega N°05/2021, afectando la erogación resultante a los créditos presupuestarios aprobados a favor de esta Unidad Ejecutora, conforme al siguiente detalle:
A12: IMPUTACIÓN PRESUPUESTARIA
A13: CÓDIGO | O13: DENOMINACIÓN DE LA PARTIDA PRESUPUESTARIA | Q13: IMPORTE
A14: PR | B14: SB | C14: PY | D14: AC | E14: OB | F14: UG | G14: FIN | H14: FUN | I14: I | J14: P | K14: P | L14: SubP | M14: M | N14: FF
A15: 27 | D15: 1 | F15: 4901 | G15: 3 | H15: 1 | I15: 2 | J15: 5 | K15: 6 | M15: 1 | N15: 1.1 | O15: Combustibles y Lubricantes | Q15: 13635
A23: TOTAL DE PESOS: Trece Mil Seiscientos Treinta y Cinco con 00/100 | Q23: =SUM(Q15:Q22) -> 13635
A25: JUSTIFICACIÓN:
A26: Adquisición de Combustibles.

Sheet NP ATENCION PRIMARIA
A1: NOTA DE PEDIDO | J1: N° | K1: 07/2021
A3: JURISDICCIÓN: | D3: 040 - Ministerio de Salud
A4: SAF: | D4: 011 - Direccion Provincial de Administración - Ministerio de Salud
A5: UNIDAD EJECUTORA: | D5: 750 - DIRECCION PROVINCIAL PRIMER NIVEL DE ATENCION PRIMARIA
A6: DEPENDENCIA SOLICITANTE: | D6: 750 - DIRECCION PROVINCIAL PRIMER NIVEL DE ATENCION PRIMARIA
A7: PERIODO UTILIZACIÓN: | D7: 2° TRIMESTRE
A8: OBJETO: | D8: Adquisición de Combustibles.
A10: Ítem | B10: Codigo Item | C10: DESCRIPCIÓN | H10: Adjunta Detalle Técnico | I10: Unidad Medida | J10: Precio Unitario Estimado | K10: Cantidad Solicitada
A12: 1 | B12: =+'Necesidades Trimestrales (2)'!B10 -> 2.5.6-793.31 | C12: =+'NP BCO DE SANGRE'!C12:G12 -> GAS OIL; PRESENTACION: POR LITRO, USO: MOTORES DIESEL,COMERCIALIZACION: GRADO 3, DESTINO: DPTO. S.F.V. DE CATAMARCA | H12: no | I12: UNIDAD | J12: =+'Necesidades Trimestrales (2)'!AR10 -> 90.9 | K12: 860 | M12: =+K12*J12 -> 78174
M13: =+K13*J13 -> 0
M14: =+K14*J14 -> 0
M15: =+K15*J15 -> 0
A19: Costo total estimado: Setenta y Ocho Mil Ciento Setenta y Cuatro con 00/100 | J19: =SUM(M12:M15) -> 78174

Sheet APG ATENCION PRIMARIA
A1: EJERCICIO: | D1: 2021 | P1: AUTORIZACION PARA GASTAR
A4: JURISDICCIÓN: | G4: 040 - Ministerio de Salud
A5: SAF: | G5: 011- Dirección Provincial de Administración
A6: UNIDAD EJECUTORA: | G6: 750 - DIRECCION PROVINCIAL PRIMER NIVEL DE ATENCION PRIMARIA
A7: DEPENDENCIA SOLICITANTE: | G7: 750 - DIRECCION PROVINCIAL PRIMER NIVEL DE ATENCION PRIMARIA
A8: AUTORIZACIÓN:
A9: Señor Jefe de Servicio Administrativo Financiero:
A10: Autorizo la realización de los trámites correspondientes, a fin de proveer a este Organismo los bienes que se detallan en Nota de pedido y Entrega N°07/2021, afectando la erogación resultante a los créditos presupuestarios aprobados a favor de esta Unidad Ejecutora, conforme al siguiente detalle:
A12: IMPUTACIÓN PRESUPUESTARIA
A13: CÓDIGO | O13: DENOMINACIÓN DE LA PARTIDA PRESUPUESTARIA | Q13: IMPORTE
A14: PR | B14: SB | C14: PY | D14: AC | E14: OB | F14: UG | G14: FIN | H14: FUN | I14: I | J14: P | K14: P | L14: SubP | M14: M | N14: FF
A15: 47 | D15: 1 | F15: 4901 | G15: 3 | H15: 1 | I15: 2 | J15: 5 | K15: 6 | M15: 1 | N15: 1.1 | O15: Combustibles y Lubricantes | Q15: 78174
A23: TOTAL DE PESOS: Setenta y Ocho Mil Ciento Setenta y Cuatro con 00/100 | Q23: =SUM(Q15:Q22) -> 78174
A25: JUSTIFICACIÓN:
A26: Adquisición de Combustibles.
