Workbook

Sheet Necesidades Trimestrales
A1: 2022
B2: Pedido de Necesidades Trimestrales
A4: JURISDICCION: | C4: 040 - Ministerio de Salud
A5: SAF N°: | C5: 011 - Direccion Provincial de Administracion - MS
A6: EJERCICIO: | C6: 2022
A7: TRIMESTRE: | C7: 4
A9: ID | B9: CODIGO ITEM | C9: RUBRO DE COMPRA | D9: I.P.P. | E9: DESCRIPCION | F9: UNIDAD DE MEDIDA | G9: CANTIDAD DPF | H9: PRECIO UNITARIO ESTIMADO | I9: IMPORTE TOTAL ESTIMADO
A10: 1 | B10: 2.5.2-1724.16 | C10: PROD. MEDICO/FARMACEUTICOS/LAB | D10: 252 | E10: ANALGESICOS; TIPO: MONODROGA, DROGA GENERICA: ACIDO ACETILSALICILICO, PRESENTACION: 100 mGr, FORMA FARMACEUTICA: COMPRIMIDO | F10: COMPRIMIDO | G10: =25000+700 -> 25700 | H10: 1.88 | I10: =+G10*H10 -> 48316 | J10: 5 | L10: 48316
A11: 2 | B11: 2.5.2-1821.524 | C11: PROD. MEDICO/FARMACEUTICOS/LAB | D11: 252 | E11: ANTIBIOTICOS P/PERSONAS; TIPO: ASOCIACION, DROGA GENERICA: AMOXICILINA + AC.CLAVULANICO 400 MG / 57 MG, FORMA FARMACEUTICA: SUSPENSION, PRESENTACION: ENVASE X 70 ML | F11: FRASCO | G11: 12000 | H11: 410 | I11: =+G11*H11 -> 4920000 | J11: 9 | L11: 4920000
A12: 3 | B12: 2.5.2-1821.440 | C12: PROD. MEDICO/FARMACEUTICOS/LAB | D12: 252 | E12: ANTIBIOTICOS P/PERSONAS; TIPO: ASOCIACION, DROGA GENERICA: AMOXICIL. 875 MG+CLAVUL.125 MG mGr, FORMA FARMACEUTICA: COMPRIMIDO, PRESENTACION: UNIDAD | F12: COMPRIMIDO | G12: 250000 | H12: 38 | I12: =+G12*H12 -> 9500000 | J12: 10 | L12: 9500000
A13: 4 | B13: 2.5.2-1821.9 | C13: PROD. MEDICO/FARMACEUTICOS/LAB | D13: 252 | E13: ANTIBIOTICOS P/PERSONAS; TIPO: MONODROGA, DROGA GENERICA: AMOXICILINA, PRESENTACION: 500 mGr, FORMA FARMACEUTICA: COMPRIMIDOS | F13: COMPRIMIDO | G13: 100000 | H13: 15 | I13: =+G13*H13 -> 1500000 | J13: 11 | L13: 1500000
A14: 5 | B14: 2.5.2-1821.399 | C14: PROD. MEDICO/FARMACEUTICOS/LAB | D14: 252 | E14: ANTIBIOTICOS P/PERSONAS; TIPO: MONODROGA, DROGA GENERICA: AMOXICILINA 500 mGr, FORMA FARMACEUTICA: SUSPENSION, PRESENTACION: ENVASE X 90 mL | F14: FRASCO | G14: 10000 | H14: 320 | I14: =+G14*H14 -> 3200000 | J14: 12 | L14: 3200000
A15: 6 | B15: 2.5.2-1821.389 | C15: PROD. MEDICO/FARMACEUTICOS/LAB | D15: 252 | E15: ANTIBIOTICOS P/PERSONAS; TIPO: ASOCIACION, DROGA GENERICA: AMPICILINA + SULBACTAN, FORMA FARMACEUTICA: FRASCO AMPOLLA, PRESENTACION: ENVASE X 1,5 GR | F15: AMPOLLA | G15: 22000 | H15: 145 | I15: =+G15*H15 -> 3190000 | J15: 13 | L15: 3190000
A16: 7 | B16: 2.5.2-1821.8 | C16: PROD. MEDICO/FARMACEUTICOS/LAB | D16: 252 | E16: ANTIBIOTICOS P/PERSONAS; TIPO: MONODROGA, DROGA GENERICA: AMPICILINA, FORMA FARMACEUTICA: AMPOLLA, PRESENTACION: 1 GR | F16: AMPOLLA | G16: 15000 | H16: 99 | I16: =+G16*H16 -> 1485000 | J16: 14 | L16: 1485000
A17: 8 | B17: 2.5.2-1821.502 | C17: PROD. MEDICO/FARMACEUTICOS/LAB | D17: 252 | E17: ANTIBIOTICOS P/PERSONAS; TIPO: MONODROGA, DROGA GENERICA: AZITROMICINA 200 mGr, FORMA FARMACEUTICA: SUSPENSION, PRESENTACION: ENVASE X 15 Ml | F17: FRASCO | G17: 12000 | H17: 562.5 | I17: =+G17*H17 -> 6750000 | J17: 18 | L17: 6750000
A18: 9 | B18: 2.5.2-1821.94 | C18: PROD. MEDICO/FARMACEUTICOS/LAB | D18: 252 | E18: ANTIBIOTICOS P/PERSONAS; TIPO: MONODROGA, DROGA GENERICA: AZITROMICINA, FORMA FARMACEUTICA: COMPRIMIDO, PRESENTACION: 500 mGr | F18: COMPRIMIDO | G18: 25000 | H18: 37.45 | I18: =+G18*H18 -> 936250 | J18: 20 | L18: 936250
A19: 10 | B19: 2.5.2-1883.188 | C19: PROD. MEDICO/FARMACEUTICOS/LAB | D19: 252 | E19: ANESTESICOS LOCALES; TIPO: MONODROGA, DROGA GENERICA: BUPIVACAINA 0,5% HIPERBARICA, FORMA FARMACEUTICA: AMPOLLA, PRESENTACION: 4 ML CON AGUJA 27 G X 3 1/2 CON INTRODUCTOR | F19: AMPOLLA | G19: 200 | H19: 1420 | I19: =+G19*H19 -> 284000 | J19: 27 | L19: 284000
A20: 11 | B20: 2.5.2-1821.321 | C20: PROD. MEDICO/FARMACEUTICOS/LAB | D20: 252 | E20: ANTIBIOTICOS P/PERSONAS; TIPO: MONODROGA, DROGA GENERICA: CEFALEXINA 500 mGr, FORMA FARMACEUTICA: COMPRIMIDO, PRESENTACION: 1 UN | F20: COMPRIMIDO | G20: 60000 | H20: 15.3 | I20: =+G20*H20 -> 918000 | J20: 28 | L20: 918000
A21: 12 | B21: 2.5.2-1821.337 | C21: PROD. MEDICO/FARMACEUTICOS/LAB | D21: 252 | E21: ANTIBIOTICOS P/PERSONAS; TIPO: MONODROGA, DROGA GENERICA: CEFALEXINA 500MG, FORMA FARMACEUTICA: SUSPENSION, PRESENTACION: ENVASE X 90 mL | F21: FRASCO | G21: 6000 | H21: 298 | I21: =+G21*H21 -> 1788000 | J21: 29 | L21: 1788000
A22: 13 | B22: 2.5.2-1821.405 | C22: PROD. MEDICO/FARMACEUTICOS/LAB | D22: 252 | E22: ANTIBIOTICOS P/PERSONAS; TIPO: MONODROGA, DROGA GENERICA: CEFALOTINA SODICA, FORMA FARMACEUTICA: FRASCO AMPOLLA, PRESENTACION: 1 GR | F22: AMPOLLA | G22: 12000 | H22: 145 | I22: =+G22*H22 -> 1740000 | J22: 30 | L22: 1740000
... A28: 19 | B28: 2.5.2-1724.140 | C28: PROD. MEDICO/FARMACEUTICOS/LAB | D28: 252 | E28: ANALGESICOS; TIPO: MONODROGA, DROGA GENERICA: DICLOFENAC X 75 MG, FORMA FARMACEUTICA: COMPRIMIDO, PRESENTACION: UNIDAD | F28: COMPRIMIDO | G28: 250000 | H28: 3.05 | I28: =+G28*H28 -> 762500 | J28: 51 | L28: 762500
A29: 20 | B29: 2.5.2-1724.117 | C29: PROD. MEDICO/FARMACEUTICOS/LAB | D29: 252 | E29: ANALGESICOS; TIPO: ASOCIACION, DROGA GENERICA: DICLOFENAC SODICO, FORMA FARMACEUTICA: AMPOLLA, PRESENTACION: 3 Ml | F29: AMPOLLA | G29: =100000+500 -> 100500 | H29: 35.9 | I29: =+G29*H29 -> 3607950 | J29: 52 | L29: 3607950
A30: 21 | B30: 2.5.2-1724.208 | C30: PROD. MEDICO/FARMACEUTICOS/LAB | D30: 252 | E30: ANALGESICOS; TIPO: MONODROGA, DROGA GENERICA: DIPIRONA SODICA 1 GR, FORMA FARMACEUTICA: AMPOLLA, PRESENTACION: 2 mL | F30: AMPOLLA | G30: =120000+500 -> 120500 | H30: 38.5 | I30: =+G30*H30 -> 4639250 | J30: 54 | L30: 4639250
A31: 22 | B31: 2.5.2-1724.74 | C31: PROD. MEDICO/FARMACEUTICOS/LAB | D31: 252 | E31: ANALGESICOS; TIPO: MONODROGA, DROGA GENERICA: DIPIRONA, FORMA FARMACEUTICA: JARABE, PRESENTACION: FRASCO X 120 mL | F31: FRASCO | G31: 10000 | H31: 698 | I31: =+G31*H31 -> 6980000 | J31: 55 | L31: 6980000
A32: 23 | B32: 2.5.2-1821.458 | C32: PROD. MEDICO/FARMACEUTICOS/LAB | D32: 252 | E32: ANTIBIOTICOS P/PERSONAS; TIPO: MONODROGA, DROGA GENERICA: DOXICICLINA 100 mGr, FORMA FARMACEUTICA: COMPRIMIDO, PRESENTACION: UNIDAD | F32: COMPRIMIDO | G32: 2000 | H32: 62.17 | I32: =+G32*H32 -> 124340 | J32: 56 | L32: 124340
A33: 24 | B33: 2.5.2-1821.238 | C33: PROD. MEDICO/FARMACEUTICOS/LAB | D33: 252 | E33: ANTIBIOTICOS P/PERSONAS; TIPO: MONODROGA, DROGA GENERICA: FLUCONAZOL 100 MG, FORMA FARMACEUTICA: COMPRIMIDO, PRESENTACION: 100 mGr | F33: COMPRIMIDO | G33: 1000 | H33: 36 | I33: =+G33*H33 -> 36000 | J33: 59 | L33: 36000
A34: 25 | B34: 2.5.2-1821.4 | C34: PROD. MEDICO/FARMACEUTICOS/LAB | D34: 252 | E34: ANTIBIOTICOS P/PERSONAS; DROGA GENERICA: GENTAMICINA, FORMA FARMACEUTICA: AMPOLLA, PRESENTACION: 80 mGr, TIPO: MONODROGA | F34: AMPOLLA | G34: 16000 | H34: 42 | I34: =+G34*H34 -> 672000 | J34: 66 | L34: 672000
A35: 26 | B35: 2.5.2-1724.163 | C35: PROD. MEDICO/FARMACEUTICOS/LAB | D35: 252 | E35: ANALGESICOS; TIPO: MONODROGA, DROGA GENERICA: IBUPROFENO 2%, FORMA FARMACEUTICA: SUSPENSION, PRESENTACION: ENVASE X 90 mL | F35: FRASCO | G35: =20000+50 -> 20050 | H35: 110 | I35: =+G35*H35 -> 2205500 | J35: 67 | L35: 2205500
A36: 27 | B36: 2.5.2-1725.68 | C36: PROD. MEDICO/FARMACEUTICOS/LAB | D36: 252 | E36: ANTIINFLAMATORIOS NO ESTEROIDE; TIPO: MONODROGA, DROGA GENERICA: IBUPROFENO, FORMA FARMACEUTICA: COMPRIMIDO, PRESENTACION: 400 mGr | F36: COMPRIMIDO | G36: =150000+1000 -> 151000 | H36: 4.8 | I36: =+G36*H36 -> 724800 | J36: 69 | L36: 724800
A37: 28 | B37: 2.5.2-1725.49 | C37: PROD. MEDICO/FARMACEUTICOS/LAB | D37: 252 | E37: ANTIINFLAMATORIOS NO ESTEROIDE; DROGA GENERICA: KETOROLAC, FORMA FARMACEUTICA: COMPRIMIDO, PRESENTACION: 10 mGr, TIPO: MONODROGA | F37: COMPRIMIDO | G37: =40000+500 -> 40500 | H37: 4.95 | I37: =+G37*H37 -> 200475 | J37: 79 | L37: 200475
A38: 29 | B38: 2.5.2-1724.23 | C38: PROD. MEDICO/FARMACEUTICOS/LAB | D38: 252 | E38: ANALGESICOS; TIPO: MONODROGA, DROGA GENERICA: KETOROLAC, FORMA FARMACEUTICA: AMPOLLA, PRESENTACION: 30 mGr | F38: AMPOLLA | G38: 10000 | H38: 59 | I38: =+G38*H38 -> 590000 | J38: 80 | L38: 590000
A39: 30 | B39: 2.5.2-1821.71 | C39: PROD. MEDICO/FARMACEUTICOS/LAB | D39: 252 | E39: ANTIBIOTICOS P/PERSONAS; TIPO: MONODROGA, DROGA GENERICA: LEVOFLOXACINA, PRESENTACION: 500 mGr, FORMA FARMACEUTICA: COMPRIMIDO | F39: COMPRIMIDO | G39: 10000 | H39: 18 | I39: =+G39*H39 -> 180000 | J39: 81 | L39: 180000
A40: 31 | B40: 2.5.2-1883.186 | C40: PROD. MEDICO/FARMACEUTICOS/LAB | D40: 252 | E40: ANESTESICOS LOCALES; TIPO: MONODROGA, DROGA GENERICA: LIDOCAINA 2%S/EPINEFRINA, FORMA FARMACEUTICA: AMPOLLA, PRESENTACION: 5 mL | F40: AMPOLLA | G40: 20000 | H40: 33 | I40: =+G40*H40 -> 660000 | J40: 82 | L40: 660000
A41: 32 | B41: 2.5.2-1883.111 | C41: PROD. MEDICO/FARMACEUTICOS/LAB | D41: 252 | E41: ANESTESICOS LOCALES; TIPO: ASOCIACION, DROGA GENERICA: LIDOCAINA 2% C/EPINEFRINA, FORMA FARMACEUTICA: FRASCO AMPOLLA, PRESENTACION: 20 mL | F41: AMPOLLA | G41: 500 | H41: 493 | I41: =+G41*H41 -> 246500 | J41: 84 | L41: 246500
A42: 33 | B42: 2.5.2-1883.19 | C42: PROD. MEDICO/FARMACEUTICOS/LAB | D42: 252 | E42: ANESTESICOS LOCALES; TIPO: MONODROGA, DROGA GENERICA: LIDOCAINA VISCOSA, FORMA FARMACEUTICA: ENVASE, PRESENTACION: 50 mL | F42: UNIDAD | G42: 30 | H42: 245 | I42: =+G42*H42 -> 7350 | J42: 87 | L42: 7350
A43: 34 | B43: 2.5.2-1857.12 | C43: PROD. MEDICO/FARMACEUTICOS/LAB | D43: 252 | E43: ANTIPARASITARIOS; TIPO: MONODROGA, DROGA GENERICA: MEBENDAZOL, FORMA FARMACEUTICA: COMPRIMIDOS, PRESENTACION: 100 mGr | F43: COMPRIMIDO | G43: 5000 | H43: 135 | I43: =+G43*H43 -> 675000 | J43: 89 | L43: 675000
A44: 35 | B44: 2.5.2-1857.36 | C44: PROD. MEDICO/FARMACEUTICOS/LAB | D44: 252 | E44: ANTIPARASITARIOS; TIPO: MONODROGA, DROGA GENERICA: MEBENDAZOL 2%, FORMA FARMACEUTICA: SUSPENSION, PRESENTACION: ENVASE X 30 mL | F44: FRASCO | G44: 2000 | H44: 220 | I44: =+G44*H44 -> 440000 | J44: 90 | L44: 440000
A45: 36 | B45: 2.5.2-1821.334 | C45: PROD. MEDICO/FARMACEUTICOS/LAB | D45: 252 | E45: ANTIBIOTICOS P/PERSONAS; TIPO: MONODROGA, DROGA GENERICA: METRONIDAZOL 125MG/5ML, FORMA FARMACEUTICA: SUSPENSION ORAL, PRESENTACION: ENVASE X 120 mL | F45: FRASCO | G45: 1000 | H45: 169 | I45: =+G45*H45 -> 169000 | J45: 93 | L45: 169000
A46: 37 | B46: 2.5.2-1821.76 | C46: PROD. MEDICO/FARMACEUTICOS/LAB | D46: 252 | E46: ANTIBIOTICOS P/PERSONAS; TIPO: MONODROGA, FORMA FARMACEUTICA: COMPRIMIDO, PRESENTACION: 500 mGr, DROGA GENERICA: METRONIDAZOL | F46: COMPRIMIDO | G46: 32000 | H46: 7.69 | I46: =+G46*H46 -> 246080 | J46: 94 | L46: 246080
A47: 38 | B47: 2.5.2-1821.400 | C47: PROD. MEDICO/FARMACEUTICOS/LAB | D47: 252 | E47: ANTIBIOTICOS P/PERSONAS; TIPO: MONODROGA, DROGA GENERICA: METRONIDAZOL 500 mGr, FORMA FARMACEUTICA: SACHET X 100 mL, PRESENTACION: UNIDAD | F47: UNIDAD | G47: 5000 | H47: 138 | I47: =+G47*H47 -> 690000 | J47: 95 | L47: 690000
...

Sheet  NotaPedido
A1: NOTA DE PEDIDO | J1: N° | K1: xxx/2022
A3: JURISDICCIÓN: | D3: ='Necesidades Trimestrales'!C4 -> 040 - Ministerio de Salud
A4: SAF: | D4: ='Necesidades Trimestrales'!C5 -> 011 - Direccion Provincial de Administracion - MS
A5: UNIDAD EJECUTORA: | D5: 469 - Direccion Provincial de Farmacia e Insumos
A6: DEPENDENCIA SOLICITANTE: | D6: 469 - Direccion Provincial de Farmacia e Insumos
A7: PERIODO UTILIZACIÓN: | D7: Semestral
A8: OBJETO: | D8: Adquisición de TERAPIA ANTIINFECCIOSA SISTEMICA/SUEROS INMUNES E INMUNOGLOBULINAS Y MEDIOS DE CONTRASTES /ANALGESICOS ANTINFLAMATORIOS /MIORRELAJANTES/ANESTESICOS/ANALGESICOS OPIACIOS
A10: Ítem | B10: Codigo Item | C10: DESCRIPCIÓN | H10: Adjunta Detalle Técnico | I10: Unidad Medida | J10: Precio Unitario Estimado | K10: Cantidad Solicitada
A12: 1 | B12: =+'Necesidades Trimestrales'!B10 -> 2.5.2-1724.16 | C12: =+'Necesidades Trimestrales'!E10 -> ANALGESICOS; TIPO: MONODROGA, DROGA GENERICA: ACIDO ACETILSALICILICO, PRESENTACION: 100 mGr, FORMA FARMACEUTICA: COMPRIMIDO | H12: NO | I12: =+'Necesidades Trimestrales'!F10 -> COMPRIMIDO | J12: =+'Necesidades Trimestrales'!H10 -> 1.88 | K12: =+'Necesidades Trimestrales'!G10 -> 25700
A13: 2 | B13: =+'Necesidades Trimestrales'!B11 -> 2.5.2-1821.524 | C13: =+'Necesidades Trimestrales'!E11 -> ANTIBIOTICOS P/PERSONAS; TIPO: ASOCIACION, DROGA GENERICA: AMOXICILINA + AC.CLAVULANICO 400 MG / 57 MG, FORMA FARMACEUTICA: SUSPENSION, PRESENTACION: ENVASE X 70 ML | H13: NO | I13: =+'Necesidades Trimestrales'!F11 -> FRASCO | J13: =+'Necesidades Trimestrales'!H11 -> 410 | K13: =+'Necesidades Trimestrales'!G11 -> 12000
A14: 3 | B14: =+'Necesidades Trimestrales'!B12 -> 2.5.2-1821.440 | C14: =+'Necesidades Trimestrales'!E12 -> ANTIBIOTICOS P/PERSONAS; TIPO: ASOCIACION, DROGA GENERICA: AMOXICIL. 875 MG+CLAVUL.125 MG mGr, FORMA FARMACEUTICA: COMPRIMIDO, PRESENTACION: UNIDAD | H14: NO | I14: =+'Necesidades Trimestrales'!F12 -> COMPRIMIDO | J14: =+'Necesidades Trimestrales'!H12 -> 38 | K14: =+'Necesidades Trimestrales'!G12 -> 250000
A15: 4 | B15: =+'Necesidades Trimestrales'!B13 -> 2.5.2-1821.9 | C15: =+'Necesidades Trimestrales'!E13 -> ANTIBIOTICOS P/PERSONAS; TIPO: MONODROGA, DROGA GENERICA: AMOXICILINA, PRESENTACION: 500 mGr, FORMA FARMACEUTICA: COMPRIMIDOS | H15: NO | I15: =+'Necesidades Trimestrales'!F13 -> COMPRIMIDO | J15: =+'Necesidades Trimestrales'!H13 -> 15 | K15: =+'Necesidades Trimestrales'!G13 -> 100000
A16: 5 | B16: =+'Necesidades Trimestrales'!B14 -> 2.5.2-1821.399 | C16: =+'Necesidades Trimestrales'!E14 -> ANTIBIOTICOS P/PERSONAS; TIPO: MONODROGA, DROGA GENERICA: AMOXICILINA 500 mGr, FORMA FARMACEUTICA: SUSPENSION, PRESENTACION: ENVASE X 90 mL | H16: NO | I16: =+'Necesidades Trimestrales'!F14 -> FRASCO | J16: =+'Necesidades Trimestrales'!H14 -> 320 | K16: =+'Necesidades Trimestrales'!G14 -> 10000
A17: 6 | B17: =+'Necesidades Trimestrales'!B15 -> 2.5.2-1821.389 | C17: =+'Necesidades Trimestrales'!E15 -> ANTIBIOTICOS P/PERSONAS; TIPO: ASOCIACION, DROGA GENERICA: AMPICILINA + SULBACTAN, FORMA FARMACEUTICA: FRASCO AMPOLLA, PRESENTACION: ENVASE X 1,5 GR | H17: NO | I17: =+'Necesidades Trimestrales'!F15 -> AMPOLLA | J17: =+'Necesidades Trimestrales'!H15 -> 145 | K17: =+'Necesidades Trimestrales'!G15 -> 22000
A18: 7 | B18: =+'Necesidades Trimestrales'!B16 -> 2.5.2-1821.8 | C18: =+'Necesidades Trimestrales'!E16 -> ANTIBIOTICOS P/PERSONAS; TIPO: MONODROGA, DROGA GENERICA: AMPICILINA, FORMA FARMACEUTICA: AMPOLLA, PRESENTACION: 1 GR | H18: NO | I18: =+'Necesidades Trimestrales'!F16 -> AMPOLLA | J18: =+'Necesidades Trimestrales'!H16 -> 99 | K18: =+'Necesidades Trimestrales'!G16 -> 15000
A19: 8 | B19: =+'Necesidades Trimestrales'!B17 -> 2.5.2-1821.502 | C19: =+'Necesidades Trimestrales'!E17 -> ANTIBIOTICOS P/PERSONAS; TIPO: MONODROGA, DROGA GENERICA: AZITROMICINA 200 mGr, FORMA FARMACEUTICA: SUSPENSION, PRESENTACION: ENVASE X 15 Ml | H19: NO | I19: =+'Necesidades Trimestrales'!F17 -> FRASCO | J19: =+'Necesidades Trimestrales'!H17 -> 562.5 | K19: =+'Necesidades Trimestrales'!G17 -> 12000
A20: 9 | B20: =+'Necesidades Trimestrales'!B18 -> 2.5.2-1821.94 | C20: =+'Necesidades Trimestrales'!E18 -> ANTIBIOTICOS P/PERSONAS; TIPO: MONODROGA, DROGA GENERICA: AZITROMICINA, FORMA FARMACEUTICA: COMPRIMIDO, PRESENTACION: 500 mGr | H20: NO | I20: =+'Necesidades Trimestrales'!F18 -> COMPRIMIDO | J20: =+'Necesidades Trimestrales'!H18 -> 37.45 | K20: =+'Necesidades Trimestrales'!G18 -> 25000
A21: 10 | B21: =+'Necesidades Trimestrales'!B19 -> 2.5.2-1883.188 | C21: =+'Necesidades Trimestrales'!E19 -> ANESTESICOS LOCALES; TIPO: MONODROGA, DROGA GENERICA: BUPIVACAINA 0,5% HIPERBARICA, FORMA FARMACEUTICA: AMPOLLA, PRESENTACION: 4 ML CON AGUJA 27 G X 3 1/2 CON INTRODUCTOR | H21: NO | I21: =+'Necesidades Trimestrales'!F19 -> AMPOLLA | J21: =+'Necesidades Trimestrales'!H19 -> 1420 | K21: =+'Necesidades Trimestrales'!G19 -> 200
A22: 11 | B22: =+'Necesidades Trimestrales'!B20 -> 2.5.2-1821.321 | C22: =+'Necesidades Trimestrales'!E20 -> ANTIBIOTICOS P/PERSONAS; TIPO: MONODROGA, DROGA GENERICA: CEFALEXINA 500 mGr, FORMA FARMACEUTICA: COMPRIMIDO, PRESENTACION: 1 UN | H22: NO | I22: =+'Necesidades Trimestrales'!F20 -> COMPRIMIDO | J22: =+'Necesidades Trimestrales'!H20 -> 15.3 | K22: =+'Necesidades Trimestrales'!G20 -> 60000
A23: 12 | B23: =+'Necesidades Trimestrales'!B21 -> 2.5.2-1821.337 | C23: =+'Necesidades Trimestrales'!E21 -> ANTIBIOTICOS P/PERSONAS; TIPO: MONODROGA, DROGA GENERICA: CEFALEXINA 500MG, FORMA FARMACEUTICA: SUSPENSION, PRESENTACION: ENVASE X 90 mL | H23: NO | I23: =+'Necesidades Trimestrales'!F21 -> FRASCO | J23: =+'Necesidades Trimestrales'!H21 -> 298 | K23: =+'Necesidades Trimestrales'!G21 -> 6000
... A62: 51 | B62: =+'Necesidades Trimestrales'!B60 -> 2.5.2-1724.154 | C62: =+'Necesidades Trimestrales'!E60 -> ANALGESICOS; TIPO: MONODROGA, DROGA GENERICA: TRAMADOL 50 mGr, FORMA FARMACEUTICA: AMPOLLA, PRESENTACION: UNIDAD | H62: NO | I62: =+'Necesidades Trimestrales'!F60 -> AMPOLLA | J62: =+'Necesidades Trimestrales'!H60 -> 65 | K62: =+'Necesidades Trimestrales'!G60 -> 1000
A63: Costo total estimado: PESOS SETENTA Y OCHO MILLONES OCHOCIENTOS CUATRO MIL CUATROCIENTOS VEINTIUNO con 00/100. | J63: =SUMPRODUCT(J12:J62,K12:K62) -> 78804421

Sheet Autor Gastar
A1: EJERCICIO: | D1: ='Necesidades Trimestrales'!C6 -> 2022 | P1: AUTORIZACION PARA GASTAR
A4: JURISDICCIÓN: | G4: =' NotaPedido'!D3 -> 040 - Ministerio de Salud
A5: SAF: | G5: =' NotaPedido'!D4 -> 011 - Direccion Provincial de Administracion - MS
A6: UNIDAD EJECUTORA: | G6: =' NotaPedido'!D5 -> 469 - Direccion Provincial de Farmacia e Insumos
A7: DEPENDENCIA SOLICITANTE: | G7: =' NotaPedido'!D6 -> 469 - Direccion Provincial de Farmacia e Insumos
A8: AUTORIZACIÓN:
A9: Señor Jefe de Servicio Administrativo Financiero:
A10: ="Autorizo la realización de los trámites correspondientes, a fin de proveer a este Organismo los bienes y/o servicios que se detallan en Nota de Pedido N° " & ' NotaPedido'!K1&", afectando la erogación resultante a los créditos presupuestarios aprobados a favor de esta Unidad Ejecutora, conforme al siguiente detalle:" -> Autorizo la realización de los trámites correspondientes, a fin de proveer a este Organismo los bienes y/o servicios que se detallan en Nota de Pedido N° xxx/2022, afectando la erogación resultante a los créditos presupuestarios aprobados a favor de esta Unidad Ejecutora, conforme al siguiente detalle:
A12: IMPUTACIÓN PRESUPUESTARIA
A13: CÓDIGO | O13: DENOMINACIÓN DE LA PARTIDA PRESUPUESTARIA | Q13: IMPORTE
A14: PR | B14: SB | C14: PY | D14: AC | E14: OB | F14: UG | G14: FIN | H14: FUN | I14: I | J14: P | K14: P | L14: SubP | M14: M | N14: FF
A15: 30 | D15: 1 | F15: 4901 | G15: 3 | H15: 1 | I15: 2 | J15: 5 | K15: 2 | M15: 1 | N15: 1.1 | O15: Productos Farmacéuticos y Medicinales | Q15: =' NotaPedido'!J63 -> 78804421
A23: TOTAL DE PESOS: SETENTA Y OCHO MILLONES OCHOCIENTOS CUATRO MIL CUATROCIENTOS VEINTIUNO con 00/100. | Q23: =SUM(Q15:Q22) -> 78804421
A25: JUSTIFICACIÓN:
A26: =' NotaPedido'!D8 -> Adquisición de TERAPIA ANTIINFECCIOSA SISTEMICA/SUEROS INMUNES E INMUNOGLOBULINAS Y MEDIOS DE CONTRASTES /ANALGESICOS ANTINFLAMATORIOS /MIORRELAJANTES/ANESTESICOS/ANALGESICOS OPIACIOS
