Workbook

Sheet Necesidades trimestrales
D1: Pedido de Necesidades Trimestrales
A4: JURISDICCION: | D4: 040 - Ministerio de Salud
A5: SAF N°: | D5: 024 - Hospital Interzonal de Niños
A6: EJERCICIO: | D6: 2021
A7: TRIMESTRE: | D7: 2
A9: ID | B9: CODIGO ITEM | C9: RUBRO DE COMPRA | D9: I.P.P. | E9: DESCRIPCION | F9: UNIDAD DE MEDIDA | G9: CANTIDAD | H9: PRECIO UNITARIO ESTIMADO | I9: IMPORTE TOTAL ESTIMADO
A10: 1 | B10: 2.9.6-1355.937 | C10: REPUESTOS | D10: 2.9.6 | E10: CARTUCHOS DE TINTA; CODIGO: HP21, DESCRIPCION: SIN VALOR, COLOR: SIN VALOR, USO: HEWLETT PACKARD | F10: Unidad | G10: 16 | H10: 1290 | I10: =+H10*G10 -> 20640
A11: 2 | B11: 2.9.6-1355.938 | C11: REPUESTOS | D11: 2.9.6 | E11: CARTUCHOS DE TINTA; CODIGO: HP22, DESCRIPCION: SIN VALOR, COLOR: SIN VALOR, USO: HEWLETT PACKARD | F11: Unidad | G11: 16 | H11: 2334 | I11: =+H11*G11 -> 37344
A12: 3 | B12: 2.9.6-1355.1044 | C12: REPUESTOS | D12: 2.9.6 | E12: CARTUCHOS DE TINTA; CODIGO: HP27, DESCRIPCION: CARTUCHO TINTA, COLOR: NEGRO, USO: HEWLETT PACKARD | F12: Unidad | G12: 6 | H12: 1150 | I12: =+H12*G12 -> 6900
A13: 4 | B13: 2.9.6-1355.1045 | C13: REPUESTOS | D13: 2.9.6 | E13: CARTUCHOS DE TINTA; CODIGO: HP28, DESCRIPCION: CARTUCHO TINTA, COLOR: COLOR, USO: HEWLETT PACKARD | F13: Unidad | G13: 6 | H13: 1430 | I13: =+H13*G13 -> 8580
A14: 5 | B14: 2.9.6-1355.664 | C14: REPUESTOS | D14: 2.9.6 | E14: CARTUCHOS DE TINTA; CODIGO: C6656A, PRODUCTO: TINTA, COLOR: NEGRA, USO: HEWLETT PACKARD, DESCRIPCION: TINTA | F14: Unidad | G14: 3 | H14: 1499 | I14: =+H14*G14 -> 4497
A15: 6 | B15: 2.9.6-1355.1138 | C15: REPUESTOS | D15: 2.9.6 | E15: CARTUCHOS DE TINTA; CODIGO: C6657AL, DESCRIPCION: CARTUCHO DE TINTA, COLOR: COLOR, USO: HEWLETT PACKARD | F15: Unidad | G15: 3 | H15: 1699 | I15: =+H15*G15 -> 5097
A16: 7 | B16: 2.9.6-1355.1854 | C16: REPUESTOS | D16: 2.9.6 | E16: CARTUCHOS DE TINTA; CODIGO: CC640XL, USO: HP 3515 | F16: Unidad | G16: 10 | H16: 2070 | I16: =+H16*G16 -> 20700
A17: 8 | B17: 2.9.6-1355.1855 | C17: REPUESTOS | D17: 2.9.6 | E17: CARTUCHOS DE TINTA; CODIGO: CC643XL, USO: HP 3515 | F17: Unidad | G17: 10 | H17: 2330 | I17: =+H17*G17 -> 23300
A18: 9 | B18: 2.9.6-1355.1950 | C18: REPUESTOS | D18: 2.9.6 | E18: CARTUCHOS DE TINTA; CODIGO: 662XL, USO: HP | F18: Unidad | G18: 6 | H18: 1999 | I18: =+H18*G18 -> 11994
A19: 10 | B19: 2.9.6-1355.1950 | C19: REPUESTOS | D19: 2.9.6 | E19: CARTUCHOS DE TINTA; CODIGO: 662XL, USO: HP | F19: Unidad | G19: 6 | H19: 2325 | I19: =+H19*G19 -> 13950
A20: 11 | B20: 2.9.6-1355.1988 | C20: REPUESTOS | D20: 2.9.6 | E20: CARTUCHOS DE TINTA; CODIGO: 664, USO: HEWLET PACKARD | F20: Unidad | G20: 8 | H20: 1699 | I20: =+H20*G20 -> 13592
A21: 12 | B21: 2.9.6-1355.1988 | C21: REPUESTOS | D21: 2.9.6 | E21: CARTUCHOS DE TINTA; CODIGO: 664, USO: HEWLET PACKARD | F21: Unidad | G21: 8 | H21: 2155 | I21: =+H21*G21 -> 17240
... A42: 33 | B42: 2.9.6-401.2138 | C42: REPUESTOS | D42: 2.9.6 | E42: CARTUCHOS DE TONER; CODIGO: CF280X, USO: HEWLETT PACKARD | F42: Unidad | G42: 2 | H42: 910 | I42: =+H42*G42 -> 1820
A44: Plazos y lugares de entrega
A45: Lugar de Entrega: SERVICIO DE INFORMATICA -HOSPITAL INT. DE NIÑOS – AV. VIRGEN DEL VALLE N° 1050-CATAMARCA DE 8:00 A 12:00HS., DEBIENDO CORRER LOS GASTOS DE FLETES, ACARREO, CARGA, DESCARGA Y SEGURO A CARGO DEL ADJUDICATARIO.
A47: Plazo de entrega: Dentro de los 10 días de notificada la Orden de Compra
A48: Mantenimiento de Oferta:
D49: 45 dias habiles
A51: Especificaciones Técnicas:
A53: ITEM Nº 1: | C53: Cartucho Alternativo 21 XL (Negro)
A54: ITEM Nº 2: | C54: Cartucho Alternativo 22 XL (Tricolor)
A55: ITEM Nº 3: | C55: Cartucho Alternativo 27 XL (Negro)
A56: ITEM Nº :4 | C56: Cartucho Alternativo 28 XL (Tricolor)
A57: ITEM Nº 5: | C57: Cartucho Alternativo 56 (Negro)
A58: ITEM Nº 6: | C58: Cartucho Alternativo 57 (Tricolor)
A59: ITEM Nº 7: | C59: Cartucho Alternativo 60 XL (Negro)
A60: ITEM Nº 8: | C60: Cartucho Alternativo 60 XL (Tricolor)
A61: ITEM Nº 9: | C61: Cartucho Alternativo 662 XL (Negro)
A62: ITEM Nº 10: | C62: Cartucho Alternativo 662 XL (Tricolor)
A63: ITEM Nº 11: | C63: Cartucho Original HP 664 (Negro)
A64: ITEM Nº 12: | C64: Cartucho Original HP 664 (Tricolor)
... A70: ITEM Nº 18: | C70: Cartucho Alternativo 951 XL (Amarillo)
A71: ITEM Nº 19: | B71: 25 un. | C71: Cartucho Alternativo 954 XL (Negro)
B72: 25 un. | C72: Cartucho Alternativo 954 XL (Cyan)
...

Sheet Nota de Pedido
A1: NOTA DE PEDIDO | J1: N° | K1: 044/2021
A3: JURISDICCIÓN: | D3: 040- Ministerio de Slud
A4: SAF: | D4: 024- Hospital Interzonal de Niños
A5: UNIDAD EJECUTORA: | D5: 024 - Hospital Interzonal de Niños
A6: DEPENDENCIA SOLICITANTE: | D6: Servicio de Informatica
A7: PERIODO UTILIZACIÓN: | D7: 2 do Trimestre
A8: OBJETO: | D8: Cartuchos de Tintas y Toners
A10: Ítem | B10: Codigo Item | C10: DESCRIPCIÓN | H10: Adjunta Detalle Técnico | I10: Unidad Medida | J10: Precio Unitario Estimado | K10: Cantidad Solicitada
A12: 1 | B12: =+'Necesidades trimestrales'!B10 -> 2.9.6-1355.937 | C12: ='Necesidades trimestrales'!E10 -> CARTUCHOS DE TINTA; CODIGO: HP21, DESCRIPCION: SIN VALOR, COLOR: SIN VALOR, USO: HEWLETT PACKARD | H12: SI | I12: Unidad | J12: ='Necesidades trimestrales'!H10 -> 1290 | K12: ='Necesidades trimestrales'!G10 -> 16
A13: 2 | B13: =+'Necesidades trimestrales'!B11 -> 2.9.6-1355.938 | C13: ='Necesidades trimestrales'!E11 -> CARTUCHOS DE TINTA; CODIGO: HP22, DESCRIPCION: SIN VALOR, COLOR: SIN VALOR, USO: HEWLETT PACKARD | H13: SI | I13: Unidad | J13: ='Necesidades trimestrales'!H11 -> 2334 | K13: ='Necesidades trimestrales'!G11 -> 16
A14: 3 | B14: =+'Necesidades trimestrales'!B12 -> 2.9.6-1355.1044 | C14: ='Necesidades trimestrales'!E12 -> CARTUCHOS DE TINTA; CODIGO: HP27, DESCRIPCION: CARTUCHO TINTA, COLOR: NEGRO, USO: HEWLETT PACKARD | H14: SI | I14: Unidad | J14: ='Necesidades trimestrales'!H12 -> 1150 | K14: ='Necesidades trimestrales'!G12 -> 6
A15: 4 | B15: =+'Necesidades trimestrales'!B13 -> 2.9.6-1355.1045 | C15: ='Necesidades trimestrales'!E13 -> CARTUCHOS DE TINTA; CODIGO: HP28, DESCRIPCION: CARTUCHO TINTA, COLOR: COLOR, USO: HEWLETT PACKARD | H15: SI | I15: Unidad | J15: ='Necesidades trimestrales'!H13 -> 1430 | K15: ='Necesidades trimestrales'!G13 -> 6
A16: 5 | B16: =+'Necesidades trimestrales'!B14 -> 2.9.6-1355.664 | C16: ='Necesidades trimestrales'!E14 -> CARTUCHOS DE TINTA; CODIGO: C6656A, PRODUCTO: TINTA, COLOR: NEGRA, USO: HEWLETT PACKARD, DESCRIPCION: TINTA | H16: SI | I16: Unidad | J16: ='Necesidades trimestrales'!H14 -> 1499 | K16: ='Necesidades trimestrales'!G14 -> 3
A17: 6 | B17: =+'Necesidades trimestrales'!B15 -> 2.9.6-1355.1138 | C17: ='Necesidades trimestrales'!E15 -> CARTUCHOS DE TINTA; CODIGO: C6657AL, DESCRIPCION: CARTUCHO DE TINTA, COLOR: COLOR, USO: HEWLETT PACKARD | H17: SI | I17: Unidad | J17: ='Necesidades trimestrales'!H15 -> 1699 | K17: ='Necesidades trimestrales'!G15 -> 3
A18: 7 | B18: =+'Necesidades trimestrales'!B16 -> 2.9.6-1355.1854 | C18: ='Necesidades trimestrales'!E16 -> CARTUCHOS DE TINTA; CODIGO: CC640XL, USO: HP 3515 | H18: SI | I18: Unidad | J18: ='Necesidades trimestrales'!H16 -> 2070 | K18: ='Necesidades trimestrales'!G16 -> 10
A19: 8 | B19: =+'Necesidades trimestrales'!B17 -> 2.9.6-1355.1855 | C19: ='Necesidades trimestrales'!E17 -> CARTUCHOS DE TINTA; CODIGO: CC643XL, USO: HP 3515 | H19: SI | I19: Unidad | J19: ='Necesidades trimestrales'!H17 -> 2330 | K19: ='Necesidades trimestrales'!G17 -> 10
A20: 9 | B20: =+'Necesidades trimestrales'!B18 -> 2.9.6-1355.1950 | C20: ='Necesidades trimestrales'!E18 -> CARTUCHOS DE TINTA; CODIGO: 662XL, USO: HP | H20: SI | I20: Unidad | J20: ='Necesidades trimestrales'!H18 -> 1999 | K20: ='Necesidades trimestrales'!G18 -> 6
A21: 10 | B21: =+'Necesidades trimestrales'!B19 -> 2.9.6-1355.1950 | C21: ='Necesidades trimestrales'!E19 -> CARTUCHOS DE TINTA; CODIGO: 662XL, USO: HP | H21: SI | I21: Unidad | J21: ='Necesidades trimestrales'!H19 -> 2325 | K21: ='Necesidades trimestrales'!G19 -> 6
A22: 11 | B22: =+'Necesidades trimestrales'!B20 -> 2.9.6-1355.1988 | C22: ='Necesidades trimestrales'!E20 -> CARTUCHOS DE TINTA; CODIGO: 664, USO: HEWLET PACKARD | H22: SI | I22: Unidad | J22: ='Necesidades trimestrales'!H20 -> 1699 | K22: ='Necesidades trimestrales'!G20 -> 8
A23: 12 | B23: =+'Necesidades trimestrales'!B21 -> 2.9.6-1355.1988 | C23: ='Necesidades trimestrales'!E21 -> CARTUCHOS DE TINTA; CODIGO: 664, USO: HEWLET PACKARD | H23: SI | I23: Unidad | J23: ='Necesidades trimestrales'!H21 -> 2155 | K23: ='Necesidades trimestrales'!G21 -> 8
... A44: 33 | B44: =+'Necesidades trimestrales'!B42 -> 2.9.6-401.2138 | C44: ='Necesidades trimestrales'!E42 -> CARTUCHOS DE TONER; CODIGO: CF280X, USO: HEWLETT PACKARD | H44: SI | I44: Unidad | J44: ='Necesidades trimestrales'!H42 -> 910 | K44: ='Necesidades trimestrales'!G42 -> 2
A45: COSTO TOTAL ESTIMADO : SEISCIENTOS VEINTISIETE MIL CUATROCIENTOS NUEVE CON 00/100 : | J45: 627409

Sheet APG
A1: EJERCICIO: | D1: 2021 | P1: AUTORIZACION PARA GASTAR
A4: JURISDICCIÓN: | G4: 040- Ministerio de Salud
A5: SAF: | G5: 024- Hospital Interzonal de Niños
A6: UNIDAD EJECUTORA: | G6: 024- Hospital Interzonal de Niños
A7: DEPENDENCIA SOLICITANTE: | G7: Servicio de Informatica
A8: AUTORIZACIÓN:
A9: Señor Jefe de Servicio Administrativo Financiero:
A10: Autorizo la realización de los trámites correspondientes, a fin de proveer a este Organismo los bienes y/o servicios que se detallan en Nota de Pedido N° 44/2021, afectando la erogación resultante a los créditos presupuestarios aprobados a favor de esta Unidad Ejecutora, conforme al siguiente detalle:
A12: IMPUTACIÓN PRESUPUESTARIA
A13: CÓDIGO | O13: DENOMINACIÓN DE LA PARTIDA PRESUPUESTARIA | Q13: IMPORTE
A14: PR | B14: SB | C14: PY | D14: AC | E14: OB | F14: UG | G14: FIN | H14: FUN | I14: I | J14: P | K14: P | L14: SubP | M14: M | N14: FF
A15: 36 | D15: 1 | F15: 4901 | G15: 3 | H15: 310 | I15: 2 | J15: 9 | K15: 6 | M15: 1 | N15: 1.1 | O15: REPUESTOS | Q15: 627409
A18: TOTAL DE PESOS: SEISCIENTOS VEINTISIETE MIL CUATROCIENTOS NUEVE CON 00/100. | Q18: =SUM(Q15:Q17) -> 627409
A20: JUSTIFICACIÓN:
A21: Para la adquisición de CARTUCHOS DE TINTAS Y TONERS destinados al servico de Informatica del Hospital Interzonal de Niños Eva Peron, para el normal funcionamiento del organismo.
