Workbook

Sheet Necesidades Trimestrales
B2: Pedido de Necesidades Trimestrales
A4: JURISDICCION: | C4: 70 - MINISTERIO DE CIENCIA E INNOVACION TECNOLOGICA
A5: SAF N°: | C5: 20 - MINISTERIO DE CIENCIA E INNOVACION TECNOLOGICA
A6: EJERCICIO: | C6: 2021
A7: TRIMESTRE: | C7: 4
A174: 1 | B174: 4.3.5-8922.8 | C174: ARTICULOS DEL HOGAR | D174: =LEFT(B174,5) -> 4.3.5 | E174: JUEGOS DE SALON; TIPO: CONSOLA DE VIDEOJUEGOS | F174: UNIDAD | G174: 3 | H174: 185000 | I174: =G174*H174 -> 555000 | K174: 435 | L174: =I174+I175+I181+I183+I184+I186+I187+I188+I189 -> 3872840
A175: 2 | B175: 4.3.5-9163.64 | C175: EQUIPOS | D175: =LEFT(B175,5) -> 4.3.5 | E175: EQUIPOS DIDACTICOS TECNICOS; NOMBRE: SISTEMA DE SONIDO, TIPO: ESTEREO | F175: UNIDAD | G175: 4 | H175: 10000 | I175: =G175*H175 -> 40000 | K175: 436 | L175: =I177+I185 -> 2851176
A176: 3 | B176: 4.3.7-46.128 | C176: EQUIPO DE OFICINA Y MUEBLES | D176: =LEFT(B176,5) -> 4.3.7 | E176: SILLONES EJECUTIVOS; TAPIZADO: ECOCUERO, ALTURA: REGULABLE, GIRATORIO: SI, MATERIAL: ACERO Y PLASTICO | F176: UNIDAD | G176: 6 | H176: 34800 | I176: =G176*H176 -> 208800 | K176: 437 | L176: =I176+I178+I179+I180+I182 -> 1537600
A177: 4 | B177: 4.3.6-9707.20 | C177: EQUIPOS | D177: =LEFT(B177,5) -> 4.3.6 | E177: IMPRESORA 3D; TIPO: FDM, DIMENSION: 220 X 220 X 260 MM, RESOLUCION: SEGÚN PLIEGO, PRECISION: SEGÚN PLIEGO, ESPESOR CAPA: SEGÚN PLIEGO | F177: UNIDAD | G177: 16 | H177: 43200 | I177: =G177*H177 -> 691200 | L177: =SUM(L174:L176) -> 8261616
A178: 5 | B178: 4.3.7-45.517 | C178: EQUIPO DE OFICINA Y MUEBLES | D178: =LEFT(B178,5) -> 4.3.7 | E178: SILLAS; MATERIAL ESTRUCTURA: METAL, TAPIZADO: SIN, ALTURA: 77 Cm, GIRATORIA: NO | F178: UNIDAD | G178: 80 | H178: 7900 | I178: =G178*H178 -> 632000
A179: 6 | B179: 4.3.7-40.1320 | C179: EQUIPO DE OFICINA Y MUEBLES | D179: =LEFT(B179,5) -> 4.3.7 | E179: ESCRITORIOS; MATERIAL ESTRUCTURA: AGLOMERADO, TERMINACION: ENCHAPADO EN MELAMINA, DIM. DEL PLANO DE APOYO: 1,20 X 0,60 X 0,75 M, CANTIDAD DE CAJONES: 2 | F179: UNIDAD | G179: 8 | H179: 15000 | I179: =G179*H179 -> 120000
A180: 7 | B180: 4.3.7-1362.52 | C180: EQUIPO DE OFICINA Y MUEBLES | D180: =LEFT(B180,5) -> 4.3.7 | E180: MESAS CURVAS; CURVA: CIRCULAR, DIMENSION: DIAMETRO 120 Cm, MATERIAL: METAL, TERMINACION: FIBRA DE VIDRIO | F180: UNIDAD | G180: 16 | H180: 34500 | I180: =G180*H180 -> 552000
A181: 8 | B181: 4.3.5-241.105 | C181: ARTICULOS DEL HOGAR | D181: =LEFT(B181,5) -> 4.3.5 | E181: TELEVISORES; PANTALLA: SMART LED FULL HD 60 pulg, NORMA: MULTINORMA, CANTIDAD DE CANALES: INDEFINIDO, APAGADO: CON, VISION MULTICANAL: CON | F181: UNIDAD | G181: 4 | H181: 110000 | I181: =G181*H181 -> 440000
A182: 9 | B182: 4.3.7-56.26 | C182: EQUIPO DE OFICINA Y MUEBLES | D182: =LEFT(B182,5) -> 4.3.7 | E182: MESAS P/TELEVISORES; MATERIAL: AGLOMERADO, TAMAÑO: 110 X 110 X 60 Cm, PATAS: CON RUEDAS, ESTANTE: 2 | F182: UNIDAD | G182: 4 | H182: 6200 | I182: =G182*H182 -> 24800
A183: 10 | B183: 4.3.5-9163.90 | C183: EQUIPOS | D183: =LEFT(B183,5) -> 4.3.5 | E183: EQUIPOS DIDACTICOS TECNICOS; NOMBRE: KIT EXPERIMENTAL , TIPO: SEGÚN PLIEGO | F183: UNIDAD | G183: 80 | H183: 2200 | I183: =G183*H183 -> 176000
A184: 11 | B184: 4.3.5-9163.90 | C184: EQUIPOS | D184: =LEFT(B184,5) -> 4.3.5 | E184: EQUIPOS DIDACTICOS TECNICOS; NOMBRE: KIT EXPERIMENTAL , TIPO: SEGÚN PLIEGO | F184: UNIDAD | G184: 80 | H184: 14999 | I184: =G184*H184 -> 1199920
A185: 12 | B185: 4.3.6-6160.222 | C185: INFORMATICA | D185: =LEFT(B185,5) -> 4.3.6 | E185: COMPUTADORAS; TIPO: NOTEBOOK, CODIGO ETAP: PC-007, VERSION ETAP: 23.0 | F185: UNIDAD | G185: 24 | H185: 89999 | I185: =G185*H185 -> 2159976
A186: 13 | B186: 4.3.5-9163.76 | C186: EQUIPOS | D186: =LEFT(B186,5) -> 4.3.5 | E186: EQUIPOS DIDACTICOS TECNICOS; NOMBRE: ROBOT DIDACTICO, TIPO: 4 EJES | F186: UNIDAD | G186: 8 | H186: 11800 | I186: =G186*H186 -> 94400
A187: 14 | B187: 4.3.5-9163.90 | C187: EQUIPOS | D187: =LEFT(B187,5) -> 4.3.5 | E187: EQUIPOS DIDACTICOS TECNICOS; NOMBRE: KIT EXPERIMENTAL , EQUIPOS DIDACTICOS TECNICOS; NOMBRE: KIT EXPERIMENTAL , TIPO: SEGÚN PLIEGO SEGÚN PLIEGO | F187: UNIDAD | G187: 8 | H187: 99000 | I187: =G187*H187 -> 792000
A188: 15 | B188: 4.3.5-9163.90 | C188: EQUIPOS | D188: =LEFT(B188,5) -> 4.3.5 | E188: EQUIPOS DIDACTICOS TECNICOS; NOMBRE: KIT EXPERIMENTAL , TIPO: SEGÚN PLIEGO | F188: UNIDAD | G188: 8 | H188: 62140 | I188: =G188*H188 -> 497120
A189: 16 | B189: 4.3.5-9163.90 | C189: EQUIPOS | D189: =LEFT(B189,5) -> 4.3.5 | E189: EQUIPOS DIDACTICOS TECNICOS; NOMBRE: KIT EXPERIMENTAL , TIPO: SEGÚN PLIEGO | F189: UNIDAD | G189: 8 | H189: 9800 | I189: =G189*H189 -> 78400
A190: Costo total estimado: PROYECTO LABORATORIO DE ROBOTICA | I190: =SUM(I174:I189) -> 8261616
B194: Especificidades Item N° 1
B195: Descripción técnica
C196: Consola de video juego Tipo Sony Playstation 5 825GB standart
B197: Plazos y lugares de entrega
C198: El plazo de entrega no podrá ser superior a los diez (10) días hábiles a partir de la fecha de recepción de la respectiva Orden de Compra en el domicilio especial electrónico constituido, en virtud del método de contratación. La entrega de dichos bienes se realizará en el Ministerio de Ciencia e Innovación Tecnologica, sito en Avenida Republica de Venezuela S/N° - CAPE- Pabellón N° 26 San Fernando del Valle de Catamarca. Se presentará Remito que deberá cumplimentar lo dispuesto por la R.G. AFIP 1415/03, sin excepción.
B199: Calidad Minima esperada
B201: Mantenimiento
C202: Treinta (30) Días hábiles.
B203: Garantia
C204: mínima de Un (1) año
B207: Especificidades Item N° 2
B208: Descripción técnica
C209: Asistente virtual tipo alexa pantalla Parlante inteligente integrada de 2,5" black
B210: Plazos y lugares de entrega
C211: El plazo de entrega no podrá ser superior a los diez (10) días hábiles a partir de la fecha de recepción de la respectiva Orden de Compra en el domicilio especial electrónico constituido, en virtud del método de contratación. La entrega de dichos bienes se realizará en el Ministerio de Ciencia e Innovación Tecnologica, sito en Avenida Republica de Venezuela S/N° - CAPE- Pabellón N° 26 San Fernando del Valle de Catamarca. Se presentará Remito que deberá cumplimentar lo dispuesto por la R.G. AFIP 1415/03, sin excepción.
B212: Calidad Minima esperada
B214: Mantenimiento
C215: Treinta (30) Días hábiles.
...

Sheet Nota de Pedido
A1: NOTA DE PEDIDO | J1: N° | K1: 038/2021
A3: JURISDICCIÓN: | D3: 70 - MINISTERIO DE CIENCIA E INNOVACION TECNOLOGICA
A4: SAF: | D4: 20 - MINISTERIO DE CIENCIA E INNOVACION TECNOLOGICA
A5: UNIDAD EJECUTORA: | D5: SECRETARIA DE CIENCIA Y TECNOLOGIA - SECRETARIA DE INNOVACION TECNOLOGICA
A6: DEPENDENCIA SOLICITANTE: | D6: DIRECCION PROVINCIAL DE GESTION ADMINISTRATIVA RECURSOS HUMANOS
A7: PERIODO UTILIZACIÓN: | D7: 4° TRIMESTRE 2021
A8: OBJETO: | D8: ADQUISICIÓN DE EQUIPOS PARA LOS LABORATORIO DE ROBOTICA DE LAS SECRETARIA DE CIENCIA Y TECNOLOGIA Y SECRETARIA DE INNOVACION TECNOLOGICA DEL MCIT.-
A10: Ítem | B10: Codigo Item | C10: DESCRIPCIÓN | H10: Adjunta Detalle Técnico | I10: Unidad Medida | J10: Precio Unitario Estimado | K10: Cantidad Solicitada
A12: 1 | B12: ='Necesidades Trimestrales'!B174 -> 4.3.5-8922.8 | C12: ='Necesidades Trimestrales'!E174 -> JUEGOS DE SALON; TIPO: CONSOLA DE VIDEOJUEGOS | H12: SI | I12: UNIDAD | J12: ='Necesidades Trimestrales'!H174 -> 185000 | K12: ='Necesidades Trimestrales'!G174 -> 3
A13: 2 | B13: ='Necesidades Trimestrales'!B175 -> 4.3.5-9163.64 | C13: ='Necesidades Trimestrales'!E175 -> EQUIPOS DIDACTICOS TECNICOS; NOMBRE: SISTEMA DE SONIDO, TIPO: ESTEREO | H13: SI | I13: UNIDAD | J13: ='Necesidades Trimestrales'!H175 -> 10000 | K13: ='Necesidades Trimestrales'!G175 -> 4
A14: 3 | B14: ='Necesidades Trimestrales'!B176 -> 4.3.7-46.128 | C14: ='Necesidades Trimestrales'!E176 -> SILLONES EJECUTIVOS; TAPIZADO: ECOCUERO, ALTURA: REGULABLE, GIRATORIO: SI, MATERIAL: ACERO Y PLASTICO | H14: SI | I14: UNIDAD | J14: ='Necesidades Trimestrales'!H176 -> 34800 | K14: ='Necesidades Trimestrales'!G176 -> 6
A15: 4 | B15: ='Necesidades Trimestrales'!B177 -> 4.3.6-9707.20 | C15: ='Necesidades Trimestrales'!E177 -> IMPRESORA 3D; TIPO: FDM, DIMENSION: 220 X 220 X 260 MM, RESOLUCION: SEGÚN PLIEGO, PRECISION: SEGÚN PLIEGO, ESPESOR CAPA: SEGÚN PLIEGO | H15: SI | I15: UNIDAD | J15: ='Necesidades Trimestrales'!H177 -> 43200 | K15: ='Necesidades Trimestrales'!G177 -> 16
A16: 5 | B16: ='Necesidades Trimestrales'!B178 -> 4.3.7-45.517 | C16: ='Necesidades Trimestrales'!E178 -> SILLAS; MATERIAL ESTRUCTURA: METAL, TAPIZADO: SIN, ALTURA: 77 Cm, GIRATORIA: NO | H16: SI | I16: UNIDAD | J16: ='Necesidades Trimestrales'!H178 -> 7900 | K16: ='Necesidades Trimestrales'!G178 -> 80
A17: 6 | B17: ='Necesidades Trimestrales'!B179 -> 4.3.7-40.1320 | C17: ='Necesidades Trimestrales'!E179 -> ESCRITORIOS; MATERIAL ESTRUCTURA: AGLOMERADO, TERMINACION: ENCHAPADO EN MELAMINA, DIM. DEL PLANO DE APOYO: 1,20 X 0,60 X 0,75 M, CANTIDAD DE CAJONES: 2 | H17: SI | I17: UNIDAD | J17: ='Necesidades Trimestrales'!H179 -> 15000 | K17: ='Necesidades Trimestrales'!G179 -> 8
A18: 7 | B18: ='Necesidades Trimestrales'!B180 -> 4.3.7-1362.52 | C18: ='Necesidades Trimestrales'!E180 -> MESAS CURVAS; CURVA: CIRCULAR, DIMENSION: DIAMETRO 120 Cm, MATERIAL: METAL, TERMINACION: FIBRA DE VIDRIO | H18: SI | I18: UNIDAD | J18: ='Necesidades Trimestrales'!H180 -> 34500 | K18: ='Necesidades Trimestrales'!G180 -> 16
A19: 8 | B19: ='Necesidades Trimestrales'!B181 -> 4.3.5-241.105 | C19: ='Necesidades Trimestrales'!E181 -> TELEVISORES; PANTALLA: SMART LED FULL HD 60 pulg, NORMA: MULTINORMA, CANTIDAD DE CANALES: INDEFINIDO, APAGADO: CON, VISION MULTICANAL: CON | H19: SI | I19: UNIDAD | J19: ='Necesidades Trimestrales'!H181 -> 110000 | K19: ='Necesidades Trimestrales'!G181 -> 4
A20: 9 | B20: ='Necesidades Trimestrales'!B182 -> 4.3.7-56.26 | C20: ='Necesidades Trimestrales'!E182 -> MESAS P/TELEVISORES; MATERIAL: AGLOMERADO, TAMAÑO: 110 X 110 X 60 Cm, PATAS: CON RUEDAS, ESTANTE: 2 | H20: SI | I20: UNIDAD | J20: ='Necesidades Trimestrales'!H182 -> 6200 | K20: ='Necesidades Trimestrales'!G182 -> 4
A21: 10 | B21: ='Necesidades Trimestrales'!B183 -> 4.3.5-9163.90 | C21: ='Necesidades Trimestrales'!E183 -> EQUIPOS DIDACTICOS TECNICOS; NOMBRE: KIT EXPERIMENTAL , TIPO: SEGÚN PLIEGO | H21: SI | I21: UNIDAD | J21: ='Necesidades Trimestrales'!H183 -> 2200 | K21: ='Necesidades Trimestrales'!G183 -> 80
A22: 11 | B22: ='Necesidades Trimestrales'!B184 -> 4.3.5-9163.90 | C22: ='Necesidades Trimestrales'!E184 -> EQUIPOS DIDACTICOS TECNICOS; NOMBRE: KIT EXPERIMENTAL , TIPO: SEGÚN PLIEGO | H22: SI | I22: UNIDAD | J22: ='Necesidades Trimestrales'!H184 -> 14999 | K22: ='Necesidades Trimestrales'!G184 -> 80
A23: 12 | B23: ='Necesidades Trimestrales'!B185 -> 4.3.6-6160.222 | C23: ='Necesidades Trimestrales'!E185 -> COMPUTADORAS; TIPO: NOTEBOOK, CODIGO ETAP: PC-007, VERSION ETAP: 23.0 | H23: SI | I23: UNIDAD | J23: ='Necesidades Trimestrales'!H185 -> 89999 | K23: ='Necesidades Trimestrales'!G185 -> 24
... A27: 16 | B27: ='Necesidades Trimestrales'!B189 -> 4.3.5-9163.90 | C27: ='Necesidades Trimestrales'!E189 -> EQUIPOS DIDACTICOS TECNICOS; NOMBRE: KIT EXPERIMENTAL , TIPO: SEGÚN PLIEGO | H27: SI | I27: UNIDAD | J27: ='Necesidades Trimestrales'!H189 -> 9800 | K27: ='Necesidades Trimestrales'!G189 -> 8
A28: Costo total estimado: PESOS OCHO MILLONES DOSCIENTOS SESETENTA Y UN MIL SEISCIENTOS DIECISEIS CON 00/100.- | J28: =SUMPRODUCT(J12:J27,K12:K27) -> 8261616

Sheet Auto Gastar
A1: EJERCICIO: | D1: ='[1]Necesidades Trimestrales'!C6 -> 2021 | P1: AUTORIZACION PARA GASTAR
A4: JURISDICCIÓN: | G4: ='[1] NotaPedido'!D3 -> 70 - MINISTERIO DE CIENCIA E INNOVACION TECNOLOGICA
A5: SAF: | G5: ='[1] NotaPedido'!D4 -> 20 - MINISTERIO DE CIENCIA E INNOVACION TECNOLOGICA
A6: UNIDAD EJECUTORA: | G6: SECRETARIA DE CIENCIA Y TECNOLOGIA - SECRETARIA DE INNOVACION TECNOLOGICA
A7: DEPENDENCIA SOLICITANTE: | G7: ='[1] NotaPedido'!D6 -> DIRECCION PROVINCIAL DE GESTION ADMINISTRATIVA RECURSOS HUMANOS
A8: AUTORIZACIÓN:
A9: Señor Jefe de Servicio Administrativo Financiero:
A10: Autorizo la realización de los trámites correspondientes, a fin de proveer a este Organismo los bienes y/o servicios que se detallan en Nota de Pedido N° 038/2021, afectando la erogación resultante a los créditos presupuestarios aprobados a favor de esta Unidad Ejecutora, conforme al siguiente detalle:
A12: IMPUTACIÓN PRESUPUESTARIA
A13: CÓDIGO | O13: DENOMINACIÓN DE LA PARTIDA PRESUPUESTARIA | Q13: IMPORTE
A14: PR | B14: SB | C14: PY | D14: AC | E14: OB | F14: UG | G14: FIN | H14: FUN | I14: I | J14: P | K14: P | L14: SubP | M14: M | N14: FF
A15: 2 | B15: 0 | C15: 0 | D15: 1 | E15: 0 | F15: 4901 | G15: 3 | H15: 5 | I15: 4 | J15: 3 | K15: 5 | L15: 0 | M15: 1 | N15: 1.1 | O15: Equipo Educacional y Recreativo | Q15: 3872840
A16: 3 | B16: 0 | C16: 0 | D16: 1 | E16: 0 | F16: 4901 | G16: 3 | H16: 5 | I16: 4 | J16: 3 | K16: 6 | L16: 0 | M16: 1 | N16: 1.1 | O16: Equipos para Computación | Q16: 2851176
A17: 3 | B17: 0 | C17: 0 | D17: 1 | E17: 0 | F17: 4901 | G17: 3 | H17: 5 | I17: 4 | J17: 3 | K17: 7 | L17: 0 | M17: 1 | N17: 1.1 | O17: Equipos de Oficina y Muebles | Q17: 1537600
A23: PESOS: PESOS OCHO MILLONES DOSCIENTOS SESETENTA Y UN MIL SEISCIENTOS DIECISEIS CON 00/100.- | Q23: =SUM(Q15:Q22) -> 8261616
A25: JUSTIFICACIÓN:
A26: ADQUISICIÓN DE EQUIPOS PARA LOS LABORATORIO DE ROBOTICA DE LAS SECRETARIA DE CIENCIA Y TECNOLOGIA Y SECRETARIA DE INNOVACION TECNOLOGICA DEL MCIT.-
