Workbook

Sheet SAF 011
A1: 2022
B2: Pedido de Necesidades Trimestrales
A4: JURISDICCION: | C4: 040 - MINISTERIO DE SALUD
A5: SAF N°: | C5: 011 - DIRECCION PROVINCIAL DE ADMINISTRACION - MINISTERIO DE SALUD
A6: EJERCICIO: | C6: 2022
A7: TRIMESTRE: | C7: 3º
A9: ID | B9: CODIGO ITEM | C9: RUBRO DE COMPRA | D9: I.P.P. | E9: DESCRIPCION | F9: UNIDAD DE MEDIDA | G9: CANTIDAD TOTAL | H9: PRECIO UNITARIO ESTIMADO | I9: IMPORTE TOTAL ESTIMADO | J9: ESPECIFICACION TECNICA
A10: 1 | B10: 2.9.5-6292.12 | C10: PROD. MEDICO/FARMACEUTICOS/LAB | D10: 2.9.5. | E10: CLAVOS P/TRAUMATOLOGIA; TIPO: ENDOMEDULAR TIBIA, MATERIAL: TITANIO, MEDIDA: VARIABLE | F10: UNIDAD | G10: 7 | H10: 83000 | I10: =+G10*H10 -> 581000 | J10: CLAVO ENDOMEDULAR ACERROJADO DINAMICO Y ESTATICOS PARA TIBIA, SET DE COLOCACION Y ALTERNATIVAS EN TITANIO.
A11: 2 | B11: 2.9.5-6292.11 | C11: PROD. MEDICO/FARMACEUTICOS/LAB | D11: 2.9.5. | E11: CLAVOS P/TRAUMATOLOGIA; TIPO: ENDOMEDULAR TIBIA, MATERIAL: ACERO, MEDIDA: VARIABLE | F11: UNIDAD | G11: 15 | H11: 73000 | I11: =+G11*H11 -> 1095000 | J11: CLAVO ENDOMEDULAR ACERROJADO DINAMICO Y ESTATICOS PARA TIBIA, SET DE COLOCACION Y ALTERNATIVAS EN ACERO.
A12: 3 | B12: 2.9.5-6292.9 | C12: PROD. MEDICO/FARMACEUTICOS/LAB | D12: 2.9.5. | E12: CLAVOS P/TRAUMATOLOGIA; TIPO: ENDOMEDULAR FEMUR, MATERIAL: ACERO, MEDIDA: VARIABLE | F12: UNIDAD | G12: 10 | H12: 79000 | I12: =+G12*H12 -> 790000 | J12: CLAVO ENDOMEDULAR ACERROJADO DINAMICO Y ESTATICOS PARA FEMUR, SET DE COLOCACION Y ALTERNATIVAS EN ACERO.
A13: 4 | B13: 2.9.5-6292.10 | C13: PROD. MEDICO/FARMACEUTICOS/LAB | D13: 2.9.5. | E13: CLAVOS P/TRAUMATOLOGIA; TIPO: ENDOMEDULAR FEMUR, MATERIAL: TITANIO, MEDIDA: VARIABLE | F13: UNIDAD | G13: 5 | H13: 94000 | I13: =+G13*H13 -> 470000 | J13: CLAVO ENDOMEDULAR ACERROJADO DINAMICO Y ESTATICOS PARA FEMUR, SET DE COLOCACION Y ALTERNATIVAS EN TITANIO.
A14: 5 | B14: 2.9.5-6292.8 | C14: PROD. MEDICO/FARMACEUTICOS/LAB | D14: 2.9.5. | E14: CLAVOS P/TRAUMATOLOGIA; TIPO: ENDOMEDULAR HUMERO, MATERIAL: TITANIO, MEDIDA: VARIABLE | F14: UNIDAD | G14: 3 | H14: 126000 | I14: =+G14*H14 -> 378000 | J14: CLAVO ENDOMEDULAR ACERROJADO DINAMICO Y ESTATICOS PARA HUMERO, SET DE COLOCACION Y ALTERNATIVAS EN TITANIO.
A15: 6 | B15: 2.9.5-10015.1 | C15: PROD. MEDICO/FARMACEUTICOS/LAB | D15: 2.9.5. | E15: COMPONENTES P/TUTOR EXT. DE TRAUMATOLOGIA; TIPO: ROTULA TUBO-SHANTZ P/TUTOR EXTERNO, MATERIAL: ACERO; MEDIDA: VARIABLE | F15: UNIDAD | G15: 10 | H15: 20500 | I15: =+G15*H15 -> 205000 | J15: ROTULA TUBO-SHANTZ PARA TUTOR EXTERNO
A16: 7 | B16: 2.9.5-6292.16 | C16: PROD. MEDICO/FARMACEUTICOS/LAB | D16: 2.9.5. | E16: CLAVOS P/TRAUMATOLOGIA; TIPO: SCHANZ TUTORES EXTERNOS, MATERIAL: ACERO, MEDIDA: VARIABLE | F16: UNIDAD | G16: 4 | H16: 13500 | I16: =+G16*H16 -> 54000 | J16: SHANTZ CONICO DE 4 MM PARA TUTOR EXTERNO
A17: 8 | B17: 2.9.5-6292.16 | C17: PROD. MEDICO/FARMACEUTICOS/LAB | D17: 2.9.5. | E17: CLAVOS P/TRAUMATOLOGIA; TIPO: SCHANZ TUTORES EXTERNOS, MATERIAL: ACERO, MEDIDA: VARIABLE | F17: UNIDAD | G17: 3 | H17: 13500 | I17: =+G17*H17 -> 40500 | J17: SHANTZ CONICO DE 5 MM PARA TUTOR EXTERNO
A18: 9 | B18: 2.9.5-6292.16 | C18: PROD. MEDICO/FARMACEUTICOS/LAB | D18: 2.9.5. | E18: CLAVOS P/TRAUMATOLOGIA; TIPO: SCHANZ TUTORES EXTERNOS, MATERIAL: ACERO, MEDIDA: VARIABLE | F18: UNIDAD | G18: 3 | H18: 13500 | I18: =+G18*H18 -> 40500 | J18: SHANTZ CONICO DE 6 MM PARA TUTOR EXTERNO
A19: 10 | B19: 2.9.5-9948.2 | C19: PROD. MEDICO/FARMACEUTICOS/LAB | D19: 2.9.5. | E19: PLACAS P/TRAUMATOLOGIA; TIPO: BLOQUEADA DOBLE HILERA, MEDIDA: 2,7 mm, USO: MUÑECA, MATERIAL: TITANIO | F19: UNIDAD | G19: 10 | H19: 51000 | I19: =+G19*H19 -> 510000 | J19: PLACAS PARA RADIO DISTAL DOBLE HILERA DE 2.7 MM Y RESPECTIVOS TORNILLOS EN TITANIO.
A20: 11 | B20: 2.9.5-9948.7 | C20: PROD. MEDICO/FARMACEUTICOS/LAB | D20: 2.9.5. | E20: PLACAS P/TRAUMATOLOGIA; TIPO: BLOQUEADA EN T Y L, MEDIDA: 4,5 mm, USO: PLATILLO TIBIAL, MATERIAL: ACERO | F20: UNIDAD | G20: 15 | H20: 49000 | I20: =+G20*H20 -> 735000 | J20: PLACA BLOQUEADA PARA PLATILLO TIBIAL EN T L Y PALO DE HOCHEY Y RESPECTIVOS TORNILLOS EN ACERO 4,5 MM.
A21: 12 | B21: 2.9.5-9948.8 | C21: PROD. MEDICO/FARMACEUTICOS/LAB | D21: 2.9.5. | E21: PLACAS P/TRAUMATOLOGIA; TIPO: BLOQUEADA EN T Y L, MEDIDA: 4,5 mm, USO: PLATILLO TIBIAL, MATERIAL: TITANIO | F21: UNIDAD | G21: 7 | H21: 83000 | I21: =+G21*H21 -> 581000 | J21: PLACA BLOQUEADA PARA PLATILLO TIBIAL EN T L Y PALO DE HOCHEY Y RESPECTIVOS TORNILLOS EN TITANIO 4,5 MM.
... A54: 45 | B54: 2.9.5-10015.3 | C54: PROD. MEDICO/FARMACEUTICOS/LAB | D54: 2.9.5. | E54: COMPONENTES P/TUTOR EXT. DE TRAUMATOLOGIA; TIPO: ROTULA TUBO-TUBO PARA TUTOR EXTERNO, MATERIAL: ACERO; MEDIDA: VARIABLE | F54: UNIDAD | G54: 10 | H54: 20500 | I54: =+G54*H54 -> 205000 | J54: ROTULA TUBO-TUBO PARA TUTOR EXTERNO
E56: TOTAL RUBRO PROD. MEDICO/FARMACEUTICOS/LAB | I56: =SUM(I10:I54) -> 19520000
C58: DETALLE TECNICO Y ESPECIFICACIONES | D58: ANEXO 1-Para oferentes de la Provincia de Catamarca deberán presentar Habilitación Provincial para comercializar el producto que cotizan. 2-Para el resto de oferentes deberán presentar Certificado de Inscripción de ANMAT vigente al momento de la oferta, el mismo deberá ser correspondiente al objeto de la contratación y de encontrarse vencido adjuntar la solicitud de renovación. Deberán contar con presencia en la Provincia de Catamarca. 3-No se aceptarán ofertas de productos no registrados y autorizada su venta por ANMAT. Se deberá especificar en cada ítem de la propuesta, marca y número de certificado otorgado por dicho ente regulador, en caso de corresponder.- 4-Los productos deberán tener un vencimiento posterior a doce (12) meses a partir de la fecha de su recepción. 5- Prótesis en Stock disponible para entrega inmediata según requerimiento. 6- Al momento de la entrega de cada prótesis, la misma debe venir acompañada de la correspondiente caja de instrumental quirúrgico solicitada por el profesional médico.
C62: Plazos de entrega: | D62: A partir de la notificacion de la ORDEN DE COMPRA. Se realizarán pedidos a requerimiento de acuerdo a las necesidades de la Dirección Provincial de Medicina Social Integral, los cuales deberán ser provistos en un plazo de 2 (dos) días.- durante el lapso de duración del contrato y al precio unitario adjudicado, hasta el límite del monto adjudicado. CON OPCION A PRORROGA POR IGUAL PERIODO.
C64: Lugar de entrega: | D64: Dirección Provincial Medicina Social Integral, Chacabuco N° 169. Debiendo correr los gastos de flete, acarreo, carga, descarga y seguro a cargo del adjudicatario.
C66: Calidad Minima esperada:
C68: Mantenimiento: | D68: CUARENTA Y CINCO (45) DIAS
C70: Garantia:
C75: ITEM 1:
C76: =J10 -> CLAVO ENDOMEDULAR ACERROJADO DINAMICO Y ESTATICOS PARA TIBIA, SET DE COLOCACION Y ALTERNATIVAS EN TITANIO.
C78: ITEM 2:
C79: =J11 -> CLAVO ENDOMEDULAR ACERROJADO DINAMICO Y ESTATICOS PARA TIBIA, SET DE COLOCACION Y ALTERNATIVAS EN ACERO.
C81: ITEM 3:
C82: =J12 -> CLAVO ENDOMEDULAR ACERROJADO DINAMICO Y ESTATICOS PARA FEMUR, SET DE COLOCACION Y ALTERNATIVAS EN ACERO.
C84: ITEM 4:
C85: =J13 -> CLAVO ENDOMEDULAR ACERROJADO DINAMICO Y ESTATICOS PARA FEMUR, SET DE COLOCACION Y ALTERNATIVAS EN TITANIO.
C87: ITEM 5:
C88: =J14 -> CLAVO ENDOMEDULAR ACERROJADO DINAMICO Y ESTATICOS PARA HUMERO, SET DE COLOCACION Y ALTERNATIVAS EN TITANIO.
C90: ITEM 6:
C91: =J15 -> ROTULA TUBO-SHANTZ PARA TUTOR EXTERNO
C93: ITEM 7:
...

Sheet NP
A1: NOTA DE PEDIDO
A3: JURISDICCIÓN: | D3: 40 - MINISTERIO DE SALUD
A4: SAF: | D4: 011 - DIRECCION PROVINCIAL DE ADMINISTRACION - M.S.
A5: UNIDAD EJECUTORA: | D5: 131 - DIRECCION PROVINCIAL DE MEDICINA SOCIAL INTEGRAL
A6: DEPENDENCIA SOLICITANTE: | D6: 131 - DIRECCION PROVINCIAL DE MEDICINA SOCIAL INTEGRAL
A7: PERIODO UTILIZACIÓN: | D7: 3º TRIMESTRE
A8: OBJETO: | D8: CONTRATACION PARA LA PROVISION DE PROTESIS DE TRAUMA PARA PERSONAS DE ESCASOS RECURSOS PERTENECIENTES A LA DIRECCION PROVINCIAL DE MEDICINA SOCIAL INTEGRAL.
A10: Ítem | B10: Codigo Item | C10: DESCRIPCIÓN | H10: Adjunta Detalle Técnico | I10: Unidad Medida | J10: Precio Unitario Estimado | K10: Cantidad Solicitada
A12: 1 | B12: ='SAF 011'!B10 -> 2.9.5-6292.12 | C12: ='SAF 011'!E10 -> CLAVOS P/TRAUMATOLOGIA; TIPO: ENDOMEDULAR TIBIA, MATERIAL: TITANIO, MEDIDA: VARIABLE | H12: SI | I12: ='SAF 011'!F10 -> UNIDAD | J12: ='SAF 011'!H10 -> 83000 | K12: ='SAF 011'!G10 -> 7 | M12: =+J12*K12 -> 581000
A13: 2 | B13: ='SAF 011'!B11 -> 2.9.5-6292.11 | C13: ='SAF 011'!E11 -> CLAVOS P/TRAUMATOLOGIA; TIPO: ENDOMEDULAR TIBIA, MATERIAL: ACERO, MEDIDA: VARIABLE | H13: SI | I13: ='SAF 011'!F11 -> UNIDAD | J13: ='SAF 011'!H11 -> 73000 | K13: ='SAF 011'!G11 -> 15 | M13: =+J13*K13 -> 1095000
A14: 3 | B14: ='SAF 011'!B12 -> 2.9.5-6292.9 | C14: ='SAF 011'!E12 -> CLAVOS P/TRAUMATOLOGIA; TIPO: ENDOMEDULAR FEMUR, MATERIAL: ACERO, MEDIDA: VARIABLE | H14: SI | I14: ='SAF 011'!F12 -> UNIDAD | J14: ='SAF 011'!H12 -> 79000 | K14: ='SAF 011'!G12 -> 10 | M14: =+J14*K14 -> 790000
A15: 4 | B15: ='SAF 011'!B13 -> 2.9.5-6292.10 | C15: ='SAF 011'!E13 -> CLAVOS P/TRAUMATOLOGIA; TIPO: ENDOMEDULAR FEMUR, MATERIAL: TITANIO, MEDIDA: VARIABLE | H15: SI | I15: ='SAF 011'!F13 -> UNIDAD | J15: ='SAF 011'!H13 -> 94000 | K15: ='SAF 011'!G13 -> 5 | M15: =+J15*K15 -> 470000
A16: 5 | B16: ='SAF 011'!B14 -> 2.9.5-6292.8 | C16: ='SAF 011'!E14 -> CLAVOS P/TRAUMATOLOGIA; TIPO: ENDOMEDULAR HUMERO, MATERIAL: TITANIO, MEDIDA: VARIABLE | H16: SI | I16: ='SAF 011'!F14 -> UNIDAD | J16: ='SAF 011'!H14 -> 126000 | K16: ='SAF 011'!G14 -> 3 | M16: =+J16*K16 -> 378000
A17: 6 | B17: ='SAF 011'!B15 -> 2.9.5-10015.1 | C17: ='SAF 011'!E15 -> COMPONENTES P/TUTOR EXT. DE TRAUMATOLOGIA; TIPO: ROTULA TUBO-SHANTZ P/TUTOR EXTERNO, MATERIAL: ACERO; MEDIDA: VARIABLE | H17: SI | I17: ='SAF 011'!F15 -> UNIDAD | J17: ='SAF 011'!H15 -> 20500 | K17: ='SAF 011'!G15 -> 10 | M17: =+J17*K17 -> 205000
A18: 7 | B18: ='SAF 011'!B16 -> 2.9.5-6292.16 | C18: ='SAF 011'!E16 -> CLAVOS P/TRAUMATOLOGIA; TIPO: SCHANZ TUTORES EXTERNOS, MATERIAL: ACERO, MEDIDA: VARIABLE | H18: SI | I18: ='SAF 011'!F16 -> UNIDAD | J18: ='SAF 011'!H16 -> 13500 | K18: ='SAF 011'!G16 -> 4 | M18: =+J18*K18 -> 54000
A19: 8 | B19: ='SAF 011'!B17 -> 2.9.5-6292.16 | C19: ='SAF 011'!E17 -> CLAVOS P/TRAUMATOLOGIA; TIPO: SCHANZ TUTORES EXTERNOS, MATERIAL: ACERO, MEDIDA: VARIABLE | H19: SI | I19: ='SAF 011'!F17 -> UNIDAD | J19: ='SAF 011'!H17 -> 13500 | K19: ='SAF 011'!G17 -> 3
A20: 9 | B20: ='SAF 011'!B18 -> 2.9.5-6292.16 | C20: ='SAF 011'!E18 -> CLAVOS P/TRAUMATOLOGIA; TIPO: SCHANZ TUTORES EXTERNOS, MATERIAL: ACERO, MEDIDA: VARIABLE | H20: SI | I20: ='SAF 011'!F18 -> UNIDAD | J20: ='SAF 011'!H18 -> 13500 | K20: ='SAF 011'!G18 -> 3
A21: 10 | B21: ='SAF 011'!B19 -> 2.9.5-9948.2 | C21: ='SAF 011'!E19 -> PLACAS P/TRAUMATOLOGIA; TIPO: BLOQUEADA DOBLE HILERA, MEDIDA: 2,7 mm, USO: MUÑECA, MATERIAL: TITANIO | H21: SI | I21: ='SAF 011'!F19 -> UNIDAD | J21: ='SAF 011'!H19 -> 51000 | K21: ='SAF 011'!G19 -> 10
A22: 11 | B22: ='SAF 011'!B20 -> 2.9.5-9948.7 | C22: ='SAF 011'!E20 -> PLACAS P/TRAUMATOLOGIA; TIPO: BLOQUEADA EN T Y L, MEDIDA: 4,5 mm, USO: PLATILLO TIBIAL, MATERIAL: ACERO | H22: SI | I22: ='SAF 011'!F20 -> UNIDAD | J22: ='SAF 011'!H20 -> 49000 | K22: ='SAF 011'!G20 -> 15
A23: 12 | B23: ='SAF 011'!B21 -> 2.9.5-9948.8 | C23: ='SAF 011'!E21 -> PLACAS P/TRAUMATOLOGIA; TIPO: BLOQUEADA EN T Y L, MEDIDA: 4,5 mm, USO: PLATILLO TIBIAL, MATERIAL: TITANIO | H23: SI | I23: ='SAF 011'!F21 -> UNIDAD | J23: ='SAF 011'!H21 -> 83000 | K23: ='SAF 011'!G21 -> 7
A24: 13 | B24: ='SAF 011'!B22 -> 2.9.5-9948.20 | C24: ='SAF 011'!E22 -> PLACAS P/TRAUMATOLOGIA; TIPO: BLOQUEDAD, MEDIDA: VARIABLE, USO: CLAVICULA, MATERIAL: TITANIO | H24: SI | I24: ='SAF 011'!F22 -> UNIDAD | J24: ='SAF 011'!H22 -> 51000 | K24: ='SAF 011'!G22 -> 15
A25: 14 | B25: ='SAF 011'!B23 -> 2.9.5-9948.18 | C25: ='SAF 011'!E23 -> PLACAS P/TRAUMATOLOGIA; TIPO: TERCIO DE TUBO BLOQUEADA, MEDIDA: 3,5 mm, USO: TOBILLO, MATERIAL: ACERO | H25: SI | I25: ='SAF 011'!F23 -> UNIDAD | J25: ='SAF 011'!H23 -> 41000 | K25: ='SAF 011'!G23 -> 30
A26: 15 | B26: ='SAF 011'!B24 -> 2.9.5-9948.19 | C26: ='SAF 011'!E24 -> PLACAS P/TRAUMATOLOGIA; TIPO: TERCIO DE TUBO BLOQUEADA, MEDIDA: 3,5 mm, USO: TOBILLO, MATERIAL: TITANIO | H26: SI | I26: ='SAF 011'!F24 -> UNIDAD | J26: ='SAF 011'!H24 -> 46000 | K26: ='SAF 011'!G24 -> 15
A27: 16 | B27: ='SAF 011'!B25 -> 2.9.5-391.16 | C27: ='SAF 011'!E25 -> PROTESIS ORTOPEDICA; COMPONENTES: CLAVO, USO: CIRUGIA | H27: SI | I27: ='SAF 011'!F25 -> UNIDAD | J27: ='SAF 011'!H25 -> 94000 | K27: ='SAF 011'!G25 -> 3
A28: 17 | B28: ='SAF 011'!B26 -> 2.9.5-391.16 | C28: ='SAF 011'!E26 -> PROTESIS ORTOPEDICA; COMPONENTES: CLAVO, USO: CIRUGIA | H28: SI | I28: ='SAF 011'!F27 -> UNIDAD | J28: ='SAF 011'!H26 -> 94000 | K28: ='SAF 011'!G26 -> 2
A29: 18 | B29: ='SAF 011'!B27 -> 2.9.5-391.16 | C29: ='SAF 011'!E27 -> PROTESIS ORTOPEDICA; COMPONENTES: CLAVO, USO: CIRUGIA | H29: SI | I29: ='SAF 011'!F28 -> UNIDAD | J29: ='SAF 011'!H27 -> 30000 | K29: ='SAF 011'!G27 -> 10
A30: 19 | B30: ='SAF 011'!B28 -> 2.9.5-391.3 | C30: ='SAF 011'!E28 -> PROTESIS ORTOPEDICA; COMPONENTES: FEMORALES, USO: REEMPLAZO PARCIAL CADERA | H30: SI | I30: ='SAF 011'!F29 -> UNIDAD | J30: ='SAF 011'!H28 -> 125000 | K30: ='SAF 011'!G28 -> 3
A31: 20 | B31: ='SAF 011'!B29 -> 2.9.5-391.3 | C31: ='SAF 011'!E29 -> PROTESIS ORTOPEDICA; COMPONENTES: FEMORALES, USO: REEMPLAZO PARCIAL CADERA | H31: SI | I31: ='SAF 011'!F30 -> UNIDAD | J31: ='SAF 011'!H29 -> 125000 | K31: ='SAF 011'!G29 -> 2
A32: 21 | B32: ='SAF 011'!B30 -> 2.9.5-391.1 | C32: ='SAF 011'!E30 -> PROTESIS ORTOPEDICA; COMPONENTES: FEMORALES, USO: REEMPLAZO TOTAL CADERA | H32: SI | I32: ='SAF 011'!F31 -> UNIDAD | J32: ='SAF 011'!H30 -> 388000 | K32: ='SAF 011'!G30 -> 2
A33: 22 | B33: ='SAF 011'!B31 -> 2.9.5-391.2 | C33: ='SAF 011'!E31 -> PROTESIS ORTOPEDICA; COMPONENTES: FEMORALES, USO: REEMPLAZO TOTAL RODILLA | H33: SI | I33: ='SAF 011'!F32 -> UNIDAD | J33: ='SAF 011'!H31 -> 284000 | K33: ='SAF 011'!G31 -> 2
A34: 23 | B34: ='SAF 011'!B32 -> 2.9.5-391.62 | C34: ='SAF 011'!E32 -> PROTESIS ORTOPEDICA; COMPONENTES: PLACA P/FEMUR DISTAL, USO: CIRUGIA ORTOPEDIA | H34: SI | I34: ='SAF 011'!F33 -> UNIDAD | J34: ='SAF 011'!H32 -> 73000 | K34: ='SAF 011'!G32 -> 5
A35: 24 | B35: ='SAF 011'!B33 -> 2.9.5-391.62 | C35: ='SAF 011'!E33 -> PROTESIS ORTOPEDICA; COMPONENTES: PLACA P/FEMUR DISTAL, USO: CIRUGIA ORTOPEDIA | H35: SI | I35: ='SAF 011'!F34 -> UNIDAD | J35: ='SAF 011'!H33 -> 83000 | K35: ='SAF 011'!G33 -> 2
A36: 25 | B36: ='SAF 011'!B34 -> 2.9.5-391.77 | C36: ='SAF 011'!E34 -> PROTESIS ORTOPEDICA; COMPONENTES: PLACAS BLOQUEADAS P/TIBIA, USO: OSTEOSINTESIS | H36: SI | I36: ='SAF 011'!F35 -> UNIDAD | J36: ='SAF 011'!H34 -> 62000 | K36: ='SAF 011'!G34 -> 5
A37: 26 | B37: ='SAF 011'!B35 -> 2.9.5-391.77 | C37: ='SAF 011'!E35 -> PROTESIS ORTOPEDICA; COMPONENTES: PLACAS BLOQUEADAS P/TIBIA, USO: OSTEOSINTESIS | H37: SI | I37: ='SAF 011'!F36 -> UNIDAD | J37: ='SAF 011'!H35 -> 62000 | K37: ='SAF 011'!G35 -> 5
A38: 27 | B38: ='SAF 011'!B36 -> 2.9.5-391.77 | C38: ='SAF 011'!E36 -> PROTESIS ORTOPEDICA; COMPONENTES: PLACAS BLOQUEADAS P/TIBIA, USO: OSTEOSINTESIS | H38: SI | I38: ='SAF 011'!F37 -> UNIDAD | J38: ='SAF 011'!H36 -> 66000 | K38: ='SAF 011'!G36 -> 3
A39: 28 | B39: ='SAF 011'!B37 -> 2.9.5-391.77 | C39: ='SAF 011'!E37 -> PROTESIS ORTOPEDICA; COMPONENTES: PLACAS BLOQUEADAS P/TIBIA, USO: OSTEOSINTESIS | H39: SI | I39: ='SAF 011'!F38 -> UNIDAD | J39: ='SAF 011'!H37 -> 66000 | K39: ='SAF 011'!G37 -> 2
A40: 29 | B40: ='SAF 011'!B38 -> 2.9.5-391.75 | C40: ='SAF 011'!E38 -> PROTESIS ORTOPEDICA; COMPONENTES: PLACAS DE RECONSTRUCCION, USO: OSTEOSINTESIS | H40: SI | I40: ='SAF 011'!F40 -> UNIDAD | J40: ='SAF 011'!H38 -> 40000 | K40: ='SAF 011'!G38 -> 15
A41: 30 | B41: ='SAF 011'!B39 -> 2.9.5-391.75 | C41: ='SAF 011'!E39 -> PROTESIS ORTOPEDICA; COMPONENTES: PLACAS DE RECONSTRUCCION, USO: OSTEOSINTESIS | H41: SI | I41: ='SAF 011'!F42 -> UNIDAD | J41: ='SAF 011'!H39 -> 40000 | K41: ='SAF 011'!G39 -> 15
A42: 31 | B42: ='SAF 011'!B40 -> 2.9.5-391.75 | C42: ='SAF 011'!E40 -> PROTESIS ORTOPEDICA; COMPONENTES: PLACAS DE RECONSTRUCCION, USO: OSTEOSINTESIS | H42: SI | I42: ='SAF 011'!F44 -> UNIDAD | J42: ='SAF 011'!H40 -> 44000 | K42: ='SAF 011'!G40 -> 8
A43: 32 | B43: ='SAF 011'!B41 -> 2.9.5-391.75 | C43: ='SAF 011'!E41 -> PROTESIS ORTOPEDICA; COMPONENTES: PLACAS DE RECONSTRUCCION, USO: OSTEOSINTESIS | H43: SI | I43: ='SAF 011'!F46 -> UNIDAD | J43: ='SAF 011'!H41 -> 44000 | K43: ='SAF 011'!G41 -> 7
...

Sheet APG
A1: EJERCICIO: 2022 | P1: AUTORIZACION PARA GASTAR
A4: JURISDICCIÓN: | G4: =NP!D3 -> 40 - MINISTERIO DE SALUD
A5: SAF: | G5: =NP!D4 -> 011 - DIRECCION PROVINCIAL DE ADMINISTRACION - M.S.
A6: UNIDAD EJECUTORA: | G6: =NP!D5 -> 131 - DIRECCION PROVINCIAL DE MEDICINA SOCIAL INTEGRAL
A7: DEPENDENCIA SOLICITANTE: | G7: =NP!D6 -> 131 - DIRECCION PROVINCIAL DE MEDICINA SOCIAL INTEGRAL
A8: AUTORIZACIÓN:
A9: Señor Director de Administración o Titular del Servicio Administrativo Financiero:
A10: Autorizo la realización de los trámites correspondientes, a fin de proveer a este Organismo los bienes que se detallan en Nota de Pedido, afectando la erogación resultante a los créditos presupuestarios aprobados a favor de esta Unidad Ejecutora, conforme al siguiente detalle:
A12: IMPUTACIÓN PRESUPUESTARIA
A13: CÓDIGO | O13: DENOMINACIÓN DE LA PARTIDA PRESUPUESTARIA | Q13: IMPORTE
A14: PR | B14: SB | C14: PY | D14: AC | E14: OB | F14: UG | G14: FIN | H14: FUN | I14: I | J14: P | K14: P | L14: SubP | M14: M | N14: FF
A15: 41 | D15: 1 | F15: 4901 | G15: 3 | H15: 2 | I15: 2 | J15: 9 | K15: 5 | M15: 1 | N15: 1.1 | O15: UTILES MENORES MEDICO, QUIRURGICO Y DE LABORATORIO | Q15: 19520000
A38: TOTAL DE PESOS: DIECINUEVE MILLONES QUINIENTOS VEINTE MIL CON 00/100.- | Q38: =+Q15 -> 19520000
A40: JUSTIFICACIÓN:
A41: =NP!D8 -> CONTRATACION PARA LA PROVISION DE PROTESIS DE TRAUMA PARA PERSONAS DE ESCASOS RECURSOS PERTENECIENTES A LA DIRECCION PROVINCIAL DE MEDICINA SOCIAL INTEGRAL.
