Workbook

Sheet SAF 011
A1: 2022
B2: Pedido de Necesidades Trimestrales
A4: JURISDICCION: | C4: 040 - MINISTERIO DE SALUD
A5: SAF N°: | C5: 011 - DIRECCION PROVINCIAL DE ADMINISTRACION - MINISTERIO DE SALUD
A6: EJERCICIO: | C6: 2022
A7: TRIMESTRE: | C7: PRIMERO
A9: ID | B9: CODIGO ITEM | C9: RUBRO DE COMPRA | D9: I.P.P. | E9: DESCRIPCION | F9: UNIDAD DE MEDIDA | G9: SECRETARIA DE ADMINISTRACION | H9: TOTAL S.A. | I9: SMPyPS | J9: TOTAL SMPyPS | K9: DIR. LAB. CENTRAL | L9: TOTAL DE LAB CENTRAL | M9: BCO DE SANGRE | N9: TOTAL BANCO DE SANGRE | O9: APS | P9: TOTAL A.P.S. | Q9: DIR DE CANCER | R9: TOTAL DE DIR DE CANCER | S9: FARMACIA | T9: TOTAL FARMACIA | U9: ODONTOLOGIA | V9: TOTAL DE ODONTOLOG | W9: SAME | X9: TOTAL SAME | Y9: HPTAL MALBRAN | Z9: TOTAL HPTAL MALBRAN | AA9: MATERNIDAD E INFANCIA | AB9: TOTAL MATERNIDAD E INFANCIA | AC9: SASP | AD9: TOTAL SASP | AE9: SALUD Y MEDIO AMBIENTE | AF9: TOTAL SALUD Y MEDIO AMBIENTE | AG9: VECTORES Y ZOONOSIS | AH9: TOTAL DE VECT Y ZOON | AI9: CRONICAS | AJ9: TOTAL CRONICAS | AK9: CUR | AL9: TOTAL CUR | AM9: SPyGS | AN9: TOTAL SPyGS | AO9: SALUD MENTAL | AP9: TOTAL SALUD MENTAL | AQ9: AREAS Y DPAS | AR9: TOTAL DPAS | AS9: EPIDEMIOLOGIA | AT9: TOTAL EPIDEMIOLOGIA | AU9: AREA 1 | AV9: TOTAL AREA 1 | AW9: CANTIDAD TOTAL | AX9: PRECIO UNITARIO ESTIMADO | AY9: IMPORTE TOTAL ESTIMADO | AZ9: ESPECIFICACION TECNICA
A10: 1 | B10: 2.9.5-470.13 | C10: PROD. MEDICO/FARMACEUTICOS/LAB | D10: 2.9.5 | E10: ALGODONES; TIPO: HIDROFILADO, CAPACIDAD: 500 GR, PRESENTACION: ENVASE X 500 GR | F10: UNIDAD | T10: =+S10*AX10 -> 0 | AE10: 6 | AF10: =+AE10*AX10 -> 2269.44 | AW10: =+AQ10+AO10+AM10+AK10+AI10+AG10+AE10+AC10+AA10+Y10+W10+U10+S10+Q10+O10+M10+K10+I10+AS10+G10+AU10 -> 6 | AX10: 378.24 | AY10: =+AW10*AX10 -> 2269.44
A11: 2 | B11: 2.9.5-287.3 | C11: PROD. MEDICO/FARMACEUTICOS/LAB | D11: 2.9.5 | E11: AMPOLLAS P/DECANTACION; CAPACIDAD: 1000 mL | F11: UNIDAD | T11: =+S11*AX11 -> 0 | AE11: 1 | AF11: =+AE11*AX11 -> 8292 | AW11: =+AQ11+AO11+AM11+AK11+AI11+AG11+AE11+AC11+AA11+Y11+W11+U11+S11+Q11+O11+M11+K11+I11+AS11+G11+AU11 -> 1 | AX11: 8292 | AY11: =+AW11*AX11 -> 8292
A12: 3 | B12: 2.9.5-5703.8 | C12: PROD. MEDICO/FARMACEUTICOS/LAB | D12: 2.9.5 | E12: ANSA; PRESENTACION: ENVASE X 20 UN, TIPO: CALIBRADA | F12: caja | T12: =+S12*AX12 -> 0 | AE12: 1 | AF12: =+AE12*AX12 -> 1507.2 | AW12: =+AQ12+AO12+AM12+AK12+AI12+AG12+AE12+AC12+AA12+Y12+W12+U12+S12+Q12+O12+M12+K12+I12+AS12+G12+AU12 -> 1 | AX12: 1507.2 | AY12: =+AW12*AX12 -> 1507.2
A13: 4 | B13: 2.9.5-5703.9 | C13: PROD. MEDICO/FARMACEUTICOS/LAB | D13: 2.9.5 | E13: ANSA; PRESENTACION: ENVASE X 20 UN, TIPO: PUNTA RECTA | F13: caja | T13: =+S13*AX13 -> 0 | AE13: 1 | AF13: =+AE13*AX13 -> 1231.18 | AW13: =+AQ13+AO13+AM13+AK13+AI13+AG13+AE13+AC13+AA13+Y13+W13+U13+S13+Q13+O13+M13+K13+I13+AS13+G13+AU13 -> 1 | AX13: 1231.18 | AY13: =+AW13*AX13 -> 1231.18
A14: 5 | B14: 2.9.5-5703.15 | C14: PROD. MEDICO/FARMACEUTICOS/LAB | D14: 2.9.5 | E14: ANSA; PRESENTACION: UNIDAD, TIPO: PLASTICA DESCARTABLE | F14: UNIDAD | T14: =+S14*AX14 -> 0 | AE14: 200 | AF14: =+AE14*AX14 -> 2400 | AW14: =+AQ14+AO14+AM14+AK14+AI14+AG14+AE14+AC14+AA14+Y14+W14+U14+S14+Q14+O14+M14+K14+I14+AS14+G14+AU14 -> 200 | AX14: 12 | AY14: =+AW14*AX14 -> 2400
A15: 6 | B15: 2.9.5-2505.16 | C15: PROD. MEDICO/FARMACEUTICOS/LAB | D15: 2.9.5 | E15: BOLSAS COLECTORAS; TIPO: ESTERIL, USO: MUESTREO, CAPACIDAD: 400 mL | F15: UNIDAD | T15: =+S15*AX15 -> 0 | AE15: 10 | AF15: =+AE15*AX15 -> 44400 | AW15: =+AQ15+AO15+AM15+AK15+AI15+AG15+AE15+AC15+AA15+Y15+W15+U15+S15+Q15+O15+M15+K15+I15+AS15+G15+AU15 -> 10 | AX15: 4440 | AY15: =+AW15*AX15 -> 44400
A16: 7 | B16: 2.9.5-5770.9 | C16: PROD. MEDICO/FARMACEUTICOS/LAB | D16: 2.9.5 | E16: CAPSULAS DE PORCELANA; USO: P/CALCINACION, CAPACIDAD: 100 CM3, MEDIDAS: 136-100 mm, DIMENSION: 136-100 mm | F16: UNIDAD | T16: =+S16*AX16 -> 0 | AE16: 10 | AF16: =+AE16*AX16 -> 7620 | AW16: =+AQ16+AO16+AM16+AK16+AI16+AG16+AE16+AC16+AA16+Y16+W16+U16+S16+Q16+O16+M16+K16+I16+AS16+G16+AU16 -> 10 | AX16: 762 | AY16: =+AW16*AX16 -> 7620
A17: 8 | B17: 2.9.5-5770.10 | C17: PROD. MEDICO/FARMACEUTICOS/LAB | D17: 2.9.5 | E17: CAPSULAS DE PORCELANA; USO: P/LABORATORIO, CAPACIDAD: 75 mL, MEDIDAS: 50 X 44 mm, DIMENSION: 50 X 44 mm | F17: UNIDAD | T17: =+S17*AX17 -> 0 | AE17: 10 | AF17: =+AE17*AX17 -> 6943.2 | AW17: =+AQ17+AO17+AM17+AK17+AI17+AG17+AE17+AC17+AA17+Y17+W17+U17+S17+Q17+O17+M17+K17+I17+AS17+G17+AU17 -> 10 | AX17: 694.32 | AY17: =+AW17*AX17 -> 6943.2
A18: 9 | B18: 2.9.5-1908.12 | C18: PROD. MEDICO/FARMACEUTICOS/LAB | D18: 2.9.5 | E18: CEPILLOS P/LABORATORIO; TIPO: LIMPIEZA DE TUBOS, MATERIAL: CERDA, TAMAÑO: 1 Cm | F18: UNIDAD | T18: =+S18*AX18 -> 0 | AE18: 10 | AF18: =+AE18*AX18 -> 1238.6 | AW18: =+AQ18+AO18+AM18+AK18+AI18+AG18+AE18+AC18+AA18+Y18+W18+U18+S18+Q18+O18+M18+K18+I18+AS18+G18+AU18 -> 10 | AX18: 123.86 | AY18: =+AW18*AX18 -> 1238.6
A19: 10 | B19: 2.9.5-1908.3 | C19: PROD. MEDICO/FARMACEUTICOS/LAB | D19: 2.9.5 | E19: CEPILLOS P/LABORATORIO; TIPO: LIMPIEZA DE TUBOS, MATERIAL: CERDA, TAMAÑO: CHICO | F19: UNIDAD | T19: =+S19*AX19 -> 0 | AE19: 10 | AF19: =+AE19*AX19 -> 1492.3 | AW19: =+AQ19+AO19+AM19+AK19+AI19+AG19+AE19+AC19+AA19+Y19+W19+U19+S19+Q19+O19+M19+K19+I19+AS19+G19+AU19 -> 10 | AX19: 149.23 | AY19: =+AW19*AX19 -> 1492.3
A20: 11 | B20: 2.9.5-1908.2 | C20: PROD. MEDICO/FARMACEUTICOS/LAB | D20: 2.9.5 | E20: CEPILLOS P/LABORATORIO; TIPO: LIMPIEZA DE TUBOS, MATERIAL: CERDA, TAMAÑO: MEDIANO | F20: UNIDAD | T20: =+S20*AX20 -> 0 | AE20: 10 | AF20: =+AE20*AX20 -> 2820.4 | AW20: =+AQ20+AO20+AM20+AK20+AI20+AG20+AE20+AC20+AA20+Y20+W20+U20+S20+Q20+O20+M20+K20+I20+AS20+G20+AU20 -> 10 | AX20: 282.04 | AY20: =+AW20*AX20 -> 2820.4
A21: 12 | B21: 2.9.5-1908.40 | C21: PROD. MEDICO/FARMACEUTICOS/LAB | D21: 2.9.5 | E21: CEPILLOS P/LABORATORIO; TIPO: LIMPIEZA ERLENMEYER, MATERIAL: CERDA, TAMAÑO: DIAM. 45 mm | F21: UNIDAD | T21: =+S21*AX21 -> 0 | AE21: 5 | AF21: =+AE21*AX21 -> 2539.8 | AW21: =+AQ21+AO21+AM21+AK21+AI21+AG21+AE21+AC21+AA21+Y21+W21+U21+S21+Q21+O21+M21+K21+I21+AS21+G21+AU21 -> 5 | AX21: 507.96 | AY21: =+AW21*AX21 -> 2539.8
... A33: 24 | B33: 2.9.5-448.79 | C33: PROD. MEDICO/FARMACEUTICOS/LAB | D33: 2.9.5 | E33: FRASCOS ESTERILES; CAPACIDAD: 250 mL, PRESENTACION: UNIDAD, GRABADO: SIN, USO: LABORATORIO | F33: UNIDAD | T33: =+S33*AX33 -> 0 | AE33: 10 | AF33: =+AE33*AX33 -> 1879.2 | AW33: =+AQ33+AO33+AM33+AK33+AI33+AG33+AE33+AC33+AA33+Y33+W33+U33+S33+Q33+O33+M33+K33+I33+AS33+G33+AU33 -> 10 | AX33: 187.92 | AY33: =+AW33*AX33 -> 1879.2
A34: 25 | B34: 2.9.5-2600.22 | C34: PROD. MEDICO/FARMACEUTICOS/LAB | D34: 2.9.5 | E34: FRASCOS P/MUESTRAS; DIMENSION: SIN VALOR, MATERIAL: VIDRIO GRADUADO AUTOCLAVABLE, CAPACIDAD: 250 mL, TAPA: A ROSCA | F34: UNIDAD | AE34: 10 | AF34: =+AE34*AX34 -> 7116 | AW34: =+AQ34+AO34+AM34+AK34+AI34+AG34+AE34+AC34+AA34+Y34+W34+U34+S34+Q34+O34+M34+K34+I34+AS34+G34+AU34 -> 10 | AX34: 711.6 | AY34: =+AW34*AX34 -> 7116
A35: 26 | B35: 2.9.5-2600.23 | C35: PROD. MEDICO/FARMACEUTICOS/LAB | D35: 2.9.5 | E35: FRASCOS P/MUESTRAS; DIMENSION: SIN VALOR, MATERIAL: VIDRIO GRADUADO AUTOCLAVABLE, CAPACIDAD: 500 mL, TAPA: A ROSCA | F35: UNIDAD | T35: =+S35*AX35 -> 0 | AE35: 10 | AF35: =+AE35*AX35 -> 8085.6 | AW35: =+AQ35+AO35+AM35+AK35+AI35+AG35+AE35+AC35+AA35+Y35+W35+U35+S35+Q35+O35+M35+K35+I35+AS35+G35+AU35 -> 10 | AX35: 808.56 | AY35: =+AW35*AX35 -> 8085.6
A36: 27 | B36: 2.9.5-2600.117 | C36: PROD. MEDICO/FARMACEUTICOS/LAB | D36: 2.9.5 | E36: FRASCOS P/MUESTRAS; MATERIAL: VIDRIO GRADUADO AUTOCLAVABLE, DIMENSION: NO APLICA, CAPACIDAD: 100 mL, TAPA: A ROSCA | F36: UNIDAD | T36: =+S36*AX36 -> 0 | AE36: 10 | AF36: =+AE36*AX36 -> 5472 | AW36: =+AQ36+AO36+AM36+AK36+AI36+AG36+AE36+AC36+AA36+Y36+W36+U36+S36+Q36+O36+M36+K36+I36+AS36+G36+AU36 -> 10 | AX36: 547.2 | AY36: =+AW36*AX36 -> 5472
A37: 28 | B37: 2.9.5-2600.24 | C37: PROD. MEDICO/FARMACEUTICOS/LAB | D37: 2.9.5 | E37: FRASCOS P/MUESTRAS; MATERIAL: VIDRIO GRADUADO AUTOCLAVABLE, DIMENSION: SIN VALOR, CAPACIDAD: 1000 mL, TAPA: A ROSCA | F37: UNIDAD | T37: =+S37*AX37 -> 0 | AE37: 10 | AF37: =+AE37*AX37 -> 15117.6 | AW37: =+AQ37+AO37+AM37+AK37+AI37+AG37+AE37+AC37+AA37+Y37+W37+U37+S37+Q37+O37+M37+K37+I37+AS37+G37+AU37 -> 10 | AX37: 1511.76 | AY37: =+AW37*AX37 -> 15117.6
A38: 29 | B38: 2.9.5-3017.1 | C38: PROD. MEDICO/FARMACEUTICOS/LAB | D38: 2.9.5 | E38: GRADILLAS P/LABORATORIO; CANTIDAD DE TUBOS: 48, MATERIAL: ALAMBRE PLASTIFICADO, MEDIDA TUBO: 6 X 1,5 Cm, TAMAÑO TUBO: 6 X 1,5 Cm, CANT. DE ELEMENTOS: 48, MEDIDA: 6 X 1,5 Cm | F38: UNIDAD | T38: =+S38*AX38 -> 0 | AE38: 5 | AF38: =+AE38*AX38 -> 23880 | AW38: =+AQ38+AO38+AM38+AK38+AI38+AG38+AE38+AC38+AA38+Y38+W38+U38+S38+Q38+O38+M38+K38+I38+AS38+G38+AU38 -> 5 | AX38: 4776 | AY38: =+AW38*AX38 -> 23880
A39: 30 | B39: 2.9.5-3017.3 | C39: PROD. MEDICO/FARMACEUTICOS/LAB | D39: 2.9.5 | E39: GRADILLAS P/LABORATORIO; TAMAÑO TUBO: 13 mm, CANTIDAD DE TUBOS: 36, MATERIAL: VIDRIO FORRADA, MEDIDA TUBO: 13 mm, CANT. DE ELEMENTOS: 36, MEDIDA: 13 mm | F39: UNIDAD | T39: =+S39*AX39 -> 0 | AE39: 5 | AF39: =+AE39*AX39 -> 16560 | AW39: =+AQ39+AO39+AM39+AK39+AI39+AG39+AE39+AC39+AA39+Y39+W39+U39+S39+Q39+O39+M39+K39+I39+AS39+G39+AU39 -> 5 | AX39: 3312 | AY39: =+AW39*AX39 -> 16560
A40: 31 | B40: 2.9.5-3017.4 | C40: PROD. MEDICO/FARMACEUTICOS/LAB | D40: 2.9.5 | E40: GRADILLAS P/LABORATORIO; TAMAÑO TUBO: 3,4 X 12 Cm, CANTIDAD DE TUBOS: 12, MATERIAL: ALAMBRE PLASTIFICADO, MEDIDA TUBO: 3,4 X 12 Cm, CANT. DE ELEMENTOS: 12, MEDIDA: 3,4 X 12 Cm | F40: UNIDAD | T40: =+S40*AX40 -> 0 | AE40: 5 | AF40: =+AE40*AX40 -> 12918 | AW40: =+AQ40+AO40+AM40+AK40+AI40+AG40+AE40+AC40+AA40+Y40+W40+U40+S40+Q40+O40+M40+K40+I40+AS40+G40+AU40 -> 5 | AX40: 2583.6 | AY40: =+AW40*AX40 -> 12918
A41: 32 | B41: 2.9.5-7591.1 | C41: PROD. MEDICO/FARMACEUTICOS/LAB | D41: 2.9.5 | E41: MANGOS DE KOLL; LARGO: 25 Cm, MATERIAL: ACERO INOXIDABLE, PRESENTACION: UNIDAD, USO: TOMA DE MUESTRAS | F41: UNIDAD | T41: =+S41*AX41 -> 0 | AE41: 3 | AF41: =+AE41*AX41 -> 5364 | AW41: =+AQ41+AO41+AM41+AK41+AI41+AG41+AE41+AC41+AA41+Y41+W41+U41+S41+Q41+O41+M41+K41+I41+AS41+G41+AU41 -> 3 | AX41: 1788 | AY41: =+AW41*AX41 -> 5364
A42: 33 | B42: 2.9.5-4539.37 | C42: PROD. MEDICO/FARMACEUTICOS/LAB | D42: 2.9.5 | E42: MATRAZ AFORADO; ESTADO: SOLIDO, MATERIAL: POLIPROPILENO, PRESENTACION: UNIDAD, CAPACIDAD: 100 mL | F42: UNIDAD | T42: =+S42*AX42 -> 0 | AE42: 5 | AF42: =+AE42*AX42 -> 4117.2 | AW42: =+AQ42+AO42+AM42+AK42+AI42+AG42+AE42+AC42+AA42+Y42+W42+U42+S42+Q42+O42+M42+K42+I42+AS42+G42+AU42 -> 5 | AX42: 823.44 | AY42: =+AW42*AX42 -> 4117.2
A43: 34 | B43: 2.9.5-4539.40 | C43: PROD. MEDICO/FARMACEUTICOS/LAB | D43: 2.9.5 | E43: MATRAZ AFORADO; ESTADO: SOLIDO, MATERIAL: POLIPROPILENO, PRESENTACION: UNIDAD, CAPACIDAD: 250 mL | F43: UNIDAD | T43: =+S43*AX43 -> 0 | AE43: 5 | AF43: =+AE43*AX43 -> 5358.2 | AW43: =+AQ43+AO43+AM43+AK43+AI43+AG43+AE43+AC43+AA43+Y43+W43+U43+S43+Q43+O43+M43+K43+I43+AS43+G43+AU43 -> 5 | AX43: 1071.64 | AY43: =+AW43*AX43 -> 5358.2
A44: 35 | B44: 2.9.5-4539.8 | C44: PROD. MEDICO/FARMACEUTICOS/LAB | D44: 2.9.5 | E44: MATRAZ AFORADO; ESTADO: SOLIDO, MATERIAL: VIDRIO BOROSILICATO, PRESENTACION: UNIDAD, CAPACIDAD: 250 mL | F44: UNIDAD | T44: =+S44*AX44 -> 0 | AE44: 10 | AF44: =+AE44*AX44 -> 11242.8 | AW44: =+AQ44+AO44+AM44+AK44+AI44+AG44+AE44+AC44+AA44+Y44+W44+U44+S44+Q44+O44+M44+K44+I44+AS44+G44+AU44 -> 10 | AX44: 1124.28 | AY44: =+AW44*AX44 -> 11242.8
A45: 36 | B45: 2.9.5-4539.21 | C45: PROD. MEDICO/FARMACEUTICOS/LAB | D45: 2.9.5 | E45: MATRAZ AFORADO; ESTADO: SOLIDO, MATERIAL: VIDRIO, PRESENTACION: UNIDAD, CAPACIDAD: 100 Ml | F45: UNIDAD | T45: =+S45*AX45 -> 0 | AE45: 10 | AF45: =+AE45*AX45 -> 8410.8 | AW45: =+AQ45+AO45+AM45+AK45+AI45+AG45+AE45+AC45+AA45+Y45+W45+U45+S45+Q45+O45+M45+K45+I45+AS45+G45+AU45 -> 10 | AX45: 841.08 | AY45: =+AW45*AX45 -> 8410.8
A46: 37 | B46: 2.9.5-4539.22 | C46: PROD. MEDICO/FARMACEUTICOS/LAB | D46: 2.9.5 | E46: MATRAZ AFORADO; ESTADO: SOLIDO, MATERIAL: VIDRIO, PRESENTACION: UNIDAD, CAPACIDAD: 200 Ml | F46: UNIDAD | T46: =+S46*AX46 -> 0 | AE46: 10 | AF46: =+AE46*AX46 -> 10707.6 | AW46: =+AQ46+AO46+AM46+AK46+AI46+AG46+AE46+AC46+AA46+Y46+W46+U46+S46+Q46+O46+M46+K46+I46+AS46+G46+AU46 -> 10 | AX46: 1070.76 | AY46: =+AW46*AX46 -> 10707.6
... A50: 41 | B50: 2.9.5-3024.49 | C50: PROD. MEDICO/FARMACEUTICOS/LAB | D50: 2.9.5 | E50: PAPEL FILTRO; FORMA: CIRCULAR, DIMENSION: 110 mm, PORO: WATMAN 40/41, PRESENTACION: ENVASE X 100 | F50: UNIDAD | T50: =+S50*AX50 -> 0 | AE50: 1 | AF50: =+AE50*AX50 -> 8784 | AW50: =+AQ50+AO50+AM50+AK50+AI50+AG50+AE50+AC50+AA50+Y50+W50+U50+S50+Q50+O50+M50+K50+I50+AS50+G50+AU50 -> 1 | AX50: 8784 | AY50: =+AW50*AX50 -> 8784
A51: 42 | B51: 2.9.5-469.92 | C51: PROD. MEDICO/FARMACEUTICOS/LAB | D51: 2.9.5 | E51: PIPETAS DE VIDRIO; USO: GENERAL, TIPO: GRADUADA X 1 ML | F51: UNIDAD | AE51: 10 | AF51: =+AE51*AX51 -> 3483.6 | AW51: =+AQ51+AO51+AM51+AK51+AI51+AG51+AE51+AC51+AA51+Y51+W51+U51+S51+Q51+O51+M51+K51+I51+AS51+G51+AU51 -> 10 | AX51: 348.36 | AY51: =+AW51*AX51 -> 3483.6
A52: 43 | B52: 2.9.5-469.36 | C52: PROD. MEDICO/FARMACEUTICOS/LAB | D52: 2.9.5 | E52: PIPETAS DE VIDRIO; USO: LABORATORIO, TIPO: 1 AFORO DE 50 ML | F52: UNIDAD | T52: =+S52*AX52 -> 0 | AE52: 10 | AF52: =+AE52*AX52 -> 4140 | AW52: =+AQ52+AO52+AM52+AK52+AI52+AG52+AE52+AC52+AA52+Y52+W52+U52+S52+Q52+O52+M52+K52+I52+AS52+G52+AU52 -> 10 | AX52: 414 | AY52: =+AW52*AX52 -> 4140
A53: 44 | B53: 2.9.5-469.62 | C53: PROD. MEDICO/FARMACEUTICOS/LAB | D53: 2.9.5 | E53: PIPETAS DE VIDRIO; USO: LABORATORIO, TIPO: AFORO SIMPLE 100 ML | F53: UNIDAD | T53: =+S53*AX53 -> 0 | AE53: 10 | AF53: =+AE53*AX53 -> 4320 | AW53: =+AQ53+AO53+AM53+AK53+AI53+AG53+AE53+AC53+AA53+Y53+W53+U53+S53+Q53+O53+M53+K53+I53+AS53+G53+AU53 -> 10 | AX53: 432 | AY53: =+AW53*AX53 -> 4320
A54: 45 | B54: 2.9.5-469.59 | C54: PROD. MEDICO/FARMACEUTICOS/LAB | D54: 2.9.5 | E54: PIPETAS DE VIDRIO; USO: LABORATORIO, TIPO: DOBLE AFORO 100 mL | F54: UNIDAD | T54: =+S54*AX54 -> 0 | AE54: 5 | AF54: =+AE54*AX54 -> 60374.15 | AW54: =+AQ54+AO54+AM54+AK54+AI54+AG54+AE54+AC54+AA54+Y54+W54+U54+S54+Q54+O54+M54+K54+I54+AS54+G54+AU54 -> 5 | AX54: 12074.83 | AY54: =+AW54*AX54 -> 60374.15
A55: 46 | B55: 2.9.5-469.45 | C55: PROD. MEDICO/FARMACEUTICOS/LAB | D55: 2.9.5 | E55: PIPETAS DE VIDRIO; USO: LABORATORIO, TIPO: DOBLE AFORO 11 Ml | F55: UNIDAD | T55: =+S55*AX55 -> 0 | AE55: 10 | AF55: =+AE55*AX55 -> 22369 | AW55: =+AQ55+AO55+AM55+AK55+AI55+AG55+AE55+AC55+AA55+Y55+W55+U55+S55+Q55+O55+M55+K55+I55+AS55+G55+AU55 -> 10 | AX55: 2236.9 | AY55: =+AW55*AX55 -> 22369
A56: 47 | B56: 2.9.5-469.35 | C56: PROD. MEDICO/FARMACEUTICOS/LAB | D56: 2.9.5 | E56: PIPETAS DE VIDRIO; USO: LABORATORIO, TIPO: DOBLE AFORO 25 mL | F56: UNIDAD | T56: =+S56*AX56 -> 0 | AE56: 5 | AF56: =+AE56*AX56 -> 17899.2 | AW56: =+AQ56+AO56+AM56+AK56+AI56+AG56+AE56+AC56+AA56+Y56+W56+U56+S56+Q56+O56+M56+K56+I56+AS56+G56+AU56 -> 5 | AX56: 3579.84 | AY56: =+AW56*AX56 -> 17899.2
...

Sheet NP
A1: NOTA DE PEDIDO | J1: N° | K1: 02/2022
A3: JURISDICCIÓN: | D3: ='SAF 011'!C4 -> 040 - MINISTERIO DE SALUD
A4: SAF: | D4: ='SAF 011'!C5 -> 011 - DIRECCION PROVINCIAL DE ADMINISTRACION - MINISTERIO DE SALUD
A5: UNIDAD EJECUTORA: | D5: DIRECCION PROVINCIAL DE SALUD Y MEDIO AMBIENTE
A6: DEPENDENCIA SOLICITANTE: | D6: DIRECCION PROVINCIAL DE SALUD Y MEDIO AMBIENTE
A7: PERIODO UTILIZACIÓN: | D7: 1° TRIMESTRE 2022
A8: OBJETO: | D8: ADQUISICION DEL RUBRO UTILES DE LABORATORIO
A10: Ítem | B10: Codigo Item | C10: DESCRIPCIÓN | H10: Adjunta Detalle Técnico | I10: Unidad Medida | J10: Precio Unitario Estimado | K10: Cantidad Solicitada
A12: 1 | B12: ='SAF 011'!B10 -> 2.9.5-470.13 | C12: ='SAF 011'!E10 -> ALGODONES; TIPO: HIDROFILADO, CAPACIDAD: 500 GR, PRESENTACION: ENVASE X 500 GR | H12: NO | I12: ='SAF 011'!F10 -> UNIDAD | J12: ='SAF 011'!AX10 -> 378.24 | K12: ='SAF 011'!AE10 -> 6 | M12: =+J12*K12 -> 2269.44
A13: 2 | B13: ='SAF 011'!B11 -> 2.9.5-287.3 | C13: ='SAF 011'!E11 -> AMPOLLAS P/DECANTACION; CAPACIDAD: 1000 mL | H13: NO | I13: ='SAF 011'!F11 -> UNIDAD | J13: ='SAF 011'!AX11 -> 8292 | K13: ='SAF 011'!AE11 -> 1 | M13: =+J13*K13 -> 8292
A14: 3 | B14: ='SAF 011'!B12 -> 2.9.5-5703.8 | C14: ='SAF 011'!E12 -> ANSA; PRESENTACION: ENVASE X 20 UN, TIPO: CALIBRADA | H14: NO | I14: ='SAF 011'!F12 -> caja | J14: ='SAF 011'!AX12 -> 1507.2 | K14: ='SAF 011'!AE12 -> 1 | M14: =+J14*K14 -> 1507.2
A15: 4 | B15: ='SAF 011'!B13 -> 2.9.5-5703.9 | C15: ='SAF 011'!E13 -> ANSA; PRESENTACION: ENVASE X 20 UN, TIPO: PUNTA RECTA | H15: NO | I15: ='SAF 011'!F13 -> caja | J15: ='SAF 011'!AX13 -> 1231.18 | K15: ='SAF 011'!AE13 -> 1 | M15: =+J15*K15 -> 1231.18
A16: 5 | B16: ='SAF 011'!B14 -> 2.9.5-5703.15 | C16: ='SAF 011'!E14 -> ANSA; PRESENTACION: UNIDAD, TIPO: PLASTICA DESCARTABLE | H16: NO | I16: ='SAF 011'!F14 -> UNIDAD | J16: ='SAF 011'!AX14 -> 12 | K16: ='SAF 011'!AE14 -> 200 | M16: =+J16*K16 -> 2400
A17: 6 | B17: ='SAF 011'!B15 -> 2.9.5-2505.16 | C17: ='SAF 011'!E15 -> BOLSAS COLECTORAS; TIPO: ESTERIL, USO: MUESTREO, CAPACIDAD: 400 mL | H17: NO | I17: ='SAF 011'!F15 -> UNIDAD | J17: ='SAF 011'!AX15 -> 4440 | K17: ='SAF 011'!AE15 -> 10 | M17: =+J17*K17 -> 44400
A18: 7 | B18: ='SAF 011'!B16 -> 2.9.5-5770.9 | C18: ='SAF 011'!E16 -> CAPSULAS DE PORCELANA; USO: P/CALCINACION, CAPACIDAD: 100 CM3, MEDIDAS: 136-100 mm, DIMENSION: 136-100 mm | H18: NO | I18: ='SAF 011'!F16 -> UNIDAD | J18: ='SAF 011'!AX16 -> 762 | K18: ='SAF 011'!AE16 -> 10 | M18: =+J18*K18 -> 7620
A19: 8 | B19: ='SAF 011'!B17 -> 2.9.5-5770.10 | C19: ='SAF 011'!E17 -> CAPSULAS DE PORCELANA; USO: P/LABORATORIO, CAPACIDAD: 75 mL, MEDIDAS: 50 X 44 mm, DIMENSION: 50 X 44 mm | H19: NO | I19: ='SAF 011'!F17 -> UNIDAD | J19: ='SAF 011'!AX17 -> 694.32 | K19: ='SAF 011'!AE17 -> 10 | M19: =+J19*K19 -> 6943.2
A20: 9 | B20: ='SAF 011'!B18 -> 2.9.5-1908.12 | C20: ='SAF 011'!E18 -> CEPILLOS P/LABORATORIO; TIPO: LIMPIEZA DE TUBOS, MATERIAL: CERDA, TAMAÑO: 1 Cm | H20: NO | I20: ='SAF 011'!F18 -> UNIDAD | J20: ='SAF 011'!AX18 -> 123.86 | K20: ='SAF 011'!AE18 -> 10 | M20: =+J20*K20 -> 1238.6
A21: 10 | B21: ='SAF 011'!B19 -> 2.9.5-1908.3 | C21: ='SAF 011'!E19 -> CEPILLOS P/LABORATORIO; TIPO: LIMPIEZA DE TUBOS, MATERIAL: CERDA, TAMAÑO: CHICO | H21: NO | I21: ='SAF 011'!F19 -> UNIDAD | J21: ='SAF 011'!AX19 -> 149.23 | K21: ='SAF 011'!AE19 -> 10 | M21: =+J21*K21 -> 1492.3
A22: 11 | B22: ='SAF 011'!B20 -> 2.9.5-1908.2 | C22: ='SAF 011'!E20 -> CEPILLOS P/LABORATORIO; TIPO: LIMPIEZA DE TUBOS, MATERIAL: CERDA, TAMAÑO: MEDIANO | H22: NO | I22: ='SAF 011'!F20 -> UNIDAD | J22: ='SAF 011'!AX20 -> 282.04 | K22: ='SAF 011'!AE20 -> 10 | M22: =+J22*K22 -> 2820.4
A23: 12 | B23: ='SAF 011'!B21 -> 2.9.5-1908.40 | C23: ='SAF 011'!E21 -> CEPILLOS P/LABORATORIO; TIPO: LIMPIEZA ERLENMEYER, MATERIAL: CERDA, TAMAÑO: DIAM. 45 mm | H23: NO | I23: ='SAF 011'!F21 -> UNIDAD | J23: ='SAF 011'!AX21 -> 507.96 | K23: ='SAF 011'!AE21 -> 5 | M23: =+J23*K23 -> 2539.8
... A76: 65 | B76: ='SAF 011'!B74 -> 2.9.5-2764.7 | C76: ='SAF 011'!E74 -> VASO DE PRECIPITADO; MATERIAL: VIDRIO, TIPO: GRIFFIN, CAPACIDAD: 50 mL, GRADUADO: SI, GRADUACION: SI | H76: NO | I76: ='SAF 011'!F74 -> UNIDAD | J76: ='SAF 011'!AX74 -> 390 | K76: ='SAF 011'!AE74 -> 10 | M76: =+J76*K76 -> 3900
A78: Costo total estimado: SEISCIENTOS TRES MIL DOSCIENTOS TREINTA Y TRES CON 82/100.- | J78: =+M78 -> 603233.82 | M78: =SUM(M12:M77) -> 603233.82
M80: =+M78-M72 -> 602153.82

Sheet APG
A1: EJERCICIO: | D1: 2022 | P1: AUTORIZACION PARA GASTAR
A4: JURISDICCIÓN: | G4: =NP!D3 -> 040 - MINISTERIO DE SALUD
A5: SAF: | G5: =NP!D4 -> 011 - DIRECCION PROVINCIAL DE ADMINISTRACION - MINISTERIO DE SALUD
A6: UNIDAD EJECUTORA: | G6: =NP!D5 -> DIRECCION PROVINCIAL DE SALUD Y MEDIO AMBIENTE
A7: DEPENDENCIA SOLICITANTE: | G7: =NP!D6 -> DIRECCION PROVINCIAL DE SALUD Y MEDIO AMBIENTE
A8: AUTORIZACIÓN:
A9: Señor Director de Administración o Titular del Servicio Administrativo Financiero:
A10: Autorizo la realización de los trámites correspondientes, a fin de proveer a este Organismo los bienes que se detallan en Nota de Pedido N° 02/2022 afectando la erogación resultante a los créditos presupuestarios aprobados a favor de esta Unidad Ejecutora, conforme al siguiente detalle:
A12: IMPUTACIÓN PRESUPUESTARIA
A13: CÓDIGO | O13: DENOMINACIÓN DE LA PARTIDA PRESUPUESTARIA | Q13: IMPORTE
A14: PR | B14: SB | C14: PY | D14: AC | E14: OB | F14: UG | G14: FIN | H14: FUN | I14: I | J14: P | K14: P | L14: SubP | M14: M | N14: FF
A15: 22 | D15: 1 | F15: 4901 | G15: 2 | H15: 2 | I15: 2 | J15: 9 | K15: 5 | M15: 1 | N15: 1.1 | O15: UTILES MENORES MEDICOS, QUIRURGICOS Y DE LABORATORIO | Q15: =NP!M80 -> 602153.82
A16: 22 | D16: 1 | F16: 4901 | G16: 2 | H16: 2 | I16: 2 | J16: 9 | K16: 6 | M16: 1 | N16: 1.1 | O16: REPUESTOS Y ACCESORIOS | Q16: =NP!M72 -> 1080
A38: TOTAL DE PESOS: SEISCIENTOS TRES MIL DOSCIENTOS TREINTA Y TRES CON 82/100.- | Q38: =SUM(Q15:Q37) -> 603233.82
A40: JUSTIFICACIÓN:
A41: =NP!D8 -> ADQUISICION DEL RUBRO UTILES DE LABORATORIO
