Workbook

Sheet gas
B2: Pedido de Necesidades Trimestrales
A4: JURISDICCION: | C4: 45- Ministerio de Desarrollo Social y Deporte.-
A5: SAF N°: | C5: 25- Direccion Provincial de Gestion Administracion y RRHH
A6: EJERCICIO: | C6: 2020
A7: TRIMESTRE: | C7: 3
A9: ID | B9: CODIGO ITEM | C9: RUBRO DE COMPRA | D9: I.P.P. | E9: DESCRIPCION | F9: UNIDAD DE MEDIDA | G9: CANTIDAD | H9: PRECIO UNITARIO ESTIMADO | I9: IMPORTE TOTAL ESTIMADO
A10: 28 | B10: 2.5.6-798.8 | C10: COMBUSTIBLES Y LUBRICANTES | D10: 2.5.6 | E10: GAS EN GARRAFA; CAPACIDAD: 10 Kg | F10: UNIDAD | G10: 240 | H10: 450 | I10: =+G10*H10 -> 108000
B13: Especificidades Item N° 1:
B15: Descripción técnica
B16: GARRAFA X 10 KGS. TIPO COMERCIAL
B17: Plazos y lugares de entrega
B18: SEMANAL
B19: COMEDOR | D19: CANTIDAD | E19: DOMICILIO DE ENTREGA
B20: ='[1]COMEDORES EMERGENTES'!$B$3 -> UNA SONRISA AV. LOS COBACHO | D20: 1 | E20: ='[1]COMEDORES EMERGENTES'!$G$3 -> Bº SAN CARLOS OESTE AV. Bonifacio cobacho 670
B21: ='[1]COMEDORES EMERGENTES'!$B$4 -> C.I.F Nº1 - RIVERA DEL VALLE Y FLORIDA | D21: 1 | E21: ='[1]COMEDORES EMERGENTES'!$G$4 -> AV. RIVIERA DEL VALLE ENTRE FLORIDA Y SANTA FE
B22: ='[1]COMEDORES EMERGENTES'!$B$5 -> C.I.F - RIVERA DEL VALLE - DILORENZO | D22: 1 | E22: ='[1]COMEDORES EMERGENTES'!$G$5 -> Bº RIVERA DEL VALLE ENTRE VILLA EUMELIA Y MONTE CRISTO
B23: ='[1]COMEDORES EMERGENTES'!$B$6 -> ESFUERZO PROPIO- Bº ALTOS DE CHOYA | D23: 1 | E23: ='[1]COMEDORES EMERGENTES'!$G$6 -> Bº MUNICIPAL 35VV. NORTE C/14
B24: ='[1]COMEDORES EMERGENTES'!$B$7 -> ANGELITOS - LOTEO SUSSEX | D24: 1 | E24: ='[1]COMEDORES EMERGENTES'!$G$7 -> Bº LOTEO SUSEX MZA.Nº 4 LOTE Nº3
B25: ='[1]COMEDORES EMERGENTES'!$B$8 -> CLUB DEPORTIVO CHACARITA | D25: 1 | E25: ='[1]COMEDORES EMERGENTES'!$G$8 -> CALLE DR.DERMIDIO GALINDEZ C/2660
B26: ='[1]COMEDORES EMERGENTES'!$B$9 -> LA MORO | D26: 1 | E26: ='[1]COMEDORES EMERGENTES'!$G$9 -> MAIPU NORTE 1º ETAPA MZA "H" Bº MI JARDIN
B27: ='[1]COMEDORES EMERGENTES'!$B$10 -> PAPA FRANCISCO | D27: 1 | E27: ='[1]COMEDORES EMERGENTES'!$G$10 -> ENTRE AV.TEREBINTO Y AV.SAN JUAN LOTE "2" MZA. "B"
B28: ='[1]COMEDORES EMERGENTES'!$B$11 -> E.P.C - 100 V.V NORTE | D28: 1 | E28: ='[1]COMEDORES EMERGENTES'!$G$11 -> Bº VV NORTE C/48 ENTRE ESPAÑA Y FRANCIA
B29: ='[1]COMEDORES EMERGENTES'!$B$12 -> HOGAR DE CRISTO - PADRE RAUL CONTRERAS | D29: 1 | E29: ='[1]COMEDORES EMERGENTES'!$G$12 -> Bº SANTA MARTA MZA. "S" LOTE "M" C/39
B30: ='[1]COMEDORES EMERGENTES'!$B$13 -> LA LUCIERNAGA | D30: 1 | E30: ='[1]COMEDORES EMERGENTES'!$G$13 -> Bº 20 V.V NORTE C/3
B31: ='[1]COMEDORES EMERGENTES'!$B$14 -> VALLE VIEJO - SUMALAO | D31: 1 | E31: ='[1]COMEDORES EMERGENTES'!$G$14 -> PADRE SEGURA S/N
B32: ='[1]COMEDORES EMERGENTES'!$B$15 -> NUESTRO FUTURO - LAS VIAS | D32: 1 | E32: ='[1]COMEDORES EMERGENTES'!$G$15 -> Bº LAS VIAS OESTE LOTE 42
B33: ='[1]COMEDORES EMERGENTES'!$B$16 -> SAN JOSE OBRERO | D33: 1 | E33: ='[1]COMEDORES EMERGENTES'!$G$16 -> Bº SAN JOSE OBRERO. PJE. SANDOVAL S/Nº
B34: ='[1]COMEDORES EMERGENTES'!$B$17 -> VIRGEN DE LUJAN | D34: 1 | E34: ='[1]COMEDORES EMERGENTES'!$G$17 -> Bº OJO DE AGUA C/DR.TEODULFO BARRIONUEVO S/Nº
B35: ='[1]COMEDORES EMERGENTES'!$B$18 -> RENACER | D35: 1 | E35: ='[1]COMEDORES EMERGENTES'!$G$18 -> Bº VIRGEN MORENITA
B36: ='[1]COMEDORES EMERGENTES'!$B$19 -> CENTRO VECINAL MI JARDIN | D36: 1 | E36: ='[1]COMEDORES EMERGENTES'!$G$19 -> C/ LOS TULIPANES ENTRE FLOR DE CEREZO Y HOLANDA MZA.27 Bº MI JARDIN
B37: ='[1]COMEDORES EMERGENTES'!$B$20 -> LA VIEJA ESQUINA | D37: 1 | E37: ='[1]COMEDORES EMERGENTES'!$G$20 -> B° CRISTO REY PJE CAPATAZ VILLAFAÑEZ Y ARMANDO CORREA
B38: ='[1]COMEDORES EMERGENTES'!$B$21 -> GAUCHITO GIL | D38: 1 | E38: ='[1]COMEDORES EMERGENTES'!$G$21 -> B° 26 VIVIENDAS CASA N° 3
B39: ='[1]COMEDORES EMERGENTES'!$B$22 -> LOS TOLDOS | D39: 1 | E39: ='[1]COMEDORES EMERGENTES'!$G$22 -> LOTEO PARQUE SUR CALLE S/NOMBRE S/N°
B40: Garantia
B41: S/E

Sheet limpieza
B2: Pedido de Necesidades Trimestrales
A4: JURISDICCION: | C4: 45- Ministerio de Desarrollo Social y Deporte.-
A5: SAF N°: | C5: 25- Direccion Provincial de Gestion Administracion y RRHH
A6: EJERCICIO: | C6: 2020
A7: TRIMESTRE: | C7: 3
A9: ID | B9: CODIGO ITEM | C9: RUBRO DE COMPRA | D9: I.P.P. | E9: DESCRIPCION | F9: UNIDAD DE MEDIDA | G9: CANTIDAD | H9: PRECIO UNITARIO ESTIMADO | I9: IMPORTE TOTAL ESTIMADO
A10: 1 | B10: 2.9.1-6951.30 | C10: ELEMENTOS DE LIMPIEZA | D10: 2.9.1 | E10: LIMPIADORES; TIPO: LAVANDINA, PRESENTACION: ENVASE X 5 L | F10: LITROS | G10: 240 | H10: 175 | I10: =+H10*G10 -> 42000
A11: 2 | B11: 2.9.1-6951.12 | C11: ELEMENTOS DE LIMPIEZA | D11: 2.9.1 | E11: LIMPIADORES; PRESENTACION: ENVASE X 5 L, TIPO: DETERGENTE | F11: LITROS | G11: 240 | H11: 225 | I11: =+H11*G11 -> 54000
A12: 3 | B12: 2.9.1-4784.51 | C12: ELEMENTOS DE LIMPIEZA | D12: 2.9.1 | E12: LIMPIADORES MULTIUSO; COMPUESTOS BIODEGRADABLES: SI, PRESENTACION: ENVASE X 5 L, TIPO: DESENGRASANTE | F12: LITROS | G12: 240 | H12: 320 | I12: =+H12*G12 -> 76800
B15: Especificidades Item N° 1:
B17: Descripción técnica
C18: PRESENTACION EN BIDONES PLASTICOS POR 5LTS.
B19: Plazos y lugares de entrega
B20: SEMANAL
B21: COMEDOR | D21: CANTIDAD | E21: DOMICILIO DE ENTREGA
B22: ='[1]COMEDORES EMERGENTES'!$B$3 -> UNA SONRISA AV. LOS COBACHO | D22: 1 | E22: ='[1]COMEDORES EMERGENTES'!$G$3 -> Bº SAN CARLOS OESTE AV. Bonifacio cobacho 670
B23: ='[1]COMEDORES EMERGENTES'!$B$4 -> C.I.F Nº1 - RIVERA DEL VALLE Y FLORIDA | D23: 1 | E23: ='[1]COMEDORES EMERGENTES'!$G$4 -> AV. RIVIERA DEL VALLE ENTRE FLORIDA Y SANTA FE
B24: ='[1]COMEDORES EMERGENTES'!$B$5 -> C.I.F - RIVERA DEL VALLE - DILORENZO | D24: 1 | E24: ='[1]COMEDORES EMERGENTES'!$G$5 -> Bº RIVERA DEL VALLE ENTRE VILLA EUMELIA Y MONTE CRISTO
B25: ='[1]COMEDORES EMERGENTES'!$B$6 -> ESFUERZO PROPIO- Bº ALTOS DE CHOYA | D25: 1 | E25: ='[1]COMEDORES EMERGENTES'!$G$6 -> Bº MUNICIPAL 35VV. NORTE C/14
B26: ='[1]COMEDORES EMERGENTES'!$B$7 -> ANGELITOS - LOTEO SUSSEX | D26: 1 | E26: ='[1]COMEDORES EMERGENTES'!$G$7 -> Bº LOTEO SUSEX MZA.Nº 4 LOTE Nº3
B27: ='[1]COMEDORES EMERGENTES'!$B$8 -> CLUB DEPORTIVO CHACARITA | D27: 1 | E27: ='[1]COMEDORES EMERGENTES'!$G$8 -> CALLE DR.DERMIDIO GALINDEZ C/2660
B28: ='[1]COMEDORES EMERGENTES'!$B$9 -> LA MORO | D28: 1 | E28: ='[1]COMEDORES EMERGENTES'!$G$9 -> MAIPU NORTE 1º ETAPA MZA "H" Bº MI JARDIN
B29: ='[1]COMEDORES EMERGENTES'!$B$10 -> PAPA FRANCISCO | D29: 1 | E29: ='[1]COMEDORES EMERGENTES'!$G$10 -> ENTRE AV.TEREBINTO Y AV.SAN JUAN LOTE "2" MZA. "B"
B30: ='[1]COMEDORES EMERGENTES'!$B$11 -> E.P.C - 100 V.V NORTE | D30: 1 | E30: ='[1]COMEDORES EMERGENTES'!$G$11 -> Bº VV NORTE C/48 ENTRE ESPAÑA Y FRANCIA
B31: ='[1]COMEDORES EMERGENTES'!$B$12 -> HOGAR DE CRISTO - PADRE RAUL CONTRERAS | D31: 1 | E31: ='[1]COMEDORES EMERGENTES'!$G$12 -> Bº SANTA MARTA MZA. "S" LOTE "M" C/39
B32: ='[1]COMEDORES EMERGENTES'!$B$13 -> LA LUCIERNAGA | D32: 1 | E32: ='[1]COMEDORES EMERGENTES'!$G$13 -> Bº 20 V.V NORTE C/3
B33: ='[1]COMEDORES EMERGENTES'!$B$14 -> VALLE VIEJO - SUMALAO | D33: 1 | E33: ='[1]COMEDORES EMERGENTES'!$G$14 -> PADRE SEGURA S/N
B34: ='[1]COMEDORES EMERGENTES'!$B$15 -> NUESTRO FUTURO - LAS VIAS | D34: 1 | E34: ='[1]COMEDORES EMERGENTES'!$G$15 -> Bº LAS VIAS OESTE LOTE 42
B35: ='[1]COMEDORES EMERGENTES'!$B$16 -> SAN JOSE OBRERO | D35: 1 | E35: ='[1]COMEDORES EMERGENTES'!$G$16 -> Bº SAN JOSE OBRERO. PJE. SANDOVAL S/Nº
B36: ='[1]COMEDORES EMERGENTES'!$B$17 -> VIRGEN DE LUJAN | D36: 1 | E36: ='[1]COMEDORES EMERGENTES'!$G$17 -> Bº OJO DE AGUA C/DR.TEODULFO BARRIONUEVO S/Nº
B37: ='[1]COMEDORES EMERGENTES'!$B$18 -> RENACER | D37: 1 | E37: ='[1]COMEDORES EMERGENTES'!$G$18 -> Bº VIRGEN MORENITA
B38: ='[1]COMEDORES EMERGENTES'!$B$19 -> CENTRO VECINAL MI JARDIN | D38: 1 | E38: ='[1]COMEDORES EMERGENTES'!$G$19 -> C/ LOS TULIPANES ENTRE FLOR DE CEREZO Y HOLANDA MZA.27 Bº MI JARDIN
B39: ='[1]COMEDORES EMERGENTES'!$B$20 -> LA VIEJA ESQUINA | D39: 1 | E39: ='[1]COMEDORES EMERGENTES'!$G$20 -> B° CRISTO REY PJE CAPATAZ VILLAFAÑEZ Y ARMANDO CORREA
B40: ='[1]COMEDORES EMERGENTES'!$B$21 -> GAUCHITO GIL | D40: 1 | E40: ='[1]COMEDORES EMERGENTES'!$G$21 -> B° 26 VIVIENDAS CASA N° 3
B41: ='[1]COMEDORES EMERGENTES'!$B$22 -> LOS TOLDOS | D41: 1 | E41: ='[1]COMEDORES EMERGENTES'!$G$22 -> LOTEO PARQUE SUR CALLE S/NOMBRE S/N°
B42: Calidad Minima esperada
C43: ALTA
B44: Mantenimiento
C45: 60 DIAS
B46: Garantia
...

Sheet alimento
B1: Pedido de Necesidades Trimestrales
A3: JURISDICCION: | C3: 45- Ministerio de Desarrollo Social y Deporte.-
A4: SAF N°: | C4: 25- Direccion Provincial de Gestion Administracion y RRHH
A5: EJERCICIO: | C5: 2020
A6: TRIMESTRE: | C6: 3
A8: ID | B8: CODIGO ITEM | C8: RUBRO DE COMPRA | D8: I.P.P. | E8: DESCRIPCION | F8: UNIDAD DE MEDIDA | G8: CANTIDAD | H8: PRECIO UNITARIO ESTIMADO | I8: IMPORTE TOTAL ESTIMADO
A9: 1 | B9: 2.1.1-482.69 | C9: ALIMENTOS | D9: =LEFT(B9,5) -> 2.1.1 | E9: HARINAS; TIPO: MAIZ, PRESENTACION: ENVASE X 1 Kg, MATERIAL ENVASE: PAPEL, CERTICADO FORESTAL (GFS): SIN, ELEM. TRANSPORTE: SIN, MATERIAL ELEM. TRANSPORTE: SIN, LIBRE DE GLUTEN: NO | F9: UNIDAD | G9: 7164
A10: 2 | B10: 2.1.1-435.60 | C10: ALIMENTOS | D10: 2.1.1 | E10: ARROZ; TIPO GRANO: LARGO-FINO, TIPO: BLANCO, PROCESO: SIN CASCARA, PRESENTACION: BOLSA X 1 Kg, MATERIAL ENVASE: PLASTICO, CERTIFICADO FORESTAL (GFS): SIN, ELEM. TRANSPORTE: SIN, MATERIAL ELEM. TRANSPORTE: SIN, LIBRE DE GLUTEN: SI | F10: UNIDAD | G10: 5232
A11: 3 | B11: 2.1.1-6547.22 | C11: ALIMENTOS | D11: 2.1.1 | E11: LEGUMBRES; VARIEDAD: LENTEJA, ESTADO: NATURAL, PRESENTACION: BOLSA PLASTICA, PESO: 500 GR | F11: UNIDAD | G11: 9504
A12: 4 | B12: 2.1.1-2616.9 | C12: ALIMENTOS | D12: =LEFT(B12,5) -> 2.1.1 | E12: MAIZ; TIPO: BLANCO PISADO, PRESENTACION: ENVASE X 500 GR, FORMA DE PRESENTACION: SIN VALOR | F12: UNIDAD | G12: 9504
A13: 5 | B13: 2.1.1-6547.56 | C13: ALIMENTOS | D13: 2.1.1 | E13: LEGUMBRES; VARIEDAD: POROTO BLANCO OVAL, ESTADO: SECO, PRESENTACION: BOLSA, PESO: 500 GR | F13: UNIDAD | G13: 4284
A14: 6 | B14: 2.1.1-6546.4 | C14: ALIMENTOS | D14: 2.1.1 | E14: VERDURAS Y HORTALIZAS; VARIEDAD: TOMATE PERITA, ESTADO: TRITURADO, PRESENTACION: BOTELLA, PESO: 950 GR | F14: UNIDAD | G14: 12828
A15: 7 | B15: 2.1.1-6547.17 | C15: ALIMENTOS | D15: =LEFT(B15,5) -> 2.1.1 | E15: LEGUMBRES; VARIEDAD: ARVEJA, ESTADO: REMOJADO EN CONSERVA, PRESENTACION: LATA, PESO: 350 GR | F15: UNIDAD | G15: 8544
A16: 8 | B16: 2.1.1-439.67 | C16: ALIMENTOS | D16: 2.1.1 | E16: ACEITES COMESTIBLES; TIPO: GIRASOL, PRESENTACION: ENVASE X 900 CM3, MATERIAL ENVASE: PLASTICO 1 (PET), ELEM. TRANSPORTE: SIN, MATERIAL ELEM. TRANSPORTE : SIN, LIBRE DE GLUTEN: NO | F16: UNIDAD | G16: 2412
A17: 9 | B17: 2.1.1-6546.46 | C17: ALIMENTOS | D17: =LEFT(B17,5) -> 2.1.1 | E17: VERDURAS Y HORTALIZAS; VARIEDAD: CEBOLLA, ESTADO: NATURAL, PRESENTACION: GRANEL, PESO: SIN VALOR | F17: KG | G17: 13296
A18: 10 | B18: 2.1.1-6546.100 | C18: ALIMENTOS | D18: =LEFT(B18,5) -> 2.1.1 | E18: VERDURAS Y HORTALIZAS; ESTADO: NATURAL, PRESENTACION: GRANEL, VARIEDAD: PAPA BLANCA, PESO: SIN VALOR | F18: KG | G18: 16668
A19: 11 | B19: 2.1.1-6546.403 | C19: ALIMENTOS | D19: =LEFT(B19,5) -> 2.1.1 | E19: VERDURAS Y HORTALIZAS; VARIEDAD: ZANAHORIA, ESTADO: NATURAL, PRESENTACION: BOLSA, PESO: NO CORRESPONDE, ELEM. TRANSPORTE: SIN, MATERIAL ELEM. TRANSPORTE: SIN, LIBRE DE GLUTEN: SI, ORGANICO: NO | F19: KG | G19: 10464
A20: 12 | B20: 2.1.1-6546.95 | C20: ALIMENTOS | D20: 2.1.1 | E20: VERDURAS Y HORTALIZAS; VARIEDAD: MORRON VERDE, ESTADO: NATURAL, PRESENTACION: GRANEL, PESO: SIN VALOR | F20: UNIDAD | G20: 14256
A21: 13 | B21: 2.1.1-6546.401 | C21: ALIMENTOS | D21: =LEFT(B21,5) -> 2.1.1 | E21: VERDURAS Y HORTALIZAS; VARIEDAD: AJO, ESTADO: NATURAL, PRESENTACION: UNIDAD, PESO: NO CORRESPONDE, ELEM. TRANSPORTE: SIN, MATERIAL ELEM. TRANSPORTE: SIN, LIBRE DE GLUTEN: SI, ORGANICO: NO | F21: UNIDAD | G21: 1440
A22: 14 | B22: 2.1.1-6546.148 | C22: ALIMENTOS | D22: =LEFT(B22,5) -> 2.1.1 | E22: VERDURAS Y HORTALIZAS; VARIEDAD: ZAPALLITO LARGO, ESTADO: NATURAL, PRESENTACION: CAJON, PESO: SIN VALOR | F22: KG | G22: 4752
A23: 15 | B23: 2.1.1-6546.47 | C23: ALIMENTOS | D23: 2.1.1 | E23: VERDURAS Y HORTALIZAS; VARIEDAD: CEBOLLA DE VERDEO, ESTADO: NATURAL, PRESENTACION: GRANEL, PESO: SIN VALOR | F23: UNIDAD | G23: 2856
A24: 16 | B24: 2.1.1-6546.162 | C24: ALIMENTOS | D24: =LEFT(B24,5) -> 2.1.1 | E24: VERDURAS Y HORTALIZAS; VARIEDAD: ZAPALLO CRIOLLO, ESTADO: NATURAL, PRESENTACION: UNIDAD, PESO: SIN VALOR | F24: KG | G24: 9504
A25: 17 | B25: 2.1.1-541.7 | C25: ALIMENTOS | D25: =LEFT(B25,5) -> 2.1.1 | E25: CARNES; ESPECIE: VACUNA, CORTE: PICADA ESPECIAL, TIPO: VACUNA | F25: KG | G25: 4752
A26: 18 | B26: 2.1.1-541.49 | C26: ALIMENTOS | D26: =LEFT(B26,5) -> 2.1.1 | E26: CARNES; ESPECIE: VACUNA, CORTE: NALGA, TIPO: VACUNA | F26: KG | G26: 8544
A27: 19 | B27: 2.1.1-621.3 | C27: ALIMENTOS | D27: =LEFT(B27,5) -> 2.1.1 | E27: AVES; PRESENTACION: TROZADO SIN PIEL, ESPECIE: POLLO, EVISCERADO: SIN VALOR, TIPO: POLLO | F27: KG | G27: 7164
A28: 20 | B28: 2.1.1-669.32 | C28: ALIMENTOS | D28: 2.1.1 | E28: PANES; PRESENTACION: UNIDAD, TIPO: BAGUETTE | F28: KG | G28: 19008
A29: 21 | B29: 2.1.1-489.132 | C29: ALIMENTOS | D29: 2.1.1 | E29: ESPECIAS; TIPO: PIMIENTA BLANCA, PRESENTACION: ENVASE X 1 Kg | F29: KG | G29: 120
A30: 22 | B30: 2.1.1-489.66 | C30: ALIMENTOS | D30: =LEFT(B30,5) -> 2.1.1 | E30: ESPECIAS; TIPO: OREGANO, PRESENTACION: BOLSA DE 1 Kg | F30: KG | G30: 120
A31: 23 | B31: 2.1.1-489.67 | C31: ALIMENTOS | D31: 2.1.1 | E31: ESPECIAS; TIPO: PIMENTON, PRESENTACION: BOLSA DE 1 Kg | F31: KG | G31: 120
A32: 24 | B32: 2.1.1-489.109 | C32: ALIMENTOS | D32: 2.1.1 | E32: ESPECIAS; TIPO: PROVENZAL, PRESENTACION: PAQUETE X 1 Kg | F32: KG | G32: 120
A33: 25 | B33: 2.1.1-514.2 | C33: ALIMENTOS | D33: =LEFT(B33,5) -> 2.1.1 | E33: SAL DE MESA; CONSISTENCIA: FINA, PESO: 500 GR, TIPO: SIN VALOR, ENVASE: PAQUETE | F33: UNIDAD | G33: 492
A34: 26 | B34: 2.1.1-514.15 | C34: ALIMENTOS | D34: =LEFT(B34,5) -> 2.1.1 | E34: SAL DE MESA; CONSISTENCIA: GRUESA, ENVASE: BOLSA, PESO: 1 Kg, TIPO: SIN VALOR | F34: KG | G34: 270
A35: 27 | B35: 2.1.1-6539.8 | C35: ALIMENTOS | D35: 2.1.1 | E35: FRUTAS; VARIEDAD: NARANJA ESPECIAL, ESTADO: NATURAL, PRESENTACION: CAJON, PESO: SIN VALOR | F35: UNIDAD | G35: 23760
A36: 28 | B36: 2.1.1-6539.19 | C36: ALIMENTOS | D36: 2.1.1 | E36: FRUTAS; ESTADO: NATURAL, VARIEDAD: MANZANA RED ELEGIDA, PRESENTACION: CAJON, PESO: SIN VALOR | F36: UNIDAD | G36: 23760
A37: 29 | B37: 2.1.1-6539.30 | C37: ALIMENTOS | D37: =LEFT(B37,5) -> 2.1.1 | E37: FRUTAS; VARIEDAD: BANANA, PRESENTACION: CAJON, ESTADO: NATURAL, PESO: SIN VALOR | F37: UNIDAD | G37: 23760
A38: 30 | B38: 2.1.1-6539.32 | C38: ALIMENTOS | D38: =LEFT(B38,5) -> 2.1.1 | E38: FRUTAS; VARIEDAD: PERA AMARILLA, ESTADO: NATURAL, PRESENTACION: CAJON, PESO: SIN VALOR | F38: UNIDAD | G38: 23760
B41: Especificidades Item N° 1:
B43: Descripción técnica
B45: Plazos y lugares de entrega
B46: SEMANAL
...

Sheet ALIM-IMP
B1: Pedido de Necesidades Trimestrales
A3: JURISDICCION: | C3: 45- Ministerio de Desarrollo Social.-
A4: SAF N°: | C4: 25- Direccion Provincial de Gestion Administracion y RRHH
A5: EJERCICIO: | C5: 2022
A6: TRIMESTRE | C6: 2
A8: ID | B8: CODIGO ITEM | C8: RUBRO DE COMPRA | D8: I.P.P. | E8: DESCRIPCION | F8: UNIDAD DE MEDIDA | G8: CANTIDAD | H8: PRECIO UNITARIO ESTIMADO | I8: IMPORTE TOTAL ESTIMADO
A9: 1 | B9: 2.1.1-2868.59 | C9: ALIMENTOS | D9: 2.1.1 | E9: FIDEOS SECOS; VARIEDAD: MOSTACHOLES, RELLENO: SIN, PRESENTACION: ENVASE X 500 GR, MATERIAL ENVASE: PVC, ELEM. TRANSPORTE: CAJA, MATERIAL ELEM. TRANSPORTE: CARTON, CERTIFICADO FORESTAL (GFS): SIN, LIBRE DE GLUTEN: NO | F9: PAQUETE | G9: 15840 | H9: 93 | I9: =G9*H9 -> 1473120 | J9: =E9=K9 -> TRUE | K9: FIDEOS SECOS; VARIEDAD: MOSTACHOLES, RELLENO: SIN, PRESENTACION: ENVASE X 500 GR, MATERIAL ENVASE: PVC, ELEM. TRANSPORTE: CAJA, MATERIAL ELEM. TRANSPORTE: CARTON, CERTIFICADO FORESTAL (GFS): SIN, LIBRE DE GLUTEN: NO
A10: 2 | B10: 2.1.1-435.60 | C10: ALIMENTOS | D10: 2.1.1 | E10: ARROZ; TIPO GRANO: LARGO-FINO, TIPO: BLANCO, PROCESO: SIN CASCARA, PRESENTACION: BOLSA X 1 Kg, MATERIAL ENVASE: PLASTICO, CERTIFICADO FORESTAL (GFS): SIN, ELEM. TRANSPORTE: SIN, MATERIAL ELEM. TRANSPORTE: SIN, LIBRE DE GLUTEN: SI | F10: BOLSA | G10: 3348 | H10: 180 | I10: =G10*H10 -> 602640 | J10: =E10=K10 -> FALSE
A11: 3 | B11: 2.1.1-6547.55 | C11: ALIMENTOS | D11: 2.1.1 | E11: LEGUMBRES; VARIEDAD: POROTO SECO, ESTADO: SECA Y CONSERVADA, PRESENTACION: BOLSA PLASTICA, PESO: 1 Kg | F11: BOLSA | G11: 3348 | H11: 328 | I11: =G11*H11 -> 1098144 | J11: =E11=K11 -> TRUE | K11: LEGUMBRES; VARIEDAD: POROTO SECO, ESTADO: SECA Y CONSERVADA, PRESENTACION: BOLSA PLASTICA, PESO: 1 Kg
A12: 4 | B12: 2.1.1-483.33 | C12: ALIMENTOS | D12: 2.1.1 | E12: HUEVO DE GALLINA; TAMAÑO: MEDIANOS, COLOR: BLANCOS, PRESENTACION: 30 | F12: MAPLE | G12: 1320 | H12: 900 | I12: =G12*H12 -> 1188000 | J12: =E12=K12 -> FALSE
A13: 5 | B13: 2.1.1-6546.158 | C13: ALIMENTOS | D13: 2.1.1 | E13: VERDURAS Y HORTALIZAS; ESTADO: NATURAL, VARIEDAD: ZAPALLO ANCO, PRESENTACION: GRANEL, PESO: SIN VALOR | F13: KG | G13: 15216 | H13: 135 | I13: =G13*H13 -> 2054160 | J13: =E13=K13 -> FALSE
A14: 6 | B14: 2.1.1-6546.4 | C14: ALIMENTOS | D14: 2.1.1 | E14: VERDURAS Y HORTALIZAS; VARIEDAD: TOMATE PERITA, ESTADO: TRITURADO, PRESENTACION: BOTELLA, PESO: 950 GR | F14: BOTELLA | G14: 13200 | H14: 300 | I14: =G14*H14 -> 3960000 | J14: =E14=K14 -> FALSE
A15: 7 | B15: 2.1.1-6547.17 | C15: ALIMENTOS | D15: 2.1.1 | E15: LEGUMBRES; VARIEDAD: ARVEJA, ESTADO: REMOJADO EN CONSERVA, PRESENTACION: LATA, PESO: 350 GR | F15: LATA | G15: 9948 | H15: 78 | I15: =G15*H15 -> 775944 | J15: =E15=K15 -> FALSE
A16: 8 | B16: 2.1.1-439.67 | C16: ALIMENTOS | D16: 2.1.1 | E16: ACEITES COMESTIBLES; TIPO: GIRASOL, PRESENTACION: ENVASE X 900 CM3, MATERIAL ENVASE: PLASTICO 1 (PET), ELEM. TRANSPORTE: SIN, MATERIAL ELEM. TRANSPORTE : SIN, LIBRE DE GLUTEN: NO | F16: BOTELLA | G16: 4644 | H16: 397 | I16: =G16*H16 -> 1843668 | J16: =E16=K16 -> FALSE
A17: 9 | B17: 2.1.1-6546.46 | C17: ALIMENTOS | D17: 2.1.1 | E17: VERDURAS Y HORTALIZAS; VARIEDAD: CEBOLLA, ESTADO: NATURAL, PRESENTACION: GRANEL, PESO: SIN VALOR | F17: KG | G17: 17844 | H17: 120 | I17: =G17*H17 -> 2141280 | J17: =E17=K17 -> FALSE
A18: 10 | B18: 2.1.1-6546.100 | C18: ALIMENTOS | D18: 2.1.1 | E18: VERDURAS Y HORTALIZAS; ESTADO: NATURAL, PRESENTACION: GRANEL, VARIEDAD: PAPA BLANCA, PESO: SIN VALOR | F18: KG | G18: 36348 | H18: 90 | I18: =G18*H18 -> 3271320 | J18: =E18=K18 -> FALSE
A19: 11 | B19: 2.1.1-6546.403 | C19: ALIMENTOS | D19: 2.1.1 | E19: VERDURAS Y HORTALIZAS; VARIEDAD: ZANAHORIA, ESTADO: NATURAL, PRESENTACION: BOLSA, PESO: NO CORRESPONDE, ELEM. TRANSPORTE: SIN, MATERIAL ELEM. TRANSPORTE: SIN, LIBRE DE GLUTEN: SI, ORGANICO: NO | F19: KG | G19: 5280 | H19: 180 | I19: =G19*H19 -> 950400 | J19: =E19=K19 -> FALSE
A20: 12 | B20: 2.1.1-6546.95 | C20: ALIMENTOS | D20: 2.1.1 | E20: VERDURAS Y HORTALIZAS; VARIEDAD: MORRON VERDE, ESTADO: NATURAL, PRESENTACION: GRANEL, PESO: SIN VALOR | F20: UNIDAD | G20: 19800 | H20: 120 | I20: =G20*H20 -> 2376000 | J20: =E20=K20 -> FALSE
A21: 13 | B21: 2.1.1-6546.401 | C21: ALIMENTOS | D21: 2.1.1 | E21: VERDURAS Y HORTALIZAS; VARIEDAD: AJO, ESTADO: NATURAL, PRESENTACION: UNIDAD, PESO: NO CORRESPONDE, ELEM. TRANSPORTE: SIN, MATERIAL ELEM. TRANSPORTE: SIN, LIBRE DE GLUTEN: SI, ORGANICO: NO | F21: CABEZA | G21: 4644 | H21: 90 | I21: =G21*H21 -> 417960 | J21: =E21=K21 -> FALSE
A22: 14 | B22: 2.1.1-6546.47 | C22: ALIMENTOS | D22: 2.1.1 | E22: VERDURAS Y HORTALIZAS; VARIEDAD: CEBOLLA DE VERDEO, ESTADO: NATURAL, PRESENTACION: GRANEL, PESO: SIN VALOR | F22: ATADO | G22: 6600 | H22: 140 | I22: =G22*H22 -> 924000 | J22: =E22=K22 -> TRUE | K22: VERDURAS Y HORTALIZAS; VARIEDAD: CEBOLLA DE VERDEO, ESTADO: NATURAL, PRESENTACION: GRANEL, PESO: SIN VALOR
A23: 15 | B23: 2.1.1-6546.162 | C23: ALIMENTOS | D23: 2.1.1 | E23: VERDURAS Y HORTALIZAS; VARIEDAD: ZAPALLO CRIOLLO, ESTADO: NATURAL, PRESENTACION: UNIDAD, PESO: SIN VALOR | F23: KG | G23: 26400 | H23: 120 | I23: =G23*H23 -> 3168000 | J23: =E23=K23 -> TRUE | K23: VERDURAS Y HORTALIZAS; VARIEDAD: ZAPALLO CRIOLLO, ESTADO: NATURAL, PRESENTACION: UNIDAD, PESO: SIN VALOR
A24: 16 | B24: 2.1.1-482.69 | C24: ALIMENTOS | D24: 2.1.1 | E24: HARINAS; TIPO: MAIZ, PRESENTACION: ENVASE X 1 Kg, MATERIAL ENVASE: PAPEL, CERTICADO FORESTAL (GFS): SIN, ELEM. TRANSPORTE: SIN, MATERIAL ELEM. TRANSPORTE: SIN, LIBRE DE GLUTEN: NO | F24: PAQUETE | G24: 9948 | H24: 140 | I24: =G24*H24 -> 1392720 | J24: =E24=K24 -> TRUE | K24: HARINAS; TIPO: MAIZ, PRESENTACION: ENVASE X 1 Kg, MATERIAL ENVASE: PAPEL, CERTICADO FORESTAL (GFS): SIN, ELEM. TRANSPORTE: SIN, MATERIAL ELEM. TRANSPORTE: SIN, LIBRE DE GLUTEN: NO
A25: 17 | B25: 2.1.1-541.7 | C25: ALIMENTOS | D25: 2.1.1 | E25: CARNES; ESPECIE: VACUNA, CORTE: PICADA ESPECIAL, TIPO: VACUNA | F25: KG | G25: 17160 | H25: 1275 | I25: =G25*H25 -> 21879000 | J25: =E25=K25 -> FALSE
A26: 18 | B26: 2.1.1-541.49 | C26: ALIMENTOS | D26: 2.1.1 | E26: CARNES; ESPECIE: VACUNA, CORTE: NALGA, TIPO: VACUNA | F26: KG | G26: 6600 | H26: 1875 | I26: =G26*H26 -> 12375000 | J26: =E26=K26 -> FALSE
A27: 19 | B27: 2.1.1-621.3 | C27: ALIMENTOS | D27: 2.1.1 | E27: AVES; PRESENTACION: TROZADO SIN PIEL, ESPECIE: POLLO, EVISCERADO: SIN VALOR, TIPO: POLLO | F27: KG | G27: 16548 | H27: 480 | I27: =G27*H27 -> 7943040 | J27: =E27=K27 -> FALSE
A28: 20 | B28: 2.1.1-669.35 | C28: ALIMENTOS | D28: 2.1.1 | E28: PANES; TIPO: FRANCES, PRESENTACION: GRANEL | F28: KG | G28: 39600 | H28: 280 | I28: =G28*H28 -> 11088000 | J28: =E28=K28 -> FALSE
A29: 21 | B29: 2.1.1-489.132 | C29: ALIMENTOS | D29: 2.1.1 | E29: ESPECIAS; TIPO: PIMIENTA BLANCA, PRESENTACION: ENVASE X 1 Kg | F29: BOLSA | G29: 102 | H29: 840 | I29: =G29*H29 -> 85680 | J29: =E29=K29 -> FALSE
A30: 22 | B30: 2.1.1-489.66 | C30: ALIMENTOS | D30: 2.1.1 | E30: ESPECIAS; TIPO: OREGANO, PRESENTACION: BOLSA DE 1 Kg | F30: BOLSA | G30: 102 | H30: 900 | I30: =G30*H30 -> 91800 | J30: =E30=K30 -> FALSE
A31: 23 | B31: 2.1.1-489.67 | C31: ALIMENTOS | D31: 2.1.1 | E31: ESPECIAS; TIPO: PIMENTON, PRESENTACION: BOLSA DE 1 Kg | F31: BOLSA | G31: 102 | H31: 750 | I31: =G31*H31 -> 76500 | J31: =E31=K31 -> FALSE
A32: 24 | B32: 2.1.1-489.109 | C32: ALIMENTOS | D32: 2.1.1 | E32: ESPECIAS; TIPO: PROVENZAL, PRESENTACION: PAQUETE X 1 Kg | F32: PAQUETE | G32: 102 | H32: 900 | I32: =G32*H32 -> 91800 | J32: =E32=K32 -> FALSE
A33: 25 | B33: 2.1.1-514.2 | C33: ALIMENTOS | D33: 2.1.1 | E33: SAL DE MESA; CONSISTENCIA: FINA, PESO: 500 GR, TIPO: SIN VALOR, ENVASE: PAQUETE | F33: PAQUETE | G33: 1320 | H33: 63 | I33: =G33*H33 -> 83160 | J33: =E33=K33 -> FALSE
A34: 26 | B34: 2.1.1-514.15 | C34: ALIMENTOS | D34: 2.1.1 | E34: SAL DE MESA; CONSISTENCIA: GRUESA, ENVASE: BOLSA, PESO: 1 Kg, TIPO: SIN VALOR | F34: BOLSA | G34: 684 | H34: 126 | I34: =G34*H34 -> 86184 | J34: =E34=K34 -> FALSE
A35: 27 | B35: 2.1.1-6539.8 | C35: ALIMENTOS | D35: 2.1.1 | E35: FRUTAS; VARIEDAD: NARANJA ESPECIAL, ESTADO: NATURAL, PRESENTACION: CAJON, PESO: SIN VALOR | F35: CAJON | G35: 390 | H35: 3000 | I35: =G35*H35 -> 1170000 | J35: =E35=K35 -> FALSE
A36: 28 | B36: 2.1.1-6539.19 | C36: ALIMENTOS | D36: 2.1.1 | E36: FRUTAS; ESTADO: NATURAL, VARIEDAD: MANZANA RED ELEGIDA, PRESENTACION: CAJON, PESO: SIN VALOR | F36: CAJON | G36: 342 | H36: 8250 | I36: =G36*H36 -> 2821500 | J36: =E36=K36 -> FALSE
... A39: 31 | B39: 2.1.1-669.25 | C39: ALIMENTOS | D39: 2.1.1 | E39: PANES; TIPO: RALLADO, PRESENTACION: BOLSA DE 1000 GR | F39: BOLSA | G39: 3348 | H39: 278 | I39: =G39*H39 -> 930744 | J39: =E39=K39 -> FALSE
A40: 32 | B40: 2.1.1-2616.6 | C40: ALIMENTOS | D40: 2.1.1 | E40: MAIZ; TIPO: BLANCO, PRESENTACION: PAQUETE X 1 Kg, FORMA DE PRESENTACION: PISADO | F40: PAQUETE | G40: 6600 | H40: 343 | I40: =G40*H40 -> 2263800 | J40: =E40=K40 -> TRUE | K40: MAIZ; TIPO: BLANCO, PRESENTACION: PAQUETE X 1 Kg, FORMA DE PRESENTACION: PISADO
A41: 33 | B41: 2.1.1-2431.13 | C41: ALIMENTOS | D41: 2.1.1 | E41: CALDOS; GUSTO: VERDURA, TIPO: DESHIDRATADO, PRESENTACION: ENVASE X 12 UN | F41: CAJA | G41: 1320 | H41: 170 | I41: =G41*H41 -> 224400 | J41: =E41=K41 -> TRUE | K41: CALDOS; GUSTO: VERDURA, TIPO: DESHIDRATADO, PRESENTACION: ENVASE X 12 UN
A42: 34 | B42: 2.1.1-6546.132 | C42: ALIMENTOS | D42: 2.1.1 | E42: VERDURAS Y HORTALIZAS; VARIEDAD: PEREJIL, ESTADO: NATURAL, PRESENTACION: GRANEL, PESO: SIN VALOR | F42: ATADO | G42: 2640 | H42: 90 | I42: =G42*H42 -> 237600 | J42: =E42=K42 -> FALSE
I43: =SUM(I9:I42) -> 94431564

Sheet Autor Gastar
A1: EJERCICIO: | D1: ='ALIM-IMP'!C5 -> 2022 | P1: AUTORIZACION PARA GASTAR
A4: JURISDICCIÓN: | G4: =' NotaPedido'!D3 -> 45- Ministerio de Desarrollo Social
A5: SAF: | G5: =' NotaPedido'!D4 -> 25- Direccion Provincial de Gestion Administracion y RRHH
A6: UNIDAD EJECUTORA: | G6: 20 - Direccion Provincial de Programas Alimentarias
A7: DEPENDENCIA SOLICITANTE: | G7: 01- Actividad Central
A8: AUTORIZACIÓN:
A9: Señor Jefe de Servicio Administrativo Financiero:
A10: "Autorizo la realización de los trámites correspondientes, a fin de proveer a este Organismo los bienes y/o servicios que se detallan en Nota de Pedido N° 203/22, afectando la erogación resultante a los créditos presupuestarios aprobados a favor de esta Unidad Ejecutora, conforme al siguiente detalle:"
A12: IMPUTACIÓN PRESUPUESTARIA
A13: CÓDIGO | O13: DENOMINACIÓN DE LA PARTIDA PRESUPUESTARIA | Q13: IMPORTE
A14: PR | B14: SB | C14: PY | D14: AC | E14: OB | F14: UG | G14: FIN | H14: FUN | I14: I | J14: P | K14: P | L14: SubP | M14: M | N14: FF
A15: 1 | D15: 1 | F15: 4901 | G15: 1 | H15: 4 | I15: =LEFT('[2]Necesidades Trimestrales'!D10,1) -> 2 | J15: 1 | K15: 1 | M15: 1 | N15: 1.1 | O15: Alimentos para Personas | Q15: ='ALIM-IMP'!I43 -> 94431564
A23: TOTAL DE PESOS: NOVENTA Y CUATRO MILLONES CUATROCIENTOS TREINTA Y UN MIL QUINIENTOS SESENTA Y CUATRO CON 00/100.- | Q23: =SUM(Q15:Q22) -> 94431564
A25: JUSTIFICACIÓN:
A26: Adquisición de Alimentos para asistir a Personas de escasos Recursos a traves de los Comedores Emergentes.-

Sheet  NotaPedido
A1: NOTA DE PEDIDO | J1: N° | K1: 203/2022
A3: JURISDICCIÓN: | D3: 45- Ministerio de Desarrollo Social
A4: SAF: | D4: =alimento!C4 -> 25- Direccion Provincial de Gestion Administracion y RRHH
A5: UNIDAD EJECUTORA: | D5: 20 - Direccion Provincial de Programas Alimentarias
A6: DEPENDENCIA SOLICITANTE: | D6: 01- Actividad Central
A7: PERIODO UTILIZACIÓN: | D7: ='ALIM-IMP'!C6& "° Trimestre - Año " & 'ALIM-IMP'!C5 -> 2° Trimestre - Año 2022
A8: OBJETO: | D8: Adquisición de Alimentos para asistir a Personas de escasos Recursos a traves de los Comedores Emergentes.-
A10: Ítem | B10: Codigo Item | C10: DESCRIPCIÓN | H10: Adjunta Detalle Técnico | I10: Unidad Medida | J10: Precio Unitario Estimado | K10: Cantidad Solicitada | L10: Importe Estimado
A12: 1 | B12: ='ALIM-IMP'!B9 -> 2.1.1-2868.59 | C12: ='ALIM-IMP'!E9 -> FIDEOS SECOS; VARIEDAD: MOSTACHOLES, RELLENO: SIN, PRESENTACION: ENVASE X 500 GR, MATERIAL ENVASE: PVC, ELEM. TRANSPORTE: CAJA, MATERIAL ELEM. TRANSPORTE: CARTON, CERTIFICADO FORESTAL (GFS): SIN, LIBRE DE GLUTEN: NO | H12: SI | I12: ='ALIM-IMP'!F9 -> PAQUETE | J12: ='ALIM-IMP'!H9 -> 93 | K12: ='ALIM-IMP'!G9 -> 15840 | L12: =J12*K12 -> 1473120
A13: 2 | B13: ='ALIM-IMP'!B10 -> 2.1.1-435.60 | C13: ='ALIM-IMP'!E10 -> ARROZ; TIPO GRANO: LARGO-FINO, TIPO: BLANCO, PROCESO: SIN CASCARA, PRESENTACION: BOLSA X 1 Kg, MATERIAL ENVASE: PLASTICO, CERTIFICADO FORESTAL (GFS): SIN, ELEM. TRANSPORTE: SIN, MATERIAL ELEM. TRANSPORTE: SIN, LIBRE DE GLUTEN: SI | H13: SI | I13: ='ALIM-IMP'!F10 -> BOLSA | J13: ='ALIM-IMP'!H10 -> 180 | K13: ='ALIM-IMP'!G10 -> 3348 | L13: =J13*K13 -> 602640
A14: 3 | B14: ='ALIM-IMP'!B11 -> 2.1.1-6547.55 | C14: ='ALIM-IMP'!E11 -> LEGUMBRES; VARIEDAD: POROTO SECO, ESTADO: SECA Y CONSERVADA, PRESENTACION: BOLSA PLASTICA, PESO: 1 Kg | H14: SI | I14: ='ALIM-IMP'!F11 -> BOLSA | J14: ='ALIM-IMP'!H11 -> 328 | K14: ='ALIM-IMP'!G11 -> 3348 | L14: =J14*K14 -> 1098144
A15: 4 | B15: ='ALIM-IMP'!B12 -> 2.1.1-483.33 | C15: ='ALIM-IMP'!E12 -> HUEVO DE GALLINA; TAMAÑO: MEDIANOS, COLOR: BLANCOS, PRESENTACION: 30 | H15: SI | I15: ='ALIM-IMP'!F12 -> MAPLE | J15: ='ALIM-IMP'!H12 -> 900 | K15: ='ALIM-IMP'!G12 -> 1320 | L15: =J15*K15 -> 1188000
A16: 5 | B16: ='ALIM-IMP'!B13 -> 2.1.1-6546.158 | C16: ='ALIM-IMP'!E13 -> VERDURAS Y HORTALIZAS; ESTADO: NATURAL, VARIEDAD: ZAPALLO ANCO, PRESENTACION: GRANEL, PESO: SIN VALOR | H16: SI | I16: ='ALIM-IMP'!F13 -> KG | J16: ='ALIM-IMP'!H13 -> 135 | K16: ='ALIM-IMP'!G13 -> 15216 | L16: =J16*K16 -> 2054160
A17: 6 | B17: ='ALIM-IMP'!B14 -> 2.1.1-6546.4 | C17: ='ALIM-IMP'!E14 -> VERDURAS Y HORTALIZAS; VARIEDAD: TOMATE PERITA, ESTADO: TRITURADO, PRESENTACION: BOTELLA, PESO: 950 GR | H17: SI | I17: ='ALIM-IMP'!F14 -> BOTELLA | J17: ='ALIM-IMP'!H14 -> 300 | K17: ='ALIM-IMP'!G14 -> 13200 | L17: =J17*K17 -> 3960000
A18: 7 | B18: ='ALIM-IMP'!B15 -> 2.1.1-6547.17 | C18: ='ALIM-IMP'!E15 -> LEGUMBRES; VARIEDAD: ARVEJA, ESTADO: REMOJADO EN CONSERVA, PRESENTACION: LATA, PESO: 350 GR | H18: SI | I18: ='ALIM-IMP'!F15 -> LATA | J18: ='ALIM-IMP'!H15 -> 78 | K18: ='ALIM-IMP'!G15 -> 9948 | L18: =J18*K18 -> 775944
A19: 8 | B19: ='ALIM-IMP'!B16 -> 2.1.1-439.67 | C19: ='ALIM-IMP'!E16 -> ACEITES COMESTIBLES; TIPO: GIRASOL, PRESENTACION: ENVASE X 900 CM3, MATERIAL ENVASE: PLASTICO 1 (PET), ELEM. TRANSPORTE: SIN, MATERIAL ELEM. TRANSPORTE : SIN, LIBRE DE GLUTEN: NO | H19: SI | I19: ='ALIM-IMP'!F16 -> BOTELLA | J19: ='ALIM-IMP'!H16 -> 397 | K19: ='ALIM-IMP'!G16 -> 4644 | L19: =J19*K19 -> 1843668
A20: 9 | B20: ='ALIM-IMP'!B17 -> 2.1.1-6546.46 | C20: ='ALIM-IMP'!E17 -> VERDURAS Y HORTALIZAS; VARIEDAD: CEBOLLA, ESTADO: NATURAL, PRESENTACION: GRANEL, PESO: SIN VALOR | H20: SI | I20: ='ALIM-IMP'!F17 -> KG | J20: ='ALIM-IMP'!H17 -> 120 | K20: ='ALIM-IMP'!G17 -> 17844 | L20: =J20*K20 -> 2141280
A21: 10 | B21: ='ALIM-IMP'!B18 -> 2.1.1-6546.100 | C21: ='ALIM-IMP'!E18 -> VERDURAS Y HORTALIZAS; ESTADO: NATURAL, PRESENTACION: GRANEL, VARIEDAD: PAPA BLANCA, PESO: SIN VALOR | H21: SI | I21: ='ALIM-IMP'!F18 -> KG | J21: ='ALIM-IMP'!H18 -> 90 | K21: ='ALIM-IMP'!G18 -> 36348 | L21: =J21*K21 -> 3271320
A22: 11 | B22: ='ALIM-IMP'!B19 -> 2.1.1-6546.403 | C22: ='ALIM-IMP'!E19 -> VERDURAS Y HORTALIZAS; VARIEDAD: ZANAHORIA, ESTADO: NATURAL, PRESENTACION: BOLSA, PESO: NO CORRESPONDE, ELEM. TRANSPORTE: SIN, MATERIAL ELEM. TRANSPORTE: SIN, LIBRE DE GLUTEN: SI, ORGANICO: NO | H22: SI | I22: ='ALIM-IMP'!F19 -> KG | J22: ='ALIM-IMP'!H19 -> 180 | K22: ='ALIM-IMP'!G19 -> 5280 | L22: =J22*K22 -> 950400
A23: 12 | B23: ='ALIM-IMP'!B20 -> 2.1.1-6546.95 | C23: ='ALIM-IMP'!E20 -> VERDURAS Y HORTALIZAS; VARIEDAD: MORRON VERDE, ESTADO: NATURAL, PRESENTACION: GRANEL, PESO: SIN VALOR | H23: SI | I23: ='ALIM-IMP'!F20 -> UNIDAD | J23: ='ALIM-IMP'!H20 -> 120 | K23: ='ALIM-IMP'!G20 -> 19800 | L23: =J23*K23 -> 2376000
... A45: 34 | B45: ='ALIM-IMP'!B42 -> 2.1.1-6546.132 | C45: ='ALIM-IMP'!E42 -> VERDURAS Y HORTALIZAS; VARIEDAD: PEREJIL, ESTADO: NATURAL, PRESENTACION: GRANEL, PESO: SIN VALOR | H45: SI | I45: ='ALIM-IMP'!F42 -> ATADO | J45: ='ALIM-IMP'!H42 -> 90 | K45: ='ALIM-IMP'!G42 -> 2640 | L45: =J45*K45 -> 237600
A46: Costo total estimado: TOTAL DE PESOS: NOVENTA Y CUATRO MILLONES CUATROCIENTOS TREINTA Y UN MIL QUINIENTOS SESENTA Y CUATRO CON 00/100.- | J46: =SUM(L12:L45) -> 94431564

Sheet GAS-IMP
B2: Pedido de Necesidades Trimestrales
A4: JURISDICCION: | C4: 45- Ministerio de Desarrollo Social y Deporte.-
A5: SAF N°: | C5: 25- Direccion Provincial de Gestion Administracion y RRHH
A6: EJERCICIO: | C6: 2021
A7: TRIMESTRE: | C7: 3
A9: ID | B9: CODIGO ITEM | C9: RUBRO DE COMPRA | D9: I.P.P. | E9: DESCRIPCION | F9: UNIDAD DE MEDIDA | G9: CANTIDAD | H9: PRECIO UNITARIO ESTIMADO | I9: IMPORTE TOTAL ESTIMADO
A10: 1 | B10: 2.5.6-798.8 | C10: COMBUSTIBLES Y LUBRICANTES | D10: 2.5.6 | E10: GAS EN GARRAFA; CAPACIDAD: 10 Kg | F10: UNIDAD | G10: 816 | H10: 800 | I10: =G10*H10 -> 652800
A11: 2 | B11: 2.5.6-798.7 | C11: COMBUSTIBLES Y LUBRICANTES | D11: 2.5.6 | E11: GAS EN GARRAFA; CAPACIDAD: 45 Kg | F11: UNIDAD | G11: 27 | H11: 8200 | I11: =G11*H11 -> 221400
I12: =SUM(I10:I11) -> 874200
B13: Especificidades Item N° 1:
B15: Descripción técnica
B16: GARRAFA X 10 KGS. TIPO COMERCIAL
B17: Plazos y lugares de entrega
B18: SEMANAL
B19: COMEDOR | D19: CANTIDAD | E19: DOMICILIO DE ENTREGA
B20: UNA SONRISA | D20: 2 | E20: Bº SAN CARLOS OESTE AV. BONIFACIO COBACHO N° 670
B21: C.I.F Nº1 | D21: 2 | E21: AV. RIVIERA DEL VALLE ENTRE FLORIDA Y SANTA FE
B22: C.I.F - RIVERA DEL VALLE | D22: 2 | E22: Bº RIVERA DEL VALLE ENTRE VILLA EUMELIA Y MONTE CRISTO
B23: ESFUERZO PROPIO | D23: 2 | E23: Bº MUNICIPAL 35VV. NORTE C/14
B24: JIREH LOTEO SUSSEX | D24: 2 | E24: B° LA RIVERA CASA N° 28
B25: CLUB DEPORTIVO CHACARITA | D25: 2 | E25: CALLE DR.DERMIDIO GALINDEZ C/2660
B26: PAPA FRANCISCO | D26: 2 | E26: ENTRE AV.TEREBINTO Y AV.SAN JUAN LOTE "2" MZA. "B"
B27: E.P.C - 100 V.V NORTE | D27: 2 | E27: Bº VV NORTE C/48 ENTRE ESPAÑA Y FRANCIA
B28: HOGAR DE CRISTO | D28: 2 | E28: Bº SANTA MARTA MZA. "S" LOTE "M" C/39
B29: VALLE VIEJO - SUMALAO | D29: 2 | E29: PADRE SEGURA S/N
B30: NUESTRO FUTURO | D30: 2 | E30: Bº LAS VIAS OESTE LOTE 42
B31: SAN JOSE OBRERO | D31: 2 | E31: Bº SAN JOSE OBRERO. PJE. SANDOVAL S/Nº
... B36: CORAZONES FELICES | D36: 2 | E36: LOTEO PARQUE SUR MZ 1 LOTE N° 21
B37: *SE REALIZA LA ENTREGA DE 34 UNIDADES POR SEMANA (2 POR CADA COMEDOR) LO QUE HACE UNA SUMA DE 136 UNIDADES MENSUALES QUE REPRESENTAN UN TOTAL DE 816 UNIDADES SEMESTRALES
B38: Garantia
B39: S/E
B43: Especificidades Item N° 2:
B45: Descripción técnica
B46: GARRAFA X 45 KGS. TIPO COMERCIAL
B47: Plazos y lugares de entrega
B48: CADA 20 DIAS
B49: COMEDOR | D49: CANTIDAD | E49: DOMICILIO DE ENTREGA
B50: LA MORO | D50: 1 | E50: MAIPU NORTE 1º ETAPA MZA "H" Bº MI JARDIN
B51: LA LUCIERNAGA | D51: 1 | E51: Bº 20 V.V NORTE C/3
B52: GAUCHITO GIL | D52: 1 | E52: B° 26 VIVIENDAS CASA N° 3
...

Sheet LIM-IMP
B1: Pedido de Necesidades Trimestrales
A3: JURISDICCION: | C3: 45- Ministerio de Desarrollo Social y Deporte.-
A4: SAF N°: | C4: 25- Direccion Provincial de Gestion Administracion y RRHH
A5: EJERCICIO: | C5: 2020
A6: TRIMESTRE: | C6: 4
A8: ID | B8: CODIGO ITEM | C8: RUBRO DE COMPRA | D8: I.P.P. | E8: DESCRIPCION | F8: UNIDAD DE MEDIDA | G8: CANTIDAD | H8: PRECIO UNITARIO ESTIMADO | I8: IMPORTE TOTAL ESTIMADO
A9: 1 | B9: 2.9.1-6951.30 | C9: ELEMENTOS DE LIMPIEZA | D9: 2.9.1 | E9: LIMPIADORES; TIPO: LAVANDINA, PRESENTACION: ENVASE X 5 L | F9: LITROS | G9: 240 | I9: =G9*H9 -> 0
A10: 2 | B10: 2.9.1-6951.12 | C10: ELEMENTOS DE LIMPIEZA | D10: 2.9.1 | E10: LIMPIADORES; PRESENTACION: ENVASE X 5 L, TIPO: DETERGENTE | F10: LITROS | G10: 240 | I10: =G10*H10 -> 0
A11: 3 | B11: 2.9.1-4784.51 | C11: ELEMENTOS DE LIMPIEZA | D11: 2.9.1 | E11: LIMPIADORES MULTIUSO; COMPUESTOS BIODEGRADABLES: SI, PRESENTACION: ENVASE X 5 L, TIPO: DESENGRASANTE | F11: LITROS | G11: 240 | I11: =G11*H11 -> 0
B14: Especificidades Item N° 1:
B16: Descripción técnica
C17: PRESENTACION EN BIDONES PLASTICOS POR 5LTS.
B18: Plazos y lugares de entrega
B19: SEMANAL
B20: COMEDOR | D20: CANTIDAD | E20: DOMICILIO DE ENTREGA
B21: UNA SONRISA | D21: 1 | E21: Bº SAN CARLOS OESTE AV. BONIFACIO COBACHO N° 670
B22: C.I.F Nº1 | D22: 1 | E22: AV. RIVIERA DEL VALLE ENTRE FLORIDA Y SANTA FE
B23: C.I.F - RIVERA DEL VALLE | D23: 1 | E23: Bº RIVERA DEL VALLE ENTRE VILLA EUMELIA Y MONTE CRISTO
B24: ESFUERZO PROPIO | D24: 1 | E24: Bº MUNICIPAL 35VV. NORTE C/14
B25: JIREH LOTEO SUSSEX | D25: 1 | E25: B° LA RIVERA CASA N° 28
B26: CLUB DEPORTIVO CHACARITA | D26: 1 | E26: CALLE DR.DERMIDIO GALINDEZ C/2660
B27: LA MORO | D27: 1 | E27: MAIPU NORTE 1º ETAPA MZA "H" Bº MI JARDIN
B28: PAPA FRANCISCO | D28: 1 | E28: ENTRE AV.TEREBINTO Y AV.SAN JUAN LOTE "2" MZA. "B"
B29: E.P.C - 100 V.V NORTE | D29: 1 | E29: Bº VV NORTE C/48 ENTRE ESPAÑA Y FRANCIA
B30: HOGAR DE CRISTO | D30: 1 | E30: Bº SANTA MARTA MZA. "S" LOTE "M" C/39
B31: LA LUCIERNAGA | D31: 1 | E31: Bº 20 V.V NORTE C/3
B32: VALLE VIEJO - SUMALAO | D32: 1 | E32: PADRE SEGURA S/N
... B40: CORAZONES FELICES | D40: 1 | E40: LOTEO PARQUE SUR MZ 1 LOTE N° 21
B41: *SE REALIZA LA ENTREGA DE 20 UNIDADES POR SEMANA (1 POR CADA COMEDOR) LO QUE HACE UNA SUMA DE 80 UNIDADES MENSUALES QUE REPRESENTAN UN TOTAL DE 240 UNIDADES TRIMESTRALES
B42: Calidad Minima esperada
C43: ALTA
B44: Mantenimiento
C45: 60 DIAS
B46: Garantia
C47: S/E
B50: Especificidades Item N° 2:
B52: Descripción técnica
C53: PRESENTACION EN BIDONES PLASTICOS POR 5LTS.
B54: Plazos y lugares de entrega
B55: SEMANAL
...
