Workbook

Sheet Necesidades Trimestrales
B2: Pedido de Necesidades Trimestrales
A4: JURISDICCION: | C4: 90 - Ministerio de Seguridad
A5: SAF N°: | C5: 7 - Direccion Provincial de Administracion de la Policia de Catamarca
A6: EJERCICIO: | C6: 2020
A7: TRIMESTRE: | C7: 4
A9: ID | B9: CODIGO ITEM | C9: RUBRO DE COMPRA | D9: I.P.P. | E9: DESCRIPCION | F9: UNIDAD DE MEDIDA | G9: CANTIDAD | H9: PRECIO UNITARIO ESTIMADO | I9: IMPORTE TOTAL ESTIMADO
A10: 1 | B10: 3.5.4-2065.1 | C10: BANCOS Y SEGUROS | D10: =LEFT(B10,5) -> 3.5.4 | E10: SEGURO DE RESPONSABILIDAD; DESCRIPCION: SEGURO DE RESPONSABILIDAD | F10: UNIDAD | G10: =70+141 -> 211 | I10: =SUM(1567676+178060) -> 1745736
B13: Especificidades Item N° 1:
B15: Descripción técnica
C16: CARACTERÍSTICAS: “Seguro Obligatorio de Responsabilidad Civil del Automotor conforme Res. SSN N° 35.863, 36.100 y modificatorias. Responsabilidad Civil con límites, en la República Argentina y países limítrofes: por lesiones y/o muerte y daños a cosas de terceros no transportados por acontecimientos hasta la suma de pesos 6.000.000,00. Extensión a países limítrofes sin cargo” de 212 vehiculos que integran el Parque Automotor Policial, cuyos datos se detallan en Anexo. VIGENCIA: desde el 30/12/2020 al 30/12/2021.
B17: Plazos y lugares de entrega
C18: a) LUGAR DE ENTREGA: SECCION CONTROL PATRIMONIAL (Dpto Logística), sito en Chacabuco N° 809 - Capital - De 08 a 12 horas. b) FORMA DE LA ENTREGA: Las Pólizas deben entregarse detallando el vehículo que está cubriendo el seguro contratado. c) PLAZO DE ENTREGA: El Oferente deberá establecer plazo de entrega de los elementos cotizados, debiendo ser expresado en días hábiles; que no podrá ser superior a cinco (5) días hábiles, contados a partir de la recepción de la comunicación prevista en el Artículo 80° de del Reglamento Parcial N° 2 de la ley 4938.
B20: Calidad Minima esperada
C21: Que cumpla íntegramente con lo solicitado y se extienda a todo y cada uno de los vehiculos desagregados en la planilla anexa a la presente.
B22: Mantenimiento
C23: 30 (treinta) días
B24: Garantia

Sheet  NotaPedido
A1: NOTA DE PEDIDO | J1: N° | K1: 90/2020
A3: JURISDICCIÓN: | D3: ='Necesidades Trimestrales'!C4 -> 90 - Ministerio de Seguridad
A4: SAF: | D4: ='Necesidades Trimestrales'!C5 -> 7 - Direccion Provincial de Administracion de la Policia de Catamarca
A5: UNIDAD EJECUTORA: | D5: Jefatura de Policía de la Provincia de Catamarca
A6: DEPENDENCIA SOLICITANTE: | D6: Sección Control Patrimonial - Dpto. Logistica (D-4)
A7: PERIODO UTILIZACIÓN: | D7: ='Necesidades Trimestrales'!C7 & "° Trimestre - Año " & 'Necesidades Trimestrales'!C6 -> 4° Trimestre - Año 2020
A8: OBJETO:
A10: Ítem | B10: Codigo Item | C10: DESCRIPCIÓN | H10: Adjunta Detalle Técnico | I10: Unidad Medida | J10: Precio Unitario Estimado | K10: Cantidad Solicitada
A12: 1 | B12: ='Necesidades Trimestrales'!B10 -> 3.5.4-2065.1 | C12: ='Necesidades Trimestrales'!E10 -> SEGURO DE RESPONSABILIDAD; DESCRIPCION: SEGURO DE RESPONSABILIDAD | H12: SI | I12: ='Necesidades Trimestrales'!F10 -> UNIDAD | J12: ='Necesidades Trimestrales'!H10 -> 0 | K12: ='Necesidades Trimestrales'!G10 -> 211
A13: 2
A14: 3
A15: 4
A16: 5
A17: Costo total estimado: Un Millon Setecientos Cuarenta y Cinco Mil Setecientos Treinta y Seis con 00/100 | J17: ='Necesidades Trimestrales'!I10 -> 1745736

Sheet Autor Gastar
A1: EJERCICIO: | D1: ='Necesidades Trimestrales'!C6 -> 2020 | P1: AUTORIZACION PARA GASTAR
A4: JURISDICCIÓN: | G4: =' NotaPedido'!D3 -> 90 - Ministerio de Seguridad
A5: SAF: | G5: =' NotaPedido'!D4 -> 7 - Direccion Provincial de Administracion de la Policia de Catamarca
A6: UNIDAD EJECUTORA: | G6: =' NotaPedido'!D5 -> Jefatura de Policía de la Provincia de Catamarca
A7: DEPENDENCIA SOLICITANTE: | G7: =' NotaPedido'!D6 -> Sección Control Patrimonial - Dpto. Logistica (D-4)
A8: AUTORIZACIÓN:
A9: Señor Jefe de Servicio Administrativo Financiero:
A10: ="Autorizo la realización de los trámites correspondientes, a fin de proveer a este Organismo los bienes y/o servicios que se detallan en Nota de Pedido N° " & ' NotaPedido'!K1&", afectando la erogación resultante a los créditos presupuestarios aprobados a favor de esta Unidad Ejecutora, conforme al siguiente detalle:" -> Autorizo la realización de los trámites correspondientes, a fin de proveer a este Organismo los bienes y/o servicios que se detallan en Nota de Pedido N° 90/2020, afectando la erogación resultante a los créditos presupuestarios aprobados a favor de esta Unidad Ejecutora, conforme al siguiente detalle:
A12: IMPUTACIÓN PRESUPUESTARIA
A13: CÓDIGO | O13: DENOMINACIÓN DE LA PARTIDA PRESUPUESTARIA | Q13: IMPORTE
A14: PR | B14: SB | C14: PY | D14: AC | E14: OB | F14: UG | G14: FIN | H14: FUN | I14: I | J14: P | K14: P | L14: SubP | M14: M | N14: FF
A15: 16 | B15: 0 | C15: 0 | D15: 1 | E15: 0 | F15: 10 | G15: 2 | H15: 210 | I15: =LEFT('Necesidades Trimestrales'!D10,1) -> 3 | J15: =MID('Necesidades Trimestrales'!D10,3,1) -> 5 | K15: =RIGHT('Necesidades Trimestrales'!D10,1) -> 4 | L15: 0 | M15: 1 | N15: 1.1 | O15: PRIMAS Y GASTOS DE SEGUROS | Q15: ='Necesidades Trimestrales'!I10 -> 1745736
A23: TOTAL DE PESOS: Un Millon Setecientos Cuarenta y Cinco Mil Setecientos Treinta y Seis con 00/100 | Q23: =SUM(Q15:Q22) -> 1745736
A25: JUSTIFICACIÓN:
A26: Para la adquisición de Seguro Obligatorio de Responsabilidad Civil del Automotor para los vehiculos pertenecientes a la Institucion Policial.-

Sheet Planilla Tecnica
A1: AUTOMOVILES
A2: Nº | B2: TIPO | C2: DOMINIO | D2: MARCA | E2: MOD. | F2: MOTOR | G2: CHASIS
A3: 1 | B3: AUTO | C3: OSL-109 | D3: TOYOTA ETIOS X 1,5 M/T 5P | E3: 2015 | F3: 2NRV274614 | G3: 9BRK29BT3F0055994
A4: 2 | B4: AUTO | C4: EUE-056 | D4: VW POLO | E4: 2005 | F4: 1Y958444 | G4: 8AWZZZ9EZ5A688395
A5: 3 | B5: AUTO | C5: HKX-868 | D5: VW POLO | E5: 2008 | F5: UVC038611 | G5: 8AWZZZ9EZ9A002754
A6: 4 | B6: AUTO | C6: HKX-869 | D6: VW POLO | E6: 2008 | F6: UVC038558 | G6: 8AWZZZ9EZ9A002872
A7: 5 | B7: AUTO | C7: KSV-199 | D7: FIAT SIENA | E7: 2011 | F7: 178F4055 2176328 | G7: 8AP17269HC 2241027
A8: 6 | B8: AUTO | C8: LYY-007 | D8: CHEVROLET CORSA -SPIRIT LT 1.4 | E8: 2012 | F8: T85148700 | G8: 8AGSE1950DR180215
A9: 7 | B9: AUTO | C9: LYY-053 | D9: CHEVROLET PRISMA 1,4LS | E9: 2013 | F9: T70034459 | G9: 9BGRG6950CG401440
A10: 8 | B10: AUTO | C10: HKX-841 | D10: CHEVR. CORSA | E10: 2008 | F10: 7H5145376 | G10: 8AGSB19N09R102420
A11: 9 | B11: AUTO | C11: NHS 501 | D11: TOYOTA COROLLA | E11: 2013 | F11: 2ZRM175001 | G11: 9BRBU48E4778689
A12: 10 | B12: AUTO | C12: PHO-195 | D12: FIAT PALIO ATTRACTIVE 1,4 | E12: 2015 | F12: 327A0552366431 | G12: 8AP196475F4124427
A13: 11 | B13: AUTO | C13: PHO-196 | D13: FIAT PALIO ATTRACTIVE 1,4 | E13: 2015 | F13: 327A0552346624 | G13: 8AP196475F4123099
A14: 12 | B14: AUTO | C14: AB 322 SC | D14: TOYOTA ETIOS X 1,5 M/T 5P | E14: 2017 | F14: 2NR4073730 | G14: 9BRK29BT9H0111908
A15: 13 | B15: AUTO | C15: MXR-597 | D15: CHEVROLET CORSA -SPIRIT LT 1.4 | E15: 2013 | F15: T85170468 | G15: 8AGSC1950ER113641
A16: CAMIONETAS
A17: Nº | B17: TIPO | C17: DOMINIO | D17: MARCA | E17: MOD. | F17: MOTOR | G17: CHASIS
A18: 14 | B18: CAMIONETA | C18: LZR-302 | D18: TOYOTA HILUX 4X2 SR 3.0 TDI | E18: 2012 | F18: 1KD-5931120 | G18: 8AJEZ32G4D1012111
A19: 15 | B19: CAMIONETA | C19: NQS-933 | D19: TOYOTA HILUX 4X2 D/C PACK DX 2,5 TDI | E19: 2013 | F19: 2KD-A106134 | G19: 8AJFR22G9D4566063
A20: 16 | B20: CAMIONETA | C20: OYW-526 | D20: TOYOTA HILUX 4X2 D/C PACK DX 2,5 TDI | E20: 2015 | F20: 2KD-A789175 | G20: 8AJER32G3F4057901
A21: 17 | B21: CAMIONETA | C21: OYW-527 | D21: TOYOTA HILUX 4X2 D/C PACK DX 2,5 TDI | E21: 2015 | F21: 2KD-A786575 | G21: 8AJER32G0F4057855
A22: 18 | B22: CAMIONETA | C22: OYW-528 | D22: TOYOTA HILUX 4X2 D/C PACK DX 2,5 TDI | E22: 2015 | F22: 2KD-A786461 | G22: 8AJER32G0F4057855
A23: 19 | B23: CAMIONETA | C23: OYW-530 | D23: TOYOTA HILUX 4X2 D/C PACK DX 2,5 TDI | E23: 2015 | F23: 2KD-A790442 | G23: 8AJER32G8F4057909
A24: 20 | B24: CAMIONETA | C24: OYW-531 | D24: TOYOTA HILUX 4X2 D/C PACK DX 2,5 TDI | E24: 2015 | F24: 2KD-A791057 | G24: 8AJER32G5F4057804
A25: 21 | B25: CAMIONETA | C25: FGD-109 | D25: CHEVROLET S-10 STD 4X2 | E25: 2005 | F25: 40704214298 | G25: 9BG138AC05C425603
A26: 22 | B26: CAMIONETA | C26: FGJ-769 | D26: CHEVROLET S-10 STD 4X2 | E26: 2005 | F26: 40704214142 | G26: 9BG138AC05C425904
A27: 23 | B27: CAMIONETA | C27: LJT-997 | D27: TOYOTA HILUX 4X2 D/C PACK DX 2,5 TDI | E27: 2012 | F27: 2KD-5647509 | G27: 8AJER32G1C4041563
A28: 24 | B28: CAMIONETA | C28: FHM-882 | D28: CHEVROLET S-10 STD 4X2 | E28: 2005 | F28: M1T239064 | G28: 9BG138BC06C406383
A29: 25 | B29: CAMIONETA | C29: FGD-110 | D29: CHEVROLET S-10 STD 4X2 | E29: 2005 | F29: 40704214140 | G29: 9BG138AC05C425771
A30: CAMIONETAS
A31: Nº | B31: TIPO | C31: DOMINIO | D31: MARCA | E31: MOD. | F31: MOTOR | G31: CHASIS
A32: 26 | B32: CAMIONETA | C32: OZB-152 | D32: TOYOTA HILUX 4X4 SR 3.0 TDI | E32: 2015 | F32: 2KD-A797676 | G32: 8AJFR22G7F4580238
A33: 27 | B33: CAMIONETA | C33: OZB-153 | D33: TOYOTA HILUX 4X4 SR 3.0 TDI | E33: 2015 | F33: 2KD-A799562 | G33: 8AJFR22G7F4580272
A34: 28 | B34: CAMIONETA | C34: OUL-117 | D34: TOYOTA HILUX 4X2 D/C PACK DX 2,5 TDI | E34: 2015 | F34: 1KD-A7366258 | G34: 8AJEZ32G9F1017162
A35: 29 | B35: CAMIONETA | C35: PCN-063 | D35: TOYOTA HILUX 4X2 D/C PACK DX 2,5 TDI | E35: 2015 | F35: 2KD-A824596 | G35: 8AJER32G2F4059204
A36: 30 | B36: CAMIONETA | C36: PCN-064 | D36: TOYOTA HILUX 4X2 D/C PACK DX 2,5 TDI | E36: 2015 | F36: 2KD-A824348 | G36: 8AJER32G9F4059183
A37: 31 | B37: CAMIONETA | C37: PCN-065 | D37: TOYOTA HILUX 4X2 D/C PACK DX 2,5 TDI | E37: 2015 | F37: 2KD-A823692 | G37: 8AJER32G9F4059149
A38: 32 | B38: CAMIONETA | C38: PCN-066 | D38: TOYOTA HILUX 4X2 D/C PACK DX 2,5 TDI | E38: 2015 | F38: 2KD-A824560 | G38: 8AJER32G6F4059187
A39: 33 | B39: CAMIONETA | C39: PEB-293 | D39: TOYOTA HILUX 4X2 D/C PACK DX 2,5 TDI | E39: 2015 | F39: 2KD-A835061 | G39: 8AJER32G5F4059567
A40: 34 | B40: CAMIONETA | C40: PEG-687 | D40: TOYOTA HILUX 4X2 D/C PACK DX 2,5 TDI | E40: 2015 | F40: 2KD-A839103 | G40: 8AJER32G0F4059587
...
