Workbook

Sheet Necesidades Trimestrales
B2: Pedido de Necesidades Trimestrales
A4: JURISDICCION: | C4: 40-Ministerio de Salud
A5: SAF N°: | C5: 28- Maternidad Provincial 25 de Mayo
A6: EJERCICIO: | C6: 2021
A7: TRIMESTRE: | C7: 3
A9: ID | B9: CODIGO ITEM | C9: RUBRO DE COMPRA | D9: I.P.P. | E9: DESCRIPCION | F9: UNIDAD DE MEDIDA | G9: CANTIDAD | H9: PRECIO UNITARIO ESTIMADO | I9: IMPORTE TOTAL ESTIMADO
A10: 1 | B10: 2.9.6-1891.587 | C10: REPUESTOS | D10: 2.9.2 | E10: REP. Y ACC. P/IMPRESORA; MODELO EQUIPO: LX-350, MARCA EQUIPO: EPSON, ELEMENTO: CINTA IMPRESION | F10: UNIDAD | G10: 2 | H10: 420 | I10: =H10*G10 -> 840
A11: 2 | B11: 2.9.6-1355.1988 | C11: REPUESTOS | D11: 2.9.2 | E11: CARTUCHOS DE TINTA; CODIGO: 664, USO: HEWLET PACKARD | F11: UNIDAD | G11: 30 | H11: 2600 | I11: =H11*G11 -> 78000
A12: 3 | B12: 2.9.6-1355.1988 | C12: REPUESTOS | D12: 2.9.2 | E12: CARTUCHOS DE TINTA; CODIGO: 664, USO: HEWLET PACKARD | F12: UNIDAD | G12: 30 | H12: 2600 | I12: =H12*G12 -> 78000
A13: 4 | B13: 2.9.6-401.2228 | C13: REPUESTOS | D13: 2.9.2 | E13: CARTUCHOS DE TONER; CODIGO: CF217A, USO: HP LASERJET MFP | F13: UNIDAD | G13: 20 | H13: 1000 | I13: =H13*G13 -> 20000
A14: 5 | B14: 2.9.6-1355.2065 | C14: REPUESTOS | D14: 2.9.2 | E14: CARTUCHOS DE TINTA; CODIGO: 667XL - NEGRO, USO: HP | F14: UNIDAD | G14: 20 | H14: 3500 | I14: =H14*G14 -> 70000
A15: 6 | B15: 2.9.6-1355.2066 | C15: REPUESTOS | D15: 2.9.2 | E15: CARTUCHOS DE TINTA; CODIGO: 667XL - TRICOLOR, USO: HP | F15: UNIDAD | G15: 20 | H15: 3500 | I15: =H15*G15 -> 70000
B18: Especificidades Item N° 1:
C19: Cinta de impresión alternativa
B20: Descripción técnica
C21: Cartucho 664XL COLOR- Alternativo
B22: Plazos entrega:
C23: 10 dias desde la firma del instrumento contractual.
B24: Lugar de entrega:
C25: DIVISION DE INFORMÁTICA - MATERNIDAD PROVINCIAL 25 DE MAYO -HERNANDO. DE PEDRAZA 1650
B26: Hora de entrega:
E27: 08 a 12 horas
B28: Calidad Minima esperada
B30: Mantenimiento
C31: 30 dias habiles
B32: Garantia
B36: Especificidades Item N° 2:
B38: Descripción técnica
C39: Cartucho 664XL COLOR- Alternativo
B40: Plazos entrega:
C41: 10 dias desde la firma del instrumento contractual.
B42: Lugar de entrega:
C43: DIVISION DE INFORMÁTICA - MATERNIDAD PROVINCIAL 25 DE MAYO -HERNANDO. DE PEDRAZA 1650
B44: Hora de entrega:
E45: 08 a 12 horas
B46: Calidad Minima esperada
B48: Mantenimiento
C49: 30 dias habiles
B50: Garantia
B53: Especificidades Item N° 3:
...

Sheet  NotaPedido
A1: NOTA DE PEDIDO | J1: N° | K1: 106/2021
A3: JURISDICCIÓN: | D3: ='Necesidades Trimestrales'!C4 -> 40-Ministerio de Salud
A4: SAF: | D4: ='Necesidades Trimestrales'!C5 -> 28- Maternidad Provincial 25 de Mayo
A5: UNIDAD EJECUTORA: | D5: 171-Direccion de Administración
A6: DEPENDENCIA SOLICITANTE: | D6: División Informática
A7: PERIODO UTILIZACIÓN: | D7: ='Necesidades Trimestrales'!C7 & "° Trimestre - Año " & 'Necesidades Trimestrales'!C6 -> 3° Trimestre - Año 2021
A8: OBJETO: | D8: Adquisicion de Cartuchos de Tinta
A10: Ítem | B10: Codigo Item | C10: DESCRIPCIÓN | H10: Adjunta Detalle Técnico | I10: Unidad Medida | J10: Precio Unitario Estimado | K10: Cantidad Solicitada
A12: ='Necesidades Trimestrales'!A10 -> 1 | B12: ='Necesidades Trimestrales'!B10 -> 2.9.6-1891.587 | C12: ='Necesidades Trimestrales'!E10 -> REP. Y ACC. P/IMPRESORA; MODELO EQUIPO: LX-350, MARCA EQUIPO: EPSON, ELEMENTO: CINTA IMPRESION | H12: NO | I12: ='Necesidades Trimestrales'!F10 -> UNIDAD | J12: ='Necesidades Trimestrales'!H10 -> 420 | K12: ='Necesidades Trimestrales'!G10 -> 2
A13: ='Necesidades Trimestrales'!A11 -> 2 | B13: ='Necesidades Trimestrales'!B11 -> 2.9.6-1355.1988 | C13: ='Necesidades Trimestrales'!E11 -> CARTUCHOS DE TINTA; CODIGO: 664, USO: HEWLET PACKARD | H13: SI | I13: ='Necesidades Trimestrales'!F11 -> UNIDAD | J13: ='Necesidades Trimestrales'!H11 -> 2600 | K13: ='Necesidades Trimestrales'!G11 -> 30
A14: ='Necesidades Trimestrales'!A12 -> 3 | B14: ='Necesidades Trimestrales'!B12 -> 2.9.6-1355.1988 | C14: ='Necesidades Trimestrales'!E12 -> CARTUCHOS DE TINTA; CODIGO: 664, USO: HEWLET PACKARD | H14: SI | I14: ='Necesidades Trimestrales'!F12 -> UNIDAD | J14: ='Necesidades Trimestrales'!H12 -> 2600 | K14: ='Necesidades Trimestrales'!G12 -> 30
A15: ='Necesidades Trimestrales'!A13 -> 4 | B15: ='Necesidades Trimestrales'!B13 -> 2.9.6-401.2228 | C15: ='Necesidades Trimestrales'!E13 -> CARTUCHOS DE TONER; CODIGO: CF217A, USO: HP LASERJET MFP | H15: SI | I15: ='Necesidades Trimestrales'!F13 -> UNIDAD | J15: ='Necesidades Trimestrales'!H13 -> 1000 | K15: ='Necesidades Trimestrales'!G13 -> 20
A16: ='Necesidades Trimestrales'!A14 -> 5 | B16: ='Necesidades Trimestrales'!B14 -> 2.9.6-1355.2065 | C16: ='Necesidades Trimestrales'!E14 -> CARTUCHOS DE TINTA; CODIGO: 667XL - NEGRO, USO: HP | H16: SI | I16: ='Necesidades Trimestrales'!F14 -> UNIDAD | J16: ='Necesidades Trimestrales'!H14 -> 3500 | K16: ='Necesidades Trimestrales'!G14 -> 20
A17: ='Necesidades Trimestrales'!A15 -> 6 | B17: ='Necesidades Trimestrales'!B15 -> 2.9.6-1355.2066 | C17: ='Necesidades Trimestrales'!E15 -> CARTUCHOS DE TINTA; CODIGO: 667XL - TRICOLOR, USO: HP | H17: SI | I17: ='Necesidades Trimestrales'!F15 -> UNIDAD | J17: ='Necesidades Trimestrales'!H15 -> 3500 | K17: ='Necesidades Trimestrales'!G15 -> 20
A18: Costo total estimado: TRESCIENTOS DIECISEIS MIL OCHOCIENTOS CUARENTA CON 00/100 | J18: =SUMPRODUCT(J12:J17*K12:K17) -> 316840

Sheet Autor Gastar
A1: EJERCICIO: | D1: ='Necesidades Trimestrales'!C6 -> 2021 | P1: AUTORIZACION PARA GASTAR
A4: JURISDICCIÓN: | G4: =' NotaPedido'!D3 -> 40-Ministerio de Salud
A5: SAF: | G5: =' NotaPedido'!D4 -> 28- Maternidad Provincial 25 de Mayo
A6: UNIDAD EJECUTORA: | G6: =' NotaPedido'!D5 -> 171-Direccion de Administración
A7: DEPENDENCIA SOLICITANTE: | G7: =' NotaPedido'!D6 -> División Informática
A8: AUTORIZACIÓN:
A9: Señor Jefe de Servicio Administrativo Financiero:
A10: ="Autorizo la realización de los trámites correspondientes, a fin de proveer a este Organismo los bienes y/o servicios que se detallan en Nota de Pedido N° " & ' NotaPedido'!K1&", afectando la erogación resultante a los créditos presupuestarios aprobados a favor de esta Unidad Ejecutora, conforme al siguiente detalle:" -> Autorizo la realización de los trámites correspondientes, a fin de proveer a este Organismo los bienes y/o servicios que se detallan en Nota de Pedido N° 106/2021, afectando la erogación resultante a los créditos presupuestarios aprobados a favor de esta Unidad Ejecutora, conforme al siguiente detalle:
A12: IMPUTACIÓN PRESUPUESTARIA
A13: CÓDIGO | O13: DENOMINACIÓN DE LA PARTIDA PRESUPUESTARIA | Q13: IMPORTE
A14: PR | B14: SB | C14: PY | D14: AC | E14: OB | F14: UG | G14: FIN | H14: FUN | I14: I | J14: P | K14: P | L14: SubP | M14: M | N14: FF
A15: 42 | D15: 3 | G15: 1 | H15: 6 | I15: 2 | J15: 9 | K15: 2 | M15: 1 | N15: 1.1 | O15: Utiles de escritorio Oficina y Enseñanzas | Q15: 316840
A22: TOTAL DE PESOS: TRESCIENTOS DIECISEIS MIL OCHOCIENTOS CUARENTA CON 00/100 | Q22: =SUM(Q15:Q21) -> 316840
A24: JUSTIFICACIÓN:
A25: ADQUISICION DE CARTUCHOS DE TINTAS PARA SER DESTINADAS A LA MATERNIDAD 25 DE MAYO
