Workbook

Sheet SAF 011
A1: 2022
B2: Pedido de Necesidades Trimestrales
A4: JURISDICCION: | C4: 040 - MINISTERIO DE SALUD
A5: SAF N°: | C5: 011 - DIRECCION PROVINCIAL DE ADMINISTRACION - MINISTERIO DE SALUD
A6: EJERCICIO: | C6: 2022
A7: TRIMESTRE: | C7: CUARTO
A9: ID | B9: CODIGO ITEM | C9: RUBRO DE COMPRA | D9: I.P.P. | E9: DESCRIPCION | F9: UNIDAD DE MEDIDA | G9: CANTIDAD TOTAL | H9: PRECIO UNITARIO ESTIMADO | I9: IMPORTE TOTAL ESTIMADO | J9: ESPECIFICACION TECNICA | L9: 222 | M9: 252 | N9: 256 | O9: 259 | P9: 265 | Q9: 295
A10: 1 | B10: 2.5.6-7104.276 | C10: COMBUSTIBLES Y LUBRICANTES | D10: 256 | E10: ACEITES LUBRICANTES; USO: MAQUINA, PRESENTACION: AEROSOL X 400 CM3, NORMA: MULTIUSO | F10: UNIDAD | G10: 150 | H10: 700 | I10: =+G10*H10 -> 105000 | N10: =+I10 -> 105000
A11: 2 | B11: 2.5.2-3204.13 | C11: PROD. MEDICO/FARMACEUTICOS/LAB | D11: 252 | E11: ACIDO GRABADOR ODONTOLOG.; ESTADO: GEL, PRESENTACION: JERINGA X 12 GR, CAPACIDAD: 12 GR | F11: UNIDAD | G11: 300 | H11: 700 | I11: =+G11*H11 -> 210000 | J11: ACIDO FOSFORICO 37% GEL JERINGA 12 GR | M11: =+I11 -> 210000
A12: 3 | B12: 2.5.2-2327.29 | C12: PROD. MEDICO/FARMACEUTICOS/LAB | D12: 295 | E12: ACRILICOS AUTOCURABLES; TIPO: POLIMERO DE AUTOPOLIMERIZACION, PRESENTACION: FRASCO X 1 Kg | F12: UNIDAD | G12: 6 | H12: 5500 | I12: =+G12*H12 -> 33000 | J12: POLIMERO AUTOCURADO 1 KG T/ NEW POLL | Q12: =+I12 -> 33000
A13: 4 | B13: 2.5.2-6021.4 | C13: PROD. MEDICO/FARMACEUTICOS/LAB | D13: 295 | E13: ACRILICOS TERMOCURABLES; TIPO: POLIMERO, PRESENTACION: ENVASE X 1 Kg | F13: UNIDAD | G13: 15 | H13: 5500 | I13: =+G13*H13 -> 82500 | J13: POLIMERO TERMOCURADO 1 KG T/ NEW POLL | Q13: =+I13 -> 82500
A14: 5 | B14: 2.5.2-5538.8 | C14: PROD. MEDICO/FARMACEUTICOS/LAB | D14: 252 | E14: ADHESIVOS P/ODONTOLOGIA; PRESENTACION: FRASCO X 4,5 mm, TIPO: ADHESIVO+PRIMER, USO: ODONTOLOGICO | F14: UNIDAD | G14: 200 | H14: 1500 | I14: =+G14*H14 -> 300000 | M14: =+I14 -> 300000
A15: 6 | B15: 2.9.5-441.82 | C15: PROD. MEDICO/FARMACEUTICOS/LAB | D15: 295 | E15: AGUJAS QUIRURGICAS; TIPO: CARPULE, ESPECIFICACION: CORTA, UNIDAD VENTA: CAJA X 100, PRESENTACION: CAJA X 100 | F15: CAJA | G15: 200 | H15: 900 | I15: =+G15*H15 -> 180000 | J15: AGUJA CARPULE CORTA 21 MM CAJA X 100 UNID. | Q15: =+I15 -> 180000
A16: 7 | B16: 2.9.5-441.428 | C16: PROD. MEDICO/FARMACEUTICOS/LAB | D16: 295 | E16: AGUJAS QUIRURGICAS; TIPO: CARPULE, ESPECIFICACION: EXTRA CORTAS, PRESENTACION: ENVASE X 100 UN | F16: CAJA | G16: 40 | H16: 900 | I16: =+G16*H16 -> 36000 | J16: AGUJA CARPULE EXTRACORTA 12 MM CAJA X 100 UNID. | Q16: =+I16 -> 36000
A17: 8 | B17: 2.9.5-441.119 | C17: PROD. MEDICO/FARMACEUTICOS/LAB | D17: 295 | E17: AGUJAS QUIRURGICAS; TIPO: CARPULE, ESPECIFICACION: LARGA, PRESENTACION: CAJA X 100, UNIDAD VENTA: CAJA X 100 | F17: CAJA | G17: 40 | H17: 900 | I17: =+G17*H17 -> 36000 | J17: AGUJA CARPULE INTERMEDIA 25 MM CAJA X 100 UNID. | Q17: =+I17 -> 36000
A18: 9 | B18: 2.9.5-470.29 | C18: PROD. MEDICO/FARMACEUTICOS/LAB | D18: 295 | E18: ALGODONES; TIPO: ESTERIL, CAPACIDAD: PAQUETE X 500 ROLLOS, PRESENTACION: ENVASE X 500 | F18: BOLSA | G18: 50 | H18: 700 | I18: =+G18*H18 -> 35000 | J18: ROLLO DE ALGODÓN X 500 UNIDADES (0,375X 1-1/2") ODONTOLOGICO | Q18: =+I18 -> 35000
A19: 10 | B19: 2.5.2-1883.135 | C19: PROD. MEDICO/FARMACEUTICOS/LAB | D19: 252 | E19: ANESTESICOS LOCALES; TIPO: MONODROGA, DROGA GENERICA: LIDOCAINA 5%, FORMA FARMACEUTICA: GEL, PRESENTACION: ENVASE X 18 GR | F19: UNIDAD | G19: 50 | H19: 1800 | I19: =+G19*H19 -> 90000 | J19: ANESTESIA TOPICA LIDOCAINA 5 % X 18 GR | M19: =+I19 -> 90000
A20: 11 | B20: 2.5.2-1883.37 | C20: PROD. MEDICO/FARMACEUTICOS/LAB | D20: 252 | E20: ANESTESICOS LOCALES; TIPO: SIN VALOR, DROGA GENERICA: CLORHIDRATO DE CARTICAINA 4%, FORMA FARMACEUTICA: ANESTUBO CARPULE, PRESENTACION: CAJA X 50 UN | F20: CAJA | G20: 1440 | H20: 4500 | I20: =+G20*H20 -> 6480000 | M20: =+I20 -> 6480000
A21: 12 | B21: 2.5.2-1723.59 | C21: PROD. MEDICO/FARMACEUTICOS/LAB | D21: 252 | E21: ANTISEPTICOS LOCALES P/PERSONA; TIPO: MONODROGA, DROGA GENERICA: EDTAC, FORMA FARMACEUTICA: SOLUCION, PRESENTACION: FRASCO X 20 mL | F21: UNIDAD | G21: 20 | H21: 400 | I21: =+G21*H21 -> 8000 | M21: =+I21 -> 8000
A22: 13 | B22: 2.5.2-1723.53 | C22: PROD. MEDICO/FARMACEUTICOS/LAB | D22: 252 | E22: ANTISEPTICOS LOCALES P/PERSONA; TIPO: MONODROGA, DROGA GENERICA: EUGENOL, FORMA FARMACEUTICA: LIQUIDO, PRESENTACION: FRASCO X 20 mL | F22: UNIDAD | G22: 60 | H22: 700 | I22: =+G22*H22 -> 42000 | M22: =+I22 -> 42000
A23: 14 | B23: 2.5.2-1723.148 | C23: PROD. MEDICO/FARMACEUTICOS/LAB | D23: 252 | E23: ANTISEPTICOS LOCALES P/PERSONA; TIPO: MONODROGA, DROGA GENERICA: IODOFORMO, FORMA FARMACEUTICA: POLVO, PRESENTACION: ENVASE X 20 GR | F23: UNIDAD | G23: 50 | H23: 500 | I23: =+G23*H23 -> 25000 | M23: =+I23 -> 25000
A24: 15 | B24: 2.9.9-3095.4 | C24: INDUMENT TEXTIL Y CONFECCIONES | D24: 222 | E24: BABEROS; TIPO: DESCARTABLE, MATERIAL: FISELINA NO ESTERIL, PRESENTACION: CAJA X 100 UN | F24: CAJA | G24: 200 | H24: 700 | I24: =+G24*H24 -> 140000 | J24: BABEROS DE FRISELINA DESCARTABLE USO ODONTOLOGICO | L24: =+I24 -> 140000
A25: 16 | B25: 2.9.5-5507.2 | C25: PROD. MEDICO/FARMACEUTICOS/LAB | D25: 295 | E25: CADENAS P/BABEROS; MATERIAL : 147 dBV/mPa , USO: ODONTOLOGIA, MATERIAL: METAL | F25: UNIDAD | G25: 50 | H25: 230 | I25: =+G25*H25 -> 11500 | Q25: =+I25 -> 11500
A26: 17 | B26: 2.9.5-2563.4 | C26: PROD. MEDICO/FARMACEUTICOS/LAB | D26: 252 | E26: CARIOSTATICOS; ENVASE: AVIO X 5 mL, PRESENTACION: AVIO X 5 mL | F26: UNIDAD | G26: 100 | H26: 1000 | I26: =+G26*H26 -> 100000 | J26: CARIOSTATICO FLUORSILVER 5 ML REMINERALIZADOR FLUORURO DIAMINO 38 % | M26: =+I26 -> 100000
A27: 18 | B27: 2.5.2-2322.20 | C27: PROD. MEDICO/FARMACEUTICOS/LAB | D27: 252 | E27: CEMENTOS QUIRURGICOS; PRESENTACION: AVIO 13 GRS/11 GRS, TIPO: HIDROXIDO DE CALCIO FRAGUABLE, USO: ODONTOLOGIA | F27: CAJA | G27: 20 | H27: 500 | I27: =+G27*H27 -> 10000 | J27: PASTA DE HIDROXIDO DE CALCIO FOTOPOLIMERIZABLE, AVIO 13/11 GR | M27: =+I27 -> 10000
A28: 19 | B28: 2.5.2-2322.12 | C28: PROD. MEDICO/FARMACEUTICOS/LAB | D28: 252 | E28: CEMENTOS QUIRURGICOS; PRESENTACION: ENVASE X 20 GR, TIPO: GROSSMAN, USO: ODONTOLOGIA | F28: UNIDAD | G28: 50 | H28: 500 | I28: =+G28*H28 -> 25000 | J28: CEMENTO GROSSMAN AVIO 20 G | M28: =+I28 -> 25000
A29: 20 | B29: 2.5.9-1687.7 | C29: PINTURAS | D29: 259 | E29: CERAS; TIPO: ROSA, USO: ODONTOLOGICO, CAPACIDAD: ENVASE X 1 Kg, PRESENTACION: ENVASE X 1 Kg | F29: UNIDAD | G29: 100 | H29: 200 | I29: 20000 | J29: CERA ROSA LAMINA X 1KG USO ODONTOLOGICO | O29: =+I29 -> 20000
A30: 21 | B30: 2.5.9-1687.3 | C30: PINTURAS | D30: 259 | E30: CERAS; TIPO: UTILITY, USO: ODONTOLOGICO, CAPACIDAD: ENVASE X 200 GR, PRESENTACION: ENVASE X 200 GR | F30: UNIDAD | G30: 50 | H30: 1000 | I30: 50000 | J30: CERA UTILITY ROJA X 200 GM USO ODONTOLOGICO UNIDAD | O30: =+I30 -> 50000
A31: 22 | B31: 2.9.5-2567.163 | C31: PROD. MEDICO/FARMACEUTICOS/LAB | D31: 295 | E31: FRESAS P/ODONTOLOGIA; MATERIAL: PIEDRA DE DIAMANTE, NUMERO: 4, LARGO: STANDAR, TIPO: REDONDA FG | F31: UNIDAD | G31: 20 | H31: 300 | I31: =+G31*H31 -> 6000 | Q31: =+I31 -> 6000
A32: 23 | B32: 2.9.5-2567.164 | C32: PROD. MEDICO/FARMACEUTICOS/LAB | D32: 295 | E32: FRESAS P/ODONTOLOGIA; MATERIAL: PIEDRA DE DIAMANTE, NUMERO: 5, LARGO: STANDAR, TIPO: REDONDA FG | F32: UNIDAD | G32: 20 | H32: 300 | I32: =+G32*H32 -> 6000 | Q32: =+I32 -> 6000
A33: 24 | B33: 2.9.5-2567.165 | C33: PROD. MEDICO/FARMACEUTICOS/LAB | D33: 295 | E33: FRESAS P/ODONTOLOGIA; MATERIAL: PIEDRA DE DIAMANTE, NUMERO: 6, LARGO: STANDAR, TIPO: REDONDA FG | F33: UNIDAD | G33: 20 | H33: 300 | I33: =+G33*H33 -> 6000 | Q33: =+I33 -> 6000
A34: 25 | B34: 2.9.5-2567.201 | C34: PROD. MEDICO/FARMACEUTICOS/LAB | D34: 295 | E34: FRESAS P/ODONTOLOGIA; MATERIAL: PIEDRA DE DIAMANTE, NUMERO: SIN, LARGO: STANDAR, TIPO: AGUJA GRANO ULTRA FINO FG | F34: UNIDAD | G34: 100 | H34: 300 | I34: =+G34*H34 -> 30000 | J34: Piedra de diamante aguja grano ultrafino FG numero 296 | Q34: =+I34 -> 30000
A35: 26 | B35: 2.9.5-2567.239 | C35: PROD. MEDICO/FARMACEUTICOS/LAB | D35: 295 | E35: FRESAS P/ODONTOLOGIA; MATERIAL: PIEDRA DE DIAMANTE, NUMERO: SIN, LARGO: STANDAR, TIPO: CILINDRICA FG | F35: UNIDAD | G35: 100 | H35: 300 | I35: =+G35*H35 -> 30000 | J35: Piedra de diamante FG cilindrica numero 109 | Q35: =+I35 -> 30000
A36: 27 | B36: 2.9.5-444.24 | C36: PROD. MEDICO/FARMACEUTICOS/LAB | D36: 295 | E36: HOJAS DE BISTURI; TIPO: CAJA X 100 UN, Nº: 15, NUMERO: 15 | F36: CAJA | G36: 10 | H36: 1200 | I36: =+G36*H36 -> 12000 | Q36: =+I36 -> 12000
A37: 28 | B37: 2.7.5-421.19 | C37: FERRETERIA | D37: 295 | E37: HOJAS DE SIERRA; DIENTES X PULGADA: SIN VALOR, LONG.DE CUERPO: 14 Cm, TIPO: COMUN | F37: UNIDAD | G37: 20 | H37: 200 | I37: =+G37*H37 -> 4000 | J37: Hoja tipo Ney para sierra odontologia- laboratorio longitud 14 cm- ancho 1mm | Q37: =+I37 -> 4000
A38: 29 | B38: 2.9.5-5144.184 | C38: PROD. MEDICO/FARMACEUTICOS/LAB | D38: 295 | E38: INSTRUMENTAL ODONTOLOGICO; DESCARTABLE: NO, PRESENTACION: UNIDAD, TIPO: ALICATE DE CORTE Y MODELADO | F38: UNIDAD | G38: 6 | H38: 4000 | I38: =+G38*H38 -> 24000 | J38: ALICATE DE CORTE P/ PROTESIS | Q38: =+I38 -> 24000
A39: 30 | B39: 2.9.5-5144.177 | C39: PROD. MEDICO/FARMACEUTICOS/LAB | D39: 295 | E39: INSTRUMENTAL ODONTOLOGICO; DESCARTABLE: NO, PRESENTACION: UNIDAD, TIPO: MATRIZ METALICA | F39: UNIDAD | G39: 10 | H39: 500 | I39: =+G39*H39 -> 5000 | J39: MATRIZ DE ACERO 6 MM | Q39: =+I39 -> 5000
A40: 31 | B40: 2.9.5-5144.593 | C40: PROD. MEDICO/FARMACEUTICOS/LAB | D40: 295 | E40: INSTRUMENTAL ODONTOLOGICO; TIPO: CEPILLO DE 4 HILERAS, DESCARTABLE: SI, PRESENTACION: UNIDAD | F40: UNIDAD | G40: 30 | H40: 400 | I40: =+G40*H40 -> 12000 | J40: PARA PULIR PROTESIS | Q40: =+I40 -> 12000
A41: 32 | B41: 2.9.5-5144.481 | C41: PROD. MEDICO/FARMACEUTICOS/LAB | D41: 295 | E41: INSTRUMENTAL ODONTOLOGICO; TIPO: CLIP P/RADIOGRAFIA, DESCARTABLE: NO, PRESENTACION: UNIDAD | F41: UNIDAD | G41: 10 | H41: 1500 | I41: =+G41*H41 -> 15000 | J41: CLIP PARA RX METALICO - CAJA X 7 UNID | Q41: =+I41 -> 15000
A42: 33 | B42: 2.9.5-5144.563 | C42: PROD. MEDICO/FARMACEUTICOS/LAB | D42: 295 | E42: INSTRUMENTAL ODONTOLOGICO; TIPO: COMPRESA P/PLATINA AZUL, DESCARTABLE: SI, PRESENTACION: CAJA X 500 UN | F42: CAJA | G42: 700 | H42: 200 | I42: =+G42*H42 -> 140000 | J42: COMPRESA DESCARTABLE X 500 UNIDADES USO ODONTOLOGICO | Q42: =+I42 -> 140000
...

Sheet NP
A1: NOTA DE PEDIDO | J1: N° | K1: XX/2022
A3: JURISDICCIÓN: | D3: ='SAF 011'!C4 -> 040 - MINISTERIO DE SALUD
A4: SAF: | D4: ='SAF 011'!C5 -> 011 - DIRECCION PROVINCIAL DE ADMINISTRACION - MINISTERIO DE SALUD
A5: UNIDAD EJECUTORA: | D5: 470 - DIRECCION PROVINCIAL DE ODONTOLOGIA
A6: DEPENDENCIA SOLICITANTE: | D6: 470 - DIRECCION PROVINCIAL DE ODONTOLOGIA
A7: PERIODO UTILIZACIÓN: | D7: TRES (3) MESES
A8: OBJETO: | D8: ADQ. RUBRO INSUMOS PARA ODONTOLOGIA
A10: Ítem | B10: Codigo Item | C10: DESCRIPCIÓN | H10: Adjunta Detalle Técnico | I10: Unidad Medida | J10: Precio Unitario Estimado | K10: Cantidad Solicitada
A12: 1 | B12: ='SAF 011'!B10 -> 2.5.6-7104.276 | C12: ='SAF 011'!E10 -> ACEITES LUBRICANTES; USO: MAQUINA, PRESENTACION: AEROSOL X 400 CM3, NORMA: MULTIUSO | H12: NO | I12: ='SAF 011'!F10 -> UNIDAD | J12: ='SAF 011'!H10 -> 700 | K12: ='SAF 011'!G10 -> 150
A13: 2 | B13: ='SAF 011'!B11 -> 2.5.2-3204.13 | C13: ='SAF 011'!E11 -> ACIDO GRABADOR ODONTOLOG.; ESTADO: GEL, PRESENTACION: JERINGA X 12 GR, CAPACIDAD: 12 GR | H13: SI | I13: ='SAF 011'!F11 -> UNIDAD | J13: ='SAF 011'!H11 -> 700 | K13: ='SAF 011'!G11 -> 300
A14: 3 | B14: ='SAF 011'!B12 -> 2.5.2-2327.29 | C14: ='SAF 011'!E12 -> ACRILICOS AUTOCURABLES; TIPO: POLIMERO DE AUTOPOLIMERIZACION, PRESENTACION: FRASCO X 1 Kg | H14: SI | I14: ='SAF 011'!F12 -> UNIDAD | J14: ='SAF 011'!H12 -> 5500 | K14: ='SAF 011'!G12 -> 6
A15: 4 | B15: ='SAF 011'!B13 -> 2.5.2-6021.4 | C15: ='SAF 011'!E13 -> ACRILICOS TERMOCURABLES; TIPO: POLIMERO, PRESENTACION: ENVASE X 1 Kg | H15: SI | I15: ='SAF 011'!F13 -> UNIDAD | J15: ='SAF 011'!H13 -> 5500 | K15: ='SAF 011'!G13 -> 15
A16: 5 | B16: ='SAF 011'!B14 -> 2.5.2-5538.8 | C16: ='SAF 011'!E14 -> ADHESIVOS P/ODONTOLOGIA; PRESENTACION: FRASCO X 4,5 mm, TIPO: ADHESIVO+PRIMER, USO: ODONTOLOGICO | H16: NO | I16: ='SAF 011'!F14 -> UNIDAD | J16: ='SAF 011'!H14 -> 1500 | K16: ='SAF 011'!G14 -> 200
A17: 6 | B17: ='SAF 011'!B15 -> 2.9.5-441.82 | C17: ='SAF 011'!E15 -> AGUJAS QUIRURGICAS; TIPO: CARPULE, ESPECIFICACION: CORTA, UNIDAD VENTA: CAJA X 100, PRESENTACION: CAJA X 100 | H17: SI | I17: ='SAF 011'!F15 -> CAJA | J17: ='SAF 011'!H15 -> 900 | K17: ='SAF 011'!G15 -> 200
A18: 7 | B18: ='SAF 011'!B16 -> 2.9.5-441.428 | C18: ='SAF 011'!E16 -> AGUJAS QUIRURGICAS; TIPO: CARPULE, ESPECIFICACION: EXTRA CORTAS, PRESENTACION: ENVASE X 100 UN | H18: SI | I18: ='SAF 011'!F16 -> CAJA | J18: ='SAF 011'!H16 -> 900 | K18: ='SAF 011'!G16 -> 40
A19: 8 | B19: ='SAF 011'!B17 -> 2.9.5-441.119 | C19: ='SAF 011'!E17 -> AGUJAS QUIRURGICAS; TIPO: CARPULE, ESPECIFICACION: LARGA, PRESENTACION: CAJA X 100, UNIDAD VENTA: CAJA X 100 | H19: SI | I19: ='SAF 011'!F17 -> CAJA | J19: ='SAF 011'!H17 -> 900 | K19: ='SAF 011'!G17 -> 40
A20: 9 | B20: ='SAF 011'!B18 -> 2.9.5-470.29 | C20: ='SAF 011'!E18 -> ALGODONES; TIPO: ESTERIL, CAPACIDAD: PAQUETE X 500 ROLLOS, PRESENTACION: ENVASE X 500 | H20: SI | I20: ='SAF 011'!F18 -> BOLSA | J20: ='SAF 011'!H18 -> 700 | K20: ='SAF 011'!G18 -> 50
A21: 10 | B21: ='SAF 011'!B19 -> 2.5.2-1883.135 | C21: ='SAF 011'!E19 -> ANESTESICOS LOCALES; TIPO: MONODROGA, DROGA GENERICA: LIDOCAINA 5%, FORMA FARMACEUTICA: GEL, PRESENTACION: ENVASE X 18 GR | H21: SI | I21: ='SAF 011'!F19 -> UNIDAD | J21: ='SAF 011'!H19 -> 1800 | K21: ='SAF 011'!G19 -> 50
A22: 11 | B22: ='SAF 011'!B20 -> 2.5.2-1883.37 | C22: ='SAF 011'!E20 -> ANESTESICOS LOCALES; TIPO: SIN VALOR, DROGA GENERICA: CLORHIDRATO DE CARTICAINA 4%, FORMA FARMACEUTICA: ANESTUBO CARPULE, PRESENTACION: CAJA X 50 UN | H22: NO | I22: ='SAF 011'!F20 -> CAJA | J22: ='SAF 011'!H20 -> 4500 | K22: ='SAF 011'!G20 -> 1440
A23: 12 | B23: ='SAF 011'!B21 -> 2.5.2-1723.59 | C23: ='SAF 011'!E21 -> ANTISEPTICOS LOCALES P/PERSONA; TIPO: MONODROGA, DROGA GENERICA: EDTAC, FORMA FARMACEUTICA: SOLUCION, PRESENTACION: FRASCO X 20 mL | H23: NO | I23: ='SAF 011'!F21 -> UNIDAD | J23: ='SAF 011'!H21 -> 400 | K23: ='SAF 011'!G21 -> 20
... A124: 113 | B124: ='SAF 011'!B122 -> 2.5.2-9146.8 | C124: ='SAF 011'!E122 -> YESOS; TIPO: TALLER, PRESENTACION: ENVASE X 25 Kg | H124: SI | I124: ='SAF 011'!F122 -> UNIDAD | J124: ='SAF 011'!H122 -> 2000 | K124: ='SAF 011'!G122 -> 12
A125: Costo total estimado: PESOS DOCE MILLONES OCHOCIENTOS CINCUENTA Y SEIS MIL TRESCIENTOS CON 00/100.- | J125: =SUMPRODUCT(J12:J124,K12:K124) -> 12856300

Sheet APG
A1: EJERCICIO: | D1: 2022 | P1: AUTORIZACION PARA GASTAR
A4: JURISDICCIÓN: | G4: =NP!D3 -> 040 - MINISTERIO DE SALUD
A5: SAF: | G5: =NP!D4 -> 011 - DIRECCION PROVINCIAL DE ADMINISTRACION - MINISTERIO DE SALUD
A6: UNIDAD EJECUTORA: | G6: =NP!D5 -> 470 - DIRECCION PROVINCIAL DE ODONTOLOGIA
A7: DEPENDENCIA SOLICITANTE: | G7: =NP!D6 -> 470 - DIRECCION PROVINCIAL DE ODONTOLOGIA
A8: AUTORIZACIÓN:
A9: Señor Director de Administración o Titular del Servicio Administrativo Financiero:
A10: Autorizo la realización de los trámites correspondientes, a fin de proveer a este Organismo los bienes que se detallan en Nota de Pedido N°....... , afectando la erogación resultante a los créditos presupuestarios aprobados a favor de esta Unidad Ejecutora, conforme al siguiente detalle:
A12: IMPUTACIÓN PRESUPUESTARIA
A13: CÓDIGO | O13: DENOMINACIÓN DE LA PARTIDA PRESUPUESTARIA | Q13: IMPORTE
A14: PR | B14: SB | C14: PY | D14: AC | E14: OB | F14: UG | G14: FIN | H14: FUN | I14: I | J14: P | K14: P | L14: SubP | M14: M | N14: FF
A15: 29 | D15: 1 | F15: 4901 | G15: 3 | H15: 1 | I15: 2 | J15: 2 | K15: 2 | M15: 1 | N15: 1.1 | O15: PRENDAS DE VESTIR | Q15: ='SAF 011'!L123 -> 140000
A16: 29 | D16: 1 | F16: 4901 | G16: 3 | H16: 1 | I16: 2 | J16: 5 | K16: 2 | M16: 1 | N16: 1.1 | O16: PRODUCTOS FARMACEUTICOS Y MEDICINALES | Q16: ='SAF 011'!M123 -> 8663500
A17: 29 | D17: 1 | F17: 4901 | G17: 3 | H17: 1 | I17: 2 | J17: 5 | K17: 6 | M17: 1 | N17: 1.1 | O17: COMBUSTIBLES Y LUBRICANTES | Q17: ='SAF 011'!N123 -> 105000
A18: 29 | D18: 1 | F18: 4901 | G18: 3 | H18: 1 | I18: 2 | J18: 5 | K18: 9 | M18: 1 | N18: 1.1 | O18: OTROS NEP | Q18: ='SAF 011'!O123 -> 570000
A19: 29 | D19: 1 | F19: 4901 | G19: 3 | H19: 1 | I19: 2 | J19: 6 | K19: 5 | M19: 1 | N19: 1.1 | O19: CEMENTO, CAL Y YESO | Q19: ='SAF 011'!P123 -> 53600
A20: 29 | D20: 1 | F20: 4901 | G20: 3 | H20: 1 | I20: 2 | J20: 9 | K20: 5 | M20: 1 | N20: 1.1 | O20: UTILES MENORES MEDICOS, QUIRURGICOS Y DE LABORATORIO | Q20: ='SAF 011'!Q123 -> 3324200
A38: TOTAL DE PESOS: DOCE MILLONES OCHOCIENTOS CINCUENTA Y SEIS MIL TRESCIENTOS CON 00/100.- | Q38: =SUM(Q15:Q37) -> 12856300
A40: JUSTIFICACIÓN:
A41: =NP!D8 -> ADQ. RUBRO INSUMOS PARA ODONTOLOGIA
