Workbook

Sheet Necesidades Trimestrales
B2: Pedido de Necesidades Trimestrales
A4: JURISDICCION: | C4: 40 - Ministerio de Salud
A5: SAF N°: | C5: 23 - Hospital Interzonal San Juan Bautista
A6: EJERCICIO: | C6: 2022
A7: TRIMESTRE: | C7: 2
A9: ID | B9: CODIGO ITEM | C9: RUBRO DE COMPRA | D9: I.P.P. | E9: DESCRIPCION | F9: UNIDAD DE MEDIDA | G9: CANTIDAD | H9: PRECIO UNITARIO ESTIMADO | I9: IMPORTE TOTAL ESTIMADO
A10: 1 | C10: Compuestos Quimicos | D10: 2.5.1 | E10: ACID WASH SOLUTION 2 X 1800 MLP/COBAS C311 | F10: CAJA | G10: 20 | H10: 41462 | I10: =G10*H10 -> 829240
A11: 2 | C11: Compuestos Quimicos | D11: 2.5.1 | E11: AMPOULER PARA COBAS B221 | F11: CAJA | G11: 2 | H11: 7577 | I11: =G11*H11 -> 15154
A12: 3 | C12: Compuestos Quimicos | D12: 2.5.1 | E12: ANTICUERPOS ANTITRANSGLUTAMINASA TIPO ORGESTRIOL -ANTI TRANSGLUTAMINASA EN IGA x 96 DET. | F12: CAJA | G12: 4 | H12: 41184 | I12: =G12*H12 -> 164736
A13: 4 | C13: Compuestos Quimicos | D13: 2.5.1 | E13: CALIBRADOR ACTH X 10 CAL COBAS E-411 ROCHE | F13: CAJA | G13: 1 | H13: 60026 | I13: =G13*H13 -> 60026
A14: 5 | C14: Compuestos Quimicos | D14: 2.5.1 | E14: CALIBRADOR ALFA FETO PROTEINA X 10 CAL COBAS E-411 ROCHE | F14: CAJA | G14: 1 | H14: 15611 | I14: =G14*H14 -> 15611
A15: 6 | C15: Compuestos Quimicos | D15: 2.5.1 | E15: CALIBRADOR ANTI SARS COV-2 CUANTITATIVO P/ COBAS E411 x 100 DET | F15: CAJA | G15: 1 | H15: 3900 | I15: =G15*H15 -> 3900
A16: 7 | C16: Compuestos Quimicos | D16: 2.5.1 | E16: CALIBRADOR ANTI TIROGLOBULINA X 10 CAL COBAS E-411 ROCHE | F16: CAJA | G16: 1 | H16: 20282 | I16: =G16*H16 -> 20282
A17: 8 | C17: Compuestos Quimicos | D17: 2.5.1 | E17: CALIBRADOR ANTI TPO X 10 CAL COBAS E-411 ROCHE | F17: CAJA | G17: 3 | H17: 20282 | I17: =G17*H17 -> 60846
A18: 9 | C18: Compuestos Quimicos | D18: 2.5.1 | E18: CALIBRADOR B-CROSS LAP X 10 CAL COBAS E-411 ROCHE | F18: CAJA | G18: 1 | H18: 20282 | I18: =G18*H18 -> 20282
A19: 10 | C19: Compuestos Quimicos | D19: 2.5.1 | E19: CALIBRADOR CA 125 X 10 CAL COBAS E-411 ROCHE | F19: CAJA | G19: 1 | H19: 18627 | I19: =G19*H19 -> 18627
A20: 11 | C20: Compuestos Quimicos | D20: 2.5.1 | E20: CALIBRADOR CA 15-3 X 10 CAL COBAS E-411 ROCHE | F20: CAJA | G20: 1 | H20: 24270 | I20: =G20*H20 -> 24270
A21: 12 | C21: Compuestos Quimicos | D21: 2.5.1 | E21: CALIBRADOR CA 19-9 X 10 CAL COBAS E-411 ROCHE | F21: CAJA | G21: 1 | H21: 24270 | I21: =G21*H21 -> 24270
... A224: 215 | C224: Compuestos Quimicos | D224: 2.5.1 | E224: TROMBOPLASTINA 10X4ML TIPO HEMOMEDICA | F224: CAJA | G224: 15 | H224: 22000 | I224: =G224*H224 -> 330000
C226: Presentar copia certificada de Resolución de Habilitación expedida por la Subsecretaria de Asistencia en Salud Publica o copia certificada de Certificado de Habilitación de Establecimiento y/o copia certificada de Certificado de Transito Interjurisdiccional emitido por A.N.M.A.T, el que correspondiere conforme a la situación de cada establecimiento cotizante (Laboratorio, Droguería, etc.), en caso de corresponder. Indicar Marca y Numero de Certificado de ANMAT por ítem. VENCIMIENTO DE LOS INSUMOS: UN PLAZO NO MENOR A LOS 06 MESES DE LA FECHA DE RECEPCION
C227: LUGAR Y PLAZO DE ENTREGA: Servicio de Laboratorio Central del HISJB - Avda. Illia y Mariano Moreno - Lunes a Viernes de 08:00 a 12:00 horas - 15 días habiles
C228: PLAZO DE MANTENIMIENTO: 45 DIAS HABILES
B231: Especificidades Item N° :
B233: Descripción técnica
B235: Plazos y lugares de entrega
C236: 15 dias habiles - Servicio de Laboratorio Central del HISJB - Lunes a Viernes de 08:00 a 12:00 horas
B238: Calidad Minima esperada
B240: Mantenimiento
C241: 45 dias habiles
B242: Garantia

Sheet NotaPedido
A1: NOTA DE PEDIDO | J1: N° | K1: 037/2022
A3: JURISDICCIÓN: | D3: ='Necesidades Trimestrales'!C4 -> 40 - Ministerio de Salud
A4: SAF: | D4: ='Necesidades Trimestrales'!C5 -> 23 - Hospital Interzonal San Juan Bautista
A5: UNIDAD EJECUTORA: | D5: 168 - Direccion Asistencial
A6: DEPENDENCIA SOLICITANTE: | D6: Servicio de Laboratorio Central
A7: PERIODO UTILIZACIÓN: | D7: ='Necesidades Trimestrales'!C7 & "° Trimestre - Año " & 'Necesidades Trimestrales'!C6 -> 2° Trimestre - Año 2022
A8: OBJETO: | D8: Adquisición de Reactivos para Laboratorio
A10: Ítem | B10: Codigo Item | C10: DESCRIPCIÓN | H10: Adjunta Detalle Técnico | I10: Unidad Medida | J10: Precio Unitario Estimado | K10: Cantidad Solicitada
A12: 1 | B12: ='Necesidades Trimestrales'!B10 -> 0 | C12: ='Necesidades Trimestrales'!E10 -> ACID WASH SOLUTION 2 X 1800 MLP/COBAS C311 | H12: NO | I12: ='Necesidades Trimestrales'!F10 -> CAJA | J12: ='Necesidades Trimestrales'!H10 -> 41462 | K12: ='Necesidades Trimestrales'!G10 -> 20
A13: 2 | B13: ='Necesidades Trimestrales'!B11 -> 0 | C13: ='Necesidades Trimestrales'!E11 -> AMPOULER PARA COBAS B221 | H13: NO | I13: ='Necesidades Trimestrales'!F11 -> CAJA | J13: ='Necesidades Trimestrales'!H11 -> 7577 | K13: ='Necesidades Trimestrales'!G11 -> 2
A14: 3 | B14: ='Necesidades Trimestrales'!B12 -> 0 | C14: ='Necesidades Trimestrales'!E12 -> ANTICUERPOS ANTITRANSGLUTAMINASA TIPO ORGESTRIOL -ANTI TRANSGLUTAMINASA EN IGA x 96 DET. | H14: NO | I14: ='Necesidades Trimestrales'!F12 -> CAJA | J14: ='Necesidades Trimestrales'!H12 -> 41184 | K14: ='Necesidades Trimestrales'!G12 -> 4
A15: 4 | B15: ='Necesidades Trimestrales'!B13 -> 0 | C15: ='Necesidades Trimestrales'!E13 -> CALIBRADOR ACTH X 10 CAL COBAS E-411 ROCHE | H15: NO | I15: ='Necesidades Trimestrales'!F13 -> CAJA | J15: ='Necesidades Trimestrales'!H13 -> 60026 | K15: ='Necesidades Trimestrales'!G13 -> 1
A16: 5 | B16: ='Necesidades Trimestrales'!B14 -> 0 | C16: ='Necesidades Trimestrales'!E14 -> CALIBRADOR ALFA FETO PROTEINA X 10 CAL COBAS E-411 ROCHE | H16: NO | I16: ='Necesidades Trimestrales'!F14 -> CAJA | J16: ='Necesidades Trimestrales'!H14 -> 15611 | K16: ='Necesidades Trimestrales'!G14 -> 1
A17: 6 | B17: ='Necesidades Trimestrales'!B15 -> 0 | C17: ='Necesidades Trimestrales'!E15 -> CALIBRADOR ANTI SARS COV-2 CUANTITATIVO P/ COBAS E411 x 100 DET | H17: NO | I17: ='Necesidades Trimestrales'!F15 -> CAJA | J17: ='Necesidades Trimestrales'!H15 -> 3900 | K17: ='Necesidades Trimestrales'!G15 -> 1
A18: 7 | B18: ='Necesidades Trimestrales'!B16 -> 0 | C18: ='Necesidades Trimestrales'!E16 -> CALIBRADOR ANTI TIROGLOBULINA X 10 CAL COBAS E-411 ROCHE | H18: NO | I18: ='Necesidades Trimestrales'!F16 -> CAJA | J18: ='Necesidades Trimestrales'!H16 -> 20282 | K18: ='Necesidades Trimestrales'!G16 -> 1
A19: 8 | B19: ='Necesidades Trimestrales'!B17 -> 0 | C19: ='Necesidades Trimestrales'!E17 -> CALIBRADOR ANTI TPO X 10 CAL COBAS E-411 ROCHE | H19: NO | I19: ='Necesidades Trimestrales'!F17 -> CAJA | J19: ='Necesidades Trimestrales'!H17 -> 20282 | K19: ='Necesidades Trimestrales'!G17 -> 3
A20: 9 | B20: ='Necesidades Trimestrales'!B18 -> 0 | C20: ='Necesidades Trimestrales'!E18 -> CALIBRADOR B-CROSS LAP X 10 CAL COBAS E-411 ROCHE | H20: NO | I20: ='Necesidades Trimestrales'!F18 -> CAJA | J20: ='Necesidades Trimestrales'!H18 -> 20282 | K20: ='Necesidades Trimestrales'!G18 -> 1
A21: 10 | B21: ='Necesidades Trimestrales'!B19 -> 0 | C21: ='Necesidades Trimestrales'!E19 -> CALIBRADOR CA 125 X 10 CAL COBAS E-411 ROCHE | H21: NO | I21: ='Necesidades Trimestrales'!F19 -> CAJA | J21: ='Necesidades Trimestrales'!H19 -> 18627 | K21: ='Necesidades Trimestrales'!G19 -> 1
A22: 11 | B22: ='Necesidades Trimestrales'!B20 -> 0 | C22: ='Necesidades Trimestrales'!E20 -> CALIBRADOR CA 15-3 X 10 CAL COBAS E-411 ROCHE | H22: NO | I22: ='Necesidades Trimestrales'!F20 -> CAJA | J22: ='Necesidades Trimestrales'!H20 -> 24270 | K22: ='Necesidades Trimestrales'!G20 -> 1
A23: 12 | B23: ='Necesidades Trimestrales'!B21 -> 0 | C23: ='Necesidades Trimestrales'!E21 -> CALIBRADOR CA 19-9 X 10 CAL COBAS E-411 ROCHE | H23: NO | I23: ='Necesidades Trimestrales'!F21 -> CAJA | J23: ='Necesidades Trimestrales'!H21 -> 24270 | K23: ='Necesidades Trimestrales'!G21 -> 1
... A171: 160 | B171: ='Necesidades Trimestrales'!B169 -> 0 | C171: ='Necesidades Trimestrales'!E169 -> REACTIVO GOT/AST (IFCC) COBAS C-311 ROCHE X 500 DET | H171: NO | I171: ='Necesidades Trimestrales'!F169 -> CASSETTE | J171: ='Necesidades Trimestrales'!H169 -> 10612 | K171: ='Necesidades Trimestrales'!G169 -> 7
A172: 161 | B172: ='Necesidades Trimestrales'!B157 -> 0 | C172: ='Necesidades Trimestrales'!E170 -> REACTIVO GPT/ALT (IFCC) COBAS C - 311 ROCHE X 500 DET | H172: NO | I172: ='Necesidades Trimestrales'!F170 -> CASSETTE | J172: ='Necesidades Trimestrales'!H170 -> 10612 | K172: ='Necesidades Trimestrales'!G170 -> 7
A173: 162 | B173: ='Necesidades Trimestrales'!B158 -> 0 | C173: ='Necesidades Trimestrales'!E171 -> REACTIVO HBsAg G2 reactico para Cobas E411 x 100 DET | H173: NO | I173: ='Necesidades Trimestrales'!F171 -> CAJA | J173: ='Necesidades Trimestrales'!H171 -> 28418 | K173: ='Necesidades Trimestrales'!G171 -> 4
A174: 163 | B174: ='Necesidades Trimestrales'!B159 -> 0 | C174: ='Necesidades Trimestrales'!E172 -> REACTIVO HCG + BETA P COBAS E 411 X 100 DET | H174: NO | I174: ='Necesidades Trimestrales'!F172 -> CAJA | J174: ='Necesidades Trimestrales'!H172 -> 38046 | K174: ='Necesidades Trimestrales'!G172 -> 2
A175: 164 | B175: ='Necesidades Trimestrales'!B160 -> 0 | C175: ='Necesidades Trimestrales'!E173 -> REACTIVO HDL COLESTEROL P/COBAS C311 X 350 DET | H175: NO | I175: ='Necesidades Trimestrales'!F173 -> CASSETTE | J175: ='Necesidades Trimestrales'!H173 -> 22148 | K175: ='Necesidades Trimestrales'!G173 -> 5
A176: 165 | B176: ='Necesidades Trimestrales'!B161 -> 0 | C176: ='Necesidades Trimestrales'!E174 -> REACTIVO HEMOGLOBINA GLICOSILADA P/ COBAS C311 X 150 DET | H176: NO | I176: ='Necesidades Trimestrales'!F174 -> CASSETTE | J176: ='Necesidades Trimestrales'!H174 -> 28418 | K176: ='Necesidades Trimestrales'!G174 -> 7
A177: 166 | B177: ='Necesidades Trimestrales'!B162 -> 0 | C177: ='Necesidades Trimestrales'!E175 -> REACTIVO HEMOLISANTE P/COBAS C311 HBAIC2 X 800 DET | H177: NO | I177: ='Necesidades Trimestrales'!F175 -> CASSETTE | J177: ='Necesidades Trimestrales'!H175 -> 5426 | K177: ='Necesidades Trimestrales'!G175 -> 3
A178: 167 | B178: ='Necesidades Trimestrales'!B163 -> 0 | C178: ='Necesidades Trimestrales'!E176 -> REACTIVO HIERRO COBAS C-311 ROCHE X 200 DET | H178: NO | I178: ='Necesidades Trimestrales'!F176 -> CASSETTE | J178: ='Necesidades Trimestrales'!H176 -> 2504 | K178: ='Necesidades Trimestrales'!G176 -> 3
A179: 168 | B179: ='Necesidades Trimestrales'!B164 -> 0 | C179: ='Necesidades Trimestrales'!E177 -> REACTIVO HTLV P/COBAS E411 X 100 DET | H179: NO | I179: ='Necesidades Trimestrales'!F177 -> CAJA | J179: ='Necesidades Trimestrales'!H177 -> 53272.3 | K179: ='Necesidades Trimestrales'!G177 -> 1
A180: 169 | B180: ='Necesidades Trimestrales'!B165 -> 0 | C180: ='Necesidades Trimestrales'!E178 -> REACTIVO IGA COBAS ROCHE C311 X 150 DET | H180: NO | I180: ='Necesidades Trimestrales'!F178 -> CASSETTE | J180: ='Necesidades Trimestrales'!H178 -> 23265 | K180: ='Necesidades Trimestrales'!G178 -> 2
A181: 170 | B181: ='Necesidades Trimestrales'!B149 -> 0 | C181: ='Necesidades Trimestrales'!E179 -> REACTIVO IGG COBAS ROCHE C311 X 150 DET | H181: NO | I181: ='Necesidades Trimestrales'!F179 -> CASSETTE | J181: ='Necesidades Trimestrales'!H179 -> 23265 | K181: ='Necesidades Trimestrales'!G179 -> 3
A182: 171 | B182: ='Necesidades Trimestrales'!B150 -> 0 | C182: ='Necesidades Trimestrales'!E180 -> REACTIVO IGM P/ COBAS C311 X 150 DET | H182: NO | I182: ='Necesidades Trimestrales'!F180 -> CASSETTE | J182: ='Necesidades Trimestrales'!H180 -> 23265 | K182: ='Necesidades Trimestrales'!G180 -> 2
A183: 172 | B183: ='Necesidades Trimestrales'!B151 -> 0 | C183: ='Necesidades Trimestrales'!E181 -> REACTIVO INMUNOGLOBULINA IG E P COBAS E 411 X 100 DET ROCHE | H183: NO | I183: ='Necesidades Trimestrales'!F181 -> CAJA | J183: ='Necesidades Trimestrales'!H181 -> 21608 | K183: ='Necesidades Trimestrales'!G181 -> 2
A184: 173 | B184: ='Necesidades Trimestrales'!B152 -> 0 | C184: ='Necesidades Trimestrales'!E182 -> REACTIVO INSULINA COBAS E-411 ROCHE X 100 DET | H184: NO | I184: ='Necesidades Trimestrales'!F182 -> CAJA | J184: ='Necesidades Trimestrales'!H182 -> 28621 | K184: ='Necesidades Trimestrales'!G182 -> 6
A185: 174 | B185: ='Necesidades Trimestrales'!B153 -> 0 | C185: ='Necesidades Trimestrales'!E183 -> REACTIVO LDH OPTIMIZADA COBAS C-311 ROCHE X 300 DET | H185: NO | I185: ='Necesidades Trimestrales'!F183 -> CASSETTE | J185: ='Necesidades Trimestrales'!H183 -> 14258 | K185: ='Necesidades Trimestrales'!G183 -> 6
A186: 175 | B186: ='Necesidades Trimestrales'!B154 -> 0 | C186: ='Necesidades Trimestrales'!E184 -> REACTIVO LDL COLESTEROL P/COBAS C311 x 200 DET | H186: NO | I186: ='Necesidades Trimestrales'!F184 -> CASSETTE | J186: ='Necesidades Trimestrales'!H184 -> 19924 | K186: ='Necesidades Trimestrales'!G184 -> 7
A187: 176 | B187: ='Necesidades Trimestrales'!B155 -> 0 | C187: ='Necesidades Trimestrales'!E185 -> REACTIVO LH COBAS E-411 ROCHE X 100 DET | H187: NO | I187: ='Necesidades Trimestrales'!F185 -> CAJA | J187: ='Necesidades Trimestrales'!H185 -> 22210 | K187: ='Necesidades Trimestrales'!G185 -> 3
A188: 177 | B188: ='Necesidades Trimestrales'!B156 -> 0 | C188: ='Necesidades Trimestrales'!E186 -> REACTIVO LIPASA COBAS C-311 ROCHE X 200 DET | H188: NO | I188: ='Necesidades Trimestrales'!F186 -> CASSETTE | J188: ='Necesidades Trimestrales'!H186 -> 12671 | K188: ='Necesidades Trimestrales'!G186 -> 8
A189: 178 | B189: ='Necesidades Trimestrales'!B157 -> 0 | C189: ='Necesidades Trimestrales'!E187 -> REACTIVO MAGNESIO COBAS C-311 ROCHE X 175 DET | H189: NO | I189: ='Necesidades Trimestrales'!F187 -> CASSETTE | J189: ='Necesidades Trimestrales'!H187 -> 5539 | K189: ='Necesidades Trimestrales'!G187 -> 2
A190: 179 | B190: ='Necesidades Trimestrales'!B158 -> 0 | C190: ='Necesidades Trimestrales'!E188 -> REACTIVO PHYFILIS TREPONEMICO P/COBAS E411 X100 DET | H190: NO | I190: ='Necesidades Trimestrales'!F188 -> CAJA | J190: ='Necesidades Trimestrales'!H188 -> 55034 | K190: ='Necesidades Trimestrales'!G188 -> 1
...

Sheet Autor Gastar
A1: EJERCICIO: | D1: ='Necesidades Trimestrales'!C6 -> 2022 | P1: AUTORIZACION PARA GASTAR
A4: JURISDICCIÓN: | G4: =NotaPedido!D3 -> 40 - Ministerio de Salud
A5: SAF: | G5: =NotaPedido!D4 -> 23 - Hospital Interzonal San Juan Bautista
A6: UNIDAD EJECUTORA: | G6: =NotaPedido!D5 -> 168 - Direccion Asistencial
A7: DEPENDENCIA SOLICITANTE: | G7: =NotaPedido!D6 -> Servicio de Laboratorio Central
A8: AUTORIZACIÓN:
A9: Señor Jefe de Servicio Administrativo Financiero:
A10: ="Autorizo la realización de los trámites correspondientes, a fin de proveer a este Organismo los bienes y/o servicios que se detallan en Nota de Pedido N° " & NotaPedido!K1&", afectando la erogación resultante a los créditos presupuestarios aprobados a favor de esta Unidad Ejecutora, conforme al siguiente detalle:" -> Autorizo la realización de los trámites correspondientes, a fin de proveer a este Organismo los bienes y/o servicios que se detallan en Nota de Pedido N° 037/2022, afectando la erogación resultante a los créditos presupuestarios aprobados a favor de esta Unidad Ejecutora, conforme al siguiente detalle:
A12: IMPUTACIÓN PRESUPUESTARIA
A13: CÓDIGO | O13: DENOMINACIÓN DE LA PARTIDA PRESUPUESTARIA | Q13: IMPORTE
A14: PR | B14: SB | C14: PY | D14: AC | E14: OB | F14: UG | G14: FIN | H14: FUN | I14: I | J14: P | K14: P | L14: SubP | M14: M | N14: FF
A15: 33 | D15: 2 | F15: 4901 | G15: 3 | H15: 3.1 | I15: 2 | J15: 5 | K15: 1 | M15: 1 | N15: 1.1 | O15: Compuestos Quimicos | Q15: 19995819
A23: TOTAL DE PESOS: DIECINUEVE MILLONES NOVECIENTOS NOVENTA Y CINCO MIL OCHOCIENTOS DIECINUEVE CON 30/100.- | Q23: =SUM(Q15:Q22) -> 19995819
A25: JUSTIFICACIÓN:
A26: ="Para la "& NotaPedido!D8 &"para ser destinados al "& NotaPedido!D6 &"del HISJB del Ministerio de Salud." -> Para la Adquisición de Reactivos para Laboratorio para ser destinados al Servicio de Laboratorio Central del HISJB del Ministerio de Salud.
