Workbook

Sheet Necesidades Trimestrales
B2: Pedido de Necesidades Trimestrales
A4: JURISDICCION: | C4: 40 - Ministerio de Salud
A5: SAF N°: | C5: 23 - Hospital Interzonal San Juan Bautista
A6: EJERCICIO: | C6: 2021
A7: TRIMESTRE: | C7: 1
A9: ID | B9: CODIGO ITEM | C9: RUBRO DE COMPRA | D9: I.P.P. | E9: DESCRIPCION | F9: UNIDAD DE MEDIDA | G9: CANTIDAD | H9: PRECIO UNITARIO ESTIMADO | I9: IMPORTE TOTAL ESTIMADO
A10: 1 | B10: 2.1.1-439.60 | C10: ALIMENTOS | D10: 2.1.1 | E10: ACEITES COMESTIBLES; TIPO: MEZCLA, PRESENTACION: ENVASE X 900 CM3, MATERIAL ENVASE: PLASTICO 1 (PET), ELEM. TRANSPORTE: SIN, MATERIAL ELEM. TRANSPORTE : SIN, LIBRE DE GLUTEN: SI | F10: BOTELLA | G10: 250 | H10: =98.72*1.2 -> 118.464 | I10: =G10*H10 -> 29616
A11: 2 | B11: 2.1.1-481.38 | C11: ALIMENTOS | D11: 2.1.1 | E11: AZUCARES; TIPO: "A" COMUN, ESTADO: MOLIDA, PESO: 1 Kg, MATERIAL ENVASE: PLASTICO, CERTIFICADO FORESTAL (GFS): SIN, ELEM. TRANSPORTE: SIN, MATERIAL ELEM. TRANSPORTE: SIN | F11: PAQUETES | G11: 400 | H11: =60*1.2 -> 72 | I11: =G11*H11 -> 28800
A12: 3 | B12: 2.1.1-705.116 | C12: ALIMENTOS | D12: 2.1.1 | E12: LECHE; ESTADO: LIQUIDO, TIPO: DESCREMADA, PROCESO: LARGA VIDA, AGREGADO: VITAMINAS A Y D, PRESENTACION: ENVASE X 1 L, MATERIAL ENVASE: PLASTICO, ELEM. TRANSPORTE: SIN, MATERIAL ELEM. TRANSPORTE: SIN, CERTIFICADO FORESTAL (GFS): SIN, LIBRE DE GLUTEN: SIN VALOR | F12: LITROS | G12: 600 | H12: =59.98*1.2 -> 71.976 | I12: =G12*H12 -> 43185.6
A13: 4 | B13: 2.1.1-2868.55 | C13: ALIMENTOS | D13: 2.1.1 | E13: FIDEOS SECOS; VARIEDAD: TALLARIN, RELLENO: SIN, PRESENTACION: ENVASE X 500 GR, MATERIAL ENVASE: PLASTICO 1 (PET), ELEM. TRANSPORTE: SIN, MATERIAL ELEM. TRANSPORTE: SIN, CERTIFICADO FORESTAL (GFS): SIN, LIBRE DE GLUTEN: NO | F13: PAQUETES | G13: 50 | H13: =38.88*1.2 -> 46.656 | I13: =G13*H13 -> 2332.8
A14: 5 | B14: 2.1.1-511.8 | C14: ALIMENTOS | D14: 2.1.1 | E14: TE; SAQUITOS 2G P/CAJA: 50, PESO: SIN VALOR, TIPO: SIN VALOR, PRESENTACION: EN SAQUITOS | F14: CAJAS | G14: 650 | H14: =(135.01/2)*1.2 -> 81.006 | I14: =G14*H14 -> 52653.9
A15: 6 | B15: 2.1.1-454.25 | C15: ALIMENTOS | D15: 2.1.1 | E15: YERBAS; PALO: CON, PESO: 1 Kg, MATERIAL ENVASE : PAPEL, CERTIFICADO FORESTAL (GFS): CON, ELEM. TRANSPORTE: SIN, MATERIAL ELEM. TRANSPORTE: SIN, LIBRE DE GLUTEN: SI | F15: PAQUETES | G15: 25 | H15: =189*1.2 -> 226.8 | I15: =G15*H15 -> 5670
A16: 7 | B16: 2.1.1-2126.13 | C16: ALIMENTOS | D16: 2.1.1 | E16: SEMOLAS; TIPO: VITINA, PRESENTACION: BOLSA, PESO: 500 GR, MATERIAL ENVASE: PLASTICO 1 (PET), CERTICADO FORESTAL (GFS): SIN, LIBRE DE GLUTEN: NO | F16: PAQUETES | G16: 7 | H16: =85*1.2 -> 102 | I16: =G16*H16 -> 714
A17: 8 | B17: 2.1.1-2868.53 | C17: ALIMENTOS | D17: 2.1.1 | E17: FIDEOS SECOS; VARIEDAD: TIRABUZON, RELLENO: SIN, PRESENTACION: ENVASE X 500 GR, MATERIAL ENVASE: PLASTICO 1 (PET), ELEM. TRANSPORTE: SIN, MATERIAL ELEM. TRANSPORTE: SIN, CERTIFICADO FORESTAL (GFS): SIN, LIBRE DE GLUTEN: NO | F17: PAQUETES | G17: 42 | H17: =38.88*1.2 -> 46.656 | I17: =G17*H17 -> 1959.552
A18: 9 | B18: 2.1.1-613.9 | C18: ALIMENTOS | D18: 2.1.1 | E18: FECULA DE MAIZ; ENVASE: BOLSA, PESO: 500 GR, LIBRE DE GLUTEN: SI | F18: PAQUETES | G18: 17 | H18: =78.99*1.2 -> 94.788 | I18: =G18*H18 -> 1611.396
A19: 10 | B19: 2.1.1-6547.57 | C19: ALIMENTOS | D19: 2.1.1 | E19: LEGUMBRES; VARIEDAD: LENTEJAS SECAS, ESTADO: SECO, PRESENTACION: BOLSA, PESO: 500 GR | F19: PAQUETES | G19: 13 | H19: =98.37*1.2 -> 118.044 | I19: =G19*H19 -> 1534.572
A20: 11 | B20: 2.1.1-514.2 | C20: ALIMENTOS | D20: 2.1.1 | E20: SAL DE MESA; CONSISTENCIA: FINA, PESO: 500 GR, TIPO: SIN VALOR, ENVASE: PAQUETE | F20: PAQUETES | G20: 33 | H20: =37.9*1.2 -> 45.48 | I20: =G20*H20 -> 1500.84
A21: 12 | B21: 2.1.1-514.11 | C21: ALIMENTOS | D21: 2.1.1 | E21: SAL DE MESA; CONSISTENCIA: GRUESA, PESO: 50 Kg, TIPO: SIN VALOR, ENVASE: BOLSA | F21: BOLSAS | G21: 5 | H21: =(43.35*50)*1.2 -> 2601 | I21: =G21*H21 -> 13005
A22: 13 | B22: 2.1.1-482.61 | C22: ALIMENTOS | D22: 2.1.1 | E22: HARINAS; TIPO: LEUDANTE, PRESENTACION: ENVASE X 1 Kg, MATERIAL ENVASE: PAPEL, CERTICADO FORESTAL (GFS): SIN, ELEM. TRANSPORTE: PALLET RETORNABLE, MATERIAL ELEM. TRANSPORTE: MADERA | F22: PAQUETES | G22: 17 | H22: =52.15*1.2 -> 62.58 | I22: =G22*H22 -> 1063.86
A23: 14 | B23: 2.1.1-482.69 | C23: ALIMENTOS | D23: 2.1.1 | E23: HARINAS; TIPO: MAIZ, PRESENTACION: ENVASE X 1 Kg, MATERIAL ENVASE: PAPEL, CERTICADO FORESTAL (GFS): SIN, ELEM. TRANSPORTE: SIN, MATERIAL ELEM. TRANSPORTE: SIN, LIBRE DE GLUTEN: NO | F23: PAQUETES | G23: 10 | H23: =50.02*1.2 -> 60.024 | I23: =G23*H23 -> 600.24
A24: 15 | B24: 2.1.1-706.4 | C24: ALIMENTOS | D24: 2.1.1 | E24: MATE COCIDO; ENVASE: CAJA CARTON, PESO X SAQ.: 3, PRESENTACION: ENSOBRADO, SAQUITOS P/CAJA: 50 | F24: CAJAS | G24: 25 | H24: =171.36*1.2 -> 205.632 | I24: =G24*H24 -> 5140.8
A25: 16 | B25: 2.1.1-595.2 | C25: ALIMENTOS | D25: 2.1.1 | E25: EDULCORANTES; PRESENTACION: LIQUIDO, ENVASE: BOTELLA PLASTICA, CONTENIDO: 500 CM3 | F25: BOTELLAS | G25: 17 | H25: =145*1.2 -> 174 | I25: =G25*H25 -> 2958
A26: 17 | B26: 2.1.1-2868.86 | C26: ALIMENTOS | D26: 2.1.1 | E26: FIDEOS SECOS; VARIEDAD: SPAGHETTI AL HUEVO, RELLENO: SIN, PRESENTACION: PAQUETE X 500 GR, MATERIAL ENVASE: PLASTICO 1 (PET), ELEM. TRANSPORTE: SIN, MATERIAL ELEM. TRANSPORTE: SIN, CERTIFICADO FORESTAL (GFS): SIN, LIBRE DE GLUTEN: NO | F26: PAQUETES | G26: 50 | H26: =55.8*1.2 -> 66.96 | I26: =G26*H26 -> 3348
A27: 18 | B27: 2.1.1-482.80 | C27: ALIMENTOS | D27: 2.1.1 | E27: HARINAS; TIPO: DE TRIGO 000, PRESENTACION: ENVASE X 1 Kg, MATERIAL ENVASE: PAPEL, CERTICADO FORESTAL (GFS): SIN, ELEM. TRANSPORTE: SIN, MATERIAL ELEM. TRANSPORTE: SIN, LIBRE DE GLUTEN: NO | F27: PAQUETES | G27: 10 | H27: =40.44*1.2 -> 48.528 | I27: =G27*H27 -> 485.28
A28: 19 | B28: 2.1.1-435.38 | C28: ALIMENTOS | D28: 2.1.1 | E28: ARROZ; TIPO GRANO: DOBLE, TIPO: BLANCO, PROCESO: PARBOLIZADO, PRESENTACION: ENVASE X 1 Kg, MATERIAL ENVASE: CARTON, CERTIFICADO FORESTAL (GFS): SIN, ELEM. TRANSPORTE: SIN, MATERIAL ELEM. TRANSPORTE: SIN | F28: PAQUETES | G28: 117 | H28: =125*1.2 -> 150 | I28: =G28*H28 -> 17550
A29: 20 | B29: 2.1.1-510.5 | C29: ALIMENTOS | D29: 2.1.1 | E29: GELATINAS; ENVASE: CAJA DE CARTON, PESO: 30 GR, TIPO: BAJAS CALORIAS, SABOR: FRUTILLA | F29: CAJAS | G29: 133 | H29: =49.89*1.2 -> 59.868 | I29: =G29*H29 -> 7962.444
A30: 21 | B30: 2.1.1-435.50 | C30: ALIMENTOS | D30: 2.1.1 | E30: ARROZ; TIPO GRANO: ENTERO, TIPO: BLANCO, PROCESO: FORTIFICADO, PRESENTACION: ENVASE X 1 Kg, MATERIAL ENVASE: PLASTICO 1 (PET), CERTIFICADO FORESTAL (GFS): SIN, ELEM. TRANSPORTE: SIN, MATERIAL ELEM. TRANSPORTE: SIN, LIBRE DE GLUTEN: NO | F30: PAQUETES | G30: 17 | H30: =67.68*1.2 -> 81.216 | I30: =G30*H30 -> 1380.672
A31: 22 | B31: 2.1.1-517.28 | C31: ALIMENTOS | D31: 2.1.1 | E31: POSTRES; SABOR: CHOCOLATE, ENVASE: CAJA DE CARTON, TIPO: DIETETICO, PESO: 30 GR, ESTADO PREPARACION: CON COCCION | F31: CAJAS | G31: 20 | H31: =65*1.2 -> 78 | I31: =G31*H31 -> 1560
A32: 23 | B32: 2.1.1-517.86 | C32: ALIMENTOS | D32: 2.1.1 | E32: POSTRES; ESTADO PREPARACION: CON COCCION, TIPO: POLVO, ENVASE: CAJA DE CARTON, PESO: 80 GR, SABOR: VAINILLA, LIBRE DE GLUTEN: SI | F32: CAJAS | G32: 13 | H32: =32.94*1.2 -> 39.528 | I32: =G32*H32 -> 513.864
A33: 24 | B33: 2.1.1-5917.8 | C33: ALIMENTOS | D33: 2.1.1 | E33: CEREALES; TIPO: TRIGO BURGOL, PRESENTACION: ENVASE X 1 Kg | F33: PAQUETES | G33: 4 | H33: 95 | I33: =G33*H33 -> 380
A34: 25 | B34: 2.1.1-6539.114 | C34: ALIMENTOS | D34: 2.1.1 | E34: FRUTAS; VARIEDAD: CIRUELA ( SIN CAROZO ), ESTADO: DESECADA, PRESENTACION: ENVASE X 10 Kg, PESO: 10 Kg | F34: ENVASE | G34: 1 | H34: 5600 | I34: =G34*H34 -> 5600
A35: 26 | B35: 2.1.1-6539.178 | C35: ALIMENTOS | D35: 2.1.1 | E35: FRUTAS; VARIEDAD: DURAZNO ( SIN CAROZO ), ESTADO: DESECADA, PRESENTACION: ENVASE X 5 Kg, ELEM. TRANSPORTE: SIN, MATERIAL ELEM. TRANSPORTE: SIN | F35: ENVASE | G35: 1 | H35: 3400 | I35: =G35*H35 -> 3400
A36: 27 | B36: 2.1.1-513.9 | C36: ALIMENTOS | D36: 2.1.1 | E36: FLANES; PESO: 60 GR, ENVASE: CAJA CARTON, ESTADO PREPARACION: CON COCCION, SABOR: VAINILLA, TIPO: SIN VALOR, PRESENTACION: 60 GR | F36: CAJAS | G36: 67 | H36: =35.53*1.2 -> 42.636 | I36: =G36*H36 -> 2856.612
A37: 28 | B37: 2.1.1-519.27 | C37: ALIMENTOS | D37: 2.1.1 | E37: VINAGRES; TIPO: VINO, PRESENTACION: ENVASE X 1 L, MATERIAL ENVASE: PLASTICO 1 (PET), LIBRE DE GLUTEN: NO | F37: BOTELLA | G37: 7 | H37: =82*1.2 -> 98.4 | I37: =G37*H37 -> 688.8
A38: 29 | B38: 2.1.1-2124.3 | C38: ALIMENTOS | D38: 2.1.1 | E38: AVENAS; TIPO: ARROLLADA, ESTADO: NATURAL, PRESENTACION: BOLSA, PESO: 1 Kg | F38: PAQUETES | G38: 4 | H38: =170*1.2 -> 204 | I38: =G38*H38 -> 816
A39: 30 | B39: 2.1.1-6547.84 | C39: ALIMENTOS | D39: 2.1.1 | E39: LEGUMBRES; VARIEDAD: ARVEJAS, ESTADO: CONSERVA, PRESENTACION: LATA, PESO: 350 GR, MATERIAL ENVASE: METAL, ELEM. TRANSPORTE: SIN, MATERIAL ELEM. TRANSPORTE: SIN, LIBRE DE GLUTEN: NO | F39: LATAS | G39: 100 | H39: =30.1*1.2 -> 36.12 | I39: =G39*H39 -> 3612
A40: 31 | B40: 2.1.1-708.43 | C40: ALIMENTOS | D40: 2.1.1 | E40: CONSERVAS PESCADO Y FRUTOS MAR; TIPO: ATUN, ESTADO: AL NATURAL, PESO: 170 GR, ENVASE: LATA, ELEM. TRANSPORTE: SIN, MATERIAL ELEM. TRANSPORTE: SIN | F40: LATAS | G40: 33 | H40: =135*1.2 -> 162 | I40: =G40*H40 -> 5346
A41: 32 | B41: 2.1.1-6546.183 | C41: ALIMENTOS | D41: 2.1.1 | E41: VERDURAS Y HORTALIZAS; VARIEDAD: TOMATE PERITA, ESTADO: NATURAL, PRESENTACION: LATA, PESO: 380 GR | F41: LATAS | G41: 100 | H41: =57.32*1.2 -> 68.784 | I41: =G41*H41 -> 6878.4
A42: 33 | B42: 2.1.1-6539.46 | C42: ALIMENTOS | D42: 2.1.1 | E42: FRUTAS; VARIEDAD: DURAZNO, ESTADO: CONSERVA, PRESENTACION: ENVASE X 800 GR, PESO: 800 GR | F42: LATAS | G42: 200 | H42: =165*1.2 -> 198 | I42: =G42*H42 -> 39600
A43: 34 | B43: 2.1.1-597.41 | C43: ALIMENTOS | D43: 2.1.1 | E43: CONSERVAS DE FRUTAS; VARIEDAD: COCTEL, ENVASE: LATA, PESO: 800 GR, ELEM. TRANSPORTE: SIN, MATERIAL ELEM. TRANSPORTE: SIN, LIBRE DE GLUTEN: NO | F43: LATAS | G43: 200 | H43: =210*1.2 -> 252 | I43: =G43*H43 -> 50400
...

Sheet NotaPedido
A1: NOTA DE PEDIDO | J1: N° | K1: 366 - 2020
A3: JURISDICCIÓN: | D3: ='Necesidades Trimestrales'!C4 -> 40 - Ministerio de Salud
A4: SAF: | D4: ='Necesidades Trimestrales'!C5 -> 23 - Hospital Interzonal San Juan Bautista
A5: UNIDAD EJECUTORA: | D5: 168 - Direccion Asistencial
A6: DEPENDENCIA SOLICITANTE: | D6: Servicio de Nutrición
A7: PERIODO UTILIZACIÓN: | D7: ='Necesidades Trimestrales'!C7 & "° Trimestre - Año " & 'Necesidades Trimestrales'!C6 -> 1° Trimestre - Año 2021
A8: OBJETO: | D8: Adquisición de Alimentos Perecederos y no Perecederos
A10: Ítem | B10: Codigo Item | C10: DESCRIPCIÓN | H10: Adjunta Detalle Técnico | I10: Unidad Medida | J10: Precio Unitario Estimado | K10: Cantidad Solicitada
A12: 1 | B12: ='Necesidades Trimestrales'!B10 -> 2.1.1-439.60 | C12: ='Necesidades Trimestrales'!E10 -> ACEITES COMESTIBLES; TIPO: MEZCLA, PRESENTACION: ENVASE X 900 CM3, MATERIAL ENVASE: PLASTICO 1 (PET), ELEM. TRANSPORTE: SIN, MATERIAL ELEM. TRANSPORTE : SIN, LIBRE DE GLUTEN: SI | H12: NO | I12: ='Necesidades Trimestrales'!F10 -> BOTELLA | J12: ='Necesidades Trimestrales'!H10 -> 118.464 | K12: ='Necesidades Trimestrales'!G10 -> 250
A13: 2 | B13: ='Necesidades Trimestrales'!B11 -> 2.1.1-481.38 | C13: ='Necesidades Trimestrales'!E11 -> AZUCARES; TIPO: "A" COMUN, ESTADO: MOLIDA, PESO: 1 Kg, MATERIAL ENVASE: PLASTICO, CERTIFICADO FORESTAL (GFS): SIN, ELEM. TRANSPORTE: SIN, MATERIAL ELEM. TRANSPORTE: SIN | H13: NO | I13: ='Necesidades Trimestrales'!F11 -> PAQUETES | J13: ='Necesidades Trimestrales'!H11 -> 72 | K13: ='Necesidades Trimestrales'!G11 -> 400
A14: 3 | B14: ='Necesidades Trimestrales'!B12 -> 2.1.1-705.116 | C14: ='Necesidades Trimestrales'!E12 -> LECHE; ESTADO: LIQUIDO, TIPO: DESCREMADA, PROCESO: LARGA VIDA, AGREGADO: VITAMINAS A Y D, PRESENTACION: ENVASE X 1 L, MATERIAL ENVASE: PLASTICO, ELEM. TRANSPORTE: SIN, MATERIAL ELEM. TRANSPORTE: SIN, CERTIFICADO FORESTAL (GFS): SIN, LIBRE DE GLUTEN: SIN VALOR | H14: NO | I14: ='Necesidades Trimestrales'!F12 -> LITROS | J14: ='Necesidades Trimestrales'!H12 -> 71.976 | K14: ='Necesidades Trimestrales'!G12 -> 600
A15: 4 | B15: ='Necesidades Trimestrales'!B13 -> 2.1.1-2868.55 | C15: ='Necesidades Trimestrales'!E13 -> FIDEOS SECOS; VARIEDAD: TALLARIN, RELLENO: SIN, PRESENTACION: ENVASE X 500 GR, MATERIAL ENVASE: PLASTICO 1 (PET), ELEM. TRANSPORTE: SIN, MATERIAL ELEM. TRANSPORTE: SIN, CERTIFICADO FORESTAL (GFS): SIN, LIBRE DE GLUTEN: NO | H15: NO | I15: ='Necesidades Trimestrales'!F13 -> PAQUETES | J15: ='Necesidades Trimestrales'!H13 -> 46.656 | K15: ='Necesidades Trimestrales'!G13 -> 50
A16: 5 | B16: ='Necesidades Trimestrales'!B14 -> 2.1.1-511.8 | C16: ='Necesidades Trimestrales'!E14 -> TE; SAQUITOS 2G P/CAJA: 50, PESO: SIN VALOR, TIPO: SIN VALOR, PRESENTACION: EN SAQUITOS | H16: NO | I16: ='Necesidades Trimestrales'!F14 -> CAJAS | J16: ='Necesidades Trimestrales'!H14 -> 81.006 | K16: ='Necesidades Trimestrales'!G14 -> 650
A17: 6 | B17: ='Necesidades Trimestrales'!B15 -> 2.1.1-454.25 | C17: ='Necesidades Trimestrales'!E15 -> YERBAS; PALO: CON, PESO: 1 Kg, MATERIAL ENVASE : PAPEL, CERTIFICADO FORESTAL (GFS): CON, ELEM. TRANSPORTE: SIN, MATERIAL ELEM. TRANSPORTE: SIN, LIBRE DE GLUTEN: SI | H17: NO | I17: ='Necesidades Trimestrales'!F15 -> PAQUETES | J17: ='Necesidades Trimestrales'!H15 -> 226.8 | K17: ='Necesidades Trimestrales'!G15 -> 25
A18: 7 | B18: ='Necesidades Trimestrales'!B16 -> 2.1.1-2126.13 | C18: ='Necesidades Trimestrales'!E16 -> SEMOLAS; TIPO: VITINA, PRESENTACION: BOLSA, PESO: 500 GR, MATERIAL ENVASE: PLASTICO 1 (PET), CERTICADO FORESTAL (GFS): SIN, LIBRE DE GLUTEN: NO | H18: NO | I18: ='Necesidades Trimestrales'!F16 -> PAQUETES | J18: ='Necesidades Trimestrales'!H16 -> 102 | K18: ='Necesidades Trimestrales'!G16 -> 7
A19: 8 | B19: ='Necesidades Trimestrales'!B17 -> 2.1.1-2868.53 | C19: ='Necesidades Trimestrales'!E17 -> FIDEOS SECOS; VARIEDAD: TIRABUZON, RELLENO: SIN, PRESENTACION: ENVASE X 500 GR, MATERIAL ENVASE: PLASTICO 1 (PET), ELEM. TRANSPORTE: SIN, MATERIAL ELEM. TRANSPORTE: SIN, CERTIFICADO FORESTAL (GFS): SIN, LIBRE DE GLUTEN: NO | H19: NO | I19: ='Necesidades Trimestrales'!F17 -> PAQUETES | J19: ='Necesidades Trimestrales'!H17 -> 46.656 | K19: ='Necesidades Trimestrales'!G17 -> 42
A20: 9 | B20: ='Necesidades Trimestrales'!B18 -> 2.1.1-613.9 | C20: ='Necesidades Trimestrales'!E18 -> FECULA DE MAIZ; ENVASE: BOLSA, PESO: 500 GR, LIBRE DE GLUTEN: SI | H20: NO | I20: ='Necesidades Trimestrales'!F18 -> PAQUETES | J20: ='Necesidades Trimestrales'!H18 -> 94.788 | K20: ='Necesidades Trimestrales'!G18 -> 17
A21: 10 | B21: ='Necesidades Trimestrales'!B19 -> 2.1.1-6547.57 | C21: ='Necesidades Trimestrales'!E19 -> LEGUMBRES; VARIEDAD: LENTEJAS SECAS, ESTADO: SECO, PRESENTACION: BOLSA, PESO: 500 GR | H21: NO | I21: ='Necesidades Trimestrales'!F19 -> PAQUETES | J21: ='Necesidades Trimestrales'!H19 -> 118.044 | K21: ='Necesidades Trimestrales'!G19 -> 13
A22: 11 | B22: ='Necesidades Trimestrales'!B20 -> 2.1.1-514.2 | C22: ='Necesidades Trimestrales'!E20 -> SAL DE MESA; CONSISTENCIA: FINA, PESO: 500 GR, TIPO: SIN VALOR, ENVASE: PAQUETE | H22: NO | I22: ='Necesidades Trimestrales'!F20 -> PAQUETES | J22: ='Necesidades Trimestrales'!H20 -> 45.48 | K22: ='Necesidades Trimestrales'!G20 -> 33
A23: 12 | B23: ='Necesidades Trimestrales'!B21 -> 2.1.1-514.11 | C23: ='Necesidades Trimestrales'!E21 -> SAL DE MESA; CONSISTENCIA: GRUESA, PESO: 50 Kg, TIPO: SIN VALOR, ENVASE: BOLSA | H23: NO | I23: ='Necesidades Trimestrales'!F21 -> BOLSAS | J23: ='Necesidades Trimestrales'!H21 -> 2601 | K23: ='Necesidades Trimestrales'!G21 -> 5
... A102: 91 | B102: ='Necesidades Trimestrales'!B100 -> 2.1.1-455.16 | C102: ='Necesidades Trimestrales'!E100 -> DULCE DE LECHE; ENVASE: DE CARTON, CAPACIDAD: 5000 GR, TIPO: DE REPOSTERIA, PRESENTACION: ENVASE DE CARTON X 5 Kg | H102: NO | I102: ='Necesidades Trimestrales'!F100 -> UNIDAD | J102: ='Necesidades Trimestrales'!H100 -> 1068.54 | K102: ='Necesidades Trimestrales'!G100 -> 1
A103: Costo total estimado: dos millones doscientos ochenta y siete mil ciento noventa y nueve con 76/100.------------- | J103: =SUMPRODUCT(J12:J102,K12:K102) -> 2287199.8

Sheet Autor Gastar
A1: EJERCICIO: | D1: ='Necesidades Trimestrales'!C6 -> 2021 | P1: AUTORIZACION PARA GASTAR
A4: JURISDICCIÓN: | G4: =NotaPedido!D3 -> 40 - Ministerio de Salud
A5: SAF: | G5: =NotaPedido!D4 -> 23 - Hospital Interzonal San Juan Bautista
A6: UNIDAD EJECUTORA: | G6: =NotaPedido!D5 -> 168 - Direccion Asistencial
A7: DEPENDENCIA SOLICITANTE: | G7: =NotaPedido!D6 -> Servicio de Nutrición
A8: AUTORIZACIÓN:
A9: Señor Jefe de Servicio Administrativo Financiero:
A10: ="Autorizo la realización de los trámites correspondientes, a fin de proveer a este Organismo los bienes y/o servicios que se detallan en Nota de Pedido N° " & NotaPedido!K1&", afectando la erogación resultante a los créditos presupuestarios aprobados a favor de esta Unidad Ejecutora, conforme al siguiente detalle:" -> Autorizo la realización de los trámites correspondientes, a fin de proveer a este Organismo los bienes y/o servicios que se detallan en Nota de Pedido N° 366 - 2020, afectando la erogación resultante a los créditos presupuestarios aprobados a favor de esta Unidad Ejecutora, conforme al siguiente detalle:
A12: IMPUTACIÓN PRESUPUESTARIA
A13: CÓDIGO | O13: DENOMINACIÓN DE LA PARTIDA PRESUPUESTARIA | Q13: IMPORTE
A14: PR | B14: SB | C14: PY | D14: AC | E14: OB | F14: UG | G14: FIN | H14: FUN | I14: I | J14: P | K14: P | L14: SubP | M14: M | N14: FF
A15: 33 | D15: 2 | F15: 4901 | G15: 3 | H15: 3.1 | I15: 2 | J15: 1 | K15: 1 | M15: 1 | N15: 1.1 | O15: Alimentos para Personas | Q15: =+NotaPedido!J103 -> 2287199.8
A23: TOTAL DE PESOS: DOS MILLONES DOSCIENTOS OCHENTA Y SIETE MIL CIENTO NOVENTA Y NUEVE CON 76/100.-- | Q23: =SUM(Q15:Q22) -> 2287199.8
A25: JUSTIFICACIÓN:
A26: ="Para la "& NotaPedido!D8 &" para ser destinados al " & NotaPedido!D6 &" del HISJB del Ministerio de Salud." -> Para la Adquisición de Alimentos Perecederos y no Perecederos para ser destinados al Servicio de Nutrición del HISJB del Ministerio de Salud.
