Workbook

Sheet PROGRAMACION TRIMESTRAL
B2: Pedido de Necesidades Trimestrales
A4: JURISDICCION: | C4: 40-Ministerio de Salud
A5: SAF N°: | C5: 28- Maternidad Provincial 25 de Mayo
A6: EJERCICIO: | C6: 2022
A7: TRIMESTRE: | C7: 3
A9: ID | B9: CODIGO ITEM | C9: RUBRO | D9: I.P.P. | E9: DESCRIPCION | F9: UNIDAD DE MEDIDA | G9: CANTIDAD | H9: PRECIO UNITARIO ESTIMADO | I9: IMPORTE TOTAL ESTIMADO
A10: 1 | B10: 2.1.1-4227.59 | C10: PROD.MEDICO/FARMACEUTICO/LAB | D10: 2.5.2 | E10: SUPLEMENTOS DIETARIOS; ESTADO: POLVO, TIPO: FORMULA LACTEA MEDICAMENTOSA PARA LACTANTE, PROCESO: PASTEURIZADA, AGREGADO: HIDROLIZADO PARCIAL DE PROTEINA - CACEINATO DE SODIO, PRESENTACION: ENVASE X 400 GRS, MATERIAL: ENVASE METAL | F10: UNIDAD | G10: 8 | H10: 5040 | I10: =H10*G10 -> 40320
A11: 2 | B11: 2.1.1-4227.57 | C11: PROD.MEDICO/FARMACEUTICO/LAB | D11: 2.5.2 | E11: SUPLEMENTOS DIETARIOS; ESTADO: POLVO, TIPO: FORMULA LACTEA MEDICAMENTOSA PARA LACTANTE, PROCESO: PASTEURIZADA, AGREGADO: HIDROLIZADO DE PROTEINA SUERO - HIDROLIZADO ENZIMAL - PARCIAL DE PROTEINA DE SUERO GOS/FOS, PRESENTACION: ENVASE POR 400 GRAMOS, MATERIAL DEL ENVASE: METAL | F11: UNIDAD | G11: 6 | H11: 8469 | I11: =H11*G11 -> 50814
A12: 3 | B12: 2.1.1-4227.61 | C12: PROD.MEDICO/FARMACEUTICO/LAB | D12: 2.5.2 | E12: SUPLEMENTOS DIETARIOS; ESTADO: LIQUIDO, TIPO: FORMULA LACTEA DE INICIO DE 0 A 6 MESES, PROCESO: PASTEURIZADA, AGREGADO: VITAMINAS, MINERALES, ARA, DHA, PRESENTACION: ENVASE X 200 GRS, MATERIAL: ENVASE TETRAFILM. | F12: UNIDAD | G12: 1100 | H12: 103.5 | I12: =H12*G12 -> 113850
A13: 4 | B13: 2.1.1-4227.62 | C13: PROD.MEDICO/FARMACEUTICO/LAB | D13: 2.5.2 | E13: SUPLEMENTOS DIETARIOS; ESTADO: LIQUIDO, TIPO: FORMULA LACTEA PARA PREMATURO O BAJO PESO, PROCESO: PASTEURIZADA, AGREGADO: VITAMINAS, MINERALES, ARA, DHA, PRESENTACION: ENVASE X 70 GRS, MATERIAL: ENVASE PLASTICO. | F13: UNIDAD | G13: 2160 | H13: 480.7 | I13: =H13*G13 -> 1038312
A14: 5 | B14: 2.1.1-4227.4 | C14: PROD.MEDICO/FARMACEUTICO/LAB | D14: 2.5.2 | E14: SUPLEMENTOS DIETARIOS; TIPO: ASOCIACION, DROGA GENERICA: HC-PROT- Y VIT.MINERALES, PRESENTACION: 50 SOBRES X 2 GR | F14: CAJA | G14: 3 | H14: 8422 | I14: =H14*G14 -> 25266
B17: Especificidades Item N° 1 :
C18: Formula Lactea en polvo con proteina parcialmente hidrolizada. Sin lactosa. Presentacion en lata por 400 gramos
B19: Plazo de Entrega : | D19: 10(diez) dias habiles
B21: Lugares de entrega: | C21: SECTOR DE NUTRICION-MATERNIDAD PROVINCIAL 25 DE MAYO , HERNADO DE PEDRAZA 1650-
B23: Hora de entrega: | D23: 8 a 10 Hs
B25: Calidad Minima esperada
B27: Mantenimiento | D27: 30(treinta) dias habiles
B30: Especificidades Item N° 2:
C31: Formula Lactea en polvo con proteina totalmente hidrolizada. Sin lactosa. Presentacion en lata por 400 gramos
B32: Plazo de Entrega : | D32: 10(diez) dias habiles
B34: Lugares de entrega: | C34: SECTOR DE NUTRICION-MATERNIDAD PROVINCIAL 25 DE MAYO , HERNADO DE PEDRAZA 1650-
B36: Hora de entrega: | D36: 8 a 10 Hs
B38: Calidad Minima esperada
B40: Mantenimiento | D40: 30(treinta) dias habiles
B43: Especificidades Item N° 3:
C44: Formula Lactea liquida de inicio para niños de 0 a 6 meses. Con ARA y DHA sin agregado de azucar. Presentacion tetrapáck de 200 ml
B45: Plazo de Entrega : | D45: 10(diez) dias habiles
B47: Lugares de entrega: | C47: SECTOR DE NUTRICION-MATERNIDAD PROVINCIAL 25 DE MAYO , HERNADO DE PEDRAZA 1650-
B49: Hora de entrega: | D49: 8 a 10 Hs
B51: Calidad Minima esperada
B53: Mantenimiento | D53: 30(treinta) dias habiles
B55: Garantia
B57: Especificidades Item N° 4:
C58: Formula Lactea liquida para RN prematuro o bajo peso. Con ARA y DHA.
B59: Plazo de Entrega : | D59: 10(diez) dias habiles
B61: Lugares de entrega: | C61: SECTOR DE NUTRICION-MATERNIDAD PROVINCIAL 25 DE MAYO , HERNADO DE PEDRAZA 1650-
B63: Hora de entrega: | D63: 8 a 10 Hs
B65: Calidad Minima esperada
B67: Mantenimiento | D67: 30(treinta) dias habiles
...

Sheet  NotaPedido
A1: NOTA DE PEDIDO | J1: N° | K1: /2022
A3: JURISDICCIÓN: | D3: ='PROGRAMACION TRIMESTRAL'!C4 -> 40-Ministerio de Salud
A4: SAF: | D4: ='PROGRAMACION TRIMESTRAL'!C5 -> 28- Maternidad Provincial 25 de Mayo
A5: UNIDAD EJECUTORA: | D5: 169-Direccion Asistencial
A6: DEPENDENCIA SOLICITANTE: | D6: Servicio de Nutricion
A7: PERIODO UTILIZACIÓN: | D7: ='PROGRAMACION TRIMESTRAL'!C7 & "° Trimestre - Año " & 'PROGRAMACION TRIMESTRAL'!C6 -> 3° Trimestre - Año 2022
A8: OBJETO: | D8: Adquisición de Formulas lácteas para el servicio de Nutrición
A10: Ítem | B10: Código Ítem | C10: DESCRIPCIÓN | H10: Adjunta Detalle Técnico | I10: Unidad Medida | J10: Precio Unitario Estimado | K10: Cantidad Solicitada
A12: =+'PROGRAMACION TRIMESTRAL'!A10 -> 1 | B12: =+'PROGRAMACION TRIMESTRAL'!B10 -> 2.1.1-4227.59 | C12: ='PROGRAMACION TRIMESTRAL'!$E$10 -> SUPLEMENTOS DIETARIOS; ESTADO: POLVO, TIPO: FORMULA LACTEA MEDICAMENTOSA PARA LACTANTE, PROCESO: PASTEURIZADA, AGREGADO: HIDROLIZADO PARCIAL DE PROTEINA - CACEINATO DE SODIO, PRESENTACION: ENVASE X 400 GRS, MATERIAL: ENVASE METAL | H12: SI | I12: ='PROGRAMACION TRIMESTRAL'!F10 -> UNIDAD | J12: =+'PROGRAMACION TRIMESTRAL'!H10 -> 5040 | K12: =+'PROGRAMACION TRIMESTRAL'!G10 -> 8
A13: =+'PROGRAMACION TRIMESTRAL'!A11 -> 2 | B13: =+'PROGRAMACION TRIMESTRAL'!B11 -> 2.1.1-4227.57 | C13: ='PROGRAMACION TRIMESTRAL'!$E$11 -> SUPLEMENTOS DIETARIOS; ESTADO: POLVO, TIPO: FORMULA LACTEA MEDICAMENTOSA PARA LACTANTE, PROCESO: PASTEURIZADA, AGREGADO: HIDROLIZADO DE PROTEINA SUERO - HIDROLIZADO ENZIMAL - PARCIAL DE PROTEINA DE SUERO GOS/FOS, PRESENTACION: ENVASE POR 400 GRAMOS, MATERIAL DEL ENVASE: METAL | H13: SI | I13: ='PROGRAMACION TRIMESTRAL'!F11 -> UNIDAD | J13: =+'PROGRAMACION TRIMESTRAL'!H11 -> 8469 | K13: =+'PROGRAMACION TRIMESTRAL'!G11 -> 6
A14: =+'PROGRAMACION TRIMESTRAL'!A12 -> 3 | B14: =+'PROGRAMACION TRIMESTRAL'!B12 -> 2.1.1-4227.61 | C14: ='PROGRAMACION TRIMESTRAL'!$E$12 -> SUPLEMENTOS DIETARIOS; ESTADO: LIQUIDO, TIPO: FORMULA LACTEA DE INICIO DE 0 A 6 MESES, PROCESO: PASTEURIZADA, AGREGADO: VITAMINAS, MINERALES, ARA, DHA, PRESENTACION: ENVASE X 200 GRS, MATERIAL: ENVASE TETRAFILM. | H14: SI | I14: ='PROGRAMACION TRIMESTRAL'!F12 -> UNIDAD | J14: =+'PROGRAMACION TRIMESTRAL'!H12 -> 103.5 | K14: =+'PROGRAMACION TRIMESTRAL'!G12 -> 1100
A15: =+'PROGRAMACION TRIMESTRAL'!A13 -> 4 | B15: =+'PROGRAMACION TRIMESTRAL'!B13 -> 2.1.1-4227.62 | C15: SUPLEMENTOS DIETARIOS; ESTADO: LIQUIDO, TIPO: FORMULA LACTEA PARA PREMATURO O BAJO PESO, PROCESO: PASTEURIZADA, AGREGADO: VITAMINAS, MINERALES, ARA, DHA, PRESENTACION: ENVASE X 70 GRS, MATERIAL: ENVASE PLASTICO. | H15: SI | I15: UNIDAD | J15: =+'PROGRAMACION TRIMESTRAL'!H13 -> 480.7 | K15: =+'PROGRAMACION TRIMESTRAL'!G13 -> 2160
A16: =+'PROGRAMACION TRIMESTRAL'!A14 -> 5 | B16: =+'PROGRAMACION TRIMESTRAL'!B14 -> 2.1.1-4227.4 | C16: ='PROGRAMACION TRIMESTRAL'!$E$14 -> SUPLEMENTOS DIETARIOS; TIPO: ASOCIACION, DROGA GENERICA: HC-PROT- Y VIT.MINERALES, PRESENTACION: 50 SOBRES X 2 GR | H16: SI | I16: CAJA | J16: =+'PROGRAMACION TRIMESTRAL'!H14 -> 8422 | K16: =+'PROGRAMACION TRIMESTRAL'!G14 -> 3
A17: Costo total estimado: UN MILLON DOSCIENTOS SESENTA Y OCHO MIL QUINIENTOS SESENTA Y DOS CON 00/100 | J17: =SUMPRODUCT(J12:J16*K12:K16) -> 1268562

Sheet Autor Gastar
A1: EJERCICIO: | D1: ='PROGRAMACION TRIMESTRAL'!C6 -> 2022 | P1: AUTORIZACION PARA GASTAR
A4: JURISDICCIÓN: | G4: =' NotaPedido'!D3 -> 40-Ministerio de Salud
A5: SAF: | G5: =' NotaPedido'!D4 -> 28- Maternidad Provincial 25 de Mayo
A6: UNIDAD EJECUTORA: | G6: =' NotaPedido'!D5 -> 169-Direccion Asistencial
A7: DEPENDENCIA SOLICITANTE: | G7: =' NotaPedido'!D6 -> Servicio de Nutricion
A8: AUTORIZACIÓN:
A9: Señor Jefe de Servicio Administrativo Financiero:
A10: ="Autorizo la realización de los trámites correspondientes, a fin de proveer a este Organismo los bienes y/o servicios que se detallan en Nota de Pedido N° " & ' NotaPedido'!K1&", afectando la erogación resultante a los créditos presupuestarios aprobados a favor de esta Unidad Ejecutora, conforme al siguiente detalle:" -> Autorizo la realización de los trámites correspondientes, a fin de proveer a este Organismo los bienes y/o servicios que se detallan en Nota de Pedido N° /2022, afectando la erogación resultante a los créditos presupuestarios aprobados a favor de esta Unidad Ejecutora, conforme al siguiente detalle:
A12: IMPUTACIÓN PRESUPUESTARIA
A13: CÓDIGO | O13: DENOMINACIÓN DE LA PARTIDA PRESUPUESTARIA | Q13: IMPORTE
A14: PR | B14: SB | C14: PY | D14: AC | E14: OB | F14: UG | G14: FIN | H14: FUN | I14: I | J14: P | K14: P | L14: SubP | M14: M | N14: FF
A15: 42 | D15: 2 | F15: 4901 | G15: 3 | H15: 1 | I15: 2 | J15: 5 | K15: 2 | M15: 1 | N15: 1.1 | O15: ALIMENTOS PARA PERSONAS | Q15: 1268562
A19: TOTAL DE PESOS: UN MILLON DOSCIENTOS SESENTA Y OCHO MIL QUINIENTOS SESENTA Y DOS CON 00/100 | Q19: =SUM(Q15:Q18) -> 1268562
A21: JUSTIFICACIÓN:
A22: Para la Adquisición de Formulas lácteas para ser destinados al Servicio de Nutrición de la Maternidad Provincial 25 de Mayo del Ministerio de Salud.
