Workbook

Sheet Necesidades Trimestrales
A1: =ROW(A1) -> 1
B2: Pedido de Necesidades Trimestrales
A4: JURISDICCION: | C4: 42-Ministerio de Salud
A5: SAF N°: | C5: 28- Maternidad Provincial 25 de Mayo
A6: EJERCICIO: | C6: 2020
A7: TRIMESTRE: | C7: 4°
A9: ID | B9: CODIGO ITEM | C9: RUBRO DE COMPRA | D9: I.P.P. | E9: DESCRIPCION | F9: UNIDAD DE MEDIDA | G9: CANTIDAD | H9: PRECIO UNITARIO ESTIMADO | I9: IMPORTE TOTAL ESTIMADO
A10: 1 | C10: PROD. MEDICO/FARMACEUTICOS/LAB | D10: 2.5.2 | E10: BUPIBACAIHNA CLORIDRATO HIPERBARICA 5MG/ML AMP-KIT CON AGUJA INTRODUCTORA 27 GX3 1/2 TIPO CASARA SCOTT | F10: UNIDAD | G10: 500 | H10: 800 | I10: =G10*H10 -> 400000
A11: 2 | C11: PROD. MEDICO/FARMACEUTICOS/LAB | D11: 2.5.2 | E11: IMIPENEM FRASCO FRASCO/AMPOLLA X 500 MG | F11: UNIDAD | G11: 150 | H11: 700 | I11: =G11*H11 -> 105000
A12: 3 | C12: PROD. MEDICO/FARMACEUTICOS/LAB | D12: 2.9.5 | E12: AGUJA DESCARTABLE 16/5 | F12: UNIDAD | G12: 2500 | H12: 1.18 | I12: =G12*H12 -> 2950
A13: 4 | C13: PROD. MEDICO/FARMACEUTICOS/LAB | D13: 2.9.5 | E13: AGUJA DESCARTABLE 25/8 | F13: UNIDAD | G13: 22500 | H13: 1.18 | I13: =G13*H13 -> 26550
A14: 5 | C14: PROD. MEDICO/FARMACEUTICOS/LAB | D14: 2.9.5 | E14: AGUJA DESCARTABLE 40/12 | F14: UNIDAD | G14: 500 | H14: 1.53 | I14: =G14*H14 -> 765
A15: 6 | C15: PROD. MEDICO/FARMACEUTICOS/LAB | D15: 2.9.5 | E15: AGUJA DESCARTABLE 40/8 | F15: UNIDAD | G15: 18000 | H15: 1.18 | I15: =G15*H15 -> 21240
A16: 7 | C16: PROD. MEDICO/FARMACEUTICOS/LAB | D16: 2.9.5 | E16: AGUJA DESCARTABLE 50/8 | F16: UNIDAD | G16: 500 | H16: 1.53 | I16: =G16*H16 -> 765
A17: 8 | C17: PROD. MEDICO/FARMACEUTICOS/LAB | D17: 2.9.5 | E17: ALGODÓN x 500 GRS.TIPO DONCELLA | F17: UNIDAD | G17: 900 | H17: 228 | I17: =G17*H17 -> 205200
A18: 9 | C18: PROD. MEDICO/FARMACEUTICOS/LAB | D18: 2.9.5 | E18: BAJALENGUA X 100 UNIDADES | F18: UNIDAD | G18: 20 | H18: 103 | I18: =G18*H18 -> 2060
A19: 10 | C19: PROD. MEDICO/FARMACEUTICOS/LAB | D19: 2.9.5 | E19: BOTAS ALTAS DESCARTABLES DE 30 GRAMOS CON TIRA EL PAR | F19: UNIDAD | G19: 5000 | H19: 15.6 | I19: =G19*H19 -> 78000
A20: 11 | C20: PROD. MEDICO/FARMACEUTICOS/LAB | D20: 2.9.5 | E20: CAMISOLINES DES. SMS CON MANGAS Y PUÑO DE 1,40 MTS. DE LARGO, 30 GRS. COLOR AZUL | F20: UNIDAD | G20: 4000 | H20: 76.2 | I20: =G20*H20 -> 304800
A21: 12 | C21: PROD. MEDICO/FARMACEUTICOS/LAB | D21: 2.9.5 | E21: CATETER INTRAVENOSO Nº 22 TIPO HOSPIRA/BD | F21: UNIDAD | G21: 50 | H21: 17.72 | I21: =G21*H21 -> 886
... A75: 66 | C75: PROD. MEDICO/FARMACEUTICOS/LAB | D75: 2.5.2 | E75: MISOPROSTOL 200 MG COMPRIMIDOS VAGINALES RAM X 12 | F75: UNIDAD | G75: 60 | H75: 6082.93 | I75: =G75*H75 -> 364975.8
B79: Especificidades Item N° 13:
B81: Descripción técnica
C82: CATETER INTRAVENOSO 24 de calidad tipo HOSPIRA O BD ya que si no cumplen con esta calidad al momento de la canalización se producen hematomas flebitis e infecciones que revierten mayor gravedad en los NEONATOS.
B83: Plazos y lugares de entrega
C84: MATERNIDAD PROVINCIAL 25 DE MAYO- H. DE PEDRAZA 1.650
B86: Calidad Minima esperada
C87: tipo HOSPIRA O BD
B88: Mantenimiento
B90: Garantia
B94: Especificidades Item N° 58:
B96: Descripción técnica
C97: Las vías centrales deben ser de una calidad adecuada ya que son utilizadas en neonatos. Se recomienda tipo ARROW
B98: Plazos y lugares de entrega
C99: MATERNIDAD PROVINCIAL 25 DE MAYO- H. DE PEDRAZA 1.650
B101: Calidad Minima esperada
C102: tipo ARROW
B103: Mantenimiento
B105: Garantia
B109: Especificidades Item N° 59:
B111: Descripción técnica
...

Sheet  NotaPedido 301-20
A1: NOTA DE PEDIDO | J1: N° | K1: 303/2020
A3: JURISDICCIÓN: | D3: ='Necesidades Trimestrales'!C4 -> 42-Ministerio de Salud
A4: SAF: | D4: ='Necesidades Trimestrales'!C5 -> 28- Maternidad Provincial 25 de Mayo
A5: UNIDAD EJECUTORA: | D5: 169- Direccion Asistencial
A6: DEPENDENCIA SOLICITANTE: | D6: Servicio de Farmacia
A7: PERIODO UTILIZACIÓN: | D7: ='Necesidades Trimestrales'!C7 & " - Año " & 'Necesidades Trimestrales'!C6 -> 4° - Año 2020
A8: OBJETO: | D8: ADQUISICION DE ANESTESICOS Y DESCARTABLES
A10: Ítem | B10: Codigo Item | C10: DESCRIPCIÓN | H10: Adjunta Detalle Técnico | I10: Unidad Medida | J10: Precio Unitario Estimado | K10: Cantidad Solicitada
A12: ='Necesidades Trimestrales'!A10 -> 1 | B12: ='Necesidades Trimestrales'!B10 -> 0 | C12: ='Necesidades Trimestrales'!E10 -> BUPIBACAIHNA CLORIDRATO HIPERBARICA 5MG/ML AMP-KIT CON AGUJA INTRODUCTORA 27 GX3 1/2 TIPO CASARA SCOTT | H12: NO | I12: ='Necesidades Trimestrales'!F10 -> UNIDAD | J12: ='Necesidades Trimestrales'!H10 -> 800 | K12: ='Necesidades Trimestrales'!G10 -> 500
A13: ='Necesidades Trimestrales'!A11 -> 2 | B13: ='Necesidades Trimestrales'!B11 -> 0 | C13: ='Necesidades Trimestrales'!E11 -> IMIPENEM FRASCO FRASCO/AMPOLLA X 500 MG | H13: NO | I13: ='Necesidades Trimestrales'!F11 -> UNIDAD | J13: ='Necesidades Trimestrales'!H11 -> 700 | K13: ='Necesidades Trimestrales'!G11 -> 150
A14: ='Necesidades Trimestrales'!A12 -> 3 | B14: ='Necesidades Trimestrales'!B12 -> 0 | C14: ='Necesidades Trimestrales'!E12 -> AGUJA DESCARTABLE 16/5 | H14: NO | I14: ='Necesidades Trimestrales'!F12 -> UNIDAD | J14: ='Necesidades Trimestrales'!H12 -> 1.18 | K14: ='Necesidades Trimestrales'!G12 -> 2500
A15: ='Necesidades Trimestrales'!A13 -> 4 | B15: ='Necesidades Trimestrales'!B13 -> 0 | C15: ='Necesidades Trimestrales'!E13 -> AGUJA DESCARTABLE 25/8 | H15: NO | I15: ='Necesidades Trimestrales'!F13 -> UNIDAD | J15: ='Necesidades Trimestrales'!H13 -> 1.18 | K15: ='Necesidades Trimestrales'!G13 -> 22500
A16: ='Necesidades Trimestrales'!A14 -> 5 | B16: ='Necesidades Trimestrales'!B14 -> 0 | C16: ='Necesidades Trimestrales'!E14 -> AGUJA DESCARTABLE 40/12 | H16: NO | I16: ='Necesidades Trimestrales'!F14 -> UNIDAD | J16: ='Necesidades Trimestrales'!H14 -> 1.53 | K16: ='Necesidades Trimestrales'!G14 -> 500
A17: ='Necesidades Trimestrales'!A15 -> 6 | B17: ='Necesidades Trimestrales'!B15 -> 0 | C17: ='Necesidades Trimestrales'!E15 -> AGUJA DESCARTABLE 40/8 | H17: NO | I17: ='Necesidades Trimestrales'!F15 -> UNIDAD | J17: ='Necesidades Trimestrales'!H15 -> 1.18 | K17: ='Necesidades Trimestrales'!G15 -> 18000
A18: ='Necesidades Trimestrales'!A16 -> 7 | B18: ='Necesidades Trimestrales'!B16 -> 0 | C18: ='Necesidades Trimestrales'!E16 -> AGUJA DESCARTABLE 50/8 | H18: NO | I18: ='Necesidades Trimestrales'!F16 -> UNIDAD | J18: ='Necesidades Trimestrales'!H16 -> 1.53 | K18: ='Necesidades Trimestrales'!G16 -> 500
A19: ='Necesidades Trimestrales'!A17 -> 8 | B19: ='Necesidades Trimestrales'!B17 -> 0 | C19: ='Necesidades Trimestrales'!E17 -> ALGODÓN x 500 GRS.TIPO DONCELLA | H19: NO | I19: ='Necesidades Trimestrales'!F17 -> UNIDAD | J19: ='Necesidades Trimestrales'!H17 -> 228 | K19: ='Necesidades Trimestrales'!G17 -> 900
A20: ='Necesidades Trimestrales'!A18 -> 9 | B20: ='Necesidades Trimestrales'!B18 -> 0 | C20: ='Necesidades Trimestrales'!E18 -> BAJALENGUA X 100 UNIDADES | H20: NO | I20: ='Necesidades Trimestrales'!F18 -> UNIDAD | J20: ='Necesidades Trimestrales'!H18 -> 103 | K20: ='Necesidades Trimestrales'!G18 -> 20
A21: ='Necesidades Trimestrales'!A19 -> 10 | B21: ='Necesidades Trimestrales'!B19 -> 0 | C21: ='Necesidades Trimestrales'!E19 -> BOTAS ALTAS DESCARTABLES DE 30 GRAMOS CON TIRA EL PAR | H21: NO | I21: ='Necesidades Trimestrales'!F19 -> UNIDAD | J21: ='Necesidades Trimestrales'!H19 -> 15.6 | K21: ='Necesidades Trimestrales'!G19 -> 5000
A22: ='Necesidades Trimestrales'!A20 -> 11 | B22: ='Necesidades Trimestrales'!B20 -> 0 | C22: ='Necesidades Trimestrales'!E20 -> CAMISOLINES DES. SMS CON MANGAS Y PUÑO DE 1,40 MTS. DE LARGO, 30 GRS. COLOR AZUL | H22: NO | I22: ='Necesidades Trimestrales'!F20 -> UNIDAD | J22: ='Necesidades Trimestrales'!H20 -> 76.2 | K22: ='Necesidades Trimestrales'!G20 -> 4000
A23: ='Necesidades Trimestrales'!A21 -> 12 | B23: ='Necesidades Trimestrales'!B21 -> 0 | C23: ='Necesidades Trimestrales'!E21 -> CATETER INTRAVENOSO Nº 22 TIPO HOSPIRA/BD | H23: NO | I23: ='Necesidades Trimestrales'!F21 -> UNIDAD | J23: ='Necesidades Trimestrales'!H21 -> 17.72 | K23: ='Necesidades Trimestrales'!G21 -> 50
... A77: ='Necesidades Trimestrales'!A75 -> 66 | B77: ='Necesidades Trimestrales'!B75 -> 0 | C77: ='Necesidades Trimestrales'!E75 -> MISOPROSTOL 200 MG COMPRIMIDOS VAGINALES RAM X 12 | H77: NO | I77: ='Necesidades Trimestrales'!F75 -> UNIDAD | J77: ='Necesidades Trimestrales'!H75 -> 6082.93 | K77: ='Necesidades Trimestrales'!G75 -> 60
A78: Costo total estimado: CINCO MILLONES TRESCIENTOS SEIS MIL DOSCIENTOS VEINTE CON 30/100 | J78: =SUMPRODUCT(J12:J77,K12:K77) -> 5306220.3

Sheet Autor Gastar
A1: EJERCICIO: | D1: ='Necesidades Trimestrales'!C6 -> 2020 | P1: AUTORIZACION PARA GASTAR
A4: JURISDICCIÓN: | G4: =' NotaPedido 301-20'!D3 -> 42-Ministerio de Salud
A5: SAF: | G5: =' NotaPedido 301-20'!D4 -> 28- Maternidad Provincial 25 de Mayo
A6: UNIDAD EJECUTORA: | G6: =' NotaPedido 301-20'!D5 -> 169- Direccion Asistencial
A7: DEPENDENCIA SOLICITANTE: | G7: =' NotaPedido 301-20'!D6 -> Servicio de Farmacia
A8: AUTORIZACIÓN:
A9: Señor Jefe de Servicio Administrativo Financiero:
A10: ="Autorizo la realización de los trámites correspondientes, a fin de proveer a este Organismo los bienes y/o servicios que se detallan en Nota de Pedido N° " & ' NotaPedido 301-20'!K1&", afectando la erogación resultante a los créditos presupuestarios aprobados a favor de esta Unidad Ejecutora, conforme al siguiente detalle:" -> Autorizo la realización de los trámites correspondientes, a fin de proveer a este Organismo los bienes y/o servicios que se detallan en Nota de Pedido N° 303/2020, afectando la erogación resultante a los créditos presupuestarios aprobados a favor de esta Unidad Ejecutora, conforme al siguiente detalle:
A12: IMPUTACIÓN PRESUPUESTARIA
A13: CÓDIGO | O13: DENOMINACIÓN DE LA PARTIDA PRESUPUESTARIA | Q13: IMPORTE
A14: PR | B14: SB | C14: PY | D14: AC | E14: OB | F14: UG | G14: FIN | H14: FUN | I14: I | J14: P | K14: P | L14: SubP | M14: M | N14: FF
A15: 42 | D15: 2 | F15: 4901 | G15: 3 | H15: 1 | I15: 2 | J15: 5 | K15: 2 | M15: 1 | N15: 1.1 | O15: Productos Farmaceuticos y medicinales | Q15: 889325.8
A16: 42 | D16: 2 | F16: 4901 | G16: 3 | H16: 1 | I16: 2 | J16: 9 | K16: 5 | M16: 1 | N16: 1.1 | O16: Utiles Menores Medico, Quirurgico y de Laboratorio | Q16: 3893814.5
A17: 42 | D17: 2 | F17: 4901 | G17: 3 | H17: 1 | I17: 2 | J17: 5 | K17: 1 | M17: 1 | N17: 1.1 | O17: Compuestos Quimicos | Q17: 523080
A18: TOTAL DE PESOS: CINCO MILLONES TRESCIENTOS SEIS MIL DOSCIENTOS VEINTE CON 30/100 | Q18: =SUM(Q15:Q17) -> 5306220.3
A20: JUSTIFICACIÓN:
A21: Para la adquisición de anestesicos y descartables, para ser destinados al Servico de Farmacia de Maternidad Provincial 25 de Mayo.
