Workbook

Sheet Necesidades Trimestrales
B2: Pedido de Necesidades Trimestrales
A4: JURISDICCION: | C4: 45- Ministerio de Desarrollo Social y Deporte.-
A5: SAF N°: | C5: 25- Direccion Provincial de Gestion Administracion y RRHH
A6: EJERCICIO: | C6: 2021
A7: TRIMESTRE: | C7: 4
A9: ID | B9: CODIGO ITEM | C9: RUBRO DE COMPRA | D9: I.P.P. | E9: DESCRIPCION | F9: UNIDAD DE MEDIDA | G9: CANTIDAD | H9: PRECIO UNITARIO ESTIMADO | I9: IMPORTE TOTAL ESTIMADO
A10: 1 | B10: 2.1.1-705.93 | C10: ALIMENTOS | D10: 2.1.1 | E10: LECHE; ESTADO: POLVO, TIPO: ENTERA, PROCESO: PASTEURIZADA, AGREGADO: VITAMINAS A Y D, PRESENTACION: ENVASE X 800 GR, MATERIAL ENVASE: CARTON, ELEM. TRANSPORTE: SIN, MATERIAL ELEM. TRANSPORTE: SIN, CERTIFICADO FORESTAL (GFS): SIN, LIBRE DE GLUTEN: SI | F10: UNIDAD | G10: 50000 | H10: 599 | I10: =+G10*H10 -> 29950000
A11: 2 | B11: 2.1.1-439.67 | C11: ALIMENTOS | D11: =LEFT(B11,5) -> 2.1.1 | E11: ACEITES COMESTIBLES; TIPO: GIRASOL, PRESENTACION: ENVASE X 900 CM3, MATERIAL ENVASE: PLASTICO 1 (PET), ELEM. TRANSPORTE: SIN, MATERIAL ELEM. TRANSPORTE : SIN, LIBRE DE GLUTEN: NO | F11: UNIDAD | G11: 50000 | H11: 197 | I11: =+G11*H11 -> 9850000
A12: 3 | B12: 2.1.1-454.25 | C12: ALIMENTOS | D12: =LEFT(B12,5) -> 2.1.1 | E12: YERBAS; PALO: CON, PESO: 1 Kg, MATERIAL ENVASE : PAPEL, CERTIFICADO FORESTAL (GFS): CON, ELEM. TRANSPORTE: SIN, MATERIAL ELEM. TRANSPORTE: SIN, LIBRE DE GLUTEN: SI | F12: UNIDAD | G12: 50000 | H12: 299 | I12: =+G12*H12 -> 14950000
A13: 4 | B13: 2.1.1-708.23 | C13: ALIMENTOS | D13: =LEFT(B13,5) -> 2.1.1 | E13: CONSERVAS PESCADO Y FRUTOS MAR; ESTADO: AL NATURAL, PESO: 380 GR, ENVASE: LATA, TIPO: CABALLA, ESPECIE: CABALLA | F13: UNIDAD | G13: 50000 | H13: 190 | I13: =+G13*H13 -> 9500000
A14: 5 | B14: 2.1.1-435.60 | C14: ALIMENTOS | D14: 2.1.1 | E14: ARROZ; TIPO GRANO: LARGO-FINO, TIPO: BLANCO, PROCESO: SIN CASCARA, PRESENTACION: BOLSA X 1 Kg, MATERIAL ENVASE: PLASTICO, CERTIFICADO FORESTAL (GFS): SIN, ELEM. TRANSPORTE: SIN, MATERIAL ELEM. TRANSPORTE: SIN, LIBRE DE GLUTEN: SI | F14: UNIDAD | G14: 50000 | H14: 98.5 | I14: =+G14*H14 -> 4925000
A15: 6 | B15: 2.1.1-482.70 | C15: ALIMENTOS | D15: =LEFT(B15,5) -> 2.1.1 | E15: HARINAS; TIPO: 000, PRESENTACION: ENVASE X 1 Kg, MATERIAL ENVASE: PAPEL, CERTICADO FORESTAL (GFS): SI, ELEM. TRANSPORTE: SIN, MATERIAL ELEM. TRANSPORTE: SIN, LIBRE DE GLUTEN: NO | F15: UNIDAD | G15: 50000 | H15: 59 | I15: =+G15*H15 -> 2950000
A16: 7 | B16: 2.1.1-6546.260 | C16: ALIMENTOS | D16: =LEFT(B16,5) -> 2.1.1 | E16: VERDURAS Y HORTALIZAS; VARIEDAD: TOMATE, ESTADO: PURE, PRESENTACION: TETRABRIK, PESO: 520 GR | F16: UNIDAD | G16: 50000 | H16: 49.5 | I16: =+G16*H16 -> 2475000
A17: 8 | B17: 2.1.1-481.38 | C17: ALIMENTOS | D17: =LEFT(B17,5) -> 2.1.1 | E17: AZUCARES; TIPO: "A" COMUN, ESTADO: MOLIDA, PESO: 1 Kg, MATERIAL ENVASE: PLASTICO, CERTIFICADO FORESTAL (GFS): SIN, ELEM. TRANSPORTE: SIN, MATERIAL ELEM. TRANSPORTE: SIN | F17: UNIDAD | G17: 50000 | H17: 72.5 | I17: =+G17*H17 -> 3625000
A18: 9 | B18: 2.1.1-2868.54 | C18: ALIMENTOS | D18: 2.1.1 | E18: FIDEOS SECOS; VARIEDAD: SOPERO, RELLENO: SIN, PRESENTACION: ENVASE X 500 GR, MATERIAL ENVASE: PLASTICO 1 (PET), ELEM. TRANSPORTE: SIN, MATERIAL ELEM. TRANSPORTE: SIN, CERTIFICADO FORESTAL (GFS): SIN, LIBRE DE GLUTEN: NO | F18: UNIDAD | G18: 50000 | H18: 45 | I18: =+G18*H18 -> 2250000
A19: 10 | B19: 2.1.1-2868.55 | C19: ALIMENTOS | D19: 2.1.1 | E19: FIDEOS SECOS; VARIEDAD: TALLARIN, RELLENO: SIN, PRESENTACION: ENVASE X 500 GR, MATERIAL ENVASE: PLASTICO 1 (PET), ELEM. TRANSPORTE: SIN, MATERIAL ELEM. TRANSPORTE: SIN, CERTIFICADO FORESTAL (GFS): SIN, LIBRE DE GLUTEN: NO | F19: UNIDAD | G19: 50000 | H19: 45 | I19: =+G19*H19 -> 2250000
A20: 11 | B20: 2.1.1-2868.71 | C20: ALIMENTOS | D20: 2.1.1 | E20: FIDEOS SECOS; VARIEDAD: GUISERO, RELLENO: SIN, PRESENTACION: ENVASE X 500 GR, MATERIAL ENVASE: PLASTICO 1 (PET), ELEM. TRANSPORTE: SIN, MATERIAL ELEM. TRANSPORTE: SIN, CERTIFICADO FORESTAL (GFS): SIN, LIBRE DE GLUTEN: NO | F20: UNIDAD | G20: 50000 | H20: 45 | I20: =+G20*H20 -> 2250000
A21: 12 | B21: 2.1.1-6547.80 | C21: ALIMENTOS | D21: 2.1.1 | E21: LEGUMBRES; VARIEDAD: LENTEJA, ESTADO: SECO, PRESENTACION: SIN VALOR, PESO: ENVASE X 400 GR | F21: UNIDAD | G21: 50000 | H21: 126 | I21: =+G21*H21 -> 6300000
B25: Especificidades Item N° 1:
B27: Descripción técnica
B29: Plazos y lugares de entrega
C30: DENTRO DE LOS 5 (CINCO) DIAS DE LA RECEPCION DE LA ORDEN DE COMPRA.-
C31: DEPOSITO MINISTERIO DE DESARROLLO SOCIAL Y DEPORTE AREA EL PANTANILLO SAN FERNANDO DEL VALLE DE CATAMARCA
B32: Calidad Minima esperada
C33: MEDIA
B34: Mantenimiento
C35: 60DIAS
B36: Garantia
C37: S/E
B40: Especificidades Item N° 2:
B42: Descripción técnica
B44: Plazos y lugares de entrega
C45: DENTRO DE LOS 5 (CINCO) DIAS DE LA RECEPCION DE LA ORDEN DE COMPRA.-
C46: DEPOSITO MINISTERIO DE DESARROLLO SOCIAL Y DEPORTE AREA EL PANTANILLO SAN FERNANDO DEL VALLE DE CATAMARCA
B47: Calidad Minima esperada
C48: MEDIA
B49: Mantenimiento
C50: 60DIAS
B51: Garantia
C52: S/E
...

Sheet  NotaPedido
A1: NOTA DE PEDIDO | J1: N° | K1: 893/2021
A3: JURISDICCIÓN: | D3: ='Necesidades Trimestrales'!C4 -> 45- Ministerio de Desarrollo Social y Deporte.-
A4: SAF: | D4: ='Necesidades Trimestrales'!C5 -> 25- Direccion Provincial de Gestion Administracion y RRHH
A5: UNIDAD EJECUTORA: | D5: 16- Direccion Provincial de Accion Social Directa
A6: DEPENDENCIA SOLICITANTE: | D6: 02- Programa Vivir Mejor PRO.VI.ME.
A7: PERIODO UTILIZACIÓN: | D7: ='Necesidades Trimestrales'!C7 & "° Trimestre - Año " & 'Necesidades Trimestrales'!C6 -> 4° Trimestre - Año 2021
A8: OBJETO: | D8: Adquisición de Alimentos que seran destinadas a personas de escasos recursos, en el armado de modulos alimentarios, en el Marco del Programa Vivir Mejor
A10: Ítem | B10: Codigo Item | C10: DESCRIPCIÓN | H10: Adjunta Detalle Técnico | I10: Unidad Medida | J10: Precio Unitario Estimado | K10: Cantidad Solicitada
A12: 1 | B12: ='Necesidades Trimestrales'!B10 -> 2.1.1-705.93 | C12: ='Necesidades Trimestrales'!E10 -> LECHE; ESTADO: POLVO, TIPO: ENTERA, PROCESO: PASTEURIZADA, AGREGADO: VITAMINAS A Y D, PRESENTACION: ENVASE X 800 GR, MATERIAL ENVASE: CARTON, ELEM. TRANSPORTE: SIN, MATERIAL ELEM. TRANSPORTE: SIN, CERTIFICADO FORESTAL (GFS): SIN, LIBRE DE GLUTEN: SI | H12: SI | I12: ='Necesidades Trimestrales'!F10 -> UNIDAD | J12: 599 | K12: 50000
A13: 2 | B13: ='Necesidades Trimestrales'!B11 -> 2.1.1-439.67 | C13: ='Necesidades Trimestrales'!E11 -> ACEITES COMESTIBLES; TIPO: GIRASOL, PRESENTACION: ENVASE X 900 CM3, MATERIAL ENVASE: PLASTICO 1 (PET), ELEM. TRANSPORTE: SIN, MATERIAL ELEM. TRANSPORTE : SIN, LIBRE DE GLUTEN: NO | H13: SI | I13: ='Necesidades Trimestrales'!F11 -> UNIDAD | J13: 197 | K13: 50000
A14: 3 | B14: ='Necesidades Trimestrales'!B12 -> 2.1.1-454.25 | C14: ='Necesidades Trimestrales'!E12 -> YERBAS; PALO: CON, PESO: 1 Kg, MATERIAL ENVASE : PAPEL, CERTIFICADO FORESTAL (GFS): CON, ELEM. TRANSPORTE: SIN, MATERIAL ELEM. TRANSPORTE: SIN, LIBRE DE GLUTEN: SI | H14: SI | I14: ='Necesidades Trimestrales'!F12 -> UNIDAD | J14: 299 | K14: 50000
A15: 4 | B15: ='Necesidades Trimestrales'!B13 -> 2.1.1-708.23 | C15: ='Necesidades Trimestrales'!E13 -> CONSERVAS PESCADO Y FRUTOS MAR; ESTADO: AL NATURAL, PESO: 380 GR, ENVASE: LATA, TIPO: CABALLA, ESPECIE: CABALLA | H15: SI | I15: ='Necesidades Trimestrales'!F13 -> UNIDAD | J15: 190 | K15: 50000
A16: 5 | B16: ='Necesidades Trimestrales'!B14 -> 2.1.1-435.60 | C16: ='Necesidades Trimestrales'!E14 -> ARROZ; TIPO GRANO: LARGO-FINO, TIPO: BLANCO, PROCESO: SIN CASCARA, PRESENTACION: BOLSA X 1 Kg, MATERIAL ENVASE: PLASTICO, CERTIFICADO FORESTAL (GFS): SIN, ELEM. TRANSPORTE: SIN, MATERIAL ELEM. TRANSPORTE: SIN, LIBRE DE GLUTEN: SI | H16: SI | I16: ='Necesidades Trimestrales'!F14 -> UNIDAD | J16: 98.5 | K16: 50000
A17: 6 | B17: ='Necesidades Trimestrales'!B15 -> 2.1.1-482.70 | C17: ='Necesidades Trimestrales'!E15 -> HARINAS; TIPO: 000, PRESENTACION: ENVASE X 1 Kg, MATERIAL ENVASE: PAPEL, CERTICADO FORESTAL (GFS): SI, ELEM. TRANSPORTE: SIN, MATERIAL ELEM. TRANSPORTE: SIN, LIBRE DE GLUTEN: NO | H17: SI | I17: ='Necesidades Trimestrales'!F15 -> UNIDAD | J17: 59 | K17: 50000
A18: 7 | B18: ='Necesidades Trimestrales'!B16 -> 2.1.1-6546.260 | C18: ='Necesidades Trimestrales'!E16 -> VERDURAS Y HORTALIZAS; VARIEDAD: TOMATE, ESTADO: PURE, PRESENTACION: TETRABRIK, PESO: 520 GR | H18: SI | I18: UNIDAD | J18: 49.5 | K18: 50000
A19: 8 | B19: ='Necesidades Trimestrales'!B17 -> 2.1.1-481.38 | C19: ='Necesidades Trimestrales'!E17 -> AZUCARES; TIPO: "A" COMUN, ESTADO: MOLIDA, PESO: 1 Kg, MATERIAL ENVASE: PLASTICO, CERTIFICADO FORESTAL (GFS): SIN, ELEM. TRANSPORTE: SIN, MATERIAL ELEM. TRANSPORTE: SIN | H19: SI | I19: UNIDAD | J19: 72.5 | K19: 50000
A20: 9 | B20: ='Necesidades Trimestrales'!B18 -> 2.1.1-2868.54 | C20: ='Necesidades Trimestrales'!E18 -> FIDEOS SECOS; VARIEDAD: SOPERO, RELLENO: SIN, PRESENTACION: ENVASE X 500 GR, MATERIAL ENVASE: PLASTICO 1 (PET), ELEM. TRANSPORTE: SIN, MATERIAL ELEM. TRANSPORTE: SIN, CERTIFICADO FORESTAL (GFS): SIN, LIBRE DE GLUTEN: NO | H20: SI | I20: UNIDAD | J20: 45 | K20: 50000
A21: 10 | B21: ='Necesidades Trimestrales'!B19 -> 2.1.1-2868.55 | C21: ='Necesidades Trimestrales'!E19 -> FIDEOS SECOS; VARIEDAD: TALLARIN, RELLENO: SIN, PRESENTACION: ENVASE X 500 GR, MATERIAL ENVASE: PLASTICO 1 (PET), ELEM. TRANSPORTE: SIN, MATERIAL ELEM. TRANSPORTE: SIN, CERTIFICADO FORESTAL (GFS): SIN, LIBRE DE GLUTEN: NO | H21: SI | I21: UNIDAD | J21: 45 | K21: 50000
A22: 11 | B22: ='Necesidades Trimestrales'!B20 -> 2.1.1-2868.71 | C22: ='Necesidades Trimestrales'!E20 -> FIDEOS SECOS; VARIEDAD: GUISERO, RELLENO: SIN, PRESENTACION: ENVASE X 500 GR, MATERIAL ENVASE: PLASTICO 1 (PET), ELEM. TRANSPORTE: SIN, MATERIAL ELEM. TRANSPORTE: SIN, CERTIFICADO FORESTAL (GFS): SIN, LIBRE DE GLUTEN: NO | H22: SI | I22: UNIDAD | J22: 45 | K22: 50000
A23: 12 | B23: ='Necesidades Trimestrales'!B21 -> 2.1.1-6547.80 | C23: ='Necesidades Trimestrales'!E21 -> LEGUMBRES; VARIEDAD: LENTEJA, ESTADO: SECO, PRESENTACION: SIN VALOR, PESO: ENVASE X 400 GR | H23: SI | I23: UNIDAD | J23: 126 | K23: 50000
A25: Costo total estimado: NOVENTA Y UN MILLONES DOSCIENTOS SETENTA Y CINCO MIL CON 00/100.- | J25: =+J12*K12+J13*K13+J14*K14+J15*K15+J16*K16+J17*K17+J18*K18+J19*K19+J20*K20+J21*K21+J22*K22+J23*K23+J24*K24 -> 91275000

Sheet Autor Gastar
A1: EJERCICIO: | D1: ='Necesidades Trimestrales'!C6 -> 2021 | P1: AUTORIZACION PARA GASTAR
A4: JURISDICCIÓN: | G4: =' NotaPedido'!D3 -> 45- Ministerio de Desarrollo Social y Deporte.-
A5: SAF: | G5: =' NotaPedido'!D4 -> 25- Direccion Provincial de Gestion Administracion y RRHH
A6: UNIDAD EJECUTORA: | G6: 16- Direccion Provincial de Accion Social Directa
A7: DEPENDENCIA SOLICITANTE: | G7: 02- PRO.VI.ME. Programa Vivir Mejor
A8: AUTORIZACIÓN:
A9: Señor Jefe de Servicio Administrativo Financiero:
A10: ="Autorizo la realización de los trámites correspondientes, a fin de proveer a este Organismo los bienes y/o servicios que se detallan en Nota de Pedido N° " & ' NotaPedido'!K1&", afectando la erogación resultante a los créditos presupuestarios aprobados a favor de esta Unidad Ejecutora, conforme al siguiente detalle:" -> Autorizo la realización de los trámites correspondientes, a fin de proveer a este Organismo los bienes y/o servicios que se detallan en Nota de Pedido N° 893/2021, afectando la erogación resultante a los créditos presupuestarios aprobados a favor de esta Unidad Ejecutora, conforme al siguiente detalle:
A12: IMPUTACIÓN PRESUPUESTARIA
A13: CÓDIGO | O13: DENOMINACIÓN DE LA PARTIDA PRESUPUESTARIA | Q13: IMPORTE
A14: PR | B14: SB | C14: PY | D14: AC | E14: OB | F14: UG | G14: FIN | H14: FUN | I14: I | J14: P | K14: P | L14: SubP | M14: M | N14: FF
A15: 16 | D15: 2 | F15: 4901 | G15: 3 | H15: 2 | I15: =LEFT('[1]Necesidades Trimestrales'!D10,1) -> 2 | J15: 1 | K15: 1 | M15: 1 | N15: 1.1 | O15: Alimentos para Personas | Q15: 91275000
A23: TOTAL DE PESOS: NOVENTA Y UN MILLONES DOSCIENTOS SETENTA Y CINCO MIL CON 00/100.- | Q23: =SUM(Q15:Q22) -> 91275000
A25: JUSTIFICACIÓN:
A26: Adquisición de Alimentos que seran destinadas a personas de escasos recursos, en el armado de modulos alimentarios, en el Marco del Programa Vivir Mejor
