Workbook

Sheet Necesidades Trimestrales
B2: Pedido de Necesidades Trimestrales
A4: JURISDICCION: | C4: 040 - Ministerio de Salud
A5: SAF N°: | C5: 11/ 23/ 24 o 28- "…......."
A6: EJERCICIO: | C6: 2022 | I6: precio actualizado al 2do trim.2022
A7: TRIMESTRE: | C7: 1
M8: según archivo tramites 2 trim 2022 - Vademecun | P8: codificacion ruben
A9: ID | B9: CODIGO ITEM | C9: RUBRO DE COMPRA | D9: I.P.P. | E9: DESCRIPCION | F9: DESCRIPCION COMPR.AR | G9: UNIDAD DE MEDIDA | H9: CANTIDAD | I9: PRECIO UNITARIO ESTIMADO | J9: IMPORTE TOTAL ESTIMADO | M9: codigo item | N9: descripcion compr.ar | O9: unidad de medida | P9: codigo item | Q9: descripcion compr.ar | R9: unidad de medida
A10: 1 | C10: PROD. MEDICO/FARMACEUTICOS/LAB | D10: 252 | E10: ACICLOVIR 200 MG COMPRIMIDO | F10: ANTIVIRALES; TIPO: MONODROGA, DROGA GENERICA: ACICLOVIR, FORMA FARMACEUTICA: COMPRIMIDO, PRESENTACION: 200 mGr | G10: COMPRIMIDO | I10: 60.1 | J10: =+H10*I10 -> 0 | K10: ANTIVIRALES; TIPO: MONODROGA, DROGA GENERICA: ACICLOVIR, FORMA FARMACEUTICA: COMPRIMIDO, PRESENTACION: 200 mGr | L10: =K10=F10 -> TRUE | M10: =B11='[1]Necesidades Trimestrales'!B10 -> TRUE | N10: =F10='[1]Necesidades Trimestrales'!E10 -> TRUE | O10: =G10='[1]Necesidades Trimestrales'!F10 -> TRUE | P10: =B11='[2]Necesidades Trimestrales'!B10 -> TRUE | Q10: =F10='[2]Necesidades Trimestrales'!E10 -> TRUE | R10: =G10='[2]Necesidades Trimestrales'!F10 -> TRUE | S10: =+I10-'[2]Necesidades Trimestrales'!H10 -> 0
A11: 2 | B11: 2.5.2-1829.24 | C11: PROD. MEDICO/FARMACEUTICOS/LAB | D11: 252 | E11: ACICLOVIR 400 MG COMPRIMIDO | F11: ANTIVIRALES; TIPO: MONODROGA, DROGA GENERICA: ACICLOVIR, FORMA FARMACEUTICA: COMPRIMIDO, PRESENTACION: 400 mGr | G11: COMPRIMIDO | I11: 70.1 | J11: =+H11*I11 -> 0 | K11: ANTIVIRALES; TIPO: MONODROGA, DROGA GENERICA: ACICLOVIR, FORMA FARMACEUTICA: COMPRIMIDO, PRESENTACION: 400 mGr | L11: =K11=F11 -> TRUE | M11: =B12='[1]Necesidades Trimestrales'!B11 -> TRUE | N11: =F11='[1]Necesidades Trimestrales'!E11 -> TRUE | O11: =G11='[1]Necesidades Trimestrales'!F11 -> TRUE | P11: =B12='[2]Necesidades Trimestrales'!B11 -> TRUE | Q11: =F11='[2]Necesidades Trimestrales'!E11 -> TRUE | R11: =G11='[2]Necesidades Trimestrales'!F11 -> TRUE | S11: =+I11-'[2]Necesidades Trimestrales'!H11 -> 0
A12: 3 | B12: 2.5.2-1829.35 | C12: PROD. MEDICO/FARMACEUTICOS/LAB | D12: 252 | E12: ACICLOVIR 500 MG FCO AMPOLLA | F12: ANTIBIOTICOS P/PERSONAS; TIPO: MONODROGA, DROGA GENERICA: ACICLOVIR 500 MG, FORMA FARMACEUTICA: FRASCO AMPOLLA, PRESENTACION: 500 mGr | G12: AMPOLLA | I12: 450 | J12: =+H12*I12 -> 0 | K12: ANTIBIOTICOS P/PERSONAS; TIPO: MONODROGA, DROGA GENERICA: ACICLOVIR 500 MG, FORMA FARMACEUTICA: FRASCO AMPOLLA, PRESENTACION: 500 mGr | L12: =K12=F12 -> TRUE | M12: =B13='[1]Necesidades Trimestrales'!B12 -> TRUE | N12: =F12='[1]Necesidades Trimestrales'!E12 -> TRUE | O12: =G12='[1]Necesidades Trimestrales'!F12 -> TRUE | P12: =B13='[2]Necesidades Trimestrales'!B12 -> TRUE | Q12: =F12='[2]Necesidades Trimestrales'!E12 -> TRUE | R12: =G12='[2]Necesidades Trimestrales'!F12 -> TRUE | S12: =+I12-'[2]Necesidades Trimestrales'!H12 -> 0
A13: 4 | B13: 2.5.2-1821.235 | D13: 252 | E13: ACICLOVIR 80 MG/ML SUSPENSIÓN X 200ML | F13: ANTIVIRALES; TIPO: MONODROGA, DROGA GENERICA: ACICLOVIR 80 MG/ ML, FORMA FARMACEUTICA: SUSPENSION, PRESENTACION: ENVASE X 200 ML | G13: FRASCO | I13: 980 | J13: =+H13*I13 -> 0 | K13: ANTIVIRALES; TIPO: MONODROGA, DROGA GENERICA: ACICLOVIR 80 MG/ ML, FORMA FARMACEUTICA: SUSPENSION, PRESENTACION: ENVASE X 200 ML | L13: =K13=F13 -> TRUE | M13: =B14='[1]Necesidades Trimestrales'!B13 -> TRUE | N13: =F13='[1]Necesidades Trimestrales'!E13 -> TRUE | O13: =G13='[1]Necesidades Trimestrales'!F13 -> TRUE | P13: =B14='[2]Necesidades Trimestrales'!B13 -> TRUE | Q13: =F13='[2]Necesidades Trimestrales'!E13 -> TRUE | R13: =G13='[2]Necesidades Trimestrales'!F13 -> TRUE | S13: =+I13-'[2]Necesidades Trimestrales'!H13 -> 0
A14: 5 | B14: 2.5.2-1829.48 | C14: PROD. MEDICO/FARMACEUTICOS/LAB | D14: 252 | E14: ACIDO ACETIL SALICILICO 100 MG COMPRIMIDO | F14: ANALGESICOS ; TIPO: MONODROGA, DROGA GENERICA: ACIDO ACETILSALICILICO, PRESENTACION: 100 mGr, FORMA FARMACEUTICA: COMPRIMIDO | G14: COMPRIMIDO | I14: 1.55 | J14: =+H14*I14 -> 0 | K14: ANALGESICOS ; TIPO: MONODROGA, DROGA GENERICA: ACIDO ACETILSALICILICO, PRESENTACION: 100 mGr, FORMA FARMACEUTICA: COMPRIMIDO | L14: =K14=F14 -> TRUE | M14: =B15='[1]Necesidades Trimestrales'!B14 -> TRUE | N14: =F14='[1]Necesidades Trimestrales'!E14 -> TRUE | O14: =G14='[1]Necesidades Trimestrales'!F14 -> TRUE | P14: =B15='[2]Necesidades Trimestrales'!B14 -> TRUE | Q14: =F14='[2]Necesidades Trimestrales'!E14 -> TRUE | R14: =G14='[2]Necesidades Trimestrales'!F14 -> TRUE | S14: =+I14-'[2]Necesidades Trimestrales'!H14 -> 0
A15: 6 | B15: 2.5.2-1724.16 | C15: PROD. MEDICO/FARMACEUTICOS/LAB | D15: 252 | E15: ACIDO ACETIL SALICILICO 500 MG COMPRIMIDO | F15: ANALGESICOS ; PRESENTACION: 500 mGr, TIPO: MONODROGA, DROGA GENERICA: ACIDO ACETILSALICILICO, FORMA FARMACEUTICA: COMPRIMIDO | G15: COMPRIMIDO | I15: 2.01 | J15: =+H15*I15 -> 0 | K15: ANALGESICOS ; PRESENTACION: 500 mGr, TIPO: MONODROGA, DROGA GENERICA: ACIDO ACETILSALICILICO, FORMA FARMACEUTICA: COMPRIMIDO | L15: =K15=F15 -> TRUE | M15: =B16='[1]Necesidades Trimestrales'!B15 -> TRUE | N15: =F15='[1]Necesidades Trimestrales'!E15 -> TRUE | O15: =G15='[1]Necesidades Trimestrales'!F15 -> TRUE | P15: =B16='[2]Necesidades Trimestrales'!B15 -> TRUE | Q15: =F15='[2]Necesidades Trimestrales'!E15 -> TRUE | R15: =G15='[2]Necesidades Trimestrales'!F15 -> TRUE | S15: =+I15-'[2]Necesidades Trimestrales'!H15 -> 0
A16: 7 | B16: 2.5.2-1724.3 | C16: PROD. MEDICO/FARMACEUTICOS/LAB | D16: 252 | E16: ALLOPURINOL 300 MG COMPRIMIDO | F16: HIPOURICEMIANTES; TIPO: MONODROGA, DROGA GENERICA: ALOPURINOL 300 mGr, FORMA FARMACEUTICA: COMPRIMIDO, PRESENTACION: UNIDAD | G16: COMPRIMIDO | I16: 12.15 | J16: =+H16*I16 -> 0 | K16: HIPOURICEMIANTES; TIPO: MONODROGA, DROGA GENERICA: ALOPURINOL 300 mGr, FORMA FARMACEUTICA: COMPRIMIDO, PRESENTACION: UNIDAD | L16: =K16=F16 -> TRUE | M16: =B17='[1]Necesidades Trimestrales'!B16 -> TRUE | N16: =F16='[1]Necesidades Trimestrales'!E16 -> TRUE | O16: =G16='[1]Necesidades Trimestrales'!F16 -> TRUE | P16: =B17='[2]Necesidades Trimestrales'!B16 -> TRUE | Q16: =F16='[2]Necesidades Trimestrales'!E16 -> TRUE | R16: =G16='[2]Necesidades Trimestrales'!F16 -> TRUE | S16: =+I16-'[2]Necesidades Trimestrales'!H16 -> 0
A17: 8 | B17: 2.5.2-1864.6 | C17: PROD. MEDICO/FARMACEUTICOS/LAB | D17: 252 | E17: AMIKACINA 500 MG AMPOLLA | F17: ANTIBIOTICOS P/PERSONAS; TIPO: MONODROGA, DROGA GENERICA: AMIKACINA, PRESENTACION: 500 mGr, FORMA FARMACEUTICA: AMPOLLA | G17: AMPOLLA | I17: 87.95 | J17: =+H17*I17 -> 0 | K17: ANTIBIOTICOS P/PERSONAS; TIPO: MONODROGA, DROGA GENERICA: AMIKACINA, PRESENTACION: 500 mGr, FORMA FARMACEUTICA: AMPOLLA | L17: =K17=F17 -> TRUE | M17: =B18='[1]Necesidades Trimestrales'!B17 -> TRUE | N17: =F17='[1]Necesidades Trimestrales'!E17 -> TRUE | O17: =G17='[1]Necesidades Trimestrales'!F17 -> TRUE | P17: =B18='[2]Necesidades Trimestrales'!B17 -> TRUE | Q17: =F17='[2]Necesidades Trimestrales'!E17 -> TRUE | R17: =G17='[2]Necesidades Trimestrales'!F17 -> TRUE | S17: =+I17-'[2]Necesidades Trimestrales'!H17 -> 0
A18: 9 | B18: 2.5.2-1821.1 | D18: 252 | E18: AMOXICILINA 400 MG + ACIDO CLAVULANICO 57 MG SUSPENSIÓN x 70 ML | F18: ANTIBIOTICOS P/PERSONAS; TIPO: ASOCIACION, DROGA GENERICA: AMOXICILINA + AC.CLAVULANICO 400 MG / 57 MG, FORMA FARMACEUTICA: SUSPENSION, PRESENTACION: ENVASE X 70 ML | G18: FRASCO | I18: 374 | J18: =+H18*I18 -> 0 | K18: ANTIBIOTICOS P/PERSONAS; TIPO: ASOCIACION, DROGA GENERICA: AMOXICILINA + AC.CLAVULANICO 400 MG / 57 MG, FORMA FARMACEUTICA: SUSPENSION, PRESENTACION: ENVASE X 70 ML | L18: =K18=F18 -> TRUE | M18: =B19='[1]Necesidades Trimestrales'!B18 -> TRUE | N18: =F18='[1]Necesidades Trimestrales'!E18 -> TRUE | O18: =G18='[1]Necesidades Trimestrales'!F18 -> TRUE | P18: =B19='[2]Necesidades Trimestrales'!B18 -> TRUE | Q18: =F18='[2]Necesidades Trimestrales'!E18 -> TRUE | R18: =G18='[2]Necesidades Trimestrales'!F18 -> TRUE | S18: =+I18-'[2]Necesidades Trimestrales'!H18 -> 0
A19: 10 | B19: 2.5.2-1821.524 | C19: PROD. MEDICO/FARMACEUTICOS/LAB | D19: 252 | E19: AMOXICILINA + CLAVULANICO 1 G COMPRIMIDO | F19: ANTIBIOTICOS P/PERSONAS; TIPO: ASOCIACION, DROGA GENERICA: AMOXICIL. 875 MG+CLAVUL.125 MG mGr, FORMA FARMACEUTICA: COMPRIMIDO, PRESENTACION: UNIDAD | G19: COMPRIMIDO | I19: 29.5 | J19: =+H19*I19 -> 0 | K19: ANTIBIOTICOS P/PERSONAS; TIPO: ASOCIACION, DROGA GENERICA: AMOXICIL. 875 MG+CLAVUL.125 MG mGr, FORMA FARMACEUTICA: COMPRIMIDO, PRESENTACION: UNIDAD | L19: =K19=F19 -> TRUE | M19: =B20='[1]Necesidades Trimestrales'!B19 -> TRUE | N19: =F19='[1]Necesidades Trimestrales'!E19 -> TRUE | O19: =G19='[1]Necesidades Trimestrales'!F19 -> TRUE | P19: =B20='[2]Necesidades Trimestrales'!B19 -> TRUE | Q19: =F19='[2]Necesidades Trimestrales'!E19 -> TRUE | R19: =G19='[2]Necesidades Trimestrales'!F19 -> TRUE | S19: =+I19-'[2]Necesidades Trimestrales'!H19 -> 0
A20: 11 | B20: 2.5.2-1821.440 | C20: PROD. MEDICO/FARMACEUTICOS/LAB | D20: 252 | E20: AMOXICILINA 500 MG COMPRIMIDO | F20: ANTIBIOTICOS P/PERSONAS; TIPO: MONODROGA, DROGA GENERICA: AMOXICILINA, PRESENTACION: 500 mGr, FORMA FARMACEUTICA: COMPRIMIDOS | G20: COMPRIMIDO | I20: 7.85 | J20: =+H20*I20 -> 0 | K20: ANTIBIOTICOS P/PERSONAS; TIPO: MONODROGA, DROGA GENERICA: AMOXICILINA, PRESENTACION: 500 mGr, FORMA FARMACEUTICA: COMPRIMIDOS | L20: =K20=F20 -> TRUE | M20: =B21='[1]Necesidades Trimestrales'!B20 -> TRUE | N20: =F20='[1]Necesidades Trimestrales'!E20 -> TRUE | O20: =G20='[1]Necesidades Trimestrales'!F20 -> TRUE | P20: =B21='[2]Necesidades Trimestrales'!B20 -> TRUE | Q20: =F20='[2]Necesidades Trimestrales'!E20 -> TRUE | R20: =G20='[2]Necesidades Trimestrales'!F20 -> TRUE | S20: =+I20-'[2]Necesidades Trimestrales'!H20 -> 0
A21: 12 | B21: 2.5.2-1821.9 | C21: PROD. MEDICO/FARMACEUTICOS/LAB | D21: 252 | E21: AMOXICILINA 500 MG SUSPENSIÓN X 90 ML | F21: ANTIBIOTICOS P/PERSONAS; TIPO: MONODROGA, DROGA GENERICA: AMOXICILINA 500 mGr, FORMA FARMACEUTICA: SUSPENSION, PRESENTACION: ENVASE X 90 mL | G21: FRASCO | I21: 210 | J21: =+H21*I21 -> 0 | K21: ANTIBIOTICOS P/PERSONAS; TIPO: MONODROGA, DROGA GENERICA: AMOXICILINA 500 mGr, FORMA FARMACEUTICA: SUSPENSION, PRESENTACION: ENVASE X 90 mL | L21: =K21=F21 -> TRUE | M21: =B22='[1]Necesidades Trimestrales'!B21 -> TRUE | N21: =F21='[1]Necesidades Trimestrales'!E21 -> TRUE | O21: =G21='[1]Necesidades Trimestrales'!F21 -> TRUE | P21: =B22='[2]Necesidades Trimestrales'!B21 -> TRUE | Q21: =F21='[2]Necesidades Trimestrales'!E21 -> TRUE | R21: =G21='[2]Necesidades Trimestrales'!F21 -> TRUE | S21: =+I21-'[2]Necesidades Trimestrales'!H21 -> 0
A22: 13 | B22: 2.5.2-1821.399 | C22: PROD. MEDICO/FARMACEUTICOS/LAB | D22: 252 | E22: AMPICILINA + SULBACTAM 1,5 MG FCO AMPOLLA | F22: ANTIBIOTICOS P/PERSONAS; TIPO: ASOCIACION, DROGA GENERICA: AMPICILINA + SULBACTAN, FORMA FARMACEUTICA: FRASCO AMPOLLA, PRESENTACION: ENVASE X 1,5 GR | G22: AMPOLLA | I22: 138 | J22: =+H22*I22 -> 0 | K22: ANTIBIOTICOS P/PERSONAS; TIPO: ASOCIACION, DROGA GENERICA: AMPICILINA + SULBACTAN, FORMA FARMACEUTICA: FRASCO AMPOLLA, PRESENTACION: ENVASE X 1,5 GR | L22: =K22=F22 -> TRUE | M22: =B23='[1]Necesidades Trimestrales'!B22 -> TRUE | N22: =F22='[1]Necesidades Trimestrales'!E22 -> TRUE | O22: =G22='[1]Necesidades Trimestrales'!F22 -> TRUE | P22: =B23='[2]Necesidades Trimestrales'!B22 -> TRUE | Q22: =F22='[2]Necesidades Trimestrales'!E22 -> TRUE | R22: =G22='[2]Necesidades Trimestrales'!F22 -> TRUE | S22: =+I22-'[2]Necesidades Trimestrales'!H22 -> 0
A23: 14 | B23: 2.5.2-1821.389 | C23: PROD. MEDICO/FARMACEUTICOS/LAB | D23: 252 | E23: AMPICILINA 1G FCO AMPOLLA | F23: ANTIBIOTICOS P/PERSONAS; TIPO: MONODROGA, DROGA GENERICA: AMPICILINA, FORMA FARMACEUTICA: AMPOLLA, PRESENTACION: 1 GR | G23: AMPOLLA | I23: 99 | J23: =+H23*I23 -> 0 | K23: ANTIBIOTICOS P/PERSONAS; TIPO: MONODROGA, DROGA GENERICA: AMPICILINA, FORMA FARMACEUTICA: AMPOLLA, PRESENTACION: 1 GR | L23: =K23=F23 -> TRUE | M23: =B24='[1]Necesidades Trimestrales'!B23 -> TRUE | N23: =F23='[1]Necesidades Trimestrales'!E23 -> TRUE | O23: =G23='[1]Necesidades Trimestrales'!F23 -> TRUE | P23: =B24='[2]Necesidades Trimestrales'!B23 -> TRUE | Q23: =F23='[2]Necesidades Trimestrales'!E23 -> TRUE | R23: =G23='[2]Necesidades Trimestrales'!F23 -> TRUE | S23: =+I23-'[2]Necesidades Trimestrales'!H23 -> 0
A24: 15 | B24: 2.5.2-1821.8 | C24: PROD. MEDICO/FARMACEUTICOS/LAB | D24: 252 | E24: AMPICILINA 500 MG COMPRIMIDO | F24: ANTIBIOTICOS P/PERSONAS; TIPO: MONODROGA, DROGA GENERICA: AMPICILINA, FORMA FARMACEUTICA: COMPRIMIDOS, PRESENTACION: 500 mGr | G24: COMPRIMIDO | I24: 17.08 | J24: =+H24*I24 -> 0 | K24: ANTIBIOTICOS P/PERSONAS; TIPO: MONODROGA, DROGA GENERICA: AMPICILINA, FORMA FARMACEUTICA: COMPRIMIDOS, PRESENTACION: 500 mGr | L24: =K24=F24 -> TRUE | M24: =B25='[1]Necesidades Trimestrales'!B24 -> TRUE | N24: =F24='[1]Necesidades Trimestrales'!E24 -> TRUE | O24: =G24='[1]Necesidades Trimestrales'!F24 -> TRUE | P24: =B25='[2]Necesidades Trimestrales'!B24 -> TRUE | Q24: =F24='[2]Necesidades Trimestrales'!E24 -> TRUE | R24: =G24='[2]Necesidades Trimestrales'!F24 -> TRUE | S24: =+I24-'[2]Necesidades Trimestrales'!H24 -> 0
A25: 16 | B25: 2.5.2-1821.5 | D25: 252 | E25: ANFOTERICINA B LIPOSOMAL VIAL 50 MG | F25: ANTIMICOTICOS; DROGA GENERICA: ANFOTERICINA B LIPOSOMAL, FORMA FARMACEUTICA: AMPOLLA, PRESENTACION: 50 MGR, TIPO: MONODROGA | G25: AMPOLLA | I25: 25452 | J25: =+H25*I25 -> 0 | K25: ANTIMICOTICOS; DROGA GENERICA: ANFOTERICINA B LIPOSOMAL, FORMA FARMACEUTICA: AMPOLLA, PRESENTACION: 50 MGR, TIPO: MONODROGA | L25: =K25=F25 -> TRUE | M25: =B26='[1]Necesidades Trimestrales'!B25 -> TRUE | N25: =F25='[1]Necesidades Trimestrales'!E25 -> TRUE | O25: =G25='[1]Necesidades Trimestrales'!F25 -> TRUE | P25: =B26='[2]Necesidades Trimestrales'!B25 -> TRUE | Q25: =F25='[2]Necesidades Trimestrales'!E25 -> TRUE | R25: =G25='[2]Necesidades Trimestrales'!F25 -> TRUE | S25: =+I25-'[2]Necesidades Trimestrales'!H25 -> 0
A26: 17 | B26: 2.5.2-1823.113 | C26: PROD. MEDICO/FARMACEUTICOS/LAB | D26: 252 | E26: ANFOTERICINA B VIAL 50 MG | F26: ANTIMICOTICOS; DROGA GENERICA: ANFOTERICINA B, FORMA FARMACEUTICA: AMPOLLA, PRESENTACION: 50 mGr, TIPO: MONODROGA | G26: AMPOLLA | I26: 795 | J26: =+H26*I26 -> 0 | K26: ANTIMICOTICOS; DROGA GENERICA: ANFOTERICINA B, FORMA FARMACEUTICA: AMPOLLA, PRESENTACION: 50 mGr, TIPO: MONODROGA | L26: =K26=F26 -> TRUE | M26: =B27='[1]Necesidades Trimestrales'!B26 -> TRUE | N26: =F26='[1]Necesidades Trimestrales'!E26 -> TRUE | O26: =G26='[1]Necesidades Trimestrales'!F26 -> TRUE | P26: =B27='[2]Necesidades Trimestrales'!B26 -> TRUE | Q26: =F26='[2]Necesidades Trimestrales'!E26 -> TRUE | R26: =G26='[2]Necesidades Trimestrales'!F26 -> TRUE | S26: =+I26-'[2]Necesidades Trimestrales'!H26 -> 0
A27: 18 | B27: 2.5.2-1823.1 | C27: PROD. MEDICO/FARMACEUTICOS/LAB | D27: 252 | E27: AZITROMICINA 200 MG / 5 ML SUSPENSIÓN x 15 ML | F27: ANTIBIOTICOS P/PERSONAS; TIPO: MONODROGA, DROGA GENERICA: AZITROMICINA 200 mGr, FORMA FARMACEUTICA: SUSPENSION, PRESENTACION: ENVASE X 15 Ml | G27: FRASCO | I27: 310 | J27: =+H27*I27 -> 0 | K27: ANTIBIOTICOS P/PERSONAS; TIPO: MONODROGA, DROGA GENERICA: AZITROMICINA 200 mGr, FORMA FARMACEUTICA: SUSPENSION, PRESENTACION: ENVASE X 15 mL | L27: =K27=F27 -> TRUE | M27: =B28='[1]Necesidades Trimestrales'!B27 -> TRUE | N27: =F27='[1]Necesidades Trimestrales'!E27 -> TRUE | O27: =G27='[1]Necesidades Trimestrales'!F27 -> TRUE | P27: =B28='[2]Necesidades Trimestrales'!B27 -> TRUE | Q27: =F27='[2]Necesidades Trimestrales'!E27 -> TRUE | R27: =G27='[2]Necesidades Trimestrales'!F27 -> TRUE | S27: =+I27-'[2]Necesidades Trimestrales'!H27 -> 0
A28: 19 | B28: 2.5.2-1821.502 | D28: 252 | E28: ATRACURIUM 50 MG AMPOLLA | F28: BLOQUEANTES NEUROMUSCULARES; DROGA GENERICA: ATRACURIO, FORMA FARMACEUTICA: AMPOLLA, PRESENTACION: 50 mGr, TIPO: MONODROGA | G28: AMPOLLA | I28: 259 | J28: =+H28*I28 -> 0 | K28: BLOQUEANTES NEUROMUSCULARES; DROGA GENERICA: ATRACURIO, FORMA FARMACEUTICA: AMPOLLA, PRESENTACION: 50 mGr, TIPO: MONODROGA | L28: =K28=F28 -> TRUE | M28: =B29='[1]Necesidades Trimestrales'!B28 -> TRUE | N28: =F28='[1]Necesidades Trimestrales'!E28 -> TRUE | O28: =G28='[1]Necesidades Trimestrales'!F28 -> TRUE | P28: =B29='[2]Necesidades Trimestrales'!B28 -> TRUE | Q28: =F28='[2]Necesidades Trimestrales'!E28 -> TRUE | R28: =G28='[2]Necesidades Trimestrales'!F28 -> TRUE | S28: =+I28-'[2]Necesidades Trimestrales'!H28 -> 0
A29: 20 | B29: 2.5.2-2199.16 | C29: PROD. MEDICO/FARMACEUTICOS/LAB | D29: 252 | E29: AZITROMICINA 500 MG COMPRIMIDOS | F29: ANTIBIOTICOS P/PERSONAS; TIPO: MONODROGA, DROGA GENERICA: AZITROMICINA, FORMA FARMACEUTICA: COMPRIMIDO, PRESENTACION: 500 mGr | G29: COMPRIMIDO | I29: 36 | J29: =+H29*I29 -> 0 | K29: ANTIBIOTICOS P/PERSONAS; TIPO: MONODROGA, DROGA GENERICA: AZITROMICINA, FORMA FARMACEUTICA: COMPRIMIDO, PRESENTACION: 500 mGr | L29: =K29=F29 -> TRUE | M29: =B30='[1]Necesidades Trimestrales'!B29 -> TRUE | N29: =F29='[1]Necesidades Trimestrales'!E29 -> TRUE | O29: =G29='[1]Necesidades Trimestrales'!F29 -> TRUE | P29: =B30='[2]Necesidades Trimestrales'!B29 -> TRUE | Q29: =F29='[2]Necesidades Trimestrales'!E29 -> TRUE | R29: =G29='[2]Necesidades Trimestrales'!F29 -> TRUE | S29: =+I29-'[2]Necesidades Trimestrales'!H29 -> 0
A30: 21 | B30: 2.5.2-1821.94 | C30: PROD. MEDICO/FARMACEUTICOS/LAB | D30: 252 | E30: BACLOFENO 10 MG COMPRIMIDO | F30: HIPOTENSORES; TIPO: MONODROGA, DROGA GENERICA: BACLOFENO, FORMA FARMACEUTICA: COMPRIMIDO, PRESENTACION: 10 mGr | G30: COMPRIMIDO | I30: 15 | J30: =+H30*I30 -> 0 | K30: HIPOTENSORES; TIPO: MONODROGA, DROGA GENERICA: BACLOFENO, FORMA FARMACEUTICA: COMPRIMIDO, PRESENTACION: 10 mGr | L30: =K30=F30 -> TRUE | M30: =B31='[1]Necesidades Trimestrales'!B30 -> TRUE | N30: =F30='[1]Necesidades Trimestrales'!E30 -> TRUE | O30: =G30='[1]Necesidades Trimestrales'!F30 -> TRUE | P30: =B31='[2]Necesidades Trimestrales'!B30 -> TRUE | Q30: =F30='[2]Necesidades Trimestrales'!E30 -> TRUE | R30: =G30='[2]Necesidades Trimestrales'!F30 -> TRUE | S30: =+I30-'[2]Necesidades Trimestrales'!H30 -> 0
A31: 22 | B31: 2.5.2-1837.19 | D31: 252 | E31: BARIO SULFATO TIPO EZ-CAT SUSPENSION ORAL X 225 ML | F31: SOLUCIONES P/MEDICINA; TIPO: SULFATO DE BARIO, PRESENTACION: ENVASE SUSPENSION X 225 ML | G31: FRASCO | I31: 1680 | J31: =+H31*I31 -> 0 | K31: SOLUCIONES P/MEDICINA; TIPO: SULFATO DE BARIO, PRESENTACION: ENVASE SUSPENSION X 225 ML | L31: =K31=F31 -> TRUE | M31: =B32='[1]Necesidades Trimestrales'!B31 -> TRUE | N31: =F31='[1]Necesidades Trimestrales'!E31 -> TRUE | O31: =G31='[1]Necesidades Trimestrales'!F31 -> TRUE | P31: =B32='[2]Necesidades Trimestrales'!B31 -> TRUE | Q31: =F31='[2]Necesidades Trimestrales'!E31 -> TRUE | R31: =G31='[2]Necesidades Trimestrales'!F31 -> TRUE | S31: =+I31-'[2]Necesidades Trimestrales'!H31 -> 0
A32: 23 | B32: 2.5.2-1726.523 | D32: 252 | E32: BARIO SULFATO TIPO GASTROPAQUE F SUSPENSION PARA ENEMA x 500 ml | F32: SOLUCIONES P/MEDICINA; TIPO: SULFATO DE BARIO, PRESENTACION: ENVASE SUSPENSION PARA ENEMA X 500 ML | G32: FRASCO | I32: 2810 | J32: =+H32*I32 -> 0 | K32: SOLUCIONES P/MEDICINA; TIPO: SULFATO DE BARIO, PRESENTACION: ENVASE SUSPENSION PARA ENEMA X 500 ML | L32: =K32=F32 -> TRUE | M32: =B33='[1]Necesidades Trimestrales'!B32 -> TRUE | N32: =F32='[1]Necesidades Trimestrales'!E32 -> TRUE | O32: =G32='[1]Necesidades Trimestrales'!F32 -> TRUE | P32: =B33='[2]Necesidades Trimestrales'!B32 -> TRUE | Q32: =F32='[2]Necesidades Trimestrales'!E32 -> TRUE | R32: =G32='[2]Necesidades Trimestrales'!F32 -> TRUE | S32: =+I32-'[2]Necesidades Trimestrales'!H32 -> 0
A33: 24 | B33: 2.5.2-1726.524 | D33: 252 | E33: BARIO SULFATO TIPO GASTROPAQUE F SUSPENSION ORAL X 300 ML | F33: SOLUCIONES P/MEDICINA; TIPO: SULFATO DE BARIO, PRESENTACION: ENVASE SUSPENSION ORAL X 300 ML | G33: FRASCO | I33: 2350 | J33: =+H33*I33 -> 0 | K33: SOLUCIONES P/MEDICINA; TIPO: SULFATO DE BARIO, PRESENTACION: ENVASE SUSPENSION ORAL X 300 ML | L33: =K33=F33 -> TRUE | M33: =B34='[1]Necesidades Trimestrales'!B33 -> TRUE | N33: =F33='[1]Necesidades Trimestrales'!E33 -> TRUE | O33: =G33='[1]Necesidades Trimestrales'!F33 -> TRUE | P33: =B34='[2]Necesidades Trimestrales'!B33 -> TRUE | Q33: =F33='[2]Necesidades Trimestrales'!E33 -> TRUE | R33: =G33='[2]Necesidades Trimestrales'!F33 -> TRUE | S33: =+I33-'[2]Necesidades Trimestrales'!H33 -> 0
A34: 25 | B34: 2.5.2-1726.525 | C34: PROD. MEDICO/FARMACEUTICOS/LAB | D34: 252 | E34: BUPIVACAINA 0,5% C/EPINEFRINA FRASCO X 20 ML | F34: ANESTESICOS LOCALES; TIPO: ASOCIACION, DROGA GENERICA: BUPIVACAINA 0,5 % C/EPINEFRINA, FORMA FARMACEUTICA: FRASCO AMPOLLA, PRESENTACION: ENVASE X 20 mL | G34: FRASCO | I34: 3100 | J34: =+H34*I34 -> 0 | K34: ANESTESICOS LOCALES; TIPO: ASOCIACION, DROGA GENERICA: BUPIVACAINA 0,5 % C/EPINEFRINA, FORMA FARMACEUTICA: FRASCO AMPOLLA, PRESENTACION: ENVASE X 20 mL | L34: =K34=F34 -> TRUE | M34: =B35='[1]Necesidades Trimestrales'!B34 -> TRUE | N34: =F34='[1]Necesidades Trimestrales'!E34 -> TRUE | O34: =G34='[1]Necesidades Trimestrales'!F34 -> TRUE | P34: =B35='[2]Necesidades Trimestrales'!B34 -> TRUE | Q34: =F34='[2]Necesidades Trimestrales'!E34 -> TRUE | R34: =G34='[2]Necesidades Trimestrales'!F34 -> TRUE | S34: =+I34-'[2]Necesidades Trimestrales'!H34 -> 0
A35: 26 | B35: 2.5.2-1883.139 | C35: PROD. MEDICO/FARMACEUTICOS/LAB | D35: 252 | E35: BUPIVACAINA 0,5% S/EPINEFRINA FRASCO X 20 ML | F35: ANESTESICOS LOCALES; TIPO: MONODROGA, DROGA GENERICA: BUPIVACAINA 0,5 %, FORMA FARMACEUTICA: FRASCO, PRESENTACION: 20 mL | G35: FRASCO | I35: 490 | J35: =+H35*I35 -> 0 | K35: ANESTESICOS LOCALES; TIPO: MONODROGA, DROGA GENERICA: BUPIVACAINA 0,5 %, FORMA FARMACEUTICA: FRASCO, PRESENTACION: 20 mL | L35: =K35=F35 -> TRUE | M35: =B36='[1]Necesidades Trimestrales'!B35 -> TRUE | N35: =F35='[1]Necesidades Trimestrales'!E35 -> TRUE | O35: =G35='[1]Necesidades Trimestrales'!F35 -> TRUE | P35: =B36='[2]Necesidades Trimestrales'!B35 -> TRUE | Q35: =F35='[2]Necesidades Trimestrales'!E35 -> TRUE | R35: =G35='[2]Necesidades Trimestrales'!F35 -> TRUE | S35: =+I35-'[2]Necesidades Trimestrales'!H35 -> 0
A36: 27 | B36: 2.5.2-1883.24 | D36: 252 | E36: BUPIVACAINA 5 MG / ML HIBERBARICA AMPOLLA DE 4 ML CON AGUJA 27 G X 3 1/2 CON INTRODUCTOR | F36: ANESTESICOS LOCALES; TIPO: MONODROGA, DROGA GENERICA: BUPIVACAINA 0,5% HIPERBARICA, FORMA FARMACEUTICA: AMPOLLA, PRESENTACION: 4 ML CON AGUJA 27 G X 3 1/2 CON INTRODUCTOR | G36: AMPOLLA | I36: 1420 | J36: =+H36*I36 -> 0 | K36: ANESTESICOS LOCALES; TIPO: MONODROGA, DROGA GENERICA: BUPIVACAINA 0,5% HIPERBARICA, FORMA FARMACEUTICA: AMPOLLA, PRESENTACION: 4 ML CON AGUJA 27 G X 3 1/2 CON INTRODUCTOR | L36: =K36=F36 -> TRUE | M36: =B37='[1]Necesidades Trimestrales'!B36 -> TRUE | N36: =F36='[1]Necesidades Trimestrales'!E36 -> TRUE | O36: =G36='[1]Necesidades Trimestrales'!F36 -> TRUE | P36: =B37='[2]Necesidades Trimestrales'!B36 -> TRUE | Q36: =F36='[2]Necesidades Trimestrales'!E36 -> TRUE | R36: =G36='[2]Necesidades Trimestrales'!F36 -> TRUE | S36: =+I36-'[2]Necesidades Trimestrales'!H36 -> 0
A37: 28 | B37: 2.5.2-1883.188 | C37: PROD. MEDICO/FARMACEUTICOS/LAB | D37: 252 | E37: CEFALEXINA 500 MG COMPRIMIDOS | F37: ANTIBIOTICOS P/PERSONAS; TIPO: MONODROGA, DROGA GENERICA: CEFALEXINA 500 mGr, FORMA FARMACEUTICA: COMPRIMIDO, PRESENTACION: 1 UN | G37: COMPRIMIDO | I37: 13.9 | J37: =+H37*I37 -> 0 | K37: ANTIBIOTICOS P/PERSONAS; TIPO: MONODROGA, DROGA GENERICA: CEFALEXINA 500 mGr, FORMA FARMACEUTICA: COMPRIMIDO, PRESENTACION: 1 UN | L37: =K37=F37 -> TRUE | M37: =B38='[1]Necesidades Trimestrales'!B37 -> TRUE | N37: =F37='[1]Necesidades Trimestrales'!E37 -> TRUE | O37: =G37='[1]Necesidades Trimestrales'!F37 -> TRUE | P37: =B38='[2]Necesidades Trimestrales'!B37 -> TRUE | Q37: =F37='[2]Necesidades Trimestrales'!E37 -> TRUE | R37: =G37='[2]Necesidades Trimestrales'!F37 -> TRUE | S37: =+I37-'[2]Necesidades Trimestrales'!H37 -> 0
A38: 29 | B38: 2.5.2-1821.321 | C38: PROD. MEDICO/FARMACEUTICOS/LAB | D38: 252 | E38: CEFALEXINA 500 MG SUSPENSIÓN X 90 ML | F38: ANTIBIOTICOS P/PERSONAS; TIPO: MONODROGA, DROGA GENERICA: CEFALEXINA 500MG, FORMA FARMACEUTICA: SUSPENSION, PRESENTACION: ENVASE X 90 mL | G38: FRASCO | I38: 350 | J38: =+H38*I38 -> 0 | K38: ANTIBIOTICOS P/PERSONAS; TIPO: MONODROGA, DROGA GENERICA: CEFALEXINA 500MG, FORMA FARMACEUTICA: SUSPENSION, PRESENTACION: ENVASE X 90 mL | L38: =K38=F38 -> TRUE | M38: =B39='[1]Necesidades Trimestrales'!B38 -> TRUE | N38: =F38='[1]Necesidades Trimestrales'!E38 -> TRUE | O38: =G38='[1]Necesidades Trimestrales'!F38 -> TRUE | P38: =B39='[2]Necesidades Trimestrales'!B38 -> TRUE | Q38: =F38='[2]Necesidades Trimestrales'!E38 -> TRUE | R38: =G38='[2]Necesidades Trimestrales'!F38 -> TRUE | S38: =+I38-'[2]Necesidades Trimestrales'!H38 -> 0
A39: 30 | B39: 2.5.2-1821.337 | C39: PROD. MEDICO/FARMACEUTICOS/LAB | D39: 252 | E39: CEFALOTINA 1 GR. AMP. | F39: ANTIBIOTICOS P/PERSONAS; TIPO: MONODROGA, DROGA GENERICA: CEFALOTINA SODICA, FORMA FARMACEUTICA: FRASCO AMPOLLA, PRESENTACION: 1 GR | G39: AMPOLLA | I39: 145 | J39: =+H39*I39 -> 0 | K39: ANTIBIOTICOS P/PERSONAS; TIPO: MONODROGA, DROGA GENERICA: CEFALOTINA SODICA, FORMA FARMACEUTICA: FRASCO AMPOLLA, PRESENTACION: 1 GR | L39: =K39=F39 -> TRUE | M39: =B40='[1]Necesidades Trimestrales'!B39 -> TRUE | N39: =F39='[1]Necesidades Trimestrales'!E39 -> TRUE | O39: =G39='[1]Necesidades Trimestrales'!F39 -> TRUE | P39: =B40='[2]Necesidades Trimestrales'!B39 -> TRUE | Q39: =F39='[2]Necesidades Trimestrales'!E39 -> TRUE | R39: =G39='[2]Necesidades Trimestrales'!F39 -> TRUE | S39: =+I39-'[2]Necesidades Trimestrales'!H39 -> 0
A40: 31 | B40: 2.5.2-1821.405 | C40: PROD. MEDICO/FARMACEUTICOS/LAB | D40: 252 | E40: CEFAZOLINA 1GR FCO AMPOLLA | F40: ANTIBIOTICOS P/PERSONAS; TIPO: MONODROGA, DROGA GENERICA: CEFAZOLINA, FORMA FARMACEUTICA: AMPOLLA, PRESENTACION: 1 GR | G40: AMPOLLA | I40: 148 | J40: =+H40*I40 -> 0 | K40: ANTIBIOTICOS P/PERSONAS; TIPO: MONODROGA, DROGA GENERICA: CEFAZOLINA, FORMA FARMACEUTICA: AMPOLLA, PRESENTACION: 1 GR | L40: =K40=F40 -> TRUE | M40: =B41='[1]Necesidades Trimestrales'!B40 -> TRUE | N40: =F40='[1]Necesidades Trimestrales'!E40 -> TRUE | O40: =G40='[1]Necesidades Trimestrales'!F40 -> TRUE | P40: =B41='[2]Necesidades Trimestrales'!B40 -> TRUE | Q40: =F40='[2]Necesidades Trimestrales'!E40 -> TRUE | R40: =G40='[2]Necesidades Trimestrales'!F40 -> TRUE | S40: =+I40-'[2]Necesidades Trimestrales'!H40 -> 0
A41: 32 | B41: 2.5.2-1821.62 | C41: PROD. MEDICO/FARMACEUTICOS/LAB | D41: 252 | E41: CEFTAZIDIMA 1G FCO AMPOLLA | F41: ANTIBIOTICOS P/PERSONAS; TIPO: MONODROGA, DROGA GENERICA: CEFTAZIDIMA, FORMA FARMACEUTICA: FRASCO AMPOLLA, PRESENTACION: ENVASE X 1 GR | G41: AMPOLLA | I41: 144 | J41: =+H41*I41 -> 0 | K41: ANTIBIOTICOS P/PERSONAS; TIPO: MONODROGA, DROGA GENERICA: CEFTAZIDIMA, FORMA FARMACEUTICA: FRASCO AMPOLLA, PRESENTACION: ENVASE X 1 GR | L41: =K41=F41 -> TRUE | M41: =B42='[1]Necesidades Trimestrales'!B41 -> TRUE | N41: =F41='[1]Necesidades Trimestrales'!E41 -> TRUE | O41: =G41='[1]Necesidades Trimestrales'!F41 -> TRUE | P41: =B42='[2]Necesidades Trimestrales'!B41 -> TRUE | Q41: =F41='[2]Necesidades Trimestrales'!E41 -> TRUE | R41: =G41='[2]Necesidades Trimestrales'!F41 -> TRUE | S41: =+I41-'[2]Necesidades Trimestrales'!H41 -> 0
A42: 33 | B42: 2.5.2-1821.384 | C42: PROD. MEDICO/FARMACEUTICOS/LAB | D42: 252 | E42: CEFTRIAXONA 1 GR FCO AMPOLLA | F42: ANTIBIOTICOS P/PERSONAS; TIPO: MONODROGA, DROGA GENERICA: CEFTRIAXONA, FORMA FARMACEUTICA: FRASCO AMPOLLA, PRESENTACION: 1 GR | G42: AMPOLLA | I42: 130 | J42: =+H42*I42 -> 0 | K42: ANTIBIOTICOS P/PERSONAS; TIPO: MONODROGA, DROGA GENERICA: CEFTRIAXONA, FORMA FARMACEUTICA: FRASCO AMPOLLA, PRESENTACION: 1 GR | L42: =K42=F42 -> TRUE | M42: =B43='[1]Necesidades Trimestrales'!B42 -> TRUE | N42: =F42='[1]Necesidades Trimestrales'!E42 -> TRUE | O42: =G42='[1]Necesidades Trimestrales'!F42 -> TRUE | P42: =B43='[2]Necesidades Trimestrales'!B42 -> TRUE | Q42: =F42='[2]Necesidades Trimestrales'!E42 -> TRUE | R42: =G42='[2]Necesidades Trimestrales'!F42 -> TRUE | S42: =+I42-'[2]Necesidades Trimestrales'!H42 -> 0
...

Sheet  NotaPedido
A1: NOTA DE PEDIDO | J1: N° | K1: xxx/2022
A3: JURISDICCIÓN: | D3: ='Necesidades Trimestrales'!C4 -> 040 - Ministerio de Salud
A4: SAF: | D4: ='Necesidades Trimestrales'!C5 -> 11/ 23/ 24 o 28- "…......."
A5: UNIDAD EJECUTORA: | D5: XXXX
A6: DEPENDENCIA SOLICITANTE: | D6: XXXX
A7: PERIODO UTILIZACIÓN: | D7: Semestral
A8: OBJETO: | D8: Adquisición de TERAPIA ANTIINFECCIOSA SISTEMICA/SUEROS INMUNES E INMUNOGLOBULINAS Y MEDIOS DE CONTRASTES /ANALGESICOS ANTINFLAMATORIOS /MIORRELAJANTES/ANESTESICOS/ANALGESICOS OPIACIOS
A10: Ítem | B10: Codigo Item | C10: DESCRIPCIÓN | H10: Adjunta Detalle Técnico | I10: Unidad Medida | J10: Precio Unitario Estimado | K10: Cantidad Solicitada
A12: 1 | C12: =+'Necesidades Trimestrales'!E10 -> ACICLOVIR 200 MG COMPRIMIDO | H12: NO | I12: =+'Necesidades Trimestrales'!G10 -> COMPRIMIDO | J12: =+'Necesidades Trimestrales'!I10 -> 60.1 | K12: =+'Necesidades Trimestrales'!H10 -> 0
A13: 2 | C13: =+'Necesidades Trimestrales'!E11 -> ACICLOVIR 400 MG COMPRIMIDO | H13: NO | I13: =+'Necesidades Trimestrales'!G11 -> COMPRIMIDO | J13: =+'Necesidades Trimestrales'!I11 -> 70.1 | K13: =+'Necesidades Trimestrales'!H11 -> 0
A14: 3 | C14: =+'Necesidades Trimestrales'!E12 -> ACICLOVIR 500 MG FCO AMPOLLA | H14: NO | I14: =+'Necesidades Trimestrales'!G12 -> AMPOLLA | J14: =+'Necesidades Trimestrales'!I12 -> 450 | K14: =+'Necesidades Trimestrales'!H12 -> 0
A15: 4 | C15: =+'Necesidades Trimestrales'!E13 -> ACICLOVIR 80 MG/ML SUSPENSIÓN X 200ML | H15: NO | I15: =+'Necesidades Trimestrales'!G13 -> FRASCO | J15: =+'Necesidades Trimestrales'!I13 -> 980 | K15: =+'Necesidades Trimestrales'!H13 -> 0
A16: 5 | C16: =+'Necesidades Trimestrales'!E14 -> ACIDO ACETIL SALICILICO 100 MG COMPRIMIDO | H16: NO | I16: =+'Necesidades Trimestrales'!G14 -> COMPRIMIDO | J16: =+'Necesidades Trimestrales'!I14 -> 1.55 | K16: =+'Necesidades Trimestrales'!H14 -> 0
A17: 6 | C17: =+'Necesidades Trimestrales'!E15 -> ACIDO ACETIL SALICILICO 500 MG COMPRIMIDO | H17: NO | I17: =+'Necesidades Trimestrales'!G15 -> COMPRIMIDO | J17: =+'Necesidades Trimestrales'!I15 -> 2.01 | K17: =+'Necesidades Trimestrales'!H15 -> 0
A18: 7 | C18: =+'Necesidades Trimestrales'!E16 -> ALLOPURINOL 300 MG COMPRIMIDO | H18: NO | I18: =+'Necesidades Trimestrales'!G16 -> COMPRIMIDO | J18: =+'Necesidades Trimestrales'!I16 -> 12.15 | K18: =+'Necesidades Trimestrales'!H16 -> 0
A19: 8 | C19: =+'Necesidades Trimestrales'!E17 -> AMIKACINA 500 MG AMPOLLA | H19: NO | I19: =+'Necesidades Trimestrales'!G17 -> AMPOLLA | J19: =+'Necesidades Trimestrales'!I17 -> 87.95 | K19: =+'Necesidades Trimestrales'!H17 -> 0
A20: 9 | C20: =+'Necesidades Trimestrales'!E18 -> AMOXICILINA 400 MG + ACIDO CLAVULANICO 57 MG SUSPENSIÓN x 70 ML | H20: NO | I20: =+'Necesidades Trimestrales'!G18 -> FRASCO | J20: =+'Necesidades Trimestrales'!I18 -> 374 | K20: =+'Necesidades Trimestrales'!H18 -> 0
A21: 10 | C21: =+'Necesidades Trimestrales'!E19 -> AMOXICILINA + CLAVULANICO 1 G COMPRIMIDO | H21: NO | I21: =+'Necesidades Trimestrales'!G19 -> COMPRIMIDO | J21: =+'Necesidades Trimestrales'!I19 -> 29.5 | K21: =+'Necesidades Trimestrales'!H19 -> 0
A22: 11 | C22: =+'Necesidades Trimestrales'!E20 -> AMOXICILINA 500 MG COMPRIMIDO | H22: NO | I22: =+'Necesidades Trimestrales'!G20 -> COMPRIMIDO | J22: =+'Necesidades Trimestrales'!I20 -> 7.85 | K22: =+'Necesidades Trimestrales'!H20 -> 0
A23: 12 | C23: =+'Necesidades Trimestrales'!E21 -> AMOXICILINA 500 MG SUSPENSIÓN X 90 ML | H23: NO | I23: =+'Necesidades Trimestrales'!G21 -> FRASCO | J23: =+'Necesidades Trimestrales'!I21 -> 210 | K23: =+'Necesidades Trimestrales'!H21 -> 0
... A29: 18 | C29: =+'Necesidades Trimestrales'!E27 -> AZITROMICINA 200 MG / 5 ML SUSPENSIÓN x 15 ML | H29: NO | I29: =+'Necesidades Trimestrales'!G27 -> FRASCO | J29: =+'Necesidades Trimestrales'!I27 -> 310 | K29: =+'Necesidades Trimestrales'!H27 -> 0
A30: 19 | C30: =+'Necesidades Trimestrales'!E29 -> AZITROMICINA 500 MG COMPRIMIDOS | H30: NO | I30: =+'Necesidades Trimestrales'!G29 -> COMPRIMIDO | J30: =+'Necesidades Trimestrales'!I29 -> 36 | K30: =+'Necesidades Trimestrales'!H29 -> 0
A31: 20 | C31: =+'Necesidades Trimestrales'!E30 -> BACLOFENO 10 MG COMPRIMIDO | H31: NO | I31: =+'Necesidades Trimestrales'!G30 -> COMPRIMIDO | J31: =+'Necesidades Trimestrales'!I30 -> 15 | K31: =+'Necesidades Trimestrales'!H30 -> 0
A32: 21 | C32: =+'Necesidades Trimestrales'!E31 -> BARIO SULFATO TIPO EZ-CAT SUSPENSION ORAL X 225 ML | H32: NO | I32: =+'Necesidades Trimestrales'!G31 -> FRASCO | J32: =+'Necesidades Trimestrales'!I31 -> 1680 | K32: =+'Necesidades Trimestrales'!H31 -> 0
A33: 22 | C33: =+'Necesidades Trimestrales'!E32 -> BARIO SULFATO TIPO GASTROPAQUE F SUSPENSION PARA ENEMA x 500 ml | H33: NO | I33: =+'Necesidades Trimestrales'!G32 -> FRASCO | J33: =+'Necesidades Trimestrales'!I32 -> 2810 | K33: =+'Necesidades Trimestrales'!H32 -> 0
A34: 23 | C34: =+'Necesidades Trimestrales'!E33 -> BARIO SULFATO TIPO GASTROPAQUE F SUSPENSION ORAL X 300 ML | H34: NO | I34: =+'Necesidades Trimestrales'!G33 -> FRASCO | J34: =+'Necesidades Trimestrales'!I33 -> 2350 | K34: =+'Necesidades Trimestrales'!H33 -> 0
A35: 24 | C35: =+'Necesidades Trimestrales'!E34 -> BUPIVACAINA 0,5% C/EPINEFRINA FRASCO X 20 ML | H35: NO | I35: =+'Necesidades Trimestrales'!G34 -> FRASCO | J35: =+'Necesidades Trimestrales'!I34 -> 3100 | K35: =+'Necesidades Trimestrales'!H34 -> 0
A36: 25 | C36: =+'Necesidades Trimestrales'!E35 -> BUPIVACAINA 0,5% S/EPINEFRINA FRASCO X 20 ML | H36: NO | I36: =+'Necesidades Trimestrales'!G35 -> FRASCO | J36: =+'Necesidades Trimestrales'!I35 -> 490 | K36: =+'Necesidades Trimestrales'!H35 -> 0
A37: 26 | C37: =+'Necesidades Trimestrales'!E36 -> BUPIVACAINA 5 MG / ML HIBERBARICA AMPOLLA DE 4 ML CON AGUJA 27 G X 3 1/2 CON INTRODUCTOR | H37: NO | I37: =+'Necesidades Trimestrales'!G36 -> AMPOLLA | J37: =+'Necesidades Trimestrales'!I36 -> 1420 | K37: =+'Necesidades Trimestrales'!H36 -> 0
A38: 27 | C38: =+'Necesidades Trimestrales'!E37 -> CEFALEXINA 500 MG COMPRIMIDOS | H38: NO | I38: =+'Necesidades Trimestrales'!G37 -> COMPRIMIDO | J38: =+'Necesidades Trimestrales'!I37 -> 13.9 | K38: =+'Necesidades Trimestrales'!H37 -> 0
A39: 28 | C39: =+'Necesidades Trimestrales'!E38 -> CEFALEXINA 500 MG SUSPENSIÓN X 90 ML | H39: NO | I39: =+'Necesidades Trimestrales'!G38 -> FRASCO | J39: =+'Necesidades Trimestrales'!I38 -> 350 | K39: =+'Necesidades Trimestrales'!H38 -> 0
A40: 29 | C40: =+'Necesidades Trimestrales'!E39 -> CEFALOTINA 1 GR. AMP. | H40: NO | I40: =+'Necesidades Trimestrales'!G39 -> AMPOLLA | J40: =+'Necesidades Trimestrales'!I39 -> 145 | K40: =+'Necesidades Trimestrales'!H39 -> 0
A41: 30 | C41: =+'Necesidades Trimestrales'!E40 -> CEFAZOLINA 1GR FCO AMPOLLA | H41: NO | I41: =+'Necesidades Trimestrales'!G40 -> AMPOLLA | J41: =+'Necesidades Trimestrales'!I40 -> 148 | K41: =+'Necesidades Trimestrales'!H40 -> 0
... A58: 47 | C58: =+'Necesidades Trimestrales'!E57 -> DEXMEDETOMIDINA 200MG x 2 ml AMPOLLA | H58: NO | I58: =+'Necesidades Trimestrales'!G57 -> AMPOLLA | J58: =+'Necesidades Trimestrales'!I57 -> 490 | K58: =+'Necesidades Trimestrales'!H57 -> 0
A59: 48 | C59: DIATRIZOATO DE SODIO 25 GR X 50 ML ( TIPO TRIYOSOM 50) | H59: NO | I59: FRASCO | J59: 2358
A60: 49 | C60: =+'Necesidades Trimestrales'!E59 -> DIATRIZOATO DE MEGLUMINA + DIATRIZOATO DE SODIO (TIPO TRIYOSOM GI, TEMISTAC) X 120 ML SOLUCION ORAL Y RECTAL | H60: NO | I60: =+'Necesidades Trimestrales'!G59 -> AMPOLLA | J60: =+'Necesidades Trimestrales'!I59 -> 2890 | K60: =+'Necesidades Trimestrales'!H59 -> 0
A61: 50 | C61: =+'Necesidades Trimestrales'!E60 -> DICLOFENAC 75 MG COMPRIMIDOS | H61: NO | I61: =+'Necesidades Trimestrales'!G60 -> COMPRIMIDO | J61: =+'Necesidades Trimestrales'!I60 -> 3.05 | K61: =+'Necesidades Trimestrales'!H60 -> 0
A62: 51 | C62: =+'Necesidades Trimestrales'!E61 -> DICLOFENAC 75 MG. AMPOLLA | H62: NO | I62: =+'Necesidades Trimestrales'!G61 -> AMPOLLA | J62: =+'Necesidades Trimestrales'!I61 -> 35.9 | K62: =+'Necesidades Trimestrales'!H61 -> 0
A63: 52 | C63: =+'Necesidades Trimestrales'!E62 -> DICLOFENAC POTASICO 500MG/100ML JARABE X 120 | H63: NO | I63: =+'Necesidades Trimestrales'!G62 -> FRASCO | J63: =+'Necesidades Trimestrales'!I62 -> 158 | K63: =+'Necesidades Trimestrales'!H62 -> 0
A64: 53 | C64: =+'Necesidades Trimestrales'!E63 -> DIPIRONA 1GR AMPOLLA | H64: NO | I64: =+'Necesidades Trimestrales'!G63 -> AMPOLLA | J64: =+'Necesidades Trimestrales'!I63 -> 38.5 | K64: =+'Necesidades Trimestrales'!H63 -> 0
...

Sheet Autor Gastar
A1: EJERCICIO: | D1: ='Necesidades Trimestrales'!C6 -> 2022 | P1: AUTORIZACION PARA GASTAR
A4: JURISDICCIÓN: | G4: =' NotaPedido'!D3 -> 040 - Ministerio de Salud
A5: SAF: | G5: =' NotaPedido'!D4 -> 11/ 23/ 24 o 28- "…......."
A6: UNIDAD EJECUTORA: | G6: =' NotaPedido'!D5 -> XXXX
A7: DEPENDENCIA SOLICITANTE: | G7: =' NotaPedido'!D6 -> XXXX
A8: AUTORIZACIÓN:
A9: Señor Jefe de Servicio Administrativo Financiero:
A10: ="Autorizo la realización de los trámites correspondientes, a fin de proveer a este Organismo los bienes y/o servicios que se detallan en Nota de Pedido N° " & ' NotaPedido'!K1&", afectando la erogación resultante a los créditos presupuestarios aprobados a favor de esta Unidad Ejecutora, conforme al siguiente detalle:" -> Autorizo la realización de los trámites correspondientes, a fin de proveer a este Organismo los bienes y/o servicios que se detallan en Nota de Pedido N° xxx/2022, afectando la erogación resultante a los créditos presupuestarios aprobados a favor de esta Unidad Ejecutora, conforme al siguiente detalle:
A12: IMPUTACIÓN PRESUPUESTARIA
A13: CÓDIGO | O13: DENOMINACIÓN DE LA PARTIDA PRESUPUESTARIA | Q13: IMPORTE
A14: PR | B14: SB | C14: PY | D14: AC | E14: OB | F14: UG | G14: FIN | H14: FUN | I14: I | J14: P | K14: P | L14: SubP | M14: M | N14: FF
F15: 4901 | G15: 3 | H15: 310 | I15: 2 | J15: 5 | K15: 2 | M15: 1 | N15: 1.1
A23: TOTAL DE PESOS: xxxxxxxxxxxxxxx con 00/100. | Q23: =SUM(Q15:Q22) -> 0
A25: JUSTIFICACIÓN:
A26: Para la adquisición de .... … destinados al servico de …... del Hospital …...............
