Workbook

Sheet Necesidades Trimestrales
B2: Pedido de Necesidades Trimestrales
E3: QUIROFANO
A4: JURISDICCION: | C4: 40-Ministerio de Salud
A5: SAF N°: | C5: 28- Maternidad Provincial 25 de Mayo
A6: EJERCICIO: | C6: 2022
A7: TRIMESTRE: | C7: 4 Trimestre - 2022
A9: ID | B9: CODIGO ITEM | C9: RUBRO DE COMPRA | D9: I.P.P. | E9: DESCRIPCION | F9: UNIDAD DE MEDIDA | G9: CANTIDAD | H9: PRECIO UNITARIO ESTIMADO | I9: IMPORTE TOTAL ESTIMADO
A10: 1 | B10: 2.9.5-459.94 | C10: PROD. MEDICO/FARMACEUTICOS/LAB | D10: =LEFT(B10,5) -> 2.9.5 | E10: TIJERAS P/MEDICINA; TIPO: METZEMBAUNG, MEDIDA: 25 Cm, USO: CIRUGIA GENERAL | F10: unidad | G10: 5 | H10: 2960 | I10: =G10*H10 -> 14800
A11: 2 | B11: 2.9.5-6504.6 | C11: PROD. MEDICO/FARMACEUTICOS/LAB | D11: =LEFT(B11,5) -> 2.9.5 | E11: FRASCOS ASPIRADORES; USO: CIRUGIA GENERAL, PRESENTACION: FRASCO DE 3 L | F11: unidad | G11: 2 | H11: 6500 | I11: =G11*H11 -> 13000
A12: 3 | B12: 2.9.5-459.15 | C12: PROD. MEDICO/FARMACEUTICOS/LAB | D12: =LEFT(B12,5) -> 2.9.5 | E12: TIJERAS P/MEDICINA; TIPO: RECTA, MEDIDA: 17, MODELO: MAYO, USO: CIRUGIA, MODELO EQUIPO: MAYO | F12: unidad | G12: 10 | H12: 1815 | I12: =G12*H12 -> 18150
A13: 4 | B13: 2.9.5-472.72 | C13: PROD. MEDICO/FARMACEUTICOS/LAB | D13: =LEFT(B13,5) -> 2.9.5 | E13: PINZAS DE CIRUGIA; TIPO: KOCHER, MEDIDA: 18 Cm | F13: unidad | G13: 20 | H13: 1987 | I13: =G13*H13 -> 39740
A14: 5 | B14: 2.9.5-5769.41 | C14: PROD. MEDICO/FARMACEUTICOS/LAB | D14: =LEFT(B14,5) -> 2.9.5 | E14: PINZAS P/MEDICINA; USO: CIRUGIA GENERAL, TIPO: KOCHER, MEDIDA: 14 Cm | F14: unidad | G14: 20 | H14: 1355 | I14: =G14*H14 -> 27100
A15: 6 | B15: 2.9.5-472.6 | C15: PROD. MEDICO/FARMACEUTICOS/LAB | D15: =LEFT(B15,5) -> 2.9.5 | E15: PINZAS DE CIRUGIA; MEDIDA: 16 Cm, TIPO: DISECCION SIN DIENTE | F15: unidad | G15: 10 | H15: 750 | I15: =G15*H15 -> 7500
A16: 7 | B16: 2.9.5-5769.50 | C16: PROD. MEDICO/FARMACEUTICOS/LAB | D16: 2.9.5 | E16: PINZAS P/MEDICINA; USO: CIRUGIA GENERAL, TIPO: DISECCION, MEDIDA: 20 Cm | F16: unidad | G16: 10 | H16: 1128 | I16: =G16*H16 -> 11280
A17: 8 | B17: 2.9.5-5627.17 | C17: PROD. MEDICO/FARMACEUTICOS/LAB | D17: =LEFT(B17,5) -> 2.9.5 | E17: MANGOS DE BISTURI; TIPO: HOJA INTERCAMBIABLE, USO: DISECCION, CAMBIAR HOJAS: SI, NUMERO: 4, MATERIAL: ACERO INOXIDABLE | F17: unidad | G17: 10 | H17: 566 | I17: =G17*H17 -> 5660
A18: 9 | B18: 2.9.5-7791.1 | C18: PROD. MEDICO/FARMACEUTICOS/LAB | D18: =LEFT(B19,5) -> 2.9.5 | E18: ESPECULOS; MATERIAL: ACERO QUIRURGICO, TIPO: VAGINAL, PRESENTACION: UNIDAD | F18: unidad | G18: 3 | H18: 4990 | I18: =G18*H18 -> 14970
A19: 10 | B19: 2.9.5-7791.1 | C19: PROD. MEDICO/FARMACEUTICOS/LAB | D19: =LEFT(B16,5) -> 2.9.5 | E19: ESPECULOS; MATERIAL: ACERO QUIRURGICO, TIPO: VAGINAL, PRESENTACION: UNIDAD | F19: unidad | G19: 12 | H19: 4990 | I19: =G19*H19 -> 59880
A20: 11 | B20: 2.9.5-7791.1 | C20: PROD. MEDICO/FARMACEUTICOS/LAB | D20: =LEFT(B17,5) -> 2.9.5 | E20: ESPECULOS; MATERIAL: ACERO QUIRURGICO, TIPO: VAGINAL, PRESENTACION: UNIDAD | F20: unidad | G20: 5 | H20: 4990 | I20: =G20*H20 -> 24950
A21: 12 | B21: 2.9.5-8874.110 | C21: PROD. MEDICO/FARMACEUTICOS/LAB | D21: =LEFT(B18,5) -> 2.9.5 | E21: INSTRUMENTAL MEDICO; DESCARTABLE: NO, MATERIAL: ACERO QUIRURGICO, ELEMENTO: LEGRA CURVA | F21: unidad | G21: 4 | H21: 5308 | I21: =G21*H21 -> 21232
A22: 13 | B22: 2.9.5-6337.7 | C22: PROD. MEDICO/FARMACEUTICOS/LAB | D22: =LEFT(B19,5) -> 2.9.5 | E22: PORTA AGUJAS; MATERIAL: ACERO QUIRURGICO, TAMAÑO: 16 Cm, PRESENTACION: UNIDAD | F22: unidad | G22: 10 | H22: 1880 | I22: =G22*H22 -> 18800
A23: 14 | B23: 2.9.5-5512.12 | C23: PROD. MEDICO/FARMACEUTICOS/LAB | D23: =LEFT(B20,5) -> 2.9.5 | E23: CAJAS P/ESTERILIZAR; MATERIAL: ACERO QUIRURGICO, TIPO: LISA, DIMENSION: 25 X 15 X 5 Cm | F23: unidad | G23: 5 | H23: 8986 | I23: =G23*H23 -> 44930
A24: 15 | B24: 2.9.5-5512.12 | C24: PROD. MEDICO/FARMACEUTICOS/LAB | D24: =LEFT(B21,5) -> 2.9.5 | E24: CAJAS P/ESTERILIZAR; MATERIAL: ACERO QUIRURGICO, TIPO: LISA, DIMENSION: 25 X 15 X 5 Cm | F24: unidad | G24: 5 | H24: 8986 | I24: =G24*H24 -> 44930
A25: 16 | B25: 2.9.5-5512.12 | C25: PROD. MEDICO/FARMACEUTICOS/LAB | D25: =LEFT(B22,5) -> 2.9.5 | E25: CAJAS P/ESTERILIZAR; MATERIAL: ACERO QUIRURGICO, TIPO: LISA, DIMENSION: 25 X 15 X 5 Cm | F25: unidad | G25: 10 | H25: 9986 | I25: =G25*H25 -> 99860
A26: 17 | B26: 2.9.5-5512.4 | C26: PROD. MEDICO/FARMACEUTICOS/LAB | D26: =LEFT(B28,5) -> 2.9.5 | E26: CAJAS P/ESTERILIZAR; MATERIAL: ACERO QUIRURGICO, TIPO: PERFORADA, DIMENSION: 16,5 X 26,7 X 32 Cm | F26: unidad | G26: 5 | H26: 20897 | I26: =G26*H26 -> 104485
A27: 18 | B27: 2.9.5-8142.7 | C27: PROD. MEDICO/FARMACEUTICOS/LAB | D27: =LEFT(B30,5) -> 2.9.5 | E27: VALVAS; MATERIAL: ACERO QUIRURGICO, TIPO: FINOCCHIETO, ANCHO: 6 Cm | F27: unidad | G27: 2 | H27: 14916 | I27: =G27*H27 -> 29832
A28: 19 | B28: 2.9.5-8142.4 | C28: PROD. MEDICO/FARMACEUTICOS/LAB | D28: =LEFT(B29,5) -> 2.9.5 | E28: VALVAS; MATERIAL: ACERO QUIRURGICO , TIPO: DOYEN, ANCHO: 15 Cm | F28: unidad | G28: 2 | H28: 10700 | I28: =G28*H28 -> 21400
A29: 20 | B29: 2.9.5-8142.3 | C29: PROD. MEDICO/FARMACEUTICOS/LAB | D29: =LEFT(B31,5) -> 2.9.5 | E29: VALVAS; MATERIAL: ACERO QUIRURGICO , TIPO: BREISKY MEDIANA, ANCHO: 10 Cm | F29: unidad | G29: 2 | H29: 13987 | I29: =G29*H29 -> 27974
A30: 21 | B30: 2.9.5-8142.2 | C30: PROD. MEDICO/FARMACEUTICOS/LAB | D30: =LEFT(B32,5) -> 2.9.5 | E30: VALVAS; MATERIAL: ACERO QUIRURGICO , TIPO: BREISKY CHICA, ANCHO: 6 Cm | F30: unidad | G30: 2 | H30: 12976 | I30: =G30*H30 -> 25952
A31: 22 | B31: 2.9.5-472.70 | C31: PROD. MEDICO/FARMACEUTICOS/LAB | D31: =LEFT(B34,5) -> 2.9.5 | E31: PINZAS DE CIRUGIA; TIPO: DE PEAN, MEDIDA: GRANDE | F31: unidad | G31: 10 | H31: 4202 | I31: =G31*H31 -> 42020
A32: 23 | B32: 2.9.5-472.336 | C32: PROD. MEDICO/FARMACEUTICOS/LAB | D32: =LEFT(B33,5) -> 2.9.5 | E32: PINZAS DE CIRUGIA; TIPO: PEAN, MEDIDA: 16 Cm | F32: unidad | G32: 10 | H32: 1803 | I32: =G32*H32 -> 18030
A33: 24 | B33: 2.9.5-472.242 | C33: PROD. MEDICO/FARMACEUTICOS/LAB | D33: =LEFT(B34,5) -> 2.9.5 | E33: PINZAS DE CIRUGIA; TIPO: DOBLE UTILIDAD , MEDIDA: 24 Cm | F33: unidad | G33: 4 | H33: 6500 | I33: =G33*H33 -> 26000
A34: 25 | B34: 2.9.5-472.241 | C34: PROD. MEDICO/FARMACEUTICOS/LAB | D34: =LEFT(B35,5) -> 2.9.5 | E34: PINZAS DE CIRUGIA; TIPO: DOBLE UTILIDAD , MEDIDA: 18 Cm | F34: unidad | G34: 4 | H34: 4000 | I34: =G34*H34 -> 16000
A35: 26 | B35: 2.9.5-8430.2 | C35: PROD. MEDICO/FARMACEUTICOS/LAB | D35: =LEFT(B14,5) -> 2.9.5 | E35: HISTEROMETROS; TIPO: NO DESCARTABLE, MATERIAL: METAL, USO: MEDICION CANAL UTERINO | F35: unidad | G35: 6 | H35: 2620 | I35: =G35*H35 -> 15720
I36: =SUM(I10:I35) -> 794195
B37: Especificidades Item N° 1 AL 26
B38: Descripción técnica
B39: Plazos y lugares de entrega | C39: 10 DIAS HABILES -SERVICIO DE QUIROFANO. Maternidad Provincial 25 de Mayo - H de Pedraza 1500
B41: Calidad Minima esperada
B42: Mantenimiento | C42: 30 DIAS HABILES
B44: Garantia | C44: 1 AÑO
...

Sheet  NotaPedido
A1: NOTA DE PEDIDO | F1: N° | G1: 00/2022
A3: JURISDICCIÓN: | C3: =+'Necesidades Trimestrales'!C4:E4 -> 40-Ministerio de Salud
A4: SAF: | C4: ='[1]Necesidades Trimestrales'!C5 -> 28- Maternidad Provincial 25 de Mayo
A5: UNIDAD EJECUTORA: | C5: 169-Direccion Asistencial
A6: DEPENDENCIA SOLICITANTE: | C6: Servicio de Quirófano
A7: PERIODO UTILIZACIÓN: | C7: ='Necesidades Trimestrales'!C7 -> 4 Trimestre - 2022
A8: OBJETO: | C8: Instrumentos de Trabajo para quirofano
A10: Ítem | B10: Codigo Item | C10: DESCRIPCIÓN | D10: Adjunta Detalle Técnico | E10: Unidad Medida | F10: Precio Unitario Estimado | G10: Cantidad Solicitada
A12: ='Necesidades Trimestrales'!A10 -> 1 | B12: ='Necesidades Trimestrales'!B10 -> 2.9.5-459.94 | C12: ='Necesidades Trimestrales'!E10 -> TIJERAS P/MEDICINA; TIPO: METZEMBAUNG, MEDIDA: 25 Cm, USO: CIRUGIA GENERAL | D12: SI | E12: ='Necesidades Trimestrales'!F10 -> unidad | F12: ='Necesidades Trimestrales'!H10 -> 2960 | G12: ='Necesidades Trimestrales'!G10 -> 5
A13: ='Necesidades Trimestrales'!A11 -> 2 | B13: ='Necesidades Trimestrales'!B11 -> 2.9.5-6504.6 | C13: ='Necesidades Trimestrales'!E11 -> FRASCOS ASPIRADORES; USO: CIRUGIA GENERAL, PRESENTACION: FRASCO DE 3 L | D13: SI | E13: ='Necesidades Trimestrales'!F11 -> unidad | F13: ='Necesidades Trimestrales'!H11 -> 6500 | G13: ='Necesidades Trimestrales'!G11 -> 2
A14: ='Necesidades Trimestrales'!A12 -> 3 | B14: ='Necesidades Trimestrales'!B12 -> 2.9.5-459.15 | C14: ='Necesidades Trimestrales'!E12 -> TIJERAS P/MEDICINA; TIPO: RECTA, MEDIDA: 17, MODELO: MAYO, USO: CIRUGIA, MODELO EQUIPO: MAYO | D14: SI | E14: ='Necesidades Trimestrales'!F12 -> unidad | F14: ='Necesidades Trimestrales'!H12 -> 1815 | G14: ='Necesidades Trimestrales'!G12 -> 10
A15: ='Necesidades Trimestrales'!A13 -> 4 | B15: ='Necesidades Trimestrales'!B13 -> 2.9.5-472.72 | C15: ='Necesidades Trimestrales'!E13 -> PINZAS DE CIRUGIA; TIPO: KOCHER, MEDIDA: 18 Cm | D15: SI | E15: ='Necesidades Trimestrales'!F13 -> unidad | F15: ='Necesidades Trimestrales'!H13 -> 1987 | G15: ='Necesidades Trimestrales'!G13 -> 20
A16: ='Necesidades Trimestrales'!A14 -> 5 | B16: ='Necesidades Trimestrales'!B14 -> 2.9.5-5769.41 | C16: ='Necesidades Trimestrales'!E14 -> PINZAS P/MEDICINA; USO: CIRUGIA GENERAL, TIPO: KOCHER, MEDIDA: 14 Cm | D16: SI | E16: ='Necesidades Trimestrales'!F14 -> unidad | F16: ='Necesidades Trimestrales'!H14 -> 1355 | G16: ='Necesidades Trimestrales'!G14 -> 20
A17: ='Necesidades Trimestrales'!A15 -> 6 | B17: ='Necesidades Trimestrales'!B15 -> 2.9.5-472.6 | C17: ='Necesidades Trimestrales'!E15 -> PINZAS DE CIRUGIA; MEDIDA: 16 Cm, TIPO: DISECCION SIN DIENTE | D17: SI | E17: ='Necesidades Trimestrales'!F15 -> unidad | F17: ='Necesidades Trimestrales'!H15 -> 750 | G17: ='Necesidades Trimestrales'!G15 -> 10
A18: ='Necesidades Trimestrales'!A16 -> 7 | B18: ='Necesidades Trimestrales'!B16 -> 2.9.5-5769.50 | C18: ='Necesidades Trimestrales'!E16 -> PINZAS P/MEDICINA; USO: CIRUGIA GENERAL, TIPO: DISECCION, MEDIDA: 20 Cm | D18: SI | E18: ='Necesidades Trimestrales'!F16 -> unidad | F18: ='Necesidades Trimestrales'!H16 -> 1128 | G18: ='Necesidades Trimestrales'!G16 -> 10
A19: ='Necesidades Trimestrales'!A17 -> 8 | B19: ='Necesidades Trimestrales'!B17 -> 2.9.5-5627.17 | C19: ='Necesidades Trimestrales'!E17 -> MANGOS DE BISTURI; TIPO: HOJA INTERCAMBIABLE, USO: DISECCION, CAMBIAR HOJAS: SI, NUMERO: 4, MATERIAL: ACERO INOXIDABLE | D19: SI | E19: ='Necesidades Trimestrales'!F17 -> unidad | F19: ='Necesidades Trimestrales'!H17 -> 566 | G19: ='Necesidades Trimestrales'!G17 -> 10
A20: ='Necesidades Trimestrales'!A18 -> 9 | B20: ='Necesidades Trimestrales'!B18 -> 2.9.5-7791.1 | C20: ='Necesidades Trimestrales'!E18 -> ESPECULOS; MATERIAL: ACERO QUIRURGICO, TIPO: VAGINAL, PRESENTACION: UNIDAD | D20: SI | E20: ='Necesidades Trimestrales'!F18 -> unidad | F20: ='Necesidades Trimestrales'!H18 -> 4990 | G20: ='Necesidades Trimestrales'!G18 -> 3
A21: ='Necesidades Trimestrales'!A19 -> 10 | B21: ='Necesidades Trimestrales'!B19 -> 2.9.5-7791.1 | C21: ='Necesidades Trimestrales'!E19 -> ESPECULOS; MATERIAL: ACERO QUIRURGICO, TIPO: VAGINAL, PRESENTACION: UNIDAD | D21: SI | E21: ='Necesidades Trimestrales'!F19 -> unidad | F21: ='Necesidades Trimestrales'!H19 -> 4990 | G21: ='Necesidades Trimestrales'!G19 -> 12
A22: ='Necesidades Trimestrales'!A20 -> 11 | B22: ='Necesidades Trimestrales'!B20 -> 2.9.5-7791.1 | C22: ='Necesidades Trimestrales'!E20 -> ESPECULOS; MATERIAL: ACERO QUIRURGICO, TIPO: VAGINAL, PRESENTACION: UNIDAD | D22: SI | E22: ='Necesidades Trimestrales'!F20 -> unidad | F22: ='Necesidades Trimestrales'!H20 -> 4990 | G22: ='Necesidades Trimestrales'!G20 -> 5
A23: ='Necesidades Trimestrales'!A21 -> 12 | B23: ='Necesidades Trimestrales'!B21 -> 2.9.5-8874.110 | C23: ='Necesidades Trimestrales'!E21 -> INSTRUMENTAL MEDICO; DESCARTABLE: NO, MATERIAL: ACERO QUIRURGICO, ELEMENTO: LEGRA CURVA | D23: SI | E23: ='Necesidades Trimestrales'!F21 -> unidad | F23: ='Necesidades Trimestrales'!H21 -> 5308 | G23: ='Necesidades Trimestrales'!G21 -> 4
... A37: ='Necesidades Trimestrales'!A35 -> 26 | B37: ='Necesidades Trimestrales'!B35 -> 2.9.5-8430.2 | C37: ='Necesidades Trimestrales'!E35 -> HISTEROMETROS; TIPO: NO DESCARTABLE, MATERIAL: METAL, USO: MEDICION CANAL UTERINO | D37: SI | E37: ='Necesidades Trimestrales'!F35 -> unidad | F37: ='Necesidades Trimestrales'!H35 -> 2620 | G37: ='Necesidades Trimestrales'!G35 -> 6
A38: Costo total estimado: SETECIENTOS NOVENTA Y CUATRO MIL CIENTO NOVENTA Y CINCO 00/100 | F38: =SUMPRODUCT(G12:G37,F12:F37) -> 794195

Sheet Autor Gastar
A1: EJERCICIO: | D1: 2022 | P1: AUTORIZACION PARA GASTAR
A4: JURISDICCIÓN: | G4: 40-Ministerio de Salud
A5: SAF: | G5: 28- Maternidad Provincial 25 de Mayo
A6: UNIDAD EJECUTORA: | G6: 169-Direccion Asistencial
A7: DEPENDENCIA SOLICITANTE: | G7: Servicio de Quirófano
A8: AUTORIZACIÓN:
A9: Señor Jefe de Servicio Administrativo Financiero:
A10: ="Autorizo la realización de los trámites correspondientes, a fin de proveer a este Organismo los bienes y/o servicios que se detallan en Nota de Pedido N° " & ' NotaPedido'!G1&", afectando la erogación resultante a los créditos presupuestarios aprobados a favor de esta Unidad Ejecutora, conforme al siguiente detalle:" -> Autorizo la realización de los trámites correspondientes, a fin de proveer a este Organismo los bienes y/o servicios que se detallan en Nota de Pedido N° 00/2022, afectando la erogación resultante a los créditos presupuestarios aprobados a favor de esta Unidad Ejecutora, conforme al siguiente detalle:
A12: IMPUTACIÓN PRESUPUESTARIA
A13: CÓDIGO | O13: DENOMINACIÓN DE LA PARTIDA PRESUPUESTARIA | Q13: IMPORTE
A14: PR | B14: SB | C14: PY | D14: AC | E14: OB | F14: UG | G14: FIN | H14: FUN | I14: I | J14: P | K14: P | L14: SubP | M14: M | N14: FF
A15: 42 | D15: 2 | F15: 4901 | G15: 3 | H15: 1 | I15: 2 | J15: 9 | K15: 5 | M15: 1 | N15: 1.1 | O15: Utiles Menores Médico, Quirúrgico y de Laboratorio | Q15: 794195
A19: TOTAL DE PESOS: SETECIENTOS NOVENTA Y CUATRO MIL CIENTO NOVENTA Y CINCO 00/100 | Q19: =SUM(Q15:Q18) -> 794195
A21: JUSTIFICACIÓN:
A22: Para la adquisición de Instrumental para quirofano de la Maternidad Provincial 25 de Mayo
