Workbook

Sheet SAF 011 - NECESIDAD TRIMESTRAL
A1: 2022
B2: Pedido de Necesidades Trimestrales
A4: JURISDICCION: | C4: 040 - MINISTERIO DE SALUD
A5: SAF N°: | C5: 011 - DIRECCION PROVINCIAL DE ADMINISTRACION - MINISTERIO DE SALUD
A6: EJERCICIO: | C6: 2022
A7: TRIMESTRE: | C7: SEGUNDO
A9: ID | B9: CODIGO ITEM | C9: RUBRO DE COMPRA | D9: I.P.P. | E9: DESCRIPCION | F9: UNIDAD DE MEDIDA | G9: SECRETARIA DE ADMINISTRACION | H9: TOTAL S.A. | I9: SMPyPS | J9: TOTAL SMPyPS | K9: DIR. LAB. CENTRAL | L9: TOTAL DE LAB CENTRAL | M9: BCO DE SANGRE | N9: TOTAL BANCO DE SANGRE | O9: APS | P9: TOTAL A.P.S. | Q9: DIR DE CANCER | R9: TOTAL DE DIR DE CANCER | S9: FARMACIA | T9: TOTAL FARMACIA | U9: ODONTOLOGIA | V9: TOTAL DE ODONTOLOG | W9: SAME | X9: TOTAL SAME | Y9: HPTAL MALBRAN | Z9: TOTAL HPTAL MALBRAN | AA9: MATERNIDAD E INFANCIA | AB9: TOTAL MATERNIDAD E INFANCIA | AC9: SASP | AD9: TOTAL SASP | AE9: SALUD Y MEDIO AMBIENTE | AF9: TOTAL SALUD Y MEDIO AMBIENTE | AG9: VECTORES Y ZOONOSIS | AH9: TOTAL DE VECT Y ZOON | AI9: CRONICAS | AJ9: TOTAL CRONICAS | AK9: CUR | AL9: TOTAL CUR | AM9: SPyGS | AN9: TOTAL SPyGS | AO9: SALUD MENTAL | AP9: TOTAL SALUD MENTAL | AQ9: AREAS Y DPAS | AR9: TOTAL DPAS | AS9: EPIDEMIOLOGIA | AT9: TOTAL EPIDEMIOLOGIA | AU9: MS | AV9: TOTAL MS | AW9: CANTIDAD TOTAL | AX9: PRECIO UNITARIO ESTIMADO | AY9: IMPORTE TOTAL ESTIMADO | AZ9: ESPECIFICACION TECNICA
A10: 1 | C10: PROD. MEDICO/FARMACEUTICOS/LAB. | D10: 2.9.5. | E10: ANSA CALIBRADA PS DE 10 ul ESTERIL-ENVASE INDIVIDUAL X 20 U Tipo DELTALAB | F10: BOLSA | K10: 50 | L10: =+K10*AX10 -> 32000 | N10: =+M10*AX10 -> 0 | AF10: =+AE10*AX10 -> 0 | AL10: =+AK10*AX10 -> 0 | AW10: =+AQ10+AO10+AM10+AK10+AI10+AG10+AE10+AC10+AA10+Y10+W10+U10+S10+Q10+O10+M10+K10+I10+AS10+G10+AU10 -> 50 | AX10: 640 | AY10: =+AW10*AX10 -> 32000
A11: 2 | C11: PROD. MEDICO/FARMACEUTICOS/LAB. | D11: 2.9.5. | E11: APOSITOS; TIPO: POST EXTRACCION SANGUINEA, TAMAÑO: 40 X 40 mm | F11: CAJA | L11: =+K11*AX11 -> 0 | M11: 50 | N11: =+M11*AX11 -> 35100 | AF11: =+AE11*AX11 -> 0 | AL11: =+AK11*AX11 -> 0 | AW11: =+AQ11+AO11+AM11+AK11+AI11+AG11+AE11+AC11+AA11+Y11+W11+U11+S11+Q11+O11+M11+K11+I11+AS11+G11+AU11 -> 50 | AX11: 702 | AY11: =+AW11*AX11 -> 35100
A12: 3 | C12: PROD. MEDICO/FARMACEUTICOS/LAB | D12: 2.9.5 | E12: BOLSAS COLECTORAS; TIPO: ESTERIL, USO: MUESTREO, CAPACIDAD: 400 mL | F12: UNIDAD | L12: =+K12*AX12 -> 0 | N12: =+M12*AX12 -> 0 | AE12: 10 | AF12: =+AE12*AX12 -> 44500 | AW12: =+AQ12+AO12+AM12+AK12+AI12+AG12+AE12+AC12+AA12+Y12+W12+U12+S12+Q12+O12+M12+K12+I12+AS12+G12+AU12 -> 10 | AX12: 4450 | AY12: =+AW12*AX12 -> 44500
A13: 4 | C13: PROD. MEDICO/FARMACEUTICOS/LAB. | D13: 2.9.5. | E13: BOLSAS DE SANGRE TRIPLE KS | F13: UNIDAD | L13: =+K13*AX13 -> 0 | M13: 1794 | N13: =+M13*AX13 -> 1964430 | AF13: =+AE13*AX13 -> 0 | AL13: =+AK13*AX13 -> 0 | AW13: =+AQ13+AO13+AM13+AK13+AI13+AG13+AE13+AC13+AA13+Y13+W13+U13+S13+Q13+O13+M13+K13+I13+AS13+G13+AU13 -> 1794 | AX13: 1095 | AY13: =+AW13*AX13 -> 1964430
A14: 5 | C14: PROD. MEDICO/FARMACEUTICOS/LAB. | D14: 2.9.5. | E14: BOLSAS DE SANGRE TRIPLE KS TIPO GRIFOLS | F14: UNIDAD | L14: =+K14*AX14 -> 0 | M14: =1800+1794 -> 3594 | N14: =+M14*AX14 -> 4276860 | AF14: =+AE14*AX14 -> 0 | AL14: =+AK14*AX14 -> 0 | AW14: =+AQ14+AO14+AM14+AK14+AI14+AG14+AE14+AC14+AA14+Y14+W14+U14+S14+Q14+O14+M14+K14+I14+AS14+G14+AU14 -> 3594 | AX14: 1190 | AY14: =+AW14*AX14 -> 4276860
A15: 6 | C15: PROD. MEDICO/FARMACEUTICOS/LAB | D15: 2.9.5 | E15: BOLSAS PARA DIGESTOR 1000 ML. 18 X 29 CM CON CIERRE X 100 UNIDADES TIPO GAMAFIL | F15: CAJA | L15: =+K15*AX15 -> 0 | N15: =+M15*AX15 -> 0 | AE15: 1 | AF15: =+AE15*AX15 -> 16500 | AW15: =+AQ15+AO15+AM15+AK15+AI15+AG15+AE15+AC15+AA15+Y15+W15+U15+S15+Q15+O15+M15+K15+I15+AS15+G15+AU15 -> 1 | AX15: 16500 | AY15: =+AW15*AX15 -> 16500
A16: 7 | C16: PROD. MEDICO/FARMACEUTICOS/LAB. | D16: 2.9.5. | E16: CEPILLO LIMPIA PIPETA DE CERDA NATURAL DE 10 MM | F16: UNIDAD | L16: =+K16*AX16 -> 0 | M16: 10 | N16: =+M16*AX16 -> 1250 | AF16: =+AE16*AX16 -> 0 | AL16: =+AK16*AX16 -> 0 | AW16: =+AQ16+AO16+AM16+AK16+AI16+AG16+AE16+AC16+AA16+Y16+W16+U16+S16+Q16+O16+M16+K16+I16+AS16+G16+AU16 -> 10 | AX16: 125 | AY16: =+AW16*AX16 -> 1250
A17: 8 | C17: PROD. MEDICO/FARMACEUTICOS/LAB. | D17: 2.9.5. | E17: CONEXIÓN POR RADIOFRECUENCIA Y GR PARA AUTOMATIZACION | F17: UNIDAD | L17: =+K17*AX17 -> 0 | M17: 900 | N17: =+M17*AX17 -> 3555000 | AF17: =+AE17*AX17 -> 0 | AL17: =+AK17*AX17 -> 0 | AW17: =+AQ17+AO17+AM17+AK17+AI17+AG17+AE17+AC17+AA17+Y17+W17+U17+S17+Q17+O17+M17+K17+I17+AS17+G17+AU17 -> 900 | AX17: 3950 | AY17: =+AW17*AX17 -> 3555000
A18: 9 | C18: PROD. MEDICO/FARMACEUTICOS/LAB. | D18: 2.9.5. | E18: CUBETA PARA FIBRINTIMER x 500 UN. Tipo WIENER | F18: CAJA | K18: 10 | L18: =+K18*AX18 -> 258600 | N18: =+M18*AX18 -> 0 | AF18: =+AE18*AX18 -> 0 | AL18: =+AK18*AX18 -> 0 | AW18: =+AQ18+AO18+AM18+AK18+AI18+AG18+AE18+AC18+AA18+Y18+W18+U18+S18+Q18+O18+M18+K18+I18+AS18+G18+AU18 -> 10 | AX18: 25860 | AY18: =+AW18*AX18 -> 258600
A19: 10 | C19: PROD. MEDICO/FARMACEUTICOS/LAB. | D19: 2.9.5. | E19: CUBETAS SERIE X 500 UN Tipo TECO GMBH (ALEMANIA) | F19: CAJA | K19: 20 | L19: =+K19*AX19 -> 287440 | N19: =+M19*AX19 -> 0 | AF19: =+AE19*AX19 -> 0 | AL19: =+AK19*AX19 -> 0 | AW19: =+AQ19+AO19+AM19+AK19+AI19+AG19+AE19+AC19+AA19+Y19+W19+U19+S19+Q19+O19+M19+K19+I19+AS19+G19+AU19 -> 20 | AX19: 14372 | AY19: =+AW19*AX19 -> 287440
A20: 11 | C20: PROD. MEDICO/FARMACEUTICOS/LAB | D20: 2.9.5 | E20: EQUIPO AQASSAY ARSENICO DISPOSITIVO BURBUJEADOR TIPO GT LAB | F20: UNIDAD | L20: =+K20*AX20 -> 0 | N20: =+M20*AX20 -> 0 | AE20: 1 | AF20: =+AE20*AX20 -> 18300 | AW20: =+AQ20+AO20+AM20+AK20+AI20+AG20+AE20+AC20+AA20+Y20+W20+U20+S20+Q20+O20+M20+K20+I20+AS20+G20+AU20 -> 1 | AX20: 18300 | AY20: =+AW20*AX20 -> 18300
A21: 12 | C21: PROD. MEDICO/FARMACEUTICOS/LAB | D21: 2.9.5 | E21: EQUIPO DE VIDRIO PARA FILTRACIÓN POR MEMBRANAS DE Ø47MM TIPO GLASSCO COMPUESTO POR: KITASATOS DE BOCA ESMERILADA X 1000 ML, INTERMEDIARIOS CON DISCO SINTERIZADO DE Ø 47MM, VASOS GRADUADOS X 300 ML Y PINZAS METÁLICAS. | F21: UNIDAD | L21: =+K21*AX21 -> 0 | N21: =+M21*AX21 -> 0 | AE21: 10 | AF21: =+AE21*AX21 -> 458000 | AW21: =+AQ21+AO21+AM21+AK21+AI21+AG21+AE21+AC21+AA21+Y21+W21+U21+S21+Q21+O21+M21+K21+I21+AS21+G21+AU21 -> 10 | AX21: 45800 | AY21: =+AW21*AX21 -> 458000
A22: 13 | C22: PROD. MEDICO/FARMACEUTICOS/LAB. | D22: 2.9.5. | E22: ERITUBO CON CITRATO 3,8% + PIPETA PARA ERITROSEDIMENTACION 1 ML (BOLSA X 100 UN) Tipo VITIS | F22: BOLSA | K22: 5 | L22: =+K22*AX22 -> 31145 | N22: =+M22*AX22 -> 0 | AF22: =+AE22*AX22 -> 0 | AL22: =+AK22*AX22 -> 0 | AW22: =+AQ22+AO22+AM22+AK22+AI22+AG22+AE22+AC22+AA22+Y22+W22+U22+S22+Q22+O22+M22+K22+I22+AS22+G22+AU22 -> 5 | AX22: 6229 | AY22: =+AW22*AX22 -> 31145
A23: 14 | C23: PROD. MEDICO/FARMACEUTICOS/LAB | D23: 2.9.5 | E23: ERLENMEYER; TIPO: BOCA COMUN, CAPACIDAD: 500 mL, GRADUADO: SI, GRADUACION: SI TIPO GLASSCO | F23: UNIDAD | L23: =+K23*AX23 -> 0 | N23: =+M23*AX23 -> 0 | AE23: 10 | AF23: =+AE23*AX23 -> 13000 | AW23: =+AQ23+AO23+AM23+AK23+AI23+AG23+AE23+AC23+AA23+Y23+W23+U23+S23+Q23+O23+M23+K23+I23+AS23+G23+AU23 -> 10 | AX23: 1300 | AY23: =+AW23*AX23 -> 13000
A24: 15 | C24: PROD. MEDICO/FARMACEUTICOS/LAB | D24: 2.9.5 | E24: FILTRO DE MEMBRANA DE CN ESTERIL, Ø47MM (045ɥm X 1.000 U). | F24: UNIDAD | L24: =+K24*AX24 -> 0 | N24: =+M24*AX24 -> 0 | AE24: 1 | AF24: =+AE24*AX24 -> 45300 | AW24: =+AQ24+AO24+AM24+AK24+AI24+AG24+AE24+AC24+AA24+Y24+W24+U24+S24+Q24+O24+M24+K24+I24+AS24+G24+AU24 -> 1 | AX24: 45300 | AY24: =+AW24*AX24 -> 45300
A25: 16 | C25: PROD. MEDICO/FARMACEUTICOS/LAB | D25: 2.9.5 | E25: FRASCO GRADUADO C/TAPA A ROSCA AUTOCLAVABLE X 250 ML TIPO GLASSCO | F25: UNIDAD | L25: =+K25*AX25 -> 0 | N25: =+M25*AX25 -> 0 | AE25: 20 | AF25: =+AE25*AX25 -> 16400 | AW25: =+AQ25+AO25+AM25+AK25+AI25+AG25+AE25+AC25+AA25+Y25+W25+U25+S25+Q25+O25+M25+K25+I25+AS25+G25+AU25 -> 20 | AX25: 820 | AY25: =+AW25*AX25 -> 16400
A26: 17 | C26: PROD. MEDICO/FARMACEUTICOS/LAB. | D26: 2.9.5. | E26: GOMA LATEX/EXTRACCION CAJA X 10 U TIPO DELTALAB | F26: CAJA | K26: 20 | L26: =+K26*AX26 -> 6000 | N26: =+M26*AX26 -> 0 | AF26: =+AE26*AX26 -> 0 | AL26: =+AK26*AX26 -> 0 | AW26: =+AQ26+AO26+AM26+AK26+AI26+AG26+AE26+AC26+AA26+Y26+W26+U26+S26+Q26+O26+M26+K26+I26+AS26+G26+AU26 -> 20 | AX26: 300 | AY26: =+AW26*AX26 -> 6000
A27: 18 | C27: PROD. MEDICO/FARMACEUTICOS/LAB. | D27: 2.9.5. | E27: GRADILLAS PARA TUBOS DE KAHN | F27: UNIDAD | K27: 50 | L27: =+K27*AX27 -> 193300 | N27: =+M27*AX27 -> 0 | AF27: =+AE27*AX27 -> 0 | AL27: =+AK27*AX27 -> 0 | AW27: =+AQ27+AO27+AM27+AK27+AI27+AG27+AE27+AC27+AA27+Y27+W27+U27+S27+Q27+O27+M27+K27+I27+AS27+G27+AU27 -> 50 | AX27: 3866 | AY27: =+AW27*AX27 -> 193300
A28: 19 | C28: PROD. MEDICO/FARMACEUTICOS/LAB | D28: 2.9.5 | E28: GUIA V20 C/RUEDITA *SANGRE* | F28: UNIDAD | L28: =+K28*AX28 -> 0 | M28: 1200 | N28: =+M28*AX28 -> 110400 | AW28: =+AQ28+AO28+AM28+AK28+AI28+AG28+AE28+AC28+AA28+Y28+W28+U28+S28+Q28+O28+M28+K28+I28+AS28+G28+AU28 -> 1200 | AX28: 92 | AY28: =+AW28*AX28 -> 110400
A29: 20 | C29: PROD. MEDICO/FARMACEUTICOS/LAB. | D29: 2.9.5. | E29: KIT PLAQUETAS CON FILTRO | F29: UNIDAD | L29: =+K29*AX29 -> 0 | M29: 48 | N29: =+M29*AX29 -> 1968912 | AF29: =+AE29*AX29 -> 0 | AL29: =+AK29*AX29 -> 0 | AW29: =+AQ29+AO29+AM29+AK29+AI29+AG29+AE29+AC29+AA29+Y29+W29+U29+S29+Q29+O29+M29+K29+I29+AS29+G29+AU29 -> 48 | AX29: 41019 | AY29: =+AW29*AX29 -> 1968912
A30: 21 | C30: PROD. MEDICO/FARMACEUTICOS/LAB. | D30: 2.9.5. | E30: MANOPLAS DE POLIETILENO x 100 U | F30: BOLSA | K30: 200 | L30: =+K30*AX30 -> 35800 | N30: =+M30*AX30 -> 0 | AF30: =+AE30*AX30 -> 0 | AW30: =+AQ30+AO30+AM30+AK30+AI30+AG30+AE30+AC30+AA30+Y30+W30+U30+S30+Q30+O30+M30+K30+I30+AS30+G30+AU30 -> 200 | AX30: 179 | AY30: =+AW30*AX30 -> 35800
A31: 22 | C31: PROD. MEDICO/FARMACEUTICOS/LAB | D31: 2.9.5 | E31: MATRAZ AFORADO MATRAZ AFORADO; ESTADO: SOLIDO, MATERIAL: POLIPROPILENO, PRESENTACION: UNIDAD, CAPACIDAD: 100 mL | F31: UNIDAD | L31: =+K31*AX31 -> 0 | N31: =+M31*AX31 -> 0 | AE31: 5 | AF31: =+AE31*AX31 -> 4750 | AW31: =+AQ31+AO31+AM31+AK31+AI31+AG31+AE31+AC31+AA31+Y31+W31+U31+S31+Q31+O31+M31+K31+I31+AS31+G31+AU31 -> 5 | AX31: 950 | AY31: =+AW31*AX31 -> 4750
A32: 23 | C32: PROD. MEDICO/FARMACEUTICOS/LAB | D32: 2.9.5 | E32: MATRAZ AFORADO MATRAZ AFORADO; ESTADO: SOLIDO, MATERIAL: POLIPROPILENO, PRESENTACION: UNIDAD, CAPACIDAD: 250 mL | F32: UNIDAD | L32: =+K32*AX32 -> 0 | N32: =+M32*AX32 -> 0 | AE32: 5 | AF32: =+AE32*AX32 -> 5358.2 | AW32: =+AQ32+AO32+AM32+AK32+AI32+AG32+AE32+AC32+AA32+Y32+W32+U32+S32+Q32+O32+M32+K32+I32+AS32+G32+AU32 -> 5 | AX32: 1071.64 | AY32: =+AW32*AX32 -> 5358.2
A33: 24 | C33: PROD. MEDICO/FARMACEUTICOS/LAB. | D33: 2.9.5. | E33: MICROPIPETAS REGULABLES; CAPACIDAD: 100 - 1000 µL, DIVISIONES: CADA 5 µL, MATERIAL: PLASTICO | F33: UNIDAD | L33: =+K33*AX33 -> 0 | M33: 2 | N33: =+M33*AX33 -> 104700 | AF33: =+AE33*AX33 -> 0 | AW33: =+AQ33+AO33+AM33+AK33+AI33+AG33+AE33+AC33+AA33+Y33+W33+U33+S33+Q33+O33+M33+K33+I33+AS33+G33+AU33 -> 2 | AX33: 52350 | AY33: =+AW33*AX33 -> 104700
A34: 25 | C34: PROD. MEDICO/FARMACEUTICOS/LAB. | D34: 2.9.5. | E34: MICROPIPETAS REGULABLES; CAPACIDAD: 10-100 µL, DIVISIONES: CADA 1 µL, MATERIAL: PLASTICO | F34: UNIDAD | L34: =+K34*AX34 -> 0 | M34: 2 | N34: =+M34*AX34 -> 100700 | AF34: =+AE34*AX34 -> 0 | AL34: =+AK34*AX34 -> 0 | AW34: =+AQ34+AO34+AM34+AK34+AI34+AG34+AE34+AC34+AA34+Y34+W34+U34+S34+Q34+O34+M34+K34+I34+AS34+G34+AU34 -> 2 | AX34: 50350 | AY34: =+AW34*AX34 -> 100700
A35: 26 | C35: PROD. MEDICO/FARMACEUTICOS/LAB | D35: 2.9.5 | E35: PAPEL FILTRO; FORMA: CIRCULAR, DIMENSION: 110 mm, PORO: WATMAN 40/41, PRESENTACION: ENVASE X 100 | F35: CAJA | L35: =+K35*AX35 -> 0 | N35: =+M35*AX35 -> 0 | AE35: 1 | AF35: =+AE35*AX35 -> 8791 | AW35: =+AQ35+AO35+AM35+AK35+AI35+AG35+AE35+AC35+AA35+Y35+W35+U35+S35+Q35+O35+M35+K35+I35+AS35+G35+AU35 -> 1 | AX35: 8791 | AY35: =+AW35*AX35 -> 8791
A36: 27 | C36: PROD. MEDICO/FARMACEUTICOS/LAB. | D36: 2.3.4 | E36: PAPEL para contador MINDRAY | F36: UNIDAD | K36: 90 | L36: =+K36*AX36 -> 64260 | N36: =+M36*AX36 -> 0 | AF36: =+AE36*AX36 -> 0 | AL36: =+AK36*AX36 -> 0 | AW36: =+AQ36+AO36+AM36+AK36+AI36+AG36+AE36+AC36+AA36+Y36+W36+U36+S36+Q36+O36+M36+K36+I36+AS36+G36+AU36 -> 90 | AX36: 714 | AY36: =+AW36*AX36 -> 64260
A37: 28 | C37: PROD. MEDICO/FARMACEUTICOS/LAB | D37: 2.9.5 | E37: PICNÓMETRO DE VIDRIO C/TERMÓMETRO INCLUIDO C/TAPA ESMERILADA TIPO FITE X 5 ml | F37: UNIDAD | L37: =+K37*AX37 -> 0 | N37: =+M37*AX37 -> 0 | AE37: 1 | AF37: =+AE37*AX37 -> 65000 | AW37: =+AQ37+AO37+AM37+AK37+AI37+AG37+AE37+AC37+AA37+Y37+W37+U37+S37+Q37+O37+M37+K37+I37+AS37+G37+AU37 -> 1 | AX37: 65000 | AY37: =+AW37*AX37 -> 65000
A38: 29 | C38: PROD. MEDICO/FARMACEUTICOS/LAB | D38: 2.9.5 | E38: PINZA PMP C/EXTREMO EN PUNTA AUTOCLAVABLE TIPO BRAND | F38: UNIDAD | L38: =+K38*AX38 -> 0 | N38: =+M38*AX38 -> 0 | AE38: 5 | AF38: =+AE38*AX38 -> 18500 | AW38: =+AQ38+AO38+AM38+AK38+AI38+AG38+AE38+AC38+AA38+Y38+W38+U38+S38+Q38+O38+M38+K38+I38+AS38+G38+AU38 -> 5 | AX38: 3700 | AY38: =+AW38*AX38 -> 18500
A39: 30 | C39: PROD. MEDICO/FARMACEUTICOS/LAB. | D39: 2.9.5. | E39: PISETA 500 Ml | F39: BOTELLA | K39: 30 | L39: =+K39*AX39 -> 26700 | N39: =+M39*AX39 -> 0 | AF39: =+AE39*AX39 -> 0 | AL39: =+AK39*AX39 -> 0 | AW39: =+AQ39+AO39+AM39+AK39+AI39+AG39+AE39+AC39+AA39+Y39+W39+U39+S39+Q39+O39+M39+K39+I39+AS39+G39+AU39 -> 30 | AX39: 890 | AY39: =+AW39*AX39 -> 26700
A40: 31 | C40: PROD. MEDICO/FARMACEUTICOS/LAB. | D40: 2.9.5. | E40: PLACA PARA VDRL CON POCILLO PROFUNDO 12HOYOS | F40: UNIDAD | L40: =+K40*AX40 -> 0 | M40: 20 | N40: =+M40*AX40 -> 24400 | AF40: =+AE40*AX40 -> 0 | AL40: =+AK40*AX40 -> 0 | AW40: =+AQ40+AO40+AM40+AK40+AI40+AG40+AE40+AC40+AA40+Y40+W40+U40+S40+Q40+O40+M40+K40+I40+AS40+G40+AU40 -> 20 | AX40: 1220 | AY40: =+AW40*AX40 -> 24400
A41: 32 | C41: PROD. MEDICO/FARMACEUTICOS/LAB | D41: 2.9.5 | E41: PLACAS DE PETRI PLACAS DE PETRI; MATERIAL: PLASTICO ESTERIL, DIAMETRO: 5 Cm, ALTURA: SIN VALOR | F41: UNIDAD | L41: =+K41*AX41 -> 0 | N41: =+M41*AX41 -> 0 | AE41: 400 | AF41: =+AE41*AX41 -> 12800 | AW41: =+AQ41+AO41+AM41+AK41+AI41+AG41+AE41+AC41+AA41+Y41+W41+U41+S41+Q41+O41+M41+K41+I41+AS41+G41+AU41 -> 400 | AX41: 32 | AY41: =+AW41*AX41 -> 12800
A42: 33 | C42: PROD. MEDICO/FARMACEUTICOS/LAB | D42: 2.9.5 | E42: PLACAS DE PETRI PLACAS DE PETRI; MATERIAL: SOLIDO, DIAMETRO: 100 mm, ALTURA: 15 mm | F42: UNIDAD | L42: =+K42*AX42 -> 0 | N42: =+M42*AX42 -> 0 | AE42: 300 | AF42: =+AE42*AX42 -> 10245 | AW42: =+AQ42+AO42+AM42+AK42+AI42+AG42+AE42+AC42+AA42+Y42+W42+U42+S42+Q42+O42+M42+K42+I42+AS42+G42+AU42 -> 300 | AX42: 34.15 | AY42: =+AW42*AX42 -> 10245
...

Sheet NP DPLAB
A1: NOTA DE PEDIDO | J1: N° | K1: 07/2022
A3: JURISDICCIÓN: | D3: 040 - MINISTERIO DE SALUD
A4: SAF: | D4: 011 - DIRECCION PROVINCIAL DE ADMINISTRACION DEL MINISTERIO DE SALUD
A5: UNIDAD EJECUTORA: | D5: 468 - DIRECCION PROVINCIAL DE LABORATORIO
A6: DEPENDENCIA SOLICITANTE: | D6: 468 - DIRECCION PROVINCIAL DE LABORATORIO
A7: PERIODO UTILIZACIÓN: | D7: TRES (3) MESES
A8: OBJETO: | D8: ADQUISICION DEL RUBRO DESCARTABLES PARA LABORATORIO
A10: Ítem | B10: Codigo Item | C10: DESCRIPCIÓN | H10: Adjunta Detalle Técnico | I10: Unidad Medida | J10: Precio Unitario Estimado | K10: Cantidad Solicitada
A12: 1 | C12: ='SAF 011 - NECESIDAD TRIMESTRAL'!E10 -> ANSA CALIBRADA PS DE 10 ul ESTERIL-ENVASE INDIVIDUAL X 20 U Tipo DELTALAB | H12: NO | I12: ='SAF 011 - NECESIDAD TRIMESTRAL'!F10 -> BOLSA | J12: ='SAF 011 - NECESIDAD TRIMESTRAL'!AX10 -> 640 | K12: ='SAF 011 - NECESIDAD TRIMESTRAL'!K10 -> 50 | M12: =+J12*K12 -> 32000
A13: 2 | C13: ='SAF 011 - NECESIDAD TRIMESTRAL'!E18 -> CUBETA PARA FIBRINTIMER x 500 UN. Tipo WIENER | H13: NO | I13: ='SAF 011 - NECESIDAD TRIMESTRAL'!F18 -> CAJA | J13: ='SAF 011 - NECESIDAD TRIMESTRAL'!AX18 -> 25860 | K13: ='SAF 011 - NECESIDAD TRIMESTRAL'!K18 -> 10 | M13: =+J13*K13 -> 258600
A14: 3 | C14: ='SAF 011 - NECESIDAD TRIMESTRAL'!E19 -> CUBETAS SERIE X 500 UN Tipo TECO GMBH (ALEMANIA) | H14: NO | I14: ='SAF 011 - NECESIDAD TRIMESTRAL'!F19 -> CAJA | J14: ='SAF 011 - NECESIDAD TRIMESTRAL'!AX19 -> 14372 | K14: ='SAF 011 - NECESIDAD TRIMESTRAL'!K19 -> 20 | M14: =+J14*K14 -> 287440
A15: 4 | C15: ='SAF 011 - NECESIDAD TRIMESTRAL'!E22 -> ERITUBO CON CITRATO 3,8% + PIPETA PARA ERITROSEDIMENTACION 1 ML (BOLSA X 100 UN) Tipo VITIS | H15: NO | I15: ='SAF 011 - NECESIDAD TRIMESTRAL'!F22 -> BOLSA | J15: ='SAF 011 - NECESIDAD TRIMESTRAL'!AX22 -> 6229 | K15: ='SAF 011 - NECESIDAD TRIMESTRAL'!K22 -> 5 | M15: =+J15*K15 -> 31145
A16: 5 | C16: ='SAF 011 - NECESIDAD TRIMESTRAL'!E26 -> GOMA LATEX/EXTRACCION CAJA X 10 U TIPO DELTALAB | H16: NO | I16: ='SAF 011 - NECESIDAD TRIMESTRAL'!F26 -> CAJA | J16: ='SAF 011 - NECESIDAD TRIMESTRAL'!AX26 -> 300 | K16: ='SAF 011 - NECESIDAD TRIMESTRAL'!K26 -> 20 | L16: medidas? | M16: =+J16*K16 -> 6000
A17: 6 | C17: ='SAF 011 - NECESIDAD TRIMESTRAL'!E27 -> GRADILLAS PARA TUBOS DE KAHN | H17: NO | I17: ='SAF 011 - NECESIDAD TRIMESTRAL'!F27 -> UNIDAD | J17: ='SAF 011 - NECESIDAD TRIMESTRAL'!AX27 -> 3866 | K17: ='SAF 011 - NECESIDAD TRIMESTRAL'!K27 -> 50 | M17: =+J17*K17 -> 193300
A18: 7 | C18: ='SAF 011 - NECESIDAD TRIMESTRAL'!E30 -> MANOPLAS DE POLIETILENO x 100 U | H18: NO | I18: ='SAF 011 - NECESIDAD TRIMESTRAL'!F30 -> BOLSA | J18: ='SAF 011 - NECESIDAD TRIMESTRAL'!AX30 -> 179 | K18: ='SAF 011 - NECESIDAD TRIMESTRAL'!K30 -> 200 | M18: =+J18*K18 -> 35800
A19: 8 | C19: ='SAF 011 - NECESIDAD TRIMESTRAL'!E36 -> PAPEL para contador MINDRAY | H19: NO | I19: ='SAF 011 - NECESIDAD TRIMESTRAL'!F36 -> UNIDAD | J19: ='SAF 011 - NECESIDAD TRIMESTRAL'!AX36 -> 714 | K19: ='SAF 011 - NECESIDAD TRIMESTRAL'!K36 -> 90 | L19: caracterisiticas? | M19: =+J19*K19 -> 64260
A20: 9 | C20: ='SAF 011 - NECESIDAD TRIMESTRAL'!E39 -> PISETA 500 Ml | H20: NO | I20: ='SAF 011 - NECESIDAD TRIMESTRAL'!F39 -> BOTELLA | J20: ='SAF 011 - NECESIDAD TRIMESTRAL'!AX39 -> 890 | K20: ='SAF 011 - NECESIDAD TRIMESTRAL'!K39 -> 30 | M20: =+J20*K20 -> 26700
A21: 10 | C21: ='SAF 011 - NECESIDAD TRIMESTRAL'!E44 -> TIMER DIGITAL 5 ALARMAS Tipo KINDER | H21: NO | I21: ='SAF 011 - NECESIDAD TRIMESTRAL'!F44 -> UNIDAD | J21: ='SAF 011 - NECESIDAD TRIMESTRAL'!AX44 -> 1781 | K21: ='SAF 011 - NECESIDAD TRIMESTRAL'!K44 -> 20 | M21: =+J21*K21 -> 35620
A22: 11 | C22: ='SAF 011 - NECESIDAD TRIMESTRAL'!E50 -> TUBO DE CALIBRACION DE GASES P/TS2 Tipo OPTI MEDICAL (USA) | H22: NO | I22: ='SAF 011 - NECESIDAD TRIMESTRAL'!F50 -> GARRAFA | J22: ='SAF 011 - NECESIDAD TRIMESTRAL'!AX50 -> 43657 | K22: ='SAF 011 - NECESIDAD TRIMESTRAL'!K50 -> 10 | L22: IPP | M22: =+J22*K22 -> 436570
A23: 12 | C23: ='SAF 011 - NECESIDAD TRIMESTRAL'!E52 -> TUBO DE KAHN DE VIDRIO | H23: NO | I23: ='SAF 011 - NECESIDAD TRIMESTRAL'!F52 -> UNIDAD | J23: ='SAF 011 - NECESIDAD TRIMESTRAL'!AX52 -> 27 | K23: ='SAF 011 - NECESIDAD TRIMESTRAL'!K52 -> 5000 | M23: =+J23*K23 -> 135000
A25: Costo total estimado: UN MILLON QUINIENTOS CUARENTA Y DOS MIL CUATROCIENTOS TREINTA Y CINCO CON 00/100.- | J25: =SUMPRODUCT(J12:J23,K12:K23) -> 1542435 | M25: =SUM(M12:M24) -> 1542435
I27: 640 | J27: 50 | K27: =I27*J27 -> 32000 | M27: =+M25-M19 -> 1478175
I28: 25860 | J28: 10 | K28: =I28*J28 -> 258600
I29: 14372 | J29: 20 | K29: =I29*J29 -> 287440
I30: 6229 | J30: 5 | K30: =I30*J30 -> 31145
I31: 300 | J31: 20 | K31: =I31*J31 -> 6000
I32: 3866 | J32: 50 | K32: =I32*J32 -> 193300
I33: 179 | J33: 200 | K33: =I33*J33 -> 35800
I34: 714 | J34: 90 | K34: =I34*J34 -> 64260
I35: 890 | J35: 30 | K35: =I35*J35 -> 26700
I36: 1781 | J36: 20 | K36: =I36*J36 -> 35620
I37: 43657 | J37: 10 | K37: =I37*J37 -> 436570
I38: 27 | J38: 5000 | K38: =I38*J38 -> 135000
K39: =SUM(K27:K38) -> 1542435

Sheet APG DPLAB
A1: EJERCICIO: | D1: 2022 | P1: AUTORIZACION PARA GASTAR
A4: JURISDICCIÓN: | G4: ='NP DPLAB'!D3 -> 040 - MINISTERIO DE SALUD
A5: SAF: | G5: ='NP DPLAB'!D4 -> 011 - DIRECCION PROVINCIAL DE ADMINISTRACION DEL MINISTERIO DE SALUD
A6: UNIDAD EJECUTORA: | G6: ='NP DPLAB'!D5 -> 468 - DIRECCION PROVINCIAL DE LABORATORIO
A7: DEPENDENCIA SOLICITANTE: | G7: ='NP DPLAB'!D6 -> 468 - DIRECCION PROVINCIAL DE LABORATORIO
A8: AUTORIZACIÓN:
A9: Señor Director de Administración o Titular del Servicio Administrativo Financiero:
A10: Autorizo la realización de los trámites correspondientes, a fin de proveer a este Organismo los bienes, servicios o ejecución de obras públicas que se detallan en Nota de Pedido N° 07/2022 , afectando la erogación resultante a los créditos presupuestarios aprobados a favor de esta Unidad Ejecutora, conforme al siguiente detalle:
A12: IMPUTACIÓN PRESUPUESTARIA
A13: CÓDIGO | O13: DENOMINACIÓN DE LA PARTIDA PRESUPUESTARIA | Q13: IMPORTE
A14: PR | B14: SB | C14: PY | D14: AC | E14: OB | F14: UG | G14: FIN | H14: FUN | I14: I | J14: P | K14: P | L14: SubP | M14: M | N14: FF
A15: 62 | D15: 1 | F15: 4901 | G15: 3 | H15: 1 | I15: 2 | J15: 9 | K15: 5 | M15: 1 | N15: 1.1 | O15: UTILES MENORES MEDICOS, QUIRURGICOS Y DE LABORATORIO | Q15: ='NP DPLAB'!M27 -> 1478175
A16: 62 | D16: 1 | F16: 4901 | G16: 3 | H16: 1 | I16: 2 | J16: 3 | K16: 4 | M16: 1 | N16: 1.1 | O16: PRODUCTOS DE PAPEL Y CARTON | Q16: ='NP DPLAB'!M19 -> 64260
A38: TOTAL DE PESOS: UN MILLON QUINIENTOS CUARENTA Y DOS MIL CUATROCIENTOS TREINTA Y CINCO CON 00/100.- | Q38: =SUM(Q15:Q37) -> 1542435
A40: JUSTIFICACIÓN:
A41: ='NP DPLAB'!D8 -> ADQUISICION DEL RUBRO DESCARTABLES PARA LABORATORIO

Sheet NP DPBS
A1: NOTA DE PEDIDO | J1: N° | K1: 10/2022
A3: JURISDICCIÓN: | D3: 040 - MINISTERIO DE SALUD
A4: SAF: | D4: 011 - DIRECCION PROVINCIAL DE ADMINISTRACION DEL MINISTERIO DE SALUD
A5: UNIDAD EJECUTORA: | D5: 747 - DIRECCION PROVINCIAL BANCO DE SANGRE
A6: DEPENDENCIA SOLICITANTE: | D6: 747 - DIRECCION PROVINCIAL BANCO DE SANGRE
A7: PERIODO UTILIZACIÓN: | D7: TRES (3) MESES
A8: OBJETO: | D8: ADQUISICION DEL RUBRO DESCARTABLES PARA LABORATORIO
A10: Ítem | B10: Codigo Item | C10: DESCRIPCIÓN | H10: Adjunta Detalle Técnico | I10: Unidad Medida | J10: Precio Unitario Estimado | K10: Cantidad Solicitada
A12: 1 | C12: ='SAF 011 - NECESIDAD TRIMESTRAL'!E11 -> APOSITOS; TIPO: POST EXTRACCION SANGUINEA, TAMAÑO: 40 X 40 mm | H12: NO | I12: ='SAF 011 - NECESIDAD TRIMESTRAL'!F11 -> CAJA | J12: ='SAF 011 - NECESIDAD TRIMESTRAL'!AX11 -> 702 | K12: ='SAF 011 - NECESIDAD TRIMESTRAL'!M11 -> 50
A13: 2 | C13: ='SAF 011 - NECESIDAD TRIMESTRAL'!E13 -> BOLSAS DE SANGRE TRIPLE KS | H13: NO | I13: ='SAF 011 - NECESIDAD TRIMESTRAL'!F13 -> UNIDAD | J13: ='SAF 011 - NECESIDAD TRIMESTRAL'!AX13 -> 1095 | K13: ='SAF 011 - NECESIDAD TRIMESTRAL'!M13 -> 1794
A14: 3 | C14: ='SAF 011 - NECESIDAD TRIMESTRAL'!E14 -> BOLSAS DE SANGRE TRIPLE KS TIPO GRIFOLS | H14: NO | I14: ='SAF 011 - NECESIDAD TRIMESTRAL'!F14 -> UNIDAD | J14: ='SAF 011 - NECESIDAD TRIMESTRAL'!AX14 -> 1190 | K14: ='SAF 011 - NECESIDAD TRIMESTRAL'!M14 -> 3594
A15: 4 | C15: ='SAF 011 - NECESIDAD TRIMESTRAL'!E16 -> CEPILLO LIMPIA PIPETA DE CERDA NATURAL DE 10 MM | H15: NO | I15: ='SAF 011 - NECESIDAD TRIMESTRAL'!F16 -> UNIDAD | J15: ='SAF 011 - NECESIDAD TRIMESTRAL'!AX16 -> 125 | K15: ='SAF 011 - NECESIDAD TRIMESTRAL'!M16 -> 10
A16: 5 | C16: ='SAF 011 - NECESIDAD TRIMESTRAL'!E17 -> CONEXIÓN POR RADIOFRECUENCIA Y GR PARA AUTOMATIZACION | H16: NO | I16: ='SAF 011 - NECESIDAD TRIMESTRAL'!F17 -> UNIDAD | J16: ='SAF 011 - NECESIDAD TRIMESTRAL'!AX17 -> 3950 | K16: ='SAF 011 - NECESIDAD TRIMESTRAL'!M17 -> 900 | L16: IPP
A17: 6 | C17: ='SAF 011 - NECESIDAD TRIMESTRAL'!E28 -> GUIA V20 C/RUEDITA *SANGRE* | H17: NO | I17: ='SAF 011 - NECESIDAD TRIMESTRAL'!F28 -> UNIDAD | J17: ='SAF 011 - NECESIDAD TRIMESTRAL'!AX28 -> 92 | K17: ='SAF 011 - NECESIDAD TRIMESTRAL'!M28 -> 1200
A18: 7 | C18: ='SAF 011 - NECESIDAD TRIMESTRAL'!E29 -> KIT PLAQUETAS CON FILTRO | H18: NO | I18: ='SAF 011 - NECESIDAD TRIMESTRAL'!F29 -> UNIDAD | J18: ='SAF 011 - NECESIDAD TRIMESTRAL'!AX29 -> 41019 | K18: ='SAF 011 - NECESIDAD TRIMESTRAL'!M29 -> 48 | L18: caracteristicas?
A19: 8 | C19: ='SAF 011 - NECESIDAD TRIMESTRAL'!E33 -> MICROPIPETAS REGULABLES; CAPACIDAD: 100 - 1000 µL, DIVISIONES: CADA 5 µL, MATERIAL: PLASTICO | H19: NO | I19: ='SAF 011 - NECESIDAD TRIMESTRAL'!F33 -> UNIDAD | J19: ='SAF 011 - NECESIDAD TRIMESTRAL'!AX33 -> 52350 | K19: ='SAF 011 - NECESIDAD TRIMESTRAL'!M33 -> 2 | L19: rever precio
A20: 9 | C20: ='SAF 011 - NECESIDAD TRIMESTRAL'!E34 -> MICROPIPETAS REGULABLES; CAPACIDAD: 10-100 µL, DIVISIONES: CADA 1 µL, MATERIAL: PLASTICO | H20: NO | I20: ='SAF 011 - NECESIDAD TRIMESTRAL'!F34 -> UNIDAD | J20: ='SAF 011 - NECESIDAD TRIMESTRAL'!AX34 -> 50350 | K20: ='SAF 011 - NECESIDAD TRIMESTRAL'!M34 -> 2 | L20: rever precio
A21: 10 | C21: ='SAF 011 - NECESIDAD TRIMESTRAL'!E40 -> PLACA PARA VDRL CON POCILLO PROFUNDO 12HOYOS | H21: NO | I21: ='SAF 011 - NECESIDAD TRIMESTRAL'!F40 -> UNIDAD | J21: ='SAF 011 - NECESIDAD TRIMESTRAL'!AX40 -> 1220 | K21: ='SAF 011 - NECESIDAD TRIMESTRAL'!M40 -> 20
A22: 11 | C22: ='SAF 011 - NECESIDAD TRIMESTRAL'!E45 -> TIP; TIPO: AMARILLO, PRESENTACION: ENVASE X 1000 UN, CAPACIDAD: 5 A 200 µl | H22: NO | I22: ='SAF 011 - NECESIDAD TRIMESTRAL'!F45 -> BOLSA | J22: ='SAF 011 - NECESIDAD TRIMESTRAL'!AX45 -> 2865 | K22: ='SAF 011 - NECESIDAD TRIMESTRAL'!M45 -> 5
A23: 12 | C23: ='SAF 011 - NECESIDAD TRIMESTRAL'!E46 -> TIPS AMARILLO CON CORONA X 1000 UNIDADES | H23: NO | I23: ='SAF 011 - NECESIDAD TRIMESTRAL'!F46 -> BOLSA | J23: ='SAF 011 - NECESIDAD TRIMESTRAL'!AX46 -> 1540 | K23: ='SAF 011 - NECESIDAD TRIMESTRAL'!M46 -> 2
A24: 13 | C24: ='SAF 011 - NECESIDAD TRIMESTRAL'!E47 -> TIPS AMARILLO SIN CORONA X 1000 UNIDADES | H24: NO | I24: ='SAF 011 - NECESIDAD TRIMESTRAL'!F47 -> BOLSA | J24: ='SAF 011 - NECESIDAD TRIMESTRAL'!AX47 -> 1540 | K24: ='SAF 011 - NECESIDAD TRIMESTRAL'!M47 -> 2
A25: 14 | C25: ='SAF 011 - NECESIDAD TRIMESTRAL'!E49 -> TIPS AZUL AUTOCLAVABLE | H25: NO | I25: ='SAF 011 - NECESIDAD TRIMESTRAL'!F49 -> BOLSA | J25: ='SAF 011 - NECESIDAD TRIMESTRAL'!AX49 -> 2204 | K25: ='SAF 011 - NECESIDAD TRIMESTRAL'!M49 -> 2 | L25: cantidad?
A26: 15 | C26: ='SAF 011 - NECESIDAD TRIMESTRAL'!E53 -> TUBOS DE ENSAYO; TIPO: CONICO P/CENTRIFUGA, MATERIAL: POLIPROPILENO, DIMENSION: 0,5 A 15 mL, ACCESORIO: SIN VALOR - A ROSCA 15ML NO ETERIL, BOLSA X 100 UNID TIPO BIOLIX | H26: NO | I26: ='SAF 011 - NECESIDAD TRIMESTRAL'!F53 -> BOLSA | J26: ='SAF 011 - NECESIDAD TRIMESTRAL'!AX53 -> 5353 | K26: ='SAF 011 - NECESIDAD TRIMESTRAL'!M53 -> 10
A27: 16 | C27: ='SAF 011 - NECESIDAD TRIMESTRAL'!E54 -> TUBOS DE ENSAYO; TIPO: EPPENDORF, MATERIAL: PLASTICO, DIMENSION: 1.5 mL, ACCESORIOS: SIN, ACCESORIO: SIN | H27: NO | I27: ='SAF 011 - NECESIDAD TRIMESTRAL'!F54 -> BOLSA | J27: ='SAF 011 - NECESIDAD TRIMESTRAL'!AX54 -> 3558 | K27: ='SAF 011 - NECESIDAD TRIMESTRAL'!M54 -> 10 | L27: cantidad?
A28: 17 | C28: ='SAF 011 - NECESIDAD TRIMESTRAL'!E55 -> TUBOS DE ENSAYO; TIPO: VACUTAINER UN, MATERIAL: VIDRIO, DIMENSION: 10 mL, ACCESORIOS: SIN, ACCESORIO: SIN (X100 UNIDADES) | H28: NO | I28: ='SAF 011 - NECESIDAD TRIMESTRAL'!F55 -> CAJA | J28: ='SAF 011 - NECESIDAD TRIMESTRAL'!AX55 -> 13000 | K28: ='SAF 011 - NECESIDAD TRIMESTRAL'!M55 -> 4
A29: 18 | C29: ='SAF 011 - NECESIDAD TRIMESTRAL'!E56 -> TUBOS DE HEMOLISIS; MATERIAL: VIDRIO, PRESENTACION: CAJA, DIMENSION: 100 X 13 DIAM. EXT., MEDIDAS: 100 X 13 DIAM. EXT., FORMA DE PRESENTACION: SOLIDO, ESTADO: SOLIDO (1000 TUBOS) | H29: NO | I29: ='SAF 011 - NECESIDAD TRIMESTRAL'!F56 -> UNIDAD | J29: ='SAF 011 - NECESIDAD TRIMESTRAL'!AX56 -> 72000 | K29: ='SAF 011 - NECESIDAD TRIMESTRAL'!M56 -> 1
A30: 19 | C30: ='SAF 011 - NECESIDAD TRIMESTRAL'!E57 -> TUBOS VACUTAINER P/SUERO DE 4ML, TAPA ROJA C/ETIQUETA CODIGO 367812 (1000 TUBOS) | H30: NO | I30: ='SAF 011 - NECESIDAD TRIMESTRAL'!F57 -> CAJA | J30: ='SAF 011 - NECESIDAD TRIMESTRAL'!AX57 -> 13700 | K30: ='SAF 011 - NECESIDAD TRIMESTRAL'!M57 -> 2
A32: Costo total estimado: DOCE MILLONES CUATROCIENTOS SIETE MIL CIENTO CINCUENTA Y CINCO CON 00/100.- | J32: =SUMPRODUCT(J12:J30,K12:K30) -> 12407155
J34: 702 | K34: =J34*K12 -> 35100
J35: 1095 | K35: =J35*K13 -> 1964430
J36: 1190 | K36: =J36*K14 -> 4276860
J37: 125 | K37: =J37*K15 -> 1250
J38: 3950 | K38: =J38*K16 -> 3555000
J39: 92 | K39: =J39*K17 -> 110400
J40: 41019 | K40: =J40*K18 -> 1968912
J41: 52350 | K41: =J41*K19 -> 104700
J42: 50350 | K42: =J42*K20 -> 100700
J43: 1220 | K43: =J43*K21 -> 24400
J44: 2865 | K44: =J44*K22 -> 14325
J45: 1540 | K45: =J45*K23 -> 3080
...

Sheet APG DPBS
A1: EJERCICIO: | D1: 2022 | P1: AUTORIZACION PARA GASTAR
A4: JURISDICCIÓN: | G4: ='NP DPBS'!D3 -> 040 - MINISTERIO DE SALUD
A5: SAF: | G5: ='NP DPBS'!D4 -> 011 - DIRECCION PROVINCIAL DE ADMINISTRACION DEL MINISTERIO DE SALUD
A6: UNIDAD EJECUTORA: | G6: ='NP DPBS'!D5 -> 747 - DIRECCION PROVINCIAL BANCO DE SANGRE
A7: DEPENDENCIA SOLICITANTE: | G7: ='NP DPBS'!D6 -> 747 - DIRECCION PROVINCIAL BANCO DE SANGRE
A8: AUTORIZACIÓN:
A9: Señor Director de Administración o Titular del Servicio Administrativo Financiero:
A10: Autorizo la realización de los trámites correspondientes, a fin de proveer a este Organismo los bienes, servicios o ejecución de obras públicas que se detallan en Nota de Pedido N° 10/2022 , afectando la erogación resultante a los créditos presupuestarios aprobados a favor de esta Unidad Ejecutora, conforme al siguiente detalle:
A12: IMPUTACIÓN PRESUPUESTARIA
A13: CÓDIGO | O13: DENOMINACIÓN DE LA PARTIDA PRESUPUESTARIA | Q13: IMPORTE
A14: PR | B14: SB | C14: PY | D14: AC | E14: OB | F14: UG | G14: FIN | H14: FUN | I14: I | J14: P | K14: P | L14: SubP | M14: M | N14: FF
A15: 27 | D15: 1 | F15: 4901 | G15: 3 | H15: 1 | I15: 2 | J15: 9 | K15: 5 | M15: 1 | N15: 1.1 | O15: UTILES MENORES MEDICOS, QUIRURGICOS Y DE LABORATORIO | Q15: ='NP DPBS'!J32 -> 12407155
A38: TOTAL DE PESOS: DOCE MILLONES CUATROCIENTOS SIETE MIL CIENTO CINCUENTA CINCO CON 00/100.- | Q38: =SUM(Q15:Q37) -> 12407155
A40: JUSTIFICACIÓN:
A41: ='NP DPBS'!D8 -> ADQUISICION DEL RUBRO DESCARTABLES PARA LABORATORIO

Sheet NP DPSMA
A1: NOTA DE PEDIDO | J1: N° | K1: 07/2022
A3: JURISDICCIÓN: | D3: 040 - MINISTERIO DE SALUD
A4: SAF: | D4: 011 - DIRECCION PROVINCIAL DE ADMINISTRACION DEL MINISTERIO DE SALUD
A5: UNIDAD EJECUTORA: | D5: 488 - DIRECCION PROVINCIAL DE SALUD Y MEDIO AMBIENTE
A6: DEPENDENCIA SOLICITANTE: | D6: 488 - DIRECCION PROVINCIAL DE SALUD Y MEDIO AMBIENTE
A7: PERIODO UTILIZACIÓN: | D7: TRES (3) MESES
A8: OBJETO: | D8: ADQUISICION DEL RUBRO DESCARTABLES PARA LABORATORIO
A10: Ítem | B10: Codigo Item | C10: DESCRIPCIÓN | H10: Adjunta Detalle Técnico | I10: Unidad Medida | J10: Precio Unitario Estimado | K10: Cantidad Solicitada
A12: 1 | C12: ='SAF 011 - NECESIDAD TRIMESTRAL'!E12 -> BOLSAS COLECTORAS; TIPO: ESTERIL, USO: MUESTREO, CAPACIDAD: 400 mL | H12: NO | I12: ='SAF 011 - NECESIDAD TRIMESTRAL'!F12 -> UNIDAD | J12: ='SAF 011 - NECESIDAD TRIMESTRAL'!AX12 -> 4450 | K12: ='SAF 011 - NECESIDAD TRIMESTRAL'!AE12 -> 10 | L12: precio de la unidad o paquete?
A13: 2 | C13: ='SAF 011 - NECESIDAD TRIMESTRAL'!E15 -> BOLSAS PARA DIGESTOR 1000 ML. 18 X 29 CM CON CIERRE X 100 UNIDADES TIPO GAMAFIL | H13: NO | I13: ='SAF 011 - NECESIDAD TRIMESTRAL'!F15 -> CAJA | J13: ='SAF 011 - NECESIDAD TRIMESTRAL'!AX15 -> 16500 | K13: ='SAF 011 - NECESIDAD TRIMESTRAL'!AE15 -> 1
A14: 3 | C14: ='SAF 011 - NECESIDAD TRIMESTRAL'!E20 -> EQUIPO AQASSAY ARSENICO DISPOSITIVO BURBUJEADOR TIPO GT LAB | H14: NO | I14: ='SAF 011 - NECESIDAD TRIMESTRAL'!F20 -> UNIDAD | J14: ='SAF 011 - NECESIDAD TRIMESTRAL'!AX20 -> 18300 | K14: ='SAF 011 - NECESIDAD TRIMESTRAL'!AE20 -> 1
A15: 4 | C15: ='SAF 011 - NECESIDAD TRIMESTRAL'!E21 -> EQUIPO DE VIDRIO PARA FILTRACIÓN POR MEMBRANAS DE Ø47MM TIPO GLASSCO COMPUESTO POR: KITASATOS DE BOCA ESMERILADA X 1000 ML, INTERMEDIARIOS CON DISCO SINTERIZADO DE Ø 47MM, VASOS GRADUADOS X 300 ML Y PINZAS METÁLICAS. | H15: NO | I15: ='SAF 011 - NECESIDAD TRIMESTRAL'!F21 -> UNIDAD | J15: ='SAF 011 - NECESIDAD TRIMESTRAL'!AX21 -> 45800 | K15: ='SAF 011 - NECESIDAD TRIMESTRAL'!AE21 -> 10 | L15: IPP?
A16: 5 | C16: ='SAF 011 - NECESIDAD TRIMESTRAL'!E23 -> ERLENMEYER; TIPO: BOCA COMUN, CAPACIDAD: 500 mL, GRADUADO: SI, GRADUACION: SI TIPO GLASSCO | H16: NO | I16: ='SAF 011 - NECESIDAD TRIMESTRAL'!F23 -> UNIDAD | J16: ='SAF 011 - NECESIDAD TRIMESTRAL'!AX23 -> 1300 | K16: ='SAF 011 - NECESIDAD TRIMESTRAL'!AE23 -> 10
A17: 6 | C17: ='SAF 011 - NECESIDAD TRIMESTRAL'!E24 -> FILTRO DE MEMBRANA DE CN ESTERIL, Ø47MM (045ɥm X 1.000 U). | H17: NO | I17: ='SAF 011 - NECESIDAD TRIMESTRAL'!F24 -> UNIDAD | J17: ='SAF 011 - NECESIDAD TRIMESTRAL'!AX24 -> 45300 | K17: ='SAF 011 - NECESIDAD TRIMESTRAL'!AE24 -> 1
A18: 7 | C18: ='SAF 011 - NECESIDAD TRIMESTRAL'!E25 -> FRASCO GRADUADO C/TAPA A ROSCA AUTOCLAVABLE X 250 ML TIPO GLASSCO | H18: NO | I18: ='SAF 011 - NECESIDAD TRIMESTRAL'!F25 -> UNIDAD | J18: ='SAF 011 - NECESIDAD TRIMESTRAL'!AX25 -> 820 | K18: ='SAF 011 - NECESIDAD TRIMESTRAL'!AE25 -> 20
A19: 8 | C19: ='SAF 011 - NECESIDAD TRIMESTRAL'!E31 -> MATRAZ AFORADO MATRAZ AFORADO; ESTADO: SOLIDO, MATERIAL: POLIPROPILENO, PRESENTACION: UNIDAD, CAPACIDAD: 100 mL | H19: NO | I19: ='SAF 011 - NECESIDAD TRIMESTRAL'!F31 -> UNIDAD | J19: ='SAF 011 - NECESIDAD TRIMESTRAL'!AX31 -> 950 | K19: ='SAF 011 - NECESIDAD TRIMESTRAL'!AE31 -> 5
A20: 9 | C20: ='SAF 011 - NECESIDAD TRIMESTRAL'!E32 -> MATRAZ AFORADO MATRAZ AFORADO; ESTADO: SOLIDO, MATERIAL: POLIPROPILENO, PRESENTACION: UNIDAD, CAPACIDAD: 250 mL | H20: NO | I20: ='SAF 011 - NECESIDAD TRIMESTRAL'!F32 -> UNIDAD | J20: ='SAF 011 - NECESIDAD TRIMESTRAL'!AX32 -> 1071.64 | K20: ='SAF 011 - NECESIDAD TRIMESTRAL'!AE32 -> 5
A21: 10 | C21: ='SAF 011 - NECESIDAD TRIMESTRAL'!E35 -> PAPEL FILTRO; FORMA: CIRCULAR, DIMENSION: 110 mm, PORO: WATMAN 40/41, PRESENTACION: ENVASE X 100 | H21: NO | I21: ='SAF 011 - NECESIDAD TRIMESTRAL'!F35 -> CAJA | J21: ='SAF 011 - NECESIDAD TRIMESTRAL'!AX35 -> 8791 | K21: ='SAF 011 - NECESIDAD TRIMESTRAL'!AE35 -> 1
A22: 11 | C22: ='SAF 011 - NECESIDAD TRIMESTRAL'!E37 -> PICNÓMETRO DE VIDRIO C/TERMÓMETRO INCLUIDO C/TAPA ESMERILADA TIPO FITE X 5 ml | H22: NO | I22: ='SAF 011 - NECESIDAD TRIMESTRAL'!F37 -> UNIDAD | J22: ='SAF 011 - NECESIDAD TRIMESTRAL'!AX37 -> 65000 | K22: ='SAF 011 - NECESIDAD TRIMESTRAL'!AE37 -> 1 | L22: IPP?
A23: 12 | C23: ='SAF 011 - NECESIDAD TRIMESTRAL'!E38 -> PINZA PMP C/EXTREMO EN PUNTA AUTOCLAVABLE TIPO BRAND | H23: NO | I23: ='SAF 011 - NECESIDAD TRIMESTRAL'!F38 -> UNIDAD | J23: ='SAF 011 - NECESIDAD TRIMESTRAL'!AX38 -> 3700 | K23: ='SAF 011 - NECESIDAD TRIMESTRAL'!AE38 -> 5
A24: 13 | C24: ='SAF 011 - NECESIDAD TRIMESTRAL'!E41 -> PLACAS DE PETRI PLACAS DE PETRI; MATERIAL: PLASTICO ESTERIL, DIAMETRO: 5 Cm, ALTURA: SIN VALOR | H24: NO | I24: ='SAF 011 - NECESIDAD TRIMESTRAL'!F41 -> UNIDAD | J24: ='SAF 011 - NECESIDAD TRIMESTRAL'!AX41 -> 32 | K24: ='SAF 011 - NECESIDAD TRIMESTRAL'!AE41 -> 400
A25: 14 | C25: ='SAF 011 - NECESIDAD TRIMESTRAL'!E42 -> PLACAS DE PETRI PLACAS DE PETRI; MATERIAL: SOLIDO, DIAMETRO: 100 mm, ALTURA: 15 mm | H25: NO | I25: ='SAF 011 - NECESIDAD TRIMESTRAL'!F42 -> UNIDAD | J25: ='SAF 011 - NECESIDAD TRIMESTRAL'!AX42 -> 34.15 | K25: ='SAF 011 - NECESIDAD TRIMESTRAL'!AE42 -> 300
A26: 15 | C26: ='SAF 011 - NECESIDAD TRIMESTRAL'!E43 -> SOPLA DE GOMA P/BURETA TIPO DAIGGER | H26: NO | I26: ='SAF 011 - NECESIDAD TRIMESTRAL'!F43 -> UNIDAD | J26: ='SAF 011 - NECESIDAD TRIMESTRAL'!AX43 -> 22000 | K26: ='SAF 011 - NECESIDAD TRIMESTRAL'!AE43 -> 2
A27: 16 | C27: ='SAF 011 - NECESIDAD TRIMESTRAL'!E48 -> TIPS AMARILLOS C/CORONA 5-200 UL X 1000 UNIDADES TIPO PARALWALL | H27: NO | I27: ='SAF 011 - NECESIDAD TRIMESTRAL'!F48 -> CAJA | J27: ='SAF 011 - NECESIDAD TRIMESTRAL'!AX48 -> 1230 | K27: ='SAF 011 - NECESIDAD TRIMESTRAL'!AE48 -> 2
A28: 17 | C28: ='SAF 011 - NECESIDAD TRIMESTRAL'!E51 -> TUBO DE ENSAYO SIN SELLO TIPO PYREX ( Ø 16 X 150 MM) | H28: NO | I28: ='SAF 011 - NECESIDAD TRIMESTRAL'!F51 -> UNIDAD | J28: ='SAF 011 - NECESIDAD TRIMESTRAL'!AX51 -> 38 | K28: ='SAF 011 - NECESIDAD TRIMESTRAL'!AE51 -> 300
A30: Costo total estimado: SETECIENTOS NOVENTA Y CINCO MIL TRESCIENTOS CUATRO CON 20/100.- | J30: =SUMPRODUCT(J12:J28,K12:K28) -> 795304.2
J32: 4450 | K32: =J32*K12 -> 44500
J33: 16500 | K33: =J33*K13 -> 16500
J34: 18300 | K34: =J34*K14 -> 18300
J35: 45800 | K35: =J35*K15 -> 458000
J36: 1300 | K36: =J36*K16 -> 13000
J37: 45300 | K37: =J37*K17 -> 45300
J38: 820 | K38: =J38*K18 -> 16400
J39: 950 | K39: =J39*K19 -> 4750
J40: 1071.64 | K40: =J40*K20 -> 5358.2
J41: 8791 | K41: =J41*K21 -> 8791
J42: 65000 | K42: =J42*K22 -> 65000
J43: 3700 | K43: =J43*K23 -> 18500
... J48: 38 | K48: =J48*K28 -> 11400
K49: =SUM(K32:K48) -> 795304.2

Sheet APG DPSMA
A1: EJERCICIO: | D1: 2022 | P1: AUTORIZACION PARA GASTAR
A4: JURISDICCIÓN: | G4: ='NP DPSMA'!D3 -> 040 - MINISTERIO DE SALUD
A5: SAF: | G5: ='NP DPSMA'!D4 -> 011 - DIRECCION PROVINCIAL DE ADMINISTRACION DEL MINISTERIO DE SALUD
A6: UNIDAD EJECUTORA: | G6: ='NP DPSMA'!D5 -> 488 - DIRECCION PROVINCIAL DE SALUD Y MEDIO AMBIENTE
A7: DEPENDENCIA SOLICITANTE: | G7: ='NP DPSMA'!D6 -> 488 - DIRECCION PROVINCIAL DE SALUD Y MEDIO AMBIENTE
A8: AUTORIZACIÓN:
A9: Señor Director de Administración o Titular del Servicio Administrativo Financiero:
A10: Autorizo la realización de los trámites correspondientes, a fin de proveer a este Organismo los bienes, servicios o ejecución de obras públicas que se detallan en Nota de Pedido N° 07/2022 , afectando la erogación resultante a los créditos presupuestarios aprobados a favor de esta Unidad Ejecutora, conforme al siguiente detalle:
A12: IMPUTACIÓN PRESUPUESTARIA
A13: CÓDIGO | O13: DENOMINACIÓN DE LA PARTIDA PRESUPUESTARIA | Q13: IMPORTE
A14: PR | B14: SB | C14: PY | D14: AC | E14: OB | F14: UG | G14: FIN | H14: FUN | I14: I | J14: P | K14: P | L14: SubP | M14: M | N14: FF
A15: 22 | D15: 1 | F15: 4901 | G15: 4 | H15: 4 | I15: 2 | J15: 9 | K15: 5 | M15: 1 | N15: 1.1 | O15: UTILES MENORES MEDICOS, QUIRURGICOS Y DE LABORATORIO | Q15: ='NP DPSMA'!J30 -> 795304.2
A38: TOTAL DE PESOS: SETECIENTOS NOVENTA Y CINCO MIL TRESCIENTOS CUATRO CON 20/100.- | Q38: =SUM(Q15:Q37) -> 795304.2
A40: JUSTIFICACIÓN:
A41: ='NP DPSMA'!D8 -> ADQUISICION DEL RUBRO DESCARTABLES PARA LABORATORIO
