Workbook
Name A: 'Necesidades Trimestrales'!#REF!

Sheet Necesidades Trimestrales
C2: Pedido de Necesidades Trimestrales
A4: JURISDICCION: | C4: 40 - Ministerio de Salud
A5: SAF N°: | C5: 28 - MATERNIDAD PROVINCIAL 25 DE MAYO
A6: EJERCICIO: | C6: Año 2022
A7: TRIMESTRE: | C7: 2° TRIMESTRE
A9: ID | B9: CODIGO DE ITEMS | C9: RUBRO DE COMPRA | D9: I.P.P | E9: DESCRIPCION | F9: UNIDAD DE MEDIDA | G9: CANTIDAD | H9: PRECIO UNITARIO ESTIMADO | I9: IMPORTE TOTAL ESTIMADO
A10: 1 | C10: QUIMICOS | D10: 2.5.1 | E10: ALERE DETERMINE SYPHILIS TP PRESENTACION: SOBRE X 20 DET | F10: SOBRE | G10: 10 | H10: 13886.25 | I10: =+H10*G10 -> 138862.5
A11: 2 | C11: QUIMICOS | D11: 2.5.1 | E11: AMPOULE ADAPTER X 150 UN ROCHE | F11: CAJA | G11: 4 | H11: 9168.17 | I11: =+H11*G11 -> 36672.68
A12: 3 | C12: QUIMICOS | D12: 2.5.1 | E12: BILIRRUBINA DIRECTA COBAS C-311 ROCHE X 350 DET | F12: CASSETTE | G12: 2 | H12: 4920 | I12: =+H12*G12 -> 9840
A13: 4 | C13: QUIMICOS | D13: 2.5.1 | E13: BILIRRUBINA TOTAL GEN 3 COBAS C-311 ROCHE X 250 DET | F13: CASSETTE | G13: 4 | H13: 5050 | I13: =+H13*G13 -> 20200
A14: 5 | C14: QUIMICOS | D14: 2.5.1 | E14: CAJAS TARJETAS LISS/COOMBS PARA TECNICA EN GEL X 48 UNIDADES DIAMED-BIORAD | F14: CAJA | G14: 3 | H14: 18091.8 | I14: =+H14*G14 -> 54275.4
A15: 6 | C15: QUIMICOS | D15: 2.5.1 | E15: CEPILLOS PARA TUBOS DE 1,5 CM X 25 CM | F15: UNIDAD | G15: 10 | H15: 317.4 | I15: =+H15*G15 -> 3174
A16: 7 | C16: QUIMICOS | D16: 2.5.1 | E16: CHAGAS ELISA LISADO WIENER X 96 DET | F16: CAJA | G16: 18 | H16: 13088 | I16: =+H16*G16 -> 235584
A17: 8 | C17: QUIMICOS | D17: 2.5.1 | E17: CHAGAS HAI WIENER X 96 DET | F17: CAJA | G17: 12 | H17: 13899 | I17: =+H17*G17 -> 166788
A18: 9 | C18: QUIMICOS | D18: 2.5.1 | E18: CLEANSER EZ PROBE PARA BC 3000 PLUS PRTESENTACION: BOTELLA X 50 ML | F18: UNIDAD | G18: 5 | H18: 7650 | I18: =+H18*G18 -> 38250
A19: 10 | C19: QUIMICOS | D19: 2.5.1 | E19: COBAS B 221 COMBITROL PLUS B LEVEL 1 x 30 UNIDADES ROCHE | F19: CAJA | G19: 1 | H19: 26023 | I19: =+H19*G19 -> 26023
A20: 11 | C20: QUIMICOS | D20: 2.5.1 | E20: COBAS B 221 COMBITROL PLUS B LEVEL 2 x 30 UNIDADES ROCHE | F20: CAJA | G20: 1 | H20: 26023 | I20: =+H20*G20 -> 26023
A21: 12 | C21: QUIMICOS | D21: 2.5.1 | E21: COBAS B 221 COMBITROL PLUS B LEVEL 3 x 30 UNIDADES ROCHE | F21: CAJA | G21: 1 | H21: 26023 | I21: =+H21*G21 -> 26023
... A58: 49 | C58: QUIMICOS | D58: 2.5.1 | E58: W19 CONTROL AA 3 NIVELES 3 X 3 ML (BAJO-NORMAL-ALTO) WIENER | F58: UNIDAD | G58: 1 | H58: 8847 | I58: =+H58*G58 -> 8847
C60: Especificidades Item N° 1: 1 a 49
C62: Descripción técnica
C64: Plazos de entrega | D64: 20(veinte) dias habiles desde la firma del documento contractual
C66: Lugar de Entrega: | D66: SERVICIO DE LABORATORIO -MATERNIDAD PROVINCIAL 25 DE MAYO - HERNANDO DE PEDRAZA 1650
D67: Horario de 07:00 a 12:00
C69: Calidad Minima esperada
C71: Mantenimiento | D71: 30 (treinta) dias habiles
C73: Garantia

Sheet  NotaPedido
A1: NOTA DE PEDIDO | H1: N° | I1: 37/2022
A3: JURISDICCIÓN: | D3: 40- Ministerio de Salud
A4: SAF: | D4: 28- Maternidad Provincial 25 de Mayo
A5: UNIDAD EJECUTORA: | D5: 169-Direccion Asistencial
A6: DEPENDENCIA SOLICITANTE: | D6: Servicio de Laboratorio-(Bacteriología)-(Hemoterapia)
A7: PERIODO UTILIZACIÓN: | D7: 2 ° Trimestre -Año 2022
A8: OBJETO: | D8: ADQUISICION DE COMPUESTOS QUIMICOS
A10: Ítem | B10: Codigo Item | C10: DESCRIPCIÓN | F10: Adjunta Detalle Técnico | G10: Unidad Medida | H10: Precio Unitario Estimado | I10: Cantidad Solicitada
A12: =+'Necesidades Trimestrales'!A10 -> 1 | B12: 0 | C12: AMPOULE ADAPTER X 150 UN ROCHE | D12: =+'Necesidades Trimestrales'!E10 -> ALERE DETERMINE SYPHILIS TP PRESENTACION: SOBRE X 20 DET | E12: AMPOULE ADAPTER X 150 UN ROCHE | F12: NO | G12: =+'Necesidades Trimestrales'!F10 -> SOBRE | H12: =+'Necesidades Trimestrales'!H10 -> 13886.25 | I12: =+'Necesidades Trimestrales'!G10 -> 10
A13: =+'Necesidades Trimestrales'!A11 -> 2 | B13: 0 | C13: BILIRRUBINA DIRECTA COBAS C-311 ROCHE X 350 DET | D13: =+'Necesidades Trimestrales'!E11 -> AMPOULE ADAPTER X 150 UN ROCHE | E13: ='Necesidades Trimestrales'!F12 -> CASSETTE | F13: NO | G13: =+'Necesidades Trimestrales'!F11 -> CAJA | H13: =+'Necesidades Trimestrales'!H11 -> 9168.17 | I13: =+'Necesidades Trimestrales'!G11 -> 4
A14: =+'Necesidades Trimestrales'!A12 -> 3 | B14: 0 | C14: BILIRRUBINA TOTAL GEN 3 COBAS C-311 ROCHE X 250 DET | D14: =+'Necesidades Trimestrales'!E12 -> BILIRRUBINA DIRECTA COBAS C-311 ROCHE X 350 DET | E14: ='Necesidades Trimestrales'!F13 -> CASSETTE | F14: NO | G14: =+'Necesidades Trimestrales'!F12 -> CASSETTE | H14: =+'Necesidades Trimestrales'!H12 -> 4920 | I14: =+'Necesidades Trimestrales'!G12 -> 2
A15: =+'Necesidades Trimestrales'!A13 -> 4 | B15: 0 | C15: CHAGAS ELISA LISADO WIENER X 96 DET | D15: =+'Necesidades Trimestrales'!E13 -> BILIRRUBINA TOTAL GEN 3 COBAS C-311 ROCHE X 250 DET | E15: ='Necesidades Trimestrales'!F16 -> CAJA | F15: NO | G15: =+'Necesidades Trimestrales'!F13 -> CASSETTE | H15: =+'Necesidades Trimestrales'!H13 -> 5050 | I15: =+'Necesidades Trimestrales'!G13 -> 4
A16: =+'Necesidades Trimestrales'!A14 -> 5 | B16: 0 | C16: CHAGAS HAI WIENER X 96 DET | D16: =+'Necesidades Trimestrales'!E14 -> CAJAS TARJETAS LISS/COOMBS PARA TECNICA EN GEL X 48 UNIDADES DIAMED-BIORAD | E16: ='Necesidades Trimestrales'!F17 -> CAJA | F16: NO | G16: =+'Necesidades Trimestrales'!F14 -> CAJA | H16: =+'Necesidades Trimestrales'!H14 -> 18091.8 | I16: =+'Necesidades Trimestrales'!G14 -> 3
A17: =+'Necesidades Trimestrales'!A15 -> 6 | B17: 0 | C17: CLEANSER EZ PROBE PARA BC 3000 PLUS PRTESENTACION: BOTELLA X 50 ML | D17: =+'Necesidades Trimestrales'!E15 -> CEPILLOS PARA TUBOS DE 1,5 CM X 25 CM | E17: ='Necesidades Trimestrales'!F18 -> UNIDAD | F17: NO | G17: =+'Necesidades Trimestrales'!F15 -> UNIDAD | H17: =+'Necesidades Trimestrales'!H15 -> 317.4 | I17: =+'Necesidades Trimestrales'!G15 -> 10
A18: =+'Necesidades Trimestrales'!A16 -> 7 | B18: 0 | C18: COBAS B 221 COMBITROL PLUS B LEVEL 1 x 30 UNIDADES ROCHE | D18: =+'Necesidades Trimestrales'!E16 -> CHAGAS ELISA LISADO WIENER X 96 DET | E18: ='Necesidades Trimestrales'!F19 -> CAJA | F18: NO | G18: =+'Necesidades Trimestrales'!F16 -> CAJA | H18: =+'Necesidades Trimestrales'!H16 -> 13088 | I18: =+'Necesidades Trimestrales'!G16 -> 18
A19: =+'Necesidades Trimestrales'!A17 -> 8 | B19: 0 | C19: COBAS B 221 COMBITROL PLUS B LEVEL 2 x 30 UNIDADES ROCHE | D19: =+'Necesidades Trimestrales'!E17 -> CHAGAS HAI WIENER X 96 DET | E19: ='Necesidades Trimestrales'!F20 -> CAJA | F19: NO | G19: =+'Necesidades Trimestrales'!F17 -> CAJA | H19: =+'Necesidades Trimestrales'!H17 -> 13899 | I19: =+'Necesidades Trimestrales'!G17 -> 12
A20: =+'Necesidades Trimestrales'!A18 -> 9 | B20: 0 | C20: COBAS B 221 COMBITROL PLUS B LEVEL 3 x 30 UNIDADES ROCHE | D20: =+'Necesidades Trimestrales'!E18 -> CLEANSER EZ PROBE PARA BC 3000 PLUS PRTESENTACION: BOTELLA X 50 ML | E20: ='Necesidades Trimestrales'!F21 -> CAJA | F20: NO | G20: =+'Necesidades Trimestrales'!F18 -> UNIDAD | H20: =+'Necesidades Trimestrales'!H18 -> 7650 | I20: =+'Necesidades Trimestrales'!G18 -> 5
A21: =+'Necesidades Trimestrales'!A19 -> 10 | B21: 0 | C21: COBAS B121 / B221 ELECTRODO DE PO2 ROCHE | D21: =+'Necesidades Trimestrales'!E19 -> COBAS B 221 COMBITROL PLUS B LEVEL 1 x 30 UNIDADES ROCHE | E21: ='Necesidades Trimestrales'!F22 -> UNIDAD | F21: NO | G21: =+'Necesidades Trimestrales'!F19 -> CAJA | H21: =+'Necesidades Trimestrales'!H19 -> 26023 | I21: =+'Necesidades Trimestrales'!G19 -> 1
A22: =+'Necesidades Trimestrales'!A20 -> 11 | B22: 0 | C22: COBAS B121 / B221 ELECTRODO DE POTASIO (K) ROCHE | D22: =+'Necesidades Trimestrales'!E20 -> COBAS B 221 COMBITROL PLUS B LEVEL 2 x 30 UNIDADES ROCHE | E22: ='Necesidades Trimestrales'!F23 -> UNIDAD | F22: NO | G22: =+'Necesidades Trimestrales'!F20 -> CAJA | H22: =+'Necesidades Trimestrales'!H20 -> 26023 | I22: =+'Necesidades Trimestrales'!G20 -> 1
A23: =+'Necesidades Trimestrales'!A21 -> 12 | B23: 0 | C23: COBAS B121 / B221 ELECTRODO DE SODIO (Na) ROCHE | D23: =+'Necesidades Trimestrales'!E21 -> COBAS B 221 COMBITROL PLUS B LEVEL 3 x 30 UNIDADES ROCHE | E23: ='Necesidades Trimestrales'!F24 -> UNIDAD | F23: NO | G23: =+'Necesidades Trimestrales'!F21 -> CAJA | H23: =+'Necesidades Trimestrales'!H21 -> 26023 | I23: =+'Necesidades Trimestrales'!G21 -> 1
A24: =+'Necesidades Trimestrales'!A22 -> 13 | B24: 0 | C24: COBAS B121 / B221 ELECTRODO DE CALCIO ROCHE | D24: =+'Necesidades Trimestrales'!E22 -> COBAS B121 / B221 ELECTRODO DE PO2 ROCHE | E24: ='Necesidades Trimestrales'!F25 -> UNIDAD | F24: NO | G24: UNIDAD | H24: =+'Necesidades Trimestrales'!H22 -> 13880 | I24: =+'Necesidades Trimestrales'!G22 -> 1
A25: =+'Necesidades Trimestrales'!A23 -> 14 | B25: 0 | C25: COBAS B121 / B221 ELECTRODO DE CLIORO ROCHE | D25: =+'Necesidades Trimestrales'!E23 -> COBAS B121 / B221 ELECTRODO DE POTASIO (K) ROCHE | E25: ='Necesidades Trimestrales'!F26 -> UNIDAD | F25: NO | G25: UNIDAD | H25: =+'Necesidades Trimestrales'!H23 -> 13880 | I25: =+'Necesidades Trimestrales'!G23 -> 1
A26: =+'Necesidades Trimestrales'!A24 -> 15 | B26: 0 | C26: COBAS B121 / B221 ELECTRODO DE PH ROCHE | D26: =+'Necesidades Trimestrales'!E24 -> COBAS B121 / B221 ELECTRODO DE SODIO (Na) ROCHE | E26: ='Necesidades Trimestrales'!F27 -> UNIDAD | F26: NO | G26: UNIDAD | H26: =+'Necesidades Trimestrales'!H24 -> 52717 | I26: =+'Necesidades Trimestrales'!G24 -> 1
A27: =+'Necesidades Trimestrales'!A25 -> 16 | B27: 0 | C27: COBAS B221 REFERENCE CONTACT ( RCON) ROCHE | D27: =+'Necesidades Trimestrales'!E25 -> COBAS B121 / B221 ELECTRODO DE CALCIO ROCHE | E27: ='Necesidades Trimestrales'!F28 -> UNIDAD | F27: NO | G27: UNIDAD | H27: =+'Necesidades Trimestrales'!H25 -> 23156 | I27: =+'Necesidades Trimestrales'!G25 -> 1
A28: =+'Necesidades Trimestrales'!A26 -> 17 | B28: 0 | C28: COBAS SAMPLE CLEANER 1 (MULTICLEAN ) 12 x 60 ml ROCHE | D28: =+'Necesidades Trimestrales'!E26 -> COBAS B121 / B221 ELECTRODO DE CLIORO ROCHE | E28: ='Necesidades Trimestrales'!F29 -> CAJA | F28: NO | G28: UNIDAD | H28: =+'Necesidades Trimestrales'!H26 -> 13880 | I28: =+'Necesidades Trimestrales'!G26 -> 1
A29: =+'Necesidades Trimestrales'!A27 -> 18 | B29: 0 | C29: CUBRE OBJETOS 20 X 20 X 100 UNID. | D29: =+'Necesidades Trimestrales'!E27 -> COBAS B121 / B221 ELECTRODO DE PH ROCHE | E29: ='Necesidades Trimestrales'!F31 -> CAJA | F29: NO | G29: UNIDAD | H29: =+'Necesidades Trimestrales'!H27 -> 13880 | I29: =+'Necesidades Trimestrales'!G27 -> 1
A30: =+'Necesidades Trimestrales'!A28 -> 19 | B30: 0 | C30: DETERGENTE P/CONTADOR MINDRAY BC3000 PLUS X 5 L | D30: =+'Necesidades Trimestrales'!E28 -> COBAS B221 REFERENCE CONTACT ( RCON) ROCHE | E30: ='Necesidades Trimestrales'!F32 -> UNIDAD | F30: NO | G30: UNIDAD | H30: =+'Necesidades Trimestrales'!H28 -> 29300 | I30: =+'Necesidades Trimestrales'!G28 -> 1
A31: =+'Necesidades Trimestrales'!A29 -> 20 | B31: 0 | C31: DILUYENTE PARA CONTADOR HEMATOLOGICO MINDRAY BC-3000 PLUS X 20 LITROS | D31: =+'Necesidades Trimestrales'!E29 -> COBAS SAMPLE CLEANER 1 (MULTICLEAN ) 12 x 60 ml ROCHE | E31: ='Necesidades Trimestrales'!F33 -> UNIDAD | F31: NO | G31: =+'Necesidades Trimestrales'!F29 -> CAJA | H31: =+'Necesidades Trimestrales'!H29 -> 6020 | I31: =+'Necesidades Trimestrales'!G29 -> 1
A32: =+'Necesidades Trimestrales'!A30 -> 21 | B32: 0 | C32: FECUNTEST STRIPS (WIENER LAB) X 25 UN | D32: =+'Necesidades Trimestrales'!E30 -> CUBETAS PARA COAGULOMETRO SIEMENS BFT II X 100 UNIDADES X 5 PLANCHAS | E32: ='Necesidades Trimestrales'!F34 -> FRASCO | F32: NO | G32: =+'Necesidades Trimestrales'!F30 -> CAJA | H32: =+'Necesidades Trimestrales'!H30 -> 28433.75 | I32: =+'Necesidades Trimestrales'!G30 -> 1
A33: =+'Necesidades Trimestrales'!A31 -> 22 | B33: 0 | C33: HBSAG ELISA WIENER X 96 DET | D33: =+'Necesidades Trimestrales'!E31 -> CUBRE OBJETOS 20 X 20 X 100 UNID. | E33: ='Necesidades Trimestrales'!F35 -> CAJA | F33: NO | G33: =+'Necesidades Trimestrales'!F31 -> CAJA | H33: =+'Necesidades Trimestrales'!H31 -> 124 | I33: =+'Necesidades Trimestrales'!G31 -> 5
A34: =+'Necesidades Trimestrales'!A32 -> 23 | B34: 0 | C34: KIT PARA RETICULOCITOS (AZUL DE CRESIL BRILLANTE) X 50 TUBOS DELTALAB | D34: =+'Necesidades Trimestrales'!E32 -> DETERGENTE P/CONTADOR MINDRAY BC3000 PLUS X 5 L | E34: ='Necesidades Trimestrales'!F38 -> CAJA | F34: NO | G34: UNIDAD | H34: =+'Necesidades Trimestrales'!H32 -> 6996 | I34: =+'Necesidades Trimestrales'!G32 -> 18
A35: =+'Necesidades Trimestrales'!A33 -> 24 | B35: 0 | C35: LAMPARA HALOGENA COBAS C-311 ROCHE | D35: =+'Necesidades Trimestrales'!E33 -> DILUYENTE PARA CONTADOR HEMATOLOGICO MINDRAY BC-3000 PLUS X 20 LITROS | E35: ='Necesidades Trimestrales'!F39 -> UNIDAD | F35: NO | G35: UNIDAD | H35: =+'Necesidades Trimestrales'!H33 -> 9174 | I35: =+'Necesidades Trimestrales'!G33 -> 18
A36: =+'Necesidades Trimestrales'!A34 -> 25 | B36: 0 | C36: LYSE CF-BC 3000 PLUS x 1 litro LABIX | D36: =+'Necesidades Trimestrales'!E34 -> FECUNTEST STRIPS (WIENER LAB) X 25 UN | E36: ='Necesidades Trimestrales'!F40 -> CAJA | F36: NO | G36: CAJA | H36: =+'Necesidades Trimestrales'!H34 -> 2045 | I36: =+'Necesidades Trimestrales'!G34 -> 30
A37: =+'Necesidades Trimestrales'!A35 -> 26 | B37: 0 | C37: M-52 DIFF LYSE PARA MINDRAY BC-5150 X 500 ML | D37: =+'Necesidades Trimestrales'!E35 -> HBSAG ELISA WIENER X 96 DET | E37: ='Necesidades Trimestrales'!F41 -> UNIDAD | F37: NO | G37: =+'Necesidades Trimestrales'!F35 -> CAJA | H37: =+'Necesidades Trimestrales'!H35 -> 17319 | I37: =+'Necesidades Trimestrales'!G35 -> 20
A38: =+'Necesidades Trimestrales'!A36 -> 27 | B38: 0 | C38: M-52 LH LYSE PARA MINDRAY BC-5150 X 100 ML | D38: =+'Necesidades Trimestrales'!E36 -> HEMOCULTIVO AUTOMATIZADO P/ PEDIATRICO X 100 U | E38: ='Necesidades Trimestrales'!F42 -> UNIDAD | F38: NO | G38: =+'Necesidades Trimestrales'!F36 -> CAJA | H38: =+'Necesidades Trimestrales'!H36 -> 1190.25 | I38: =+'Necesidades Trimestrales'!G36 -> 200
A39: =+'Necesidades Trimestrales'!A37 -> 28 | B39: 0 | C39: M-52D - DILUENT PARA MINDRAY BC-5150 X 20 LITROS | D39: =+'Necesidades Trimestrales'!E37 -> HEMOCULTIVO AUTOMATIZADO P/BACTALERT ADULTO X 100 U | E39: ='Necesidades Trimestrales'!F43 -> UNIDAD | F39: NO | G39: =+'Necesidades Trimestrales'!F37 -> CAJA | H39: =+'Necesidades Trimestrales'!H37 -> 1190.25 | I39: =+'Necesidades Trimestrales'!G37 -> 25
A40: =+'Necesidades Trimestrales'!A38 -> 29 | B40: 0 | C40: MICROPIPETA REGULABLE 100 - 1000 ul SOCOREX | D40: =+'Necesidades Trimestrales'!E38 -> KIT PARA RETICULOCITOS (AZUL DE CRESIL BRILLANTE) X 50 TUBOS DELTALAB | E40: ='Necesidades Trimestrales'!F44 -> UNIDAD | F40: NO | G40: =+'Necesidades Trimestrales'!F38 -> CAJA | H40: =+'Necesidades Trimestrales'!H38 -> 9775 | I40: =+'Necesidades Trimestrales'!G38 -> 2
A41: =+'Necesidades Trimestrales'!A39 -> 30 | B41: 0 | C41: MICROPIPETA REGULABLE 10-100 ul SOCOREX | D41: =+'Necesidades Trimestrales'!E39 -> LAMPARA HALOGENA COBAS C-311 ROCHE | E41: ='Necesidades Trimestrales'!F45 -> UNIDAD | F41: NO | G41: =+'Necesidades Trimestrales'!F39 -> UNIDAD | H41: =+'Necesidades Trimestrales'!H39 -> 78467 | I41: =+'Necesidades Trimestrales'!G39 -> 2
A42: =+'Necesidades Trimestrales'!A40 -> 31 | B42: 0 | C42: MICROPIPETA REGULABLE 20-200 ul SOCOREX | D42: =+'Necesidades Trimestrales'!E40 -> LYSE CF-BC 3000 PLUS x 1 litro LABIX | E42: ='Necesidades Trimestrales'!F46 -> UNIDAD | F42: NO | G42: UNIDAD | H42: =+'Necesidades Trimestrales'!H40 -> 11699 | I42: =+'Necesidades Trimestrales'!G40 -> 10
A43: =+'Necesidades Trimestrales'!A41 -> 32 | B43: 0 | C43: MICROPIPETA REGULABLE 5-50 ul SOCOREX | D43: =+'Necesidades Trimestrales'!E41 -> M-52 DIFF LYSE PARA MINDRAY BC-5150 X 500 ML | E43: ='Necesidades Trimestrales'!F47 -> UNIDAD | F43: NO | G43: =+'Necesidades Trimestrales'!F41 -> UNIDAD | H43: =+'Necesidades Trimestrales'!H41 -> 20210 | I43: =+'Necesidades Trimestrales'!G41 -> 25
...

Sheet Autor Gastar
A1: EJERCICIO: | D1: 2022 | P1: AUTORIZACION PARA GASTAR
A4: JURISDICCIÓN: | G4: 40- Ministerio de Salud
A5: SAF: | G5: 28- Maternidad Provincial 25 de Mayo
A6: UNIDAD EJECUTORA: | G6: Servicio de Laboratorio-(Bacteriología)-(Hemoterapia)
A7: DEPENDENCIA SOLICITANTE: | G7: Servicio de Laboratorio-(Bacteriología)-(Hemoterapia)
A8: AUTORIZACIÓN:
A9: Señor Jefe de Servicio Administrativo Financiero:
A10: Autorizo la realización de los trámites correspondientes, a fin de proveer a este Organismo los bienes y/o servicios que se detallan en Nota de Pedido N° 37/2022 , afectando la erogación resultante a los créditos presupuestarios aprobados a favor de esta Unidad Ejecutora, conforme al siguiente detalle:"
A12: IMPUTACIÓN PRESUPUESTARIA
A13: CÓDIGO | O13: DENOMINACIÓN DE LA PARTIDA PRESUPUESTARIA | Q13: IMPORTE
A14: PR | B14: SB | C14: PY | D14: AC | E14: OB | F14: UG | G14: FIN | H14: FUN | I14: I | J14: P | K14: P | L14: SubP | M14: M | N14: FF
A15: 42 | D15: 2 | F15: 4901 | G15: 3 | H15: 1 | I15: 2 | J15: 3 | K15: 4 | M15: 1 | N15: 1.1 | O15: Productos de Papel y Carton | Q15: 172046
A16: 42 | D16: 2 | F16: 4901 | G16: 3 | H16: 1 | I16: 2 | J16: 5 | K16: 1 | M16: 1 | N16: 1.1 | O16: Compuestos Químicos | Q16: 3715442.3
A17: 42 | D17: 2 | F17: 4901 | G17: 3 | H17: 1 | I17: 2 | J17: 9 | K17: 3 | M17: 1 | N17: 1.1 | O17: Utiles y Materiales Electricos | Q17: 156934
A18: 42 | D18: 2 | F18: 4901 | G18: 3 | H18: 1 | I18: 2 | J18: 9 | K18: 5 | M18: 1 | N18: 1.1 | O18: Utiles Menores Médico, Quirúrgico y de Laboratorio | Q18: 65794
A19: TOTAL DE PESOS: : CUATRO MILLONES CIENTO DIEZ MIL DOSCIENTOS DIECISEIS CON 33/100 CENTAVOS | Q19: =SUM(Q15:Q18) -> 4110216.3
A21: JUSTIFICACIÓN:
A22: Para la adquisición de Compuestos Químicos, para ser destinados al Servicio de Laboratorio-Sector Bacteriología y Sector Hemoterapia de la Maternidad Provincial 25 de Mayo.-
