Workbook

Sheet gas
B2: Pedido de Necesidades Trimestrales
A4: JURISDICCION: | C4: 45- Ministerio de Desarrollo Social y Deporte.-
A5: SAF N°: | C5: 25- Direccion Provincial de Gestion Administracion y RRHH
A6: EJERCICIO: | C6: 2020
A7: TRIMESTRE: | C7: 3
A9: ID | B9: CODIGO ITEM | C9: RUBRO DE COMPRA | D9: I.P.P. | E9: DESCRIPCION | F9: UNIDAD DE MEDIDA | G9: CANTIDAD | H9: PRECIO UNITARIO ESTIMADO | I9: IMPORTE TOTAL ESTIMADO
A10: 28 | B10: 2.5.6-798.8 | C10: COMBUSTIBLES Y LUBRICANTES | D10: 2.5.6 | E10: GAS EN GARRAFA; CAPACIDAD: 10 Kg | F10: UNIDAD | G10: 240 | H10: 450 | I10: =+G10*H10 -> 108000
B13: Especificidades Item N° 1:
B15: Descripción técnica
B16: GARRAFA X 10 KGS. TIPO COMERCIAL
B17: Plazos y lugares de entrega
B18: SEMANAL
B19: COMEDOR | D19: CANTIDAD | E19: DOMICILIO DE ENTREGA
B20: ='[1]COMEDORES EMERGENTES'!$B$3 -> UNA SONRISA AV. LOS COBACHO | D20: 1 | E20: ='[1]COMEDORES EMERGENTES'!$G$3 -> Bº SAN CARLOS OESTE AV. Bonifacio cobacho 670
B21: ='[1]COMEDORES EMERGENTES'!$B$4 -> C.I.F Nº1 - RIVERA DEL VALLE Y FLORIDA | D21: 1 | E21: ='[1]COMEDORES EMERGENTES'!$G$4 -> AV. RIVIERA DEL VALLE ENTRE FLORIDA Y SANTA FE
B22: ='[1]COMEDORES EMERGENTES'!$B$5 -> C.I.F - RIVERA DEL VALLE - DILORENZO | D22: 1 | E22: ='[1]COMEDORES EMERGENTES'!$G$5 -> Bº RIVERA DEL VALLE ENTRE VILLA EUMELIA Y MONTE CRISTO
B23: ='[1]COMEDORES EMERGENTES'!$B$6 -> ESFUERZO PROPIO- Bº ALTOS DE CHOYA | D23: 1 | E23: ='[1]COMEDORES EMERGENTES'!$G$6 -> Bº MUNICIPAL 35VV. NORTE C/14
B24: ='[1]COMEDORES EMERGENTES'!$B$7 -> ANGELITOS - LOTEO SUSSEX | D24: 1 | E24: ='[1]COMEDORES EMERGENTES'!$G$7 -> Bº LOTEO SUSEX MZA.Nº 4 LOTE Nº3
B25: ='[1]COMEDORES EMERGENTES'!$B$8 -> CLUB DEPORTIVO CHACARITA | D25: 1 | E25: ='[1]COMEDORES EMERGENTES'!$G$8 -> CALLE DR.DERMIDIO GALINDEZ C/2660
B26: ='[1]COMEDORES EMERGENTES'!$B$9 -> LA MORO | D26: 1 | E26: ='[1]COMEDORES EMERGENTES'!$G$9 -> MAIPU NORTE 1º ETAPA MZA "H" Bº MI JARDIN
B27: ='[1]COMEDORES EMERGENTES'!$B$10 -> PAPA FRANCISCO | D27: 1 | E27: ='[1]COMEDORES EMERGENTES'!$G$10 -> ENTRE AV.TEREBINTO Y AV.SAN JUAN LOTE "2" MZA. "B"
B28: ='[1]COMEDORES EMERGENTES'!$B$11 -> E.P.C - 100 V.V NORTE | D28: 1 | E28: ='[1]COMEDORES EMERGENTES'!$G$11 -> Bº VV NORTE C/48 ENTRE ESPAÑA Y FRANCIA
B29: ='[1]COMEDORES EMERGENTES'!$B$12 -> HOGAR DE CRISTO - PADRE RAUL CONTRERAS | D29: 1 | E29: ='[1]COMEDORES EMERGENTES'!$G$12 -> Bº SANTA MARTA MZA. "S" LOTE "M" C/39
B30: ='[1]COMEDORES EMERGENTES'!$B$13 -> LA LUCIERNAGA | D30: 1 | E30: ='[1]COMEDORES EMERGENTES'!$G$13 -> Bº 20 V.V NORTE C/3
B31: ='[1]COMEDORES EMERGENTES'!$B$14 -> VALLE VIEJO - SUMALAO | D31: 1 | E31: ='[1]COMEDORES EMERGENTES'!$G$14 -> PADRE SEGURA S/N
B32: ='[1]COMEDORES EMERGENTES'!$B$15 -> NUESTRO FUTURO - LAS VIAS | D32: 1 | E32: ='[1]COMEDORES EMERGENTES'!$G$15 -> Bº LAS VIAS OESTE LOTE 42
B33: ='[1]COMEDORES EMERGENTES'!$B$16 -> SAN JOSE OBRERO | D33: 1 | E33: ='[1]COMEDORES EMERGENTES'!$G$16 -> Bº SAN JOSE OBRERO. PJE. SANDOVAL S/Nº
B34: ='[1]COMEDORES EMERGENTES'!$B$17 -> VIRGEN DE LUJAN | D34: 1 | E34: ='[1]COMEDORES EMERGENTES'!$G$17 -> Bº OJO DE AGUA C/DR.TEODULFO BARRIONUEVO S/Nº
B35: ='[1]COMEDORES EMERGENTES'!$B$18 -> RENACER | D35: 1 | E35: ='[1]COMEDORES EMERGENTES'!$G$18 -> Bº VIRGEN MORENITA
B36: ='[1]COMEDORES EMERGENTES'!$B$19 -> CENTRO VECINAL MI JARDIN | D36: 1 | E36: ='[1]COMEDORES EMERGENTES'!$G$19 -> C/ LOS TULIPANES ENTRE FLOR DE CEREZO Y HOLANDA MZA.27 Bº MI JARDIN
B37: ='[1]COMEDORES EMERGENTES'!$B$20 -> LA VIEJA ESQUINA | D37: 1 | E37: ='[1]COMEDORES EMERGENTES'!$G$20 -> B° CRISTO REY PJE CAPATAZ VILLAFAÑEZ Y ARMANDO CORREA
B38: ='[1]COMEDORES EMERGENTES'!$B$21 -> GAUCHITO GIL | D38: 1 | E38: ='[1]COMEDORES EMERGENTES'!$G$21 -> B° 26 VIVIENDAS CASA N° 3
B39: ='[1]COMEDORES EMERGENTES'!$B$22 -> LOS TOLDOS | D39: 1 | E39: ='[1]COMEDORES EMERGENTES'!$G$22 -> LOTEO PARQUE SUR CALLE S/NOMBRE S/N°
B40: Garantia
B41: S/E

Sheet limpieza
B2: Pedido de Necesidades Trimestrales
A4: JURISDICCION: | C4: 45- Ministerio de Desarrollo Social y Deporte.-
A5: SAF N°: | C5: 25- Direccion Provincial de Gestion Administracion y RRHH
A6: EJERCICIO: | C6: 2020
A7: TRIMESTRE: | C7: 3
A9: ID | B9: CODIGO ITEM | C9: RUBRO DE COMPRA | D9: I.P.P. | E9: DESCRIPCION | F9: UNIDAD DE MEDIDA | G9: CANTIDAD | H9: PRECIO UNITARIO ESTIMADO | I9: IMPORTE TOTAL ESTIMADO
A10: 1 | B10: 2.9.1-6951.30 | C10: ELEMENTOS DE LIMPIEZA | D10: 2.9.1 | E10: LIMPIADORES; TIPO: LAVANDINA, PRESENTACION: ENVASE X 5 L | F10: LITROS | G10: 240 | H10: 175 | I10: =+H10*G10 -> 42000
A11: 2 | B11: 2.9.1-6951.12 | C11: ELEMENTOS DE LIMPIEZA | D11: 2.9.1 | E11: LIMPIADORES; PRESENTACION: ENVASE X 5 L, TIPO: DETERGENTE | F11: LITROS | G11: 240 | H11: 225 | I11: =+H11*G11 -> 54000
A12: 3 | B12: 2.9.1-4784.51 | C12: ELEMENTOS DE LIMPIEZA | D12: 2.9.1 | E12: LIMPIADORES MULTIUSO; COMPUESTOS BIODEGRADABLES: SI, PRESENTACION: ENVASE X 5 L, TIPO: DESENGRASANTE | F12: LITROS | G12: 240 | H12: 320 | I12: =+H12*G12 -> 76800
B15: Especificidades Item N° 1:
B17: Descripción técnica
C18: PRESENTACION EN BIDONES PLASTICOS POR 5LTS.
B19: Plazos y lugares de entrega
B20: SEMANAL
B21: COMEDOR | D21: CANTIDAD | E21: DOMICILIO DE ENTREGA
B22: ='[1]COMEDORES EMERGENTES'!$B$3 -> UNA SONRISA AV. LOS COBACHO | D22: 1 | E22: ='[1]COMEDORES EMERGENTES'!$G$3 -> Bº SAN CARLOS OESTE AV. Bonifacio cobacho 670
B23: ='[1]COMEDORES EMERGENTES'!$B$4 -> C.I.F Nº1 - RIVERA DEL VALLE Y FLORIDA | D23: 1 | E23: ='[1]COMEDORES EMERGENTES'!$G$4 -> AV. RIVIERA DEL VALLE ENTRE FLORIDA Y SANTA FE
B24: ='[1]COMEDORES EMERGENTES'!$B$5 -> C.I.F - RIVERA DEL VALLE - DILORENZO | D24: 1 | E24: ='[1]COMEDORES EMERGENTES'!$G$5 -> Bº RIVERA DEL VALLE ENTRE VILLA EUMELIA Y MONTE CRISTO
B25: ='[1]COMEDORES EMERGENTES'!$B$6 -> ESFUERZO PROPIO- Bº ALTOS DE CHOYA | D25: 1 | E25: ='[1]COMEDORES EMERGENTES'!$G$6 -> Bº MUNICIPAL 35VV. NORTE C/14
B26: ='[1]COMEDORES EMERGENTES'!$B$7 -> ANGELITOS - LOTEO SUSSEX | D26: 1 | E26: ='[1]COMEDORES EMERGENTES'!$G$7 -> Bº LOTEO SUSEX MZA.Nº 4 LOTE Nº3
B27: ='[1]COMEDORES EMERGENTES'!$B$8 -> CLUB DEPORTIVO CHACARITA | D27: 1 | E27: ='[1]COMEDORES EMERGENTES'!$G$8 -> CALLE DR.DERMIDIO GALINDEZ C/2660
B28: ='[1]COMEDORES EMERGENTES'!$B$9 -> LA MORO | D28: 1 | E28: ='[1]COMEDORES EMERGENTES'!$G$9 -> MAIPU NORTE 1º ETAPA MZA "H" Bº MI JARDIN
B29: ='[1]COMEDORES EMERGENTES'!$B$10 -> PAPA FRANCISCO | D29: 1 | E29: ='[1]COMEDORES EMERGENTES'!$G$10 -> ENTRE AV.TEREBINTO Y AV.SAN JUAN LOTE "2" MZA. "B"
B30: ='[1]COMEDORES EMERGENTES'!$B$11 -> E.P.C - 100 V.V NORTE | D30: 1 | E30: ='[1]COMEDORES EMERGENTES'!$G$11 -> Bº VV NORTE C/48 ENTRE ESPAÑA Y FRANCIA
B31: ='[1]COMEDORES EMERGENTES'!$B$12 -> HOGAR DE CRISTO - PADRE RAUL CONTRERAS | D31: 1 | E31: ='[1]COMEDORES EMERGENTES'!$G$12 -> Bº SANTA MARTA MZA. "S" LOTE "M" C/39
B32: ='[1]COMEDORES EMERGENTES'!$B$13 -> LA LUCIERNAGA | D32: 1 | E32: ='[1]COMEDORES EMERGENTES'!$G$13 -> Bº 20 V.V NORTE C/3
B33: ='[1]COMEDORES EMERGENTES'!$B$14 -> VALLE VIEJO - SUMALAO | D33: 1 | E33: ='[1]COMEDORES EMERGENTES'!$G$14 -> PADRE SEGURA S/N
B34: ='[1]COMEDORES EMERGENTES'!$B$15 -> NUESTRO FUTURO - LAS VIAS | D34: 1 | E34: ='[1]COMEDORES EMERGENTES'!$G$15 -> Bº LAS VIAS OESTE LOTE 42
B35: ='[1]COMEDORES EMERGENTES'!$B$16 -> SAN JOSE OBRERO | D35: 1 | E35: ='[1]COMEDORES EMERGENTES'!$G$16 -> Bº SAN JOSE OBRERO. PJE. SANDOVAL S/Nº
B36: ='[1]COMEDORES EMERGENTES'!$B$17 -> VIRGEN DE LUJAN | D36: 1 | E36: ='[1]COMEDORES EMERGENTES'!$G$17 -> Bº OJO DE AGUA C/DR.TEODULFO BARRIONUEVO S/Nº
B37: ='[1]COMEDORES EMERGENTES'!$B$18 -> RENACER | D37: 1 | E37: ='[1]COMEDORES EMERGENTES'!$G$18 -> Bº VIRGEN MORENITA
B38: ='[1]COMEDORES EMERGENTES'!$B$19 -> CENTRO VECINAL MI JARDIN | D38: 1 | E38: ='[1]COMEDORES EMERGENTES'!$G$19 -> C/ LOS TULIPANES ENTRE FLOR DE CEREZO Y HOLANDA MZA.27 Bº MI JARDIN
B39: ='[1]COMEDORES EMERGENTES'!$B$20 -> LA VIEJA ESQUINA | D39: 1 | E39: ='[1]COMEDORES EMERGENTES'!$G$20 -> B° CRISTO REY PJE CAPATAZ VILLAFAÑEZ Y ARMANDO CORREA
B40: ='[1]COMEDORES EMERGENTES'!$B$21 -> GAUCHITO GIL | D40: 1 | E40: ='[1]COMEDORES EMERGENTES'!$G$21 -> B° 26 VIVIENDAS CASA N° 3
B41: ='[1]COMEDORES EMERGENTES'!$B$22 -> LOS TOLDOS | D41: 1 | E41: ='[1]COMEDORES EMERGENTES'!$G$22 -> LOTEO PARQUE SUR CALLE S/NOMBRE S/N°
B42: Calidad Minima esperada
C43: ALTA
B44: Mantenimiento
C45: 60 DIAS
B46: Garantia
...

Sheet alimento
B1: Pedido de Necesidades Trimestrales
A3: JURISDICCION: | C3: 45- Ministerio de Desarrollo Social y Deporte.-
A4: SAF N°: | C4: 25- Direccion Provincial de Gestion Administracion y RRHH
A5: EJERCICIO: | C5: 2020
A6: TRIMESTRE: | C6: 3
A8: ID | B8: CODIGO ITEM | C8: RUBRO DE COMPRA | D8: I.P.P. | E8: DESCRIPCION | F8: UNIDAD DE MEDIDA | G8: CANTIDAD | H8: PRECIO UNITARIO ESTIMADO | I8: IMPORTE TOTAL ESTIMADO
A9: 1 | B9: 2.1.1-482.69 | C9: ALIMENTOS | D9: =LEFT(B9,5) -> 2.1.1 | E9: HARINAS; TIPO: MAIZ, PRESENTACION: ENVASE X 1 Kg, MATERIAL ENVASE: PAPEL, CERTICADO FORESTAL (GFS): SIN, ELEM. TRANSPORTE: SIN, MATERIAL ELEM. TRANSPORTE: SIN, LIBRE DE GLUTEN: NO | F9: UNIDAD | G9: 7164
A10: 2 | B10: 2.1.1-435.60 | C10: ALIMENTOS | D10: 2.1.1 | E10: ARROZ; TIPO GRANO: LARGO-FINO, TIPO: BLANCO, PROCESO: SIN CASCARA, PRESENTACION: BOLSA X 1 Kg, MATERIAL ENVASE: PLASTICO, CERTIFICADO FORESTAL (GFS): SIN, ELEM. TRANSPORTE: SIN, MATERIAL ELEM. TRANSPORTE: SIN, LIBRE DE GLUTEN: SI | F10: UNIDAD | G10: 5232
A11: 3 | B11: 2.1.1-6547.22 | C11: ALIMENTOS | D11: 2.1.1 | E11: LEGUMBRES; VARIEDAD: LENTEJA, ESTADO: NATURAL, PRESENTACION: BOLSA PLASTICA, PESO: 500 GR | F11: UNIDAD | G11: 9504
A12: 4 | B12: 2.1.1-2616.9 | C12: ALIMENTOS | D12: =LEFT(B12,5) -> 2.1.1 | E12: MAIZ; TIPO: BLANCO PISADO, PRESENTACION: ENVASE X 500 GR, FORMA DE PRESENTACION: SIN VALOR | F12: UNIDAD | G12: 9504
A13: 5 | B13: 2.1.1-6547.56 | C13: ALIMENTOS | D13: 2.1.1 | E13: LEGUMBRES; VARIEDAD: POROTO BLANCO OVAL, ESTADO: SECO, PRESENTACION: BOLSA, PESO: 500 GR | F13: UNIDAD | G13: 4284
A14: 6 | B14: 2.1.1-6546.4 | C14: ALIMENTOS | D14: 2.1.1 | E14: VERDURAS Y HORTALIZAS; VARIEDAD: TOMATE PERITA, ESTADO: TRITURADO, PRESENTACION: BOTELLA, PESO: 950 GR | F14: UNIDAD | G14: 12828
A15: 7 | B15: 2.1.1-6547.17 | C15: ALIMENTOS | D15: =LEFT(B15,5) -> 2.1.1 | E15: LEGUMBRES; VARIEDAD: ARVEJA, ESTADO: REMOJADO EN CONSERVA, PRESENTACION: LATA, PESO: 350 GR | F15: UNIDAD | G15: 8544
A16: 8 | B16: 2.1.1-439.67 | C16: ALIMENTOS | D16: 2.1.1 | E16: ACEITES COMESTIBLES; TIPO: GIRASOL, PRESENTACION: ENVASE X 900 CM3, MATERIAL ENVASE: PLASTICO 1 (PET), ELEM. TRANSPORTE: SIN, MATERIAL ELEM. TRANSPORTE : SIN, LIBRE DE GLUTEN: NO | F16: UNIDAD | G16: 2412
A17: 9 | B17: 2.1.1-6546.46 | C17: ALIMENTOS | D17: =LEFT(B17,5) -> 2.1.1 | E17: VERDURAS Y HORTALIZAS; VARIEDAD: CEBOLLA, ESTADO: NATURAL, PRESENTACION: GRANEL, PESO: SIN VALOR | F17: KG | G17: 13296
A18: 10 | B18: 2.1.1-6546.100 | C18: ALIMENTOS | D18: =LEFT(B18,5) -> 2.1.1 | E18: VERDURAS Y HORTALIZAS; ESTADO: NATURAL, PRESENTACION: GRANEL, VARIEDAD: PAPA BLANCA, PESO: SIN VALOR | F18: KG | G18: 16668
A19: 11 | B19: 2.1.1-6546.403 | C19: ALIMENTOS | D19: =LEFT(B19,5) -> 2.1.1 | E19: VERDURAS Y HORTALIZAS; VARIEDAD: ZANAHORIA, ESTADO: NATURAL, PRESENTACION: BOLSA, PESO: NO CORRESPONDE, ELEM. TRANSPORTE: SIN, MATERIAL ELEM. TRANSPORTE: SIN, LIBRE DE GLUTEN: SI, ORGANICO: NO | F19: KG | G19: 10464
A20: 12 | B20: 2.1.1-6546.95 | C20: ALIMENTOS | D20: 2.1.1 | E20: VERDURAS Y HORTALIZAS; VARIEDAD: MORRON VERDE, ESTADO: NATURAL, PRESENTACION: GRANEL, PESO: SIN VALOR | F20: UNIDAD | G20: 14256
A21: 13 | B21: 2.1.1-6546.401 | C21: ALIMENTOS | D21: =LEFT(B21,5) -> 2.1.1 | E21: VERDURAS Y HORTALIZAS; VARIEDAD: AJO, ESTADO: NATURAL, PRESENTACION: UNIDAD, PESO: NO CORRESPONDE, ELEM. TRANSPORTE: SIN, MATERIAL ELEM. TRANSPORTE: SIN, LIBRE DE GLUTEN: SI, ORGANICO: NO | F21: UNIDAD | G21: 1440
A22: 14 | B22: 2.1.1-6546.148 | C22: ALIMENTOS | D22: =LEFT(B22,5) -> 2.1.1 | E22: VERDURAS Y HORTALIZAS; VARIEDAD: ZAPALLITO LARGO, ESTADO: NATURAL, PRESENTACION: CAJON, PESO: SIN VALOR | F22: KG | G22: 4752
A23: 15 | B23: 2.1.1-6546.47 | C23: ALIMENTOS | D23: 2.1.1 | E23: VERDURAS Y HORTALIZAS; VARIEDAD: CEBOLLA DE VERDEO, ESTADO: NATURAL, PRESENTACION: GRANEL, PESO: SIN VALOR | F23: UNIDAD | G23: 2856
A24: 16 | B24: 2.1.1-6546.162 | C24: ALIMENTOS | D24: =LEFT(B24,5) -> 2.1.1 | E24: VERDURAS Y HORTALIZAS; VARIEDAD: ZAPALLO CRIOLLO, ESTADO: NATURAL, PRESENTACION: UNIDAD, PESO: SIN VALOR | F24: KG | G24: 9504
A25: 17 | B25: 2.1.1-541.7 | C25: ALIMENTOS | D25: =LEFT(B25,5) -> 2.1.1 | E25: CARNES; ESPECIE: VACUNA, CORTE: PICADA ESPECIAL, TIPO: VACUNA | F25: KG | G25: 4752
A26: 18 | B26: 2.1.1-541.49 | C26: ALIMENTOS | D26: =LEFT(B26,5) -> 2.1.1 | E26: CARNES; ESPECIE: VACUNA, CORTE: NALGA, TIPO: VACUNA | F26: KG | G26: 8544
A27: 19 | B27: 2.1.1-621.3 | C27: ALIMENTOS | D27: =LEFT(B27,5) -> 2.1.1 | E27: AVES; PRESENTACION: TROZADO SIN PIEL, ESPECIE: POLLO, EVISCERADO: SIN VALOR, TIPO: POLLO | F27: KG | G27: 7164
A28: 20 | B28: 2.1.1-669.32 | C28: ALIMENTOS | D28: 2.1.1 | E28: PANES; PRESENTACION: UNIDAD, TIPO: BAGUETTE | F28: KG | G28: 19008
A29: 21 | B29: 2.1.1-489.132 | C29: ALIMENTOS | D29: 2.1.1 | E29: ESPECIAS; TIPO: PIMIENTA BLANCA, PRESENTACION: ENVASE X 1 Kg | F29: KG | G29: 120
A30: 22 | B30: 2.1.1-489.66 | C30: ALIMENTOS | D30: =LEFT(B30,5) -> 2.1.1 | E30: ESPECIAS; TIPO: OREGANO, PRESENTACION: BOLSA DE 1 Kg | F30: KG | G30: 120
A31: 23 | B31: 2.1.1-489.67 | C31: ALIMENTOS | D31: 2.1.1 | E31: ESPECIAS; TIPO: PIMENTON, PRESENTACION: BOLSA DE 1 Kg | F31: KG | G31: 120
A32: 24 | B32: 2.1.1-489.109 | C32: ALIMENTOS | D32: 2.1.1 | E32: ESPECIAS; TIPO: PROVENZAL, PRESENTACION: PAQUETE X 1 Kg | F32: KG | G32: 120
A33: 25 | B33: 2.1.1-514.2 | C33: ALIMENTOS | D33: =LEFT(B33,5) -> 2.1.1 | E33: SAL DE MESA; CONSISTENCIA: FINA, PESO: 500 GR, TIPO: SIN VALOR, ENVASE: PAQUETE | F33: UNIDAD | G33: 492
A34: 26 | B34: 2.1.1-514.15 | C34: ALIMENTOS | D34: =LEFT(B34,5) -> 2.1.1 | E34: SAL DE MESA; CONSISTENCIA: GRUESA, ENVASE: BOLSA, PESO: 1 Kg, TIPO: SIN VALOR | F34: KG | G34: 270
A35: 27 | B35: 2.1.1-6539.8 | C35: ALIMENTOS | D35: 2.1.1 | E35: FRUTAS; VARIEDAD: NARANJA ESPECIAL, ESTADO: NATURAL, PRESENTACION: CAJON, PESO: SIN VALOR | F35: UNIDAD | G35: 23760
A36: 28 | B36: 2.1.1-6539.19 | C36: ALIMENTOS | D36: 2.1.1 | E36: FRUTAS; ESTADO: NATURAL, VARIEDAD: MANZANA RED ELEGIDA, PRESENTACION: CAJON, PESO: SIN VALOR | F36: UNIDAD | G36: 23760
A37: 29 | B37: 2.1.1-6539.30 | C37: ALIMENTOS | D37: =LEFT(B37,5) -> 2.1.1 | E37: FRUTAS; VARIEDAD: BANANA, PRESENTACION: CAJON, ESTADO: NATURAL, PESO: SIN VALOR | F37: UNIDAD | G37: 23760
A38: 30 | B38: 2.1.1-6539.32 | C38: ALIMENTOS | D38: =LEFT(B38,5) -> 2.1.1 | E38: FRUTAS; VARIEDAD: PERA AMARILLA, ESTADO: NATURAL, PRESENTACION: CAJON, PESO: SIN VALOR | F38: UNIDAD | G38: 23760
B41: Especificidades Item N° 1:
B43: Descripción técnica
B45: Plazos y lugares de entrega
B46: SEMANAL
...

Sheet  NotaPedido
A1: NOTA DE PEDIDO | J1: N° | K1: 686/2021
A3: JURISDICCIÓN: | D3: =alimento!C3 -> 45- Ministerio de Desarrollo Social y Deporte.-
A4: SAF: | D4: =alimento!C4 -> 25- Direccion Provincial de Gestion Administracion y RRHH
A5: UNIDAD EJECUTORA: | D5: 20- Promocion Socio Alimentaria- PPG- MDSD
A6: DEPENDENCIA SOLICITANTE: | D6: 01- Actividad Central
A7: PERIODO UTILIZACIÓN: | D7: ='ALIM-IMP'!C6& "° Trimestre - Año " & 'ALIM-IMP'!C5 -> 3° Trimestre - Año 2021
A8: OBJETO: | D8: Adquisición de Alimentos para asistir a Personas de escasos Recursos a traves de los Comedores Emergentes por un Periodo de 3 meses
A10: Ítem | B10: Codigo Item | C10: DESCRIPCIÓN | H10: Adjunta Detalle Técnico | I10: Unidad Medida | J10: Precio Unitario Estimado | K10: Cantidad Solicitada | L10: Importe Estimado
A12: 1 | B12: ='ALIM-IMP'!B9 -> 2.1.1-2868.55 | C12: ='ALIM-IMP'!E9 -> FIDEOS SECOS; VARIEDAD: TALLARIN, RELLENO: SIN, PRESENTACION: ENVASE X 500 GR, MATERIAL ENVASE: PLASTICO 1 (PET), ELEM. TRANSPORTE: SIN, MATERIAL ELEM. TRANSPORTE: SIN, CERTIFICADO FORESTAL (GFS): SIN, LIBRE DE GLUTEN: NO | H12: SI | I12: ='ALIM-IMP'!F9 -> PAQUETE | J12: ='ALIM-IMP'!H9 -> 53 | K12: ='ALIM-IMP'!G9 -> 15876 | L12: =J12*K12 -> 841428
A13: 2 | B13: ='ALIM-IMP'!B10 -> 2.1.1-435.60 | C13: ='ALIM-IMP'!E10 -> ARROZ; TIPO GRANO: LARGO-FINO, TIPO: BLANCO, PROCESO: SIN CASCARA, PRESENTACION: BOLSA X 1 Kg, MATERIAL ENVASE: PLASTICO, CERTIFICADO FORESTAL (GFS): SIN, ELEM. TRANSPORTE: SIN, MATERIAL ELEM. TRANSPORTE: SIN, LIBRE DE GLUTEN: SI | H13: SI | I13: ='ALIM-IMP'!F10 -> BOLSA | J13: ='ALIM-IMP'!H10 -> 146 | K13: ='ALIM-IMP'!G10 -> 2628 | L13: =J13*K13 -> 383688
A14: 3 | B14: ='ALIM-IMP'!B11 -> 2.1.1-6547.55 | C14: ='ALIM-IMP'!E11 -> LEGUMBRES; VARIEDAD: POROTO SECO, ESTADO: SECA Y CONSERVADA, PRESENTACION: BOLSA PLASTICA, PESO: 1 Kg | H14: SI | I14: BOLSA | J14: ='ALIM-IMP'!H11 -> 486 | K14: ='ALIM-IMP'!G11 -> 3324 | L14: =J14*K14 -> 1615464
A15: 4 | B15: ='ALIM-IMP'!B12 -> 2.1.1-483.33 | C15: ='ALIM-IMP'!E12 -> HUEVO DE GALLINA; TAMAÑO: MEDIANOS, COLOR: BLANCOS, PRESENTACION: 30 | H15: SI | I15: ='ALIM-IMP'!F12 -> MAPLE | J15: ='ALIM-IMP'!H12 -> 475 | K15: ='ALIM-IMP'!G12 -> 1284 | L15: =J15*K15 -> 609900
A16: 5 | B16: ='ALIM-IMP'!B13 -> 2.1.1-6546.330 | C16: ='ALIM-IMP'!E13 -> VERDURAS Y HORTALIZAS; VARIEDAD: ZAPALLO ANCO, ESTADO: NATURAL, PRESENTACION: UNIDAD, PESO: 1 Kg | H16: SI | I16: ='ALIM-IMP'!F13 -> KG | J16: ='ALIM-IMP'!H13 -> 50 | K16: ='ALIM-IMP'!G13 -> 12576 | L16: =J16*K16 -> 628800
A17: 6 | B17: ='ALIM-IMP'!B14 -> 2.1.1-6546.4 | C17: ='ALIM-IMP'!E14 -> VERDURAS Y HORTALIZAS; VARIEDAD: TOMATE PERITA, ESTADO: TRITURADO, PRESENTACION: BOTELLA, PESO: 950 GR | H17: SI | I17: ='ALIM-IMP'!F14 -> BOTELLA | J17: ='ALIM-IMP'!H14 -> 180 | K17: ='ALIM-IMP'!G14 -> 13200 | L17: =J17*K17 -> 2376000
A18: 7 | B18: ='ALIM-IMP'!B15 -> 2.1.1-6547.17 | C18: ='ALIM-IMP'!E15 -> LEGUMBRES; VARIEDAD: ARVEJA, ESTADO: REMOJADO EN CONSERVA, PRESENTACION: LATA, PESO: 350 GR | H18: SI | I18: ='ALIM-IMP'!F15 -> LATA | J18: ='ALIM-IMP'!H15 -> 56 | K18: ='ALIM-IMP'!G15 -> 9924 | L18: =J18*K18 -> 555744
A19: 8 | B19: ='ALIM-IMP'!B16 -> 2.1.1-439.67 | C19: ='ALIM-IMP'!E16 -> ACEITES COMESTIBLES; TIPO: GIRASOL, PRESENTACION: ENVASE X 900 CM3, MATERIAL ENVASE: PLASTICO 1 (PET), ELEM. TRANSPORTE: SIN, MATERIAL ELEM. TRANSPORTE : SIN, LIBRE DE GLUTEN: NO | H19: SI | I19: ='ALIM-IMP'!F16 -> BOTELLA | J19: ='ALIM-IMP'!H16 -> 241 | K19: ='ALIM-IMP'!G16 -> 4680 | L19: =J19*K19 -> 1127880
A20: 9 | B20: ='ALIM-IMP'!B17 -> 2.1.1-6546.46 | C20: ='ALIM-IMP'!E17 -> VERDURAS Y HORTALIZAS; VARIEDAD: CEBOLLA, ESTADO: NATURAL, PRESENTACION: GRANEL, PESO: SIN VALOR | H20: SI | I20: ='ALIM-IMP'!F17 -> KG | J20: ='ALIM-IMP'!H17 -> 180 | K20: ='ALIM-IMP'!G17 -> 17868 | L20: =J20*K20 -> 3216240
A21: 10 | B21: ='ALIM-IMP'!B18 -> 2.1.1-6546.100 | C21: ='ALIM-IMP'!E18 -> VERDURAS Y HORTALIZAS; ESTADO: NATURAL, PRESENTACION: GRANEL, VARIEDAD: PAPA BLANCA, PESO: SIN VALOR | H21: SI | I21: ='ALIM-IMP'!F18 -> KG | J21: ='ALIM-IMP'!H18 -> 60 | K21: ='ALIM-IMP'!G18 -> 46188 | L21: =J21*K21 -> 2771280
A22: 11 | B22: ='ALIM-IMP'!B19 -> 2.1.1-6546.403 | C22: ='ALIM-IMP'!E19 -> VERDURAS Y HORTALIZAS; VARIEDAD: ZANAHORIA, ESTADO: NATURAL, PRESENTACION: BOLSA, PESO: NO CORRESPONDE, ELEM. TRANSPORTE: SIN, MATERIAL ELEM. TRANSPORTE: SIN, LIBRE DE GLUTEN: SI, ORGANICO: NO | H22: SI | I22: ='ALIM-IMP'!F19 -> BOLSA | J22: ='ALIM-IMP'!H19 -> 50 | K22: ='ALIM-IMP'!G19 -> 8616 | L22: =J22*K22 -> 430800
A23: 12 | B23: ='ALIM-IMP'!B20 -> 2.1.1-6546.95 | C23: ='ALIM-IMP'!E20 -> VERDURAS Y HORTALIZAS; VARIEDAD: MORRON VERDE, ESTADO: NATURAL, PRESENTACION: GRANEL, PESO: SIN VALOR | H23: SI | I23: ='ALIM-IMP'!F20 -> UNIDAD | J23: ='ALIM-IMP'!H20 -> 28 | K23: ='ALIM-IMP'!G20 -> 19788 | L23: =J23*K23 -> 554064
A24: 13 | B24: ='ALIM-IMP'!B21 -> 2.1.1-6546.401 | C24: ='ALIM-IMP'!E21 -> VERDURAS Y HORTALIZAS; VARIEDAD: AJO, ESTADO: NATURAL, PRESENTACION: UNIDAD, PESO: NO CORRESPONDE, ELEM. TRANSPORTE: SIN, MATERIAL ELEM. TRANSPORTE: SIN, LIBRE DE GLUTEN: SI, ORGANICO: NO | H24: SI | I24: ='ALIM-IMP'!F21 -> CABEZA | J24: ='ALIM-IMP'!H21 -> 50 | K24: ='ALIM-IMP'!G21 -> 4680 | L24: =J24*K24 -> 234000
A25: 14 | B25: ='ALIM-IMP'!B22 -> 2.1.1-6546.47 | C25: ='ALIM-IMP'!E22 -> VERDURAS Y HORTALIZAS; VARIEDAD: CEBOLLA DE VERDEO, ESTADO: NATURAL, PRESENTACION: GRANEL, PESO: SIN VALOR | H25: SI | I25: ='ALIM-IMP'!F22 -> ATADO | J25: ='ALIM-IMP'!H22 -> 30 | K25: ='ALIM-IMP'!G22 -> 6600 | L25: =J25*K25 -> 198000
A26: 15 | B26: ='ALIM-IMP'!B23 -> 2.1.1-6546.188 | C26: ='ALIM-IMP'!E23 -> VERDURAS Y HORTALIZAS; ESTADO: NATURAL, PRESENTACION: GRANEL, PESO: SIN VALOR, VARIEDAD: ZAPALLO CRIOLLO | H26: SI | I26: ='ALIM-IMP'!F23 -> KG | J26: ='ALIM-IMP'!H23 -> 70 | K26: ='ALIM-IMP'!G23 -> 25776 | L26: =J26*K26 -> 1804320
... A45: 34 | B45: ='ALIM-IMP'!B42 -> 2.1.1-6546.132 | C45: ='ALIM-IMP'!E42 -> VERDURAS Y HORTALIZAS; VARIEDAD: PEREJIL, ESTADO: NATURAL, PRESENTACION: GRANEL, PESO: SIN VALOR | H45: SI | I45: ='ALIM-IMP'!F42 -> ATADO | J45: ='ALIM-IMP'!H42 -> 20 | K45: ='ALIM-IMP'!G42 -> 2628 | L45: =J45*K45 -> 52560
A46: Costo total estimado: CINCUENTA Y TRES MILLONES QUINIENTOS SETENTA Y CINCO MIL SEISCIENTOS CUARENTA Y CUATRO CON 00/100 | J46: =SUM(L12:L45) -> 53575644

Sheet ALIM-IMP
B1: Pedido de Necesidades Trimestrales
A3: JURISDICCION: | C3: 45- Ministerio de Desarrollo Social y Deporte.-
A4: SAF N°: | C4: 25- Direccion Provincial de Gestion Administracion y RRHH
A5: EJERCICIO: | C5: 2021
A6: TRIMESTRE | C6: 3
A8: ID | B8: CODIGO ITEM | C8: RUBRO DE COMPRA | D8: I.P.P. | E8: DESCRIPCION | F8: UNIDAD DE MEDIDA | G8: CANTIDAD | H8: PRECIO UNITARIO ESTIMADO | I8: IMPORTE TOTAL ESTIMADO
A9: 1 | B9: 2.1.1-2868.55 | C9: ALIMENTOS | D9: 2.1.1 | E9: FIDEOS SECOS; VARIEDAD: TALLARIN, RELLENO: SIN, PRESENTACION: ENVASE X 500 GR, MATERIAL ENVASE: PLASTICO 1 (PET), ELEM. TRANSPORTE: SIN, MATERIAL ELEM. TRANSPORTE: SIN, CERTIFICADO FORESTAL (GFS): SIN, LIBRE DE GLUTEN: NO | F9: PAQUETE | G9: 15876 | H9: 53 | I9: =+H9*G9 -> 841428
A10: 2 | B10: 2.1.1-435.60 | C10: ALIMENTOS | D10: 2.1.1 | E10: ARROZ; TIPO GRANO: LARGO-FINO, TIPO: BLANCO, PROCESO: SIN CASCARA, PRESENTACION: BOLSA X 1 Kg, MATERIAL ENVASE: PLASTICO, CERTIFICADO FORESTAL (GFS): SIN, ELEM. TRANSPORTE: SIN, MATERIAL ELEM. TRANSPORTE: SIN, LIBRE DE GLUTEN: SI | F10: BOLSA | G10: 2628 | H10: 146 | I10: =+H10*G10 -> 383688
A11: 3 | B11: 2.1.1-6547.55 | C11: ALIMENTOS | D11: 2.1.1 | E11: LEGUMBRES; VARIEDAD: POROTO SECO, ESTADO: SECA Y CONSERVADA, PRESENTACION: BOLSA PLASTICA, PESO: 1 Kg | F11: BOLSA | G11: 3324 | H11: 486 | I11: =+H11*G11 -> 1615464
A12: 4 | B12: 2.1.1-483.33 | C12: ALIMENTOS | D12: 2.1.1 | E12: HUEVO DE GALLINA; TAMAÑO: MEDIANOS, COLOR: BLANCOS, PRESENTACION: 30 | F12: MAPLE | G12: 1284 | H12: 475 | I12: =+H12*G12 -> 609900
A13: 5 | B13: 2.1.1-6546.330 | C13: ALIMENTOS | D13: 2.1.1 | E13: VERDURAS Y HORTALIZAS; VARIEDAD: ZAPALLO ANCO, ESTADO: NATURAL, PRESENTACION: UNIDAD, PESO: 1 Kg | F13: KG | G13: 12576 | H13: 50 | I13: =+H13*G13 -> 628800
A14: 6 | B14: 2.1.1-6546.4 | C14: ALIMENTOS | D14: 2.1.1 | E14: VERDURAS Y HORTALIZAS; VARIEDAD: TOMATE PERITA, ESTADO: TRITURADO, PRESENTACION: BOTELLA, PESO: 950 GR | F14: BOTELLA | G14: 13200 | H14: 180 | I14: =+H14*G14 -> 2376000
A15: 7 | B15: 2.1.1-6547.17 | C15: ALIMENTOS | D15: 2.1.1 | E15: LEGUMBRES; VARIEDAD: ARVEJA, ESTADO: REMOJADO EN CONSERVA, PRESENTACION: LATA, PESO: 350 GR | F15: LATA | G15: 9924 | H15: 56 | I15: =+H15*G15 -> 555744
A16: 8 | B16: 2.1.1-439.67 | C16: ALIMENTOS | D16: 2.1.1 | E16: ACEITES COMESTIBLES; TIPO: GIRASOL, PRESENTACION: ENVASE X 900 CM3, MATERIAL ENVASE: PLASTICO 1 (PET), ELEM. TRANSPORTE: SIN, MATERIAL ELEM. TRANSPORTE : SIN, LIBRE DE GLUTEN: NO | F16: BOTELLA | G16: 4680 | H16: 241 | I16: =+H16*G16 -> 1127880
A17: 9 | B17: 2.1.1-6546.46 | C17: ALIMENTOS | D17: 2.1.1 | E17: VERDURAS Y HORTALIZAS; VARIEDAD: CEBOLLA, ESTADO: NATURAL, PRESENTACION: GRANEL, PESO: SIN VALOR | F17: KG | G17: 17868 | H17: 180 | I17: =+H17*G17 -> 3216240
A18: 10 | B18: 2.1.1-6546.100 | C18: ALIMENTOS | D18: 2.1.1 | E18: VERDURAS Y HORTALIZAS; ESTADO: NATURAL, PRESENTACION: GRANEL, VARIEDAD: PAPA BLANCA, PESO: SIN VALOR | F18: KG | G18: 46188 | H18: 60 | I18: =+H18*G18 -> 2771280
A19: 11 | B19: 2.1.1-6546.403 | C19: ALIMENTOS | D19: 2.1.1 | E19: VERDURAS Y HORTALIZAS; VARIEDAD: ZANAHORIA, ESTADO: NATURAL, PRESENTACION: BOLSA, PESO: NO CORRESPONDE, ELEM. TRANSPORTE: SIN, MATERIAL ELEM. TRANSPORTE: SIN, LIBRE DE GLUTEN: SI, ORGANICO: NO | F19: BOLSA | G19: 8616 | H19: 50 | I19: =+H19*G19 -> 430800
A20: 12 | B20: 2.1.1-6546.95 | C20: ALIMENTOS | D20: 2.1.1 | E20: VERDURAS Y HORTALIZAS; VARIEDAD: MORRON VERDE, ESTADO: NATURAL, PRESENTACION: GRANEL, PESO: SIN VALOR | F20: UNIDAD | G20: 19788 | H20: 28 | I20: =+H20*G20 -> 554064
... A42: 34 | B42: 2.1.1-6546.132 | C42: ALIMENTOS | D42: 2.1.1 | E42: VERDURAS Y HORTALIZAS; VARIEDAD: PEREJIL, ESTADO: NATURAL, PRESENTACION: GRANEL, PESO: SIN VALOR | F42: ATADO | G42: 2628 | H42: 20 | I42: =+H42*G42 -> 52560
B45: Especificidades Item N° 1:
B47: Descripción técnica
C48: FIDEO TIPO TALLARIN. PRESENTACION: PAQUETE X 500 GRAMOS
B49: Plazos y lugares de entrega
B50: SEMANAL
B51: COMEDOR | D51: CANTIDAD | E51: DOMICILIO DE ENTREGA
B52: UNA SONRISA | D52: 45 | E52: Bº SAN CARLOS OESTE AV. BONIFACIO COBACHO N° 670
B53: C.I.F Nº1 | D53: 102 | E53: AV. RIVIERA DEL VALLE ENTRE FLORIDA Y SANTA FE
B54: C.I.F - RIVERA DEL VALLE | D54: 102 | E54: Bº RIVERA DEL VALLE ENTRE VILLA EUMELIA Y MONTE CRISTO
B55: ESFUERZO PROPIO | D55: 61 | E55: Bº MUNICIPAL 35VV. NORTE C/14
B56: JIREH LOTEO SUSSEX | D56: 51 | E56: B° LA RIVERA CASA N° 28
B57: CLUB DEPORTIVO CHACARITA | D57: 45 | E57: CALLE DR.DERMIDIO GALINDEZ C/2660
B58: LA MORO | D58: 57 | E58: MAIPU NORTE 1º ETAPA MZA "H" Bº MI JARDIN
B59: PAPA FRANCISCO | D59: 57 | E59: ENTRE AV.TEREBINTO Y AV.SAN JUAN LOTE "2" MZA. "B"
B60: E.P.C - 100 V.V NORTE | D60: 122 | E60: Bº VV NORTE C/48 ENTRE ESPAÑA Y FRANCIA
B61: HOGAR DE CRISTO | D61: 81 | E61: Bº SANTA MARTA MZA. "S" LOTE "M" C/39
B62: LA LUCIERNAGA | D62: 41 | E62: Bº 20 V.V NORTE C/3
B63: VALLE VIEJO - SUMALAO | D63: 81 | E63: PADRE SEGURA S/N
... B71: CORAZONES FELICES | D71: 51 | E71: LOTEO PARQUE SUR MZ 1 LOTE N° 21
B72: *SE REALIZA LA ENTREGA DE 1.323 UNIDADES POR SEMANA ( DISTRIBUIDOS SEGÚN DETALLE PARA CADA COMEDOR) LO QUE HACE UNA SUMA DE 5.292 UNIDADES MENSUALES QUE REPRESENTAN UN TOTAL DE 15.876 UNIDADES TRIMESTRALES
B73: Calidad Minima esperada
...

Sheet Autor Gastar
A1: EJERCICIO: | D1: ='ALIM-IMP'!C5 -> 2021 | P1: AUTORIZACION PARA GASTAR
A4: JURISDICCIÓN: | G4: =' NotaPedido'!D3 -> 45- Ministerio de Desarrollo Social y Deporte.-
A5: SAF: | G5: =' NotaPedido'!D4 -> 25- Direccion Provincial de Gestion Administracion y RRHH
A6: UNIDAD EJECUTORA: | G6: 20- Promocion Socio Alimentaria PPG- MDSD
A7: DEPENDENCIA SOLICITANTE: | G7: 01- Actividad Central
A8: AUTORIZACIÓN:
A9: Señor Jefe de Servicio Administrativo Financiero:
A10: ="Autorizo la realización de los trámites correspondientes, a fin de proveer a este Organismo los bienes y/o servicios que se detallan en Nota de Pedido N° " & ' NotaPedido'!K1&", afectando la erogación resultante a los créditos presupuestarios aprobados a favor de esta Unidad Ejecutora, conforme al siguiente detalle:" -> Autorizo la realización de los trámites correspondientes, a fin de proveer a este Organismo los bienes y/o servicios que se detallan en Nota de Pedido N° 686/2021, afectando la erogación resultante a los créditos presupuestarios aprobados a favor de esta Unidad Ejecutora, conforme al siguiente detalle:
A12: IMPUTACIÓN PRESUPUESTARIA
A13: CÓDIGO | O13: DENOMINACIÓN DE LA PARTIDA PRESUPUESTARIA | Q13: IMPORTE
A14: PR | B14: SB | C14: PY | D14: AC | E14: OB | F14: UG | G14: FIN | H14: FUN | I14: I | J14: P | K14: P | L14: SubP | M14: M | N14: FF
A15: 20 | D15: 1 | F15: 4901 | G15: 3 | H15: 2 | I15: =LEFT('[2]Necesidades Trimestrales'!D10,1) -> 2 | J15: 1 | K15: 1 | M15: 1 | N15: 1.1 | O15: Alimentos para Personas | Q15: =SUM('ALIM-IMP'!I9:I42) -> 53575644
A20: TOTAL DE PESOS: CINCUENTA Y TRES MILLONES QUINIENTOS SETENTA Y CINCO MIL SEISCIENTOS CUARENTA Y CUATRO CON 00/100.- | Q20: =SUM(Q15:Q19) -> 53575644
A22: JUSTIFICACIÓN:
A23: Adquisición de Alimentos para asistir a Personas de escasos Recursos a traves de los Comedores Emergentes por un Periodo de3 meses.-

Sheet  NotaPedido (2)
A1: NOTA DE PEDIDO | J1: N° | K1: 000/2021
A3: JURISDICCIÓN: | D3: =alimento!C3 -> 45- Ministerio de Desarrollo Social y Deporte.-
A4: SAF: | D4: =alimento!C4 -> 25- Direccion Provincial de Gestion Administracion y RRHH
A5: UNIDAD EJECUTORA: | D5: 01- Ministerio de Desarrollo Social y Deporte
A6: DEPENDENCIA SOLICITANTE: | D6: 01- Actividad Central
A7: PERIODO UTILIZACIÓN: | D7: ='ALIM-IMP'!C6& "° Trimestre - Año " & 'ALIM-IMP'!C5 -> 3° Trimestre - Año 2021
A8: OBJETO: | D8: Adquisición de Alimentos para asistir a Personas de escasos Recursos atravez de los Comedores Emergentes.-
A10: Ítem | B10: Codigo Item | C10: DESCRIPCIÓN | H10: Adjunta Detalle Técnico | I10: Unidad Medida | J10: Precio Unitario Estimado | K10: Cantidad Solicitada | L10: Importe Estimado
A12: 1 | B12: ='GAS-IMP'!B10 -> 2.5.6-798.8 | C12: ='GAS-IMP'!E10 -> GAS EN GARRAFA; CAPACIDAD: 10 Kg | H12: SI | I12: ='GAS-IMP'!F10 -> UNIDAD | J12: ='GAS-IMP'!H10 -> 800 | K12: ='GAS-IMP'!G10 -> 816 | L12: =J12*K12 -> 652800
A13: 2 | B13: ='GAS-IMP'!B11 -> 2.5.6-798.7 | C13: ='GAS-IMP'!E11 -> GAS EN GARRAFA; CAPACIDAD: 45 Kg | H13: SI | I13: ='GAS-IMP'!F11 -> UNIDAD | J13: ='GAS-IMP'!H11 -> 8200 | K13: ='GAS-IMP'!G11 -> 27 | L13: =J13*K13 -> 221400
A14: Costo total estimado: TOTAL DE PESOS: OCHOCIENTOS SETENTA Y CUATRO MIL DOSCIENTOS CON 00/100.- | J14: =SUM(L12:L13) -> 874200

Sheet GAS-IMP
B2: Pedido de Necesidades Trimestrales
A4: JURISDICCION: | C4: 45- Ministerio de Desarrollo Social y Deporte.-
A5: SAF N°: | C5: 25- Direccion Provincial de Gestion Administracion y RRHH
A6: EJERCICIO: | C6: 2021
A7: TRIMESTRE: | C7: 3
A9: ID | B9: CODIGO ITEM | C9: RUBRO DE COMPRA | D9: I.P.P. | E9: DESCRIPCION | F9: UNIDAD DE MEDIDA | G9: CANTIDAD | H9: PRECIO UNITARIO ESTIMADO | I9: IMPORTE TOTAL ESTIMADO
A10: 1 | B10: 2.5.6-798.8 | C10: COMBUSTIBLES Y LUBRICANTES | D10: 2.5.6 | E10: GAS EN GARRAFA; CAPACIDAD: 10 Kg | F10: UNIDAD | G10: 816 | H10: 800 | I10: =G10*H10 -> 652800
A11: 2 | B11: 2.5.6-798.7 | C11: COMBUSTIBLES Y LUBRICANTES | D11: 2.5.6 | E11: GAS EN GARRAFA; CAPACIDAD: 45 Kg | F11: UNIDAD | G11: 27 | H11: 8200 | I11: =G11*H11 -> 221400
I12: =SUM(I10:I11) -> 874200
B13: Especificidades Item N° 1:
B15: Descripción técnica
B16: GARRAFA X 10 KGS. TIPO COMERCIAL
B17: Plazos y lugares de entrega
B18: SEMANAL
B19: COMEDOR | D19: CANTIDAD | E19: DOMICILIO DE ENTREGA
B20: UNA SONRISA | D20: 2 | E20: Bº SAN CARLOS OESTE AV. BONIFACIO COBACHO N° 670
B21: C.I.F Nº1 | D21: 2 | E21: AV. RIVIERA DEL VALLE ENTRE FLORIDA Y SANTA FE
B22: C.I.F - RIVERA DEL VALLE | D22: 2 | E22: Bº RIVERA DEL VALLE ENTRE VILLA EUMELIA Y MONTE CRISTO
B23: ESFUERZO PROPIO | D23: 2 | E23: Bº MUNICIPAL 35VV. NORTE C/14
B24: JIREH LOTEO SUSSEX | D24: 2 | E24: B° LA RIVERA CASA N° 28
B25: CLUB DEPORTIVO CHACARITA | D25: 2 | E25: CALLE DR.DERMIDIO GALINDEZ C/2660
B26: PAPA FRANCISCO | D26: 2 | E26: ENTRE AV.TEREBINTO Y AV.SAN JUAN LOTE "2" MZA. "B"
B27: E.P.C - 100 V.V NORTE | D27: 2 | E27: Bº VV NORTE C/48 ENTRE ESPAÑA Y FRANCIA
B28: HOGAR DE CRISTO | D28: 2 | E28: Bº SANTA MARTA MZA. "S" LOTE "M" C/39
B29: VALLE VIEJO - SUMALAO | D29: 2 | E29: PADRE SEGURA S/N
B30: NUESTRO FUTURO | D30: 2 | E30: Bº LAS VIAS OESTE LOTE 42
B31: SAN JOSE OBRERO | D31: 2 | E31: Bº SAN JOSE OBRERO. PJE. SANDOVAL S/Nº
... B36: CORAZONES FELICES | D36: 2 | E36: LOTEO PARQUE SUR MZ 1 LOTE N° 21
B37: *SE REALIZA LA ENTREGA DE 34 UNIDADES POR SEMANA (2 POR CADA COMEDOR) LO QUE HACE UNA SUMA DE 136 UNIDADES MENSUALES QUE REPRESENTAN UN TOTAL DE 816 UNIDADES SEMESTRALES
B38: Garantia
B39: S/E
B43: Especificidades Item N° 2:
B45: Descripción técnica
B46: GARRAFA X 45 KGS. TIPO COMERCIAL
B47: Plazos y lugares de entrega
B48: CADA 20 DIAS
B49: COMEDOR | D49: CANTIDAD | E49: DOMICILIO DE ENTREGA
B50: LA MORO | D50: 1 | E50: MAIPU NORTE 1º ETAPA MZA "H" Bº MI JARDIN
B51: LA LUCIERNAGA | D51: 1 | E51: Bº 20 V.V NORTE C/3
B52: GAUCHITO GIL | D52: 1 | E52: B° 26 VIVIENDAS CASA N° 3
...

Sheet Autor Gastar (2)
A1: EJERCICIO: | D1: ='ALIM-IMP'!C5 -> 2021 | P1: AUTORIZACION PARA GASTAR
A4: JURISDICCIÓN: | G4: =' NotaPedido'!D3 -> 45- Ministerio de Desarrollo Social y Deporte.-
A5: SAF: | G5: =' NotaPedido'!D4 -> 25- Direccion Provincial de Gestion Administracion y RRHH
A6: UNIDAD EJECUTORA: | G6: 01- Ministerio de Desarrollo Social y Deporte
A7: DEPENDENCIA SOLICITANTE: | G7: 01- Actividad Central
A8: AUTORIZACIÓN:
A9: Señor Jefe de Servicio Administrativo Financiero:
A10: ="Autorizo la realización de los trámites correspondientes, a fin de proveer a este Organismo los bienes y/o servicios que se detallan en Nota de Pedido N° " & ' NotaPedido'!K1&", afectando la erogación resultante a los créditos presupuestarios aprobados a favor de esta Unidad Ejecutora, conforme al siguiente detalle:" -> Autorizo la realización de los trámites correspondientes, a fin de proveer a este Organismo los bienes y/o servicios que se detallan en Nota de Pedido N° 686/2021, afectando la erogación resultante a los créditos presupuestarios aprobados a favor de esta Unidad Ejecutora, conforme al siguiente detalle:
A12: IMPUTACIÓN PRESUPUESTARIA
A13: CÓDIGO | O13: DENOMINACIÓN DE LA PARTIDA PRESUPUESTARIA | Q13: IMPORTE
A14: PR | B14: SB | C14: PY | D14: AC | E14: OB | F14: UG | G14: FIN | H14: FUN | I14: I | J14: P | K14: P | L14: SubP | M14: M | N14: FF
A15: 1 | D15: 1 | F15: 4901 | G15: 1 | H15: 4 | I15: =LEFT('[2]Necesidades Trimestrales'!D10,1) -> 2 | J15: 5 | K15: 6 | M15: 1 | N15: 1.1 | O15: Combustibles y Lubricantes | Q15: 874200
A23: TOTAL DE PESOS: OCHOCIENTOS SETENTA Y CUATRO MIL DOSCIENTOS CON 00/100.- | Q23: =SUM(Q15:Q22) -> 874200
A25: JUSTIFICACIÓN:
A26: Adquisición de Garrafas de Gas para asistir a Personas de escasos Recursos atravez de los Comedores Emergentes.-

Sheet LIM-IMP
B1: Pedido de Necesidades Trimestrales
A3: JURISDICCION: | C3: 45- Ministerio de Desarrollo Social y Deporte.-
A4: SAF N°: | C4: 25- Direccion Provincial de Gestion Administracion y RRHH
A5: EJERCICIO: | C5: 2020
A6: TRIMESTRE: | C6: 4
A8: ID | B8: CODIGO ITEM | C8: RUBRO DE COMPRA | D8: I.P.P. | E8: DESCRIPCION | F8: UNIDAD DE MEDIDA | G8: CANTIDAD | H8: PRECIO UNITARIO ESTIMADO | I8: IMPORTE TOTAL ESTIMADO
A9: 1 | B9: 2.9.1-6951.30 | C9: ELEMENTOS DE LIMPIEZA | D9: 2.9.1 | E9: LIMPIADORES; TIPO: LAVANDINA, PRESENTACION: ENVASE X 5 L | F9: LITROS | G9: 240 | I9: =G9*H9 -> 0
A10: 2 | B10: 2.9.1-6951.12 | C10: ELEMENTOS DE LIMPIEZA | D10: 2.9.1 | E10: LIMPIADORES; PRESENTACION: ENVASE X 5 L, TIPO: DETERGENTE | F10: LITROS | G10: 240 | I10: =G10*H10 -> 0
A11: 3 | B11: 2.9.1-4784.51 | C11: ELEMENTOS DE LIMPIEZA | D11: 2.9.1 | E11: LIMPIADORES MULTIUSO; COMPUESTOS BIODEGRADABLES: SI, PRESENTACION: ENVASE X 5 L, TIPO: DESENGRASANTE | F11: LITROS | G11: 240 | I11: =G11*H11 -> 0
B14: Especificidades Item N° 1:
B16: Descripción técnica
C17: PRESENTACION EN BIDONES PLASTICOS POR 5LTS.
B18: Plazos y lugares de entrega
B19: SEMANAL
B20: COMEDOR | D20: CANTIDAD | E20: DOMICILIO DE ENTREGA
B21: UNA SONRISA | D21: 1 | E21: Bº SAN CARLOS OESTE AV. BONIFACIO COBACHO N° 670
B22: C.I.F Nº1 | D22: 1 | E22: AV. RIVIERA DEL VALLE ENTRE FLORIDA Y SANTA FE
B23: C.I.F - RIVERA DEL VALLE | D23: 1 | E23: Bº RIVERA DEL VALLE ENTRE VILLA EUMELIA Y MONTE CRISTO
B24: ESFUERZO PROPIO | D24: 1 | E24: Bº MUNICIPAL 35VV. NORTE C/14
B25: JIREH LOTEO SUSSEX | D25: 1 | E25: B° LA RIVERA CASA N° 28
B26: CLUB DEPORTIVO CHACARITA | D26: 1 | E26: CALLE DR.DERMIDIO GALINDEZ C/2660
B27: LA MORO | D27: 1 | E27: MAIPU NORTE 1º ETAPA MZA "H" Bº MI JARDIN
B28: PAPA FRANCISCO | D28: 1 | E28: ENTRE AV.TEREBINTO Y AV.SAN JUAN LOTE "2" MZA. "B"
B29: E.P.C - 100 V.V NORTE | D29: 1 | E29: Bº VV NORTE C/48 ENTRE ESPAÑA Y FRANCIA
B30: HOGAR DE CRISTO | D30: 1 | E30: Bº SANTA MARTA MZA. "S" LOTE "M" C/39
B31: LA LUCIERNAGA | D31: 1 | E31: Bº 20 V.V NORTE C/3
B32: VALLE VIEJO - SUMALAO | D32: 1 | E32: PADRE SEGURA S/N
... B40: CORAZONES FELICES | D40: 1 | E40: LOTEO PARQUE SUR MZ 1 LOTE N° 21
B41: *SE REALIZA LA ENTREGA DE 20 UNIDADES POR SEMANA (1 POR CADA COMEDOR) LO QUE HACE UNA SUMA DE 80 UNIDADES MENSUALES QUE REPRESENTAN UN TOTAL DE 240 UNIDADES TRIMESTRALES
B42: Calidad Minima esperada
C43: ALTA
B44: Mantenimiento
C45: 60 DIAS
B46: Garantia
C47: S/E
B50: Especificidades Item N° 2:
B52: Descripción técnica
C53: PRESENTACION EN BIDONES PLASTICOS POR 5LTS.
B54: Plazos y lugares de entrega
B55: SEMANAL
...
