Workbook

Sheet MEDICAMENTOS NT 
B2: Pedido de Necesidades Trimestrales
A4: JURISDICCION: | C4: 40 - Ministerio de Salud
A5: SAF N°: | C5: 23 - Hospital Interzonal San Juan Bautista
A6: EJERCICIO: | C6: 2021
A7: TRIMESTRE: | C7: 1
A9: ID | B9: CODIGO ITEM | C9: RUBRO DE COMPRA | D9: I.P.P. | E9: DESCRIPCION | F9: UNIDAD DE MEDIDA | G9: CANTIDAD | H9: PRECIO UNITARIO ESTIMADO | I9: IMPORTE TOTAL ESTIMADO
A10: 1 | B10: 2.5.2-1837.53 | C10: PROD. MEDICO/FARMACEUTICOS/LAB | D10: =LEFT(B10,5) -> 2.5.2 | E10: HIPOTENSORES; TIPO: MONODROGA, DROGA GENERICA: ACETAZOLAMIDA 250 MG., FORMA FARMACEUTICA: COMPRIMIDO, PRESENTACION: UNIDAD | F10: Comp. | G10: 60 | H10: 20.28 | I10: =+G10*H10 -> 1216.8
A11: 2 | B11: 2.5.2-1873.5 | C11: PROD. MEDICO/FARMACEUTICOS/LAB | D11: =LEFT(B11,5) -> 2.5.2 | E11: ANTICOAGULANTES P/PERSONAS; TIPO: MONODROGA, DROGA GENERICA: ACENOCUMAROL, FORMA FARMACEUTICA: COMPRIMIDOS, PRESENTACION: 4 mGr | F11: Comp. | G11: 200 | H11: 8.08 | I11: =+G11*H11 -> 1616
A12: 3 | B12: 2.5.2-1872.49 | C12: PROD. MEDICO/FARMACEUTICOS/LAB | D12: =LEFT(B12,5) -> 2.5.2 | E12: ANTIANEMICOS; TIPO: MONODROGA, DROGA GENERICA: ACIDO FOLICO 5 MG, FORMA FARMACEUTICA: COMPRIMIDO, PRESENTACION: UNIDAD | F12: Comp. | G12: 2000 | H12: 2.57 | I12: =+G12*H12 -> 5140
A13: 4 | B13: 2.5.2-1873.18 | C13: PROD. MEDICO/FARMACEUTICOS/LAB | D13: =LEFT(B13,5) -> 2.5.2 | E13: ANTICOAGULANTES P/PERSONAS; TIPO: MONODROGA, DROGA GENERICA: AMINOCAPROICO, FORMA FARMACEUTICA: AMPOLLA, PRESENTACION: 2 GR | F13: Amp. | G13: 200 | H13: 190.64 | I13: =+G13*H13 -> 38128
A14: 5 | B14: 2.5.2-1834.10 | C14: PROD. MEDICO/FARMACEUTICOS/LAB | D14: =LEFT(B14,5) -> 2.5.2 | E14: ANTIARRITMICOS; TIPO: MONODROGA, DROGA GENERICA: ADENOSINA 3 MG/ML, FORMA FARMACEUTICA: AMPOLLA, PRESENTACION: 6 mGr | F14: Amp. | G14: 100 | H14: 123.08 | I14: =+G14*H14 -> 12308
A15: 6 | B15: 2.5.1-9037.24 | C15: QUIMICOS | D15: =LEFT(B15,5) -> 2.5.1 | E15: PROTEINAS; COMPUESTO QUIMICO: ALBUMINA HUMANA, ESTADO: SOLUCION, CALIDAD: FARMACOPEA, CONCENTRACION/PUREZA: 20 %, PRESENTACION: ENVASE X 50 mL | F15: Fco.Amp. | G15: 200 | H15: 2136 | I15: =+G15*H15 -> 427200
A16: 7 | B16: 2.9.5-7813.18 | C16: PROD. MEDICO/FARMACEUTICOS/LAB | D16: =LEFT(B16,5) -> 2.9.5 | E16: BOLSAS DE NUTRICION PARENTERAL; CAPACIDAD: 1000 A 3000 mL, USO: ADMINT SOLUC PARENTERAL | F16: Sachet | G16: 20 | H16: 442.8 | I16: =+G16*H16 -> 8856
A17: 8 | B17: 2.5.2-1875.6 | C17: PROD. MEDICO/FARMACEUTICOS/LAB | D17: =LEFT(B17,5) -> 2.5.2 | E17: ANTIASMATICO BRONCODILATADOR; TIPO: MONODROGA, FORMA FARMACEUTICA: AMPOLLA, PRESENTACION: 240 mGr, DROGA GENERICA: AMINOFILINA | F17: Amp. | G17: 100 | H17: 960.81 | I17: =+G17*H17 -> 96081
A18: 9 | B18: 2.5.2-1834.2 | C18: PROD. MEDICO/FARMACEUTICOS/LAB | D18: =LEFT(B18,5) -> 2.5.2 | E18: ANTIARRITMICOS; TIPO: MONODROGA, DROGA GENERICA: AMIODARONA, FORMA FARMACEUTICA: AMPOLLA, PRESENTACION: 150 mGr | F18: Amp. | G18: 300 | H18: 70.14 | I18: =+G18*H18 -> 21042
A19: 10 | B19: 2.5.2-1837.82 | C19: PROD. MEDICO/FARMACEUTICOS/LAB | D19: =LEFT(B19,5) -> 2.5.2 | E19: HIPOTENSORES; TIPO: MONODROGA, DROGA GENERICA: AMLODIPINA, FORMA FARMACEUTICA: COMPRIMIDO, PRESENTACION: 10 mGr | F19: Comp. | G19: 3000 | H19: 3.11 | I19: =+G19*H19 -> 9330
A20: 11 | B20: 2.5.2-1872.43 | C20: PROD. MEDICO/FARMACEUTICOS/LAB | D20: =LEFT(B20,5) -> 2.5.2 | E20: ANTIANEMICOS; TIPO: ASOCIACION, DROGA GENERICA: HIERRO + AC. FOLICO + VIT. B12, FORMA FARMACEUTICA: AMPOLLA, PRESENTACION: ENVASE X 2 mL | F20: Amp. | G20: 60 | H20: 5.96 | I20: =+G20*H20 -> 357.6
A21: 12 | B21: 2.5.2-1843.63 | C21: PROD. MEDICO/FARMACEUTICOS/LAB | D21: =LEFT(B21,5) -> 2.5.2 | E21: ANTIESPASMODICOS; TIPO: MONODROGA, DROGA GENERICA: ATROPINA 1%, FORMA FARMACEUTICA: AMPOLLA, PRESENTACION: ENVASE X 1 mL | F21: Amp. | G21: 1000 | H21: 40.81 | I21: =+G21*H21 -> 40810
... A123: 114 | B123: 2.5.2-711.13 | C123: PROD. MEDICO/FARMACEUTICOS/LAB | D123: =LEFT(B123,5) -> 2.5.2 | E123: ALCOHOL USO MEDICINAL; PUREZA: 99,8 %, CAPACIDAD: 1 L, PRESENTACION: ENVASE X 1 L | F123: LITRO | G123: 41 | H123: 490 | I123: =+G123*H123 -> 20090
A124: 115 | B124: 2.5.2-1726.23 | C124: PROD. MEDICO/FARMACEUTICOS/LAB | D124: 2.5.2. | E124: SOLUCIONES P/MEDICINA; PRESENTACION: ENVASE X 500 mL, TIPO: FISIOLOGICA | F124: Sachet | G124: 40000 | H124: 135.6 | I124: =+G124*H124 -> 5424000
B127: VENCIMIENTO DE MEDICAMENTOS: UN PLAZO NO MENOR A 24 MESES DE LA FECHA DE RECEPCION
B128: Presentar copia certificada de Resolución de Habilitación expedida por la Subsecretaria de Asistencia en Salud Publica o copia certificada de Certificado de Habilitación de Establecimiento y/o copia certificada de Certificado de Transito Interjurisdiccional emitido por A.N.M.A.T, el que correspondiere conforme a la situación de cada establecimiento cotizante (Laboratorio, Droguería, etc.), en caso de corresponder.
B129: Indicar Marca y Numero de Certificado de ANMAT por ítem.
B130: Plazo de Entrega: 10 dias habiles - Lugar de Entrega: Servicio de Farmacia - Mantenimiento de Oferta: 45 dias habiles
B132: Especificidades Item N° 08:
B134: Descripción técnica
C135: Bolsa de Nutricion Enteral - Aminoacidos glucosa lipidos electrolitos 2200kcal x 1970ml T/clinomel
B136: Plazos y lugares de entrega
B139: Calidad Minima esperada
B141: Mantenimiento
B143: Garantia
B148: Especificidades Item N° 103 :
B150: Descripción técnica
C151: SULFATO DE BARIO DIF ORAL 340 GR POLVO
B152: Plazos y lugares de entrega
B155: Calidad Minima esperada
B157: Mantenimiento
B159: Garantia
B164: Especificidades Item N° 104 :
B166: Descripción técnica
...

Sheet MEDICAMENTOS NPYE
A1: NOTA DE PEDIDO | J1: N° | K1: 381 - 2020
A3: JURISDICCIÓN: | D3: ='MEDICAMENTOS NT '!C4 -> 40 - Ministerio de Salud
A4: SAF: | D4: ='MEDICAMENTOS NT '!C5 -> 23 - Hospital Interzonal San Juan Bautista
A5: UNIDAD EJECUTORA: | D5: 168 - Direccion Asistencial
A6: DEPENDENCIA SOLICITANTE: | D6: Servicio de Farmacia
A7: PERIODO UTILIZACIÓN: | D7: ='MEDICAMENTOS NT '!C7 & "° Trimestre - Año " & 'MEDICAMENTOS NT '!C6 -> 1° Trimestre - Año 2021
A8: OBJETO: | D8: Adquisición de Medicamentos
A10: Ítem | B10: Codigo Item | C10: DESCRIPCIÓN | H10: Adjunta Detalle Técnico | I10: Unidad Medida | J10: Precio Unitario Estimado | K10: Cantidad Solicitada
A12: 1 | B12: ='MEDICAMENTOS NT '!B10 -> 2.5.2-1837.53 | C12: ='MEDICAMENTOS NT '!E10 -> HIPOTENSORES; TIPO: MONODROGA, DROGA GENERICA: ACETAZOLAMIDA 250 MG., FORMA FARMACEUTICA: COMPRIMIDO, PRESENTACION: UNIDAD | H12: NO | I12: ='MEDICAMENTOS NT '!F10 -> Comp. | J12: ='MEDICAMENTOS NT '!H10 -> 20.28 | K12: ='MEDICAMENTOS NT '!G10 -> 60
A13: 2 | B13: ='MEDICAMENTOS NT '!B11 -> 2.5.2-1873.5 | C13: ='MEDICAMENTOS NT '!E11 -> ANTICOAGULANTES P/PERSONAS; TIPO: MONODROGA, DROGA GENERICA: ACENOCUMAROL, FORMA FARMACEUTICA: COMPRIMIDOS, PRESENTACION: 4 mGr | H13: NO | I13: ='MEDICAMENTOS NT '!F11 -> Comp. | J13: ='MEDICAMENTOS NT '!H11 -> 8.08 | K13: ='MEDICAMENTOS NT '!G11 -> 200
A14: 3 | B14: ='MEDICAMENTOS NT '!B12 -> 2.5.2-1872.49 | C14: ='MEDICAMENTOS NT '!E12 -> ANTIANEMICOS; TIPO: MONODROGA, DROGA GENERICA: ACIDO FOLICO 5 MG, FORMA FARMACEUTICA: COMPRIMIDO, PRESENTACION: UNIDAD | H14: NO | I14: ='MEDICAMENTOS NT '!F12 -> Comp. | J14: ='MEDICAMENTOS NT '!H12 -> 2.57 | K14: ='MEDICAMENTOS NT '!G12 -> 2000
A15: 4 | B15: ='MEDICAMENTOS NT '!B13 -> 2.5.2-1873.18 | C15: ='MEDICAMENTOS NT '!E13 -> ANTICOAGULANTES P/PERSONAS; TIPO: MONODROGA, DROGA GENERICA: AMINOCAPROICO, FORMA FARMACEUTICA: AMPOLLA, PRESENTACION: 2 GR | H15: NO | I15: ='MEDICAMENTOS NT '!F13 -> Amp. | J15: ='MEDICAMENTOS NT '!H13 -> 190.64 | K15: ='MEDICAMENTOS NT '!G13 -> 200
A16: 5 | B16: ='MEDICAMENTOS NT '!B14 -> 2.5.2-1834.10 | C16: ='MEDICAMENTOS NT '!E14 -> ANTIARRITMICOS; TIPO: MONODROGA, DROGA GENERICA: ADENOSINA 3 MG/ML, FORMA FARMACEUTICA: AMPOLLA, PRESENTACION: 6 mGr | H16: NO | I16: ='MEDICAMENTOS NT '!F14 -> Amp. | J16: ='MEDICAMENTOS NT '!H14 -> 123.08 | K16: ='MEDICAMENTOS NT '!G14 -> 100
A17: 6 | B17: ='MEDICAMENTOS NT '!B15 -> 2.5.1-9037.24 | C17: ='MEDICAMENTOS NT '!E15 -> PROTEINAS; COMPUESTO QUIMICO: ALBUMINA HUMANA, ESTADO: SOLUCION, CALIDAD: FARMACOPEA, CONCENTRACION/PUREZA: 20 %, PRESENTACION: ENVASE X 50 mL | H17: NO | I17: ='MEDICAMENTOS NT '!F15 -> Fco.Amp. | J17: ='MEDICAMENTOS NT '!H15 -> 2136 | K17: ='MEDICAMENTOS NT '!G15 -> 200
A18: 7 | B18: ='MEDICAMENTOS NT '!B16 -> 2.9.5-7813.18 | C18: ='MEDICAMENTOS NT '!E16 -> BOLSAS DE NUTRICION PARENTERAL; CAPACIDAD: 1000 A 3000 mL, USO: ADMINT SOLUC PARENTERAL | H18: NO | I18: ='MEDICAMENTOS NT '!F16 -> Sachet | J18: ='MEDICAMENTOS NT '!H16 -> 442.8 | K18: ='MEDICAMENTOS NT '!G16 -> 20
A19: 8 | B19: ='MEDICAMENTOS NT '!B17 -> 2.5.2-1875.6 | C19: ='MEDICAMENTOS NT '!E17 -> ANTIASMATICO BRONCODILATADOR; TIPO: MONODROGA, FORMA FARMACEUTICA: AMPOLLA, PRESENTACION: 240 mGr, DROGA GENERICA: AMINOFILINA | H19: NO | I19: ='MEDICAMENTOS NT '!F17 -> Amp. | J19: ='MEDICAMENTOS NT '!H17 -> 960.81 | K19: ='MEDICAMENTOS NT '!G17 -> 100
A20: 9 | B20: ='MEDICAMENTOS NT '!B18 -> 2.5.2-1834.2 | C20: ='MEDICAMENTOS NT '!E18 -> ANTIARRITMICOS; TIPO: MONODROGA, DROGA GENERICA: AMIODARONA, FORMA FARMACEUTICA: AMPOLLA, PRESENTACION: 150 mGr | H20: NO | I20: ='MEDICAMENTOS NT '!F18 -> Amp. | J20: ='MEDICAMENTOS NT '!H18 -> 70.14 | K20: ='MEDICAMENTOS NT '!G18 -> 300
A21: 10 | B21: ='MEDICAMENTOS NT '!B19 -> 2.5.2-1837.82 | C21: ='MEDICAMENTOS NT '!E19 -> HIPOTENSORES; TIPO: MONODROGA, DROGA GENERICA: AMLODIPINA, FORMA FARMACEUTICA: COMPRIMIDO, PRESENTACION: 10 mGr | H21: NO | I21: ='MEDICAMENTOS NT '!F19 -> Comp. | J21: ='MEDICAMENTOS NT '!H19 -> 3.11 | K21: ='MEDICAMENTOS NT '!G19 -> 3000
A22: 11 | B22: ='MEDICAMENTOS NT '!B20 -> 2.5.2-1872.43 | C22: ='MEDICAMENTOS NT '!E20 -> ANTIANEMICOS; TIPO: ASOCIACION, DROGA GENERICA: HIERRO + AC. FOLICO + VIT. B12, FORMA FARMACEUTICA: AMPOLLA, PRESENTACION: ENVASE X 2 mL | H22: NO | I22: ='MEDICAMENTOS NT '!F20 -> Amp. | J22: ='MEDICAMENTOS NT '!H20 -> 5.96 | K22: ='MEDICAMENTOS NT '!G20 -> 60
A23: 12 | B23: ='MEDICAMENTOS NT '!B21 -> 2.5.2-1843.63 | C23: ='MEDICAMENTOS NT '!E21 -> ANTIESPASMODICOS; TIPO: MONODROGA, DROGA GENERICA: ATROPINA 1%, FORMA FARMACEUTICA: AMPOLLA, PRESENTACION: ENVASE X 1 mL | H23: NO | I23: ='MEDICAMENTOS NT '!F21 -> Amp. | J23: ='MEDICAMENTOS NT '!H21 -> 40.81 | K23: ='MEDICAMENTOS NT '!G21 -> 1000
... A126: 115 | B126: ='MEDICAMENTOS NT '!B124 -> 2.5.2-1726.23 | C126: ='MEDICAMENTOS NT '!E124 -> SOLUCIONES P/MEDICINA; PRESENTACION: ENVASE X 500 mL, TIPO: FISIOLOGICA | H126: NO | I126: ='MEDICAMENTOS NT '!F124 -> Sachet | J126: ='MEDICAMENTOS NT '!H124 -> 135.6 | K126: ='MEDICAMENTOS NT '!G124 -> 40000
A127: Costo total estimado: Pesos Treinta y cuatro millones treinta y seis mil doscientos sesenta con 91/100.---- | J127: =SUMPRODUCT(J12:J126,K12:K126) -> 34036261

Sheet MEDICAMENTOS APG
A1: EJERCICIO: | D1: ='MEDICAMENTOS NT '!C6 -> 2021 | P1: AUTORIZACION PARA GASTAR
A4: JURISDICCIÓN: | G4: ='MEDICAMENTOS NT '!C4 -> 40 - Ministerio de Salud
A5: SAF: | G5: ='MEDICAMENTOS NT '!C5 -> 23 - Hospital Interzonal San Juan Bautista
A6: UNIDAD EJECUTORA: | G6: ='MEDICAMENTOS NPYE'!D5 -> 168 - Direccion Asistencial
A7: DEPENDENCIA SOLICITANTE: | G7: ='MEDICAMENTOS NPYE'!D6 -> Servicio de Farmacia
A8: AUTORIZACIÓN:
A9: Señor Jefe de Servicio Administrativo Financiero:
A10: ="Autorizo la realización de los trámites correspondientes, a fin de proveer a este Organismo los bienes y/o servicios que se detallan en Nota de Pedido N° " & 'MEDICAMENTOS NPYE'!K1&", afectando la erogación resultante a los créditos presupuestarios aprobados a favor de esta Unidad Ejecutora, conforme al siguiente detalle:" -> Autorizo la realización de los trámites correspondientes, a fin de proveer a este Organismo los bienes y/o servicios que se detallan en Nota de Pedido N° 381 - 2020, afectando la erogación resultante a los créditos presupuestarios aprobados a favor de esta Unidad Ejecutora, conforme al siguiente detalle:
A12: IMPUTACIÓN PRESUPUESTARIA
A13: CÓDIGO | O13: DENOMINACIÓN DE LA PARTIDA PRESUPUESTARIA | Q13: IMPORTE
A14: PR | B14: SB | C14: PY | D14: AC | E14: OB | F14: UG | G14: FIN | H14: FUN | I14: I | J14: P | K14: P | L14: SubP | M14: M | N14: FF
A15: 33 | D15: 2 | F15: 4901 | G15: 3 | H15: 3.1 | I15: 2 | J15: 5 | K15: 1 | M15: 1 | N15: 1.1 | O15: Compuestos Quimicos | Q15: 427200
A16: 33 | D16: 2 | F16: 4901 | G16: 3 | H16: 3.1 | I16: 2 | J16: 5 | K16: 2 | M16: 1 | N16: 1.1 | O16: Productos Farmaceuticos y Medicinales | Q16: =28176204.91+5424000 -> 33600205
A17: 33 | D17: 2 | F17: 4901 | G17: 3 | H17: 3.1 | I17: 2 | J17: 9 | K17: 5 | M17: 1 | N17: 1.1 | O17: Ut. Menores Med. Quirurg. Y de Laborat. | Q17: 8856
A22: TOTAL DE PESOS: TREINTA Y CUATRO MILLONES TREINTA Y SEIS MIL DOSCIENTOS SESENTA CON 91/100.-- | Q22: =SUM(Q15:Q21) -> 34036261
A24: JUSTIFICACIÓN:
A25: ="Para la "& 'MEDICAMENTOS NPYE'!D8 &" para ser destinados al " & 'MEDICAMENTOS NPYE'!D6 &" del HISJB del Ministerio de Salud." -> Para la Adquisición de Medicamentos para ser destinados al Servicio de Farmacia del HISJB del Ministerio de Salud.
