Workbook

Sheet Necesidades Trimestrales 
A1: 2022
B2: Pedido de Necesidades Trimestrales
A4: JURISDICCION: | C4: 040 - Ministerio de Salud
A5: SAF N°: | C5: 011 - Direccion Provincial de Administracion - M.S.
A6: EJERCICIO: | C6: 2022
A7: TRIMESTRE: | C7: 4
A9: ID | B9: CODIGO ITEM | C9: RUBRO DE COMPRA | D9: I.P.P. | E9: DESCRIPCION | F9: UNIDAD DE MEDIDA | G9: CANT. FCIA | H9: TOTAL FCIA | I9: CANT DPMIyA | J9: TOTAL DPMIyA | K9: CANT. TOTAL | L9: PRECIO UNITARIO ESTIMADO | M9: IMPORTE TOTAL ESTIMADO | P9: 252 | Q9: 259 | R9: 295
A10: 1 | B10: 2.5.2-8078.68 | C10: QUIMICOS | D10: 252 | E10: EXCIPIENTES; TIPO: MONODROGA, PRESENTACION: ENVASE X 1 Kg, COMPUESTO: CARBON ACTIVADO, CONCENTRACION/PUREZA: 100 % | F10: UNIDAD | G10: 20 | H10: =+G10*L10 -> 130000 | J10: =+I10*L10 -> 0 | K10: =+G10+I10 -> 20 | L10: 6500 | M10: =+K10*L10 -> 130000 | P10: =+M10 -> 130000
A11: 2 | B11: 2.5.2-1901.7 | C11: PROD. MEDICO/FARMACEUTICOS/LAB | D11: 252 | E11: VITAMINAS; FORMA FARMACEUTICA: AMPOLLA, PRESENTACION: 2 mL, TIPO: MONODROGA, DROGA GENERICA: VITAMINA B | F11: AMPOLLA | G11: 100 | H11: =+G11*L11 -> 17000 | J11: =+I11*L11 -> 0 | K11: =+G11+I11 -> 100 | L11: 170 | M11: =+K11*L11 -> 17000 | P11: =+M11 -> 17000
A12: 3 | B12: 2.9.5-6752.8 | C12: PROD. MEDICO/FARMACEUTICOS/LAB | D12: 295 | E12: ASPIRADORES MEDICOS; TIPO: MANUAL, CAPACIDAD: 60 CM3, USO: ENDOUTERINO | F12: UNIDAD | G12: 0 | H12: =+G12*L12 -> 0 | I12: 10 | J12: =+I12*L12 -> 360000 | K12: =+G12+I12 -> 10 | L12: 36000 | M12: =+K12*L12 -> 360000 | N12: DESCARTABLES COMUNES
A13: 4 | B13: 2.9.5-2204.25 | C13: PROD. MEDICO/FARMACEUTICOS/LAB | D13: 295 | E13: GUÍAS DE SUERO; USO: ADMINISTRACIÓN DE SOLUCIONES; AGUJA: CON; MODELO: V13; TIPO: FOTOSENSIBLE; MACROGOTERO CON CONEXIÓN ROLLER LUER SLIP | F13: UNIDAD | G13: 50 | H13: =+G13*L13 -> 7500 | J13: =+I13*L13 -> 0 | K13: =+G13+I13 -> 50 | L13: 150 | M13: =+K13*L13 -> 7500 | R13: =+M13 -> 7500
A14: 5 | B14: 2.9.5-2204.51 | C14: PROD. MEDICO/FARMACEUTICOS/LAB | D14: 295 | E14: GUÍAS DE SUERO; USO: ADMINISTRACIÓN DE SOLUCIONES; AGUJA: CON; MODELO: V17; TIPO: FOTOSENSIBLE; MICROGOTERO CON CONEXIÓN ROLLER LUER SLIP | F14: UNIDAD | G14: 50 | H14: =+G14*L14 -> 9000 | J14: =+I14*L14 -> 0 | K14: =+G14+I14 -> 50 | L14: 180 | M14: =+K14*L14 -> 9000 | R14: =+M14 -> 9000
A15: 6 | B15: 2.9.5-6379.1 | C15: PROD. MEDICO/FARMACEUTICOS/LAB | D15: 295 | E15: CLAVIJAS DE CIRUGIA; TIPO: KIRSCHNER, MATERIAL: ACERO INOXIDABLE, DIAMETRO: 0,5 mm, PRESENTACION: UNIDAD | F15: UNIDAD | G15: 100 | H15: =+G15*L15 -> 69000 | J15: =+I15*L15 -> 0 | K15: =+G15+I15 -> 100 | L15: 690 | M15: =+K15*L15 -> 69000 | R15: =+M15 -> 69000
A16: 7 | B16: 2.9.5-6379.2 | C16: PROD. MEDICO/FARMACEUTICOS/LAB | D16: 295 | E16: CLAVIJAS DE CIRUGIA; TIPO: KIRSCHNER, MATERIAL: ACERO INOXIDABLE, DIAMETRO: 1 mm, PRESENTACION: UNIDAD | F16: UNIDAD | G16: 80 | H16: =+G16*L16 -> 55200 | J16: =+I16*L16 -> 0 | K16: =+G16+I16 -> 80 | L16: 690 | M16: =+K16*L16 -> 55200 | R16: =+M16 -> 55200
A17: 8 | B17: 2.9.5-6379.3 | C17: PROD. MEDICO/FARMACEUTICOS/LAB | D17: 295 | E17: CLAVIJAS DE CIRUGIA; TIPO: KIRSCHNER, MATERIAL: ACERO INOXIDABLE, DIAMETRO: 1,5 mm, PRESENTACION: UNIDAD | F17: UNIDAD | G17: 100 | H17: =+G17*L17 -> 69000 | J17: =+I17*L17 -> 0 | K17: =+G17+I17 -> 100 | L17: 690 | M17: =+K17*L17 -> 69000 | R17: =+M17 -> 69000
A18: 9 | B18: 2.9.5-6379.5 | C18: PROD. MEDICO/FARMACEUTICOS/LAB | D18: 295 | E18: CLAVIJAS DE CIRUGIA; TIPO: KIRSCHNER, MATERIAL: ACERO INOXIDABLE, DIAMETRO: 2 MM, PRESENTACION: UNIDAD | F18: UNIDAD | G18: 100 | H18: =+G18*L18 -> 69000 | J18: =+I18*L18 -> 0 | K18: =+G18+I18 -> 100 | L18: 690 | M18: =+K18*L18 -> 69000 | R18: =+M18 -> 69000
A19: 10 | B19: 2.9.5-6379.6 | C19: PROD. MEDICO/FARMACEUTICOS/LAB | D19: 295 | E19: CLAVIJAS DE CIRUGÍA; TIPO: KIRSCHNER; DIÁMETRO: 2,5 MM; MATERIAL: ACERO INOXIDABLE; PRESENTACIÓN: UNIDAD | F19: UNIDAD | G19: 100 | H19: =+G19*L19 -> 69000 | J19: =+I19*L19 -> 0 | K19: =+G19+I19 -> 100 | L19: 690 | M19: =+K19*L19 -> 69000 | R19: =+M19 -> 69000
A20: 11 | B20: 2.9.5-2554.26 | C20: PROD.MEDICO/FARMACEUTICOS/LAB | D20: 259 | E20: PAPELES P/ESTERILIZACION; TIPO: GRADO MEDICO, PRESENTACION: ROLLO X 60 CM X 200 M | F20: BOBINA | G20: 25 | H20: =+G20*L20 -> 395000 | J20: =+I20*L20 -> 0 | K20: =+G20+I20 -> 25 | L20: 15800 | M20: =+K20*L20 -> 395000 | N20: ESTERILIZACION | Q20: =+M20 -> 395000
A21: 12 | B21: 2.5.2-1839.31 | C21: PROD. MEDICO/FARMACEUTICOS/LAB | D21: 252 | E21: VASODILATADORES CORONARIOS; TIPO: MONODROGA, DROGA GENERICA: DILTIAZEM, FORMA FARMACEUTICA: COMPRIMIDO, PRESENTACION: 60 mGr | F21: COMPRIMIDO | G21: 3000 | H21: =+G21*L21 -> 101340 | J21: =+I21*L21 -> 0 | K21: =+G21+I21 -> 3000 | L21: 33.78 | M21: =+K21*L21 -> 101340 | P21: =+M21 -> 101340
A22: 13 | B22: 2.9.5-2161.545 | C22: PROD. MEDICO/FARMACEUTICOS/LAB | D22: 295 | E22: CATETERES/SONDAS; NUMERO: SIN, TIPO: TUBO DE LUKEN PARA TOMA DE MUESTRAS | F22: UNIDAD | G22: 50 | H22: =+G22*L22 -> 62500 | J22: =+I22*L22 -> 0 | K22: =+G22+I22 -> 50 | L22: 1250 | M22: =+K22*L22 -> 62500 | R22: =+M22 -> 62500
A23: 14 | B23: 2.5.2-1821.201 | C23: PROD. MEDICO/FARMACEUTICOS/LAB | D23: 252 | E23: ANTIBIOTICOS P/PERSONAS; TIPO: ANTITUBERCULOSTATICO, DROGA GENERICA: RIFAMPICINA X 2 GR, FORMA FARMACEUTICA: EN SUSPENSION CADA 100 mL, PRESENTACION: FRASCO X 50 Ml | F23: FRASCO | G23: 50 | H23: =+G23*L23 -> 42500 | J23: =+I23*L23 -> 0 | K23: =+G23+I23 -> 50 | L23: 850 | M23: =+K23*L23 -> 42500 | P23: =+M23 -> 42500
A24: 15 | B24: 2.5.2-1868.37 | C24: PROD. MEDICO/FARMACEUTICOS/LAB | D24: 252 | E24: ANSIOLITICOS; TIPO: MONODROGA, DROGA GENERICA: CLONAZEPAN 2 MG, FORMA FARMACEUTICA: COMPRIMIDOS, PRESENTACION: UNIDAD | F24: COMPRIMIDO | G24: 35000 | H24: =+G24*L24 -> 178500 | J24: =+I24*L24 -> 0 | K24: =+G24+I24 -> 35000 | L24: 5.1 | M24: =+K24*L24 -> 178500 | N24: AGREGADOS MINISTERIO SALUD + MATERNIDAD | P24: =+M24 -> 178500
A25: 16 | B25: 2.5.2-1865.79 | C25: PROD. MEDICO/FARMACEUTICOS/LAB | D25: 252 | E25: ANTIEPILEPTICOS; TIPO: MONODROGA, DROGA GENERICA: LEVETIRACETAM X 1000 MG, FORMA FARMACEUTICA: COMPRIMIDO, PRESENTACION: ENVASE X 30 UN | F25: CAJA | G25: 200 | H25: =+G25*L25 -> 674200 | J25: =+I25*L25 -> 0 | K25: =+G25+I25 -> 200 | L25: 3371 | M25: =+K25*L25 -> 674200 | P25: =+M25 -> 674200
A26: 17 | B26: 2.5.2-1871.7 | C26: PROD. MEDICO/FARMACEUTICOS/LAB | D26: 252 | E26: NEUROLEPTICOS; TIPO: MONODROGA, DROGA GENERICA: LEVOMEPROMAZINA, FORMA FARMACEUTICA: COMPRIMIDO, PRESENTACION: 25 mGr | F26: COMPRIMIDO | G26: 10000 | H26: =+G26*L26 -> 92000 | J26: =+I26*L26 -> 0 | K26: =+G26+I26 -> 10000 | L26: 9.2 | M26: =+K26*L26 -> 92000 | P26: =+M26 -> 92000
A27: 18 | B27: 2.5.2-1868.82 | C27: PROD. MEDICO/FARMACEUTICOS/LAB | D27: 252 | E27: ANSIOLITICOS; TIPO: MONODROGA, DROGA GENERICA: PREGABALINA 75 MG, FORMA FARMACEUTICA: COMPRIMIDO, PRESENTACION: UNIDAD | F27: COMPRIMIDO | G27: 5000 | H27: =+G27*L27 -> 64000 | J27: =+I27*L27 -> 0 | K27: =+G27+I27 -> 5000 | L27: 12.8 | M27: =+K27*L27 -> 64000 | P27: =+M27 -> 64000
A28: 19 | B28: 2.5.2-7316.5 | C28: PROD. MEDICO/FARMACEUTICOS/LAB | D28: 252 | E28: ANTIPSICOTICOS; PRESENTACION: COMPRIMIDOS, TIPO: MONODROGA, DROGA GENERICA: QUETIAPINA 100 mGr | F28: COMPRIMIDO | G28: 8000 | H28: =+G28*L28 -> 129600 | J28: =+I28*L28 -> 0 | K28: =+G28+I28 -> 8000 | L28: 16.2 | M28: =+K28*L28 -> 129600 | P28: =+M28 -> 129600
A29: 20 | B29: 2.5.2-1868.26 | C29: PROD. MEDICO/FARMACEUTICOS/LAB | D29: 252 | E29: ANSIOLITICOS; TIPO: MONODROGA, DROGA GENERICA: CLOBAZAM, FORMA FARMACEUTICA: COMPRIMIDO, PRESENTACION: 60 X 20 mGr | F29: CAJA | G29: 100 | H29: =+G29*L29 -> 664100 | J29: =+I29*L29 -> 0 | K29: =+G29+I29 -> 100 | L29: 6641 | M29: =+K29*L29 -> 664100 | P29: =+M29 -> 664100
A30: 21 | B30: 2.5.2-1865.29 | C30: PROD. MEDICO/FARMACEUTICOS/LAB | D30: 252 | E30: ANTIEPILEPTICOS; TIPO: MONODROGA, FORMA FARMACEUTICA: COMPRIMIDO, PRESENTACION: 60, DROGA GENERICA: CLOBAZAM X 10 mGr | F30: CAJA | G30: 120 | H30: =+G30*L30 -> 429000 | J30: =+I30*L30 -> 0 | K30: =+G30+I30 -> 120 | L30: 3575 | M30: =+K30*L30 -> 429000 | P30: =+M30 -> 429000
A31: 22 | B31: 2.9.5-8799.11 | C31: PROD. MEDICO/FARMACEUTICOS/LAB | D31: 295 | E31: JERINGA; MATERIAL: PLASTICO, CAPACIDAD: 5 CM3, ACCESORIOS: SIN, TIPO: ESTERIL, ACCESORIO: SIN | F31: UNIDAD | G31: 300000 | H31: =+G31*L31 -> 2934000 | J31: =+I31*L31 -> 0 | K31: =+G31+I31 -> 300000 | L31: 9.78 | M31: =+K31*L31 -> 2934000 | R31: =+M31 -> 2934000
A32: 23 | B32: 2.9.5-2157.73 | C32: PROD. MEDICO/FARMACEUTICOS/LAB | D32: 295 | E32: JERINGAS DESCARTABLES; CAPACIDAD: 10 CM3, AGUJA: SIN, USO: MEDICINAL | F32: UNIDAD | G32: 150000 | H32: =+G32*L32 -> 2124000 | J32: =+I32*L32 -> 0 | K32: =+G32+I32 -> 150000 | L32: 14.16 | M32: =+K32*L32 -> 2124000 | R32: =+M32 -> 2124000
A33: 24 | B33: 2.9.5-441.437 | C33: PROD. MEDICO/FARMACEUTICOS/LAB | D33: 295 | E33: AGUJAS QUIRURGICAS; TIPO: P/INSULINA, ESPECIFICACION: 32 G, PRESENTACION: ENVASE X 100 UN | F33: UNIDAD | G33: 4000 | H33: =+G33*L33 -> 18800000 | J33: =+I33*L33 -> 0 | K33: =+G33+I33 -> 4000 | L33: 4700 | M33: =+K33*L33 -> 18800000 | R33: =+M33 -> 18800000
A34: 25 | B34: 2.9.5-931.49 | C34: PROD. MEDICO/FARMACEUTICOS/LAB | D34: 295 | E34: TELAS ADHESIVAS; ANCHO: 2,5 Cm, LONG.DE CUERPO: 9 M, TIPO: IMPERMEABLE | F34: UNIDAD | G34: 8000 | H34: =+G34*L34 -> 1064000 | J34: =+I34*L34 -> 0 | K34: =+G34+I34 -> 8000 | L34: 133 | M34: =+K34*L34 -> 1064000 | R34: =+M34 -> 1064000
A35: 26 | B35: 2.9.5-931.36 | C35: PROD. MEDICO/FARMACEUTICOS/LAB | D35: 295 | E35: TELAS ADHESIVAS; ANCHO: 5 Cm, LONG.DE CUERPO: 9 M, TIPO: IMPERMEABLE | F35: UNIDAD | G35: 3000 | H35: =+G35*L35 -> 798000 | J35: =+I35*L35 -> 0 | K35: =+G35+I35 -> 3000 | L35: 266 | M35: =+K35*L35 -> 798000 | R35: =+M35 -> 798000
A36: TOTAL DESIERTOS Y FRACASADOS | H36: =SUM(H10:H35) -> 29047440 | J36: =SUM(J10:J35) -> 360000 | M36: =SUM(M10:M35) -> 29407440 | P36: =SUM(P10:P35) -> 2522240 | Q36: =SUM(Q10:Q35) -> 395000 | R36: =SUM(R10:R35) -> 26130200 | S36: =SUM(P36:R36) -> 29047440
P37: 252 | Q37: 259 | R37: 295
C38: DETALLE TECNICO Y ESPECIFICACIONES | D38: ANEXO 1-Para oferentes de la Provincia de Catamarca deberán presentar Habilitación Provincial para comercializar el producto que cotizan. 2-Para el resto de oferentes deberán presentar Certificado de Inscripción de ANMAT vigente al momento de la oferta, el mismo deberá ser correspondiente al objeto de la contratación y de encontrarse vencido adjuntar la solicitud de renovación. 3-No se aceptarán ofertas de productos no registrados y autorizada su venta por ANMAT. Se deberá especificar en cada ítem de la propuesta, marca y número de certificado otorgado por dicho ente regulador. 4-Los productos deberán tener un vencimiento posterior a doce (12) meses a partir de la fecha de su recepción.
C40: Plazos de entrega | D40: diez (10) dias habiles
C42: Lugar de Entrega: | D42: ITEMS 1, 2, 4 al 26 - DIR. PROV. DE FARMACIA E INSUMOS - CHACABUCO N° 169 - en el horario de 8:00hs a 12:00hs de lunes a viernes. DEBIENDO CORRER LOS GASTOS DE FLETES, ACARREO, CARGA, DESCARGA Y SEGURO A CARGO DEL ADJUDICATARIO.
D43: ITEM 3 - DIR. PROV. MATERNIDAD, INFANCIA Y ADOLESCENCIA - CHACABUCO N° 169 - en el horario de 8:00hs a 12:00hs de lunes a viernes. DEBIENDO CORRER LOS GASTOS DE FLETES, ACARREO, CARGA, DESCARGA Y SEGURO A CARGO DEL ADJUDICATARIO.
C45: Calidad Minima esperada
...

Sheet NP DPFeI
A1: NOTA DE PEDIDO | J1: N° | K1: xxx/2022
A3: JURISDICCIÓN: | D3: =+'Necesidades Trimestrales '!C4 -> 040 - Ministerio de Salud
A4: SAF: | D4: =+'Necesidades Trimestrales '!C5 -> 011 - Direccion Provincial de Administracion - M.S.
A5: UNIDAD EJECUTORA: | D5: 469 - Direccion Provincial de Farmacia e Insumos
A6: DEPENDENCIA SOLICITANTE: | D6: 469 - Direccion Provincial de Farmacia e Insumos
A7: PERIODO UTILIZACIÓN: | D7: Semestral
A8: OBJETO: | D8: Adquisición de DESIERTOS Y FRACASADOS TERCER TRIMESTRE
A10: Ítem | B10: Codigo Item | C10: DESCRIPCIÓN | H10: Adjunta Detalle Técnico | I10: Unidad Medida | J10: Precio Unitario Estimado | K10: Cantidad Solicitada
A12: 1 | B12: ='Necesidades Trimestrales '!B10 -> 2.5.2-8078.68 | C12: ='Necesidades Trimestrales '!E10 -> EXCIPIENTES; TIPO: MONODROGA, PRESENTACION: ENVASE X 1 Kg, COMPUESTO: CARBON ACTIVADO, CONCENTRACION/PUREZA: 100 % | H12: NO | I12: ='Necesidades Trimestrales '!F10 -> UNIDAD | J12: ='Necesidades Trimestrales '!L10 -> 6500 | K12: ='Necesidades Trimestrales '!G10 -> 20
A13: 2 | B13: ='Necesidades Trimestrales '!B11 -> 2.5.2-1901.7 | C13: ='Necesidades Trimestrales '!E11 -> VITAMINAS; FORMA FARMACEUTICA: AMPOLLA, PRESENTACION: 2 mL, TIPO: MONODROGA, DROGA GENERICA: VITAMINA B | H13: SI | I13: ='Necesidades Trimestrales '!F11 -> AMPOLLA | J13: ='Necesidades Trimestrales '!L11 -> 170 | K13: ='Necesidades Trimestrales '!G11 -> 100
A14: 3 | B14: ='Necesidades Trimestrales '!B13 -> 2.9.5-2204.25 | C14: ='Necesidades Trimestrales '!E13 -> GUÍAS DE SUERO; USO: ADMINISTRACIÓN DE SOLUCIONES; AGUJA: CON; MODELO: V13; TIPO: FOTOSENSIBLE; MACROGOTERO CON CONEXIÓN ROLLER LUER SLIP | H14: NO | I14: ='Necesidades Trimestrales '!F13 -> UNIDAD | J14: ='Necesidades Trimestrales '!L13 -> 150 | K14: ='Necesidades Trimestrales '!G13 -> 50
A15: 4 | B15: ='Necesidades Trimestrales '!B14 -> 2.9.5-2204.51 | C15: ='Necesidades Trimestrales '!E14 -> GUÍAS DE SUERO; USO: ADMINISTRACIÓN DE SOLUCIONES; AGUJA: CON; MODELO: V17; TIPO: FOTOSENSIBLE; MICROGOTERO CON CONEXIÓN ROLLER LUER SLIP | H15: NO | I15: ='Necesidades Trimestrales '!F14 -> UNIDAD | J15: ='Necesidades Trimestrales '!L14 -> 180 | K15: ='Necesidades Trimestrales '!G14 -> 50
A16: 5 | B16: ='Necesidades Trimestrales '!B15 -> 2.9.5-6379.1 | C16: ='Necesidades Trimestrales '!E15 -> CLAVIJAS DE CIRUGIA; TIPO: KIRSCHNER, MATERIAL: ACERO INOXIDABLE, DIAMETRO: 0,5 mm, PRESENTACION: UNIDAD | H16: NO | I16: ='Necesidades Trimestrales '!F15 -> UNIDAD | J16: ='Necesidades Trimestrales '!L15 -> 690 | K16: ='Necesidades Trimestrales '!G15 -> 100
A17: 6 | B17: ='Necesidades Trimestrales '!B16 -> 2.9.5-6379.2 | C17: ='Necesidades Trimestrales '!E16 -> CLAVIJAS DE CIRUGIA; TIPO: KIRSCHNER, MATERIAL: ACERO INOXIDABLE, DIAMETRO: 1 mm, PRESENTACION: UNIDAD | H17: NO | I17: ='Necesidades Trimestrales '!F16 -> UNIDAD | J17: ='Necesidades Trimestrales '!L16 -> 690 | K17: ='Necesidades Trimestrales '!G16 -> 80
A18: 7 | B18: ='Necesidades Trimestrales '!B17 -> 2.9.5-6379.3 | C18: ='Necesidades Trimestrales '!E17 -> CLAVIJAS DE CIRUGIA; TIPO: KIRSCHNER, MATERIAL: ACERO INOXIDABLE, DIAMETRO: 1,5 mm, PRESENTACION: UNIDAD | H18: NO | I18: ='Necesidades Trimestrales '!F17 -> UNIDAD | J18: ='Necesidades Trimestrales '!L17 -> 690 | K18: ='Necesidades Trimestrales '!G17 -> 100
A19: 8 | B19: ='Necesidades Trimestrales '!B18 -> 2.9.5-6379.5 | C19: ='Necesidades Trimestrales '!E18 -> CLAVIJAS DE CIRUGIA; TIPO: KIRSCHNER, MATERIAL: ACERO INOXIDABLE, DIAMETRO: 2 MM, PRESENTACION: UNIDAD | H19: NO | I19: ='Necesidades Trimestrales '!F18 -> UNIDAD | J19: ='Necesidades Trimestrales '!L18 -> 690 | K19: ='Necesidades Trimestrales '!G18 -> 100
A20: 9 | B20: ='Necesidades Trimestrales '!B19 -> 2.9.5-6379.6 | C20: ='Necesidades Trimestrales '!E19 -> CLAVIJAS DE CIRUGÍA; TIPO: KIRSCHNER; DIÁMETRO: 2,5 MM; MATERIAL: ACERO INOXIDABLE; PRESENTACIÓN: UNIDAD | H20: NO | I20: ='Necesidades Trimestrales '!F19 -> UNIDAD | J20: ='Necesidades Trimestrales '!L19 -> 690 | K20: ='Necesidades Trimestrales '!G19 -> 100
A21: 10 | B21: ='Necesidades Trimestrales '!B20 -> 2.9.5-2554.26 | C21: ='Necesidades Trimestrales '!E20 -> PAPELES P/ESTERILIZACION; TIPO: GRADO MEDICO, PRESENTACION: ROLLO X 60 CM X 200 M | H21: NO | I21: ='Necesidades Trimestrales '!F20 -> BOBINA | J21: ='Necesidades Trimestrales '!L20 -> 15800 | K21: ='Necesidades Trimestrales '!G20 -> 25
A22: 11 | B22: ='Necesidades Trimestrales '!B21 -> 2.5.2-1839.31 | C22: ='Necesidades Trimestrales '!E21 -> VASODILATADORES CORONARIOS; TIPO: MONODROGA, DROGA GENERICA: DILTIAZEM, FORMA FARMACEUTICA: COMPRIMIDO, PRESENTACION: 60 mGr | H22: NO | I22: ='Necesidades Trimestrales '!F21 -> COMPRIMIDO | J22: ='Necesidades Trimestrales '!L21 -> 33.78 | K22: ='Necesidades Trimestrales '!G21 -> 3000
A23: 12 | B23: ='Necesidades Trimestrales '!B22 -> 2.9.5-2161.545 | C23: ='Necesidades Trimestrales '!E22 -> CATETERES/SONDAS; NUMERO: SIN, TIPO: TUBO DE LUKEN PARA TOMA DE MUESTRAS | H23: NO | I23: ='Necesidades Trimestrales '!F22 -> UNIDAD | J23: ='Necesidades Trimestrales '!L22 -> 1250 | K23: ='Necesidades Trimestrales '!G22 -> 50
A24: 13 | B24: ='Necesidades Trimestrales '!B23 -> 2.5.2-1821.201 | C24: ='Necesidades Trimestrales '!E23 -> ANTIBIOTICOS P/PERSONAS; TIPO: ANTITUBERCULOSTATICO, DROGA GENERICA: RIFAMPICINA X 2 GR, FORMA FARMACEUTICA: EN SUSPENSION CADA 100 mL, PRESENTACION: FRASCO X 50 Ml | H24: NO | I24: ='Necesidades Trimestrales '!F23 -> FRASCO | J24: ='Necesidades Trimestrales '!L23 -> 850 | K24: ='Necesidades Trimestrales '!G23 -> 50
A25: 14 | B25: ='Necesidades Trimestrales '!B24 -> 2.5.2-1868.37 | C25: ='Necesidades Trimestrales '!E24 -> ANSIOLITICOS; TIPO: MONODROGA, DROGA GENERICA: CLONAZEPAN 2 MG, FORMA FARMACEUTICA: COMPRIMIDOS, PRESENTACION: UNIDAD | H25: NO | I25: ='Necesidades Trimestrales '!F24 -> COMPRIMIDO | J25: ='Necesidades Trimestrales '!L24 -> 5.1 | K25: ='Necesidades Trimestrales '!G24 -> 35000
... A36: 25 | B36: ='Necesidades Trimestrales '!B35 -> 2.9.5-931.36 | C36: ='Necesidades Trimestrales '!E35 -> TELAS ADHESIVAS; ANCHO: 5 Cm, LONG.DE CUERPO: 9 M, TIPO: IMPERMEABLE | H36: NO | I36: ='Necesidades Trimestrales '!F35 -> UNIDAD | J36: ='Necesidades Trimestrales '!L35 -> 266 | K36: ='Necesidades Trimestrales '!G35 -> 3000
A37: Costo total estimado: PESOS VEINTINUEVE MILLONES CUARENTA Y SIETE MIL CUATROCIENTOS CUARENTA con 00/100. | J37: =SUMPRODUCT(J12:J36,K12:K36) -> 29047440

Sheet APG DPFeI
A1: EJERCICIO: | D1: 2022 | P1: AUTORIZACION PARA GASTAR
A4: JURISDICCIÓN: | G4: =+'Necesidades Trimestrales '!C4 -> 040 - Ministerio de Salud
A5: SAF: | G5: ='NP DPFeI'!D4 -> 011 - Direccion Provincial de Administracion - M.S.
A6: UNIDAD EJECUTORA: | G6: ='NP DPFeI'!D5 -> 469 - Direccion Provincial de Farmacia e Insumos
A7: DEPENDENCIA SOLICITANTE: | G7: ='NP DPFeI'!D6 -> 469 - Direccion Provincial de Farmacia e Insumos
A8: AUTORIZACIÓN:
A9: Señor Jefe de Servicio Administrativo Financiero:
A10: ="Autorizo la realización de los trámites correspondientes, a fin de proveer a este Organismo los bienes y/o servicios que se detallan en Nota de Pedido N° " & 'NP DPFeI'!K1&", afectando la erogación resultante a los créditos presupuestarios aprobados a favor de esta Unidad Ejecutora, conforme al siguiente detalle:" -> Autorizo la realización de los trámites correspondientes, a fin de proveer a este Organismo los bienes y/o servicios que se detallan en Nota de Pedido N° xxx/2022, afectando la erogación resultante a los créditos presupuestarios aprobados a favor de esta Unidad Ejecutora, conforme al siguiente detalle:
A12: IMPUTACIÓN PRESUPUESTARIA
A13: CÓDIGO | O13: DENOMINACIÓN DE LA PARTIDA PRESUPUESTARIA | Q13: IMPORTE
A14: PR | B14: SB | C14: PY | D14: AC | E14: OB | F14: UG | G14: FIN | H14: FUN | I14: I | J14: P | K14: P | L14: SubP | M14: M | N14: FF
A15: 30 | D15: 1 | F15: 4901 | G15: 3 | H15: 1 | I15: 2 | J15: 5 | K15: 2 | M15: 1 | N15: 1.1 | O15: Productos Farmacéuticos y Medicinales | Q15: ='Necesidades Trimestrales '!P36 -> 2522240
A16: 30 | D16: 1 | F16: 4901 | G16: 3 | H16: 1 | I16: 2 | J16: 5 | K16: 9 | M16: 1 | N16: 1.1 | O16: Otros NEP | Q16: ='Necesidades Trimestrales '!Q36 -> 395000
A17: 30 | D17: 1 | F17: 4901 | G17: 3 | H17: 1 | I17: 2 | J17: 9 | K17: 5 | M17: 1 | N17: 1.1 | O17: Utiles menores medicos, quirurgicos y de laboratorio | Q17: ='Necesidades Trimestrales '!R36 -> 26130200
A23: TOTAL DE PESOS: VEINTINUEVE MILLONES CUARENTA Y SIETE MIL CUATROCIENTOS CUARENTA con 00/100. | Q23: =SUM(Q15:Q22) -> 29047440
A25: JUSTIFICACIÓN:
A26: ='NP DPFeI'!D8 -> Adquisición de DESIERTOS Y FRACASADOS TERCER TRIMESTRE

Sheet NP DPMIyA
A1: NOTA DE PEDIDO | J1: N° | K1: xxx/2022
A3: JURISDICCIÓN: | D3: =+'Necesidades Trimestrales '!C4 -> 040 - Ministerio de Salud
A4: SAF: | D4: =+'Necesidades Trimestrales '!C5 -> 011 - Direccion Provincial de Administracion - M.S.
A5: UNIDAD EJECUTORA: | D5: 162 - Direccion Provincial Maternidad, Infancia y Adolescencia
A6: DEPENDENCIA SOLICITANTE: | D6: 162 - Direccion Provincial Maternidad, Infancia y Adolescencia
A7: PERIODO UTILIZACIÓN: | D7: Semestral
A8: OBJETO: | D8: Adquisición de DESIERTOS Y FRACASADOS TERCER TRIMESTRE
A10: Ítem | B10: Codigo Item | C10: DESCRIPCIÓN | H10: Adjunta Detalle Técnico | I10: Unidad Medida | J10: Precio Unitario Estimado | K10: Cantidad Solicitada
A12: 1 | B12: ='Necesidades Trimestrales '!B12 -> 2.9.5-6752.8 | C12: ='Necesidades Trimestrales '!E12 -> ASPIRADORES MEDICOS; TIPO: MANUAL, CAPACIDAD: 60 CM3, USO: ENDOUTERINO | H12: SI | I12: ='Necesidades Trimestrales '!F12 -> UNIDAD | J12: ='Necesidades Trimestrales '!L12 -> 36000 | K12: ='Necesidades Trimestrales '!I12 -> 10
A13: Costo total estimado: PESOS TRESCIENTOS SESENTA MIL con 00/100. | J13: =SUMPRODUCT(J12:J12,K12:K12) -> 360000

Sheet APG DPMIyA
A1: EJERCICIO: | D1: 2022 | P1: AUTORIZACION PARA GASTAR
A4: JURISDICCIÓN: | G4: =+'Necesidades Trimestrales '!C4 -> 040 - Ministerio de Salud
A5: SAF: | G5: ='NP DPMIyA'!D4 -> 011 - Direccion Provincial de Administracion - M.S.
A6: UNIDAD EJECUTORA: | G6: ='NP DPMIyA'!D5 -> 162 - Direccion Provincial Maternidad, Infancia y Adolescencia
A7: DEPENDENCIA SOLICITANTE: | G7: ='NP DPMIyA'!D6 -> 162 - Direccion Provincial Maternidad, Infancia y Adolescencia
A8: AUTORIZACIÓN:
A9: Señor Jefe de Servicio Administrativo Financiero:
A10: ="Autorizo la realización de los trámites correspondientes, a fin de proveer a este Organismo los bienes y/o servicios que se detallan en Nota de Pedido N° " & 'NP DPMIyA'!K1&", afectando la erogación resultante a los créditos presupuestarios aprobados a favor de esta Unidad Ejecutora, conforme al siguiente detalle:" -> Autorizo la realización de los trámites correspondientes, a fin de proveer a este Organismo los bienes y/o servicios que se detallan en Nota de Pedido N° xxx/2022, afectando la erogación resultante a los créditos presupuestarios aprobados a favor de esta Unidad Ejecutora, conforme al siguiente detalle:
A12: IMPUTACIÓN PRESUPUESTARIA
A13: CÓDIGO | O13: DENOMINACIÓN DE LA PARTIDA PRESUPUESTARIA | Q13: IMPORTE
A14: PR | B14: SB | C14: PY | D14: AC | E14: OB | F14: UG | G14: FIN | H14: FUN | I14: I | J14: P | K14: P | L14: SubP | M14: M | N14: FF
A15: 20 | D15: 1 | F15: 4901 | G15: 3 | H15: 1 | I15: 2 | J15: 9 | K15: 5 | M15: 1 | N15: 1.1 | O15: Utiles menores medicos, quirurgicos y de laboratorio | Q15: ='NP DPMIyA'!J13 -> 360000
A23: TOTAL DE PESOS: TRESCIENTOS SESENTA MIL con 00/100. | Q23: =SUM(Q15:Q22) -> 360000
A25: JUSTIFICACIÓN:
A26: ='NP DPMIyA'!D8 -> Adquisición de DESIERTOS Y FRACASADOS TERCER TRIMESTRE
