Workbook

Sheet Necesidades Trimestrales
A2: 2022 | B2: Pedido de Necesidades Trimestrales
A4: JURISDICCION: | C4: 040 - MINISTERIO DE SALUD
A5: SAF N°: | C5: 011 - DIRECCION PROVINCIAL DE ADMINISTRACION - MS
A6: EJERCICIO: | C6: 2022
A7: TRIMESTRE: | C7: 3
A9: ID | B9: CODIGO ITEM COMPRAR | C9: RUBRO DE COMPRA | D9: I.P.P. | E9: DESCRIPCION | F9: UNIDAD DE MEDIDA | G9: D.P.FARMACIA | H9: TOTAL FCIA | I9: SAME | J9: TOTAL SAME | K9: D.P.M.I.A. | L9: TOTAL DPMIA | M9: CANTIDAD | N9: PRECIO UNITARIO ESTIMADO | O9: IMPORTE TOTAL ESTIMADO
A10: 1 | B10: 2.9.5-427.31 | C10: PROD. MEDICO/FARMACEUTICOS/LAB | D10: 295 | E10: APOSITOS; TIPO: P/SUJECION DE CATETER, TAMAÑO: 10 X 12 Cm | F10: UNIDAD | G10: 1000 | H10: =+G10*N10 -> 67000 | J10: =+I10*N10 -> 0 | M10: =+G10+I10+K10 -> 1000 | N10: 67 | O10: =+M10*N10 -> 67000
A11: 2 | B11: 2.9.5-427.84 | C11: PROD. MEDICO/FARMACEUTICOS/LAB | D11: 295 | E11: APOSITOS; TIPO: P/SUJECION DE CATETER, TAMAÑO: 6 X 7 Cm | F11: UNIDAD | G11: 2000 | H11: =+G11*N11 -> 75000 | J11: =+I11*N11 -> 0 | M11: =+G11+I11+K11 -> 2000 | N11: 37.5 | O11: =+M11*N11 -> 75000
A12: 3 | B12: 2.9.5-2505.6 | C12: PROD. MEDICO/FARMACEUTICOS/LAB | D12: 295 | E12: BOLSAS COLECTORAS; TIPO: DE ORINA C/DESAGOTE, USO: ADULTO, CAPACIDAD: 2000 mL | F12: UNIDAD | G12: 300 | H12: =+G12*N12 -> 16500 | J12: =+I12*N12 -> 0 | M12: =+G12+I12+K12 -> 300 | N12: 55 | O12: =+M12*N12 -> 16500
A13: 4 | B13: 2.9.5-2161.7 | C13: PROD. MEDICO/FARMACEUTICOS/LAB | D13: 295 | E13: CATÉTER INTRAVENOSO Nº 14; TIPO: INTRAVENOSO/CANALIZACIÓN | F13: UNIDAD | G13: 1000 | H13: =+G13*N13 -> 45000 | J13: =+I13*N13 -> 0 | M13: =+G13+I13+K13 -> 1000 | N13: 45 | O13: =+M13*N13 -> 45000
A14: 5 | B14: 2.9.5-2161.1 | C14: PROD. MEDICO/FARMACEUTICOS/LAB | D14: 295 | E14: CATETERES/SONDAS; NUMERO: 16, TIPO: INTRAVENOSO | F14: UNIDAD | G14: 1000 | H14: =+G14*N14 -> 45000 | J14: =+I14*N14 -> 0 | M14: =+G14+I14+K14 -> 1000 | N14: 45 | O14: =+M14*N14 -> 45000
A15: 6 | B15: 2.9.5-2161.2 | C15: PROD. MEDICO/FARMACEUTICOS/LAB | D15: 295 | E15: CATÉTER INTRAVENOSO Nº 18; TIPO: INTRAVENOSO/CANALIZACIÓN | F15: UNIDAD | G15: 15000 | H15: =+G15*N15 -> 1275000 | I15: 250 | J15: =+I15*N15 -> 21250 | M15: =+G15+I15+K15 -> 15250 | N15: 85 | O15: =+M15*N15 -> 1296250
A16: 7 | B16: 2.9.5-2161.557 | C16: PROD. MEDICO/FARMACEUTICOS/LAB | D16: 295 | E16: CATÉTER INTRAVENOSO Nº 20; TIPO: INTRAVENOSO/CANALIZACIÓN | F16: UNIDAD | G16: 6000 | H16: =+G16*N16 -> 510000 | I16: 250 | J16: =+I16*N16 -> 21250 | M16: =+G16+I16+K16 -> 6250 | N16: 85 | O16: =+M16*N16 -> 531250
A17: 8 | B17: 2.9.5-2161.4 | C17: PROD. MEDICO/FARMACEUTICOS/LAB | D17: 295 | E17: CATÉTER INTRAVENOSO Nº 22; TIPO: INTRAVENOSO/CANALIZACIÓN | F17: UNIDAD | G17: 3000 | H17: =+G17*N17 -> 255000 | I17: 150 | J17: =+I17*N17 -> 12750 | M17: =+G17+I17+K17 -> 3150 | N17: 85 | O17: =+M17*N17 -> 267750
A18: 9 | B18: 2.9.5-2161.10 | C18: PROD. MEDICO/FARMACEUTICOS/LAB | D18: 295 | E18: CATÉTER INTRAVENOSO Nº 24; TIPO: INTRAVENOSO/CANALIZACIÓN | F18: UNIDAD | G18: 3000 | H18: =+G18*N18 -> 255000 | J18: =+I18*N18 -> 0 | M18: =+G18+I18+K18 -> 3000 | N18: 85 | O18: =+M18*N18 -> 255000
A19: 10 | B19: 2.9.5-2204.58 | C19: PROD. MEDICO/FARMACEUTICOS/LAB | D19: 295 | E19: GUÍA DE SUERO; USO: ADMINISTRACIÓN DE SOLUCIONES, MODELO CON BURETRA VOLUMÉTRICA; TIPO: MACROGOTERO | F19: UNIDAD | G19: 500 | H19: =+G19*N19 -> 610000 | J19: =+I19*N19 -> 0 | M19: =+G19+I19+K19 -> 500 | N19: 1220 | O19: =+M19*N19 -> 610000
A20: 11 | B20: 2.9.5-2204.42 | C20: PROD. MEDICO/FARMACEUTICOS/LAB | D20: 295 | E20: GUÍAS DE SUERO; USO: ADMINISTRACIÓN DE SOLUCIONES; AGUJA: SIN; MODELO: V14, TIPO: MACROGOTERO CON ROLLER LUER SLIP | F20: UNIDAD | G20: 15000 | H20: =+G20*N20 -> 675000 | I20: 250 | J20: =+I20*N20 -> 11250 | M20: =+G20+I20+K20 -> 15250 | N20: 45 | O20: =+M20*N20 -> 686250
A21: 12 | B21: 2.9.5-2204.43 | C21: PROD. MEDICO/FARMACEUTICOS/LAB | D21: 295 | E21: GUÍAS DE SUERO; USO: ADMINISTRACIÓN DE SOLUCIONES; AGUJA: SIN; MODELO: V17, TIPO: MICROGOTERO CON ROLLER LUER SLIP | F21: UNIDAD | G21: 10000 | H21: =+G21*N21 -> 470000 | J21: =+I21*N21 -> 0 | M21: =+G21+I21+K21 -> 10000 | N21: 47 | O21: =+M21*N21 -> 470000
A22: 13 | B22: 2.9.5-2205.13 | C22: PROD. MEDICO/FARMACEUTICOS/LAB | D22: 295 | E22: PROLONGADORES P/GUÍA SUERO; USO: ADMINISTRACIÓN DE SOLUCIONES; MODELO: C/LLAVE DE 3 VÍAS ESTERIL 360° LUERLOCK C/PROLONGADOR DE 15CM | F22: UNIDAD | H22: =+G22*N22 -> 0 | I22: 50 | J22: =+I22*N22 -> 2750 | M22: =+G22+I22+K22 -> 50 | N22: 55 | O22: =+M22*N22 -> 2750
A23: 14 | B23: 2.9.5-2205.33 | C23: PROD. MEDICO/FARMACEUTICOS/LAB | D23: 295 | E23: PROLONGADORES P/GUÍA SUERO; USO: ADMINISTRACIÓN DE SOLUCIONES; MODELO: C/LLAVE DE 3 VÍAS ESTERIL 360° LUERLOCK C/PROLONGADOR DE 30CM | F23: UNIDAD | G23: 200 | H23: =+G23*N23 -> 12000 | J23: =+I23*N23 -> 0 | M23: =+G23+I23+K23 -> 200 | N23: 60 | O23: =+M23*N23 -> 12000
A24: 15 | B24: 2.9.5-2161.224 | C24: PROD. MEDICO/FARMACEUTICOS/LAB | D24: 295 | E24: CATETERES/SONDAS; NUMERO: 14, TIPO: FOLEY DOBLE VIA | F24: UNIDAD | G24: 100 | H24: =+G24*N24 -> 9800 | J24: =+I24*N24 -> 0 | M24: =+G24+I24+K24 -> 100 | N24: 98 | O24: =+M24*N24 -> 9800
A25: 16 | B25: 2.9.5-2161.221 | C25: PROD. MEDICO/FARMACEUTICOS/LAB | D25: 295 | E25: CATETERES/SONDAS; NUMERO: 16, TIPO: FOLEY DOBLE VIA | F25: UNIDAD | G25: 300 | H25: =+G25*N25 -> 29400 | J25: =+I25*N25 -> 0 | M25: =+G25+I25+K25 -> 300 | N25: 98 | O25: =+M25*N25 -> 29400
A26: 17 | B26: 2.9.5-2161.222 | C26: PROD. MEDICO/FARMACEUTICOS/LAB | D26: 295 | E26: CATETERES/SONDAS; NUMERO: 18, TIPO: FOLEY DOBLE VIA | F26: UNIDAD | G26: 200 | H26: =+G26*N26 -> 19600 | J26: =+I26*N26 -> 0 | M26: =+G26+I26+K26 -> 200 | N26: 98 | O26: =+M26*N26 -> 19600
A27: 18 | B27: 2.9.5-2161.216 | C27: PROD. MEDICO/FARMACEUTICOS/LAB | D27: 295 | E27: CATETERES/SONDAS; NUMERO: K-30, TIPO: ASP. MUCUS Y ADMINISTRAC. OXIG | F27: UNIDAD | H27: =+G27*N27 -> 0 | I27: 25 | J27: =+I27*N27 -> 1200 | M27: =+G27+I27+K27 -> 25 | N27: 48 | O27: =+M27*N27 -> 1200
A28: 19 | B28: 2.9.5-2161.217 | C28: PROD. MEDICO/FARMACEUTICOS/LAB | D28: 295 | E28: CATETERES/SONDAS; NUMERO: K-31, TIPO: ASP. MUCUS Y ADMINISTRAC. OXIG | F28: UNIDAD | H28: =+G28*N28 -> 0 | I28: 25 | J28: =+I28*N28 -> 1200 | M28: =+G28+I28+K28 -> 25 | N28: 48 | O28: =+M28*N28 -> 1200
A29: 20 | B29: 2.9.5-2161.188 | C29: PROD. MEDICO/FARMACEUTICOS/LAB | D29: 295 | E29: CATETERES/SONDAS; NUMERO: K-33, TIPO: NASOGASTRICA | F29: UNIDAD | H29: =+G29*N29 -> 0 | I29: 25 | J29: =+I29*N29 -> 1200 | M29: =+G29+I29+K29 -> 25 | N29: 48 | O29: =+M29*N29 -> 1200
A30: 21 | B30: 2.9.5-2161.187 | C30: PROD. MEDICO/FARMACEUTICOS/LAB | D30: 295 | E30: CATETERES/SONDAS; NUMERO: K-35, TIPO: NASOGASTRICA PARA PREMATUROS | F30: UNIDAD | H30: =+G30*N30 -> 0 | I30: 25 | J30: =+I30*N30 -> 1200 | M30: =+G30+I30+K30 -> 25 | N30: 48 | O30: =+M30*N30 -> 1200
A31: 22 | B31: 2.9.5-2161.179 | C31: PROD. MEDICO/FARMACEUTICOS/LAB | D31: 295 | E31: CATETERES/SONDAS; NUMERO: K-9, TIPO: NASOGASTRICA | F31: UNIDAD | H31: =+G31*N31 -> 0 | I31: 25 | J31: =+I31*N31 -> 1450 | M31: =+G31+I31+K31 -> 25 | N31: 58 | O31: =+M31*N31 -> 1450
A32: 23 | B32: 2.9.5-2161.176 | C32: PROD. MEDICO/FARMACEUTICOS/LAB | D32: 295 | E32: CATETERES/SONDAS; NUMERO: 20, TIPO: RECTAL | F32: UNIDAD | G32: 50 | H32: =+G32*N32 -> 4750 | J32: =+I32*N32 -> 0 | M32: =+G32+I32+K32 -> 50 | N32: 95 | O32: =+M32*N32 -> 4750
A33: 24 | B33: 2.9.5-2161.228 | C33: PROD. MEDICO/FARMACEUTICOS/LAB | D33: 295 | E33: CATETERES/SONDAS; NUMERO: 26, TIPO: RECTAL | F33: UNIDAD | G33: 50 | H33: =+G33*N33 -> 4750 | J33: =+I33*N33 -> 0 | M33: =+G33+I33+K33 -> 50 | N33: 95 | O33: =+M33*N33 -> 4750
A34: 25 | B34: 2.9.5-2226.33 | C34: PROD. MEDICO/FARMACEUTICOS/LAB | D34: 295 | E34: CONECTORES P/MEDICINA; USO: SIST. INYECCION INTERMITENTE, CONECTOR: ESTANDAR | F34: UNIDAD | G34: 1000 | H34: =+G34*N34 -> 22000 | J34: =+I34*N34 -> 0 | M34: =+G34+I34+K34 -> 1000 | N34: 22 | O34: =+M34*N34 -> 22000
A35: 26 | B35: 2.9.5-5816.6 | C35: PROD. MEDICO/FARMACEUTICOS/LAB | D35: 295 | E35: PRESERVATIVOS; TIPO: LATEX Y GEL LUBRICANTE, PRESENTACION: KIT, MEDIDA: 160 X 52 X 0,04 A 0,08 mm | F35: CAJA | H35: =+G35*N35 -> 0 | J35: =+I35*N35 -> 0 | K35: 150 | L35: =+K35*N35 -> 517275 | M35: =+G35+I35+K35 -> 150 | N35: 3448.5 | O35: =+M35*N35 -> 517275
A36: 27 | B36: 2.9.5-6752.8 | C36: PROD. MEDICO/FARMACEUTICOS/LAB | D36: 295 | E36: ASPIRADORES MEDICOS; TIPO: MANUAL, CAPACIDAD: 60 CM3, USO: ENDOUTERINO | F36: UNIDAD | K36: 30 | L36: =+K36*N36 -> 960000 | M36: =+G36+I36+K36 -> 30 | N36: 32000 | O36: =+M36*N36 -> 960000
A37: RUBRO DESCARTABLE COMUN | H37: =SUM(H10:H36) -> 4400800 | J37: =SUM(J10:J36) -> 75500 | L37: =SUM(L10:L36) -> 1477275 | O37: =SUM(O10:O36) -> 5953575
B39: DETALLE TECNICO Y ESPECIFICACIONES | C39: ANEXO 1-Para oferentes de la Provincia de Catamarca deberán presentar Habilitación Provincial para comercializar el producto que cotizan. 2-Para el resto de oferentes deberán presentar Certificado de Inscripción de ANMAT vigente al momento de la oferta, el mismo deberá ser correspondiente al objeto de la contratación y de encontrarse vencido adjuntar la solicitud de renovación. 3-No se aceptarán ofertas de productos no registrados y autorizada su venta por ANMAT. Se deberá especificar en cada ítem de la propuesta, marca y número de certificado otorgado por dicho ente regulador. 4-Los productos deberán tener un vencimiento posterior a doce (12) meses a partir de la fecha de su recepción.
B41: Plazos de entrega | C41: veinte (20) dias habiles
B43: Lugar de Entrega: | C43: ITEMS 1 al 5, 6 (15.000 UNID), 7 (6.000 UNID), 8 (3.000 UNID), 9, 10, 11 (15.000 UNID), 12, 14 al 17, 23 al 25 - DIR. PROV. DE FARMACIA E INSUMOS - CHACABUCO N° 169 - en el horario de 8:00hs a 12:00hs de lunes a viernes. DEBIENDO CORRER LOS GASTOS DE FLETES, ACARREO, CARGA, DESCARGA Y SEGURO A CARGO DEL ADJUDICATARIO.
C44: ITEMS 6 (250 UNID), 7 (250 UNID), 8 (150 UNID), 11 (250 UNID), 13, 18 al 22 - DIR. PROV. SAME - CASEROS N° 864 - en el horario de 8:00hs a 12:00hs de lunes a viernes. DEBIENDO CORRER LOS GASTOS DE FLETES, ACARREO, CARGA, DESCARGA Y SEGURO A CARGO DEL ADJUDICATARIO.
C45: ITEMS 26 y 27 - DIR. PROV. MATERNIDAD, INFANCIA Y ADOLESCENCIA - CHACABUCO N° 169 - en el horario de 8:00hs a 12:00hs de lunes a viernes. DEBIENDO CORRER LOS GASTOS DE FLETES, ACARREO, CARGA, DESCARGA Y SEGURO A CARGO DEL ADJUDICATARIO.
B47: Calidad Minima esperada
...

Sheet NP FCIA
A1: NOTA DE PEDIDO | J1: N° | K1: xxx/2022
A3: JURISDICCIÓN: | D3: ='Necesidades Trimestrales'!C4 -> 040 - MINISTERIO DE SALUD
A4: SAF: | D4: ='Necesidades Trimestrales'!C5 -> 011 - DIRECCION PROVINCIAL DE ADMINISTRACION - MS
A5: UNIDAD EJECUTORA: | D5: 469 - DIRECCION PROVINCIAL DE FARMACIA E INSUMOS
A6: DEPENDENCIA SOLICITANTE: | D6: 469 - DIRECCION PROVINCIAL DE FARMACIA E INSUMOS
A7: PERIODO UTILIZACIÓN: | D7: Semestral
A8: OBJETO: | D8: Adquisición de DESCARTABLE COMUN
A10: Ítem | B10: Codigo Item | C10: DESCRIPCIÓN | H10: Adjunta Detalle Técnico | I10: Unidad Medida | J10: Precio Unitario Estimado | K10: Cantidad Solicitada
A12: 1 | B12: =+'Necesidades Trimestrales'!B10 -> 2.9.5-427.31 | C12: =+'Necesidades Trimestrales'!E10 -> APOSITOS; TIPO: P/SUJECION DE CATETER, TAMAÑO: 10 X 12 Cm | H12: NO | I12: =+'Necesidades Trimestrales'!F10 -> UNIDAD | J12: =+'Necesidades Trimestrales'!N10 -> 67 | K12: ='Necesidades Trimestrales'!G10 -> 1000
A13: 2 | B13: =+'Necesidades Trimestrales'!B11 -> 2.9.5-427.84 | C13: =+'Necesidades Trimestrales'!E11 -> APOSITOS; TIPO: P/SUJECION DE CATETER, TAMAÑO: 6 X 7 Cm | H13: NO | I13: =+'Necesidades Trimestrales'!F11 -> UNIDAD | J13: =+'Necesidades Trimestrales'!N11 -> 37.5 | K13: ='Necesidades Trimestrales'!G11 -> 2000
A14: 3 | B14: =+'Necesidades Trimestrales'!B12 -> 2.9.5-2505.6 | C14: =+'Necesidades Trimestrales'!E12 -> BOLSAS COLECTORAS; TIPO: DE ORINA C/DESAGOTE, USO: ADULTO, CAPACIDAD: 2000 mL | H14: NO | I14: =+'Necesidades Trimestrales'!F12 -> UNIDAD | J14: =+'Necesidades Trimestrales'!N12 -> 55 | K14: ='Necesidades Trimestrales'!G12 -> 300
A15: 4 | B15: =+'Necesidades Trimestrales'!B13 -> 2.9.5-2161.7 | C15: =+'Necesidades Trimestrales'!E13 -> CATÉTER INTRAVENOSO Nº 14; TIPO: INTRAVENOSO/CANALIZACIÓN | H15: NO | I15: =+'Necesidades Trimestrales'!F13 -> UNIDAD | J15: =+'Necesidades Trimestrales'!N13 -> 45 | K15: ='Necesidades Trimestrales'!G13 -> 1000
A16: 5 | B16: =+'Necesidades Trimestrales'!B14 -> 2.9.5-2161.1 | C16: =+'Necesidades Trimestrales'!E14 -> CATETERES/SONDAS; NUMERO: 16, TIPO: INTRAVENOSO | H16: NO | I16: =+'Necesidades Trimestrales'!F14 -> UNIDAD | J16: =+'Necesidades Trimestrales'!N14 -> 45 | K16: ='Necesidades Trimestrales'!G14 -> 1000
A17: 6 | B17: =+'Necesidades Trimestrales'!B15 -> 2.9.5-2161.2 | C17: =+'Necesidades Trimestrales'!E15 -> CATÉTER INTRAVENOSO Nº 18; TIPO: INTRAVENOSO/CANALIZACIÓN | H17: NO | I17: =+'Necesidades Trimestrales'!F15 -> UNIDAD | J17: =+'Necesidades Trimestrales'!N15 -> 85 | K17: ='Necesidades Trimestrales'!G15 -> 15000
A18: 7 | B18: =+'Necesidades Trimestrales'!B16 -> 2.9.5-2161.557 | C18: =+'Necesidades Trimestrales'!E16 -> CATÉTER INTRAVENOSO Nº 20; TIPO: INTRAVENOSO/CANALIZACIÓN | H18: NO | I18: =+'Necesidades Trimestrales'!F16 -> UNIDAD | J18: =+'Necesidades Trimestrales'!N16 -> 85 | K18: ='Necesidades Trimestrales'!G16 -> 6000
A19: 8 | B19: =+'Necesidades Trimestrales'!B17 -> 2.9.5-2161.4 | C19: =+'Necesidades Trimestrales'!E17 -> CATÉTER INTRAVENOSO Nº 22; TIPO: INTRAVENOSO/CANALIZACIÓN | H19: NO | I19: =+'Necesidades Trimestrales'!F17 -> UNIDAD | J19: =+'Necesidades Trimestrales'!N17 -> 85 | K19: ='Necesidades Trimestrales'!G17 -> 3000
A20: 9 | B20: =+'Necesidades Trimestrales'!B18 -> 2.9.5-2161.10 | C20: =+'Necesidades Trimestrales'!E18 -> CATÉTER INTRAVENOSO Nº 24; TIPO: INTRAVENOSO/CANALIZACIÓN | H20: NO | I20: =+'Necesidades Trimestrales'!F18 -> UNIDAD | J20: =+'Necesidades Trimestrales'!N18 -> 85 | K20: ='Necesidades Trimestrales'!G18 -> 3000
A21: 10 | B21: =+'Necesidades Trimestrales'!B19 -> 2.9.5-2204.58 | C21: =+'Necesidades Trimestrales'!E19 -> GUÍA DE SUERO; USO: ADMINISTRACIÓN DE SOLUCIONES, MODELO CON BURETRA VOLUMÉTRICA; TIPO: MACROGOTERO | H21: NO | I21: =+'Necesidades Trimestrales'!F19 -> UNIDAD | J21: =+'Necesidades Trimestrales'!N19 -> 1220 | K21: ='Necesidades Trimestrales'!G19 -> 500
A22: 11 | B22: =+'Necesidades Trimestrales'!B20 -> 2.9.5-2204.42 | C22: =+'Necesidades Trimestrales'!E20 -> GUÍAS DE SUERO; USO: ADMINISTRACIÓN DE SOLUCIONES; AGUJA: SIN; MODELO: V14, TIPO: MACROGOTERO CON ROLLER LUER SLIP | H22: NO | I22: =+'Necesidades Trimestrales'!F20 -> UNIDAD | J22: =+'Necesidades Trimestrales'!N20 -> 45 | K22: ='Necesidades Trimestrales'!G20 -> 15000
A23: 12 | B23: =+'Necesidades Trimestrales'!B21 -> 2.9.5-2204.43 | C23: =+'Necesidades Trimestrales'!E21 -> GUÍAS DE SUERO; USO: ADMINISTRACIÓN DE SOLUCIONES; AGUJA: SIN; MODELO: V17, TIPO: MICROGOTERO CON ROLLER LUER SLIP | H23: NO | I23: =+'Necesidades Trimestrales'!F21 -> UNIDAD | J23: =+'Necesidades Trimestrales'!N21 -> 47 | K23: ='Necesidades Trimestrales'!G21 -> 10000
A24: 13 | B24: =+'Necesidades Trimestrales'!B23 -> 2.9.5-2205.33 | C24: =+'Necesidades Trimestrales'!E23 -> PROLONGADORES P/GUÍA SUERO; USO: ADMINISTRACIÓN DE SOLUCIONES; MODELO: C/LLAVE DE 3 VÍAS ESTERIL 360° LUERLOCK C/PROLONGADOR DE 30CM | H24: NO | I24: =+'Necesidades Trimestrales'!F23 -> UNIDAD | J24: =+'Necesidades Trimestrales'!N23 -> 60 | K24: ='Necesidades Trimestrales'!G23 -> 200
A25: 14 | B25: =+'Necesidades Trimestrales'!B24 -> 2.9.5-2161.224 | C25: =+'Necesidades Trimestrales'!E24 -> CATETERES/SONDAS; NUMERO: 14, TIPO: FOLEY DOBLE VIA | H25: NO | I25: =+'Necesidades Trimestrales'!F24 -> UNIDAD | J25: =+'Necesidades Trimestrales'!N24 -> 98 | K25: ='Necesidades Trimestrales'!G24 -> 100
A26: 15 | B26: =+'Necesidades Trimestrales'!B25 -> 2.9.5-2161.221 | C26: =+'Necesidades Trimestrales'!E25 -> CATETERES/SONDAS; NUMERO: 16, TIPO: FOLEY DOBLE VIA | H26: NO | I26: =+'Necesidades Trimestrales'!F25 -> UNIDAD | J26: =+'Necesidades Trimestrales'!N25 -> 98 | K26: ='Necesidades Trimestrales'!G25 -> 300
A27: 16 | B27: =+'Necesidades Trimestrales'!B26 -> 2.9.5-2161.222 | C27: =+'Necesidades Trimestrales'!E26 -> CATETERES/SONDAS; NUMERO: 18, TIPO: FOLEY DOBLE VIA | H27: NO | I27: =+'Necesidades Trimestrales'!F26 -> UNIDAD | J27: =+'Necesidades Trimestrales'!N26 -> 98 | K27: ='Necesidades Trimestrales'!G26 -> 200
A28: 17 | B28: =+'Necesidades Trimestrales'!B32 -> 2.9.5-2161.176 | C28: =+'Necesidades Trimestrales'!E32 -> CATETERES/SONDAS; NUMERO: 20, TIPO: RECTAL | H28: NO | I28: =+'Necesidades Trimestrales'!F32 -> UNIDAD | J28: =+'Necesidades Trimestrales'!N32 -> 95 | K28: ='Necesidades Trimestrales'!G32 -> 50
A29: 18 | B29: =+'Necesidades Trimestrales'!B33 -> 2.9.5-2161.228 | C29: =+'Necesidades Trimestrales'!E33 -> CATETERES/SONDAS; NUMERO: 26, TIPO: RECTAL | H29: NO | I29: =+'Necesidades Trimestrales'!F33 -> UNIDAD | J29: =+'Necesidades Trimestrales'!N33 -> 95 | K29: ='Necesidades Trimestrales'!G33 -> 50
A30: 19 | B30: =+'Necesidades Trimestrales'!B34 -> 2.9.5-2226.33 | C30: =+'Necesidades Trimestrales'!E34 -> CONECTORES P/MEDICINA; USO: SIST. INYECCION INTERMITENTE, CONECTOR: ESTANDAR | H30: SI | I30: =+'Necesidades Trimestrales'!F34 -> UNIDAD | J30: =+'Necesidades Trimestrales'!N34 -> 22 | K30: ='Necesidades Trimestrales'!G34 -> 1000
A31: Costo total estimado: PESOS CUATRO MILLONES CUATROCIENTOS MIL OCHOCIENTOS con 00/100. | J31: =SUMPRODUCT(J12:J30,K12:K30) -> 4400800

Sheet APG FCIA
A1: EJERCICIO: | D1: ='Necesidades Trimestrales'!C6 -> 2022 | P1: AUTORIZACION PARA GASTAR
A4: JURISDICCIÓN: | G4: ='NP FCIA'!D3 -> 040 - MINISTERIO DE SALUD
A5: SAF: | G5: ='NP FCIA'!D4 -> 011 - DIRECCION PROVINCIAL DE ADMINISTRACION - MS
A6: UNIDAD EJECUTORA: | G6: ='NP FCIA'!D5 -> 469 - DIRECCION PROVINCIAL DE FARMACIA E INSUMOS
A7: DEPENDENCIA SOLICITANTE: | G7: ='NP FCIA'!D6 -> 469 - DIRECCION PROVINCIAL DE FARMACIA E INSUMOS
A8: AUTORIZACIÓN:
A9: Señor Jefe de Servicio Administrativo Financiero:
A10: ="Autorizo la realización de los trámites correspondientes, a fin de proveer a este Organismo los bienes y/o servicios que se detallan en Nota de Pedido N° " & 'NP FCIA'!K1&", afectando la erogación resultante a los créditos presupuestarios aprobados a favor de esta Unidad Ejecutora, conforme al siguiente detalle:" -> Autorizo la realización de los trámites correspondientes, a fin de proveer a este Organismo los bienes y/o servicios que se detallan en Nota de Pedido N° xxx/2022, afectando la erogación resultante a los créditos presupuestarios aprobados a favor de esta Unidad Ejecutora, conforme al siguiente detalle:
A12: IMPUTACIÓN PRESUPUESTARIA
A13: CÓDIGO | O13: DENOMINACIÓN DE LA PARTIDA PRESUPUESTARIA | Q13: IMPORTE
A14: PR | B14: SB | C14: PY | D14: AC | E14: OB | F14: UG | G14: FIN | H14: FUN | I14: I | J14: P | K14: P | L14: SubP | M14: M | N14: FF
A15: 30 | D15: 1 | F15: 4901 | G15: 3 | H15: 1 | I15: 2 | J15: 9 | K15: 5 | M15: 1 | N15: 1.1 | O15: Útiles Menores Médico, Quirúrgico y de Laboratorio | Q15: ='NP FCIA'!J31 -> 4400800
A23: TOTAL DE PESOS: CUATRO MILLONES CUATROCIENTOS MIL OCHOCIENTOS con 00/100. | Q23: =SUM(Q15:Q22) -> 4400800
A25: JUSTIFICACIÓN:
A26: ='NP FCIA'!D8 -> Adquisición de DESCARTABLE COMUN

Sheet NP SAME
A1: NOTA DE PEDIDO | J1: N° | K1: xxx/2022
A3: JURISDICCIÓN: | D3: ='Necesidades Trimestrales'!C4 -> 040 - MINISTERIO DE SALUD
A4: SAF: | D4: ='Necesidades Trimestrales'!C5 -> 011 - DIRECCION PROVINCIAL DE ADMINISTRACION - MS
A5: UNIDAD EJECUTORA: | D5: 748 - DIRECCION PROVINCIAL SISTEMA DE ATENCION MEDICA DE EMERGENCIA
A6: DEPENDENCIA SOLICITANTE: | D6: 748 - DIRECCION PROVINCIAL SISTEMA DE ATENCION MEDICA DE EMERGENCIA
A7: PERIODO UTILIZACIÓN: | D7: Semestral
A8: OBJETO: | D8: Adquisición de DESCARTABLE COMUN
A10: Ítem | B10: Codigo Item | C10: DESCRIPCIÓN | H10: Adjunta Detalle Técnico | I10: Unidad Medida | J10: Precio Unitario Estimado | K10: Cantidad Solicitada
A12: 1 | B12: =+'Necesidades Trimestrales'!B15 -> 2.9.5-2161.2 | C12: =+'Necesidades Trimestrales'!E15 -> CATÉTER INTRAVENOSO Nº 18; TIPO: INTRAVENOSO/CANALIZACIÓN | H12: NO | I12: =+'Necesidades Trimestrales'!F15 -> UNIDAD | J12: =+'Necesidades Trimestrales'!N15 -> 85 | K12: ='Necesidades Trimestrales'!I15 -> 250
A13: 2 | B13: =+'Necesidades Trimestrales'!B16 -> 2.9.5-2161.557 | C13: =+'Necesidades Trimestrales'!E16 -> CATÉTER INTRAVENOSO Nº 20; TIPO: INTRAVENOSO/CANALIZACIÓN | H13: NO | I13: =+'Necesidades Trimestrales'!F16 -> UNIDAD | J13: =+'Necesidades Trimestrales'!N16 -> 85 | K13: ='Necesidades Trimestrales'!I16 -> 250
A14: 3 | B14: =+'Necesidades Trimestrales'!B17 -> 2.9.5-2161.4 | C14: =+'Necesidades Trimestrales'!E17 -> CATÉTER INTRAVENOSO Nº 22; TIPO: INTRAVENOSO/CANALIZACIÓN | H14: NO | I14: =+'Necesidades Trimestrales'!F17 -> UNIDAD | J14: =+'Necesidades Trimestrales'!N17 -> 85 | K14: ='Necesidades Trimestrales'!I17 -> 150
A15: 4 | B15: =+'Necesidades Trimestrales'!B20 -> 2.9.5-2204.42 | C15: =+'Necesidades Trimestrales'!E20 -> GUÍAS DE SUERO; USO: ADMINISTRACIÓN DE SOLUCIONES; AGUJA: SIN; MODELO: V14, TIPO: MACROGOTERO CON ROLLER LUER SLIP | H15: NO | I15: =+'Necesidades Trimestrales'!F20 -> UNIDAD | J15: =+'Necesidades Trimestrales'!N20 -> 45 | K15: ='Necesidades Trimestrales'!I20 -> 250
A16: 5 | B16: =+'Necesidades Trimestrales'!B22 -> 2.9.5-2205.13 | C16: =+'Necesidades Trimestrales'!E22 -> PROLONGADORES P/GUÍA SUERO; USO: ADMINISTRACIÓN DE SOLUCIONES; MODELO: C/LLAVE DE 3 VÍAS ESTERIL 360° LUERLOCK C/PROLONGADOR DE 15CM | H16: NO | I16: =+'Necesidades Trimestrales'!F22 -> UNIDAD | J16: =+'Necesidades Trimestrales'!N22 -> 55 | K16: ='Necesidades Trimestrales'!I22 -> 50
A17: 6 | B17: =+'Necesidades Trimestrales'!B27 -> 2.9.5-2161.216 | C17: =+'Necesidades Trimestrales'!E27 -> CATETERES/SONDAS; NUMERO: K-30, TIPO: ASP. MUCUS Y ADMINISTRAC. OXIG | H17: NO | I17: =+'Necesidades Trimestrales'!F27 -> UNIDAD | J17: =+'Necesidades Trimestrales'!N27 -> 48 | K17: ='Necesidades Trimestrales'!I27 -> 25
A18: 7 | B18: =+'Necesidades Trimestrales'!B28 -> 2.9.5-2161.217 | C18: =+'Necesidades Trimestrales'!E28 -> CATETERES/SONDAS; NUMERO: K-31, TIPO: ASP. MUCUS Y ADMINISTRAC. OXIG | H18: NO | I18: =+'Necesidades Trimestrales'!F28 -> UNIDAD | J18: =+'Necesidades Trimestrales'!N28 -> 48 | K18: ='Necesidades Trimestrales'!I28 -> 25
A19: 8 | B19: =+'Necesidades Trimestrales'!B29 -> 2.9.5-2161.188 | C19: =+'Necesidades Trimestrales'!E29 -> CATETERES/SONDAS; NUMERO: K-33, TIPO: NASOGASTRICA | H19: NO | I19: =+'Necesidades Trimestrales'!F29 -> UNIDAD | J19: =+'Necesidades Trimestrales'!N29 -> 48 | K19: ='Necesidades Trimestrales'!I29 -> 25
A20: 9 | B20: =+'Necesidades Trimestrales'!B30 -> 2.9.5-2161.187 | C20: =+'Necesidades Trimestrales'!E30 -> CATETERES/SONDAS; NUMERO: K-35, TIPO: NASOGASTRICA PARA PREMATUROS | H20: NO | I20: =+'Necesidades Trimestrales'!F30 -> UNIDAD | J20: =+'Necesidades Trimestrales'!N30 -> 48 | K20: ='Necesidades Trimestrales'!I30 -> 25
A21: 10 | B21: =+'Necesidades Trimestrales'!B31 -> 2.9.5-2161.179 | C21: =+'Necesidades Trimestrales'!E31 -> CATETERES/SONDAS; NUMERO: K-9, TIPO: NASOGASTRICA | H21: NO | I21: =+'Necesidades Trimestrales'!F31 -> UNIDAD | J21: =+'Necesidades Trimestrales'!N31 -> 58 | K21: ='Necesidades Trimestrales'!I31 -> 25
A22: Costo total estimado: PESOS SETENTA Y CINCO MIL QUINIENTOS con 00/100. | J22: =SUMPRODUCT(J12:J21,K12:K21) -> 75500

Sheet APG SAME
A1: EJERCICIO: | D1: ='Necesidades Trimestrales'!C6 -> 2022 | P1: AUTORIZACION PARA GASTAR
A4: JURISDICCIÓN: | G4: ='NP SAME'!D3 -> 040 - MINISTERIO DE SALUD
A5: SAF: | G5: ='NP SAME'!D4 -> 011 - DIRECCION PROVINCIAL DE ADMINISTRACION - MS
A6: UNIDAD EJECUTORA: | G6: ='NP SAME'!D5 -> 748 - DIRECCION PROVINCIAL SISTEMA DE ATENCION MEDICA DE EMERGENCIA
A7: DEPENDENCIA SOLICITANTE: | G7: ='NP SAME'!D6 -> 748 - DIRECCION PROVINCIAL SISTEMA DE ATENCION MEDICA DE EMERGENCIA
A8: AUTORIZACIÓN:
A9: Señor Jefe de Servicio Administrativo Financiero:
A10: ="Autorizo la realización de los trámites correspondientes, a fin de proveer a este Organismo los bienes y/o servicios que se detallan en Nota de Pedido N° " & 'NP SAME'!K1&", afectando la erogación resultante a los créditos presupuestarios aprobados a favor de esta Unidad Ejecutora, conforme al siguiente detalle:" -> Autorizo la realización de los trámites correspondientes, a fin de proveer a este Organismo los bienes y/o servicios que se detallan en Nota de Pedido N° xxx/2022, afectando la erogación resultante a los créditos presupuestarios aprobados a favor de esta Unidad Ejecutora, conforme al siguiente detalle:
A12: IMPUTACIÓN PRESUPUESTARIA
A13: CÓDIGO | O13: DENOMINACIÓN DE LA PARTIDA PRESUPUESTARIA | Q13: IMPORTE
A14: PR | B14: SB | C14: PY | D14: AC | E14: OB | F14: UG | G14: FIN | H14: FUN | I14: I | J14: P | K14: P | L14: SubP | M14: M | N14: FF
A15: 31 | D15: 1 | F15: 4901 | G15: 3 | H15: 1 | I15: 2 | J15: 9 | K15: 5 | M15: 1 | N15: 1.1 | O15: Útiles Menores Médico, Quirúrgico y de Laboratorio | Q15: ='NP SAME'!J22 -> 75500
A23: TOTAL DE PESOS: SETENTA Y CINCO MIL QUINIENTOS con 00/100. | Q23: =SUM(Q15:Q22) -> 75500
A25: JUSTIFICACIÓN:
A26: ='NP SAME'!D8 -> Adquisición de DESCARTABLE COMUN

Sheet NP DPMIA
A1: NOTA DE PEDIDO | J1: N° | K1: xxx/2022
A3: JURISDICCIÓN: | D3: ='Necesidades Trimestrales'!C4 -> 040 - MINISTERIO DE SALUD
A4: SAF: | D4: ='Necesidades Trimestrales'!C5 -> 011 - DIRECCION PROVINCIAL DE ADMINISTRACION - MS
A5: UNIDAD EJECUTORA: | D5: 162 - DIRECCION PROVINCIAL DE MATERNIDAD, INFANCIA Y ADOLESCENCIA
A6: DEPENDENCIA SOLICITANTE: | D6: 162 - DIRECCION PROVINCIAL DE MATERNIDAD, INFANCIA Y ADOLESCENCIA
A7: PERIODO UTILIZACIÓN: | D7: Semestral
A8: OBJETO: | D8: Adquisición de DESCARTABLE COMUN
A10: Ítem | B10: Codigo Item | C10: DESCRIPCIÓN | H10: Adjunta Detalle Técnico | I10: Unidad Medida | J10: Precio Unitario Estimado | K10: Cantidad Solicitada
A12: 1 | B12: ='Necesidades Trimestrales'!B35 -> 2.9.5-5816.6 | C12: =+'Necesidades Trimestrales'!E35 -> PRESERVATIVOS; TIPO: LATEX Y GEL LUBRICANTE, PRESENTACION: KIT, MEDIDA: 160 X 52 X 0,04 A 0,08 mm | H12: SI | I12: =+'Necesidades Trimestrales'!F35 -> CAJA | J12: =+'Necesidades Trimestrales'!N35 -> 3448.5 | K12: ='Necesidades Trimestrales'!K35 -> 150
A13: 2 | B13: ='Necesidades Trimestrales'!B36 -> 2.9.5-6752.8 | C13: =+'Necesidades Trimestrales'!E36 -> ASPIRADORES MEDICOS; TIPO: MANUAL, CAPACIDAD: 60 CM3, USO: ENDOUTERINO | H13: SI | I13: =+'Necesidades Trimestrales'!F36 -> UNIDAD | J13: =+'Necesidades Trimestrales'!N36 -> 32000 | K13: ='Necesidades Trimestrales'!K36 -> 30
A14: Costo total estimado: PESOS UN MILLON CUATROCIENTOS SETENTA Y SIETE MIL DOSCIENTOS SETENTA Y CINCO con 00/100. | J14: =SUMPRODUCT(J12:J13,K12:K13) -> 1477275

Sheet APG DPMIA
A1: EJERCICIO: | D1: ='Necesidades Trimestrales'!C6 -> 2022 | P1: AUTORIZACION PARA GASTAR
A4: JURISDICCIÓN: | G4: ='NP DPMIA'!D3 -> 040 - MINISTERIO DE SALUD
A5: SAF: | G5: ='NP DPMIA'!D4 -> 011 - DIRECCION PROVINCIAL DE ADMINISTRACION - MS
A6: UNIDAD EJECUTORA: | G6: ='NP DPMIA'!D5 -> 162 - DIRECCION PROVINCIAL DE MATERNIDAD, INFANCIA Y ADOLESCENCIA
A7: DEPENDENCIA SOLICITANTE: | G7: ='NP DPMIA'!D6 -> 162 - DIRECCION PROVINCIAL DE MATERNIDAD, INFANCIA Y ADOLESCENCIA
A8: AUTORIZACIÓN:
A9: Señor Jefe de Servicio Administrativo Financiero:
A10: ="Autorizo la realización de los trámites correspondientes, a fin de proveer a este Organismo los bienes y/o servicios que se detallan en Nota de Pedido N° " & 'NP DPMIA'!K1&", afectando la erogación resultante a los créditos presupuestarios aprobados a favor de esta Unidad Ejecutora, conforme al siguiente detalle:" -> Autorizo la realización de los trámites correspondientes, a fin de proveer a este Organismo los bienes y/o servicios que se detallan en Nota de Pedido N° xxx/2022, afectando la erogación resultante a los créditos presupuestarios aprobados a favor de esta Unidad Ejecutora, conforme al siguiente detalle:
A12: IMPUTACIÓN PRESUPUESTARIA
A13: CÓDIGO | O13: DENOMINACIÓN DE LA PARTIDA PRESUPUESTARIA | Q13: IMPORTE
A14: PR | B14: SB | C14: PY | D14: AC | E14: OB | F14: UG | G14: FIN | H14: FUN | I14: I | J14: P | K14: P | L14: SubP | M14: M | N14: FF
A15: 20 | D15: 1 | F15: 4901 | G15: 3 | H15: 1 | I15: 2 | J15: 9 | K15: 5 | M15: 1 | N15: 1.1 | O15: Útiles Menores Médico, Quirúrgico y de Laboratorio | Q15: ='NP DPMIA'!J14 -> 1477275
A23: TOTAL DE PESOS: UN MILLON CUATROCIENTOS SETENTA Y SIETE MIL DOSCIENTOS SETENTA Y CINCO con 00/100. | Q23: =SUM(Q15:Q22) -> 1477275
A25: JUSTIFICACIÓN:
A26: ='NP DPMIA'!D8 -> Adquisición de DESCARTABLE COMUN
