Workbook

Sheet NECESIDADES TRIMESTRALES
A1: 2021
A2: Pedido de Necesidades Trimestrales
A4: JURISDICCION: | C4: 040 - MINISTERIO DE SALUD
A5: SAF N°: | C5: 011 - DIRECCION PROVINCIAL DE ADMINISTRACION DEL MINISTERIO DE SALUD
A6: EJERCICIO: | C6: 2021
A7: PERIODO DE UTILIZACION: | C7: TERCER TRIMESTRE
A9: ID | B9: CODIGO ITEM | C9: RUBRO DE COMPA | D9: I.P.P. | E9: DESCRIPCION | F9: UNIDAD DE MEDIDA | G9: CANTIDAD SOLICITADA | H9: PRECIO UNITARIO | I9: PRECIO TOTAL | J9: DETALLE TECNICO | L9: 295 | M9: 252 | N9: 265 | O9: 259
A10: 1 | C10: PROD. MEDICO/FARMACEUTICOS/LAB | D10: 2.5.2 | E10: ACIDO GRABADOR ODONTOLOG.; ESTADO: GEL, PRESENTACION: JERINGA X 12 GR | F10: UNIDAD | G10: 150 | H10: 885 | I10: =(H10*G10) -> 132750 | M10: =+I10 -> 132750
A11: 2 | C11: PROD. MEDICO/FARMACEUTICOS/LAB | D11: 2.5.2 | E11: ADHESIVOS P/ODONTOLOGIA; TIPO: ADHESIVO+PRIMER, USO: ODONTOLOGICO, PRESENTACION: FRASCO X 4,5 mm | F11: UNIDAD | G11: 35 | H11: 1490 | I11: =(H11*G11) -> 52150 | M11: =+I11 -> 52150
A12: 3 | C12: PROD. MEDICO/FARMACEUTICOS/LAB | D12: 2.9.5 | E12: AGUJAS QUIRURGICAS; TIPO: ODONTOLOGICA, ESPECIFICACION: CORTA DE 21 mm, PRESENTACION: ENVASE X 100 UN | F12: CAJA | G12: 1500 | H12: 930 | I12: =(H12*G12) -> 1395000 | L12: =+I12 -> 1395000
A13: 4 | C13: PROD. MEDICO/FARMACEUTICOS/LAB | D13: 2.9.5 | E13: ALAMBRE DE ACERO D. 0,7 MM, DESCARTABLE: SI, PRESENTACION: ROLLO X 500 GR | F13: UNIDAD | G13: 2 | H13: 7450 | I13: =(H13*G13) -> 14900 | L13: =+I13 -> 14900
A14: 5 | C14: PROD. MEDICO/FARMACEUTICOS/LAB | D14: 2.9.5 | E14: ALAMBRE DE ACERO D. 0,8 MM; DESCARTABLE: SI, PRESENTACION: ROLLO X 100 GR | F14: UNIDAD | G14: 2 | H14: 880 | I14: =(H14*G14) -> 1760 | L14: =+I14 -> 1760
A15: 6 | C15: PROD. MEDICO/FARMACEUTICOS/LAB | D15: 2.9.5 | E15: ALAMBRE DE ACERO D. 0,9 MM, DESCARTABLE: SI, PRESENTACION: ROLLO X 500 GR | F15: UNIDAD | G15: 2 | H15: 7450 | I15: =(H15*G15) -> 14900 | L15: =+I15 -> 14900
A16: 7 | C16: PROD. MEDICO/FARMACEUTICOS/LAB | D16: 2.9.5 | E16: ALAMBRE DE ACERO D.1 MM, DESCARTABLE: SI, PRESENTACION: ROLLO X 50 GR | F16: UNIDAD | G16: 1 | H16: 880 | I16: =(H16*G16) -> 880 | L16: =+I16 -> 880
A17: 8 | C17: PROD. MEDICO/FARMACEUTICOS/LAB | D17: 2.9.5 | E17: ALGODONES; TIPO: ROLLO P/ODONTOLOGIA, PRESENTACION: ENVASE X 500 UN | F17: BOLSA | G17: 500 | H17: 655 | I17: =(H17*G17) -> 327500 | L17: =+I17 -> 327500
A18: 9 | C18: PROD. MEDICO/FARMACEUTICOS/LAB | D18: 2.9.5 | E18: ALICATE UNIVERSAL, DESCARTABLE: NO, PRESENTACION: UNIDAD | F18: UNIDAD | G18: 20 | H18: 1450 | I18: =(H18*G18) -> 29000 | L18: =+I18 -> 29000
A19: 10 | C19: PROD. MEDICO/FARMACEUTICOS/LAB | D19: 2.5.2 | E19: ANESTESICOS LOCALES; TIPO: ANESTESIA ODONTOLOGICA, DROGA GENERICA: CLORHIDRATO DE CARTICAINA 4%, FORMA FARMACEUTICA: ANESTUBOS, PRESENTACION: ENVASE X 50 ANESTUBOS | F19: CAJA | G19: 2000 | H19: 3360 | I19: =(H19*G19) -> 6720000 | M19: =+I19 -> 6720000
A20: 11 | C20: PROD. MEDICO/FARMACEUTICOS/LAB | D20: 2.5.2 | E20: ANTISEPTICOS LOCALES P/PERSONA; TIPO: ANTISEPTICO, DROGA GENERICA: EUGENOL, FORMA FARMACEUTICA: LIQUIDO, PRESENTACION: FRASCO X 10 mL | F20: UNIDAD | G20: 100 | H20: 300 | I20: =(H20*G20) -> 30000 | M20: =+I20 -> 30000
A21: 12 | C21: PROD. MEDICO/FARMACEUTICOS/LAB | D21: 2.5.2 | E21: ANTISEPTICOS LOCALES P/PERSONA; TIPO: MONODROGA, DROGA GENERICA: EDTAC, FORMA FARMACEUTICA: SOLUCION, PRESENTACION: FRASCO X 20 mL | F21: UNIDAD | G21: 30 | H21: 270 | I21: =(H21*G21) -> 8100 | M21: =+I21 -> 8100
A22: 13 | C22: PROD. MEDICO/FARMACEUTICOS/LAB | D22: 2.5.2 | E22: ANTISEPTICOS LOCALES P/PERSONA; TIPO: MONODROGA, DROGA GENERICA: IODOFORMO, FORMA FARMACEUTICA: POLVO, PRESENTACION: FRASCO X 20 GR | F22: UNIDAD | G22: 30 | H22: 1190 | I22: =(H22*G22) -> 35700 | M22: =+I22 -> 35700
A23: 14 | C23: PROD. MEDICO/FARMACEUTICOS/LAB | D23: 2.9.5 | E23: ATACADOR P/CONOS GUTA-PERCHA, PRESENTACION: UNIDAD, DESCARTABLE: NO | F23: UNIDAD | G23: 30 | H23: 299 | I23: =(H23*G23) -> 8970 | L23: =+I23 -> 8970
A24: 15 | C24: PROD. MEDICO/FARMACEUTICOS/LAB | D24: 2.9.5 | E24: BANDEJA METALICA PARA EL INSTRUMENTAL, DESCARTABLE: NO, PRESENTACION: UNIDAD | F24: UNIDAD | G24: 150 | H24: 420 | I24: =(H24*G24) -> 63000 | L24: =+I24 -> 63000
A25: 16 | C25: PROD. MEDICO/FARMACEUTICOS/LAB | D25: 2.9.5 | E25: BARBIJOS; TIPO: COPA N95 SIN VALVULA, MATERIAL: NO TEJIDO, CANTIDAD DE CAPAS: DOS, DESCARTABLE: SI, PRESENTACION: UNIDAD | F25: UNIDAD | G25: 300 | H25: 150 | I25: =(H25*G25) -> 45000 | L25: =+I25 -> 45000
A26: 17 | C26: PROD. MEDICO/FARMACEUTICOS/LAB | D26: 2.9.5 | E26: BARRA ALTO BRILLO P/PULIR, DESCARTABLE: NO, PRESENTACION: UNIDAD | F26: UNIDAD | G26: 30 | H26: 299 | I26: =(H26*G26) -> 8970 | L26: =+I26 -> 8970
A27: 18 | C27: PROD. MEDICO/FARMACEUTICOS/LAB | D27: 2.9.5 | E27: BROCHITA P/ LIMPIEZA, DESCARTABLE: SI, PRESENTACION: UNIDAD | F27: UNIDAD | G27: 50 | H27: 62.24 | I27: =(H27*G27) -> 3112 | L27: =+I27 -> 3112
A28: 19 | C28: PROD. MEDICO/FARMACEUTICOS/LAB | D28: 2.9.5 | E28: CADENAS P/BABEROS; MATERIAL : 147 dBV/mPa , USO: ODONTOLOGIA, MATERIAL: METAL | F28: UNIDAD | G28: 200 | H28: 199 | I28: =(H28*G28) -> 39800 | L28: =+I28 -> 39800
A29: 20 | C29: PROD. MEDICO/FARMACEUTICOS/LAB | D29: 2.5.2 | E29: CEMENTOS QUIRURGICOS; TIPO: FOSFATO DE ZINC, USO: ODONTOLOGIA, PRESENTACION: AVIO 35 GRS/ML | F29: CAJA | G29: 50 | H29: 1300 | I29: =(H29*G29) -> 65000 | M29: =+I29 -> 65000
A30: 21 | C30: PROD. MEDICO/FARMACEUTICOS/LAB | D30: 2.5.2 | E30: CEMENTOS QUIRURGICOS; TIPO: GROSSMAN, USO: ODONTOLOGIA, PRESENTACION: ENVASE X 20 GR | F30: CAJA | G30: 50 | H30: 440 | I30: =(H30*G30) -> 22000 | M30: =+I30 -> 22000
A31: 22 | C31: PROD. MEDICO/FARMACEUTICOS/LAB | D31: 2.5.2 | E31: CEMENTOS QUIRURGICOS; TIPO: HIDROXIDO DE CALCIO FRAGUABLE, USO: ODONTOLOGIA, PRESENTACION: AVIO 13 GRS/11 GRS | F31: CAJA | G31: 30 | H31: 1492.5 | I31: =(H31*G31) -> 44775 | M31: =+I31 -> 44775
A32: 23 | C32: PROD. MEDICO/FARMACEUTICOS/LAB | D32: 2.5.2 | E32: CEMENTOS QUIRURGICOS; TIPO: OXIDO DE ZINC Y EUGENOL REFORZ, USO: ODONTOLOGICO, PRESENTACION: AVIO 38 GRS/15 ML | F32: CAJA | G32: 50 | H32: 1850 | I32: =(H32*G32) -> 92500 | M32: =+I32 -> 92500
A33: 24 | C33: PROD. MEDICO/FARMACEUTICOS/LAB | D33: 2.9.5 | E33: CEPILLO LIMPIAFRESA, DESCARTABLE: NO, PRESENTACION: UNIDAD | F33: UNIDAD | G33: 20 | H33: 250 | I33: =(H33*G33) -> 5000 | L33: =+I33 -> 5000
A34: 25 | C34: PROD. MEDICO/FARMACEUTICOS/LAB | D34: 2.5.9 | E34: CERAS ROSAS P/ODONTOLOGIA; MATERIAL: UTILITY EN LAMINA, USO: ODONTOLOGICO, PRESENTACION: ENVASE X 1 Kg | F34: CAJA | G34: 5 | H34: 2450 | I34: =(H34*G34) -> 12250 | O34: 12250
A35: 26 | C35: PROD. MEDICO/FARMACEUTICOS/LAB | D35: 2.5.2 | E35: COMPOSITE TIPO ULTRAFILL; COLOR: A2, POLIMERIZACION: FOTOPOLIMERIZACION, TAMAÑO PARTICULA: HIBRIDO, FORMA DE PRESENTACION: JERINGA, PRESENTACION: ENVASE X 4 GR | F35: UNIDAD | G35: 250 | H35: 1290 | I35: =(H35*G35) -> 322500 | M35: =+I35 -> 322500
A36: 27 | C36: PROD. MEDICO/FARMACEUTICOS/LAB | D36: 2.5.2 | E36: COMPOSITE TIPO ULTRAFILL; COLOR: A3, POLIMERIZACION: FOTOPOLIMERIZACION, TAMAÑO PARTICULA: HIBRIDO, FORMA DE PRESENTACION: JERINGA, PRESENTACION: ENVASE X 4 GR | F36: UNIDAD | G36: 250 | H36: 1290 | I36: =(H36*G36) -> 322500 | M36: =+I36 -> 322500
A37: 28 | C37: PROD. MEDICO/FARMACEUTICOS/LAB | D37: 2.5.2 | E37: COMPOSITE TIPO ULTRAFILL; COLOR: A3,5, POLIMERIZACION: FOTOPOLIMERIZACION, TAMAÑO PARTICULA: HIBRIDO, FORMA DE PRESENTACION: JERINGA, PRESENTACION: ENVASE X 4 GR | F37: UNIDAD | G37: 100 | H37: 1290 | I37: =(H37*G37) -> 129000 | M37: =+I37 -> 129000
A38: 29 | C38: PROD. MEDICO/FARMACEUTICOS/LAB | D38: 2.9.5 | E38: COMPRESA P/PLATINA AZUL, DESCARTABLE: SI, PRESENTACION: CAJA X 500 UN | F38: CAJA | G38: 30 | H38: 2925 | I38: =(H38*G38) -> 87750 | L38: =+I38 -> 87750
A39: 30 | C39: PROD. MEDICO/FARMACEUTICOS/LAB | D39: 2.9.5 | E39: CONO DE FIELTRO Nº 4, DESCARTABLE: SI, PRESENTACION: UNIDAD | F39: UNIDAD | G39: 10 | H39: 550 | I39: =(H39*G39) -> 5500 | L39: =+I39 -> 5500
A40: 31 | C40: PROD. MEDICO/FARMACEUTICOS/LAB | D40: 2.9.5 | E40: CONO GUTAPERCHA 1ªSERIE, DESCARTABLE: SI, PRESENTACION: CAJA X 100 | F40: CAJA | G40: 30 | H40: 730 | I40: =(H40*G40) -> 21900 | L40: =+I40 -> 21900
A41: 32 | C41: PROD. MEDICO/FARMACEUTICOS/LAB | D41: 2.9.5 | E41: CONO GUTAPERCHA 2ªSERIE, DESCARTABLE: SI, PRESENTACION: CAJA X 100 | F41: CAJA | G41: 30 | H41: 730 | I41: =(H41*G41) -> 21900 | L41: =+I41 -> 21900
A42: 33 | C42: PROD. MEDICO/FARMACEUTICOS/LAB | D42: 2.9.5 | E42: CUCHARITAS DE BLACK DOBLES, DESCARTABLE: NO, PRESENTACION: UNIDAD | F42: UNIDAD | G42: 15 | H42: 298.5 | I42: =(H42*G42) -> 4477.5 | L42: =+I42 -> 4477.5
...

Sheet NOTA DE PEDIDO
A1: NOTA DE PEDIDO | J1: N° | K1: 15/2021
A3: JURISDICCIÓN: | D3: 040 - Ministerio de Salud
A4: SAF: | D4: 011 - Direccion Provincial de Administración - Ministerio de Salud
A5: UNIDAD EJECUTORA: | D5: 470 - DIRECCION PROVINCIAL DE ODONTOLOGIA
A6: DEPENDENCIA SOLICITANTE: | D6: 470 - DIRECCION PROVINCIAL DE ODONTOLOGIA
A7: PERIODO UTILIZACIÓN: | D7: 3° TRIMESTRE
A8: OBJETO: | D8: Adquisicion del RUBRO INSUMOS DE ODONTOLOGIA
A10: Ítem | B10: Codigo Item | C10: DESCRIPCIÓN | H10: Adjunta Detalle Técnico | I10: Unidad Medida | J10: Precio Unitario Estimado | K10: Cantidad Solicitada
A12: 1 | C12: ='NECESIDADES TRIMESTRALES'!E10 -> ACIDO GRABADOR ODONTOLOG.; ESTADO: GEL, PRESENTACION: JERINGA X 12 GR | H12: NO | I12: ='NECESIDADES TRIMESTRALES'!F10 -> UNIDAD | J12: ='NECESIDADES TRIMESTRALES'!H10 -> 885 | K12: ='NECESIDADES TRIMESTRALES'!G10 -> 150 | L12: =+J12*K12 -> 132750 | M12: =+J12*K12 -> 132750
A13: 2 | C13: ='NECESIDADES TRIMESTRALES'!E11 -> ADHESIVOS P/ODONTOLOGIA; TIPO: ADHESIVO+PRIMER, USO: ODONTOLOGICO, PRESENTACION: FRASCO X 4,5 mm | H13: NO | I13: ='NECESIDADES TRIMESTRALES'!F11 -> UNIDAD | J13: ='NECESIDADES TRIMESTRALES'!H11 -> 1490 | K13: ='NECESIDADES TRIMESTRALES'!G11 -> 35 | L13: =+J13*K13 -> 52150 | M13: =+J13*K13 -> 52150
A14: 3 | C14: ='NECESIDADES TRIMESTRALES'!E12 -> AGUJAS QUIRURGICAS; TIPO: ODONTOLOGICA, ESPECIFICACION: CORTA DE 21 mm, PRESENTACION: ENVASE X 100 UN | H14: NO | I14: ='NECESIDADES TRIMESTRALES'!F12 -> CAJA | J14: ='NECESIDADES TRIMESTRALES'!H12 -> 930 | K14: ='NECESIDADES TRIMESTRALES'!G12 -> 1500 | L14: =+J14*K14 -> 1395000 | M14: =+J14*K14 -> 1395000
A15: 4 | C15: ='NECESIDADES TRIMESTRALES'!E13 -> ALAMBRE DE ACERO D. 0,7 MM, DESCARTABLE: SI, PRESENTACION: ROLLO X 500 GR | H15: NO | I15: ='NECESIDADES TRIMESTRALES'!F13 -> UNIDAD | J15: ='NECESIDADES TRIMESTRALES'!H13 -> 7450 | K15: ='NECESIDADES TRIMESTRALES'!G13 -> 2 | L15: =+J15*K15 -> 14900 | M15: =+J15*K15 -> 14900
A16: 5 | C16: ='NECESIDADES TRIMESTRALES'!E14 -> ALAMBRE DE ACERO D. 0,8 MM; DESCARTABLE: SI, PRESENTACION: ROLLO X 100 GR | H16: NO | I16: ='NECESIDADES TRIMESTRALES'!F14 -> UNIDAD | J16: ='NECESIDADES TRIMESTRALES'!H14 -> 880 | K16: ='NECESIDADES TRIMESTRALES'!G14 -> 2 | L16: =+J16*K16 -> 1760 | M16: =+J16*K16 -> 1760
A17: 6 | C17: ='NECESIDADES TRIMESTRALES'!E15 -> ALAMBRE DE ACERO D. 0,9 MM, DESCARTABLE: SI, PRESENTACION: ROLLO X 500 GR | H17: NO | I17: ='NECESIDADES TRIMESTRALES'!F15 -> UNIDAD | J17: ='NECESIDADES TRIMESTRALES'!H15 -> 7450 | K17: ='NECESIDADES TRIMESTRALES'!G15 -> 2 | L17: =+J17*K17 -> 14900 | M17: =+J17*K17 -> 14900
A18: 7 | C18: ='NECESIDADES TRIMESTRALES'!E16 -> ALAMBRE DE ACERO D.1 MM, DESCARTABLE: SI, PRESENTACION: ROLLO X 50 GR | H18: NO | I18: ='NECESIDADES TRIMESTRALES'!F16 -> UNIDAD | J18: ='NECESIDADES TRIMESTRALES'!H16 -> 880 | K18: ='NECESIDADES TRIMESTRALES'!G16 -> 1 | L18: =+J18*K18 -> 880 | M18: =+J18*K18 -> 880
A19: 8 | C19: ='NECESIDADES TRIMESTRALES'!E17 -> ALGODONES; TIPO: ROLLO P/ODONTOLOGIA, PRESENTACION: ENVASE X 500 UN | H19: NO | I19: ='NECESIDADES TRIMESTRALES'!F17 -> BOLSA | J19: ='NECESIDADES TRIMESTRALES'!H17 -> 655 | K19: ='NECESIDADES TRIMESTRALES'!G17 -> 500 | L19: =+J19*K19 -> 327500 | M19: =+J19*K19 -> 327500
A20: 9 | C20: ='NECESIDADES TRIMESTRALES'!E18 -> ALICATE UNIVERSAL, DESCARTABLE: NO, PRESENTACION: UNIDAD | H20: NO | I20: ='NECESIDADES TRIMESTRALES'!F18 -> UNIDAD | J20: ='NECESIDADES TRIMESTRALES'!H18 -> 1450 | K20: ='NECESIDADES TRIMESTRALES'!G18 -> 20 | L20: =+J20*K20 -> 29000 | M20: =+J20*K20 -> 29000
A21: 10 | C21: ='NECESIDADES TRIMESTRALES'!E19 -> ANESTESICOS LOCALES; TIPO: ANESTESIA ODONTOLOGICA, DROGA GENERICA: CLORHIDRATO DE CARTICAINA 4%, FORMA FARMACEUTICA: ANESTUBOS, PRESENTACION: ENVASE X 50 ANESTUBOS | H21: NO | I21: ='NECESIDADES TRIMESTRALES'!F19 -> CAJA | J21: ='NECESIDADES TRIMESTRALES'!H19 -> 3360 | K21: ='NECESIDADES TRIMESTRALES'!G19 -> 2000 | L21: =+J21*K21 -> 6720000 | M21: =+J21*K21 -> 6720000
A22: 11 | C22: ='NECESIDADES TRIMESTRALES'!E20 -> ANTISEPTICOS LOCALES P/PERSONA; TIPO: ANTISEPTICO, DROGA GENERICA: EUGENOL, FORMA FARMACEUTICA: LIQUIDO, PRESENTACION: FRASCO X 10 mL | H22: NO | I22: ='NECESIDADES TRIMESTRALES'!F20 -> UNIDAD | J22: ='NECESIDADES TRIMESTRALES'!H20 -> 300 | K22: ='NECESIDADES TRIMESTRALES'!G20 -> 100 | L22: =+J22*K22 -> 30000 | M22: =+J22*K22 -> 30000
A23: 12 | C23: ='NECESIDADES TRIMESTRALES'!E21 -> ANTISEPTICOS LOCALES P/PERSONA; TIPO: MONODROGA, DROGA GENERICA: EDTAC, FORMA FARMACEUTICA: SOLUCION, PRESENTACION: FRASCO X 20 mL | H23: NO | I23: ='NECESIDADES TRIMESTRALES'!F21 -> UNIDAD | J23: ='NECESIDADES TRIMESTRALES'!H21 -> 270 | K23: ='NECESIDADES TRIMESTRALES'!G21 -> 30 | L23: =+J23*K23 -> 8100 | M23: =+J23*K23 -> 8100
... A43: 32 | C43: ='NECESIDADES TRIMESTRALES'!E41 -> CONO GUTAPERCHA 2ªSERIE, DESCARTABLE: SI, PRESENTACION: CAJA X 100 | H43: NO | I43: ='NECESIDADES TRIMESTRALES'!F41 -> CAJA | J43: ='NECESIDADES TRIMESTRALES'!H41 -> 730 | K43: ='NECESIDADES TRIMESTRALES'!G41 -> 30 | L43: =+J43*K43 -> 21900 | M43: =+J43*K43 -> 21900
A44: 33 | C44: ='NECESIDADES TRIMESTRALES'!E42 -> CUCHARITAS DE BLACK DOBLES, DESCARTABLE: NO, PRESENTACION: UNIDAD | H44: NO | I44: ='NECESIDADES TRIMESTRALES'!F42 -> UNIDAD | J44: ='NECESIDADES TRIMESTRALES'!H42 -> 298.5 | K44: ='NECESIDADES TRIMESTRALES'!G42 -> 15 | L44: =+J44*K44 -> 4477.5
A45: 34 | C45: ='NECESIDADES TRIMESTRALES'!E43 -> CURETA DE GRACEY, DESCARTABLE: NO, PRESENTACION: UNIDAD | H45: NO | I45: ='NECESIDADES TRIMESTRALES'!F43 -> UNIDAD | J45: ='NECESIDADES TRIMESTRALES'!H43 -> 1750 | K45: ='NECESIDADES TRIMESTRALES'!G43 -> 50 | L45: =+J45*K45 -> 87500
A46: 35 | C46: ='NECESIDADES TRIMESTRALES'!E44 -> DISCO P/ PULIR, DESCARTABLE: NO, PRESENTACION: UNIDAD | H46: NO | I46: ='NECESIDADES TRIMESTRALES'!F44 -> UNIDAD | J46: ='NECESIDADES TRIMESTRALES'!H44 -> 200 | K46: ='NECESIDADES TRIMESTRALES'!G44 -> 50 | L46: =+J46*K46 -> 10000
A47: 36 | C47: ='NECESIDADES TRIMESTRALES'!E45 -> DISCO P/PULIR COMPOSITE, DESCARTABLE: NO, PRESENTACION: ENVASE X 50 UN | H47: NO | I47: ='NECESIDADES TRIMESTRALES'!F45 -> CAJA | J47: ='NECESIDADES TRIMESTRALES'!H45 -> 9950 | K47: ='NECESIDADES TRIMESTRALES'!G45 -> 20 | L47: =+J47*K47 -> 199000
A48: 37 | C48: ='NECESIDADES TRIMESTRALES'!E46 -> ESPACIADOR P/CONOS GUTA-PERCHA, DESCARTABLE: NO, PRESENTACION: CAJA X 6 | H48: NO | I48: ='NECESIDADES TRIMESTRALES'!F46 -> CAJA | J48: ='NECESIDADES TRIMESTRALES'!H46 -> 1390 | K48: ='NECESIDADES TRIMESTRALES'!G46 -> 50 | L48: =+J48*K48 -> 69500
A49: 38 | C49: ='NECESIDADES TRIMESTRALES'!E47 -> ESPATULA P/CEMENTO DOBLE, DESCARTABLE: NO, PRESENTACION: UNIDAD | H49: NO | I49: ='NECESIDADES TRIMESTRALES'!F47 -> UNIDAD | J49: ='NECESIDADES TRIMESTRALES'!H47 -> 299 | K49: ='NECESIDADES TRIMESTRALES'!G47 -> 150 | L49: =+J49*K49 -> 44850
A50: 39 | C50: ='NECESIDADES TRIMESTRALES'!E48 -> ESPATULA PARA GUTTA, DESCARTABLE: NO, PRESENTACION: UNIDAD | H50: NO | I50: ='NECESIDADES TRIMESTRALES'!F48 -> UNIDAD | J50: ='NECESIDADES TRIMESTRALES'!H48 -> 299 | K50: ='NECESIDADES TRIMESTRALES'!G48 -> 50 | L50: =+J50*K50 -> 14950
A51: 40 | C51: ='NECESIDADES TRIMESTRALES'!E49 -> ESPEJOS BUCALES; PRESENTACION: ENVASE X 12 UN | H51: NO | I51: ='NECESIDADES TRIMESTRALES'!F49 -> CAJA | J51: ='NECESIDADES TRIMESTRALES'!H49 -> 1600 | K51: ='NECESIDADES TRIMESTRALES'!G49 -> 500 | L51: =+J51*K51 -> 800000
A52: 41 | C52: ='NECESIDADES TRIMESTRALES'!E50 -> ESPONJAS; MATERIAL: POLIESTER, USO: ODONTOLOGICO, ADITAMENTO: CON, FORMA: REDONDA, LARGO X ANCHO X ESP: DIAMETRO 4 Cm, PRESENTACION: UNIDAD | H52: NO | I52: ='NECESIDADES TRIMESTRALES'!F50 -> UNIDAD | J52: ='NECESIDADES TRIMESTRALES'!H50 -> 26 | K52: ='NECESIDADES TRIMESTRALES'!G50 -> 50 | L52: =+J52*K52 -> 1300
A53: 42 | C53: ='NECESIDADES TRIMESTRALES'!E51 -> EXPLORADOR CURVO P/EXAMEN BUCA; DESCARTABLE: NO, PRESENTACION: UNIDAD | H53: NO | I53: ='NECESIDADES TRIMESTRALES'!F51 -> UNIDAD | J53: ='NECESIDADES TRIMESTRALES'!H51 -> 202.5 | K53: ='NECESIDADES TRIMESTRALES'!G51 -> 100 | L53: =+J53*K53 -> 20250
A54: 43 | C54: ='NECESIDADES TRIMESTRALES'!E52 -> FIJADORES P/RADIOLOGIA; SENSIBILIDAD: AL VERDE, PROCESO: MANUAL, PROCESO DE UTILIZACION: MANUAL, PRESENTACION: BOTELLA, CAPACIDAD: 480 mL | H54: NO | I54: ='NECESIDADES TRIMESTRALES'!F52 -> BOTELLA | J54: ='NECESIDADES TRIMESTRALES'!H52 -> 540 | K54: ='NECESIDADES TRIMESTRALES'!G52 -> 120 | L54: =+J54*K54 -> 64800
A55: 44 | C55: ='NECESIDADES TRIMESTRALES'!E53 -> FRESAS P/ODONTOLOGIA; MATERIAL: ACERO INOXIDABLE, Nº: 6991, LARGO: CHICA, TIPO: TRONCOCONICA, NUMERO: 6991 | H55: NO | I55: ='NECESIDADES TRIMESTRALES'!F53 -> UNIDAD | J55: ='NECESIDADES TRIMESTRALES'!H53 -> 234.48 | K55: ='NECESIDADES TRIMESTRALES'!G53 -> 20 | L55: =+J55*K55 -> 4689.6
... A97: 86 | C97: ='NECESIDADES TRIMESTRALES'!E95 -> FRESAS P/ODONTOLOGIA; MATERIAL: PIEDRA DE DIAMANTE, NUMERO: SIN, LARGO: STANDAR, TIPO: CILINDRICA FG | H97: NO | I97: ='NECESIDADES TRIMESTRALES'!F95 -> UNIDAD | J97: ='NECESIDADES TRIMESTRALES'!H95 -> 225 | K97: ='NECESIDADES TRIMESTRALES'!G95 -> 20 | L97: =+J97*K97 -> 4500
A98: 87 | C98: ='NECESIDADES TRIMESTRALES'!E96 -> FRESAS P/ODONTOLOGIA; MATERIAL: PIEDRA DE DIAMANTE, NUMERO: SIN, LARGO: STANDAR, TIPO: TRONCOC CORTA GR ULTRA FINO FG | H98: NO | I98: ='NECESIDADES TRIMESTRALES'!F96 -> UNIDAD | J98: ='NECESIDADES TRIMESTRALES'!H96 -> 225 | K98: ='NECESIDADES TRIMESTRALES'!G96 -> 20 | L98: =+J98*K98 -> 4500 | M98: =+J98*K98 -> 4500
A99: 88 | C99: ='NECESIDADES TRIMESTRALES'!E97 -> FRESAS P/ODONTOLOGIA; MATERIAL: PIEDRA DE DIAMANTE, NUMERO: SIN, LARGO: STANDAR, TIPO: TRONCOC LARGA GR ULTRA FINO FG | H99: NO | I99: ='NECESIDADES TRIMESTRALES'!F97 -> UNIDAD | J99: ='NECESIDADES TRIMESTRALES'!H97 -> 225 | K99: ='NECESIDADES TRIMESTRALES'!G97 -> 20 | L99: =+J99*K99 -> 4500 | M99: =+J99*K99 -> 4500
A100: 89 | C100: ='NECESIDADES TRIMESTRALES'!E98 -> FRESAS P/ODONTOLOGIA; MATERIAL: PIEDRA DE DIAMANTE, NUMERO: SIN, LARGO: STANDAR, TIPO: TRONCOCON LARG GRUES FG | H100: NO | I100: ='NECESIDADES TRIMESTRALES'!F98 -> UNIDAD | J100: ='NECESIDADES TRIMESTRALES'!H98 -> 225 | K100: ='NECESIDADES TRIMESTRALES'!G98 -> 20 | L100: =+J100*K100 -> 4500 | M100: =+J100*K100 -> 4500
A101: 90 | C101: ='NECESIDADES TRIMESTRALES'!E99 -> FRESERO P/ODONTOLOGIA, DESCARTABLE: NO, PRESENTACION: UNIDAD | H101: NO | I101: ='NECESIDADES TRIMESTRALES'!F99 -> UNIDAD | J101: ='NECESIDADES TRIMESTRALES'!H99 -> 1290 | K101: ='NECESIDADES TRIMESTRALES'!G99 -> 10 | L101: =+J101*K101 -> 12900 | M101: =+J101*K101 -> 12900
A102: 91 | C102: ='NECESIDADES TRIMESTRALES'!E100 -> GOMAS BLANCAS P/PULIDO, DESCARTABLE: NO, PRESENTACION: UNIDAD | H102: NO | I102: ='NECESIDADES TRIMESTRALES'!F100 -> UNIDAD | J102: ='NECESIDADES TRIMESTRALES'!H100 -> 278.45 | K102: ='NECESIDADES TRIMESTRALES'!G100 -> 80 | L102: =+J102*K102 -> 22276 | M102: =+J102*K102 -> 22276
A103: 92 | C103: ='NECESIDADES TRIMESTRALES'!E101 -> HOJA DE SIERRA PLANA; DESCARTABLE: SI, PRESENTACION: UNIDAD | H103: NO | I103: ='NECESIDADES TRIMESTRALES'!F101 -> UNIDAD | J103: ='NECESIDADES TRIMESTRALES'!H101 -> 290 | K103: ='NECESIDADES TRIMESTRALES'!G101 -> 20 | L103: =+J103*K103 -> 5800 | M103: =+J103*K103 -> 5800
...

Sheet APG ODONTOLOGIA
A1: EJERCICIO: | D1: 2021 | P1: AUTORIZACION PARA GASTAR
A4: JURISDICCIÓN: | G4: ='NOTA DE PEDIDO'!D3 -> 040 - Ministerio de Salud
A5: SAF: | G5: ='NOTA DE PEDIDO'!D4 -> 011 - Direccion Provincial de Administración - Ministerio de Salud
A6: UNIDAD EJECUTORA: | G6: ='NOTA DE PEDIDO'!D5 -> 470 - DIRECCION PROVINCIAL DE ODONTOLOGIA
A7: DEPENDENCIA SOLICITANTE: | G7: ='NOTA DE PEDIDO'!D6 -> 470 - DIRECCION PROVINCIAL DE ODONTOLOGIA
A8: AUTORIZACIÓN:
A9: Señor Jefe de Servicio Administrativo Financiero:
A10: Autorizo la realización de los trámites correspondientes, a fin de proveer a este Organismo los bienes que se detallan en Nota de pedido y Entrega N° 15/2021, afectando la erogación resultante a los créditos presupuestarios aprobados a favor de esta Unidad Ejecutora, conforme al siguiente detalle:
A12: IMPUTACIÓN PRESUPUESTARIA
A13: CÓDIGO | O13: DENOMINACIÓN DE LA PARTIDA PRESUPUESTARIA | Q13: IMPORTE
A14: PR | B14: SB | C14: PY | D14: AC | E14: OB | F14: UG | G14: FIN | H14: FUN | I14: I | J14: P | K14: P | L14: SubP | M14: M | N14: FF
A15: 29 | D15: 1 | F15: 4901 | G15: 3 | H15: 1 | I15: 2 | J15: 5 | K15: 2 | M15: 1 | N15: 1.1 | O15: Productos Farmacéuticos y Medicinales | Q15: ='NECESIDADES TRIMESTRALES'!M163 -> 8647125
A16: 29 | D16: 1 | F16: 4901 | G16: 3 | H16: 1 | I16: 2 | J16: 5 | K16: 9 | M16: 1 | N16: 1.1 | O16: Otro NEP | Q16: ='NECESIDADES TRIMESTRALES'!O163 -> 412650
A17: 29 | D17: 1 | F17: 4901 | G17: 3 | H17: 1 | I17: 2 | J17: 6 | K17: 5 | M17: 1 | N17: 1.1 | O17: Cemento, cal y yeso | Q17: ='NECESIDADES TRIMESTRALES'!N163 -> 191500
A18: 29 | D18: 1 | F18: 4901 | G18: 3 | H18: 1 | I18: 2 | J18: 9 | K18: 5 | M18: 1 | N18: 1.1 | O18: Utiles menores medicos, quirurgicos y de laboratorio | Q18: ='NECESIDADES TRIMESTRALES'!L163 -> 6658729.8
A23: TOTAL DE PESOS: QUINCE MILLONES NOVECIENTOS DIEZ MIL CUATRO CON 80/100.- | Q23: =SUM(Q15:Q22) -> 15910005
A25: JUSTIFICACIÓN:
A26: ='NOTA DE PEDIDO'!D8 -> Adquisicion del RUBRO INSUMOS DE ODONTOLOGIA
