Workbook

Sheet Necesidades Trimestrales
A2: Pedido de Necesidades Trimestrales
A4: JURISDICCION: | C4: 12 -Ministerio de Gobierno, Justicia y Derechos Humanos.
A5: SAF N°: | C5: 06 - Secretaria de Gestion Administrativa del Ministerio de Gobierno, Justicia y Derechos Humanos
A6: EJERCICIO: | C6: 2022
A7: TRIMESTRE: | C7: 2do. TRIMESTRE
A9: ID | B9: CODIGO ITEM | C9: RUBRO DE COMPRA | D9: I.P.P. | E9: DESCRIPCION | F9: UNIDAD DE MEDIDA | G9: CANTIDAD | H9: PRECIO UNITARIO ESTIMADO | I9: IMPORTE TOTAL ESTIMADO
A10: 1 | B10: 2.9.2-261.14 | C10: LIBRERÍA | D10: =+LEFT(B10,5) -> 2.9.2 | E10: ABROCHADORAS DE PAPEL; TIPO: PINZA, P/BROCHES: 10/50, MATERIAL: METALICA, MEDIDA: 10/50 | F10: UNIDAD | G10: 28 | H10: 2300 | I10: =G10*H10 -> 64400
A11: 2 | B11: 2.9.2-261.9 | C11: LIBRERÍA | D11: =+LEFT(B11,5) -> 2.9.2 | E11: ABROCHADORAS DE PAPEL; P/BROCHES: 21/6 - 21/8, MATERIAL: METALICA, TIPO: DE ESCRITORIO, MEDIDA: 21/6 - 21/8 | F11: UNIDAD | G11: 5 | H11: 2600 | I11: =G11*H11 -> 13000
A12: 3 | B12: 2.9.2-261.25 | C12: LIBRERÍA | D12: =+LEFT(B12,5) -> 2.9.2 | E12: ABROCHADORAS DE PAPEL; TIPO: PINZA, P/BROCHES: 24/6 - 24/8, MATERIAL: METAL, MEDIDA: 24/6 - 24/8 | F12: UNIDAD | G12: 1 | H12: 3000 | I12: =G12*H12 -> 3000
A13: 4 | B13: 2.9.2-261.10 | C13: LIBRERÍA | D13: =+LEFT(B13,5) -> 2.9.2 | E13: ABROCHADORAS DE PAPEL; TIPO: PINZA, P/BROCHES: 64/65, MATERIAL: METALICA, MEDIDA: 64/65 | F13: UNIDAD | G13: 3 | H13: 1500 | I13: =G13*H13 -> 4500
A14: 5 | B14: 2.9.2-291.19 | C14: LIBRERÍA | D14: 2.9.2 | E14: ALMOHADILLAS P/SELLOS; MEDIDA: 8 X 15 Cm, MATERIAL: METAL | F14: UNIDAD | G14: 17 | H14: 800 | I14: =G14*H14 -> 13600
A15: 6 | B15: 2.3.1-928.8 | C15: LIBRERÍA | D15: 2.9.2 | E15: ARANDELAS DE CARTON; DIAMETRO: 1 pulg, PRESENTACION: CAJA X 500 UNIDADES | F15: CAJAS | G15: 3 | H15: 300 | I15: =G15*H15 -> 900
A16: 7 | B16: 2.9.2-1428.31 | C16: LIBRERÍA | D16: 2.9.2 | E16: BANDAS ELASTICAS; DIAMETRO: 5 Cm, PRESENTACION: CAJA DE 1 Kg, ESPESOR: 2 mm | F16: CAJAS | G16: 3 | H16: 1000 | I16: =G16*H16 -> 3000
A17: 8 | B17: 2.9.2-274.3 | C17: LIBRERÍA | D17: 2.9.2 | E17: BIBLIORATOS; ANCHO 80mm - ANILLO 2 Y PALANCA - TAMAÑO OFICIO - MATERIAL CARTON | F17: UNIDAD | G17: 180 | H17: 400 | I17: =G17*H17 -> 72000
A18: 9 | B18: 2.9.2-274.60 | C18: LIBRERÍA | D18: 2.9.2 | E18: BIBLIORATOS; ANCHO: 80 mm, ANILLO: 2, TAMAÑO: A4, MATERIAL: CARTON | F18: UNIDAD | G18: 5 | H18: 350 | I18: =G18*H18 -> 1750
A19: 10 | B19: 2.9.2-262.40 | C19: LIBRERÍA | D19: 2.9.2 | E19: ADHESIVOS P/PAPEL; PRESENTACION: 50 mL, TIPO: SINTETICO TRANS- PARENTE | F19: UNIDAD | G19: 110 | H19: 150 | I19: =G19*H19 -> 16500
A20: 11 | B20: 2.9.2-700.28 | C20: LIBRERÍA | D20: 2.9.2 | E20: BROCHES P/ABROCHADORA; NUMERO: 10/50, PRESENTACION: CAJA X 1000 UNIDADES | F20: CAJAS | G20: 150 | H20: 110 | I20: =G20*H20 -> 16500
A21: 12 | B21: 2.9.2-700.2 | C21: LIBRERÍA | D21: 2.9.2 | E21: BROCHES P/ABROCHADORA; NUMERO: 21/6, PRESENTACION: CAJA X 1000 UNIDADES | F21: CAJAS | G21: 10 | H21: 130 | I21: =G21*H21 -> 1300
A22: 13 | B22: 2.9.2-700.29 | C22: LIBRERÍA | D22: 2.9.2 | E22: BROCHES P/ABROCHADORA; NUMERO: 24/6, PRESENTACION: CAJA X 1000 UNIDADES | F22: CAJAS | G22: 2 | H22: 150 | I22: =G22*H22 -> 300
A23: 14 | B23: 2.9.2-700.22 | C23: LIBRERÍA | D23: 2.9.2 | E23: BROCHES P/ABROCHADORA; NUMERO: 65, PRESENTACION: CAJA X 1000 UNIDADES | F23: CAJAS | G23: 2 | H23: 130 | I23: =G23*H23 -> 260
A24: 15 | B24: 2.9.2-850.206 | C24: LIBRERÍA | D24: 2.9.2 | E24: CAJAS DE ARCHIVO; MATERIAL: PLASTICO CORRUGADO, DIMENSION: 39 X 28 X 12Cm | F24: UNIDAD | G24: 50 | H24: 400 | I24: =G24*H24 -> 20000
A25: 16 | B25: 2.9.2-1510.15 | C25: LIBRERÍA | D25: 2.9.2 | E25: CARPETAS COLGANTES; TIPO: INTERIOR, MATERIAL: CARTULINA, TAMAÑO: OFICIO, SUJECION: GANCHOS EN 4 PUNTAS, VISOR: TRANSPARENTE, COLOR: MARRON, PRESENTACION: CAJA X 50 UN | F25: CAJAS | G25: 14 | H25: 6000 | I25: =G25*H25 -> 84000
... A33: 24 | B33: 2.9.2-660.1 | C33: LIBRERÍA | D33: 2.9.2 | E33: CLIPS P/PAPEL; NUMERO: 3, MATERIAL: METAL, CANT. X CAJA: 100, PRESENTACION: CAJA X 100 | F33: UNIDAD | G33: 20 | H33: 100 | I33: =G33*H33 -> 2000
A34: 25 | B34: 2.3.1-6587.333 | C34: LIBRERÍA | D34: =+LEFT(B34,5) -> 2.3.1 | E34: PAPELES ENCUADERNADOS; CANT. DE HOJAS: 84 HOJAS, TAMAÑO: 21 X 29,7 Cm, TIPO: RAYADO ESPIRALADO, CERTIFICADO FORESTAL (GFS): CON, PORC. FIBRAS RECICLADAS: 0 %, CERT. FIBRA ALTERNATIVA (FCA): SIN | F34: UNIDAD | G34: 10 | H34: 800 | I34: =G34*H34 -> 8000
A35: 26 | B35: 2.3.1-6587.298 | C35: LIBRERÍA | D35: 2.3.1 | E35: PAPELES ENCUADERNADOS; CANT. DE HOJAS: 100, TAMAÑO: 21 X 16 Cm, TIPO: CUADERNO, CERTIFICADO FORESTAL (GFS): CON, PORC. FIBRAS RECICLADAS: 0 %,CERT. FIBRA ALTERNATIVA (FCA): SIN | F35: UNIDAD | G35: 21 | H35: 600 | I35: =G35*H35 -> 12600
A36: 27 | B36: 2.3.1-6587.291 | C36: LIBRERÍA | D36: 2.3.1 | E36: PAPELES ENCUADERNADOS; CANT. DE HOJAS: 120 HOJAS, TAMAÑO: 16 X 21 Cm, TIPO: RAYADO ESPIRALADO, CERTIFICADO FORESTAL (GFS): SIN, PORC. FIBRAS RECICLADAS: SIN VALOR %, CERT. FIBRA ALTERNATIVA (FCA): SIN | F36: UNIDAD | G36: 7 | H36: 950 | I36: =G36*H36 -> 6650
A37: 28 | B37: 2.3.1-6563.1009 | C37: LIBRERÍA | D37: =+LEFT(B37,5) -> 2.3.1 | E37: PAPELES EN HOJA; TIPO DE PAPEL: BLANCO, DIMENSION: OFICIO, GRAMAJE: 80 GR, PRESENTACION: ENVASE X 500 HOJAS, CERTIFICADO FORESTAL (GFS): SIN, PORC. FIBRAS RECICLADAS: 0 %, CERT. FIBRA ALTERNATIVA (FCA): SIN | F37: UNIDAD | G37: 366 | H37: 1100 | I37: =G37*H37 -> 402600
A38: 29 | B38: 2.3.1-6563.968 | C38: LIBRERÍA | D38: =+LEFT(B38,5) -> 2.3.1 | E38: PAPELES EN HOJA; TIPO DE PAPEL: EXTRA BLANCO, DIMENSION: A4, GRAMAJE: 80 GR, PRESENTACION: RESMA X 500 HOJAS, CERTIFICADO FORESTAL (GFS): SIN, PORC. FIBRAS RECICLADAS: 0 %, CERT. FIBRA ALTERNATIVA (FCA): CON | F38: UNIDAD | G38: 466 | H38: 900 | I38: =G38*H38 -> 419400
A39: 30 | B39: 2.9.2-1358.354 | C39: LIBRERÍA | D39: =+LEFT(B39,5) -> 2.9.2 | E39: CARPETAS; MATERIAL PLASTICO - TAMAÑO OFICIO. | F39: UNIDAD | G39: 50 | H39: 80 | I39: =G39*H39 -> 4000
A40: 31 | B40: 2.9.2-1358.353 | C40: LIBRERÍA | D40: =+LEFT(B40,5) -> 2.9.2 | E40: CARPETAS; MATERIAL PLASTICO - TAMAÑO A4. | F40: UNIDAD | G40: 10 | H40: 70 | I40: =G40*H40 -> 700
A41: 32 | B41: 2.9.2-866.4 | C41: LIBRERÍA | D41: =+LEFT(B41,5) -> 2.9.2 | E41: MAQUINAS SACABROCHES; EXTRACTOR: ACERO INOXIDABLE, MATERIAL: PLASTICO | F41: UNIDAD | G41: 27 | H41: 80 | I41: =G41*H41 -> 2160
A42: 33 | B42: 2.9.2-758.8 | C42: LIBRERÍA | D42: =+LEFT(B42,5) -> 2.9.2 | E42: TIJERAS P/CORTAR PAPELES; CUCHILLA: PUNTIAGUDAS, MATERIAL: ACERO BRUÑIDO, MANGO: PLASTICO, LONG.DE CUERPO: 17 Cm | F42: UNIDAD | G42: 25 | H42: 250 | I42: =G42*H42 -> 6250
A43: 34 | B43: 2.9.2-1611.22 | C43: LIBRERÍA | D43: 2.9.2. | E43: FOLIOS TRANSPARENTES; TAMAÑO: OFICIO, PERFORACIONES: 11, MATERIAL: POLIPROPILENO | F43: UNIDAD | G43: 800 | H43: 15 | I43: =G43*H43 -> 12000
A44: 35 | B44: 2.9.2-1611.23 | C44: LIBRERÍA | D44: 2.9.2 | E44: FOLIOS TRANSPARENTES; TAMAÑO: A4, PERFORACIONES: 11, MATERIAL: POLIPROPILENO | F44: UNIDAD | G44: 200 | H44: 15 | I44: =G44*H44 -> 3000
A45: 36 | B45: 2.9.2-848.20 | C45: LIBRERÍA | D45: =+LEFT(B45,5) -> 2.9.2 | E45: LAPIZ; TIPO: 2HB, COLOR: NEGRO | F45: UNIDAD | G45: 44 | H45: 30 | I45: =G45*H45 -> 1320
A46: 37 | B46: 2.9.2-698.4 | C46: LIBRERÍA | D46: =+LEFT(B46,5) -> 2.9.2 | E46: ALMOHADILLAS MOJADEDOS; MATERIAL TAPA: PLASTICO, MEDIDA: D.7.5 Cm, FORMA: REDONDA | F46: UNIDAD | G46: 10 | H46: 150 | I46: =G46*H46 -> 1500
A47: 38 | B47: 2.9.2-317.32 | C47: LIBRERÍA | D47: =+LEFT(B47,5) -> 2.9.2 | E47: BOLIGRAFOS; TRAZO: 0,8 mm. | F47: UNIDAD | G47: 275 | H47: 65 | I47: =G47*H47 -> 17875
A48: 39 | B48: 2.9.2-317.32 | C48: LIBRERÍA | D48: =+LEFT(B48,5) -> 2.9.2 | E48: BOLIGRAFOS; TRAZO: 0,8 mm. | F48: UNIDAD | G48: 245 | H48: 65 | I48: =G48*H48 -> 15925
A49: 40 | B49: 2.9.2-317.5 | C49: LIBRERÍA | D49: =+LEFT(B49,5) -> 2.9.2 | E49: BOLIGRAFOS; TRAZO 1,0mm | F49: UNIDAD | G49: 525 | H49: 65 | I49: =G49*H49 -> 34125
A50: 41 | B50: 2.9.2-317.5 | C50: LIBRERÍA | D50: =+LEFT(B50,5) -> 2.9.2 | E50: BOLIGRAFOS; TRAZO 1,0mm | F50: UNIDAD | G50: 325 | H50: 65 | I50: =G50*H50 -> 21125
...

Sheet  NotaPedido
A1: NOTA DE PEDIDO
F2: N° | G2: 25/2022
A4: JURISDICCIÓN: | C4: ='Necesidades Trimestrales'!C4 -> 12 -Ministerio de Gobierno, Justicia y Derechos Humanos.
A5: SAF: | C5: ='Necesidades Trimestrales'!C5 -> 06 - Secretaria de Gestion Administrativa del Ministerio de Gobierno, Justicia y Derechos Humanos
A6: UNIDAD EJECUTORA: | C6: Ministerio de Gobierno, Justicia y Derechos Humanos.
A7: DEPENDENCIA SOLICITANTE: | C7: Ministerio de Gob. J. y D.H.- Secretaria de la Mujer, Generos y Diversidad- Direc. Prov. De Accion Coop. Y Mutuales- Direccion Prov. de Derechos Humanos-Dirección de Justicia- Direcc. Prov. Del Registro Civil- Direcc. Insp. Personas Juridicas- Secretaria de Asuntos Municipales.
A8: PERIODO UTILIZACIÓN: | C8: 2022 - 2do Trimestre
A9: OBJETO: | C9: ADQ. DE ELEMTOS DE LIBRERIA DESTINADOS A LAS DISTINTAS DEPENDENCIAS DEL MINISTERIO DE GOBIERNO JUSTICIA Y DERECHOS HUMANOS, PARA EL 2do TRIMESTRE DEL AÑO 2022.
A11: Ítem | B11: Codigo Item | C11: DESCRIPCIÓN | D11: Adjunta Detalle Técnico | E11: Unidad Medida | F11: Precio Unitario Estimado | G11: Cantidad Solicitada
A13: 1 | B13: ='Necesidades Trimestrales'!B10 -> 2.9.2-261.14 | C13: ='Necesidades Trimestrales'!E10 -> ABROCHADORAS DE PAPEL; TIPO: PINZA, P/BROCHES: 10/50, MATERIAL: METALICA, MEDIDA: 10/50 | D13: NO | E13: ='Necesidades Trimestrales'!F10 -> UNIDAD | F13: ='Necesidades Trimestrales'!H10 -> 2300 | G13: ='Necesidades Trimestrales'!G10 -> 28
A14: 2 | B14: ='Necesidades Trimestrales'!B11 -> 2.9.2-261.9 | C14: ='Necesidades Trimestrales'!E11 -> ABROCHADORAS DE PAPEL; P/BROCHES: 21/6 - 21/8, MATERIAL: METALICA, TIPO: DE ESCRITORIO, MEDIDA: 21/6 - 21/8 | D14: NO | E14: ='Necesidades Trimestrales'!F11 -> UNIDAD | F14: ='Necesidades Trimestrales'!H11 -> 2600 | G14: ='Necesidades Trimestrales'!G11 -> 5
A15: 3 | B15: ='Necesidades Trimestrales'!B12 -> 2.9.2-261.25 | C15: ='Necesidades Trimestrales'!E12 -> ABROCHADORAS DE PAPEL; TIPO: PINZA, P/BROCHES: 24/6 - 24/8, MATERIAL: METAL, MEDIDA: 24/6 - 24/8 | D15: NO | E15: ='Necesidades Trimestrales'!F12 -> UNIDAD | F15: ='Necesidades Trimestrales'!H12 -> 3000 | G15: ='Necesidades Trimestrales'!G12 -> 1
A16: 4 | B16: ='Necesidades Trimestrales'!B13 -> 2.9.2-261.10 | C16: ='Necesidades Trimestrales'!E13 -> ABROCHADORAS DE PAPEL; TIPO: PINZA, P/BROCHES: 64/65, MATERIAL: METALICA, MEDIDA: 64/65 | D16: NO | E16: ='Necesidades Trimestrales'!F13 -> UNIDAD | F16: ='Necesidades Trimestrales'!H13 -> 1500 | G16: ='Necesidades Trimestrales'!G13 -> 3
A17: 5 | B17: ='Necesidades Trimestrales'!B14 -> 2.9.2-291.19 | C17: ='Necesidades Trimestrales'!E14 -> ALMOHADILLAS P/SELLOS; MEDIDA: 8 X 15 Cm, MATERIAL: METAL | D17: NO | E17: ='Necesidades Trimestrales'!F14 -> UNIDAD | F17: ='Necesidades Trimestrales'!H14 -> 800 | G17: ='Necesidades Trimestrales'!G14 -> 17
A18: 6 | B18: ='Necesidades Trimestrales'!B15 -> 2.3.1-928.8 | C18: ='Necesidades Trimestrales'!E15 -> ARANDELAS DE CARTON; DIAMETRO: 1 pulg, PRESENTACION: CAJA X 500 UNIDADES | D18: NO | E18: ='Necesidades Trimestrales'!F15 -> CAJAS | F18: ='Necesidades Trimestrales'!H15 -> 300 | G18: ='Necesidades Trimestrales'!G15 -> 3
A19: 7 | B19: ='Necesidades Trimestrales'!B16 -> 2.9.2-1428.31 | C19: ='Necesidades Trimestrales'!E16 -> BANDAS ELASTICAS; DIAMETRO: 5 Cm, PRESENTACION: CAJA DE 1 Kg, ESPESOR: 2 mm | D19: NO | E19: ='Necesidades Trimestrales'!F16 -> CAJAS | F19: ='Necesidades Trimestrales'!H16 -> 1000 | G19: ='Necesidades Trimestrales'!G16 -> 3
A20: 8 | B20: ='Necesidades Trimestrales'!B17 -> 2.9.2-274.3 | C20: ='Necesidades Trimestrales'!E17 -> BIBLIORATOS; ANCHO 80mm - ANILLO 2 Y PALANCA - TAMAÑO OFICIO - MATERIAL CARTON | D20: NO | E20: ='Necesidades Trimestrales'!F17 -> UNIDAD | F20: ='Necesidades Trimestrales'!H17 -> 400 | G20: ='Necesidades Trimestrales'!G17 -> 180
A21: 9 | B21: ='Necesidades Trimestrales'!B18 -> 2.9.2-274.60 | C21: ='Necesidades Trimestrales'!E18 -> BIBLIORATOS; ANCHO: 80 mm, ANILLO: 2, TAMAÑO: A4, MATERIAL: CARTON | D21: NO | E21: ='Necesidades Trimestrales'!F18 -> UNIDAD | F21: ='Necesidades Trimestrales'!H18 -> 350 | G21: ='Necesidades Trimestrales'!G18 -> 5
A22: 10 | B22: ='Necesidades Trimestrales'!B19 -> 2.9.2-262.40 | C22: ='Necesidades Trimestrales'!E19 -> ADHESIVOS P/PAPEL; PRESENTACION: 50 mL, TIPO: SINTETICO TRANS- PARENTE | D22: NO | E22: ='Necesidades Trimestrales'!F19 -> UNIDAD | F22: ='Necesidades Trimestrales'!H19 -> 150 | G22: ='Necesidades Trimestrales'!G19 -> 110
A23: 11 | B23: ='Necesidades Trimestrales'!B20 -> 2.9.2-700.28 | C23: ='Necesidades Trimestrales'!E20 -> BROCHES P/ABROCHADORA; NUMERO: 10/50, PRESENTACION: CAJA X 1000 UNIDADES | D23: NO | E23: ='Necesidades Trimestrales'!F20 -> CAJAS | F23: ='Necesidades Trimestrales'!H20 -> 110 | G23: ='Necesidades Trimestrales'!G20 -> 150
A24: 12 | B24: ='Necesidades Trimestrales'!B21 -> 2.9.2-700.2 | C24: ='Necesidades Trimestrales'!E21 -> BROCHES P/ABROCHADORA; NUMERO: 21/6, PRESENTACION: CAJA X 1000 UNIDADES | D24: NO | E24: ='Necesidades Trimestrales'!F21 -> CAJAS | F24: ='Necesidades Trimestrales'!H21 -> 130 | G24: ='Necesidades Trimestrales'!G21 -> 10
... A79: 67 | B79: ='Necesidades Trimestrales'!B76 -> 2.9.2-1616.69 | C79: ='Necesidades Trimestrales'!E76 -> MARCADORES; TIPO: AL SOLVENTE, TRAZO: GRUESO, PUNTA: REDONDA, COLOR: AZUL, RECARGABLE: SI | D79: NO | E79: ='Necesidades Trimestrales'!F76 -> UNIDAD | F79: ='Necesidades Trimestrales'!H76 -> 200 | G79: ='Necesidades Trimestrales'!G76 -> 48
A82: Costo total estimado: Pesos Un Millon Seiscientos Ochenta Mil Novecientos Ochenta con 00/100.- | F82: 1680980

Sheet APG
A1: EJERCICIO: | D1: ='Necesidades Trimestrales'!C6 -> 2022 | P1: AUTORIZACION PARA GASTAR
A4: JURISDICCIÓN: | G4: =' NotaPedido'!C4 -> 12 -Ministerio de Gobierno, Justicia y Derechos Humanos.
A5: SAF: | G5: =' NotaPedido'!C5 -> 06 - Secretaria de Gestion Administrativa del Ministerio de Gobierno, Justicia y Derechos Humanos
A6: UNIDAD EJECUTORA: | G6: =' NotaPedido'!C6 -> Ministerio de Gobierno, Justicia y Derechos Humanos.
A7: DEPENDENCIA SOLICITANTE: | G7: Ministerio de Gob. J. y D.H.- Secretaria de la Mujer, Generos y Diversidad- Direc. Prov. De Accion Coop. Y Mutuales- Direccion Prov. de Derechos Humanos-Dirección de Justicia- Direcc. Prov. Del Registro Civil- Direcc. Insp. Personas Juridicas- Secretaria de Asuntos Municipales.
A8: AUTORIZACIÓN:
A9: Señor Jefe de Servicio Administrativo Financiero:
A10: ="Autorizo la realización de los trámites correspondientes, a fin de proveer a este Organismo los bienes y/o servicios que se detallan en Nota de Pedido N° " & ' NotaPedido'!G2&", afectando la erogación resultante a los créditos presupuestarios aprobados a favor de esta Unidad Ejecutora, conforme al siguiente detalle:" -> Autorizo la realización de los trámites correspondientes, a fin de proveer a este Organismo los bienes y/o servicios que se detallan en Nota de Pedido N° 25/2022, afectando la erogación resultante a los créditos presupuestarios aprobados a favor de esta Unidad Ejecutora, conforme al siguiente detalle:
A12: IMPUTACIÓN PRESUPUESTARIA
A13: CÓDIGO | O13: DENOMINACIÓN DE LA PARTIDA PRESUPUESTARIA | Q13: IMPORTE
A14: PR | B14: SB | C14: PY | D14: AC | E14: OB | F14: UG | G14: FIN | H14: FUN | I14: I | J14: P | K14: P | L14: SubP | M14: M | N14: FF
A15: 1 | B15: 0 | C15: 0 | D15: 1 | E15: 0 | F15: 4901 | G15: 1 | H15: 3 | I15: 2 | J15: 3 | K15: 4 | L15: 0 | M15: 1 | N15: 111 | O15: Productos de Papel y Cartón | Q15: 3250
A16: 1 | B16: 0 | C16: 0 | D16: 1 | E16: 0 | F16: 4901 | G16: 1 | H16: 3 | I16: 2 | J16: 9 | K16: 2 | L16: 0 | M16: 1 | N16: 1.1 | O16: Utiles de Escritorio, Oficina y Enseñanza. | Q16: 27015
A17: 5 | B17: 0 | C17: 0 | D17: 1 | E17: 0 | F17: 4901 | G17: 3 | H17: 2 | I17: 2 | J17: 3 | K17: 1 | L17: 0 | M17: 1 | N17: 1.1 | O17: Papel de Escritorio y Cartón | Q17: 22400
A18: 5 | B18: 0 | C18: 0 | D18: 1 | E18: 0 | F18: 4901 | G18: 3 | H18: 2 | I18: 2 | J18: 3 | K18: 4 | L18: 0 | M18: 1 | N18: 1.1 | O18: Productos de Papel y Cartón | Q18: 900
A19: 5 | B19: 0 | C19: 0 | D19: 1 | E19: 0 | F19: 4901 | G19: 3 | H19: 2 | I19: 2 | J19: 9 | K19: 2 | L19: 0 | M19: 1 | N19: 1.1 | O19: Utiles de Escritorio, Oficina y Enseñanza. | Q19: 24320
A20: 6 | B20: 0 | C20: 0 | D20: 1 | E20: 0 | F20: 4901 | G20: 3 | H20: 2 | I20: 2 | J20: 3 | K20: 1 | L20: 0 | M20: 1 | N20: 1.1 | O20: Papel de Escritorio y Cartón | Q20: 20000
A21: 6 | B21: 0 | C21: 0 | D21: 1 | E21: 0 | F21: 4901 | G21: 3 | H21: 2 | I21: 2 | J21: 9 | K21: 2 | L21: 0 | M21: 1 | N21: 1.1 | O21: Utiles de Escritorio, Oficina y Enseñanza. | Q21: 13400
A22: 18 | B22: 0 | C22: 0 | D22: 1 | E22: 0 | F22: 4901 | G22: 3 | H22: 2 | I22: 2 | J22: 3 | K22: 1 | L22: 0 | M22: 1 | N22: 1.1 | O22: Papel de Escritorio y Cartón | Q22: 48900
A23: 18 | B23: 0 | C23: 0 | D23: 1 | E23: 0 | F23: 4901 | G23: 3 | H23: 2 | I23: 2 | J23: 9 | K23: 2 | L23: 0 | M23: 1 | N23: 1.1 | O23: Utiles de Escritorio, Oficina y Enseñanza. | Q23: 93400
A24: 20 | B24: 0 | C24: 0 | D24: 1 | E24: 0 | F24: 4901 | G24: 3 | H24: 6 | I24: 2 | J24: 3 | K24: 1 | L24: 0 | M24: 1 | N24: 1.1 | O24: Papel de Escritorio y Cartón | Q24: 26650
A25: 20 | B25: 0 | C25: 0 | D25: 1 | E25: 0 | F25: 4901 | G25: 3 | H25: 6 | I25: 2 | J25: 9 | K25: 2 | L25: 0 | M25: 1 | N25: 1.1 | O25: Utiles de Escritorio, Oficina y Enseñanza. | Q25: 6580
A26: 22 | B26: 0 | C26: 0 | D26: 1 | E26: 0 | F26: 4901 | G26: 1 | H26: 9 | I26: 2 | J26: 3 | K26: 1 | L26: 0 | M26: 1 | N26: 1.1 | O26: Papel de Escritorio y Cartón | Q26: 721000
A27: 22 | B27: 0 | C27: 0 | D27: 1 | E27: 0 | F27: 4901 | G27: 1 | H27: 9 | I27: 2 | J27: 3 | K27: 4 | L27: 0 | M27: 1 | N27: 1.1 | O27: Productos de Papel y Cartón | Q27: 6250
... A33: 27 | B33: 0 | C33: 0 | D33: 1 | E33: 0 | F33: 4901 | G33: 1 | H33: 5 | I33: 2 | J33: 9 | K33: 2 | L33: 0 | M33: 1 | N33: 1.1 | O33: Utiles de Escritorio, Oficina y Enseñanza. | Q33: 26275
A36: TOTAL DE PESOS: Un Millon Seiscientos Ochenta Mil Novecientos Ochenta con 00/100.- | Q36: =SUM(Q15:Q35) -> 1680980
A38: JUSTIFICACIÓN:
A39: =' NotaPedido'!C9 -> ADQ. DE ELEMTOS DE LIBRERIA DESTINADOS A LAS DISTINTAS DEPENDENCIAS DEL MINISTERIO DE GOBIERNO JUSTICIA Y DERECHOS HUMANOS, PARA EL 2do TRIMESTRE DEL AÑO 2022.
A41: OBSERVACIONES:
