Workbook

Sheet SAF 011
A1: 2022
B2: Pedido de Necesidades Trimestrales
A4: JURISDICCION: | C4: 040 - MINISTERIO DE SALUD
A5: SAF N°: | C5: 011 - DIRECCION PROVINCIAL DE ADMINISTRACION - MINISTERIO DE SALUD
A6: EJERCICIO: | C6: 2022
A7: TRIMESTRE: | C7: PRIMERO
A9: ID | B9: CODIGO ITEM | C9: RUBRO DE COMPRA | D9: I.P.P. | E9: DESCRIPCION | F9: UNIDAD DE MEDIDA | G9: SECRETARIA DE ADMINISTRACION | H9: TOTAL S.A. | I9: SMPyPS | J9: TOTAL SMPyPS | K9: DIR. LAB. CENTRAL | L9: TOTAL DE LAB CENTRAL | M9: BCO DE SANGRE | N9: TOTAL BANCO DE SANGRE | O9: APS | P9: TOTAL A.P.S. | Q9: DIR DE CANCER | R9: TOTAL DE DIR DE CANCER | S9: FARMACIA | T9: TOTAL FARMACIA | U9: ODONTOLOGIA | V9: TOTAL DE ODONTOLOG | W9: SAME | X9: TOTAL SAME | Y9: HPTAL MALBRAN | Z9: TOTAL HPTAL MALBRAN | AA9: MATERNIDAD E INFANCIA | AB9: TOTAL MATERNIDAD E INFANCIA | AC9: SASP | AD9: TOTAL SASP | AE9: SALUD Y MEDIO AMBIENTE | AF9: TOTAL SALUD Y MEDIO AMBIENTE | AG9: VECTORES Y ZOONOSIS | AH9: TOTAL DE VECT Y ZOON | AI9: CRONICAS | AJ9: TOTAL CRONICAS | AK9: CUR | AL9: TOTAL CUR | AM9: SPyGS | AN9: TOTAL SPyGS | AO9: SALUD MENTAL | AP9: TOTAL SALUD MENTAL | AQ9: AREAS Y DPAS | AR9: TOTAL DPAS | AS9: EPIDEMIOLOGIA | AT9: TOTAL EPIDEMIOLOGIA | AU9: MS | AV9: TOTAL MS | AW9: CANTIDAD TOTAL | AX9: PRECIO UNITARIO ESTIMADO | AY9: IMPORTE TOTAL ESTIMADO | AZ9: ESPECIFICACION TECNICA
A10: 1 | B10: 2.4.4-6818.986 | C10: REPUESTOS | D10: 2.4.4 | E10: NEUMATICOS; VEHICULO: AMBULANCIA/FURGON/MINIBUS, CONSTRUCCION: RADIAL, ARMADO: S/CAMARA, MEDIDA: 205/75R16 | F10: UNIDAD | N10: =+M10*AX10 -> 0 | W10: 20 | X10: =+W10*AX10 -> 840000 | AF10: =+AE10*AX10 -> 0 | AG10: 3 | AH10: =+AG10*AX10 -> 126000 | AL10: =+AK10*AX10 -> 0 | AN10: =+AM10*AX10 -> 0 | AP10: =+AO10*AX10 -> 0 | AQ10: 69 | AR10: =+AQ10*AX10 -> 2898000 | AV10: =+AU10*AX10 -> 0 | AW10: =+AQ10+AO10+AM10+AK10+AI10+AG10+AE10+AC10+AA10+Y10+W10+U10+S10+Q10+O10+M10+K10+I10+AS10+G10+AU10 -> 92 | AX10: 42000 | AY10: =+AW10*AX10 -> 3864000
A11: 2 | B11: 2.4.4-6818.801 | C11: REPUESTOS | D11: 2.4.4 | E11: NEUMATICOS; VEHICULO: CAMIONETA, CONSTRUCCION: CON CLAVOS, ARMADO: S/CAMARA, MEDIDA: 265/70R16 | F11: UNIDAD | AQ11: 8 | AR11: =+AQ11*AX11 -> 336000 | AW11: =+AQ11+AO11+AM11+AK11+AI11+AG11+AE11+AC11+AA11+Y11+W11+U11+S11+Q11+O11+M11+K11+I11+AS11+G11+AU11 -> 8 | AX11: 42000 | AY11: =+AW11*AX11 -> 336000
A12: 3 | B12: 2.4.4-6818.647 | C12: REPUESTOS | D12: 2.4.4 | E12: NEUMATICOS; VEHICULO: CAMIONETA, CONSTRUCCION: RADIAL, ARMADO: S/CAMARA, MEDIDA: 175/70R14 pulg | F12: UNIDAD | N12: =+M12*AX12 -> 0 | X12: =+W12*AX12 -> 0 | Z12: =+Y12*AX12 -> 0 | AF12: =+AE12*AX12 -> 0 | AH12: =+AG12*AX12 -> 0 | AL12: =+AK12*AX12 -> 0 | AN12: =+AM12*AX12 -> 0 | AP12: =+AO12*AX12 -> 0 | AQ12: 0 | AR12: =+AQ12*AX12 -> 0 | AU12: 5 | AV12: =+AU12*AX12 -> 117500 | AW12: =+AQ12+AO12+AM12+AK12+AI12+AG12+AE12+AC12+AA12+Y12+W12+U12+S12+Q12+O12+M12+K12+I12+AS12+G12+AU12 -> 5 | AX12: 23500 | AY12: =+AW12*AX12 -> 117500
A13: 4 | B13: 2.4.4-6818.59 | C13: REPUESTOS | D13: 2.4.4 | E13: NEUMATICOS; VEHICULO: CAMIONETA, CONSTRUCCION: RADIAL, ARMADO: S/CAMARA, MEDIDA: 195/75R16 | F13: UNIDAD | N13: =+M13*AX13 -> 0 | X13: =+W13*AX13 -> 0 | AE13: 5 | AF13: =+AE13*AX13 -> 223000 | AH13: =+AG13*AX13 -> 0 | AL13: =+AK13*AX13 -> 0 | AN13: =+AM13*AX13 -> 0 | AP13: =+AO13*AX13 -> 0 | AQ13: 8 | AR13: =+AQ13*AX13 -> 356800 | AV13: =+AU13*AX13 -> 0 | AW13: =+AQ13+AO13+AM13+AK13+AI13+AG13+AE13+AC13+AA13+Y13+W13+U13+S13+Q13+O13+M13+K13+I13+AS13+G13+AU13 -> 13 | AX13: 44600 | AY13: =+AW13*AX13 -> 579800
A14: 5 | B14: 2.4.4-6818.52 | C14: REPUESTOS | D14: 2.4.4 | E14: NEUMATICOS; VEHICULO: CAMIONETA, CONSTRUCCION: RADIAL, ARMADO: S/CAMARA, MEDIDA: 215/80R16 | F14: UNIDAD | N14: =+M14*AX14 -> 0 | X14: =+W14*AX14 -> 0 | AF14: =+AE14*AX14 -> 0 | AH14: =+AG14*AX14 -> 0 | AL14: =+AK14*AX14 -> 0 | AN14: =+AM14*AX14 -> 0 | AP14: =+AO14*AX14 -> 0 | AQ14: 20 | AR14: =+AQ14*AX14 -> 828000 | AV14: =+AU14*AX14 -> 0 | AW14: =+AQ14+AO14+AM14+AK14+AI14+AG14+AE14+AC14+AA14+Y14+W14+U14+S14+Q14+O14+M14+K14+I14+AS14+G14+AU14 -> 20 | AX14: 41400 | AY14: =+AW14*AX14 -> 828000
A15: 6 | B15: 2.4.4-6818.885 | C15: REPUESTOS | D15: 2.4.4 | E15: NEUMATICOS; VEHICULO: CAMIONETA, CONSTRUCCION: RADIAL, ARMADO: S/CAMARA, MEDIDA: 225/65R17 | F15: UNIDAD | AQ15: 4 | AR15: =+AQ15*AX15 -> 181600 | AW15: =+AQ15+AO15+AM15+AK15+AI15+AG15+AE15+AC15+AA15+Y15+W15+U15+S15+Q15+O15+M15+K15+I15+AS15+G15+AU15 -> 4 | AX15: 45400 | AY15: =+AW15*AX15 -> 181600
A16: 7 | B16: 2.4.4-6818.989 | C16: REPUESTOS | D16: 2.4.4 | E16: NEUMATICOS; VEHICULO: CAMIONETA, CONSTRUCCION: RADIAL, ARMADO: S/CAMARA, MEDIDA: 225/70 R17 | F16: UNIDAD | N16: =+M16*AX16 -> 0 | X16: =+W16*AX16 -> 0 | AF16: =+AE16*AX16 -> 0 | AH16: =+AG16*AX16 -> 0 | AL16: =+AK16*AX16 -> 0 | AN16: =+AM16*AX16 -> 0 | AP16: =+AO16*AX16 -> 0 | AQ16: 8 | AR16: =+AQ16*AX16 -> 464000 | AV16: =+AU16*AX16 -> 0 | AW16: =+AQ16+AO16+AM16+AK16+AI16+AG16+AE16+AC16+AA16+Y16+W16+U16+S16+Q16+O16+M16+K16+I16+AS16+G16+AU16 -> 8 | AX16: 58000 | AY16: =+AW16*AX16 -> 464000
A17: 8 | B17: 2.4.4-6818.744 | C17: REPUESTOS | D17: 2.4.4 | E17: NEUMATICOS; VEHICULO: CAMIONETA, CONSTRUCCION: RADIAL, ARMADO: S/CAMARA, MEDIDA: 235/70R16 | F17: UNIDAD | AN17: =+AM17*AX17 -> 0 | AP17: =+AO17*AX17 -> 0 | AQ17: 4 | AR17: =+AQ17*AX17 -> 192800 | AV17: =+AU17*AX17 -> 0 | AW17: =+AQ17+AO17+AM17+AK17+AI17+AG17+AE17+AC17+AA17+Y17+W17+U17+S17+Q17+O17+M17+K17+I17+AS17+G17+AU17 -> 4 | AX17: 48200 | AY17: =+AW17*AX17 -> 192800
A18: 9 | B18: 2.4.4-6818.751 | C18: REPUESTOS | D18: 2.4.4 | E18: NEUMATICOS; VEHICULO: CAMIONETA, CONSTRUCCION: RADIAL, ARMADO: S/CAMARA, MEDIDA: 245/65 R17 | F18: UNIDAD | N18: =+M18*AX18 -> 0 | X18: =+W18*AX18 -> 0 | AF18: =+AE18*AX18 -> 0 | AH18: =+AG18*AX18 -> 0 | AL18: =+AK18*AX18 -> 0 | AN18: =+AM18*AX18 -> 0 | AP18: =+AO18*AX18 -> 0 | AQ18: 20 | AR18: =+AQ18*AX18 -> 1039000 | AV18: =+AU18*AX18 -> 0 | AW18: =+AQ18+AO18+AM18+AK18+AI18+AG18+AE18+AC18+AA18+Y18+W18+U18+S18+Q18+O18+M18+K18+I18+AS18+G18+AU18 -> 20 | AX18: 51950 | AY18: =+AW18*AX18 -> 1039000
A19: 10 | B19: 2.4.4-6818.530 | C19: REPUESTOS | D19: 2.4.4 | E19: NEUMATICOS; VEHICULO: CAMIONETA, CONSTRUCCION: RADIAL, ARMADO: S/CAMARA, MEDIDA: 245/70R16 | F19: UNIDAD | N19: =+M19*AX19 -> 0 | X19: =+W19*AX19 -> 0 | AC19: 4 | AD19: =+AC19*AX19 -> 177000 | AF19: =+AE19*AX19 -> 0 | AH19: =+AG19*AX19 -> 0 | AL19: =+AK19*AX19 -> 0 | AN19: =+AM19*AX19 -> 0 | AP19: =+AO19*AX19 -> 0 | AQ19: 0 | AR19: =+AQ19*AX19 -> 0 | AV19: =+AU19*AX19 -> 0 | AW19: =+AQ19+AO19+AM19+AK19+AI19+AG19+AE19+AC19+AA19+Y19+W19+U19+S19+Q19+O19+M19+K19+I19+AS19+G19+AU19 -> 4 | AX19: 44250 | AY19: =+AW19*AX19 -> 177000
A20: 11 | B20: 2.4.4-6818.890 | C20: REPUESTOS | D20: 2.4.4 | E20: NEUMATICOS; VEHICULO: CAMIONETA, CONSTRUCCION: RADIAL, ARMADO: S/CAMARA, MEDIDA: 265/60R18 | F20: UNIDAD | AN20: =+AM20*AX20 -> 0 | AP20: =+AO20*AX20 -> 0 | AQ20: 0 | AR20: =+AQ20*AX20 -> 0 | AU20: 3 | AV20: =+AU20*AX20 -> 192000 | AW20: =+AQ20+AO20+AM20+AK20+AI20+AG20+AE20+AC20+AA20+Y20+W20+U20+S20+Q20+O20+M20+K20+I20+AS20+G20+AU20 -> 3 | AX20: 64000 | AY20: =+AW20*AX20 -> 192000
A21: 12 | B21: 2.4.4-6818.723 | C21: REPUESTOS | D21: 2.4.4 | E21: NEUMATICOS; VEHICULO: CAMIONETA, CONSTRUCCION: RADIAL, ARMADO: SIN CAMARA, MEDIDA: 185/65R15 | F21: UNIDAD | AQ21: 8 | AR21: =+AQ21*AX21 -> 235200 | AW21: =+AQ21+AO21+AM21+AK21+AI21+AG21+AE21+AC21+AA21+Y21+W21+U21+S21+Q21+O21+M21+K21+I21+AS21+G21+AU21 -> 8 | AX21: 29400 | AY21: =+AW21*AX21 -> 235200
A22: 13 | B22: 2.4.4-6818.48 | C22: REPUESTOS | D22: 2.4.4 | E22: NEUMATICOS; VEHICULO: CAMIONETA, CONSTRUCCION: RADIAL, MEDIDA: 235/75R15, ARMADO: S/CAMARA | F22: UNIDAD | N22: =+M22*AX22 -> 0 | O22: 2 | P22: =+O22*AX22 -> 76600 | X22: =+W22*AX22 -> 0 | AF22: =+AE22*AX22 -> 0 | AG22: 4 | AH22: =+AG22*AX22 -> 153200 | AL22: =+AK22*AX22 -> 0 | AN22: =+AM22*AX22 -> 0 | AP22: =+AO22*AX22 -> 0 | AQ22: 16 | AR22: =+AQ22*AX22 -> 612800 | AS22: 3 | AT22: =+AS22*AX22 -> 114900 | AV22: =+AU22*AX22 -> 0 | AW22: =+AQ22+AO22+AM22+AK22+AI22+AG22+AE22+AC22+AA22+Y22+W22+U22+S22+Q22+O22+M22+K22+I22+AS22+G22+AU22 -> 25 | AX22: 38300 | AY22: =+AW22*AX22 -> 957500
A23: 14 | B23: 2.4.4-6818.851 | C23: REPUESTOS | D23: 2.4.4 | E23: NEUMATICOS; VEHICULO: MINIBUS, CONSTRUCCION: CONVENCIONAL, ARMADO: S/CAMARA, MEDIDA: 225/70R15 | F23: UNIDAD | M23: 2 | N23: =+M23*AX23 -> 88200 | X23: =+W23*AX23 -> 0 | AF23: =+AE23*AX23 -> 0 | AH23: =+AG23*AX23 -> 0 | AL23: =+AK23*AX23 -> 0 | AN23: =+AM23*AX23 -> 0 | AP23: =+AO23*AX23 -> 0 | AQ23: 0 | AR23: =+AQ23*AX23 -> 0 | AV23: =+AU23*AX23 -> 0 | AW23: =+AQ23+AO23+AM23+AK23+AI23+AG23+AE23+AC23+AA23+Y23+W23+U23+S23+Q23+O23+M23+K23+I23+AS23+G23+AU23 -> 2 | AX23: 44100 | AY23: =+AW23*AX23 -> 88200
A24: 15 | B24: 2.4.4-6818.993 | C24: REPUESTOS | D24: 2.4.4 | E24: NEUMATICOS; VEHICULO: UTILITARIO, CONSTRUCCION: RADIAL, ARMADO: S/CAMARA, MEDIDA: 225/75-R16C | F24: UNIDAD | N24: =+M24*AX24 -> 0 | X24: =+W24*AX24 -> 0 | AF24: =+AE24*AX24 -> 0 | AH24: =+AG24*AX24 -> 0 | AL24: =+AK24*AX24 -> 0 | AN24: =+AM24*AX24 -> 0 | AP24: =+AO24*AX24 -> 0 | AQ24: 20 | AR24: =+AQ24*AX24 -> 1046000 | AV24: =+AU24*AX24 -> 0 | AW24: =+AQ24+AO24+AM24+AK24+AI24+AG24+AE24+AC24+AA24+Y24+W24+U24+S24+Q24+O24+M24+K24+I24+AS24+G24+AU24 -> 20 | AX24: 52300 | AY24: =+AW24*AX24 -> 1046000
E25: TOTAL RUBRO NEUMATICOS | N25: =SUM(N10:N24) -> 88200 | P25: =SUM(P10:P24) -> 76600 | V25: =+U25*AX25 -> 0 | X25: =SUM(X10:X24) -> 840000 | Z25: =SUM(Z10:Z21) -> 0 | AD25: =SUM(AD10:AD24) -> 177000 | AF25: =SUM(AF10:AF24) -> 223000 | AH25: =SUM(AH10:AH24) -> 279200 | AL25: =SUM(AL10:AL21) -> 0 | AN25: =SUM(AN10:AN21) -> 0 | AR25: =SUM(AR10:AR24) -> 8190200 | AT25: =SUM(AT10:AT24) -> 114900 | AV25: =SUM(AV10:AV24) -> 309500 | AY25: =+SUM(AY10:AY24) -> 10298600
C27: Descripción técnica:
C29: Plazos de entrega | D29: diez (10) dias habiles
C31: Lugar de Entrega: | D31: SECRETARIA DE AMINISTRACION - CHACABUCO N° 169 - en el horario de 8:00hs a 12:00hs de lunes a viernes
C33: Calidad Minima esperada
C35: Mantenimiento | D35: cuarenta y cinco (45) días
C37: Garantia: | D37: seis (6) meses

Sheet ANEXO
A1: DIRECCION PROVINCIAL ASISTENCIA SANITARIA NIVEL I Y II
A3: Area Programatica Nº1
A5: Vehiculo | B5: Dominio | C5: Nº de Motor | D5: Nº Chasis | E5: Año
A6: Renault Master - Ambulancia.- | B6: GEU-277 | C6: G9UA724C030714 | D6: 93YADCUE57J787157 | E6: 2007
A7: Renault Master- Ambulancia.- | B7: GUV-922 | C7: G9UA724C035587 | D7: 93YADCUE58J896449 | E7: 2008
A8: Renault Master-PH3 DCI 120 L1H2 Ambulancia.- | B8: KNI-753 | C8: G9UA754C268409 | D8: 93YADCUE6CJ897389 | E8: 2011
A9: Renault Master PH3 DCI 120 L1H2 - Ambulancia.- | B9: LAD-136 | C9: G9UA754C270571 | D9: 93YADCUE6CJ969873 | E9: 2012
A10: Renault Master MASTER PH3 DCI 120 - Ambulancia.- | B10: LAD-135 | C10: G9UA650C244170 | D10: 93YADC1E6CJ140233 | E10: 2012
A11: Fiat Ducato Amxicargo 2,3 JTD. Ambulancia.- | B11: AA-842-EI | C11: 7250728 | D11: 93W245G84H2160833 | E11: 2016
A12: Toyota Hilux 4x4 c/s DX 2,4 TDI M/T. Ambulancia | B12: AA-793-NE | C12: 2GD-0137533 | D12: 8AJFB8CB5H1550878 | E12: 2017
A13: Renault Master- Ambulancia.- | B13: AE-041-BD | C13: M9TB870C262154 | D13: 93YMAFESCLJ213469 | E13: 2020
A15: Area Programatica Nº2
A17: Vehiculo | B17: Dominio | C17: Nº de Motor | D17: Nº Chasis | E17: Año
A18: Fiat Ducato Maxi cargo 2,3 JTD Furgon. Ambulancia.- | B18: AA-842-EH | C18: 7250726 | D18: 93W245G84H2160832 | E18: 2016
A19: Fiat Ducato Maxi cargo 2,3 JTD Furgon. Ambulancia.- | B19: AA-842-EF | C19: 7250640 | D19: 93W245G84H2160831 | E19: 2016
A20: Fiat Ducato 2,3. Ambulancia.- | B20: NSE-229 | C20: 7166125 | D20: 93W245G74D2109008 | E20: 2014
A21: Renault Master DCI120. Ambulancia - | B21: GUO-325 | C21: G9UA7240035511 | D21: 93YADCUE58J896313 | E21: 2007
A23: Area Programatica Nº3
A25: Vehiculo | B25: Dominio | C25: Nº de Motor | D25: Nº Chasis | E25: Año
A26: Chevrolet S10 2,8 TDI - Camioneta.- | B26: GDD-914 | C26: M1A282868 | D26: 9BG138AJ07C413213 | E26: 2007
A27: Renautl Master 2,5 D - Ambulancia.- | B27: GJC-299 | C27: J9UA724C030522 | D27: 93YADCUE57J787225 | E27: 2007
A28: Fiat Ducato Maxi cargo 2,3. Ambulancia | B28: AA-702-MN | C28: 7251288 | D28: 93W245G74H2161118 | E28: 2016
A29: Ford Transit 2,2 L 125 T350 TA C/AA - Ambulancia.- | B29: MNW-258 | C29: CYRCDTT22471 | D29: WFOXXPTTFDTT22471 | E29: 2013
A30: Chevrolet S10 2,8 T.I- Ambulancia.- | B30: ESH-451 | C30: 40704192268 | D30: 986124AC05C410447 | E30: 2014
A33: Area Programatica Nº4
A35: Vehiculo | B35: Dominio | C35: Nº de Motor | D35: Nº Chasis | E35: Año
A36: Chevrolet S10 2,8 TDI SID 4x2 - Ambulancia.- | B36: GDD-918 | C36: M1A282927 | D36: 9BG1384J07C413214 | E36: 2007
A37: Chevrolet S10 2,8 TDI - Ambulancia.- | B37: ESH-453 | C37: 40704192255 | D37: 9BG124ACOSC410400 | E37: 1999
A38: Ford Transit Furgon - Ambulancia.- | B38: MNW-259 | C38: CYRCDTT23622 | D38: WF0XXPTTFDTT2362 | E38: 2013
A39: Fiat Ducato Maxicargo 2,3 JTD. Ambulancia.- | B39: AA-842-EG | C39: 7250638 | D39: 93W245G84H2160827 | E39: 2016
A40: Renault Master. Ambulancia.- | B40: AD-484-QZ | C40: A4MH737Q004131 | D40: 8A18SRD04KL428948 | E40: 2018
A41: Renault Master. Ambulancia.- | B41: AD-939-YG | C41: H4MH737Q013096 | D41: 8A18SRD04LL935267 | E41: 2018
A44: Area Programatica Nº5
A46: Vehiculo | B46: Dominio | C46: Nº de Motor | D46: Nº Chasis | E46: Año
A47: Fiat Ducato Ambulancia.- | B47: NHW-649 | C47: 7167190 | D47: 93W245G84D2109862 | E47: 2013
A48: Ford Transit 2,2 L Ambulancia.- | B48: MBW-831 | C48: CYRCCTC58021 | D48: WF0XXPTTFCTC5802 | E48: 2013
A49: Toyota Hilux. Ambulancia.- | B49: AA-793-NF | C49: 2GD-0106033 | D49: 8AJFB8CB2H1550532 | E49: 2016
A50: Fiat Ducato Ambulancia.- | B50: AA-842-EM | C50: 7250657 | D50: 93W245G84H2160779 | E50: 2016
A51: Iveco Daily - Ambulancia, Camion 3,5 Tn Modelo 4912-3300 | B51: QAC-895 | C51: 37344093481 | D51: 93ZC4980158319325 | E51: 2006
A52: Chevrolet S10 - Ambulancia.- | B52: ESH-452 | C52: 40704192455 | D52: 9BG124AC05C410604 | E52: 2004
...

Sheet NP BANCO DE SANGRE
A1: NOTA DE PEDIDO | J1: N° | K1: 08/2022
A3: JURISDICCIÓN: | D3: ='SAF 011'!C4 -> 040 - MINISTERIO DE SALUD
A4: SAF: | D4: ='SAF 011'!C5 -> 011 - DIRECCION PROVINCIAL DE ADMINISTRACION - MINISTERIO DE SALUD
A5: UNIDAD EJECUTORA: | D5: SECRETARIA DE ASISTENCIA EN SALUD PUBLICA
A6: DEPENDENCIA SOLICITANTE: | D6: DIRECCION PROVINCIAL BANCO DE SANGRE
A7: PERIODO UTILIZACIÓN: | D7: 1° TRIMESTRE 2022
A8: OBJETO: | D8: ADQUISICION DEL RUBRO CUBIERTAS.-
A10: Ítem | B10: Codigo Item | C10: DESCRIPCIÓN | H10: Adjunta Detalle Técnico | I10: Unidad Medida | J10: Precio Unitario Estimado | K10: Cantidad Solicitada
A12: 1 | B12: ='SAF 011'!B23 -> 2.4.4-6818.851 | C12: ='SAF 011'!E23 -> NEUMATICOS; VEHICULO: MINIBUS, CONSTRUCCION: CONVENCIONAL, ARMADO: S/CAMARA, MEDIDA: 225/70R15 | H12: NO | I12: ='SAF 011'!F23 -> UNIDAD | J12: ='SAF 011'!AX23 -> 44100 | K12: ='SAF 011'!M23 -> 2 | M12: =+J12*K12 -> 88200
A14: Costo total estimado: OCHENTA Y OCHO MIL DOSCIENTOS CON 00/100.- | J14: =+M14 -> 88200 | M14: =SUM(M12:M13) -> 88200

Sheet NP APS
A1: NOTA DE PEDIDO | J1: N° | K1: 03/2022
A3: JURISDICCIÓN: | D3: ='SAF 011'!C4 -> 040 - MINISTERIO DE SALUD
A4: SAF: | D4: ='SAF 011'!C5 -> 011 - DIRECCION PROVINCIAL DE ADMINISTRACION - MINISTERIO DE SALUD
A5: UNIDAD EJECUTORA: | D5: SECRETARIA DE ASISTENCIA EN SALUD PUBLICA
A6: DEPENDENCIA SOLICITANTE: | D6: DIRECCION PROVINCIAL PRIMER NIVEL ATENCION PRIMARIA
A7: PERIODO UTILIZACIÓN: | D7: 1° TRIMESTRE 2022
A8: OBJETO: | D8: ADQUISICION DEL RUBRO CUBIERTAS.-
A10: Ítem | B10: Codigo Item | C10: DESCRIPCIÓN | H10: Adjunta Detalle Técnico | I10: Unidad Medida | J10: Precio Unitario Estimado | K10: Cantidad Solicitada
A12: 1 | B12: ='SAF 011'!B22 -> 2.4.4-6818.48 | C12: ='SAF 011'!E22 -> NEUMATICOS; VEHICULO: CAMIONETA, CONSTRUCCION: RADIAL, MEDIDA: 235/75R15, ARMADO: S/CAMARA | H12: NO | I12: ='SAF 011'!F22 -> UNIDAD | J12: ='SAF 011'!AX22 -> 38300 | K12: ='SAF 011'!O22 -> 2 | M12: =+J12*K12 -> 76600
A14: Costo total estimado: SETENTA Y SEIS MIL SEISCIENTOS CON 00/100.- | J14: =+M14 -> 76600 | M14: =SUM(M12:M13) -> 76600

Sheet NP SAME
A1: NOTA DE PEDIDO | J1: N° | K1: 09/2022
A3: JURISDICCIÓN: | D3: ='SAF 011'!C4 -> 040 - MINISTERIO DE SALUD
A4: SAF: | D4: ='SAF 011'!C5 -> 011 - DIRECCION PROVINCIAL DE ADMINISTRACION - MINISTERIO DE SALUD
A5: UNIDAD EJECUTORA: | D5: SECRETARIA DE ASISTENCIA EN SALUD PUBLICA
A6: DEPENDENCIA SOLICITANTE: | D6: DIRECCION PROVINCIAL SISTEMA DE ATENCION MEDICA DE EMERGENCIA
A7: PERIODO UTILIZACIÓN: | D7: 1° TRIMESTRE 2022
A8: OBJETO: | D8: ADQUISICION DEL RUBRO CUBIERTAS.-
A10: Ítem | B10: Codigo Item | C10: DESCRIPCIÓN | H10: Adjunta Detalle Técnico | I10: Unidad Medida | J10: Precio Unitario Estimado | K10: Cantidad Solicitada
A12: 1 | B12: ='SAF 011'!B10 -> 2.4.4-6818.986 | C12: ='SAF 011'!E10 -> NEUMATICOS; VEHICULO: AMBULANCIA/FURGON/MINIBUS, CONSTRUCCION: RADIAL, ARMADO: S/CAMARA, MEDIDA: 205/75R16 | H12: NO | I12: ='SAF 011'!F10 -> UNIDAD | J12: ='SAF 011'!AX10 -> 42000 | K12: ='SAF 011'!W10 -> 20 | M12: =+J12*K12 -> 840000
A14: Costo total estimado: OCHOCIENTOS CUARENTA MIL CON 00/100.- | J14: =+M14 -> 840000 | M14: =SUM(M12:M13) -> 840000

Sheet NP SASP
A1: NOTA DE PEDIDO | J1: N° | K1: 03/2022
A3: JURISDICCIÓN: | D3: ='SAF 011'!C4 -> 040 - MINISTERIO DE SALUD
A4: SAF: | D4: ='SAF 011'!C5 -> 011 - DIRECCION PROVINCIAL DE ADMINISTRACION - MINISTERIO DE SALUD
A5: UNIDAD EJECUTORA: | D5: SECRETARIA DE ASISTENCIA EN SALUD PUBLICA
A6: DEPENDENCIA SOLICITANTE: | D6: SECRETARIA DE ASISTENCIA EN SALUD PUBLICA
A7: PERIODO UTILIZACIÓN: | D7: 1° TRIMESTRE 2022
A8: OBJETO: | D8: ADQUISICION DEL RUBRO CUBIERTAS.-
A10: Ítem | B10: Codigo Item | C10: DESCRIPCIÓN | H10: Adjunta Detalle Técnico | I10: Unidad Medida | J10: Precio Unitario Estimado | K10: Cantidad Solicitada
A12: 1 | B12: ='SAF 011'!B19 -> 2.4.4-6818.530 | C12: ='SAF 011'!E19 -> NEUMATICOS; VEHICULO: CAMIONETA, CONSTRUCCION: RADIAL, ARMADO: S/CAMARA, MEDIDA: 245/70R16 | H12: NO | I12: ='SAF 011'!F19 -> UNIDAD | J12: ='SAF 011'!AX19 -> 44250 | K12: ='SAF 011'!AC19 -> 4 | M12: =+J12*K12 -> 177000
A14: Costo total estimado: CIENTO SETENTA Y SIETE MIL CON 00/100.- | J14: =+M14 -> 177000 | M14: =SUM(M12:M13) -> 177000

Sheet APG SASP Y DEPENDENCIAS
A1: EJERCICIO: | D1: 2022 | P1: AUTORIZACION PARA GASTAR
A4: JURISDICCIÓN: | G4: ='SAF 011'!C4 -> 040 - MINISTERIO DE SALUD
A5: SAF: | G5: ='SAF 011'!C5 -> 011 - DIRECCION PROVINCIAL DE ADMINISTRACION - MINISTERIO DE SALUD
A6: UNIDAD EJECUTORA: | G6: SECRETARIA DE ASISTENCIA EN SALUD PUBLICA
A7: DEPENDENCIA SOLICITANTE: | G7: SECRETARIA DE ASISTENCIA EN SALUD PUBLICA
A8: AUTORIZACIÓN:
A9: Señor Director de Administración o Titular del Servicio Administrativo Financiero:
A10: Autorizo la realización de los trámites correspondientes, a fin de proveer a este Organismo los bienes/servicios que se detallan en Nota de Pedido N° D.P.B.S. 08/2022 - D.P.P.N.A.P. 03/2022 - D.P.S.A.M.E. 09/2022 - S.A.S.P. 03/2022 afectando la erogación resultante a los créditos presupuestarios aprobados a favor de esta Unidad Ejecutora, conforme al siguiente detalle:
A12: IMPUTACIÓN PRESUPUESTARIA
A13: CÓDIGO | O13: DENOMINACIÓN DE LA PARTIDA PRESUPUESTARIA | Q13: IMPORTE
A14: PR | B14: SB | C14: PY | D14: AC | E14: OB | F14: UG | G14: FIN | H14: FUN | I14: I | J14: P | K14: P | L14: SubP | M14: M | N14: FF
A15: 27 | D15: 1 | F15: 4901 | G15: 3 | H15: 1 | I15: 2 | J15: 4 | K15: 4 | M15: 1 | N15: 1.1 | O15: CUBIERTAS Y CAMARAS DE AIRE | Q15: ='NP BANCO DE SANGRE'!M14 -> 88200
A16: 47 | D16: 1 | F16: 4901 | G16: 3 | H16: 1 | I16: 2 | J16: 4 | K16: 4 | M16: 1 | N16: 1.1 | O16: CUBIERTAS Y CAMARAS DE AIRE | Q16: ='NP APS'!M14 -> 76600
A17: 31 | D17: 1 | F17: 4901 | G17: 3 | H17: 1 | I17: 2 | J17: 4 | K17: 4 | M17: 1 | N17: 1.1 | O17: CUBIERTAS Y CAMARAS DE AIRE | Q17: ='NP SAME'!M14 -> 840000
A18: 3 | D18: 1 | F18: 4901 | G18: 1 | H18: 3 | I18: 2 | J18: 4 | K18: 4 | M18: 1 | N18: 1.1 | O18: CUBIERTAS Y CAMARAS DE AIRE | Q18: ='NP SASP'!M14 -> 177000
A38: TOTAL DE PESOS: UN MILLON CIENTO OCHENTA Y UN MIL OCHOCIENTOS CON 00/100.- | Q38: =SUM(Q15:Q37) -> 1181800
A40: JUSTIFICACIÓN:
A41: ='NP SASP'!D8 -> ADQUISICION DEL RUBRO CUBIERTAS.-

Sheet NP MEDIO AMBIENTE
A1: NOTA DE PEDIDO | J1: N° | K1: 05/2022
A3: JURISDICCIÓN: | D3: ='SAF 011'!C4 -> 040 - MINISTERIO DE SALUD
A4: SAF: | D4: ='SAF 011'!C5 -> 011 - DIRECCION PROVINCIAL DE ADMINISTRACION - MINISTERIO DE SALUD
A5: UNIDAD EJECUTORA: | D5: SECRETARIA DE MEDICINA PREVENTIVA Y PROMOCION EN SALUD
A6: DEPENDENCIA SOLICITANTE: | D6: DIRECCION PROVINCIAL DE SALUD Y MEDIO AMBIENTE
A7: PERIODO UTILIZACIÓN: | D7: 1° TRIMESTRE 2022
A8: OBJETO: | D8: ADQUISICION DEL RUBRO CUBIERTAS.-
A10: Ítem | B10: Codigo Item | C10: DESCRIPCIÓN | H10: Adjunta Detalle Técnico | I10: Unidad Medida | J10: Precio Unitario Estimado | K10: Cantidad Solicitada
A12: 1 | B12: ='SAF 011'!B13 -> 2.4.4-6818.59 | C12: ='SAF 011'!E13 -> NEUMATICOS; VEHICULO: CAMIONETA, CONSTRUCCION: RADIAL, ARMADO: S/CAMARA, MEDIDA: 195/75R16 | H12: NO | I12: ='SAF 011'!F13 -> UNIDAD | J12: ='SAF 011'!AX13 -> 44600 | K12: ='SAF 011'!AE13 -> 5 | M12: =+J12*K12 -> 223000
A14: Costo total estimado: DOSCIENTOS VEINTITRES MIL CON 00/100.- | J14: =+M14 -> 223000 | M14: =SUM(M12:M13) -> 223000

Sheet NP VECTORES
A1: NOTA DE PEDIDO | J1: N° | K1: 04/2022
A3: JURISDICCIÓN: | D3: ='SAF 011'!C4 -> 040 - MINISTERIO DE SALUD
A4: SAF: | D4: ='SAF 011'!C5 -> 011 - DIRECCION PROVINCIAL DE ADMINISTRACION - MINISTERIO DE SALUD
A5: UNIDAD EJECUTORA: | D5: SECRETARIA DE MEDICINA PREVENTIVA Y PROMOCION EN SALUD
A6: DEPENDENCIA SOLICITANTE: | D6: DIRECCION DE CONTROL DE VECTORES Y ZOONOSIS
A7: PERIODO UTILIZACIÓN: | D7: 1° TRIMESTRE 2022
A8: OBJETO: | D8: ADQUISICION DEL RUBRO CUBIERTAS.-
A10: Ítem | B10: Codigo Item | C10: DESCRIPCIÓN | H10: Adjunta Detalle Técnico | I10: Unidad Medida | J10: Precio Unitario Estimado | K10: Cantidad Solicitada
A12: 1 | B12: ='SAF 011'!B10 -> 2.4.4-6818.986 | C12: ='SAF 011'!E10 -> NEUMATICOS; VEHICULO: AMBULANCIA/FURGON/MINIBUS, CONSTRUCCION: RADIAL, ARMADO: S/CAMARA, MEDIDA: 205/75R16 | H12: NO | I12: ='SAF 011'!F10 -> UNIDAD | J12: ='SAF 011'!AX10 -> 42000 | K12: ='SAF 011'!AG10 -> 3 | M12: =+J12*K12 -> 126000
A13: 2 | B13: ='SAF 011'!B22 -> 2.4.4-6818.48 | C13: ='SAF 011'!E22 -> NEUMATICOS; VEHICULO: CAMIONETA, CONSTRUCCION: RADIAL, MEDIDA: 235/75R15, ARMADO: S/CAMARA | H13: NO | I13: ='SAF 011'!F22 -> UNIDAD | J13: ='SAF 011'!AX22 -> 38300 | K13: ='SAF 011'!AG22 -> 4 | M13: =+J13*K13 -> 153200
A15: Costo total estimado: DOSCIENTOS SETENTA Y NUEVE MIL DOSCIENTOS CON 00/100.- | J15: =+M15 -> 279200 | M15: =SUM(M12:M14) -> 279200

Sheet NP EPIDEMIOLOGIA
A1: NOTA DE PEDIDO | J1: N° | K1: 03/2022
A3: JURISDICCIÓN: | D3: ='SAF 011'!C4 -> 040 - MINISTERIO DE SALUD
A4: SAF: | D4: ='SAF 011'!C5 -> 011 - DIRECCION PROVINCIAL DE ADMINISTRACION - MINISTERIO DE SALUD
A5: UNIDAD EJECUTORA: | D5: SECRETARIA DE MEDICINA PREVENTIVA Y PROMOCION EN SALUD
A6: DEPENDENCIA SOLICITANTE: | D6: DIRECCION PROVINCIAL DE EPIDEMIOLOGIA
A7: PERIODO UTILIZACIÓN: | D7: 1° TRIMESTRE 2022
A8: OBJETO: | D8: ADQUISICION DEL RUBRO CUBIERTAS.-
A10: Ítem | B10: Codigo Item | C10: DESCRIPCIÓN | H10: Adjunta Detalle Técnico | I10: Unidad Medida | J10: Precio Unitario Estimado | K10: Cantidad Solicitada
A12: 1 | B12: ='SAF 011'!B22 -> 2.4.4-6818.48 | C12: ='SAF 011'!E22 -> NEUMATICOS; VEHICULO: CAMIONETA, CONSTRUCCION: RADIAL, MEDIDA: 235/75R15, ARMADO: S/CAMARA | H12: NO | I12: ='SAF 011'!F22 -> UNIDAD | J12: ='SAF 011'!AX22 -> 38300 | K12: ='SAF 011'!AS22 -> 3 | M12: =+J12*K12 -> 114900
A14: Costo total estimado: CIENTO CATORCE MIL NOVECIENTOS CON 00/100.- | J14: =+M14 -> 114900 | M14: =SUM(M12:M13) -> 114900

Sheet APG DEPENDENCIAS SMPyPS
A1: EJERCICIO: | D1: 2022 | P1: AUTORIZACION PARA GASTAR
A4: JURISDICCIÓN: | G4: ='SAF 011'!C4 -> 040 - MINISTERIO DE SALUD
A5: SAF: | G5: ='SAF 011'!C5 -> 011 - DIRECCION PROVINCIAL DE ADMINISTRACION - MINISTERIO DE SALUD
A6: UNIDAD EJECUTORA: | G6: SECRETARIA DE MEDICINA PREVENTIVA Y PROMOCION EN SALUD
A7: DEPENDENCIA SOLICITANTE: | G7: SECRETARIA DE MEDICINA PREVENTIVA Y PROMOCION EN SALUD
A8: AUTORIZACIÓN:
A9: Señor Director de Administración o Titular del Servicio Administrativo Financiero:
A10: Autorizo la realización de los trámites correspondientes, a fin de proveer a este Organismo los bienes/servicios que se detallan en Nota de Pedido N° D.P.S.M.A. 05/2022 - D.C.V.Z. 04/2022 - D.P.E. 03/2022 afectando la erogación resultante a los créditos presupuestarios aprobados a favor de esta Unidad Ejecutora, conforme al siguiente detalle:
A12: IMPUTACIÓN PRESUPUESTARIA
A13: CÓDIGO | O13: DENOMINACIÓN DE LA PARTIDA PRESUPUESTARIA | Q13: IMPORTE
A14: PR | B14: SB | C14: PY | D14: AC | E14: OB | F14: UG | G14: FIN | H14: FUN | I14: I | J14: P | K14: P | L14: SubP | M14: M | N14: FF
A15: 22 | D15: 1 | F15: 4901 | G15: 4 | H15: 4 | I15: 2 | J15: 4 | K15: 4 | M15: 1 | N15: 1.1 | O15: CUBIERTAS Y CAMARAS DE AIRE | Q15: ='NP MEDIO AMBIENTE'!M14 -> 223000
A16: 23 | D16: 1 | F16: 4901 | G16: 3 | H16: 1 | I16: 2 | J16: 4 | K16: 4 | M16: 1 | N16: 1.1 | O16: CUBIERTAS Y CAMARAS DE AIRE | Q16: ='NP VECTORES'!M15 -> 279200
A17: 28 | D17: 1 | F17: 4901 | G17: 3 | H17: 1 | I17: 2 | J17: 4 | K17: 4 | M17: 1 | N17: 1.1 | O17: CUBIERTAS Y CAMARAS DE AIRE | Q17: ='NP EPIDEMIOLOGIA'!M14 -> 114900
A38: TOTAL DE PESOS: SEISCIENTOS DIECISETE MIL CIEN CON 00/100.- | Q38: =SUM(Q15:Q37) -> 617100
A40: JUSTIFICACIÓN:
A41: ='NP EPIDEMIOLOGIA'!D8 -> ADQUISICION DEL RUBRO CUBIERTAS.-

Sheet NP DPAS
A1: NOTA DE PEDIDO | J1: N° | K1: 03/2022
A3: JURISDICCIÓN: | D3: ='SAF 011'!C4 -> 040 - MINISTERIO DE SALUD
A4: SAF: | D4: ='SAF 011'!C5 -> 011 - DIRECCION PROVINCIAL DE ADMINISTRACION - MINISTERIO DE SALUD
A5: UNIDAD EJECUTORA: | D5: DIRECCION PROVINCIAL DE ASISTENCIA SANITARIA NIVEL I Y II
A6: DEPENDENCIA SOLICITANTE: | D6: DIRECCION PROVINCIAL DE ASISTENCIA SANITARIA NIVEL I Y II
A7: PERIODO UTILIZACIÓN: | D7: 1° TRIMESTRE 2022
A8: OBJETO: | D8: ADQUISICION DEL RUBRO CUBIERTAS.-
A10: Ítem | B10: Codigo Item | C10: DESCRIPCIÓN | H10: Adjunta Detalle Técnico | I10: Unidad Medida | J10: Precio Unitario Estimado | K10: Cantidad Solicitada
A12: 1 | B12: ='SAF 011'!B10 -> 2.4.4-6818.986 | C12: ='SAF 011'!E10 -> NEUMATICOS; VEHICULO: AMBULANCIA/FURGON/MINIBUS, CONSTRUCCION: RADIAL, ARMADO: S/CAMARA, MEDIDA: 205/75R16 | H12: NO | I12: ='SAF 011'!F10 -> UNIDAD | J12: ='SAF 011'!AX10 -> 42000 | K12: ='SAF 011'!AQ10 -> 69 | M12: =+J12*K12 -> 2898000
A13: 2 | B13: ='SAF 011'!B11 -> 2.4.4-6818.801 | C13: ='SAF 011'!E11 -> NEUMATICOS; VEHICULO: CAMIONETA, CONSTRUCCION: CON CLAVOS, ARMADO: S/CAMARA, MEDIDA: 265/70R16 | H13: NO | I13: ='SAF 011'!F11 -> UNIDAD | J13: ='SAF 011'!AX11 -> 42000 | K13: ='SAF 011'!AQ11 -> 8 | M13: =+J13*K13 -> 336000
A14: 3 | B14: ='SAF 011'!B13 -> 2.4.4-6818.59 | C14: ='SAF 011'!E13 -> NEUMATICOS; VEHICULO: CAMIONETA, CONSTRUCCION: RADIAL, ARMADO: S/CAMARA, MEDIDA: 195/75R16 | H14: NO | I14: ='SAF 011'!F13 -> UNIDAD | J14: ='SAF 011'!AX13 -> 44600 | K14: ='SAF 011'!AQ13 -> 8 | M14: =+J14*K14 -> 356800
A15: 4 | B15: ='SAF 011'!B14 -> 2.4.4-6818.52 | C15: ='SAF 011'!E14 -> NEUMATICOS; VEHICULO: CAMIONETA, CONSTRUCCION: RADIAL, ARMADO: S/CAMARA, MEDIDA: 215/80R16 | H15: NO | I15: ='SAF 011'!F14 -> UNIDAD | J15: ='SAF 011'!AX14 -> 41400 | K15: ='SAF 011'!AQ14 -> 20 | M15: =+J15*K15 -> 828000
A16: 5 | B16: ='SAF 011'!B15 -> 2.4.4-6818.885 | C16: ='SAF 011'!E15 -> NEUMATICOS; VEHICULO: CAMIONETA, CONSTRUCCION: RADIAL, ARMADO: S/CAMARA, MEDIDA: 225/65R17 | H16: NO | I16: ='SAF 011'!F15 -> UNIDAD | J16: ='SAF 011'!AX15 -> 45400 | K16: ='SAF 011'!AQ15 -> 4 | M16: =+J16*K16 -> 181600
A17: 6 | B17: ='SAF 011'!B16 -> 2.4.4-6818.989 | C17: ='SAF 011'!E16 -> NEUMATICOS; VEHICULO: CAMIONETA, CONSTRUCCION: RADIAL, ARMADO: S/CAMARA, MEDIDA: 225/70 R17 | H17: NO | I17: ='SAF 011'!F16 -> UNIDAD | J17: ='SAF 011'!AX16 -> 58000 | K17: ='SAF 011'!AQ16 -> 8 | M17: =+J17*K17 -> 464000
A18: 7 | B18: ='SAF 011'!B17 -> 2.4.4-6818.744 | C18: ='SAF 011'!E17 -> NEUMATICOS; VEHICULO: CAMIONETA, CONSTRUCCION: RADIAL, ARMADO: S/CAMARA, MEDIDA: 235/70R16 | H18: NO | I18: ='SAF 011'!F17 -> UNIDAD | J18: ='SAF 011'!AX17 -> 48200 | K18: ='SAF 011'!AQ17 -> 4 | M18: =+J18*K18 -> 192800
A19: 8 | B19: ='SAF 011'!B18 -> 2.4.4-6818.751 | C19: ='SAF 011'!E18 -> NEUMATICOS; VEHICULO: CAMIONETA, CONSTRUCCION: RADIAL, ARMADO: S/CAMARA, MEDIDA: 245/65 R17 | H19: NO | I19: ='SAF 011'!F18 -> UNIDAD | J19: ='SAF 011'!AX18 -> 51950 | K19: ='SAF 011'!AQ18 -> 20 | M19: =+J19*K19 -> 1039000
A20: 9 | B20: ='SAF 011'!B21 -> 2.4.4-6818.723 | C20: ='SAF 011'!E21 -> NEUMATICOS; VEHICULO: CAMIONETA, CONSTRUCCION: RADIAL, ARMADO: SIN CAMARA, MEDIDA: 185/65R15 | H20: NO | I20: ='SAF 011'!F21 -> UNIDAD | J20: ='SAF 011'!AX21 -> 29400 | K20: ='SAF 011'!AQ21 -> 8 | M20: =+J20*K20 -> 235200
A21: 10 | B21: ='SAF 011'!B22 -> 2.4.4-6818.48 | C21: ='SAF 011'!E22 -> NEUMATICOS; VEHICULO: CAMIONETA, CONSTRUCCION: RADIAL, MEDIDA: 235/75R15, ARMADO: S/CAMARA | H21: NO | I21: ='SAF 011'!F22 -> UNIDAD | J21: ='SAF 011'!AX22 -> 38300 | K21: ='SAF 011'!AQ22 -> 16 | M21: =+J21*K21 -> 612800
A22: 11 | B22: ='SAF 011'!B24 -> 2.4.4-6818.993 | C22: ='SAF 011'!E24 -> NEUMATICOS; VEHICULO: UTILITARIO, CONSTRUCCION: RADIAL, ARMADO: S/CAMARA, MEDIDA: 225/75-R16C | H22: NO | I22: ='SAF 011'!F24 -> UNIDAD | J22: ='SAF 011'!AX24 -> 52300 | K22: ='SAF 011'!AQ24 -> 20 | M22: =+J22*K22 -> 1046000
A24: Costo total estimado: OCHO MILLONES CIENTO NOVENTA MIL DOSCIENTOS CON 00/100.- | J24: =+M24 -> 8190200 | M24: =SUM(M12:M23) -> 8190200

Sheet APG DPAS
A1: EJERCICIO: | D1: 2022 | P1: AUTORIZACION PARA GASTAR
A4: JURISDICCIÓN: | G4: ='NP DPAS'!D3 -> 040 - MINISTERIO DE SALUD
A5: SAF: | G5: ='NP DPAS'!D4 -> 011 - DIRECCION PROVINCIAL DE ADMINISTRACION - MINISTERIO DE SALUD
A6: UNIDAD EJECUTORA: | G6: ='NP DPAS'!D5 -> DIRECCION PROVINCIAL DE ASISTENCIA SANITARIA NIVEL I Y II
A7: DEPENDENCIA SOLICITANTE: | G7: ='NP DPAS'!D6 -> DIRECCION PROVINCIAL DE ASISTENCIA SANITARIA NIVEL I Y II
A8: AUTORIZACIÓN:
A9: Señor Director de Administración o Titular del Servicio Administrativo Financiero:
A10: Autorizo la realización de los trámites correspondientes, a fin de proveer a este Organismo los bienes/servicios que se detallan en Nota de Pedido N° 03/2022 afectando la erogación resultante a los créditos presupuestarios aprobados a favor de esta Unidad Ejecutora, conforme al siguiente detalle:
A12: IMPUTACIÓN PRESUPUESTARIA
A13: CÓDIGO | O13: DENOMINACIÓN DE LA PARTIDA PRESUPUESTARIA | Q13: IMPORTE
A14: PR | B14: SB | C14: PY | D14: AC | E14: OB | F14: UG | G14: FIN | H14: FUN | I14: I | J14: P | K14: P | L14: SubP | M14: M | N14: FF
A15: 21 | D15: 1 | F15: 4901 | G15: 3 | H15: 1 | I15: 2 | J15: 4 | K15: 4 | M15: 1 | N15: 1.1 | O15: CUBIERTAS Y CAMARAS DE AIRE | Q15: ='NP DPAS'!M24 -> 8190200
A38: TOTAL DE PESOS: OCHO MILLONES CIENTO NOVENTA MIL DOSCIENTOS CON 00/100.- | Q38: =SUM(Q15:Q37) -> 8190200
A40: JUSTIFICACIÓN:
A41: ='NP DPAS'!D8 -> ADQUISICION DEL RUBRO CUBIERTAS.-

Sheet NP MS
A1: NOTA DE PEDIDO | J1: N° | K1: 04/2022
A3: JURISDICCIÓN: | D3: ='SAF 011'!C4 -> 040 - MINISTERIO DE SALUD
A4: SAF: | D4: ='SAF 011'!C5 -> 011 - DIRECCION PROVINCIAL DE ADMINISTRACION - MINISTERIO DE SALUD
A5: UNIDAD EJECUTORA: | D5: MINISTERIO DE SALUD
A6: DEPENDENCIA SOLICITANTE: | D6: MINISTERIO DE SALUD
A7: PERIODO UTILIZACIÓN: | D7: 1° TRIMESTRE 2022
A8: OBJETO: | D8: ADQUISICION DEL RUBRO CUBIERTAS.-
A10: Ítem | B10: Codigo Item | C10: DESCRIPCIÓN | H10: Adjunta Detalle Técnico | I10: Unidad Medida | J10: Precio Unitario Estimado | K10: Cantidad Solicitada
A12: 1 | B12: ='SAF 011'!B12 -> 2.4.4-6818.647 | C12: ='SAF 011'!E12 -> NEUMATICOS; VEHICULO: CAMIONETA, CONSTRUCCION: RADIAL, ARMADO: S/CAMARA, MEDIDA: 175/70R14 pulg | H12: NO | I12: ='SAF 011'!F12 -> UNIDAD | J12: ='SAF 011'!AX12 -> 23500 | K12: ='SAF 011'!AU12 -> 5 | M12: =+J12*K12 -> 117500
A13: 2 | B13: ='SAF 011'!B20 -> 2.4.4-6818.890 | C13: ='SAF 011'!E20 -> NEUMATICOS; VEHICULO: CAMIONETA, CONSTRUCCION: RADIAL, ARMADO: S/CAMARA, MEDIDA: 265/60R18 | H13: NO | I13: ='SAF 011'!F20 -> UNIDAD | J13: ='SAF 011'!AX20 -> 64000 | K13: ='SAF 011'!AU20 -> 3 | M13: =+J13*K13 -> 192000
A15: Costo total estimado: TRESCIENTOS NUEVE MIL QUINIENTOS CON 00/100.- | J15: =+M15 -> 309500 | M15: =SUM(M12:M14) -> 309500

Sheet APG MS
A1: EJERCICIO: | D1: 2022 | P1: AUTORIZACION PARA GASTAR
A4: JURISDICCIÓN: | G4: ='NP MS'!D3 -> 040 - MINISTERIO DE SALUD
A5: SAF: | G5: ='NP MS'!D4 -> 011 - DIRECCION PROVINCIAL DE ADMINISTRACION - MINISTERIO DE SALUD
A6: UNIDAD EJECUTORA: | G6: ='NP MS'!D5 -> MINISTERIO DE SALUD
A7: DEPENDENCIA SOLICITANTE: | G7: ='NP MS'!D6 -> MINISTERIO DE SALUD
A8: AUTORIZACIÓN:
A9: Señor Director de Administración o Titular del Servicio Administrativo Financiero:
A10: Autorizo la realización de los trámites correspondientes, a fin de proveer a este Organismo los bienes/servicios que se detallan en Nota de Pedido N° 04/2022 afectando la erogación resultante a los créditos presupuestarios aprobados a favor de esta Unidad Ejecutora, conforme al siguiente detalle:
A12: IMPUTACIÓN PRESUPUESTARIA
A13: CÓDIGO | O13: DENOMINACIÓN DE LA PARTIDA PRESUPUESTARIA | Q13: IMPORTE
A14: PR | B14: SB | C14: PY | D14: AC | E14: OB | F14: UG | G14: FIN | H14: FUN | I14: I | J14: P | K14: P | L14: SubP | M14: M | N14: FF
A15: 1 | D15: 1 | F15: 4901 | G15: 3 | H15: 1 | I15: 2 | J15: 4 | K15: 4 | M15: 1 | N15: 1.1 | O15: CUBIERTAS Y CAMARAS DE AIRE | Q15: ='NP MS'!M15 -> 309500
A38: TOTAL DE PESOS: TRESCIENTOS NUEVE MIL QUINIENTOS CON 00/100.- | Q38: =SUM(Q15:Q37) -> 309500
A40: JUSTIFICACIÓN:
A41: ='NP MS'!D8 -> ADQUISICION DEL RUBRO CUBIERTAS.-
