Workbook

Sheet Necesidades Trimestrales
B2: Pedido de Necesidades Trimestrales
A4: JURISDICCION: | C4: 40 - Ministerio de Salud
A5: SAF N°: | C5: 23 - Hospital Interzonal San Juan Bautista
A6: EJERCICIO: | C6: 2022
A7: TRIMESTRE: | C7: 4
A9: ID | B9: CODIGO ITEM | C9: RUBRO DE COMPRA | D9: I.P.P. | E9: DESCRIPCION | F9: UNIDAD DE MEDIDA | G9: CANTIDAD | H9: PRECIO UNITARIO ESTIMADO | I9: IMPORTE TOTAL ESTIMADO
A10: 1 | B10: 2.3.4-938.46 | C10: BAZAR Y MENAJE | D10: =LEFT(B10,5) -> 2.3.4 | E10: SERVILLETAS DE PAPEL; TIPO LISAS, MOTIVO: SIN DIMENSION:33X33 Cm, PRESENTACION: PAQUETEX 1000 UN. COLOR: BLANCA | F10: UNIDAD | G10: 25 | H10: 1900 | I10: =G10*H10 -> 47500
A11: 2 | B11: 2.9.4-689.15 | C11: BAZAR Y MENAJE | D11: =LEFT(B11,5) -> 2.9.4 | E11: CUCHILLOS; TIPO: DE MESA, MATERIAL: PLÁSTICO | F11: UNIDAD | G11: 25000 | H11: 4.2 | I11: =G11*H11 -> 105000
A12: 3 | B12: 2.9.4-1184.42 | C12: BAZAR Y MENAJE | D12: =LEFT(B12,5) -> 2.9.4 | E12: VASOS; MATERIAL: POLIESTIRENO EXPANDIDO, TIPO: DESCARTABLE, CAPACIDAD: 180 CM3 | F12: UNIDAD | G12: 5000 | H12: 16 | I12: =G12*H12 -> 80000
A13: 4 | B13: 2.5.8-3977.40 | C13: FERRETERIA | D13: =LEFT(B13,5) -> 2.5.8 | E13: BOLSAS DE POLIETILENO; TAMAÑO; 15X25 Cm, ESPESOR: 17mN, PRESENTACION: ROLLO X 200 UN. | F13: UNIDAD | G13: 600 | H13: 310 | I13: =G13*H13 -> 186000
A14: 5 | B14: 2.9.4-6970.3 | C14: BAZAR Y MENAJE | D14: =LEFT(B14,5) -> 2.9.4 | E14: COMPOTERAS; MATERIAL: POLICARBONATO, CAPACIDAD:250ml | F14: UNIDAD | G14: 25000 | H14: 16 | I14: =G14*H14 -> 400000
A15: 6 | B15: 2.9.4-1184.49 | C15: BAZAR Y MENAJE | D15: =LEFT(B15,5) -> 2.9.4 | E15: VASOS; MATERIAL: POLIESTIRENO, TIPO: TERMICO, CAPACIDAD: 240 mL | F15: UNIDAD | G15: 50000 | H15: 20 | I15: =G15*H15 -> 1000000
A16: 7 | B16: 2.9.4-690.15 | C16: BAZAR Y MENAJE | D16: =LEFT(B16,5) -> 2.9.4 | E16: CUCHARAS; TIPO: DE MESA, MATERIAL: PLÁSTICO. | F16: UNIDAD | G16: 25000 | H16: 4.2 | I16: =G16*H16 -> 105000
A17: 8 | B17: 2.5.8-1055.37 | C17: BAZAR Y MENAJE | D17: =LEFT(B17,5) -> 2.5.8 | E17: BANDEJA DE PLASTICO; MATERIAL:PLASTICO, LARGO X ANCHO: 233X170mm, FORMA: OVAL, PRESENTACION: CAJA X 600 UN. | F17: UNIDAD | G17: 25 | H17: 54000 | I17: =G17*H17 -> 1350000
A18: 9 | B18: 2.9.4-4743.4 | C18: BAZAR Y MENAJE | D18: =LEFT(B18,5) -> 2.9.4 | E18: BANDEJA P/TRANSP, DE ALIMENTO; CAPACIDAD: 700GR, MATERIAL: ALUMINIO, TIPO:SIN VALOR, MEDIDAS14X10X4,5Cm, INTERIOR: SIN VALOR, EXTERIOR: SIN VALOR,DIMENSION:14X10X4,5Cm,ACABADO:SIN VALOR. | F18: UNIDAD | G18: 5000 | H18: 31 | I18: =G18*H18 -> 155000 | N18: 3
A19: 10 | B19: 2.9.4-692.10 | C19: BAZAR Y MENAJE | D19: =LEFT(B19,5) -> 2.9.4 | E19: TENEDORES;TIPO:DE MESA,MATERIAL:PLASTICO | F19: UNIDAD | G19: 25000 | H19: 4.2 | I19: =G19*H19 -> 105000
A20: 11 | B20: 2.3.4-938.59 | C20: BAZAR Y MENAJE | D20: =LEFT(B20,5) -> 2.3.4 | E20: SERVILLETAS DE PAPEL; TIPO:ROLLO, MOTIVO:SIN DIMENSION 25X10Cm, PRESENTACION: ENVASE X 3 UN. | F20: UNIDAD | G20: 150 | H20: 190 | I20: =G20*H20 -> 28500
A21: 12 | B21: 2.9.4-4743.24 | C21: BAZAR Y MENAJE | D21: =LEFT(B21,5) -> 2.9.4 | E21: BANDEJA P/TRANSP. DE ALIMENTO;DIMENSION:18X14X4 CmTIPO:C/TAPA,MATERIAL:ALUMINIO APTO MICROONDAS,CAPACIDAD: 750CM3 | F21: UNIDAD | G21: 60000 | H21: 34 | I21: =G21*H21 -> 2040000
A22: 13 | B22: 2.9.4-690.16 | C22: BAZAR Y MENAJE | D22: =LEFT(B22,5) -> 2.9.4 | E22: CUCHARAS;TIPO TE, MATERIAL:PLÁSTICO. | F22: UNIDAD | G22: 25000 | H22: 2.6 | I22: =G22*H22 -> 65000
A23: 14 | B23: 2.5.8-5590.59 | C23: LIBRERIA,PAP. Y UTILES OFICINA | D23: =LEFT(B23,5) -> 2.5.8 | E23: FILMS DE POLIETILENO; ESPESOR:10MnANCHO: 45Cm, PRESENTACION:ROLLOX900M, USO: ALIMENTARIO | F23: UNIDAD | G23: 5 | H23: 8400 | I23: =G23*H23 -> 42000
A24: 15 | B24: 2.9.4-1015.40 | C24: BAZAR Y MENAJE | D24: =LEFT(B24,5) -> 2.9.4 | E24: BANDEJAS DE MESA ; MATERIAL: PLÁSTICO, DIMENSION: 16,5X12X5,5Cm, FORMA:RECTANGULAR | F24: UNIDAD | G24: 2000 | H24: 16 | I24: =G24*H24 -> 32000
A25: 16 | B25: 2.9.4-588.70 | C25: BAZAR Y MENAJE | D25: =LEFT(B25,5) -> 2.9.4 | E25: VASOS PLASTICOS DESCARTABLES; MATERIAL: POLIESTIRENO, MOTIVO: LISO, CAPACIDAD: 240 CM3, PRESENTACION: ENVASE X 1000 UN, TIPO: APTO MICROONDAS | F25: UNIDAD | G25: 60 | H25: 18000 | I25: =G25*H25 -> 1080000
A26: 17 | B26: 2.9.5-1909.206 | C26: PROD. MEDICO/FARMACEUTICOS/LAB | D26: =LEFT(B26,5) -> 2.9.5 | E26: GUANTES USO MEDICINAL; TIPO: DESCARTABLES, TAMAÑO:UNICO, MATERIAL:POLIETILENO,PRESENTACION: :ENVASE X 100UN., ESTERIL:SI, TALCO:NO DESCARTABLE: SI. | F26: UNIDAD | G26: 5 | H26: 150 | I26: =G26*H26 -> 750
A27: 18 | B27: 2.5.8-5590.41 | C27: LIBRERIA,PAP. Y UTILES OFICINA | D27: =LEFT(B27,5) -> 2.5.8 | E27: FILMS DE POLIETILENO; ESPESOR: 100 Mn, ANCHO: 2 M, PRESENTACION: ROLLO X 100 M, USO: ALIMENTARIO | F27: ROLLO | G27: 3 | H27: 32000 | I27: =G27*H27 -> 96000
A28: 19 | B28: 2.5.8-5590.3 | C28: LIBRERIA,PAP. Y UTILES OFICINA | D28: =LEFT(B28,5) -> 2.5.8 | E28: FILMS DE POLIETILENO; ESPESOR: 70 Mn, ANCHO: SIN VALOR, PRESENTACION: POR KILOGRAMO, USO: SIN VALOR | F28: ROLLO | G28: 30 | H28: 2500 | I28: =G28*H28 -> 75000
A29: 20 | B29: 2.5.8-5590.3 | C29: LIBRERIA,PAP. Y UTILES OFICINA | D29: =LEFT(B29,5) -> 2.5.8 | E29: FILMS DE POLIETILENO; ESPESOR: 70 Mn, ANCHO: SIN VALOR, PRESENTACION: POR KILOGRAMO, USO: SIN VALOR | F29: ROLLO | G29: 30 | H29: 2500 | I29: =G29*H29 -> 75000
A30: 21 | B30: 2.5.8-5590.3 | C30: LIBRERIA,PAP. Y UTILES OFICINA | D30: =LEFT(B30,5) -> 2.5.8 | E30: FILMS DE POLIETILENO; ESPESOR: 70 Mn, ANCHO: SIN VALOR, PRESENTACION: POR KILOGRAMO, USO: SIN VALOR | F30: ROLLO | G30: 30 | H30: 2500 | I30: =G30*H30 -> 75000
I31: =SUM(I10:I30) -> 7142750
B32: PLAZO DE ENTREGA: 10 DIAS - LUGAR DE ENTREGA: SERVICIO DE NUTRICION - HOSPITAL INTERZONAL SAN JUAN BAUTISTA - AV. ILLIA ESQ. MARIANO MORENO
B33: MANTENIMIENTO DE OFERTA: 45 DIAS HABILES
B36: Especificidades Item N° 2:
B38: Descripción técnica
C39: Cuchillos Plásticos Super Reforzados Serruchos color Blanco descartables
B40: Plazos y lugares de entrega
B43: Calidad Minima esperada
B45: Mantenimiento
B47: Garantia
B51: Especificidades Item N° 3:
B53: Descripción técnica
C54: VASOS DE POLIESTILENO EXPANDIDO CAPACIDAD: 180 CM3 CON TAPA
...

Sheet NotaPedido
A1: NOTA DE PEDIDO 122 | J1: N° | K1: DOCFI-2022-01958292-CAT-DASIS#HSJB
A3: JURISDICCIÓN: | D3: ='Necesidades Trimestrales'!C4 -> 40 - Ministerio de Salud
A4: SAF: | D4: ='Necesidades Trimestrales'!C5 -> 23 - Hospital Interzonal San Juan Bautista
A5: UNIDAD EJECUTORA: | D5: 168 - Direccion Asistencial
A6: DEPENDENCIA SOLICITANTE: | D6: Servicio de Nutricion
A7: PERIODO UTILIZACIÓN: | D7: ='Necesidades Trimestrales'!C7&"° Trimestre - Año "&'Necesidades Trimestrales'!C6 -> 4° Trimestre - Año 2022
A8: OBJETO: | D8: Adquisición de Descartables para Nutrición
A10: Ítem | B10: Codigo Item | C10: DESCRIPCIÓN | H10: Adjunta Detalle Técnico | I10: Unidad Medida | J10: Precio Unitario Estimado | K10: Cantidad Solicitada
A12: 1 | B12: ='Necesidades Trimestrales'!B10 -> 2.3.4-938.46 | C12: ='Necesidades Trimestrales'!E10 -> SERVILLETAS DE PAPEL; TIPO LISAS, MOTIVO: SIN DIMENSION:33X33 Cm, PRESENTACION: PAQUETEX 1000 UN. COLOR: BLANCA | H12: NO | I12: ='Necesidades Trimestrales'!F10 -> UNIDAD | J12: ='Necesidades Trimestrales'!H10 -> 1900 | K12: ='Necesidades Trimestrales'!G10 -> 25
A13: 2 | B13: ='Necesidades Trimestrales'!B11 -> 2.9.4-689.15 | C13: ='Necesidades Trimestrales'!E11 -> CUCHILLOS; TIPO: DE MESA, MATERIAL: PLÁSTICO | H13: NO | I13: ='Necesidades Trimestrales'!F11 -> UNIDAD | J13: ='Necesidades Trimestrales'!H11 -> 4.2 | K13: ='Necesidades Trimestrales'!G11 -> 25000
A14: 3 | B14: ='Necesidades Trimestrales'!B12 -> 2.9.4-1184.42 | C14: ='Necesidades Trimestrales'!E12 -> VASOS; MATERIAL: POLIESTIRENO EXPANDIDO, TIPO: DESCARTABLE, CAPACIDAD: 180 CM3 | H14: NO | I14: ='Necesidades Trimestrales'!F12 -> UNIDAD | J14: ='Necesidades Trimestrales'!H12 -> 16 | K14: ='Necesidades Trimestrales'!G12 -> 5000
A15: 4 | B15: ='Necesidades Trimestrales'!B13 -> 2.5.8-3977.40 | C15: ='Necesidades Trimestrales'!E13 -> BOLSAS DE POLIETILENO; TAMAÑO; 15X25 Cm, ESPESOR: 17mN, PRESENTACION: ROLLO X 200 UN. | H15: NO | I15: ='Necesidades Trimestrales'!F13 -> UNIDAD | J15: ='Necesidades Trimestrales'!H13 -> 310 | K15: ='Necesidades Trimestrales'!G13 -> 600
A16: 5 | B16: ='Necesidades Trimestrales'!B14 -> 2.9.4-6970.3 | C16: ='Necesidades Trimestrales'!E14 -> COMPOTERAS; MATERIAL: POLICARBONATO, CAPACIDAD:250ml | H16: NO | I16: ='Necesidades Trimestrales'!F14 -> UNIDAD | J16: ='Necesidades Trimestrales'!H14 -> 16 | K16: ='Necesidades Trimestrales'!G14 -> 25000
A17: 6 | B17: ='Necesidades Trimestrales'!B15 -> 2.9.4-1184.49 | C17: ='Necesidades Trimestrales'!E15 -> VASOS; MATERIAL: POLIESTIRENO, TIPO: TERMICO, CAPACIDAD: 240 mL | H17: NO | I17: ='Necesidades Trimestrales'!F15 -> UNIDAD | J17: ='Necesidades Trimestrales'!H15 -> 20 | K17: ='Necesidades Trimestrales'!G15 -> 50000
A18: 7 | B18: ='Necesidades Trimestrales'!B16 -> 2.9.4-690.15 | C18: ='Necesidades Trimestrales'!E16 -> CUCHARAS; TIPO: DE MESA, MATERIAL: PLÁSTICO. | H18: NO | I18: ='Necesidades Trimestrales'!F16 -> UNIDAD | J18: ='Necesidades Trimestrales'!H16 -> 4.2 | K18: ='Necesidades Trimestrales'!G16 -> 25000
A19: 8 | B19: ='Necesidades Trimestrales'!B17 -> 2.5.8-1055.37 | C19: ='Necesidades Trimestrales'!E17 -> BANDEJA DE PLASTICO; MATERIAL:PLASTICO, LARGO X ANCHO: 233X170mm, FORMA: OVAL, PRESENTACION: CAJA X 600 UN. | H19: NO | I19: ='Necesidades Trimestrales'!F17 -> UNIDAD | J19: ='Necesidades Trimestrales'!H17 -> 54000 | K19: ='Necesidades Trimestrales'!G17 -> 25
A20: 9 | B20: ='Necesidades Trimestrales'!B18 -> 2.9.4-4743.4 | C20: ='Necesidades Trimestrales'!E18 -> BANDEJA P/TRANSP, DE ALIMENTO; CAPACIDAD: 700GR, MATERIAL: ALUMINIO, TIPO:SIN VALOR, MEDIDAS14X10X4,5Cm, INTERIOR: SIN VALOR, EXTERIOR: SIN VALOR,DIMENSION:14X10X4,5Cm,ACABADO:SIN VALOR. | H20: NO | I20: ='Necesidades Trimestrales'!F18 -> UNIDAD | J20: ='Necesidades Trimestrales'!H18 -> 31 | K20: ='Necesidades Trimestrales'!G18 -> 5000
A21: 10 | B21: ='Necesidades Trimestrales'!B19 -> 2.9.4-692.10 | C21: ='Necesidades Trimestrales'!E19 -> TENEDORES;TIPO:DE MESA,MATERIAL:PLASTICO | H21: NO | I21: ='Necesidades Trimestrales'!F19 -> UNIDAD | J21: ='Necesidades Trimestrales'!H19 -> 4.2 | K21: ='Necesidades Trimestrales'!G19 -> 25000
A22: 11 | B22: ='Necesidades Trimestrales'!B20 -> 2.3.4-938.59 | C22: ='Necesidades Trimestrales'!E20 -> SERVILLETAS DE PAPEL; TIPO:ROLLO, MOTIVO:SIN DIMENSION 25X10Cm, PRESENTACION: ENVASE X 3 UN. | H22: NO | I22: ='Necesidades Trimestrales'!F20 -> UNIDAD | J22: ='Necesidades Trimestrales'!H20 -> 190 | K22: ='Necesidades Trimestrales'!G20 -> 150
A23: 12 | B23: ='Necesidades Trimestrales'!B21 -> 2.9.4-4743.24 | C23: ='Necesidades Trimestrales'!E21 -> BANDEJA P/TRANSP. DE ALIMENTO;DIMENSION:18X14X4 CmTIPO:C/TAPA,MATERIAL:ALUMINIO APTO MICROONDAS,CAPACIDAD: 750CM3 | H23: NO | I23: ='Necesidades Trimestrales'!F21 -> UNIDAD | J23: ='Necesidades Trimestrales'!H21 -> 34 | K23: ='Necesidades Trimestrales'!G21 -> 60000
... A32: 21 | B32: ='Necesidades Trimestrales'!B30 -> 2.5.8-5590.3 | C32: ='Necesidades Trimestrales'!E30 -> FILMS DE POLIETILENO; ESPESOR: 70 Mn, ANCHO: SIN VALOR, PRESENTACION: POR KILOGRAMO, USO: SIN VALOR | H32: SI | I32: ='Necesidades Trimestrales'!F30 -> ROLLO | J32: ='Necesidades Trimestrales'!H30 -> 2500 | K32: ='Necesidades Trimestrales'!G30 -> 30
A33: Costo total estimado: PESOS SIETE MILLONES CIENTO CUARENTA Y DOS MIL SETECIENTOS CINCUENTA CON 00/100.---- | J33: =SUMPRODUCT(J12:J32,K12:K32) -> 7142750

Sheet Autor Gastar
A1: EJERCICIO: | D1: ='Necesidades Trimestrales'!C6 -> 2022 | P1: AUTORIZACION PARA GASTAR
A4: JURISDICCIÓN: | G4: =NotaPedido!D3 -> 40 - Ministerio de Salud
A5: SAF: | G5: =NotaPedido!D4 -> 23 - Hospital Interzonal San Juan Bautista
A6: UNIDAD EJECUTORA: | G6: =NotaPedido!D5 -> 168 - Direccion Asistencial
A7: DEPENDENCIA SOLICITANTE: | G7: =NotaPedido!D6 -> Servicio de Nutricion
A8: AUTORIZACIÓN:
A9: Señor Jefe de Servicio Administrativo Financiero:
A10: ="Autorizo la realización de los trámites correspondientes, a fin de proveer a este Organismo los bienes y/o servicios que se detallan en Nota de Pedido N° "&NotaPedido!K1&", afectando la erogación resultante a los créditos presupuestarios aprobados a favor de esta Unidad Ejecutora, conforme al siguiente detalle:" -> Autorizo la realización de los trámites correspondientes, a fin de proveer a este Organismo los bienes y/o servicios que se detallan en Nota de Pedido N° DOCFI-2022-01958292-CAT-DASIS#HSJB, afectando la erogación resultante a los créditos presupuestarios aprobados a favor de esta Unidad Ejecutora, conforme al siguiente detalle:
A12: IMPUTACIÓN PRESUPUESTARIA
A13: CÓDIGO | O13: DENOMINACIÓN DE LA PARTIDA PRESUPUESTARIA | Q13: IMPORTE
A14: PR | B14: SB | C14: PY | D14: AC | E14: OB | F14: UG | G14: FIN | H14: FUN | I14: I | J14: P | K14: P | L14: SubP | M14: M | N14: FF
A15: 33 | D15: 2 | F15: 4901 | G15: 3 | H15: 3.1 | I15: 2 | J15: 3 | K15: 4 | M15: 1 | N15: 1.1 | O15: Productos de papel y cartón | Q15: 76000
A16: 33 | D16: 2 | F16: 4901 | G16: 3 | H16: 3.1 | I16: 2 | J16: 5 | K16: 8 | M16: 1 | N16: 1.1 | O16: Productos de material plástico | Q16: 1899000
A17: 33 | D17: 2 | F17: 4901 | G17: 3 | H17: 3.1 | I17: 2 | J17: 9 | K17: 4 | M17: 1 | N17: 1.1 | O17: Utensillos de Cocina y Comedor | Q17: 5167000
A18: 33 | D18: 2 | F18: 4901 | G18: 3 | H18: 3.1 | I18: 2 | J18: 9 | K18: 5 | M18: 1 | N18: 1.1 | O18: Utiles Menores Med. Quir. y de Lab. | Q18: 750
A22: TOTAL DE PESOS: SIETE MILLONES CIENTO CUARENTA Y DOS MIL SETECIENTOS CINCUENTA CON 00/100.--- | Q22: =SUM(Q15:Q21) -> 7142750
A24: JUSTIFICACIÓN:
A25: ="Para la "&NotaPedido!D8&" para ser destinados al "&NotaPedido!D6&" del HISJB del Ministerio de Salud." -> Para la Adquisición de Descartables para Nutrición para ser destinados al Servicio de Nutricion del HISJB del Ministerio de Salud.
