Workbook

Sheet Necesidades Trimestrales 
A1: 2021
B2: Pedido de Necesidades Trimestrales
A4: JURISDICCION: | C4: 40 - MINISTERIO DE SALUD
A5: SAF N°: | C5: 11 - DIRE PROV DE ADMINISTRACION - MINISTERIO DE SALUD
A6: EJERCICIO: | C6: 2021
A7: TRIMESTRE: | C7: TERCER TRIMESTRE
A9: ID | B9: CODIGO ITEM | C9: RUBRO DE COMPRA | D9: I.P.P. | E9: DESCRIPCION | F9: UNIDAD DE MEDIDA | G9: CANTIDAD TOTAL | H9: PRECIO UNITARIO ESTIMADO | I9: IMPORTE TOTAL ESTIMADO
A10: 1 | C10: PROD. MEDICO/FARMACEUTICOS/LAB | D10: 252 | E10: ACICLOVIR 500 MG FCO AMPOLLA | F10: UNIDAD | G10: 20 | H10: 384 | I10: =+H10*G10 -> 7680
A11: 2 | C11: PROD. MEDICO/FARMACEUTICOS/LAB | D11: 252 | E11: ACIDO ACETIL SALICILICO 500 MG COMPRIMIDO | F11: UNIDAD | G11: 4800 | H11: 2.23 | I11: =+H11*G11 -> 10704
A12: 3 | C12: PROD. MEDICO/FARMACEUTICOS/LAB | D12: 252 | E12: AGUA DESTILADA EN SACHET X 500 ML | F12: UNIDAD | G12: 10000 | H12: 140 | I12: =+H12*G12 -> 1400000
A13: 4 | C13: PROD. MEDICO/FARMACEUTICOS/LAB | D13: 252 | E13: ALIMENTACION ENTERAL X 500 ML TIPO DIBEN | F13: UNIDAD | G13: 2500 | H13: 460,95 | I13: =+H13*G13 -> 1152375
A14: 5 | C14: PROD. MEDICO/FARMACEUTICOS/LAB | D14: 252 | E14: ALIMENTACION ENTERAL X 1000 ML TIPO GLUCERNA RTH 1,5 KCAL | F14: UNIDAD | G14: 1000 | H14: 989 | I14: =+H14*G14 -> 989000
A15: 6 | C15: PROD. MEDICO/FARMACEUTICOS/LAB | D15: 252 | E15: AMIKACINA 500 MG AMPOLLA | F15: UNIDAD | G15: 5000 | H15: 58 | I15: =+H15*G15 -> 290000
A16: 7 | C16: PROD. MEDICO/FARMACEUTICOS/LAB | D16: 252 | E16: ANFOTERICINA B VIAL 50 MG | F16: UNIDAD | G16: 1200 | H16: 609.6 | I16: =+H16*G16 -> 731520
A17: 8 | C17: PROD. MEDICO/FARMACEUTICOS/LAB | D17: 252 | E17: BETAMETASONA G 12 MG ( 6 MG ACETATO/6 MG FOSFATO ) AMPOLLA | F17: UNIDAD | G17: 5000 | H17: 120 | I17: =+H17*G17 -> 600000
A18: 9 | C18: PROD. MEDICO/FARMACEUTICOS/LAB | D18: 252 | E18: BUDESONIDE SOLUCION 0,1% | F18: UNIDAD | G18: 300 | H18: 225 | I18: =+H18*G18 -> 67500
A19: 10 | C19: PROD. MEDICO/FARMACEUTICOS/LAB | D19: 252 | E19: CLONIDINA AMPOLLAS | F19: UNIDAD | G19: 1000 | H19: 42 | I19: =+H19*G19 -> 42000
A20: 11 | C20: PROD. MEDICO/FARMACEUTICOS/LAB | D20: 252 | E20: COLISTINA 100 MG FCO AMPOLLA | F20: UNIDAD | G20: =120*100 -> 12000 | H20: 405 | I20: =+H20*G20 -> 4860000
A21: 12 | C21: PROD. MEDICO/FARMACEUTICOS/LAB | D21: 252 | E21: DOBUTAMINA AMPOLLA | F21: UNIDAD | G21: 500 | H21: 304 | I21: =+H21*G21 -> 152000
A22: 13 | C22: PROD. MEDICO/FARMACEUTICOS/LAB | D22: 252 | E22: DOPAMINA 200 MG AMPOLLA | F22: UNIDAD | G22: 3000 | H22: 85 | I22: =+H22*G22 -> 255000
A23: 14 | C23: PROD. MEDICO/FARMACEUTICOS/LAB | D23: 252 | E23: ENOXAPARINA 40 MG AMPOLLA PRELLENA | F23: UNIDAD | G23: 10000 | H23: 1200 | I23: =+H23*G23 -> 12000000
A24: 15 | C24: PROD. MEDICO/FARMACEUTICOS/LAB | D24: 252 | E24: ENOXAPARINA 80 MG AMPOLLA PRELLENADA | F24: UNIDAD | G24: 2000 | H24: 1500 | I24: =+H24*G24 -> 3000000
A25: 16 | C25: PROD. MEDICO/FARMACEUTICOS/LAB | D25: 252 | E25: FENOBARBITAL 100 MG/ML AMPOLLA | F25: UNIDAD | G25: 4000 | H25: 324.02 | I25: =+H25*G25 -> 1296080
A26: 17 | C26: PROD. MEDICO/FARMACEUTICOS/LAB | D26: 252 | E26: FENTANILO 250 MCG INYECTABLE | F26: UNIDAD | G26: 30000 | H26: 387,20 | I26: =+H26*G26 -> 11616000
A27: 18 | C27: PROD. MEDICO/FARMACEUTICOS/LAB | D27: 252 | E27: FLUCONAZOL 100 MG COMPRIMIDOS | F27: UNIDAD | G27: 1000 | H27: 31.14 | I27: =+H27*G27 -> 31140
A28: 19 | C28: PROD. MEDICO/FARMACEUTICOS/LAB | D28: 252 | E28: FLUCONAZOL 200 MG SACHET 100 ML | F28: UNIDAD | G28: 2000 | H28: 554 | I28: =+H28*G28 -> 1108000
A29: 20 | C29: PROD. MEDICO/FARMACEUTICOS/LAB | D29: 252 | E29: HEPARINA SODICA 5000 UI FCO AMPOLLA | F29: UNIDAD | G29: 5000 | H29: 699 | I29: =+H29*G29 -> 3495000
A30: 21 | C30: PROD. MEDICO/FARMACEUTICOS/LAB | D30: 252 | E30: INMUNOGLOBULINAS FRAGMENTOS ANTI SARS-COV 2 30MG/ML TIPO COVIFAB | F30: UNIDAD | G30: 375 | H30: 28700 | I30: =+H30*G30 -> 10762500
A31: 22 | C31: PROD. MEDICO/FARMACEUTICOS/LAB | D31: 252 | E31: KETAMINA 50MG/ML FCO AMPOLLA | F31: UNIDAD | G31: 6000 | H31: 2013 | I31: =+H31*G31 -> 12078000
A32: 23 | C32: PROD. MEDICO/FARMACEUTICOS/LAB | D32: 252 | E32: LORAZEPAM 4 MG/2ML AMPOLLA | F32: UNIDAD | G32: 15000 | H32: 280 | I32: =+H32*G32 -> 4200000
A33: 24 | C33: PROD. MEDICO/FARMACEUTICOS/LAB | D33: 252 | E33: MEROPENEM 1000MG FCO AMPOLLA | F33: UNIDAD | G33: 500 | H33: 528 | I33: =+H33*G33 -> 264000
A34: 25 | C34: PROD. MEDICO/FARMACEUTICOS/LAB | D34: 252 | E34: METILPREDNISONA 4MG/ML AMPOLLA | F34: UNIDAD | G34: 5000 | H34: 17 | I34: =+H34*G34 -> 85000
A35: 26 | C35: PROD. MEDICO/FARMACEUTICOS/LAB | D35: 252 | E35: METILPREDNISONA 40 MG COMPRIMIDO | F35: UNIDAD | G35: 2500 | H35: 47 | I35: =+H35*G35 -> 117500
A36: 27 | C36: PROD. MEDICO/FARMACEUTICOS/LAB | E36: METILPREDNISOLONA 500 MG FCO AMPOLLA | F36: UNIDAD | G36: 200 | H36: 617 | I36: =+H36*G36 -> 123400
A37: 28 | C37: PROD. MEDICO/FARMACEUTICOS/LAB | D37: 252 | E37: NITROPRUSIATO SODIO 50 MG VIAL | F37: UNIDAD | G37: 500 | H37: 650 | I37: =+H37*G37 -> 325000
A38: 29 | C38: PROD. MEDICO/FARMACEUTICOS/LAB | D38: 252 | E38: Olanzapina 10 mg. Comprimidos | F38: UNIDAD | G38: 3000 | H38: 27 | I38: =+H38*G38 -> 81000
A39: 30 | C39: PROD. MEDICO/FARMACEUTICOS/LAB | D39: 252 | E39: PARACETAMOL 500 MG COMPRIMIDO | F39: UNIDAD | G39: 200000 | H39: 4 | I39: =+H39*G39 -> 800000
A40: 31 | C40: PROD. MEDICO/FARMACEUTICOS/LAB | D40: 252 | E40: PROPOFOL 1% AMPOLLAS X 20 ML | F40: UNIDAD | G40: 25000 | H40: 859.1 | I40: =+H40*G40 -> 21477500
A41: 32 | C41: PROD. MEDICO/FARMACEUTICOS/LAB | D41: 252 | E41: SOLUCION FISIOLOGICA 0,9% SACHET X 100 ML | F41: UNIDAD | G41: 30000 | H41: 48 | I41: =+H41*G41 -> 1440000
A42: 33 | C42: PROD. MEDICO/FARMACEUTICOS/LAB | D42: 252 | E42: SOLUCION FISIOLOGICA 0,9 % SACHET X 500 ML | F42: UNIDAD | G42: 70000 | H42: 51.18 | I42: =+H42*G42 -> 3582600
...

Sheet  NotaPedido FARMACIA
A1: NOTA DE PEDIDO | J1: N° | K1: 39/2021
A3: JURISDICCIÓN: | D3: 040 - Ministerio de Salud
A4: SAF: | D4: 011 - Direccion Provincial de Administración - Ministerio de Salud
A5: UNIDAD EJECUTORA: | D5: 469 - DIRECCION PROVINCIAL DE FARMACIA E INSUMOS
A6: DEPENDENCIA SOLICITANTE: | D6: 469 - DIRECCION PROVINCIAL DE FARMACIA E INSUMOS
A7: PERIODO UTILIZACIÓN: | D7: 3° TRIMESTRE
A8: OBJETO: | D8: Adquisicion de Medicamentos para la atencion de pacientes COVID-19
A10: Ítem | B10: Codigo Item | C10: DESCRIPCIÓN | H10: Adjunta Detalle Técnico | I10: Unidad Medida | J10: Precio Unitario Estimado | K10: Cantidad Solicitada
A12: 1 | C12: =+'Necesidades Trimestrales '!E10 -> ACICLOVIR 500 MG FCO AMPOLLA | H12: no | I12: UNIDAD | J12: =+'Necesidades Trimestrales '!H10 -> 384 | K12: =+'Necesidades Trimestrales '!G10 -> 20 | M12: =+K12*J12 -> 7680
A13: 2 | C13: =+'Necesidades Trimestrales '!E11 -> ACIDO ACETIL SALICILICO 500 MG COMPRIMIDO | H13: no | I13: UNIDAD | J13: =+'Necesidades Trimestrales '!H11 -> 2.23 | K13: =+'Necesidades Trimestrales '!G11 -> 4800 | M13: =+K13*J13 -> 10704
A14: 3 | C14: =+'Necesidades Trimestrales '!E12 -> AGUA DESTILADA EN SACHET X 500 ML | H14: no | I14: UNIDAD | J14: =+'Necesidades Trimestrales '!H12 -> 140 | K14: =+'Necesidades Trimestrales '!G12 -> 10000 | M14: =+K14*J14 -> 1400000
A15: 4 | C15: =+'Necesidades Trimestrales '!E13 -> ALIMENTACION ENTERAL X 500 ML TIPO DIBEN | H15: no | I15: UNIDAD | J15: =+'Necesidades Trimestrales '!H13 -> 460,95 | K15: =+'Necesidades Trimestrales '!G13 -> 2500 | M15: =+K15*J15 -> 1152375
A16: 5 | C16: =+'Necesidades Trimestrales '!E14 -> ALIMENTACION ENTERAL X 1000 ML TIPO GLUCERNA RTH 1,5 KCAL | H16: no | I16: UNIDAD | J16: =+'Necesidades Trimestrales '!H14 -> 989 | K16: =+'Necesidades Trimestrales '!G14 -> 1000 | M16: =+K16*J16 -> 989000
A17: 6 | C17: =+'Necesidades Trimestrales '!E15 -> AMIKACINA 500 MG AMPOLLA | H17: no | I17: UNIDAD | J17: =+'Necesidades Trimestrales '!H15 -> 58 | K17: =+'Necesidades Trimestrales '!G15 -> 5000 | M17: =+K17*J17 -> 290000
A18: 7 | C18: =+'Necesidades Trimestrales '!E16 -> ANFOTERICINA B VIAL 50 MG | H18: no | I18: UNIDAD | J18: =+'Necesidades Trimestrales '!H16 -> 609.6 | K18: =+'Necesidades Trimestrales '!G16 -> 1200 | M18: =+K18*J18 -> 731520
A19: 8 | C19: =+'Necesidades Trimestrales '!E17 -> BETAMETASONA G 12 MG ( 6 MG ACETATO/6 MG FOSFATO ) AMPOLLA | H19: no | I19: UNIDAD | J19: =+'Necesidades Trimestrales '!H17 -> 120 | K19: =+'Necesidades Trimestrales '!G17 -> 5000 | M19: =+K19*J19 -> 600000
A20: 9 | C20: =+'Necesidades Trimestrales '!E18 -> BUDESONIDE SOLUCION 0,1% | H20: no | I20: UNIDAD | J20: =+'Necesidades Trimestrales '!H18 -> 225 | K20: =+'Necesidades Trimestrales '!G18 -> 300 | M20: =+K20*J20 -> 67500
A21: 10 | C21: =+'Necesidades Trimestrales '!E19 -> CLONIDINA AMPOLLAS | H21: no | I21: UNIDAD | J21: =+'Necesidades Trimestrales '!H19 -> 42 | K21: =+'Necesidades Trimestrales '!G19 -> 1000 | M21: =+K21*J21 -> 42000
A22: 11 | C22: =+'Necesidades Trimestrales '!E20 -> COLISTINA 100 MG FCO AMPOLLA | H22: no | I22: UNIDAD | J22: =+'Necesidades Trimestrales '!H20 -> 405 | K22: =+'Necesidades Trimestrales '!G20 -> 12000 | M22: =+K22*J22 -> 4860000
A23: 12 | C23: =+'Necesidades Trimestrales '!E21 -> DOBUTAMINA AMPOLLA | H23: no | I23: UNIDAD | J23: =+'Necesidades Trimestrales '!H21 -> 304 | K23: =+'Necesidades Trimestrales '!G21 -> 500 | M23: =+K23*J23 -> 152000
... A39: 28 | C39: =+'Necesidades Trimestrales '!E37 -> NITROPRUSIATO SODIO 50 MG VIAL | H39: no | I39: UNIDAD | J39: =+'Necesidades Trimestrales '!H37 -> 650 | K39: =+'Necesidades Trimestrales '!G37 -> 500 | M39: =+K39*J39 -> 325000
A40: 29 | C40: Olanzapina 10 ml. Comprimidos | H40: no | I40: UNIDAD | J40: 27 | K40: 3000 | M40: =+K40*J40 -> 81000
A41: 30 | C41: =+'Necesidades Trimestrales '!E39 -> PARACETAMOL 500 MG COMPRIMIDO | H41: no | I41: UNIDAD | J41: =+'Necesidades Trimestrales '!H39 -> 4 | K41: =+'Necesidades Trimestrales '!G39 -> 200000 | M41: =+K41*J41 -> 800000
A42: 31 | C42: =+'Necesidades Trimestrales '!E40 -> PROPOFOL 1% AMPOLLAS X 20 ML | H42: no | I42: UNIDAD | J42: =+'Necesidades Trimestrales '!H40 -> 859.1 | K42: =+'Necesidades Trimestrales '!G40 -> 25000 | M42: =+K42*J42 -> 21477500
A43: 32 | C43: =+'Necesidades Trimestrales '!E41 -> SOLUCION FISIOLOGICA 0,9% SACHET X 100 ML | H43: no | I43: UNIDAD | J43: =+'Necesidades Trimestrales '!H41 -> 48 | K43: =+'Necesidades Trimestrales '!G41 -> 30000 | M43: =+K43*J43 -> 1440000
A44: 33 | C44: =+'Necesidades Trimestrales '!E42 -> SOLUCION FISIOLOGICA 0,9 % SACHET X 500 ML | H44: no | I44: UNIDAD | J44: =+'Necesidades Trimestrales '!H42 -> 51.18 | K44: =+'Necesidades Trimestrales '!G42 -> 70000 | M44: =+K44*J44 -> 3582600
A45: 34 | C45: =+'Necesidades Trimestrales '!E43 -> SUCCINILCOLINA 500 MG FCO AMP | H45: no | I45: UNIDAD | J45: =+'Necesidades Trimestrales '!H43 -> 242 | K45: =+'Necesidades Trimestrales '!G43 -> 1000 | M45: =+K45*J45 -> 242000
A46: 35 | C46: =+'Necesidades Trimestrales '!E44 -> TIOPENTAL SODICO 1GR FRASCO AMPOLLA | H46: no | I46: UNIDAD | J46: =+'Necesidades Trimestrales '!H44 -> 890 | K46: =+'Necesidades Trimestrales '!G44 -> 9000 | M46: =+K46*J46 -> 8010000
A47: 36 | C47: =+'Necesidades Trimestrales '!E45 -> VECURONIO BROMURO 10 MG AMPOLLA | H47: no | I47: UNIDAD | J47: =+'Necesidades Trimestrales '!H45 -> 634,68 | K47: =+'Necesidades Trimestrales '!G45 -> 22000 | M47: =+K47*J47 -> 13962960
A48: Costo total estimado: CIENTO VEINTE MILLONES SEISCIENTOS CINCUENTA Y CINCO MIL CUATROCIENTOS CINCUENTA Y NUEVE CON 00/100 | J48: =SUM(M12:M47) -> 120655459

Sheet APG FARMACIA 
A1: EJERCICIO: | D1: 2021 | P1: AUTORIZACION PARA GASTAR
A4: JURISDICCIÓN: | G4: 040 - Ministerio de Salud
A5: SAF: | G5: 011- Dirección Provincial de Administración
A6: UNIDAD EJECUTORA: | G6: 469 - DIRECCION PROVINCIAL DE FARMACIA E INSUMOS
A7: DEPENDENCIA SOLICITANTE: | G7: 469 - DIRECCION PROVINCIAL DE FARMACIA E INSUMOS
A8: AUTORIZACIÓN:
A9: Señor Jefe de Servicio Administrativo Financiero:
A10: Autorizo la realización de los trámites correspondientes, a fin de proveer a este Organismo los bienes que se detallan en Nota de pedido y Entrega N°39/2021, afectando la erogación resultante a los créditos presupuestarios aprobados a favor de esta Unidad Ejecutora, conforme al siguiente detalle:
A12: IMPUTACIÓN PRESUPUESTARIA
A13: CÓDIGO | O13: DENOMINACIÓN DE LA PARTIDA PRESUPUESTARIA | Q13: IMPORTE
A14: PR | B14: SB | C14: PY | D14: AC | E14: OB | F14: UG | G14: FIN | H14: FUN | I14: I | J14: P | K14: P | L14: SubP | M14: M | N14: FF
A15: 30 | D15: 1 | F15: 4901 | G15: 3 | H15: 1 | I15: 2 | J15: 5 | K15: 2 | M15: 1 | N15: 1.1 | O15: Productos Farmacéuticos y Medicinales | Q15: =+'Necesidades Trimestrales '!I46 -> 120655459
A21: TOTAL DE PESOS: CIENTO VEINTE MILLONES SEISCIENTOS CINCUENTA Y CINCO MIL CUATROCIENTOS CINCUENTA Y NUEVE CON 00/100 | Q21: =SUM(Q15:Q20) -> 120655459
A23: JUSTIFICACIÓN:
A24: Adquisicion de Medicamentos para la atencion de pacientes COVID-19
