Workbook

Sheet Necesidades Trimestrales
A2: Pedido de Necesidades Trimestrales
A4: JURISDICCION: | C4: 12 -Ministerio de Gobierno, Justicia y Derechos Humanos.
A5: SAF N°: | C5: 06 - Secretaria de Gestion Administrativa del Ministerio de Gobierno, Justicia y Derechos Humanos
A6: EJERCICIO: | C6: 2022
A7: TRIMESTRE: | C7: 2do. TRIMESTRE
A9: ID | B9: CODIGO ITEM | C9: RUBRO DE COMPRA | D9: I.P.P. | E9: DESCRIPCION | F9: UNIDAD DE MEDIDA | G9: CANTIDAD | H9: PRECIO UNITARIO ESTIMADO | I9: IMPORTE TOTAL ESTIMADO | J9: IMPRESORA MARCA | K9: IMPRESORA MODELO
A10: 1 | B10: 2.9.6-401.1910 | C10: REPUESTOS | D10: 2.9.2 | E10: CARTUCHOS DE TONER; CODIGO: 101 D101S, USO: SAMSUNG | F10: UNIDAD | G10: 5 | H10: 10000 | I10: =G10*H10 -> 50000 | J10: SAMSUNG | K10: ML-2165w
A11: 2 | B11: 2.9.6-1355.1503 | C11: REPUESTOS | D11: 2.9.2 | E11: CARTUCHOS DE TINTA; CODIGO: HP 60, USO: HEWLETT PACKARD | F11: UNIDAD | G11: 2 | H11: 5000 | I11: =G11*H11 -> 10000 | J11: HEWLETT-PACKARD | K11: Deskjet F4480
A12: 3 | B12: 2.9.6-1355.1503 | C12: REPUESTOS | D12: 2.9.2 | E12: CARTUCHOS DE TINTA; CODIGO: HP 60, USO: HEWLETT PACKARD | F12: UNIDAD | G12: 2 | H12: 6000 | I12: =G12*H12 -> 12000 | J12: HEWLETT-PACKARD | K12: Deskjet F4480
A13: 4 | B13: 2.9.6-1355.1938 | C13: REPUESTOS | D13: 2.9.2 | E13: CARTUCHOS DE TINTA; CODIGO: T664120, USO: EPSON | F13: UNIDAD | G13: 2 | H13: 2000 | I13: =G13*H13 -> 4000 | J13: EPSON | K13: Eco Tank L380
A14: 5 | B14: 2.9.6-1355.1939 | C14: REPUESTOS | D14: 2.9.2 | E14: CARTUCHOS DE TINTA; CODIGO: T664220, USO: EPSON | F14: UNIDAD | G14: 2 | H14: 1500 | I14: =G14*H14 -> 3000 | J14: EPSON | K14: Eco Tank L380
A15: 6 | B15: 2.9.6-1355.1940 | C15: REPUESTOS | D15: 2.9.2 | E15: CARTUCHOS DE TINTA; CODIGO: T664320, USO: EPSON | F15: UNIDAD | G15: 2 | H15: 1500 | I15: =G15*H15 -> 3000 | J15: EPSON | K15: Eco Tank L380
A16: 7 | B16: 2.9.6-1355.1941 | C16: REPUESTOS | D16: 2.9.2 | E16: CARTUCHOS DE TINTA; CODIGO: T664420, USO: EPSON | F16: UNIDAD | G16: 2 | H16: 1500 | I16: =G16*H16 -> 3000 | J16: EPSON | K16: Eco Tank L380
A17: 8 | B17: 2.9.6-401.2378 | C17: REPUESTOS | D17: 2.9.2 | E17: CARTUCHOS DE TONER; CODIGO: W1105A, USO: HEWLETT PACKARD | F17: UNIDAD | G17: 26 | H17: 3000 | I17: =G17*H17 -> 78000 | J17: HEWLETT-PACKARD | K17: LaserJet 107w
A18: 9 | B18: 2.9.6-1355.1789 | C18: REPUESTOS | D18: 2.9.2 | E18: CARTUCHOS DE TINTA; CODIGO: 35A, USO: HEWLETT PACKARD | F18: UNIDAD | G18: 1 | H18: 3000 | I18: =G18*H18 -> 3000 | J18: HEWLETT-PACKARD | K18: LaserJet Pro P1005
A19: 10 | B19: 2.9.6-401.2228 | C19: REPUESTOS | D19: 2.9.2 | E19: CARTUCHOS DE TONER; CODIGO: CF217A, USO: HP LASERJET MFP | F19: UNIDAD | G19: 15 | H19: 3000 | I19: =G19*H19 -> 45000 | J19: HEWLETT-PACKARD | K19: M102W
A20: 11 | B20: 2.9.6-401.1486 | C20: REPUESTOS | D20: 2.9.2 | E20: CARTUCHOS DE TONER; CODIGO: HP 53A, USO: HP | F20: UNIDAD | G20: 20 | H20: 2000 | I20: =G20*H20 -> 40000 | J20: HEWLETT-PACKARD | K20: LaserJet P2015d
A21: 12 | B21: 2.9.6-401.2377 | C21: REPUESTOS | D21: 2.9.2 | E21: CARTUCHOS DE TONER; CODIGO: CF279A, USO: HEWLETT PACKARD | F21: UNIDAD | G21: 40 | H21: 1300 | I21: =G21*H21 -> 52000 | J21: HEWLETT-PACKARD | K21: LaserJet Pro M12W
... A29: 20 | B29: 2.9.6-401.1765 | C29: REPUESTOS | D29: 2.9.2 | E29: CARTUCHOS DE TONER; CODIGO: 106R01531, USO: XEROX | F29: UNIDAD | G29: 3 | H29: 2500 | I29: =G29*H29 -> 7500 | J29: XEROX | K29: WORKCENTRE 3550
B32: Especificidades de los Items:
B33: ÍTEM N° 1: | C33: TONER MLT -D101S- NEGRO-ORIGINAL
B34: ÍTEM N° 2: | C34: TINTA HP 60 NEGRA- ORIGINAL
B35: ÍTEM N° 3: | C35: TINTA HP 60 MULTICOLOR- ORIGINAL
B36: ÍTEM N° 4: | C36: TINTA PARA IMPRESORA EPSON N° 664. NEGRO- ORIGINAL
B37: ÍTEM N° 5: | C37: TINTA PARA IMPRESORA EPSON N° 664. CIAN- ORIGINAL
B38: ÍTEM N° 6: | C38: TINTA PARA IMPRESORA EPSON N° 664. MAGENTA.- ORIGINAL
B39: ÍTEM N° 7: | C39: TINTA PARA IMPRESORA EPSON N° 664. YELLOW- ORIGINAL
B40: ÍTEM N° 8: | C40: TONER P/HP W1105 A- NEGRO-ALTERNATIVO
B41: ÍTEM N° 9: | C41: TONER P/HP 1005- NEGRO- ALTERNATIVO
B42: ÍTEM N° 10: | C42: TONER P/HP M102W- N° 17A- NEGRO- ALTERNATIVO
B43: ÍTEM N° 11: | C43: TONER P/HP N° 53A- NEGRO- ALTERNATIVO
B44: ÍTEM N° 12: | C44: TONER P/HP N° 79A- NEGRO-ALTERNATIVO
... B52: ÍTEM N° 20: | C52: TONER P/FOTOCOPIADORA XEROX WORKCENTRE 3550.-
B55: Plazos y lugares de entrega:
B56: a) LUGAR DE ENTREGA: Dirección Prov. de Gestion Administrativa- sito en Ayacucho N° 502 (Edificio Ex I.P.P.S) 2do Piso - De 08 a 12 horas. b) FORMA DE LA ENTREGA: Libre de flete, acarreo y embalaje, como así también, de todo riesgo de pérdida o destrucción total o parcial, por causas ajenas a la Institución. c) PLAZO DE ENTREGA: El Oferente deberá establecer plazo de entrega de los elementos cotizados, debiendo ser expresado en días hábiles; que no podrá ser superior a cinco (5) días hábiles, contados a partir de la recepción de la comunicación prevista en el Artículo 80 del Anexo I - Reglamento Parcial N° 2 de la ley 4938.
B58: Calidad Minima esperada:
B59: Que cumpla con lo solicitado y condiciones de calidad adjuntas, productos de muy buena calidad.-
B60: Mantenimiento:
B61: 30 (treinta) días habiles
B62: Forma de Pago:
...

Sheet  NotaPedido
A1: NOTA DE PEDIDO
F2: N° | G2: 26/2022
A4: JURISDICCIÓN: | C4: ='Necesidades Trimestrales'!C4 -> 12 -Ministerio de Gobierno, Justicia y Derechos Humanos.
A5: SAF: | C5: ='Necesidades Trimestrales'!C5 -> 06 - Secretaria de Gestion Administrativa del Ministerio de Gobierno, Justicia y Derechos Humanos
A6: UNIDAD EJECUTORA: | C6: Ministerio de Gobierno, Justicia y Derechos Humanos.
A7: DEPENDENCIA SOLICITANTE: | C7: Ministerio de Gob. J. y D.H.- Secretaria de la Mujer, Generos y Diversidad- Direc. Prov. De Accion Coop. Y Mutuales- Direccion Prov. de Derechos Humanos-Dirección de Justicia- Direcc. Prov. Del Registro Civil- Direcc. Insp. Personas Juridicas- Secretaria de Asuntos Municipales.
A8: PERIODO UTILIZACIÓN: | C8: 2022 - 2do Trimestre
A9: OBJETO: | C9: ADQ. DE TINTAS Y TONERS DESTINADOS A LAS DISTINTAS DEPENDENCIAS DEL MINISTERIO DE GOBIERNO JUSTICIA Y DERECHOS HUMANOS, PARA EL 2do TRIMESTRE DEL AÑO 2022.
A11: Ítem | B11: Codigo Item | C11: DESCRIPCIÓN | D11: Adjunta Detalle Técnico | E11: Unidad Medida | F11: Precio Unitario Estimado | G11: Cantidad Solicitada
A13: ='Necesidades Trimestrales'!A10 -> 1 | B13: ='Necesidades Trimestrales'!B10 -> 2.9.6-401.1910 | C13: ='Necesidades Trimestrales'!E10 -> CARTUCHOS DE TONER; CODIGO: 101 D101S, USO: SAMSUNG | D13: SI | E13: ='Necesidades Trimestrales'!F10 -> UNIDAD | F13: ='Necesidades Trimestrales'!H10 -> 10000 | G13: ='Necesidades Trimestrales'!G10 -> 5
A14: ='Necesidades Trimestrales'!A11 -> 2 | B14: ='Necesidades Trimestrales'!B11 -> 2.9.6-1355.1503 | C14: ='Necesidades Trimestrales'!E11 -> CARTUCHOS DE TINTA; CODIGO: HP 60, USO: HEWLETT PACKARD | D14: SI | E14: ='Necesidades Trimestrales'!F11 -> UNIDAD | F14: ='Necesidades Trimestrales'!H11 -> 5000 | G14: ='Necesidades Trimestrales'!G11 -> 2
A15: ='Necesidades Trimestrales'!A12 -> 3 | B15: ='Necesidades Trimestrales'!B12 -> 2.9.6-1355.1503 | C15: ='Necesidades Trimestrales'!E12 -> CARTUCHOS DE TINTA; CODIGO: HP 60, USO: HEWLETT PACKARD | D15: SI | E15: ='Necesidades Trimestrales'!F12 -> UNIDAD | F15: ='Necesidades Trimestrales'!H12 -> 6000 | G15: ='Necesidades Trimestrales'!G12 -> 2
A16: ='Necesidades Trimestrales'!A13 -> 4 | B16: ='Necesidades Trimestrales'!B13 -> 2.9.6-1355.1938 | C16: ='Necesidades Trimestrales'!E13 -> CARTUCHOS DE TINTA; CODIGO: T664120, USO: EPSON | D16: SI | E16: ='Necesidades Trimestrales'!F13 -> UNIDAD | F16: ='Necesidades Trimestrales'!H13 -> 2000 | G16: ='Necesidades Trimestrales'!G13 -> 2
A17: ='Necesidades Trimestrales'!A14 -> 5 | B17: ='Necesidades Trimestrales'!B14 -> 2.9.6-1355.1939 | C17: ='Necesidades Trimestrales'!E14 -> CARTUCHOS DE TINTA; CODIGO: T664220, USO: EPSON | D17: SI | E17: ='Necesidades Trimestrales'!F14 -> UNIDAD | F17: ='Necesidades Trimestrales'!H14 -> 1500 | G17: ='Necesidades Trimestrales'!G14 -> 2
A18: ='Necesidades Trimestrales'!A15 -> 6 | B18: ='Necesidades Trimestrales'!B15 -> 2.9.6-1355.1940 | C18: ='Necesidades Trimestrales'!E15 -> CARTUCHOS DE TINTA; CODIGO: T664320, USO: EPSON | D18: SI | E18: ='Necesidades Trimestrales'!F15 -> UNIDAD | F18: ='Necesidades Trimestrales'!H15 -> 1500 | G18: ='Necesidades Trimestrales'!G15 -> 2
A19: ='Necesidades Trimestrales'!A16 -> 7 | B19: ='Necesidades Trimestrales'!B16 -> 2.9.6-1355.1941 | C19: ='Necesidades Trimestrales'!E16 -> CARTUCHOS DE TINTA; CODIGO: T664420, USO: EPSON | D19: SI | E19: ='Necesidades Trimestrales'!F16 -> UNIDAD | F19: ='Necesidades Trimestrales'!H16 -> 1500 | G19: ='Necesidades Trimestrales'!G16 -> 2
A20: ='Necesidades Trimestrales'!A17 -> 8 | B20: ='Necesidades Trimestrales'!B17 -> 2.9.6-401.2378 | C20: ='Necesidades Trimestrales'!E17 -> CARTUCHOS DE TONER; CODIGO: W1105A, USO: HEWLETT PACKARD | D20: SI | E20: ='Necesidades Trimestrales'!F17 -> UNIDAD | F20: ='Necesidades Trimestrales'!H17 -> 3000 | G20: ='Necesidades Trimestrales'!G17 -> 26
A21: ='Necesidades Trimestrales'!A18 -> 9 | B21: ='Necesidades Trimestrales'!B18 -> 2.9.6-1355.1789 | C21: ='Necesidades Trimestrales'!E18 -> CARTUCHOS DE TINTA; CODIGO: 35A, USO: HEWLETT PACKARD | D21: SI | E21: ='Necesidades Trimestrales'!F18 -> UNIDAD | F21: ='Necesidades Trimestrales'!H18 -> 3000 | G21: ='Necesidades Trimestrales'!G18 -> 1
A22: ='Necesidades Trimestrales'!A19 -> 10 | B22: ='Necesidades Trimestrales'!B19 -> 2.9.6-401.2228 | C22: ='Necesidades Trimestrales'!E19 -> CARTUCHOS DE TONER; CODIGO: CF217A, USO: HP LASERJET MFP | D22: SI | E22: ='Necesidades Trimestrales'!F19 -> UNIDAD | F22: ='Necesidades Trimestrales'!H19 -> 3000 | G22: ='Necesidades Trimestrales'!G19 -> 15
A23: ='Necesidades Trimestrales'!A20 -> 11 | B23: ='Necesidades Trimestrales'!B20 -> 2.9.6-401.1486 | C23: ='Necesidades Trimestrales'!E20 -> CARTUCHOS DE TONER; CODIGO: HP 53A, USO: HP | D23: SI | E23: ='Necesidades Trimestrales'!F20 -> UNIDAD | F23: ='Necesidades Trimestrales'!H20 -> 2000 | G23: ='Necesidades Trimestrales'!G20 -> 20
A24: ='Necesidades Trimestrales'!A21 -> 12 | B24: ='Necesidades Trimestrales'!B21 -> 2.9.6-401.2377 | C24: ='Necesidades Trimestrales'!E21 -> CARTUCHOS DE TONER; CODIGO: CF279A, USO: HEWLETT PACKARD | D24: SI | E24: ='Necesidades Trimestrales'!F21 -> UNIDAD | F24: ='Necesidades Trimestrales'!H21 -> 1300 | G24: ='Necesidades Trimestrales'!G21 -> 40
... A32: ='Necesidades Trimestrales'!A29 -> 20 | B32: ='Necesidades Trimestrales'!B29 -> 2.9.6-401.1765 | C32: ='Necesidades Trimestrales'!E29 -> CARTUCHOS DE TONER; CODIGO: 106R01531, USO: XEROX | D32: SI | E32: ='Necesidades Trimestrales'!F29 -> UNIDAD | F32: ='Necesidades Trimestrales'!H29 -> 2500 | G32: ='Necesidades Trimestrales'!G29 -> 3
A33: Costo total estimado: Pesos Quinientos Treinta y Un Mil con 00/100.- | F33: =SUMPRODUCT(F13:F32*G13:G32) -> 531000
B37: DETALLE TECNICO de los Items:
B38: ÍTEM N° 1: | C38: TONER MLT -D101S- NEGRO-ORIGINAL
B39: ÍTEM N° 2: | C39: TINTA HP 60 NEGRA- ORIGINAL
B40: ÍTEM N° 3: | C40: TINTA HP 60 MULTICOLOR- ORIGINAL
B41: ÍTEM N° 4: | C41: TINTA PARA IMPRESORA EPSON N° 664. NEGRO- ORIGINAL
B42: ÍTEM N° 5: | C42: TINTA PARA IMPRESORA EPSON N° 664. CIAN- ORIGINAL
B43: ÍTEM N° 6: | C43: TINTA PARA IMPRESORA EPSON N° 664. MAGENTA.- ORIGINAL
B44: ÍTEM N° 7: | C44: TINTA PARA IMPRESORA EPSON N° 664. YELLOW- ORIGINAL
B45: ÍTEM N° 8: | C45: TONER P/HP W1105 A- NEGRO-ALTERNATIVO
B46: ÍTEM N° 9: | C46: TONER P/HP 1005- NEGRO- ALTERNATIVO
B47: ÍTEM N° 10: | C47: TONER P/HP M102W- N° 17A- NEGRO- ALTERNATIVO
B48: ÍTEM N° 11: | C48: TONER P/HP N° 53A- NEGRO- ALTERNATIVO
B49: ÍTEM N° 12: | C49: TONER P/HP N° 79A- NEGRO-ALTERNATIVO
... B57: ÍTEM N° 20: | C57: TONER P/FOTOCOPIADORA XEROX WORKCENTRE 3550.-

Sheet APG
A1: EJERCICIO: | D1: ='Necesidades Trimestrales'!C6 -> 2022 | P1: AUTORIZACION PARA GASTAR
A4: JURISDICCIÓN: | G4: =' NotaPedido'!C4 -> 12 -Ministerio de Gobierno, Justicia y Derechos Humanos.
A5: SAF: | G5: =' NotaPedido'!C5 -> 06 - Secretaria de Gestion Administrativa del Ministerio de Gobierno, Justicia y Derechos Humanos
A6: UNIDAD EJECUTORA: | G6: =' NotaPedido'!C6 -> Ministerio de Gobierno, Justicia y Derechos Humanos.
A7: DEPENDENCIA SOLICITANTE: | G7: Ministerio de Gob. J. y D.H.- Secretaria de la Mujer, Generos y Diversidad- Direc. Prov. De Accion Coop. Y Mutuales- Direccion Prov. de Derechos Humanos-Dirección de Justicia- Direcc. Prov. Del Registro Civil- Direcc. Insp. Personas Juridicas- Secretaria de Asuntos Municipales.
A8: AUTORIZACIÓN:
A9: Señor Jefe de Servicio Administrativo Financiero:
A10: ="Autorizo la realización de los trámites correspondientes, a fin de proveer a este Organismo los bienes y/o servicios que se detallan en Nota de Pedido N° " & ' NotaPedido'!G2&", afectando la erogación resultante a los créditos presupuestarios aprobados a favor de esta Unidad Ejecutora, conforme al siguiente detalle:" -> Autorizo la realización de los trámites correspondientes, a fin de proveer a este Organismo los bienes y/o servicios que se detallan en Nota de Pedido N° 26/2022, afectando la erogación resultante a los créditos presupuestarios aprobados a favor de esta Unidad Ejecutora, conforme al siguiente detalle:
A12: IMPUTACIÓN PRESUPUESTARIA
A13: CÓDIGO | O13: DENOMINACIÓN DE LA PARTIDA PRESUPUESTARIA | Q13: IMPORTE
A14: PR | B14: SB | C14: PY | D14: AC | E14: OB | F14: UG | G14: FIN | H14: FUN | I14: I | J14: P | K14: P | L14: SubP | M14: M | N14: FF
A15: 1 | B15: 0 | C15: 0 | D15: 1 | E15: 0 | F15: 4901 | G15: 1 | H15: 3 | I15: 2 | J15: 9 | K15: 2 | L15: 0 | M15: 1 | N15: 1.1 | O15: UTILES DE ESCRITORIO, OFICINA Y ENSEÑANZA | Q15: 30000
A16: 5 | B16: 0 | C16: 0 | D16: 1 | E16: 0 | F16: 4901 | G16: 3 | H16: 2 | I16: 2 | J16: 9 | K16: 2 | L16: 0 | M16: 1 | N16: 1.1 | O16: UTILES DE ESCRITORIO, OFICINA Y ENSEÑANZA | Q16: 14500
A17: 6 | B17: 0 | C17: 0 | D17: 1 | E17: 0 | F17: 4901 | G17: 3 | H17: 2 | I17: 2 | J17: 9 | K17: 2 | L17: 0 | M17: 1 | N17: 1.1 | O17: UTILES DE ESCRITORIO, OFICINA Y ENSEÑANZA | Q17: 45000
A18: 18 | B18: 0 | C18: 0 | D18: 1 | E18: 0 | F18: 4901 | G18: 3 | H18: 2 | I18: 2 | J18: 9 | K18: 2 | L18: 0 | M18: 1 | N18: 1.1 | O18: UTILES DE ESCRITORIO, OFICINA Y ENSEÑANZA | Q18: 30000
A19: 20 | B19: 0 | C19: 0 | D19: 1 | E19: 0 | F19: 4901 | G19: 3 | H19: 6 | I19: 2 | J19: 9 | K19: 2 | L19: 0 | M19: 1 | N19: 1.1 | O19: UTILES DE ESCRITORIO, OFICINA Y ENSEÑANZA | Q19: 28500
A20: 22 | B20: 0 | C20: 0 | D20: 1 | E20: 0 | F20: 4901 | G20: 1 | H20: 9 | I20: 2 | J20: 9 | K20: 2 | L20: 0 | M20: 1 | N20: 1.1 | O20: UTILES DE ESCRITORIO, OFICINA Y ENSEÑANZA | Q20: 330000
A21: 23 | B21: 0 | C21: 0 | D21: 1 | E21: 0 | F21: 4901 | G21: 1 | H21: 9 | I21: 2 | J21: 9 | K21: 2 | L21: 0 | M21: 1 | N21: 1.1 | O21: UTILES DE ESCRITORIO, OFICINA Y ENSEÑANZA | Q21: 3000
A22: 27 | B22: 0 | C22: 0 | D22: 1 | E22: 0 | F22: 4901 | G22: 1 | H22: 5 | I22: 2 | J22: 9 | K22: 2 | L22: 0 | M22: 1 | N22: 1.1 | O22: UTILES DE ESCRITORIO, OFICINA Y ENSEÑANZA | Q22: 50000
A26: TOTAL DE PESOS: Quinientos Treinta y Un Mil con 00/100.- | Q26: =SUM(Q15:Q25) -> 531000
A28: JUSTIFICACIÓN:
A29: =' NotaPedido'!C9 -> ADQ. DE TINTAS Y TONERS DESTINADOS A LAS DISTINTAS DEPENDENCIAS DEL MINISTERIO DE GOBIERNO JUSTICIA Y DERECHOS HUMANOS, PARA EL 2do TRIMESTRE DEL AÑO 2022.
A31: OBSERVACIONES:
