Workbook

Sheet SAF 011
B1: Pedido de Necesidades Trimestrales
A2: JURISDICCION: | C2: 040 - MINISTERIO DE SALUD
A3: SAF N°: | C3: 011 - DIRECCION PROVINCIAL DE ADMINISTRACION - MINISTERIO DE SALUD
A4: EJERCICIO: | C4: 2022
A5: TRIMESTRE: | C5: PRIMERO
A7: ID | B7: CODIGO ITEM | C7: RUBRO DE COMPRA | D7: I.P.P. | E7: DESCRIPCION | F7: UNIDAD DE MEDIDA | G7: SECRETARIA DE ADMINISTRACION | H7: TOTAL S.A. | I7: SMPyPS | J7: TOTAL SMPyPS | K7: DIR. LAB. CENTRAL | L7: TOTAL DE LAB CENTRAL | M7: BCO DE SANGRE | N7: TOTAL BANCO DE SANGRE | O7: APS | P7: TOTAL A.P.S. | Q7: DIR DE CANCER | R7: TOTAL DE DIR DE CANCER | S7: FARMACIA | T7: TOTAL FARMACIA | U7: ODONTOLOGIA | V7: TOTAL DE ODONTOLOG | W7: SAME | X7: TOTAL SAME | Y7: HPTAL MALBRAN | Z7: TOTAL HPTAL MALBRAN | AA7: MATERNIDAD E INFANCIA | AB7: TOTAL MATERNIDAD E INFANCIA | AC7: SASP | AD7: TOTAL SASP | AE7: SALUD Y MEDIO AMBIENTE | AF7: TOTAL SALUD Y MEDIO AMBIENTE | AG7: VECTORES Y ZOONOSIS | AH7: TOTAL DE VECT Y ZOON | AI7: CRONICAS | AJ7: TOTAL CRONICAS | AK7: CUR | AL7: TOTAL CUR | AM7: SPyGS | AN7: TOTAL SPyGS | AO7: SALUD MENTAL | AP7: TOTAL SALUD MENTAL | AQ7: AREAS Y DPAS | AR7: TOTAL DPAS | AS7: EPIDEMIOLOGIA | AT7: TOTAL EPIDEMIOLOGIA | AU7: AREA 1 | AV7: TOTAL AREA 1 | AW7: CANTIDAD TOTAL | AX7: PRECIO UNITARIO ESTIMADO | AY7: IMPORTE TOTAL ESTIMADO | AZ7: ESPECIFICACION TECNICA
A8: 1 | B8: 2.5.1-9009.29 | C8: QUIMICOS | D8: 2.5.1 | E8: ACIDOS; COMPUESTO QUIMICO: AC. CLORHIDRICO, ESTADO: SOLUCION, CALIDAD: PRO ANALISIS, CONCENTRACION/PUREZA: 37 %, PRESENTACION: ENVASE X 1 L | F8: UNIDAD | AE8: 2 | AF8: =+AE8*AX8 -> 2537.52 | AW8: =+AQ8+AO8+AM8+AK8+AI8+AG8+AE8+AC8+AA8+Y8+W8+U8+S8+Q8+O8+M8+K8+I8+AS8+G8+AU8 -> 2 | AX8: 1268.76 | AY8: =+AW8*AX8 -> 2537.52
A9: 2 | B9: 2.5.1-9009.99 | C9: QUIMICOS | D9: 2.5.1 | E9: ACIDOS; COMPUESTO QUIMICO: AC. SULFURICO, ESTADO: LIQUIDO, CALIDAD: PRO ANALISIS, CONCENTRACION/PUREZA: 98 %, PRESENTACION: ENVASE X 1 L | F9: UNIDAD | AE9: 2 | AF9: =+AE9*AX9 -> 2564.136 | AW9: =+AQ9+AO9+AM9+AK9+AI9+AG9+AE9+AC9+AA9+Y9+W9+U9+S9+Q9+O9+M9+K9+I9+AS9+G9+AU9 -> 2 | AX9: 1282.068 | AY9: =+AW9*AX9 -> 2564.136
A10: 3 | B10: 2.5.1-9013.22 | C10: QUIMICOS | D10: 2.5.1 | E10: ALDEHIDOS Y CETONAS; COMPUESTO QUIMICO: ACETONA, ESTADO: LIQUIDO, CALIDAD: PRO ANALISIS, CONCENTRACION/PUREZA: 99 %, PRESENTACION: ENVASE X 1 L | F10: UNIDAD | AE10: 2 | AF10: =+AE10*AX10 -> 14916.168 | AW10: =+AQ10+AO10+AM10+AK10+AI10+AG10+AE10+AC10+AA10+Y10+W10+U10+S10+Q10+O10+M10+K10+I10+AS10+G10+AU10 -> 2 | AX10: 7458.084 | AY10: =+AW10*AX10 -> 14916.168
A11: 4 | B11: 2.5.1-9015.66 | C11: QUIMICOS | D11: 2.5.1 | E11: BASES; COMPUESTO QUIMICO: HIDROXIDO DE POTASIO, ESTADO: SOLIDO, CALIDAD: FARMACOPEA, CONCENTRACION/PUREZA: 98 %, PRESENTACION: ENVASE X 1 Kg | F11: UNIDAD | AE11: 2 | AF11: =+AE11*AX11 -> 1567.2 | AW11: =+AQ11+AO11+AM11+AK11+AI11+AG11+AE11+AC11+AA11+Y11+W11+U11+S11+Q11+O11+M11+K11+I11+AS11+G11+AU11 -> 2 | AX11: 783.6 | AY11: =+AW11*AX11 -> 1567.2
A12: 5 | B12: 2.5.1-9015.52 | C12: QUIMICOS | D12: 2.5.1 | E12: BASES; COMPUESTO QUIMICO: HIDROXIDO DE SODIO, ESTADO: SOLUCION, CALIDAD: PRO ANALISIS, CONCENTRACION/PUREZA: 0,1 N, PRESENTACION: ENVASE X 1 L | F12: UNIDAD | AE12: 2 | AF12: =+AE12*AX12 -> 1495.2 | AW12: =+AQ12+AO12+AM12+AK12+AI12+AG12+AE12+AC12+AA12+Y12+W12+U12+S12+Q12+O12+M12+K12+I12+AS12+G12+AU12 -> 2 | AX12: 747.6 | AY12: =+AW12*AX12 -> 1495.2
A13: 6 | B13: 2.5.1-8976.27 | C13: QUIMICOS | D13: 2.5.1 | E13: HIDROCARBUROS; COMPUESTO QUIMICO: CICLOHEXANO, ESTADO: LIQUIDO, CONCENTRACION/PUREZA: 100 %, PRESENTACION: ENVASE X 1 L, CALIDAD: PRO ANALISIS | F13: UNIDAD | X13: =+W13*AX13 -> 0 | AE13: 2 | AF13: =+AE13*AX13 -> 12775.2 | AW13: =+AQ13+AO13+AM13+AK13+AI13+AG13+AE13+AC13+AA13+Y13+W13+U13+S13+Q13+O13+M13+K13+I13+AS13+G13+AU13 -> 2 | AX13: 6387.6 | AY13: =+AW13*AX13 -> 12775.2
A14: 7 | B14: 2.5.1-9016.184 | C14: QUÍMICOS | D14: 2.5.1 | E14: MEDIOS DE CULTIVO Y SUPLEMENTO; NOMBRE DEL PRODUCTO: AGAR BAIRD PARKER, ESTADO: SOLIDO, PRESENTACION: ENVASE X 500 GR | F14: UNIDAD | AE14: 1 | AF14: =+AE14*AX14 -> 19988.52 | AW14: =+AQ14+AO14+AM14+AK14+AI14+AG14+AE14+AC14+AA14+Y14+W14+U14+S14+Q14+O14+M14+K14+I14+AS14+G14+AU14 -> 1 | AX14: 19988.52 | AY14: =+AW14*AX14 -> 19988.52
A15: 8 | B15: 2.5.1-9016.774 | C15: QUÍMICOS | D15: 2.5.1 | E15: MEDIOS DE CULTIVO Y SUPLEMENTO; NOMBRE DEL PRODUCTO: AGAR BASE BACILLUS CEREUS, ESTADO: SOLIDO, PRESENTACION: ENVASE X 500 GR | F15: UNIDAD | H15: =SUM(H14) -> 0 | P15: =SUM(P14:P14) -> 0 | AE15: 2 | AF15: =+AE15*AX15 -> 41281.824 | AL15: =SUM(AL8:AL14) -> 0 | AW15: =+AQ15+AO15+AM15+AK15+AI15+AG15+AE15+AC15+AA15+Y15+W15+U15+S15+Q15+O15+M15+K15+I15+AS15+G15+AU15 -> 2 | AX15: 20640.912 | AY15: =+AW15*AX15 -> 41281.824
A16: 9 | B16: 2.5.1-9016.200 | C16: QUÍMICOS | D16: 2.5.1 | E16: MEDIOS DE CULTIVO Y SUPLEMENTO; NOMBRE DEL PRODUCTO: AGAR BASE SANGRE, ESTADO: SOLIDO, PRESENTACION: ENVASE X 500 Ml | F16: UNIDAD | X16: =+W16*AX16 -> 0 | AE16: 1 | AF16: =+AE16*AX16 -> 6360 | AW16: =+AQ16+AO16+AM16+AK16+AI16+AG16+AE16+AC16+AA16+Y16+W16+U16+S16+Q16+O16+M16+K16+I16+AS16+G16+AU16 -> 1 | AX16: 6360 | AY16: =+AW16*AX16 -> 6360
A17: 10 | B17: 2.5.1-9016.205 | C17: QUÍMICOS | D17: 2.5.1 | E17: MEDIOS DE CULTIVO Y SUPLEMENTO; NOMBRE DEL PRODUCTO: AGAR BILIS ESCULINA AZIDA, ESTADO: SOLIDO, PRESENTACION: ENVASE X 100 GR | F17: UNIDAD | AE17: 1 | AF17: =+AE17*AX17 -> 12526.176 | AW17: =+AQ17+AO17+AM17+AK17+AI17+AG17+AE17+AC17+AA17+Y17+W17+U17+S17+Q17+O17+M17+K17+I17+AS17+G17+AU17 -> 1 | AX17: 12526.176 | AY17: =+AW17*AX17 -> 12526.176
A18: 11 | B18: 2.5.1-9016.78 | C18: QUÍMICOS | D18: 2.5.1 | E18: MEDIOS DE CULTIVO Y SUPLEMENTO; NOMBRE DEL PRODUCTO: AGAR CETRIMIDA, ESTADO: SOLIDO, PRESENTACION: ENVASE X 500 GR | F18: UNIDAD | H18: =+G18*AR18 -> 0 | I18: 0 | J18: =+I18*AX18 -> 0 | Z18: =+Y18*AX18 -> 0 | AE18: 1 | AF18: =+AE18*AX18 -> 24630.924 | AW18: =+AQ18+AO18+AM18+AK18+AI18+AG18+AE18+AC18+AA18+Y18+W18+U18+S18+Q18+O18+M18+K18+I18+AS18+G18+AU18 -> 1 | AX18: 24630.924 | AY18: =+AW18*AX18 -> 24630.924
A19: 12 | B19: 2.5.1-9016.646 | C19: QUÍMICOS | D19: 2.5.1 | E19: MEDIOS DE CULTIVO Y SUPLEMENTO; NOMBRE DEL PRODUCTO: AGAR EMB, ESTADO: SOLIDO, PRESENTACION: ENVASE X 100 GR | F19: UNIDAD | H19: =+G19*AR19 -> 0 | J19: =+I19*AX19 -> 0 | N19: =+M19*AX19 -> 0 | P19: =+O19*AX19 -> 0 | R19: =+Q19*AX19 -> 0 | X19: =+W19*AX19 -> 0 | Z19: =+Y19*AX19 -> 0 | AB19: =+AA19*AX19 -> 0 | AD19: =+AC19*AX19 -> 0 | AE19: 2 | AF19: =+AE19*AX19 -> 47492.592 | AH19: =+AG19*AX19 -> 0 | AL19: =+AK19*AX19 -> 0 | AN19: =+AM19*AX19 -> 0 | AP19: =+AO19*AX19 -> 0 | AW19: =+AQ19+AO19+AM19+AK19+AI19+AG19+AE19+AC19+AA19+Y19+W19+U19+S19+Q19+O19+M19+K19+I19+AS19+G19+AU19 -> 2 | AX19: 23746.296 | AY19: =+AW19*AX19 -> 47492.592
A20: 13 | B20: 2.5.1-9016.244 | C20: QUÍMICOS | D20: 2.5.1 | E20: MEDIOS DE CULTIVO Y SUPLEMENTO; NOMBRE DEL PRODUCTO: AGAR MAC CONKEY SORBITOL, ESTADO: SOLIDO, PRESENTACION: ENVASE X 500 GR | F20: UNIDAD | AE20: 1 | AF20: =+AE20*AX20 -> 20170.416 | AW20: =+AQ20+AO20+AM20+AK20+AI20+AG20+AE20+AC20+AA20+Y20+W20+U20+S20+Q20+O20+M20+K20+I20+AS20+G20+AU20 -> 1 | AX20: 20170.416 | AY20: =+AW20*AX20 -> 20170.416
A21: 14 | B21: 2.5.1-9016.241 | C21: QUÍMICOS | D21: 2.5.1 | E21: MEDIOS DE CULTIVO Y SUPLEMENTO; NOMBRE DEL PRODUCTO: AGAR MAC CONKEY, ESTADO: SOLIDO, PRESENTACION: ENVASE X 500 GR | F21: UNIDAD | Z21: =+Y21*AX21 -> 0 | AE21: 2 | AF21: =+AE21*AX21 -> 35950.08 | AW21: =+AQ21+AO21+AM21+AK21+AI21+AG21+AE21+AC21+AA21+Y21+W21+U21+S21+Q21+O21+M21+K21+I21+AS21+G21+AU21 -> 2 | AX21: 17975.04 | AY21: =+AW21*AX21 -> 35950.08
A22: 15 | B22: 2.5.1-9016.181 | C22: QUIMICOS | D22: 2.5.1 | E22: MEDIOS DE CULTIVO Y SUPLEMENTO; NOMBRE DEL PRODUCTO: AGAR MANITOL SALADO, ESTADO: SOLIDO, PRESENTACION: ENVASE X 100 GR | F22: UNIDAD | AE22: 1 | AF22: =+AE22*AX22 -> 12737.16 | AW22: =+AQ22+AO22+AM22+AK22+AI22+AG22+AE22+AC22+AA22+Y22+W22+U22+S22+Q22+O22+M22+K22+I22+AS22+G22+AU22 -> 1 | AX22: 12737.16 | AY22: =+AW22*AX22 -> 12737.16
A23: 16 | B23: 2.5.1-9016.664 | C23: QUÍMICOS | D23: 2.5.1 | E23: MEDIOS DE CULTIVO Y SUPLEMENTO; NOMBRE DEL PRODUCTO: AGAR NUTRITIVO, ESTADO: SOLIDO, PRESENTACION: ENVASE X 500 GR | F23: UNIDAD | T23: =+S23*AX23 -> 0 | AE23: 1 | AF23: =+AE23*AX23 -> 5808.36 | AW23: =+AQ23+AO23+AM23+AK23+AI23+AG23+AE23+AC23+AA23+Y23+W23+U23+S23+Q23+O23+M23+K23+I23+AS23+G23+AU23 -> 1 | AX23: 5808.36 | AY23: =+AW23*AX23 -> 5808.36
A24: 17 | B24: 2.5.1-9016.86 | C24: QUIMICOS | D24: 2.5.1 | E24: MEDIOS DE CULTIVO Y SUPLEMENTO; NOMBRE DEL PRODUCTO: AGAR RECUENTO TOTAL, ESTADO: SOLIDO, PRESENTACION: ENVASE X 500 GR | F24: UNIDAD | T24: =+S24*AX24 -> 0 | AE24: 2 | AF24: =+AE24*AX24 -> 10490.256 | AW24: =+AQ24+AO24+AM24+AK24+AI24+AG24+AE24+AC24+AA24+Y24+W24+U24+S24+Q24+O24+M24+K24+I24+AS24+G24+AU24 -> 2 | AX24: 5245.128 | AY24: =+AW24*AX24 -> 10490.256
A25: 18 | B25: 2.5.1-9016.264 | C25: QUÍMICOS | D25: 2.5.1 | E25: MEDIOS DE CULTIVO Y SUPLEMENTO; NOMBRE DEL PRODUCTO: AGAR SABOURAUD GLUCOSA, ESTADO: SOLIDO, PRESENTACION: ENVASE X 500 GR | F25: UNIDAD | T25: =+S25*AX25 -> 0 | AE25: 1 | AF25: =+AE25*AX25 -> 11269.92 | AW25: =+AQ25+AO25+AM25+AK25+AI25+AG25+AE25+AC25+AA25+Y25+W25+U25+S25+Q25+O25+M25+K25+I25+AS25+G25+AU25 -> 1 | AX25: 11269.92 | AY25: =+AW25*AX25 -> 11269.92
A26: 19 | B26: 2.5.1-9016.392 | C26: QUÍMICOS | D26: 2.5.1 | E26: MEDIOS DE CULTIVO Y SUPLEMENTO; NOMBRE DEL PRODUCTO: AGAR SALMONELLA- SHIGELLA, ESTADO: SOLIDO, PRESENTACION: ENVASE X 500 GR | F26: UNIDAD | T26: =+S26*AX26 -> 0 | AE26: 1 | AF26: =+AE26*AX26 -> 16270.692 | AW26: =+AQ26+AO26+AM26+AK26+AI26+AG26+AE26+AC26+AA26+Y26+W26+U26+S26+Q26+O26+M26+K26+I26+AS26+G26+AU26 -> 1 | AX26: 16270.692 | AY26: =+AW26*AX26 -> 16270.692
A27: 20 | B27: 2.5.1-9016.709 | C27: QUIMICOS | D27: 2.5.1 | E27: MEDIOS DE CULTIVO Y SUPLEMENTO; NOMBRE DEL PRODUCTO: AGAR TIOGLICOLATO RESAZURINA, ESTADO: SOLIDO, PRESENTACION: ENVASE X 500 GR | F27: UNIDAD | T27: =+S27*AX27 -> 0 | AE27: 1 | AF27: =+AE27*AX27 -> 47244.372 | AW27: =+AQ27+AO27+AM27+AK27+AI27+AG27+AE27+AC27+AA27+Y27+W27+U27+S27+Q27+O27+M27+K27+I27+AS27+G27+AU27 -> 1 | AX27: 47244.372 | AY27: =+AW27*AX27 -> 47244.372
A28: 21 | B28: 2.5.1-9016.874 | C28: QUÍMICOS | D28: 2.5.1 | E28: MEDIOS DE CULTIVO Y SUPLEMENTO; NOMBRE DEL PRODUCTO: AGAR VIOLETA ROJO BILIS GLUCOS, ESTADO: SOLIDO, PRESENTACION: ENVASE X 500 GR | F28: UNIDAD | T28: =+S28*AX28 -> 0 | AE28: 2 | AF28: =+AE28*AX28 -> 32714.544 | AW28: =+AQ28+AO28+AM28+AK28+AI28+AG28+AE28+AC28+AA28+Y28+W28+U28+S28+Q28+O28+M28+K28+I28+AS28+G28+AU28 -> 2 | AX28: 16357.272 | AY28: =+AW28*AX28 -> 32714.544
A29: 22 | B29: 2.5.1-9016.366 | C29: QUÍMICOS | D29: 2.5.1 | E29: MEDIOS DE CULTIVO Y SUPLEMENTO; NOMBRE DEL PRODUCTO: AGAR VIOLETA ROJO NEUTRO BILIS, ESTADO: SOLIDO, PRESENTACION: ENVASE X 500 GR | F29: UNIDAD | T29: =+S29*AX29 -> 0 | AE29: 2 | AF29: =+AE29*AX29 -> 24955.344 | AW29: =+AQ29+AO29+AM29+AK29+AI29+AG29+AE29+AC29+AA29+Y29+W29+U29+S29+Q29+O29+M29+K29+I29+AS29+G29+AU29 -> 2 | AX29: 12477.672 | AY29: =+AW29*AX29 -> 24955.344
A30: 23 | B30: 2.5.1-9016.71 | C30: QUIMICOS | D30: 2.5.1 | E30: MEDIOS DE CULTIVO Y SUPLEMENTO; NOMBRE DEL PRODUCTO: AGAR XLT, ESTADO: SOLIDO, PRESENTACION: ENVASE X 500 GR | F30: UNIDAD | T30: =+S30*AX30 -> 0 | AE30: 1 | AF30: =+AE30*AX30 -> 93271.176 | AW30: =+AQ30+AO30+AM30+AK30+AI30+AG30+AE30+AC30+AA30+Y30+W30+U30+S30+Q30+O30+M30+K30+I30+AS30+G30+AU30 -> 1 | AX30: 93271.176 | AY30: =+AW30*AX30 -> 93271.176
A31: 24 | B31: 2.5.1-9016.368 | C31: QUÍMICOS | D31: 2.5.1 | E31: MEDIOS DE CULTIVO Y SUPLEMENTO; NOMBRE DEL PRODUCTO: C.LAURIL SULFATO TRIPTOSA MODI, ESTADO: SOLIDO, PRESENTACION: ENVASE X 500 mGr | F31: UNIDAD | T31: =+S31*AX31 -> 0 | AE31: 2 | AF31: =+AE31*AX31 -> 40264.08 | AW31: =+AQ31+AO31+AM31+AK31+AI31+AG31+AE31+AC31+AA31+Y31+W31+U31+S31+Q31+O31+M31+K31+I31+AS31+G31+AU31 -> 2 | AX31: 20132.04 | AY31: =+AW31*AX31 -> 40264.08
A32: 25 | B32: 2.5.1-9016.145 | C32: QUÍMICOS | D32: 2.5.1 | E32: MEDIOS DE CULTIVO Y SUPLEMENTO; NOMBRE DEL PRODUCTO: CALDO AZIDA GLUCOSA, ESTADO: SOLIDO, PRESENTACION: ENVASE X 500 GR | F32: UNIDAD | T32: =+S32*AX32 -> 0 | AE32: 1 | AF32: =+AE32*AX32 -> 21878.4 | AW32: =+AQ32+AO32+AM32+AK32+AI32+AG32+AE32+AC32+AA32+Y32+W32+U32+S32+Q32+O32+M32+K32+I32+AS32+G32+AU32 -> 1 | AX32: 21878.4 | AY32: =+AW32*AX32 -> 21878.4
A33: 26 | B33: 2.5.1-9016.373 | C33: QUÍMICOS | D33: 2.5.1 | E33: MEDIOS DE CULTIVO Y SUPLEMENTO; NOMBRE DEL PRODUCTO: CALDO ESCHERICHIA COLI, ESTADO: SOLIDO, PRESENTACION: ENVASE X 500 GR | F33: UNIDAD | T33: =+S33*AX33 -> 0 | AE33: 2 | AF33: =+AE33*AX33 -> 38476.8 | AW33: =+AQ33+AO33+AM33+AK33+AI33+AG33+AE33+AC33+AA33+Y33+W33+U33+S33+Q33+O33+M33+K33+I33+AS33+G33+AU33 -> 2 | AX33: 19238.4 | AY33: =+AW33*AX33 -> 38476.8
A34: 27 | B34: 2.5.1-9016.503 | C34: QUÍMICOS | D34: 2.5.1 | E34: MEDIOS DE CULTIVO Y SUPLEMENTO; NOMBRE DEL PRODUCTO: CALDO GIOLITTI CANTONI, ESTADO: SOLIDO, PRESENTACION: ENVASE X 500 GR | F34: UNIDAD | AE34: 1 | AF34: =+AE34*AX34 -> 30958.152 | AW34: =+AQ34+AO34+AM34+AK34+AI34+AG34+AE34+AC34+AA34+Y34+W34+U34+S34+Q34+O34+M34+K34+I34+AS34+G34+AU34 -> 1 | AX34: 30958.152 | AY34: =+AW34*AX34 -> 30958.152
A35: 28 | B35: 2.5.1-9016.54 | C35: QUÍMICOS | D35: 2.5.1 | E35: MEDIOS DE CULTIVO Y SUPLEMENTO; NOMBRE DEL PRODUCTO: CALDO SELENITO VERDE BRILLANTE, ESTADO: SOLIDO, PRESENTACION: ENVASE X 500 GR | F35: UNIDAD | T35: =+S35*AX35 -> 0 | AE35: 2 | AF35: =+AE35*AX35 -> 73214.904 | AW35: =+AQ35+AO35+AM35+AK35+AI35+AG35+AE35+AC35+AA35+Y35+W35+U35+S35+Q35+O35+M35+K35+I35+AS35+G35+AU35 -> 2 | AX35: 36607.452 | AY35: =+AW35*AX35 -> 73214.904
A36: 29 | B36: 2.5.1-9016.46 | C36: QUÍMICOS | D36: 2.5.1 | E36: MEDIOS DE CULTIVO Y SUPLEMENTO; NOMBRE DEL PRODUCTO: CALDO TETRATIONATO, ESTADO: SOLIDO, PRESENTACION: ENVASE X 500 GR | F36: UNIDAD | T36: =+S36*AX36 -> 0 | AE36: 1 | AF36: =+AE36*AX36 -> 3882.744 | AW36: =+AQ36+AO36+AM36+AK36+AI36+AG36+AE36+AC36+AA36+Y36+W36+U36+S36+Q36+O36+M36+K36+I36+AS36+G36+AU36 -> 1 | AX36: 3882.744 | AY36: =+AW36*AX36 -> 3882.744
A37: 30 | B37: 2.5.1-9016.826 | C37: QUIMICOS | D37: 2.5.1 | E37: MEDIOS DE CULTIVO Y SUPLEMENTO; NOMBRE DEL PRODUCTO: GENERADORES DE ANAEROBIOSIS, ESTADO: SOLIDO, PRESENTACION: ENVASE X 10 UN | F37: UNIDAD | T37: =+S37*AX37 -> 0 | AE37: 2 | AF37: =+AE37*AX37 -> 10951.2 | AW37: =+AQ37+AO37+AM37+AK37+AI37+AG37+AE37+AC37+AA37+Y37+W37+U37+S37+Q37+O37+M37+K37+I37+AS37+G37+AU37 -> 2 | AX37: 5475.6 | AY37: =+AW37*AX37 -> 10951.2
A38: 31 | B38: 2.5.1-9016.848 | C38: QUÍMICOS | D38: 2.5.1 | E38: MEDIOS DE CULTIVO Y SUPLEMENTO; NOMBRE DEL PRODUCTO: NOVOBIOCINA MONOSODICA, ESTADO: SOLIDO, PRESENTACION: ENVASE X 10 GR | F38: UNIDAD | T38: =+S38*AX38 -> 0 | AE38: 1 | AF38: =+AE38*AX38 -> 33924.876 | AW38: =+AQ38+AO38+AM38+AK38+AI38+AG38+AE38+AC38+AA38+Y38+W38+U38+S38+Q38+O38+M38+K38+I38+AS38+G38+AU38 -> 1 | AX38: 33924.876 | AY38: =+AW38*AX38 -> 33924.876
A39: 32 | B39: 2.5.1-9016.640 | C39: QUÍMICOS | D39: 2.5.1 | E39: MEDIOS DE CULTIVO Y SUPLEMENTO; NOMBRE DEL PRODUCTO: PEPTONA ACIDA DE CASEINA, ESTADO: SOLIDO, PRESENTACION: ENVASE X 100 GR | F39: UNIDAD | T39: =+S39*AX39 -> 0 | AE39: 4 | AF39: =+AE39*AX39 -> 36592.032 | AW39: =+AQ39+AO39+AM39+AK39+AI39+AG39+AE39+AC39+AA39+Y39+W39+U39+S39+Q39+O39+M39+K39+I39+AS39+G39+AU39 -> 4 | AX39: 9148.008 | AY39: =+AW39*AX39 -> 36592.032
A40: 33 | B40: 2.5.1-9016.410 | C40: QUÍMICOS | D40: 2.5.1 | E40: MEDIOS DE CULTIVO Y SUPLEMENTO; NOMBRE DEL PRODUCTO: SUP.EMULSION YEMA DE HUEVO, ESTADO: SOLUCION, PRESENTACION: ENVASE X 100 mL | F40: UNIDAD | T40: =+S40*AX40 -> 0 | AE40: 2 | AF40: =+AE40*AX40 -> 74118.768 | AW40: =+AQ40+AO40+AM40+AK40+AI40+AG40+AE40+AC40+AA40+Y40+W40+U40+S40+Q40+O40+M40+K40+I40+AS40+G40+AU40 -> 2 | AX40: 37059.384 | AY40: =+AW40*AX40 -> 74118.768
A41: 34 | B41: 2.5.1-9016.952 | C41: QUIMICOS | D41: 2.5.1 | E41: MEDIOS DE CULTIVO Y SUPLEMENTO; NOMBRE DEL PRODUCTO: TIOGLICOLATO USP MEDIO, ESTADO: SOLIDO, PRESENTACION: ENVASE X 500 GR | F41: UNIDAD | T41: =+S41*AX41 -> 0 | AE41: 1 | AF41: =+AE41*AX41 -> 32278.188 | AW41: =+AQ41+AO41+AM41+AK41+AI41+AG41+AE41+AC41+AA41+Y41+W41+U41+S41+Q41+O41+M41+K41+I41+AS41+G41+AU41 -> 1 | AX41: 32278.188 | AY41: =+AW41*AX41 -> 32278.188
...

Sheet NP
A1: NOTA DE PEDIDO | J1: N° | K1: 01/2022
A3: JURISDICCIÓN: | D3: ='SAF 011'!C2 -> 040 - MINISTERIO DE SALUD
A4: SAF: | D4: ='SAF 011'!C3 -> 011 - DIRECCION PROVINCIAL DE ADMINISTRACION - MINISTERIO DE SALUD
A5: UNIDAD EJECUTORA: | D5: DIRECCION PROVINCIAL DE SALUD Y MEDIO AMBIENTE
A6: DEPENDENCIA SOLICITANTE: | D6: DIRECCION PROVINCIAL DE SALUD Y MEDIO AMBIENTE
A7: PERIODO UTILIZACIÓN: | D7: 1° TRIMESTRE 2022
A8: OBJETO: | D8: ADQUISICION DEL RUBRO REACTIVOS PARA AGUA
A10: Ítem | B10: Codigo Item | C10: DESCRIPCIÓN | H10: Adjunta Detalle Técnico | I10: Unidad Medida | J10: Precio Unitario Estimado | K10: Cantidad Solicitada
A12: 1 | B12: ='SAF 011'!B8 -> 2.5.1-9009.29 | C12: ='SAF 011'!E8 -> ACIDOS; COMPUESTO QUIMICO: AC. CLORHIDRICO, ESTADO: SOLUCION, CALIDAD: PRO ANALISIS, CONCENTRACION/PUREZA: 37 %, PRESENTACION: ENVASE X 1 L | H12: NO | I12: ='SAF 011'!F8 -> UNIDAD | J12: ='SAF 011'!AX8 -> 1268.76 | K12: ='SAF 011'!AE8 -> 2 | M12: =+J12*K12 -> 2537.52
A13: 2 | B13: ='SAF 011'!B9 -> 2.5.1-9009.99 | C13: ='SAF 011'!E9 -> ACIDOS; COMPUESTO QUIMICO: AC. SULFURICO, ESTADO: LIQUIDO, CALIDAD: PRO ANALISIS, CONCENTRACION/PUREZA: 98 %, PRESENTACION: ENVASE X 1 L | H13: NO | I13: ='SAF 011'!F9 -> UNIDAD | J13: ='SAF 011'!AX9 -> 1282.068 | K13: ='SAF 011'!AE9 -> 2 | M13: =+J13*K13 -> 2564.136
A14: 3 | B14: ='SAF 011'!B10 -> 2.5.1-9013.22 | C14: ='SAF 011'!E10 -> ALDEHIDOS Y CETONAS; COMPUESTO QUIMICO: ACETONA, ESTADO: LIQUIDO, CALIDAD: PRO ANALISIS, CONCENTRACION/PUREZA: 99 %, PRESENTACION: ENVASE X 1 L | H14: NO | I14: ='SAF 011'!F10 -> UNIDAD | J14: ='SAF 011'!AX10 -> 7458.084 | K14: ='SAF 011'!AE10 -> 2 | M14: =+J14*K14 -> 14916.168
A15: 4 | B15: ='SAF 011'!B11 -> 2.5.1-9015.66 | C15: ='SAF 011'!E11 -> BASES; COMPUESTO QUIMICO: HIDROXIDO DE POTASIO, ESTADO: SOLIDO, CALIDAD: FARMACOPEA, CONCENTRACION/PUREZA: 98 %, PRESENTACION: ENVASE X 1 Kg | H15: NO | I15: ='SAF 011'!F11 -> UNIDAD | J15: ='SAF 011'!AX11 -> 783.6 | K15: ='SAF 011'!AE11 -> 2 | M15: =+J15*K15 -> 1567.2
A16: 5 | B16: ='SAF 011'!B12 -> 2.5.1-9015.52 | C16: ='SAF 011'!E12 -> BASES; COMPUESTO QUIMICO: HIDROXIDO DE SODIO, ESTADO: SOLUCION, CALIDAD: PRO ANALISIS, CONCENTRACION/PUREZA: 0,1 N, PRESENTACION: ENVASE X 1 L | H16: NO | I16: ='SAF 011'!F12 -> UNIDAD | J16: ='SAF 011'!AX12 -> 747.6 | K16: ='SAF 011'!AE12 -> 2 | M16: =+J16*K16 -> 1495.2
A17: 6 | B17: ='SAF 011'!B13 -> 2.5.1-8976.27 | C17: ='SAF 011'!E13 -> HIDROCARBUROS; COMPUESTO QUIMICO: CICLOHEXANO, ESTADO: LIQUIDO, CONCENTRACION/PUREZA: 100 %, PRESENTACION: ENVASE X 1 L, CALIDAD: PRO ANALISIS | H17: NO | I17: ='SAF 011'!F13 -> UNIDAD | J17: ='SAF 011'!AX13 -> 6387.6 | K17: ='SAF 011'!AE13 -> 2 | M17: =+J17*K17 -> 12775.2
A18: 7 | B18: ='SAF 011'!B14 -> 2.5.1-9016.184 | C18: ='SAF 011'!E14 -> MEDIOS DE CULTIVO Y SUPLEMENTO; NOMBRE DEL PRODUCTO: AGAR BAIRD PARKER, ESTADO: SOLIDO, PRESENTACION: ENVASE X 500 GR | H18: NO | I18: ='SAF 011'!F14 -> UNIDAD | J18: ='SAF 011'!AX14 -> 19988.52 | K18: ='SAF 011'!AE14 -> 1 | M18: =+J18*K18 -> 19988.52
A19: 8 | B19: ='SAF 011'!B15 -> 2.5.1-9016.774 | C19: ='SAF 011'!E15 -> MEDIOS DE CULTIVO Y SUPLEMENTO; NOMBRE DEL PRODUCTO: AGAR BASE BACILLUS CEREUS, ESTADO: SOLIDO, PRESENTACION: ENVASE X 500 GR | H19: NO | I19: ='SAF 011'!F15 -> UNIDAD | J19: ='SAF 011'!AX15 -> 20640.912 | K19: ='SAF 011'!AE15 -> 2 | M19: =+J19*K19 -> 41281.824
A20: 9 | B20: ='SAF 011'!B16 -> 2.5.1-9016.200 | C20: ='SAF 011'!E16 -> MEDIOS DE CULTIVO Y SUPLEMENTO; NOMBRE DEL PRODUCTO: AGAR BASE SANGRE, ESTADO: SOLIDO, PRESENTACION: ENVASE X 500 Ml | H20: NO | I20: ='SAF 011'!F16 -> UNIDAD | J20: ='SAF 011'!AX16 -> 6360 | K20: ='SAF 011'!AE16 -> 1 | M20: =+J20*K20 -> 6360
A21: 10 | B21: ='SAF 011'!B17 -> 2.5.1-9016.205 | C21: ='SAF 011'!E17 -> MEDIOS DE CULTIVO Y SUPLEMENTO; NOMBRE DEL PRODUCTO: AGAR BILIS ESCULINA AZIDA, ESTADO: SOLIDO, PRESENTACION: ENVASE X 100 GR | H21: NO | I21: ='SAF 011'!F17 -> UNIDAD | J21: ='SAF 011'!AX17 -> 12526.176 | K21: ='SAF 011'!AE17 -> 1 | M21: =+J21*K21 -> 12526.176
A22: 11 | B22: ='SAF 011'!B18 -> 2.5.1-9016.78 | C22: ='SAF 011'!E18 -> MEDIOS DE CULTIVO Y SUPLEMENTO; NOMBRE DEL PRODUCTO: AGAR CETRIMIDA, ESTADO: SOLIDO, PRESENTACION: ENVASE X 500 GR | H22: NO | I22: ='SAF 011'!F18 -> UNIDAD | J22: ='SAF 011'!AX18 -> 24630.924 | K22: ='SAF 011'!AE18 -> 1 | M22: =+J22*K22 -> 24630.924
A23: 12 | B23: ='SAF 011'!B19 -> 2.5.1-9016.646 | C23: ='SAF 011'!E19 -> MEDIOS DE CULTIVO Y SUPLEMENTO; NOMBRE DEL PRODUCTO: AGAR EMB, ESTADO: SOLIDO, PRESENTACION: ENVASE X 100 GR | H23: NO | I23: ='SAF 011'!F19 -> UNIDAD | J23: ='SAF 011'!AX19 -> 23746.296 | K23: ='SAF 011'!AE19 -> 2 | M23: =+J23*K23 -> 47492.592
... A63: 52 | B63: ='SAF 011'!B59 -> 2.5.1-9004.334 | C63: ='SAF 011'!E59 -> SALES; COMPUESTO QUIMICO: TELURITO DE POTASIO, ESTADO: SOLIDO, CALIDAD: PRO ANALISIS, CONCENTRACION/PUREZA: 99 %, PRESENTACION: ENVASE X 25 GR, GRADO HIDRATACION: ANHIDRO | H63: NO | I63: ='SAF 011'!F59 -> UNIDAD | J63: ='SAF 011'!AX59 -> 2238.456 | K63: ='SAF 011'!AE59 -> 2 | M63: =+J63*K63 -> 4476.912
A65: Costo total estimado: UN MILLON CIENTO DIECISIETE MIL SEISCIENTOS SETENTA Y NUEVE CON 48/100.- | J65: =+M65 -> 1117679.5 | M65: =SUM(M12:M64) -> 1117679.5

Sheet APG
A1: EJERCICIO: | D1: 2022 | P1: AUTORIZACION PARA GASTAR
A4: JURISDICCIÓN: | G4: =NP!D3 -> 040 - MINISTERIO DE SALUD
A5: SAF: | G5: =NP!D4 -> 011 - DIRECCION PROVINCIAL DE ADMINISTRACION - MINISTERIO DE SALUD
A6: UNIDAD EJECUTORA: | G6: =NP!D5 -> DIRECCION PROVINCIAL DE SALUD Y MEDIO AMBIENTE
A7: DEPENDENCIA SOLICITANTE: | G7: =NP!D6 -> DIRECCION PROVINCIAL DE SALUD Y MEDIO AMBIENTE
A8: AUTORIZACIÓN:
A9: Señor Director de Administración o Titular del Servicio Administrativo Financiero:
A10: Autorizo la realización de los trámites correspondientes, a fin de proveer a este Organismo los bienes que se detallan en Nota de Pedido N° 01/2022 afectando la erogación resultante a los créditos presupuestarios aprobados a favor de esta Unidad Ejecutora, conforme al siguiente detalle:
A12: IMPUTACIÓN PRESUPUESTARIA
A13: CÓDIGO | O13: DENOMINACIÓN DE LA PARTIDA PRESUPUESTARIA | Q13: IMPORTE
A14: PR | B14: SB | C14: PY | D14: AC | E14: OB | F14: UG | G14: FIN | H14: FUN | I14: I | J14: P | K14: P | L14: SubP | M14: M | N14: FF
A15: 22 | D15: 1 | F15: 4901 | G15: 4 | H15: 4 | I15: 2 | J15: 5 | K15: 1 | M15: 1 | N15: 1.1 | O15: COMPUESTOS QUIMICOS | Q15: =NP!J65 -> 1117679.5
A38: TOTAL DE PESOS: UN MILLON CIENTO DIECISIETE MIL SEISCIENTOS SETENTA Y NUEVE CON 48/100.- | Q38: =SUM(Q15:Q37) -> 1117679.5
A40: JUSTIFICACIÓN:
A41: =NP!D8 -> ADQUISICION DEL RUBRO REACTIVOS PARA AGUA
