Workbook

Sheet SAF 011
A1: 2022
B2: Pedido de Necesidades Trimestrales
A4: JURISDICCION: | C4: 040 - MINISTERIO DE SALUD
A5: SAF N°: | C5: 011 - DIRECCION PROVINCIAL DE ADMINISTRACION - MINISTERIO DE SALUD
A6: EJERCICIO: | C6: 2022
A7: TRIMESTRE: | C7: PRIMERO
A9: ID | B9: CODIGO ITEM | C9: RUBRO DE COMPRA | D9: I.P.P. | E9: DESCRIPCION | F9: UNIDAD DE MEDIDA | G9: CANTIDAD TOTAL | H9: PRECIO UNITARIO ESTIMADO | I9: IMPORTE TOTAL ESTIMADO | J9: ESPECIFICACION TECNICA
A10: 1 | C10: PRODUCTOS MEDICOS/FARMACEUTICOS/LAB. | D10: 234 | E10: Bobina Baja Densidad 30 X 40 rollo x 200 un. Tipo Mapsa | F10: UNIDAD | G10: 30 | H10: 780 | I10: =+G10*H10 -> 23400
A11: 2 | C11: PRODUCTOS MEDICOS/FARMACEUTICOS/LAB. | D11: 259 | E11: Bolsas termosellables de 125 x 50 x 250 mm c/ indicador paca calor húmedo x 1unid | F11: CAJA | G11: 12 | H11: 13500 | I11: =+G11*H11 -> 162000
A12: 3 | C12: PRODUCTOS MEDICOS/FARMACEUTICOS/LAB. | D12: 295 | E12: Camisolin P/Cirugia de tela verde brin con puño caña larga | F12: UNIDAD | G12: 100 | H12: 2580 | I12: =+G12*H12 -> 258000
A13: 4 | C13: PRODUCTOS MEDICOS/FARMACEUTICOS/LAB. | D13: 251 | E13: Cassettes P/Sterrad NX x 5 unidades Tipo ASP | F13: CAJA | G13: 4 | H13: 130000 | I13: =+G13*H13 -> 520000
A14: 5 | C14: PRODUCTOS MEDICOS/FARMACEUTICOS/LAB. | D14: 295 | E14: Cinta Papel Pintor 18 mm. X 50 mts. Tipo Stiko | F14: ROLLO | G14: 100 | H14: 165 | I14: =+G14*H14 -> 16500
A15: 6 | C15: PRODUCTOS MEDICOS/FARMACEUTICOS/LAB. | D15: 259 | E15: Cinta Testigo p/calor humedo (en rollo) Tipo Kims | F15: ROLLO | G15: 140 | H15: 380 | I15: =+G15*H15 -> 53200
A16: 7 | C16: PRODUCTOS MEDICOS/FARMACEUTICOS/LAB. | D16: 259 | E16: Cinta Testigo p/calor seco (en rollo) Tipo Kims | F16: ROLLO | G16: 140 | H16: 330 | I16: =+G16*H16 -> 46200
A17: 8 | C17: PRODUCTOS MEDICOS/FARMACEUTICOS/LAB. | D17: 259 | E17: Cinta Testigo P/Sterrad NX x 6 Rollos x 55 Metros Tipo ASP | F17: CAJA | G17: 10 | H17: 35000 | I17: =+G17*H17 -> 350000
A18: 9 | C18: PRODUCTOS MEDICOS/FARMACEUTICOS/LAB. | D18: 295 | E18: Compresa de Gasa Cosida; 40cm x 40cm, Rx y Cola, 5u/ doble sobre -Pouch, 50u/Caja Estéril, | F18: CAJA | G18: 4 | H18: 13200 | I18: =+G18*H18 -> 52800
A19: 10 | C19: PRODUCTOS MEDICOS/FARMACEUTICOS/LAB. | D19: 295 | E19: GASA CORTADA DE 5CM X 5CM X KILO | F19: KILO | G19: 1000 | H19: 1330 | I19: =+G19*H19 -> 1330000
A20: 11 | C20: PRODUCTOS MEDICOS/FARMACEUTICOS/LAB. | D20: 295 | E20: GASA HIDROFILA PIEZA X 1,8 KGS. TIPO HIDROSAN | F20: UNIDAD | G20: 50 | H20: 2680 | I20: =+G20*H20 -> 134000
A21: 12 | C21: PRODUCTOS MEDICOS/FARMACEUTICOS/LAB. | D21: 295 | E21: GUANTES DE NITRILO de PROTECCION QUIMICA CANA LARGA NUMERO 7 1/2 X PAR | F21: PAR | G21: 120 | H21: 480 | I21: =+G21*H21 -> 57600
... A26: 17 | C26: PRODUCTOS MEDICOS/FARMACEUTICOS/LAB. | D26: 295 | E26: LUPAS; POTENCIA: 75 Diop, DIAMETRO: 65 mm, MATERIAL LENTE: VIDRIO, ACCESORIO: C/LUZ, ARMAZON: PLASTICO, ESTRUCTURA: PLASTICO | F26: UNIDAD | G26: 10 | H26: 5560 | I26: =+G26*H26 -> 55600
A27: 18 | D27: 295 | E27: MALLA TUBULAR ALGODÓN 10 CM X 25 MTS | F27: UNIDAD | G27: 4 | H27: 890 | I27: =+G27*H27 -> 3560
A28: 19 | C28: PRODUCTOS MEDICOS/FARMACEUTICOS/LAB. | D28: 295 | E28: MALLA TUBULAR ALGODÓN 20 CM X 25 MTS | F28: UNIDAD | G28: 6 | H28: 1550 | I28: =+G28*H28 -> 9300
A29: 20 | C29: PRODUCTOS MEDICOS/FARMACEUTICOS/LAB. | D29: 295 | E29: Malla Tubular de 30 cm. Ancho X 25 mts. Largo Tipo Hidrosan | F29: UNIDAD | G29: 4 | H29: 2900 | I29: =+G29*H29 -> 11600
A30: 21 | C30: PRODUCTOS MEDICOS/FARMACEUTICOS/LAB. | D30: 291 | E30: Paño de micro fibra de 40 x 40 cm Tipo Mister Trapo | F30: UNIDAD | G30: 40 | H30: 560 | I30: =+G30*H30 -> 22400
A31: 22 | C31: PRODUCTOS MEDICOS/FARMACEUTICOS/LAB. | D31: 259 | E31: PAPEL GRADO MEDICO 120 CM X 100 MTS | F31: BOBINA | G31: 24 | H31: 6800 | I31: =+G31*H31 -> 163200
A32: 23 | C32: PRODUCTOS MEDICOS/FARMACEUTICOS/LAB. | D32: 259 | E32: PAPEL GRADO MEDICO 60 GR ANCHO 60 CM X 100 MTS | F32: BOBINA | G32: 30 | H32: 5680 | I32: =+G32*H32 -> 170400
A33: 24 | C33: PRODUCTOS MEDICOS/FARMACEUTICOS/LAB. | D33: 259 | E33: PAPEL GRADO MEDICO 80 CM X 330 MTS | F33: BOBINA | G33: 30 | H33: 9282 | I33: =+G33*H33 -> 278460
A34: 25 | C34: PRODUCTOS MEDICOS/FARMACEUTICOS/LAB. | D34: 258 | E34: Polietileno de 50 micrones 30cm. X 100 mts. Tipo MP | F34: BOBINA | G34: 20 | H34: 4200 | I34: =+G34*H34 -> 84000
A35: 26 | C35: PRODUCTOS MEDICOS/FARMACEUTICOS/LAB. | D35: 258 | E35: Polietileno de 50 micrones 40cm. X 100 mts. Tipo MP | F35: BOBINA | G35: 20 | H35: 5400 | I35: =+G35*H35 -> 108000
A36: 27 | C36: PRODUCTOS MEDICOS/FARMACEUTICOS/LAB. | D36: 259 | E36: Pouch Rollo de 100 mm x 200 mts. | F36: ROLLO | G36: 10 | H36: 4305 | I36: =+G36*H36 -> 43050
A37: 28 | C37: PRODUCTOS MEDICOS/FARMACEUTICOS/LAB. | D37: 259 | E37: Pouch Rollo de 200 mm x 200 mt. | F37: ROLLO | G37: 10 | H37: 5885 | I37: =+G37*H37 -> 58850
A38: 29 | C38: PRODUCTOS MEDICOS/FARMACEUTICOS/LAB. | D38: 259 | E38: Pouch Rollo de 300 mm x 200 mts. | F38: ROLLO | G38: 5 | H38: 8259 | I38: =+G38*H38 -> 41295
A39: 30 | C39: PRODUCTOS MEDICOS/FARMACEUTICOS/LAB. | D39: 259 | E39: Pouch Rollo de 400 mm x 200 mts. | F39: ROLLO | G39: 5 | H39: 9341 | I39: =+G39*H39 -> 46705
... A50: 41 | C50: PRODUCTOS MEDICOS/FARMACEUTICOS/LAB. | D50: 259 | E50: Tyvek Rollo de 50 cm Tipo ASP/KIMS | F50: ROLLO | G50: 4 | H50: 65000 | I50: =+G50*H50 -> 260000
E51: TOTAL RUBRO ESTERILIZACION | I51: =SUM(I10:I50) -> 5802111.2
C53: DETALLE TECNICO Y ESPECIFICACIONES | D53: ANEXO 1-Para oferentes de la Provincia de Catamarca deberán presentar Habilitación Provincial para comercializar el producto que cotizan. 2-Para el resto de oferentes deberán presentar Certificado de Inscripción de ANMAT vigente al momento de la oferta, el mismo deberá ser correspondiente al objeto de la contratación y de encontrarse vencido adjuntar la solicitud de renovación. 3-No se aceptarán ofertas de productos no registrados y autorizada su venta por ANMAT. Se deberá especificar en cada ítem de la propuesta, marca y número de certificado otorgado por dicho ente regulador. 4-Los productos deberán tener un vencimiento posterior a doce (12) meses a partir de la fecha de su recepción.
C55: Plazos de entrega | D55: veinte (20) dias habiles
C57: Lugar de Entrega: | D57: DIR. PROV. DE FARMACIA E INSUMOS - CHACABUCO N° 169 - en el horario de 8:00hs a 12:00hs de lunes a viernes
C59: Calidad Minima esperada
C61: Mantenimiento | D61: cuarenta y cinco (45) días

Sheet NP FARMACIA
A1: NOTA DE PEDIDO | J1: N° | K1: 06/2022
A3: JURISDICCIÓN: | D3: ='SAF 011'!C4 -> 040 - MINISTERIO DE SALUD
A4: SAF: | D4: ='SAF 011'!C5 -> 011 - DIRECCION PROVINCIAL DE ADMINISTRACION - MINISTERIO DE SALUD
A5: UNIDAD EJECUTORA: | D5: DIRECCION PROVINCIAL DE FARMACIA E INSUMOS
A6: DEPENDENCIA SOLICITANTE: | D6: DIRECCION PROVINCIAL DE FARMACIA E INSUMOS
A7: PERIODO UTILIZACIÓN: | D7: SEMESTRAL
A8: OBJETO: | D8: ADQUISICION DEL RUBRO ESTERILIZACION
A10: Ítem | B10: Codigo Item | C10: DESCRIPCIÓN | H10: Adjunta Detalle Técnico | I10: Unidad Medida | J10: Precio Unitario Estimado | K10: Cantidad Solicitada
A12: 1 | C12: ='SAF 011'!E10 -> Bobina Baja Densidad 30 X 40 rollo x 200 un. Tipo Mapsa | H12: NO | I12: UNIDAD | J12: 780 | K12: 30 | M12: =+J12*K12 -> 23400 | N12: 234 | P12: =+M12 -> 23400 | V12: =SUM(O12:U12) -> 23400
A13: 2 | C13: ='SAF 011'!E11 -> Bolsas termosellables de 125 x 50 x 250 mm c/ indicador paca calor húmedo x 1unid | H13: NO | I13: CAJA | J13: 13500 | K13: 12 | M13: =+J13*K13 -> 162000 | N13: 259 | S13: =+M13 -> 162000 | V13: =SUM(O13:U13) -> 162000
A14: 3 | C14: ='SAF 011'!E12 -> Camisolin P/Cirugia de tela verde brin con puño caña larga | H14: NO | I14: UNIDAD | J14: 2580 | K14: 100 | M14: =+J14*K14 -> 258000 | N14: 295 | U14: =+M14 -> 258000 | V14: =SUM(O14:U14) -> 258000
A15: 4 | C15: ='SAF 011'!E13 -> Cassettes P/Sterrad NX x 5 unidades Tipo ASP | H15: NO | I15: CAJA | J15: 130000 | K15: 4 | M15: =+J15*K15 -> 520000 | N15: 251 | Q15: =+M15 -> 520000 | V15: =SUM(O15:U15) -> 520000
A16: 5 | C16: ='SAF 011'!E14 -> Cinta Papel Pintor 18 mm. X 50 mts. Tipo Stiko | H16: NO | I16: ROLLO | J16: 165 | K16: 100 | M16: =+J16*K16 -> 16500 | N16: 295 | U16: =+M16 -> 16500 | V16: =SUM(O16:U16) -> 16500
A17: 6 | C17: ='SAF 011'!E15 -> Cinta Testigo p/calor humedo (en rollo) Tipo Kims | H17: NO | I17: ROLLO | J17: 380 | K17: 140 | M17: =+J17*K17 -> 53200 | N17: 259 | S17: =+M17 -> 53200 | V17: =SUM(O17:U17) -> 53200
A18: 7 | C18: ='SAF 011'!E16 -> Cinta Testigo p/calor seco (en rollo) Tipo Kims | H18: NO | I18: ROLLO | J18: 330 | K18: 140 | M18: =+J18*K18 -> 46200 | N18: 259 | S18: =+M18 -> 46200 | V18: =SUM(O18:U18) -> 46200
A19: 8 | C19: ='SAF 011'!E17 -> Cinta Testigo P/Sterrad NX x 6 Rollos x 55 Metros Tipo ASP | H19: NO | I19: CAJA | J19: 35000 | K19: 10 | M19: =+J19*K19 -> 350000 | N19: 259 | S19: =+M19 -> 350000 | V19: =SUM(O19:U19) -> 350000
A20: 9 | C20: ='SAF 011'!E18 -> Compresa de Gasa Cosida; 40cm x 40cm, Rx y Cola, 5u/ doble sobre -Pouch, 50u/Caja Estéril, | H20: NO | I20: CAJA | J20: 13200 | K20: 4 | M20: =+J20*K20 -> 52800 | N20: 295 | U20: =+M20 -> 52800 | V20: =SUM(O20:U20) -> 52800
A21: 10 | C21: ='SAF 011'!E19 -> GASA CORTADA DE 5CM X 5CM X KILO | H21: SI | I21: KILO | J21: 1330 | K21: 1000 | M21: =+J21*K21 -> 1330000
A22: 11 | C22: ='SAF 011'!E21 -> GUANTES DE NITRILO de PROTECCION QUIMICA CANA LARGA NUMERO 7 1/2 X PAR | H22: NO | I22: PAR | J22: 480 | K22: 120 | M22: =+J22*K22 -> 57600 | N22: 295 | U22: =+M22 -> 57600 | V22: =SUM(O22:U22) -> 57600
A23: 12 | C23: ='SAF 011'!E22 -> Indicador Biologico P/Sterrad NX x 30 Ampollas Tipo ASP | H23: NO | I23: CAJA | J23: 52000 | K23: 3 | M23: =+J23*K23 -> 156000 | N23: 251 | Q23: =+M23 -> 156000 | V23: =SUM(O23:U23) -> 156000
A24: 13 | C24: ='SAF 011'!E23 -> Indicador Quimico P/Sterrad NX x 1000 Tiras Tipo ASP | H24: NO | I24: CAJA | J24: 15800 | K24: 3 | M24: =+J24*K24 -> 47400 | N24: 251 | Q24: =+M24 -> 47400 | V24: =SUM(O24:U24) -> 47400
A25: 14 | C25: ='SAF 011'!E24 -> INDICADORES DE ESTERILIZACION,CALOR SECO,TIRAS INTEGRADORAS CAJA X 100 | H25: NO | I25: CAJA | J25: 2056 | K25: 30 | M25: =+J25*K25 -> 61680 | N25: 251 | Q25: =+M25 -> 61680 | V25: =SUM(O25:U25) -> 61680
A26: 15 | C26: ='SAF 011'!E25 -> INDICADORES DE ESTERILIZACION; METODO DE ESTERILIZACION: AUTOCLAVE DE VAPOR, TIRAS INTEGRADORAS, CAJA X 100 UN, | H26: NO | I26: CAJA | J26: 2056 | K26: 30 | M26: =+J26*K26 -> 61680 | N26: 251 | Q26: =+M26 -> 61680 | V26: =SUM(O26:U26) -> 61680
A27: 16 | C27: ='SAF 011'!E26 -> LUPAS; POTENCIA: 75 Diop, DIAMETRO: 65 mm, MATERIAL LENTE: VIDRIO, ACCESORIO: C/LUZ, ARMAZON: PLASTICO, ESTRUCTURA: PLASTICO | H27: NO | I27: UNIDAD | J27: 5560 | K27: 10 | M27: =+J27*K27 -> 55600 | N27: 295 | U27: =+M27 -> 55600 | V27: =SUM(O27:U27) -> 55600
A28: 17 | C28: ='SAF 011'!E27 -> MALLA TUBULAR ALGODÓN 10 CM X 25 MTS | H28: NO | I28: UNIDAD | J28: 890 | K28: 4 | M28: =+J28*K28 -> 3560 | N28: 295 | U28: =+M28 -> 3560 | V28: =SUM(O28:U28) -> 3560
A29: 18 | C29: ='SAF 011'!E28 -> MALLA TUBULAR ALGODÓN 20 CM X 25 MTS | H29: NO | I29: UNIDAD | J29: 1550 | K29: 6 | M29: =+J29*K29 -> 9300 | N29: 295 | U29: =+M29 -> 9300 | V29: =SUM(O29:U29) -> 9300
A30: 19 | C30: ='SAF 011'!E29 -> Malla Tubular de 30 cm. Ancho X 25 mts. Largo Tipo Hidrosan | H30: NO | I30: UNIDAD | J30: 2900 | K30: 4 | M30: =+J30*K30 -> 11600 | N30: 295 | U30: =+M30 -> 11600 | V30: =SUM(O30:U30) -> 11600
A31: 20 | C31: ='SAF 011'!E30 -> Paño de micro fibra de 40 x 40 cm Tipo Mister Trapo | H31: NO | I31: UNIDAD | J31: 560 | K31: 40 | M31: =+J31*K31 -> 22400 | N31: 291 | T31: =+M31 -> 22400 | V31: =SUM(O31:U31) -> 22400
A32: 21 | C32: ='SAF 011'!E31 -> PAPEL GRADO MEDICO 120 CM X 100 MTS | H32: NO | I32: BOBINA | J32: 6800 | K32: 24 | M32: =+J32*K32 -> 163200 | N32: 259 | S32: =+M32 -> 163200 | V32: =SUM(O32:U32) -> 163200
A33: 22 | C33: ='SAF 011'!E32 -> PAPEL GRADO MEDICO 60 GR ANCHO 60 CM X 100 MTS | H33: NO | I33: BOBINA | J33: 5680 | K33: 30 | M33: =+J33*K33 -> 170400 | N33: 259 | S33: =+M33 -> 170400 | V33: =SUM(O33:U33) -> 170400
A34: 23 | C34: ='SAF 011'!E33 -> PAPEL GRADO MEDICO 80 CM X 330 MTS | H34: NO | I34: BOBINA | J34: 9282 | K34: 30 | M34: =+J34*K34 -> 278460 | N34: 259 | S34: =+M34 -> 278460 | V34: =SUM(O34:U34) -> 278460
A35: 24 | C35: ='SAF 011'!E34 -> Polietileno de 50 micrones 30cm. X 100 mts. Tipo MP | H35: NO | I35: BOBINA | J35: 4200 | K35: 20 | M35: =+J35*K35 -> 84000 | N35: 258 | R35: =+M35 -> 84000 | V35: =SUM(O35:U35) -> 84000
A36: 25 | C36: ='SAF 011'!E35 -> Polietileno de 50 micrones 40cm. X 100 mts. Tipo MP | H36: NO | I36: BOBINA | J36: 5400 | K36: 20 | M36: =+J36*K36 -> 108000 | N36: 258 | R36: =+M36 -> 108000 | V36: =SUM(O36:U36) -> 108000
A37: 26 | C37: ='SAF 011'!E36 -> Pouch Rollo de 100 mm x 200 mts. | H37: NO | I37: ROLLO | J37: 4305 | K37: 10 | M37: =+J37*K37 -> 43050 | N37: 259 | S37: =+M37 -> 43050 | V37: =SUM(O37:U37) -> 43050
A38: 27 | C38: ='SAF 011'!E37 -> Pouch Rollo de 200 mm x 200 mt. | H38: NO | I38: ROLLO | J38: 5885 | K38: 10 | M38: =+J38*K38 -> 58850 | N38: 259 | S38: =+M38 -> 58850 | V38: =SUM(O38:U38) -> 58850
A39: 28 | C39: ='SAF 011'!E38 -> Pouch Rollo de 300 mm x 200 mts. | H39: NO | I39: ROLLO | J39: 8259 | K39: 5 | M39: =+J39*K39 -> 41295 | N39: 259 | S39: =+M39 -> 41295 | V39: =SUM(O39:U39) -> 41295
A40: 29 | C40: ='SAF 011'!E39 -> Pouch Rollo de 400 mm x 200 mts. | H40: NO | I40: ROLLO | J40: 9341 | K40: 5 | M40: =+J40*K40 -> 46705 | N40: 259 | S40: =+M40 -> 46705 | V40: =SUM(O40:U40) -> 46705
A41: 30 | C41: ='SAF 011'!E40 -> Pouch Rollo de 450 mm x 200 mts. | H41: NO | I41: ROLLO | J41: 10320 | K41: 5 | M41: =+J41*K41 -> 51600 | N41: 259 | S41: =+M41 -> 51600 | V41: =SUM(O41:U41) -> 51600
A42: 31 | C42: ='SAF 011'!E41 -> Rollo de lienzo Ecologico 60grs 1,5 x 50 mt. | H42: NO | I42: ROLLO | J42: 5600 | K42: 10 | M42: =+J42*K42 -> 56000 | N42: 221 | O42: =+M42 -> 56000 | V42: =SUM(O42:U42) -> 56000
A43: 32 | C43: ='SAF 011'!E42 -> Ropa Equipo Cirugia Universal DESCARTABLE 17 Elementos Esteril | H43: NO | I43: PAQUETE | J43: 5405.52 | K43: 60 | M43: =+J43*K43 -> 324331.2 | N43: 295 | U43: =+M43 -> 324331.2 | V43: =SUM(O43:U43) -> 324331.2
...

Sheet APG FARMACIA
A1: EJERCICIO: | D1: 2022 | P1: AUTORIZACION PARA GASTAR
A4: JURISDICCIÓN: | G4: =+'SAF 011'!C4 -> 040 - MINISTERIO DE SALUD
A5: SAF: | G5: =+'SAF 011'!C5 -> 011 - DIRECCION PROVINCIAL DE ADMINISTRACION - MINISTERIO DE SALUD
A6: UNIDAD EJECUTORA: | G6: DIRECCION PROVINCIAL DE FARMACIA E INSUMOS
A7: DEPENDENCIA SOLICITANTE: | G7: DIRECCION PROVINCIAL DE FARMACIA E INSUMOS
A8: AUTORIZACIÓN:
A9: Señor Director de Administración o Titular del Servicio Administrativo Financiero:
A10: Autorizo la realización de los trámites correspondientes, a fin de proveer a este Organismo los bienes que se detallan en Nota de Pedido N° 06/2022 afectando la erogación resultante a los créditos presupuestarios aprobados a favor de esta Unidad Ejecutora, conforme al siguiente detalle:
A12: IMPUTACIÓN PRESUPUESTARIA
A13: CÓDIGO | O13: DENOMINACIÓN DE LA PARTIDA PRESUPUESTARIA | Q13: IMPORTE
A14: PR | B14: SB | C14: PY | D14: AC | E14: OB | F14: UG | G14: FIN | H14: FUN | I14: I | J14: P | K14: P | L14: SubP | M14: M | N14: FF
A15: 53 | D15: 1 | F15: 4901 | G15: 3 | H15: 1 | I15: 2 | J15: 2 | K15: 1 | M15: 1 | N15: 1.1 | O15: HILADOS Y TELAS | Q15: ='NP FARMACIA'!O53 -> 56000
A16: 53 | D16: 1 | F16: 4901 | G16: 3 | H16: 1 | I16: 2 | J16: 3 | K16: 4 | M16: 1 | N16: 1.1 | O16: PRODUCTOS DE PAPEL Y CARTON | Q16: ='NP FARMACIA'!P53 -> 23400
A17: 30 | D17: 1 | F17: 4901 | G17: 3 | H17: 1 | I17: 2 | J17: 5 | K17: 1 | M17: 1 | N17: 1.1 | O17: COMPUESTOS QUIMICOS | Q17: ='NP FARMACIA'!Q53 -> 880060
A18: 30 | D18: 1 | F18: 4901 | G18: 3 | H18: 1 | I18: 2 | J18: 5 | K18: 8 | M18: 1 | N18: 1.1 | O18: PRODUCTOS DE MATERIAL PLASTICO | Q18: ='NP FARMACIA'!R53 -> 192000
A19: 30 | D19: 1 | F19: 4901 | G19: 3 | H19: 1 | I19: 2 | J19: 5 | K19: 9 | M19: 1 | N19: 1.1 | O19: OTROS N.E.P. | Q19: ='NP FARMACIA'!S53 -> 2374960
A20: 53 | D20: 1 | F20: 4901 | G20: 3 | H20: 1 | I20: 2 | J20: 9 | K20: 1 | M20: 1 | N20: 1.1 | O20: ELEMENTOS DE LIMPIEZA | Q20: ='NP FARMACIA'!T53 -> 22400
A21: 30 | D21: 1 | F21: 4901 | G21: 3 | H21: 1 | I21: 2 | J21: 9 | K21: 5 | M21: 1 | N21: 1.1 | O21: UTILES MENORES MEDICOS, QUIRURGICOS Y DE LABORATORIO | Q21: =+'SAF 011'!I12+'SAF 011'!I14+'SAF 011'!I18+'SAF 011'!I19+'SAF 011'!I21+'SAF 011'!I26+'SAF 011'!I27+'SAF 011'!I28+'SAF 011'!I29+'SAF 011'!I42 -> 2119291.2
A38: TOTAL DE PESOS: CINCO MILLONES SEISCIENTOS SESENTA Y OCHO MIL CIENTO ONCE CON 20/100.- | Q38: =SUM(Q15:Q37) -> 5668111.2
A40: JUSTIFICACIÓN:
A41: ADQUISICION DEL RUBRO ESTERILIZACION

Sheet NP SAME
A1: NOTA DE PEDIDO | J1: N° | K1: 04/2022
A3: JURISDICCIÓN: | D3: ='SAF 011'!C4 -> 040 - MINISTERIO DE SALUD
A4: SAF: | D4: ='SAF 011'!C5 -> 011 - DIRECCION PROVINCIAL DE ADMINISTRACION - MINISTERIO DE SALUD
A5: UNIDAD EJECUTORA: | D5: DIRECCION PROVINCIAL SISTEMA DE ATENCION MEDICA DE EMERGENCIA
A6: DEPENDENCIA SOLICITANTE: | D6: DIRECCION PROVINCIAL SISTEMA DE ATENCION MEDICA DE EMERGENCIA
A7: PERIODO UTILIZACIÓN: | D7: SEMESTRAL
A8: OBJETO: | D8: ADQUISICION DEL RUBRO ESTERILIZACION
A10: Ítem | B10: Codigo Item | C10: DESCRIPCIÓN | H10: Adjunta Detalle Técnico | I10: Unidad Medida | J10: Precio Unitario Estimado | K10: Cantidad Solicitada
A12: 1 | C12: ='SAF 011'!E20 -> GASA HIDROFILA PIEZA X 1,8 KGS. TIPO HIDROSAN | H12: NO | I12: UNIDAD | J12: 2680 | K12: 50 | M12: =+J12*K12 -> 134000
A14: Costo total estimado: CIENTO TREINTA Y CUATRO MIL CON 00/100.- | J14: =+M14 -> 134000 | M14: =SUM(M12:M13) -> 134000

Sheet APG SAME
A1: EJERCICIO: | D1: 2022 | P1: AUTORIZACION PARA GASTAR
A4: JURISDICCIÓN: | G4: ='NP SAME'!D3 -> 040 - MINISTERIO DE SALUD
A5: SAF: | G5: ='NP SAME'!D4 -> 011 - DIRECCION PROVINCIAL DE ADMINISTRACION - MINISTERIO DE SALUD
A6: UNIDAD EJECUTORA: | G6: ='NP SAME'!D5 -> DIRECCION PROVINCIAL SISTEMA DE ATENCION MEDICA DE EMERGENCIA
A7: DEPENDENCIA SOLICITANTE: | G7: ='NP SAME'!D6 -> DIRECCION PROVINCIAL SISTEMA DE ATENCION MEDICA DE EMERGENCIA
A8: AUTORIZACIÓN:
A9: Señor Director de Administración o Titular del Servicio Administrativo Financiero:
A10: Autorizo la realización de los trámites correspondientes, a fin de proveer a este Organismo los bienes que se detallan en Nota de Pedido N° 04/2022 afectando la erogación resultante a los créditos presupuestarios aprobados a favor de esta Unidad Ejecutora, conforme al siguiente detalle:
A12: IMPUTACIÓN PRESUPUESTARIA
A13: CÓDIGO | O13: DENOMINACIÓN DE LA PARTIDA PRESUPUESTARIA | Q13: IMPORTE
A14: PR | B14: SB | C14: PY | D14: AC | E14: OB | F14: UG | G14: FIN | H14: FUN | I14: I | J14: P | K14: P | L14: SubP | M14: M | N14: FF
A15: 31 | D15: 1 | F15: 4901 | G15: 3 | H15: 1 | I15: 2 | J15: 9 | K15: 5 | M15: 1 | N15: 1.1 | O15: UTILES MENORES MEDICOS, QUIRURGICOS Y DE LABORATORIO | Q15: ='NP SAME'!M14 -> 134000
A38: TOTAL DE PESOS: CIENTO TREINTA Y CUATRO MIL CON 00/100.- | Q38: =SUM(Q15:Q37) -> 134000
A40: JUSTIFICACIÓN:
A41: ='NP SAME'!D8 -> ADQUISICION DEL RUBRO ESTERILIZACION
