Workbook

Sheet SAF 011 - NECESIDAD TRIMESTRAL
A1: 2022
B2: Pedido de Necesidades Trimestrales
A4: JURISDICCION: | C4: 040 - MINISTERIO DE SALUD
A5: SAF N°: | C5: 011 - DIRECCION PROVINCIAL DE ADMINISTRACION - MINISTERIO DE SALUD
A6: EJERCICIO: | C6: 2022
A7: TRIMESTRE: | C7: TERCERO
A9: ID | B9: CODIGO ITEM | C9: RUBRO DE COMPRA | D9: I.P.P. | E9: DESCRIPCION | F9: UNIDAD DE MEDIDA | G9: SECRETARIA DE ADMINISTRACION | H9: TOTAL S.A. | I9: SMPyPS | J9: TOTAL SMPyPS | K9: DIR. LAB. CENTRAL | L9: TOTAL DE LAB CENTRAL | M9: BCO DE SANGRE | N9: TOTAL BANCO DE SANGRE | O9: APS | P9: TOTAL A.P.S. | Q9: DIR DE CANCER | R9: TOTAL DE DIR DE CANCER | S9: FARMACIA | T9: TOTAL FARMACIA | U9: ODONTOLOGIA | V9: TOTAL DE ODONTOLOG | W9: SAME | X9: TOTAL SAME | Y9: HPTAL MALBRAN | Z9: TOTAL HPTAL MALBRAN | AA9: MATERNIDAD E INFANCIA | AB9: TOTAL MATERNIDAD E INFANCIA | AC9: SASP | AD9: TOTAL SASP | AE9: SALUD Y MEDIO AMBIENTE | AF9: TOTAL SALUD Y MEDIO AMBIENTE | AG9: VECTORES Y ZOONOSIS | AH9: TOTAL DE VECT Y ZOON | AI9: CRONICAS | AJ9: TOTAL CRONICAS | AK9: CUR | AL9: TOTAL CUR | AM9: SPyGS | AN9: TOTAL SPyGS | AO9: SALUD MENTAL | AP9: TOTAL SALUD MENTAL | AQ9: AREAS Y DPAS | AR9: TOTAL DPAS | AS9: EPIDEMIOLOGIA | AT9: TOTAL EPIDEMIOLOGIA | AU9: MS | AV9: TOTAL MS | AW9: CANTIDAD TOTAL | AX9: PRECIO UNITARIO ESTIMADO | AY9: IMPORTE TOTAL ESTIMADO | AZ9: ESPECIFICACION TECNICA | BA9: IPP | BC9: RUBRO S/CATALOGO
A10: 1 | B10: 4.3.7-1367.427 | C10: EQUIPO DE OFICINA Y MUEBLES | D10: 4.3.7 | E10: ACONDICIONADORES DE AIRE; TIPO: SPLIT, FRIO: 3500 FRIG, CALOR: 3500 CAL, TENSION NOMINAL: 220 V, CRITERIO DE SEGURIDAD: SELLO DE SEGURIDAD, CONSUMO: 4000 W, CORRIENTE NOMINAL: 6 A, EFICIENCIA ENERGETICA: GRADO A | F10: UNIDAD | AU10: 70 | AV10: =+AU10*AX10 -> 5250000 | AW10: =+AQ10+AO10+AM10+AK10+AI10+AG10+AE10+AC10+AA10+Y10+W10+U10+S10+Q10+O10+M10+K10+I10+AS10+G10+AU10 -> 70 | AX10: 75000 | AY10: =+AW10*AX10 -> 5250000 | AZ10: AIRE ACONDICIONADOS SPLIT INVERTER | BA10: 437 | BB10: AIRE ACONDICIONADOS SPLIT INVERTER (Ver Eficiencia energética, no se corresponde con un Inverter) | BC10: EQUIPO DE OFICINA Y MUEBLES
A11: 2 | B11: 4.3.7-1367.320 | C11: EQUIPO DE OFICINA Y MUEBLES | D11: 4.3.7 | E11: ACONDICIONADORES DE AIRE; TIPO: SPLIT, FRIO: 4500 FRIG, CALOR: 4500 CAL, TENSION NOMINAL: 220 V, CRITERIO DE SEGURIDAD: SELLO DE SEGURIDAD, CONSUMO: MENOR A 5 KVA, CORRIENTE NOMINAL: 12 A, EFICIENCIA ENERGETICA: GRADO A | F11: UNIDAD | AU11: 42 | AV11: =+AU11*AX11 -> 3570000 | AW11: =+AQ11+AO11+AM11+AK11+AI11+AG11+AE11+AC11+AA11+Y11+W11+U11+S11+Q11+O11+M11+K11+I11+AS11+G11+AU11 -> 42 | AX11: 85000 | AY11: =+AW11*AX11 -> 3570000 | AZ11: AIRE ACONDICIONADOS SPLIT INVERTER | BA11: 437 | BB11: AIRE ACONDICIONADOS SPLIT INVERTER | BC11: EQUIPO DE OFICINA Y MUEBLES
A12: 3 | B12: 2.2.9-702.3 | C12: ARTICULOS DEL HOGAR | D12: 2.2.9 | E12: ALMOHADAS; DIMENSION: 80 X 35 Cm, CONSTRUCCION: ESPUMA | F12: UNIDAD | AU12: 100 | AV12: =+AU12*AX12 -> 420000 | AW12: =+AQ12+AO12+AM12+AK12+AI12+AG12+AE12+AC12+AA12+Y12+W12+U12+S12+Q12+O12+M12+K12+I12+AS12+G12+AU12 -> 100 | AX12: 4200 | AY12: =+AW12*AX12 -> 420000 | AZ12: Algodón lavable. Color Blanco. Relleno: espuma viscoelástica | BA12: 229 | BB12: ALMOHADAS Aguna aclaración del tipo de tela, espuma, tela, color? | BC12: ARTICULOS DEL HOGAR
A13: 4 | B13: 4.3.7-2001.4 | C13: EQUIPO DE OFICINA Y MUEBLES | D13: 4.3.7 | E13: BANQUETAS/TABURETES; MATERIAL ESTRUCTURA: 147 dBV/mPa , TERMINACION: TAPIZADO, DIMENSION: 45 X 35 Cm, RESPALDO: CON, GIRATORIA: SI, APOYABRAZO: SIN, PATAS: 5 RUEDAS, ALTURA: 42 A 54 Cm, MATERIAL: METAL | F13: UNIDAD | AU13: 60 | AV13: =+AU13*AX13 -> 1320000 | AW13: =+AQ13+AO13+AM13+AK13+AI13+AG13+AE13+AC13+AA13+Y13+W13+U13+S13+Q13+O13+M13+K13+I13+AS13+G13+AU13 -> 60 | AX13: 22000 | AY13: =+AW13*AX13 -> 1320000 | AZ13: BANQUETA METAL (c/respaldo, Giratoria, 5 patas y ruedas) | BA13: 437 | BB13: BANQUETA METAL (c/respaldo, Giratoria, 5 patas y ruedas) | BC13: EQUIPO DE OFICINA Y MUEBLES
A14: 5 | B14: 4.3.7-2001.22 | C14: EQUIPO DE OFICINA Y MUEBLES | D14: 4.3.7 | E14: BANQUETAS/TABURETES; TERMINACION: METAL, DIMENSION: 0,6 X 0,3, RESPALDO: SIN, GIRATORIA: NO, APOYABRAZO: SIN, PATAS: 4, ALTURA: REGULABLE, MATERIAL: METAL | F14: UNIDAD | AU14: 10 | AV14: =+AU14*AX14 -> 155000 | AW14: =+AQ14+AO14+AM14+AK14+AI14+AG14+AE14+AC14+AA14+Y14+W14+U14+S14+Q14+O14+M14+K14+I14+AS14+G14+AU14 -> 10 | AX14: 15500 | AY14: =+AW14*AX14 -> 155000 | AZ14: BANQUETA METAL (s/respaldo, Fija, 4 patas y sin ruedas) | BA14: 437 | BB14: BANQUETA METAL (s/respaldo, Fija, 4 patas y sin ruedas) | BC14: EQUIPO DE OFICINA Y MUEBLES
A15: 6 | B15: 4.3.7-32.680 | C15: EQUIPO DE OFICINA Y MUEBLES | D15: 4.3.7 | E15: BIBLIOTECAS; MATERIAL: MELAMINA, CANT. PUERTAS: 2, TERMINACION: LAMINADO, DIMENSION (ANCHO/PROF/ALTO): 120 X 40 X 180 Cm | F15: UNIDAD | AU15: 70 | AV15: =+AU15*AX15 -> 2170000 | AW15: =+AQ15+AO15+AM15+AK15+AI15+AG15+AE15+AC15+AA15+Y15+W15+U15+S15+Q15+O15+M15+K15+I15+AS15+G15+AU15 -> 70 | AX15: 31000 | AY15: =+AW15*AX15 -> 2170000 | AZ15: BIBLIOTECA (Melamina, 2 puertas) Estantes: 5 | BA15: 437 | BB15: BIBLIOTECA (Melamina, 2 puertas) Estantes? | BC15: EQUIPO DE OFICINA Y MUEBLES
A16: 7 | B16: 4.3.7-5605.1 | C16: EQUIPO DE OFICINA Y MUEBLES | D16: 4.3.7 | E16: BIOMBOS; TIPO: PLEGABLE, DIMENSION: 2 X 2 M, USO: SANITARIO | F16: UNIDAD | AU16: 70 | AV16: =+AU16*AX16 -> 1295000 | AW16: =+AQ16+AO16+AM16+AK16+AI16+AG16+AE16+AC16+AA16+Y16+W16+U16+S16+Q16+O16+M16+K16+I16+AS16+G16+AU16 -> 70 | AX16: 18500 | AY16: =+AW16*AX16 -> 1295000 | AZ16: Biombos sanitarios con estructura metálica protegida por pintura epoxi, con ruedas de plástico y cuerpo de tela refrozada | BA16: (no sale, 437 o 433) | BB16: Biombos sanitarios con estructura metálica protegida por pintura epoxi, con ruedas de plástico y cuerpo de tela refrozada | BC16: EQUIPO DE OFICINA Y MUEBLES
A17: 8 | B17: 4.3.9-8811.3 | C17: EQUIPOS | D17: 4.3.7 | E17: CALOVENTILADORES; TIPO: AIRE, CAPACIDAD CALORICA: 1800 W, CAUDAL: CONTINUO, MOTOR: ELECTRICO | F17: UNIDAD | AU17: 210 | AV17: =+AU17*AX17 -> 840000 | AW17: =+AQ17+AO17+AM17+AK17+AI17+AG17+AE17+AC17+AA17+Y17+W17+U17+S17+Q17+O17+M17+K17+I17+AS17+G17+AU17 -> 210 | AX17: 4000 | AY17: =+AW17*AX17 -> 840000 | AZ17: CALOVENTOR (1800 W) | BA17: 437 | BB17: CALOVENTOR (1800 W) | BC17: EQUIPOS
A18: 9 | B18: 4.3.7-2207.2 | C18: EQUIPO DE OFICINA Y MUEBLES | D18: 4.3.7 | E18: CAMAS; LARGO X ANCHO: 190 X 80 Cm, MATERIAL: MADERA, TERMINACION: LUSTRE NATURAL, TIPO: 1PLAZA | F18: UNIDAD | AU18: 10 | AV18: =+AU18*AX18 -> 200000 | AW18: =+AQ18+AO18+AM18+AK18+AI18+AG18+AE18+AC18+AA18+Y18+W18+U18+S18+Q18+O18+M18+K18+I18+AS18+G18+AU18 -> 10 | AX18: 20000 | AY18: =+AW18*AX18 -> 200000 | AZ18: CAMA Madera (1 plaza) | BA18: 437 | BB18: CAMA Madera (1 plaza) | BC18: EQUIPO DE OFICINA Y MUEBLES
A19: 10 | B19: 2.2.9-701.57 | C19: ARTICULOS DEL HOGAR | D19: 2.2.9 | E19: COLCHONES; DIMENSION: 190 X 80 Cm, DENSIDAD: 25 kg/cm3, ESPESOR: 21 Cm, CONSTRUCCION: ESPUMA, TERMINACION: MATELASSEADO | F19: UNIDAD | AU19: 10 | AV19: =+AU19*AX19 -> 200000 | AW19: =+AQ19+AO19+AM19+AK19+AI19+AG19+AE19+AC19+AA19+Y19+W19+U19+S19+Q19+O19+M19+K19+I19+AS19+G19+AU19 -> 10 | AX19: 20000 | AY19: =+AW19*AX19 -> 200000 | AZ19: COLCHONES (1 plaza) | BA19: 229 | BB19: COLCHONES (1 plaza) | BC19: ARTICULOS DEL HOGAR
A20: 11 | B20: 2.2.3-917.25 | C20: INDUMENT TEXTIL Y CONFECCIONES | D20: 2.2.3 | E20: CUBRECAMA; TIPO: ACOLCHADO, TAMAÑO: 1 1/2 PLAZA, MATERIAL: ALGODON Y POLIESTER | F20: UNIDAD | AU20: 300 | AV20: =+AU20*AX20 -> 960000 | AW20: =+AQ20+AO20+AM20+AK20+AI20+AG20+AE20+AC20+AA20+Y20+W20+U20+S20+Q20+O20+M20+K20+I20+AS20+G20+AU20 -> 300 | AX20: 3200 | AY20: =+AW20*AX20 -> 960000 | AZ20: ACOLCHADO Cubrecama Nido de abeja (1, 1/2 plaza), color beige, material: 70% algodón - 30% poliester, uso: hospitalario. | BA20: 223 | BB20: ACOLCHADO Cubrecama (1 plaza) color, % del material ? | BC20: INDUMENT TEXTIL Y CONFECCIONES
A21: 12 | B21: 4.3.7-37.82 | C21: EQUIPO DE OFICINA Y MUEBLES | D21: 4.3.7 | E21: ESCALERAS; MATERIAL: METAL, ESCALONES: 2, TRAMOS: UNICO, DESARROLLO: PLANO UNICO, SOPORTE: APOYO | F21: UNIDAD | AU21: 50 | AV21: =+AU21*AX21 -> 375000 | AW21: =+AQ21+AO21+AM21+AK21+AI21+AG21+AE21+AC21+AA21+Y21+W21+U21+S21+Q21+O21+M21+K21+I21+AS21+G21+AU21 -> 50 | AX21: 7500 | AY21: =+AW21*AX21 -> 375000 | AZ21: ESCALERA de Apoyo (2 peldaños) | BA21: 437 | BB21: ESCALERA de Apoyo (2 peldaños) | BC21: EQUIPO DE OFICINA Y MUEBLES
A22: 13 | B22: 4.3.7-4502.8 | C22: EQUIPO DE OFICINA Y MUEBLES | D22: 4.3.7 | E22: ESCRITORIOS ERGONOMICOS; MATERIAL ESTRUCTURA: AGLOMERADO, ALTURA: 75 Cm, CAJONERA: SI, CAJONES: 3, TIRANTE SOBRE CAJON: SIN, BANDEJA PORTATECLADO: CON, PASACABLES: CON, TERMINACION: MELAMINA, ANCHO MAYOR: 120 Cm, ANCHO MENOR: SIN VALOR, PROF. MAYOR: 70 Cm, PROF. MENOR: SIN VALOR, CANTIDAD DE CAJONES: 3, MATERIAL: AGLOMERADO, ANCHO MAXIMO: 120 Cm, PROFUNDIDAD MAXIMA: 70 Cm, DIMENSION (A/P/H): 120 X 70 X 75 Cm | F22: UNIDAD | AU22: 150 | AV22: =+AU22*AX22 -> 3300000 | AW22: =+AQ22+AO22+AM22+AK22+AI22+AG22+AE22+AC22+AA22+Y22+W22+U22+S22+Q22+O22+M22+K22+I22+AS22+G22+AU22 -> 150 | AX22: 22000 | AY22: =+AW22*AX22 -> 3300000 | AZ22: ESCRITORIO (Aglomerado, terminación melamina, c/3 cajones y bandeja portateclado) | BA22: 437 | BB22: ESCRITORIO (Aglomerado, terminación melamina, c/3 cajones y bandeja portateclado) | BC22: EQUIPO DE OFICINA Y MUEBLES
A23: 14 | B23: 4.3.7-40.38 | C23: EQUIPO DE OFICINA Y MUEBLES | D23: 4.3.7 | E23: ESCRITORIOS; CAJONERA: 2 IZQUIERDA, 2 DERECHA, TIRANTE SOBRE CAJON.: SIN, TERMINACION: REVESTIMIENTO MELAMINICO, DIM. DEL PLANO DE UNION: SIN VALOR, DIM. DEL PLANO DE APOYO: SIN VALOR, DIM. DE LAS PANTALLA DIVISORIA: SIN VALOR, DIM. DEL PLANO DE EXTENSION: SIN VALOR, BANDEJA PORTATECLADO: SIN VALOR, PASACABLES: SIN VALOR, MATERIAL ESTRUCTURA: AGLOMERADO, CAJONES: 4, CANTIDAD DE CAJONES: 4 | F23: UNIDAD | AU23: 150 | AV23: =+AU23*AX23 -> 3450000 | AW23: =+AQ23+AO23+AM23+AK23+AI23+AG23+AE23+AC23+AA23+Y23+W23+U23+S23+Q23+O23+M23+K23+I23+AS23+G23+AU23 -> 150 | AX23: 23000 | AY23: =+AW23*AX23 -> 3450000 | AZ23: ESCRITORIO (Aglomerado, terminación melamina, c/4 cajones) con bandeja porta teclado corredizo y pasacables | BA23: 437 | BB23: ESCRITORIO (Aglomerado, terminación melamina, c/4 cajones) Aclarar el resto de la descripción del código. | BC23: EQUIPO DE OFICINA Y MUEBLES
A24: 15 | B24: 4.3.7-1404.22 | C24: EQUIPO DE OFICINA Y MUEBLES | D24: 4.3.7 | E24: ESTANTERIAS; MATERIAL: METAL, DIMENSION: 205 X 60 Cm, ALTURA: 260 Cm, ESTANTES: 6 UN, CAPACIDAD POR ESTANTE: SIN VALOR | F24: UNIDAD | AU24: 30 | AV24: =+AU24*AX24 -> 1200000 | AW24: =+AQ24+AO24+AM24+AK24+AI24+AG24+AE24+AC24+AA24+Y24+W24+U24+S24+Q24+O24+M24+K24+I24+AS24+G24+AU24 -> 30 | AX24: 40000 | AY24: =+AW24*AX24 -> 1200000 | AZ24: ESTANTERIA METALICA (6 Estantes) (Alt.xAnc.xProf.=260x205x60cm) | BB24: ESTANTERIA METALICA (6 Estantes) (Alt.xAnc.xProf.=260x205x60cm??) | BC24: EQUIPO DE OFICINA Y MUEBLES
A25: 16 | B25: 2.2.3-920.42 | C25: INDUMENT TEXTIL Y CONFECCIONES | D25: 2.2.3 | E25: FRAZADAS; MATERIAL: POLAR, TAMAÑO: 1 1/2 PLAZA | F25: UNIDAD | AU25: 300 | AV25: =+AU25*AX25 -> 900000 | AW25: =+AQ25+AO25+AM25+AK25+AI25+AG25+AE25+AC25+AA25+Y25+W25+U25+S25+Q25+O25+M25+K25+I25+AS25+G25+AU25 -> 300 | AX25: 3000 | AY25: =+AW25*AX25 -> 900000 | AZ25: FRAZADA de Polar (1 plaza y 1/2), color beige. Polar Reversible. | BA25: 223 | BB25: FRAZADA de Polar (1 plaza y 1/2) color? Polar Reversible o no? | BC25: INDUMENT TEXTIL Y CONFECCIONES
A26: 17 | B26: 4.3.7-4500.4 | C26: EQUIPO DE OFICINA Y MUEBLES | D26: 4.3.7 | E26: GAVETEROS; MATERIAL: METAL, ALTURA: 240 Cm, ANCHO: 110 Cm, PROFUNDIDAD: 36 Cm, TERMINACION: ESMALTE, CANTIDAD DE CAJONES: 32 | F26: UNIDAD | AU26: 100 | AV26: =+AU26*AX26 -> 900000 | AW26: =+AQ26+AO26+AM26+AK26+AI26+AG26+AE26+AC26+AA26+Y26+W26+U26+S26+Q26+O26+M26+K26+I26+AS26+G26+AU26 -> 100 | AX26: 9000 | AY26: =+AW26*AX26 -> 900000 | AZ26: Incluye 3 separadores por cada cajon | BA26: 437 | BB26: GAVETERO metálico (32 cajones, terminación esmalte, HxAxProf=240x110x36 cm) | BC26: EQUIPO DE OFICINA Y MUEBLES
A27: 18 | B27: 4.3.7-15.123 | C27: ARTICULOS DEL HOGAR | D27: 4.3.7 | E27: HELADERAS; CAPACIDAD: 400 L, FRIO: CON FREEZER, CONSUMO: MENOR A 5 KVA, TENSION NOMINAL: 220 V, CRITERIO DE SEGURIDAD: SELLO DE SEGURIDAD, CORRIENTE NOMINAL: MENOR A 63 A, EFICIENCIA ENERGETICA: GRADO A | F27: UNIDAD | AU27: 10 | AV27: =+AU27*AX27 -> 1360000 | AW27: =+AQ27+AO27+AM27+AK27+AI27+AG27+AE27+AC27+AA27+Y27+W27+U27+S27+Q27+O27+M27+K27+I27+AS27+G27+AU27 -> 10 | AX27: 136000 | AY27: =+AW27*AX27 -> 1360000 | AZ27: Heladera No Frost de 400 lts aproximadamente (incluyendo el freezer), con eficiencia energética mínima A. Con estantes de vidrio templado, alarma de puerta abierta, filtro antibacterial y control de temperatura. | BA27: 437 | BB27: HELADERA c/freezer Cap.400L (Efic.energ. A) Aclarar tipo de descongelamiento, capac.con frezer incluido, inverter o no, medidas, puerta derecha o izquierda, color, etc | BC27: ARTICULOS DEL HOGAR
A28: 19 | B28: 4.3.7-96.28 | C28: ARTICULOS DEL HOGAR | D28: 4.3.7 | E28: HORNOS MICROONDAS; CAPACIDAD: 30 L, DIMENSION (A/P/H): 520 X 510 X 500 mm, ACCESORIO: BANDEJA, MATERIAL INTERNO: CHAPA ESMALTADA, POTENCIA: 1000 W, TENSION NOMINAL: 220 V, CORRIENTE NOMINAL: 4,5 A, CONSUMO: 800 W, CRITERIO DE SEGURIDAD: SELLO DE SEGURIDAD, EFICIENCIA ENERGETICA: SIN VALOR | F28: UNIDAD | AU28: 1 | AV28: =+AU28*AX28 -> 24599 | AW28: =+AQ28+AO28+AM28+AK28+AI28+AG28+AE28+AC28+AA28+Y28+W28+U28+S28+Q28+O28+M28+K28+I28+AS28+G28+AU28 -> 1 | AX28: 24599 | AY28: =+AW28*AX28 -> 24599 | AZ28: MICROONDA Cap.30L, Potencia Max.: 1000W | BA28: 437 | BB28: MICROONDA Cap.30L, Potencia Max.: 1000W | BC28: ARTICULOS DEL HOGAR
A29: 20 | B29: 4.3.9-2757.58 | C29: EQUIPOS | D29: 4.3.7 | E29: LAVADORAS; USO: ROPA, CAPACIDAD: 10 Kg, VAPOR SOBRECALENTADO: SIN, BOMBA ADICIONAL: SIN, ALIMENTACION: 220 V, TENSION NOMINAL: 220/224 V, CORRIENTE NOMINAL: 10 A, CRITERIO DE SEGURIDAD: SELLO DE SEGURIDAD, CONSUMO: 6 KW, EFICIENCIA ENERGETICA: SIN VALOR | F29: UNIDAD | AU29: 10 | AV29: =+AU29*AX29 -> 960000 | AW29: =+AQ29+AO29+AM29+AK29+AI29+AG29+AE29+AC29+AA29+Y29+W29+U29+S29+Q29+O29+M29+K29+I29+AS29+G29+AU29 -> 10 | AX29: 96000 | AY29: =+AW29*AX29 -> 960000 | AZ29: Lavarropas de tecnología inverter, de marca reconocida, con carga frontal y capacidad de 10Kg de ropa, con eficiencia energática A o superior y tensión de alimentación: 220Vca, apto para lavar con agua a diferentes temperatura, tambor de acero inoxidable y filtros atrapa pelusas. La velocidad de centrifugado mínima debe ser 1200 R.P.M. Debe contar con bloqueo de seguridad de puerta. | BA29: 437 | BB29: LAVADORA de 10 KG (Eficiencia Energ. A, Alimentación: 380 V??) grado A | BC29: EQUIPOS
A30: 21 | B30: 4.3.7-2012.7 | C30: EQUIPO DE OFICINA Y MUEBLES | D30: 4.3.7 | E30: LOCKERS; MATERIAL ESTRUCTURA: 147 dBV/mPa , DIMENSION: 182 X 78 X 52 Cm, CANTIDAD CASILLEROS: 6, ESTANTES: CON, PUERTAS: 6, CAJONES: SIN, CANTIDAD DE CAJONES: SIN, MATERIAL: METAL, CANT. PUERTAS: 6, CANTIDAD DE CASILLEROS: 6 | F30: UNIDAD | AU30: 48 | AV30: =+AU30*AX30 -> 2400000 | AW30: =+AQ30+AO30+AM30+AK30+AI30+AG30+AE30+AC30+AA30+Y30+W30+U30+S30+Q30+O30+M30+K30+I30+AS30+G30+AU30 -> 48 | AX30: 50000 | AY30: =+AW30*AX30 -> 2400000 | AZ30: LOCKER Metálicos: 6 casilleros c/estantes, dimensión: Alt. 182 x ancho 78x prof. 52 cm | BA30: 437 | BB30: LOCKER Metálicos (6 casilleros c/estantes, dimensión: 182x78x52 cm) No aclara cual es el Alto o Ancho? | BC30: EQUIPO DE OFICINA Y MUEBLES
A31: 22 | B31: 4.3.7-2208.50 | C31: EQUIPO DE OFICINA Y MUEBLES | D31: 4.3.7 | E31: MESAS DE LUZ; ANCHO: 45 Cm, PROFUNDIDAD: 40 Cm, MATERIAL: METAL, TERMINACION: MELAMINA | F31: UNIDAD | AU31: 80 | AV31: =+AU31*AX31 -> 1905919.2 | AW31: =+AQ31+AO31+AM31+AK31+AI31+AG31+AE31+AC31+AA31+Y31+W31+U31+S31+Q31+O31+M31+K31+I31+AS31+G31+AU31 -> 80 | AX31: 23823.99 | AY31: =+AW31*AX31 -> 1905919.2 | AZ31: MESA DE LUZ (c/1 cajón y 1 puerta) Alt. 70 cm aprox. | BA31: 437 | BB31: MESA DE LUZ (c/1 cajón y 1 puerta) Sin aclaración de la altura | BC31: EQUIPO DE OFICINA Y MUEBLES
A32: 23 | B32: 4.3.7-1406.271 | C32: EQUIPO DE OFICINA Y MUEBLES | D32: 4.3.7 | E32: MESAS DE REUNIONES; SUPERFICIE APOYO: AGLOMERADO, TERMINACION: LAMINADO MELAMINICO, DIM. DEL PLANO DE APOYO: 240 X 110 Cm, BASE: AGLOMERADO, CAPACIDAD: 8 PERSONAS, MATERIAL: AGLOMERADO | F32: UNIDAD | AU32: 7 | AV32: =+AU32*AX32 -> 196000 | AW32: =+AQ32+AO32+AM32+AK32+AI32+AG32+AE32+AC32+AA32+Y32+W32+U32+S32+Q32+O32+M32+K32+I32+AS32+G32+AU32 -> 7 | AX32: 28000 | AY32: =+AW32*AX32 -> 196000 | AZ32: MESA DE REUNIONES Aglomerado, terminación melamina (Cap.8 personas) | BA32: 437 | BB32: MESA DE REUNIONES Aglomerado, terminación melamina (Cap.8 personas) | BC32: EQUIPO DE OFICINA Y MUEBLES
A33: 24 | B33: 4.3.7-5446.1 | C33: EQUIPO DE OFICINA Y MUEBLES | D33: 4.3.7 | E33: MESAS P/CAMAS; BASE: ACERO INOXIDABLE, ALTURA: REGULABLE, DIMENSION DE TAPA: 50 X 80 Cm, MATERIAL DE TAPA: LAMINADA EN MELAMINA, SUPERFICIE APOYO: 50 X 80 Cm | F33: UNIDAD | AU33: 100 | AV33: =+AU33*AX33 -> 1200000 | AW33: =+AQ33+AO33+AM33+AK33+AI33+AG33+AE33+AC33+AA33+Y33+W33+U33+S33+Q33+O33+M33+K33+I33+AS33+G33+AU33 -> 100 | AX33: 12000 | AY33: =+AW33*AX33 -> 1200000 | AZ33: MESA P/CAMA (Altura regulable, laminada en melamina) | BA33: 437 | BB33: MESA P/CAMA (Altura regulable, laminada en melamina) | BC33: EQUIPO DE OFICINA Y MUEBLES
A34: 25 | B34: 4.3.7-1910.21 | C34: EQUIPO DE OFICINA Y MUEBLES | D34: 4.3.7 | E34: MESAS P/IMPRESORAS; MATERIAL: MADERA, DIM. APROX. (ANCHO/PROF/ALTO): 250 X 45 X 85 Cm | F34: UNIDAD | AU34: 1 | AV34: =+AU34*AX34 -> 10000 | AW34: =+AQ34+AO34+AM34+AK34+AI34+AG34+AE34+AC34+AA34+Y34+W34+U34+S34+Q34+O34+M34+K34+I34+AS34+G34+AU34 -> 1 | AX34: 10000 | AY34: =+AW34*AX34 -> 10000 | AZ34: MESA P/ Impresora | BA34: 437 | BB34: MESA P/ Impresora | BC34: EQUIPO DE OFICINA Y MUEBLES
A35: 26 | B35: 4.3.9-7935.2 | C35: CARPINTERIA | D35: 4.3.7 | E35: MESAS P/PLANCHADO; ESTRUCTURA: HIERRO REFORZADO, DIMENSION: 1 X 0,5 M, TERMINACION: TELA DE AMIANTO, MATERIAL ESTRUCTURA: HIERRO REFORZADO | F35: UNIDAD | AU35: 10 | AV35: =+AU35*AX35 -> 82000 | AW35: =+AQ35+AO35+AM35+AK35+AI35+AG35+AE35+AC35+AA35+Y35+W35+U35+S35+Q35+O35+M35+K35+I35+AS35+G35+AU35 -> 10 | AX35: 8200 | AY35: =+AW35*AX35 -> 82000 | AZ35: Mesa para planchado. Plegable, caño 3/4. | BA35: 437 | BB35: MESA P/Planchado (Rever el codigo elegido, tela de amianto??) o dar de Alta uno nuevo | BC35: CARPINTERIA
A36: 27 | B36: 4.3.7-9066.3 | C36: ARTICULOS DEL HOGAR | D36: 4.3.7 | E36: PAVAS ELECTRICAS; MATERIAL: ALUMINIO, CAPACIDAD: 1,7 L, POTENCIA: 2100 W, TENSION NOMINAL: 220 V, CORRIENTE NOMINAL: MENOR A 63 A, CONSUMO: MENOR A 5 KVA, CRITERIO DE SEGURIDAD: SELLO DE SEGURIDAD | F36: UNIDAD | AU36: 20 | AV36: =+AU36*AX36 -> 100000 | AW36: =+AQ36+AO36+AM36+AK36+AI36+AG36+AE36+AC36+AA36+Y36+W36+U36+S36+Q36+O36+M36+K36+I36+AS36+G36+AU36 -> 20 | AX36: 5000 | AY36: =+AW36*AX36 -> 100000 | AZ36: PAVA ELECTRICA (de Aluminio, Cap.1,7L) | BA36: 437 | BB36: PAVA ELECTRICA (de Aluminio, Cap.1,7L) | BC36: ARTICULOS DEL HOGAR
... A42: 33 | B42: 4.3.7-2004.2 | C42: EQUIPO DE OFICINA Y MUEBLES | D42: 4.3.7 | E42: SISTEMAS DE SILLAS; ALTURA FIJA - APOYABRAZO SIN - Nº DE ASIENTOS 4 - MATERIAL METAL | F42: UNIDAD | AU42: 80 | AV42: =+AU42*AX42 -> 4240000 | AW42: =+AQ42+AO42+AM42+AK42+AI42+AG42+AE42+AC42+AA42+Y42+W42+U42+S42+Q42+O42+M42+K42+I42+AS42+G42+AU42 -> 80 | AX42: 53000 | AY42: =+AW42*AX42 -> 4240000 | AZ42: SIST.DE SILLAS (4 asientos). Estructura: metal. Terminacion de la silla: plastico inyectado, color: negra, reforzada: si. | BA42: 437 | BB42: SIST.DE SILLAS (4 asientos) Aclarar que la estructura es de metal y terminacion de la silla, color, reforzada, etc??) | BC42: EQUIPO DE OFICINA Y MUEBLES
A43: 34 | B43: 2.9.1-2661.8 | C43: ELEMENTOS DE LIMPIEZA | D43: 2.9.1 | E43: TACHOS DE RESIDUOS; MATERIAL: PLASTICO, SECCION: CIRCULAR, DIMENSION: 119 L, TAPA: CON | F43: UNIDAD | AU43: 200 | AV43: =+AU43*AX43 -> 3450000 | AW43: =+AQ43+AO43+AM43+AK43+AI43+AG43+AE43+AC43+AA43+Y43+W43+U43+S43+Q43+O43+M43+K43+I43+AS43+G43+AU43 -> 200 | AX43: 17250 | AY43: =+AW43*AX43 -> 3450000 | AZ43: TACHO DE RESIDUOS (circular con tapa, capacidad: 119 litros) | BA43: 291 o 299 | BB43: TACHO DE RESIDUOS (circular con tapa, 80,5x50cm) | BC43: ELEMENTOS DE LIMPIEZA
A44: 35 | B44: 2.9.1-2661.1 | C44: ELEMENTOS DE LIMPIEZA | D44: 2.9.1 | E44: TACHOS DE RESIDUOS; MATERIAL: PLASTICO, SECCION: CIRCULAR, DIMENSION: DIAM. 30 X 80 Cm, TAPA: CON | F44: UNIDAD | AU44: 210 | AV44: =+AU44*AX44 -> 1512000 | AW44: =+AQ44+AO44+AM44+AK44+AI44+AG44+AE44+AC44+AA44+Y44+W44+U44+S44+Q44+O44+M44+K44+I44+AS44+G44+AU44 -> 210 | AX44: 7200 | AY44: =+AW44*AX44 -> 1512000 | AZ44: TACHO DE RESIDUOS (circular con tapa, 80x30cm) | BA44: 291 o 299 | BB44: TACHO DE RESIDUOS (circular con tapa, 80x30cm) tamaño similar al anterior | BC44: ELEMENTOS DE LIMPIEZA
A45: 36 | B45: 4.3.7-28.58 | C45: ARTICULOS DEL HOGAR | D45: 4.3.7 | E45: VENTILADORES; TIPO: DE PIE, POTENCIA: 140 W, TENSION NOMINAL: 220 V, CORRIENTE NOMINAL: MENOR A 0,6 A, CONSUMO: MENOR A 5 KVA, CRITERIO DE SEGURIDAD: SELLO DE SEGURIDAD | F45: UNIDAD | AU45: 210 | AV45: =+AU45*AX45 -> 1260000 | AW45: =+AQ45+AO45+AM45+AK45+AI45+AG45+AE45+AC45+AA45+Y45+W45+U45+S45+Q45+O45+M45+K45+I45+AS45+G45+AU45 -> 210 | AX45: 6000 | AY45: =+AW45*AX45 -> 1260000 | AZ45: Ventilador de pie de 20", con barral y base metálicos, con regulador de inclinación, con 3 velocidades seleccionables por perilla, con motor de 140Watts, con 3 palas de aluminio reforzadas, con rejilla protectora metálica. | BA45: 437 | BB45: VENTILADOR DE PIE (Potencia 140w) No dice el tamaño de la pantalla, ni el material del mismo (paletas y/o estructura). | BC45: ARTICULOS DEL HOGAR
A46: 37 | B46: 4.3.7-1832.16 | C46: EQUIPO DE OFICINA Y MUEBLES | D46: 4.3.7 | E46: VITRINAS; ESTRUCTURA: MADERA, ALTURA: 170 Cm, ANCHO: 132 Cm, PROFUNDIDAD: 43 Cm, ESTANTE: CON, MATERIAL ESTRUCTURA: MADERA, PUERTA: 2 DE VIDRIO Y MADERA, PUERTAS: 2 DE VIDRIO Y MADERA | F46: UNIDAD | AU46: 80 | AV46: =+AU46*AX46 -> 4280000 | AW46: =+AQ46+AO46+AM46+AK46+AI46+AG46+AE46+AC46+AA46+Y46+W46+U46+S46+Q46+O46+M46+K46+I46+AS46+G46+AU46 -> 80 | AX46: 53500 | AY46: =+AW46*AX46 -> 4280000 | AZ46: VITRINA (madera c/estantes y c/2puertas de vidrio, HxAxProf= 170x132x43cm) Estantes: 4, tipo de madera: aglomerado, terminación: melanima. Con 2 puertas vidriadas con llave | BA46: 437 | BB46: VITRINA (madera c/estantes y c/2puertas de vidrio, HxAxProf= 170x132x43cm) Aclarar cuantos estantes, el tipo de madera y su terminación. | BC46: EQUIPO DE OFICINA Y MUEBLES
E47: TOTAL RUBRO MUEBLES Y ARTICULOS DEL HOGAR | AY47: =+SUM(AY10:AY46) -> 57131518
...

Sheet NP
A1: NOTA DE PEDIDO | J1: N° | K1: 07/2022
A3: JURISDICCIÓN: | D3: 040 - MINISTERIO DE SALUD
A4: SAF: | D4: 011 - DIRECCION PROVINCIAL DE ADMINISTRACION DEL MINISTERIO DE SALUD
A5: UNIDAD EJECUTORA: | D5: 352 - MINISTERIO DE SALUD
A6: DEPENDENCIA SOLICITANTE: | D6: 352 - MINISTERIO DE SALUD
A7: PERIODO UTILIZACIÓN: | D7: CINCO (5) AÑOS
A8: OBJETO: | D8: ADQUISICION DE ARTICULOS DE HOGAR Y MUEBLES CON DESTINO A HOSPITALES DE LA PROVINCIA
A10: Ítem | B10: Codigo Item | C10: DESCRIPCIÓN | H10: Adjunta Detalle Técnico | I10: Unidad Medida | J10: Precio Unitario Estimado | K10: Cantidad Solicitada
M11: 223 | N11: 229 | O11: 291 | P11: 437
A12: 1 | B12: ='SAF 011 - NECESIDAD TRIMESTRAL'!B10 -> 4.3.7-1367.427 | C12: ='SAF 011 - NECESIDAD TRIMESTRAL'!E10 -> ACONDICIONADORES DE AIRE; TIPO: SPLIT, FRIO: 3500 FRIG, CALOR: 3500 CAL, TENSION NOMINAL: 220 V, CRITERIO DE SEGURIDAD: SELLO DE SEGURIDAD, CONSUMO: 4000 W, CORRIENTE NOMINAL: 6 A, EFICIENCIA ENERGETICA: GRADO A | H12: SI | I12: ='SAF 011 - NECESIDAD TRIMESTRAL'!F10 -> UNIDAD | J12: ='SAF 011 - NECESIDAD TRIMESTRAL'!AX10 -> 75000 | K12: ='SAF 011 - NECESIDAD TRIMESTRAL'!AU10 -> 70 | P12: =+J12*K12 -> 5250000
A13: 2 | B13: ='SAF 011 - NECESIDAD TRIMESTRAL'!B11 -> 4.3.7-1367.320 | C13: ='SAF 011 - NECESIDAD TRIMESTRAL'!E11 -> ACONDICIONADORES DE AIRE; TIPO: SPLIT, FRIO: 4500 FRIG, CALOR: 4500 CAL, TENSION NOMINAL: 220 V, CRITERIO DE SEGURIDAD: SELLO DE SEGURIDAD, CONSUMO: MENOR A 5 KVA, CORRIENTE NOMINAL: 12 A, EFICIENCIA ENERGETICA: GRADO A | H13: SI | I13: ='SAF 011 - NECESIDAD TRIMESTRAL'!F11 -> UNIDAD | J13: ='SAF 011 - NECESIDAD TRIMESTRAL'!AX11 -> 85000 | K13: ='SAF 011 - NECESIDAD TRIMESTRAL'!AU11 -> 42 | P13: =+J13*K13 -> 3570000
A14: 3 | B14: ='SAF 011 - NECESIDAD TRIMESTRAL'!B12 -> 2.2.9-702.3 | C14: ='SAF 011 - NECESIDAD TRIMESTRAL'!E12 -> ALMOHADAS; DIMENSION: 80 X 35 Cm, CONSTRUCCION: ESPUMA | H14: SI | I14: ='SAF 011 - NECESIDAD TRIMESTRAL'!F12 -> UNIDAD | J14: ='SAF 011 - NECESIDAD TRIMESTRAL'!AX12 -> 4200 | K14: ='SAF 011 - NECESIDAD TRIMESTRAL'!AU12 -> 100 | N14: =+J14*K14 -> 420000
A15: 4 | B15: ='SAF 011 - NECESIDAD TRIMESTRAL'!B13 -> 4.3.7-2001.4 | C15: ='SAF 011 - NECESIDAD TRIMESTRAL'!E13 -> BANQUETAS/TABURETES; MATERIAL ESTRUCTURA: 147 dBV/mPa , TERMINACION: TAPIZADO, DIMENSION: 45 X 35 Cm, RESPALDO: CON, GIRATORIA: SI, APOYABRAZO: SIN, PATAS: 5 RUEDAS, ALTURA: 42 A 54 Cm, MATERIAL: METAL | H15: SI | I15: ='SAF 011 - NECESIDAD TRIMESTRAL'!F13 -> UNIDAD | J15: ='SAF 011 - NECESIDAD TRIMESTRAL'!AX13 -> 22000 | K15: ='SAF 011 - NECESIDAD TRIMESTRAL'!AU13 -> 60 | P15: =+J15*K15 -> 1320000
A16: 5 | B16: ='SAF 011 - NECESIDAD TRIMESTRAL'!B14 -> 4.3.7-2001.22 | C16: ='SAF 011 - NECESIDAD TRIMESTRAL'!E14 -> BANQUETAS/TABURETES; TERMINACION: METAL, DIMENSION: 0,6 X 0,3, RESPALDO: SIN, GIRATORIA: NO, APOYABRAZO: SIN, PATAS: 4, ALTURA: REGULABLE, MATERIAL: METAL | H16: SI | I16: ='SAF 011 - NECESIDAD TRIMESTRAL'!F14 -> UNIDAD | J16: ='SAF 011 - NECESIDAD TRIMESTRAL'!AX14 -> 15500 | K16: ='SAF 011 - NECESIDAD TRIMESTRAL'!AU14 -> 10 | P16: =+J16*K16 -> 155000
A17: 6 | B17: ='SAF 011 - NECESIDAD TRIMESTRAL'!B15 -> 4.3.7-32.680 | C17: ='SAF 011 - NECESIDAD TRIMESTRAL'!E15 -> BIBLIOTECAS; MATERIAL: MELAMINA, CANT. PUERTAS: 2, TERMINACION: LAMINADO, DIMENSION (ANCHO/PROF/ALTO): 120 X 40 X 180 Cm | H17: SI | I17: ='SAF 011 - NECESIDAD TRIMESTRAL'!F15 -> UNIDAD | J17: ='SAF 011 - NECESIDAD TRIMESTRAL'!AX15 -> 31000 | K17: ='SAF 011 - NECESIDAD TRIMESTRAL'!AU15 -> 70 | P17: =+J17*K17 -> 2170000
A18: 7 | B18: ='SAF 011 - NECESIDAD TRIMESTRAL'!B16 -> 4.3.7-5605.1 | C18: ='SAF 011 - NECESIDAD TRIMESTRAL'!E16 -> BIOMBOS; TIPO: PLEGABLE, DIMENSION: 2 X 2 M, USO: SANITARIO | H18: SI | I18: ='SAF 011 - NECESIDAD TRIMESTRAL'!F16 -> UNIDAD | J18: ='SAF 011 - NECESIDAD TRIMESTRAL'!AX16 -> 18500 | K18: ='SAF 011 - NECESIDAD TRIMESTRAL'!AU16 -> 70 | P18: =+J18*K18 -> 1295000
A19: 8 | B19: ='SAF 011 - NECESIDAD TRIMESTRAL'!B17 -> 4.3.9-8811.3 | C19: ='SAF 011 - NECESIDAD TRIMESTRAL'!E17 -> CALOVENTILADORES; TIPO: AIRE, CAPACIDAD CALORICA: 1800 W, CAUDAL: CONTINUO, MOTOR: ELECTRICO | H19: SI | I19: ='SAF 011 - NECESIDAD TRIMESTRAL'!F17 -> UNIDAD | J19: ='SAF 011 - NECESIDAD TRIMESTRAL'!AX17 -> 4000 | K19: ='SAF 011 - NECESIDAD TRIMESTRAL'!AU17 -> 210 | P19: =+J19*K19 -> 840000
A20: 9 | B20: ='SAF 011 - NECESIDAD TRIMESTRAL'!B18 -> 4.3.7-2207.2 | C20: ='SAF 011 - NECESIDAD TRIMESTRAL'!E18 -> CAMAS; LARGO X ANCHO: 190 X 80 Cm, MATERIAL: MADERA, TERMINACION: LUSTRE NATURAL, TIPO: 1PLAZA | H20: SI | I20: ='SAF 011 - NECESIDAD TRIMESTRAL'!F18 -> UNIDAD | J20: ='SAF 011 - NECESIDAD TRIMESTRAL'!AX18 -> 20000 | K20: ='SAF 011 - NECESIDAD TRIMESTRAL'!AU18 -> 10 | P20: =+J20*K20 -> 200000
A21: 10 | B21: ='SAF 011 - NECESIDAD TRIMESTRAL'!B19 -> 2.2.9-701.57 | C21: ='SAF 011 - NECESIDAD TRIMESTRAL'!E19 -> COLCHONES; DIMENSION: 190 X 80 Cm, DENSIDAD: 25 kg/cm3, ESPESOR: 21 Cm, CONSTRUCCION: ESPUMA, TERMINACION: MATELASSEADO | H21: SI | I21: ='SAF 011 - NECESIDAD TRIMESTRAL'!F19 -> UNIDAD | J21: ='SAF 011 - NECESIDAD TRIMESTRAL'!AX19 -> 20000 | K21: ='SAF 011 - NECESIDAD TRIMESTRAL'!AU19 -> 10 | N21: =+J21*K21 -> 200000
A22: 11 | B22: ='SAF 011 - NECESIDAD TRIMESTRAL'!B20 -> 2.2.3-917.25 | C22: ='SAF 011 - NECESIDAD TRIMESTRAL'!E20 -> CUBRECAMA; TIPO: ACOLCHADO, TAMAÑO: 1 1/2 PLAZA, MATERIAL: ALGODON Y POLIESTER | H22: SI | I22: ='SAF 011 - NECESIDAD TRIMESTRAL'!F20 -> UNIDAD | J22: ='SAF 011 - NECESIDAD TRIMESTRAL'!AX20 -> 3200 | K22: ='SAF 011 - NECESIDAD TRIMESTRAL'!AU20 -> 300 | M22: =+K22*J22 -> 960000
A23: 12 | B23: ='SAF 011 - NECESIDAD TRIMESTRAL'!B21 -> 4.3.7-37.82 | C23: ='SAF 011 - NECESIDAD TRIMESTRAL'!E21 -> ESCALERAS; MATERIAL: METAL, ESCALONES: 2, TRAMOS: UNICO, DESARROLLO: PLANO UNICO, SOPORTE: APOYO | H23: SI | I23: ='SAF 011 - NECESIDAD TRIMESTRAL'!F21 -> UNIDAD | J23: ='SAF 011 - NECESIDAD TRIMESTRAL'!AX21 -> 7500 | K23: ='SAF 011 - NECESIDAD TRIMESTRAL'!AU21 -> 50 | P23: =+J23*K23 -> 375000
A24: 13 | B24: ='SAF 011 - NECESIDAD TRIMESTRAL'!B22 -> 4.3.7-4502.8 | C24: ='SAF 011 - NECESIDAD TRIMESTRAL'!E22 -> ESCRITORIOS ERGONOMICOS; MATERIAL ESTRUCTURA: AGLOMERADO, ALTURA: 75 Cm, CAJONERA: SI, CAJONES: 3, TIRANTE SOBRE CAJON: SIN, BANDEJA PORTATECLADO: CON, PASACABLES: CON, TERMINACION: MELAMINA, ANCHO MAYOR: 120 Cm, ANCHO MENOR: SIN VALOR, PROF. MAYOR: 70 Cm, PROF. MENOR: SIN VALOR, CANTIDAD DE CAJONES: 3, MATERIAL: AGLOMERADO, ANCHO MAXIMO: 120 Cm, PROFUNDIDAD MAXIMA: 70 Cm, DIMENSION (A/P/H): 120 X 70 X 75 Cm | H24: SI | I24: ='SAF 011 - NECESIDAD TRIMESTRAL'!F22 -> UNIDAD | J24: ='SAF 011 - NECESIDAD TRIMESTRAL'!AX22 -> 22000 | K24: ='SAF 011 - NECESIDAD TRIMESTRAL'!AU22 -> 150 | P24: =+J24*K24 -> 3300000
A25: 14 | B25: ='SAF 011 - NECESIDAD TRIMESTRAL'!B23 -> 4.3.7-40.38 | C25: ='SAF 011 - NECESIDAD TRIMESTRAL'!E23 -> ESCRITORIOS; CAJONERA: 2 IZQUIERDA, 2 DERECHA, TIRANTE SOBRE CAJON.: SIN, TERMINACION: REVESTIMIENTO MELAMINICO, DIM. DEL PLANO DE UNION: SIN VALOR, DIM. DEL PLANO DE APOYO: SIN VALOR, DIM. DE LAS PANTALLA DIVISORIA: SIN VALOR, DIM. DEL PLANO DE EXTENSION: SIN VALOR, BANDEJA PORTATECLADO: SIN VALOR, PASACABLES: SIN VALOR, MATERIAL ESTRUCTURA: AGLOMERADO, CAJONES: 4, CANTIDAD DE CAJONES: 4 | H25: SI | I25: ='SAF 011 - NECESIDAD TRIMESTRAL'!F23 -> UNIDAD | J25: ='SAF 011 - NECESIDAD TRIMESTRAL'!AX23 -> 23000 | K25: ='SAF 011 - NECESIDAD TRIMESTRAL'!AU23 -> 150 | P25: =+J25*K25 -> 3450000
A26: 15 | B26: ='SAF 011 - NECESIDAD TRIMESTRAL'!B24 -> 4.3.7-1404.22 | C26: ='SAF 011 - NECESIDAD TRIMESTRAL'!E24 -> ESTANTERIAS; MATERIAL: METAL, DIMENSION: 205 X 60 Cm, ALTURA: 260 Cm, ESTANTES: 6 UN, CAPACIDAD POR ESTANTE: SIN VALOR | H26: SI | I26: ='SAF 011 - NECESIDAD TRIMESTRAL'!F24 -> UNIDAD | J26: ='SAF 011 - NECESIDAD TRIMESTRAL'!AX24 -> 40000 | K26: ='SAF 011 - NECESIDAD TRIMESTRAL'!AU24 -> 30 | P26: =+J26*K26 -> 1200000
A27: 16 | B27: ='SAF 011 - NECESIDAD TRIMESTRAL'!B25 -> 2.2.3-920.42 | C27: ='SAF 011 - NECESIDAD TRIMESTRAL'!E25 -> FRAZADAS; MATERIAL: POLAR, TAMAÑO: 1 1/2 PLAZA | H27: SI | I27: ='SAF 011 - NECESIDAD TRIMESTRAL'!F25 -> UNIDAD | J27: ='SAF 011 - NECESIDAD TRIMESTRAL'!AX25 -> 3000 | K27: ='SAF 011 - NECESIDAD TRIMESTRAL'!AU25 -> 300 | M27: =+K27*J27 -> 900000
A28: 17 | B28: ='SAF 011 - NECESIDAD TRIMESTRAL'!B26 -> 4.3.7-4500.4 | C28: ='SAF 011 - NECESIDAD TRIMESTRAL'!E26 -> GAVETEROS; MATERIAL: METAL, ALTURA: 240 Cm, ANCHO: 110 Cm, PROFUNDIDAD: 36 Cm, TERMINACION: ESMALTE, CANTIDAD DE CAJONES: 32 | H28: SI | I28: ='SAF 011 - NECESIDAD TRIMESTRAL'!F26 -> UNIDAD | J28: ='SAF 011 - NECESIDAD TRIMESTRAL'!AX26 -> 9000 | K28: ='SAF 011 - NECESIDAD TRIMESTRAL'!AU26 -> 100 | P28: =+J28*K28 -> 900000
A29: 18 | B29: ='SAF 011 - NECESIDAD TRIMESTRAL'!B27 -> 4.3.7-15.123 | C29: ='SAF 011 - NECESIDAD TRIMESTRAL'!E27 -> HELADERAS; CAPACIDAD: 400 L, FRIO: CON FREEZER, CONSUMO: MENOR A 5 KVA, TENSION NOMINAL: 220 V, CRITERIO DE SEGURIDAD: SELLO DE SEGURIDAD, CORRIENTE NOMINAL: MENOR A 63 A, EFICIENCIA ENERGETICA: GRADO A | H29: SI | I29: ='SAF 011 - NECESIDAD TRIMESTRAL'!F27 -> UNIDAD | J29: ='SAF 011 - NECESIDAD TRIMESTRAL'!AX27 -> 136000 | K29: ='SAF 011 - NECESIDAD TRIMESTRAL'!AU27 -> 10 | P29: =+J29*K29 -> 1360000
A30: 19 | B30: ='SAF 011 - NECESIDAD TRIMESTRAL'!B28 -> 4.3.7-96.28 | C30: ='SAF 011 - NECESIDAD TRIMESTRAL'!E28 -> HORNOS MICROONDAS; CAPACIDAD: 30 L, DIMENSION (A/P/H): 520 X 510 X 500 mm, ACCESORIO: BANDEJA, MATERIAL INTERNO: CHAPA ESMALTADA, POTENCIA: 1000 W, TENSION NOMINAL: 220 V, CORRIENTE NOMINAL: 4,5 A, CONSUMO: 800 W, CRITERIO DE SEGURIDAD: SELLO DE SEGURIDAD, EFICIENCIA ENERGETICA: SIN VALOR | H30: SI | I30: ='SAF 011 - NECESIDAD TRIMESTRAL'!F28 -> UNIDAD | J30: ='SAF 011 - NECESIDAD TRIMESTRAL'!AX28 -> 24599 | K30: ='SAF 011 - NECESIDAD TRIMESTRAL'!AU28 -> 1 | P30: =+J30*K30 -> 24599
A31: 20 | B31: ='SAF 011 - NECESIDAD TRIMESTRAL'!B29 -> 4.3.9-2757.58 | C31: ='SAF 011 - NECESIDAD TRIMESTRAL'!E29 -> LAVADORAS; USO: ROPA, CAPACIDAD: 10 Kg, VAPOR SOBRECALENTADO: SIN, BOMBA ADICIONAL: SIN, ALIMENTACION: 220 V, TENSION NOMINAL: 220/224 V, CORRIENTE NOMINAL: 10 A, CRITERIO DE SEGURIDAD: SELLO DE SEGURIDAD, CONSUMO: 6 KW, EFICIENCIA ENERGETICA: SIN VALOR | H31: SI | I31: ='SAF 011 - NECESIDAD TRIMESTRAL'!F29 -> UNIDAD | J31: ='SAF 011 - NECESIDAD TRIMESTRAL'!AX29 -> 96000 | K31: ='SAF 011 - NECESIDAD TRIMESTRAL'!AU29 -> 10 | P31: =+J31*K31 -> 960000
A32: 21 | B32: ='SAF 011 - NECESIDAD TRIMESTRAL'!B30 -> 4.3.7-2012.7 | C32: ='SAF 011 - NECESIDAD TRIMESTRAL'!E30 -> LOCKERS; MATERIAL ESTRUCTURA: 147 dBV/mPa , DIMENSION: 182 X 78 X 52 Cm, CANTIDAD CASILLEROS: 6, ESTANTES: CON, PUERTAS: 6, CAJONES: SIN, CANTIDAD DE CAJONES: SIN, MATERIAL: METAL, CANT. PUERTAS: 6, CANTIDAD DE CASILLEROS: 6 | H32: SI | I32: ='SAF 011 - NECESIDAD TRIMESTRAL'!F30 -> UNIDAD | J32: ='SAF 011 - NECESIDAD TRIMESTRAL'!AX30 -> 50000 | K32: ='SAF 011 - NECESIDAD TRIMESTRAL'!AU30 -> 48 | P32: =+J32*K32 -> 2400000
A33: 22 | B33: ='SAF 011 - NECESIDAD TRIMESTRAL'!B31 -> 4.3.7-2208.50 | C33: ='SAF 011 - NECESIDAD TRIMESTRAL'!E31 -> MESAS DE LUZ; ANCHO: 45 Cm, PROFUNDIDAD: 40 Cm, MATERIAL: METAL, TERMINACION: MELAMINA | H33: SI | I33: ='SAF 011 - NECESIDAD TRIMESTRAL'!F31 -> UNIDAD | J33: ='SAF 011 - NECESIDAD TRIMESTRAL'!AX31 -> 23823.99 | K33: ='SAF 011 - NECESIDAD TRIMESTRAL'!AU31 -> 80 | P33: =+J33*K33 -> 1905919.2
A34: 23 | B34: ='SAF 011 - NECESIDAD TRIMESTRAL'!B32 -> 4.3.7-1406.271 | C34: ='SAF 011 - NECESIDAD TRIMESTRAL'!E32 -> MESAS DE REUNIONES; SUPERFICIE APOYO: AGLOMERADO, TERMINACION: LAMINADO MELAMINICO, DIM. DEL PLANO DE APOYO: 240 X 110 Cm, BASE: AGLOMERADO, CAPACIDAD: 8 PERSONAS, MATERIAL: AGLOMERADO | H34: SI | I34: ='SAF 011 - NECESIDAD TRIMESTRAL'!F32 -> UNIDAD | J34: ='SAF 011 - NECESIDAD TRIMESTRAL'!AX32 -> 28000 | K34: ='SAF 011 - NECESIDAD TRIMESTRAL'!AU32 -> 7 | P34: =+J34*K34 -> 196000
A35: 24 | B35: ='SAF 011 - NECESIDAD TRIMESTRAL'!B33 -> 4.3.7-5446.1 | C35: ='SAF 011 - NECESIDAD TRIMESTRAL'!E33 -> MESAS P/CAMAS; BASE: ACERO INOXIDABLE, ALTURA: REGULABLE, DIMENSION DE TAPA: 50 X 80 Cm, MATERIAL DE TAPA: LAMINADA EN MELAMINA, SUPERFICIE APOYO: 50 X 80 Cm | H35: SI | I35: ='SAF 011 - NECESIDAD TRIMESTRAL'!F33 -> UNIDAD | J35: ='SAF 011 - NECESIDAD TRIMESTRAL'!AX33 -> 12000 | K35: ='SAF 011 - NECESIDAD TRIMESTRAL'!AU33 -> 100 | P35: =+J35*K35 -> 1200000
A36: 25 | B36: ='SAF 011 - NECESIDAD TRIMESTRAL'!B34 -> 4.3.7-1910.21 | C36: ='SAF 011 - NECESIDAD TRIMESTRAL'!E34 -> MESAS P/IMPRESORAS; MATERIAL: MADERA, DIM. APROX. (ANCHO/PROF/ALTO): 250 X 45 X 85 Cm | H36: SI | I36: ='SAF 011 - NECESIDAD TRIMESTRAL'!F34 -> UNIDAD | J36: ='SAF 011 - NECESIDAD TRIMESTRAL'!AX34 -> 10000 | K36: ='SAF 011 - NECESIDAD TRIMESTRAL'!AU34 -> 1 | P36: =+J36*K36 -> 10000
A37: 26 | B37: ='SAF 011 - NECESIDAD TRIMESTRAL'!B35 -> 4.3.9-7935.2 | C37: ='SAF 011 - NECESIDAD TRIMESTRAL'!E35 -> MESAS P/PLANCHADO; ESTRUCTURA: HIERRO REFORZADO, DIMENSION: 1 X 0,5 M, TERMINACION: TELA DE AMIANTO, MATERIAL ESTRUCTURA: HIERRO REFORZADO | H37: SI | I37: ='SAF 011 - NECESIDAD TRIMESTRAL'!F35 -> UNIDAD | J37: ='SAF 011 - NECESIDAD TRIMESTRAL'!AX35 -> 8200 | K37: ='SAF 011 - NECESIDAD TRIMESTRAL'!AU35 -> 10 | P37: =+J37*K37 -> 82000
A38: 27 | B38: ='SAF 011 - NECESIDAD TRIMESTRAL'!B36 -> 4.3.7-9066.3 | C38: ='SAF 011 - NECESIDAD TRIMESTRAL'!E36 -> PAVAS ELECTRICAS; MATERIAL: ALUMINIO, CAPACIDAD: 1,7 L, POTENCIA: 2100 W, TENSION NOMINAL: 220 V, CORRIENTE NOMINAL: MENOR A 63 A, CONSUMO: MENOR A 5 KVA, CRITERIO DE SEGURIDAD: SELLO DE SEGURIDAD | H38: SI | I38: ='SAF 011 - NECESIDAD TRIMESTRAL'!F36 -> UNIDAD | J38: ='SAF 011 - NECESIDAD TRIMESTRAL'!AX36 -> 5000 | K38: ='SAF 011 - NECESIDAD TRIMESTRAL'!AU36 -> 20 | P38: =+J38*K38 -> 100000
A39: 28 | B39: ='SAF 011 - NECESIDAD TRIMESTRAL'!B37 -> 4.3.9-2489.10 | C39: ='SAF 011 - NECESIDAD TRIMESTRAL'!E37 -> PLANCHAS; CONSUMO: 800 W, CRITERIO DE SEGURIDAD: SELLO DE SEGURIDAD, CORRIENTE NOMINAL: MENOR A 63 A, TENSION NOMINAL: 220 - 240 V, ACCESORIO: CON, TIPO: ELECTRICA | H39: SI | I39: ='SAF 011 - NECESIDAD TRIMESTRAL'!F37 -> UNIDAD | J39: ='SAF 011 - NECESIDAD TRIMESTRAL'!AX37 -> 4500 | K39: ='SAF 011 - NECESIDAD TRIMESTRAL'!AU37 -> 10 | P39: =+J39*K39 -> 45000
A40: 29 | B40: ='SAF 011 - NECESIDAD TRIMESTRAL'!B38 -> 4.3.7-1880.1 | C40: ='SAF 011 - NECESIDAD TRIMESTRAL'!E38 -> RELOJES; TAMAÑO: 30 X 25 Cm, ALIMENTACION: ELECTRICA, MECANISMO: ANALOGICO, TIPO: DE PARED, MATERIAL: PLASTICO | H40: SI | I40: ='SAF 011 - NECESIDAD TRIMESTRAL'!F38 -> UNIDAD | J40: ='SAF 011 - NECESIDAD TRIMESTRAL'!AX38 -> 2300 | K40: ='SAF 011 - NECESIDAD TRIMESTRAL'!AU38 -> 30 | P40: =+J40*K40 -> 69000
A41: 30 | B41: ='SAF 011 - NECESIDAD TRIMESTRAL'!B39 -> 2.2.3-923.1 | C41: ='SAF 011 - NECESIDAD TRIMESTRAL'!E39 -> SABANAS; TELA: PURO ALGODON, TAMAÑO: 1 PLAZA, CONJUNTO: SUPERIOR,INFERIOR Y FUNDA | H41: SI | I41: ='SAF 011 - NECESIDAD TRIMESTRAL'!F39 -> UNIDAD | J41: ='SAF 011 - NECESIDAD TRIMESTRAL'!AX39 -> 3000 | K41: ='SAF 011 - NECESIDAD TRIMESTRAL'!AU39 -> 300 | M41: =+K41*J41 -> 900000
A42: 31 | B42: ='SAF 011 - NECESIDAD TRIMESTRAL'!B40 -> 4.3.9-2655.27 | C42: ='SAF 011 - NECESIDAD TRIMESTRAL'!E40 -> SECARROPAS/CENTRIFUGA; TIPO: ROTATIVO, SECADO: POR CALOR, CAPACIDAD: 10 Kg, TENSION NOMINAL: 220 V, CORRIENTE NOMINAL: 10 A, CRITERIO DE SEGURIDAD: SELLO DE SEGURIDAD, CONSUMO: 6 KW, EFICIENCIA ENERGETICA: GRADO B | H42: SI | I42: ='SAF 011 - NECESIDAD TRIMESTRAL'!F40 -> UNIDAD | J42: ='SAF 011 - NECESIDAD TRIMESTRAL'!AX40 -> 80000 | K42: ='SAF 011 - NECESIDAD TRIMESTRAL'!AU40 -> 10 | P42: =+J42*K42 -> 800000
...

Sheet APG
A1: EJERCICIO: | D1: 2022 | P1: AUTORIZACION PARA GASTAR
A4: JURISDICCIÓN: | G4: =NP!D3 -> 040 - MINISTERIO DE SALUD
A5: SAF: | G5: =NP!D4 -> 011 - DIRECCION PROVINCIAL DE ADMINISTRACION DEL MINISTERIO DE SALUD
A6: UNIDAD EJECUTORA: | G6: =NP!D5 -> 352 - MINISTERIO DE SALUD
A7: DEPENDENCIA SOLICITANTE: | G7: =NP!D6 -> 352 - MINISTERIO DE SALUD
A8: AUTORIZACIÓN:
A9: Señor Director de Administración o Titular del Servicio Administrativo Financiero:
A10: Autorizo la realización de los trámites correspondientes, a fin de proveer a este Organismo los bienes, servicios o ejecución de obras públicas que se detallan en Nota de Pedido N° 07/2022 , afectando la erogación resultante a los créditos presupuestarios aprobados a favor de esta Unidad Ejecutora, conforme al siguiente detalle:
A12: IMPUTACIÓN PRESUPUESTARIA
A13: CÓDIGO | O13: DENOMINACIÓN DE LA PARTIDA PRESUPUESTARIA | Q13: IMPORTE
A14: PR | B14: SB | C14: PY | D14: AC | E14: OB | F14: UG | G14: FIN | H14: FUN | I14: I | J14: P | K14: P | L14: SubP | M14: M | N14: FF
A15: 1 | D15: 1 | F15: 4901 | G15: 3 | H15: 1 | I15: 2 | J15: 2 | K15: 3 | M15: 1 | N15: 1.1 | O15: CONFECCIONES TEXTILES | Q15: =NP!M50 -> 2760000
A16: 1 | D16: 1 | F16: 4901 | G16: 3 | H16: 1 | I16: 2 | J16: 2 | K16: 9 | M16: 1 | N16: 1.1 | O16: OTROS NEP | Q16: =NP!N50 -> 620000
A17: 1 | D17: 1 | F17: 4901 | G17: 3 | H17: 1 | I17: 2 | J17: 9 | K17: 1 | M17: 1 | N17: 1.1 | O17: ELEMENTOS DE LIMPIEZA | Q17: =NP!O50 -> 4962000
A18: 1 | D18: 1 | F18: 4901 | G18: 3 | H18: 1 | I18: 4 | J18: 3 | K18: 7 | M18: 1 | N18: 1.1 | O18: EQUIPOS DE OFICINA Y MUEBLES | Q18: =NP!P50 -> 48789518
A38: TOTAL DE PESOS: CINCUENTA Y SIETE MILLONES CIENTO TREINTA Y UN MIL QUINIENTOS DIECIOCHO CON 20/100.- | Q38: =SUM(Q15:Q37) -> 57131518
A40: JUSTIFICACIÓN:
A41: =NP!D8 -> ADQUISICION DE ARTICULOS DE HOGAR Y MUEBLES CON DESTINO A HOSPITALES DE LA PROVINCIA
