Workbook

Sheet Necesidades Trimestrales
B2: Pedido de Necesidades Trimestrales
A4: JURISDICCION: | C4: 90 - Ministerio de Seguridad
A5: SAF N°: | C5: 7 - Direccion Provincial de Administracion de la Policia de Catamarca
A6: EJERCICIO: | C6: 2021
A7: TRIMESTRE: | C7: 1
A9: ID | B9: CODIGO ITEM | C9: RUBRO DE COMPRA | D9: I.P.P. | E9: DESCRIPCION | F9: UNIDAD DE MEDIDA | G9: CANTIDAD | H9: PRECIO UNITARIO ESTIMADO | I9: IMPORTE TOTAL ESTIMADO
A10: 1 | B10: 2.5.6-797.24 | C10: COMBUSTIBLES Y LUBRICANTES | D10: =LEFT(B10,5) -> 2.5.6 | E10: NAFTA SUPER; TIPO: PREMIUN, OCTANO: 97, PRESENTACION: POR LITRO, DESTINO: DPTO. S.F.V. DE CATAMARCA, COMERCIALIZACION: SIN VALOR | F10: LITROS EN VALES | G10: =63000*2 -> 126000 | H10: 75.6 | I10: =G10*H10 -> 9525600 | J10: =SUM(I10:I11) -> 29983840 | K10: =15000000*30/100 -> 4500000 | L10: =I10-K10 -> 5025600 | M10: =J10/2 -> 14991920 | N10: =SUM(I10:I11) -> 29983840
A11: 2 | B11: 2.5.6-793.31 | C11: COMBUSTIBLES Y LUBRICANTES | D11: =LEFT(B11,5) -> 2.5.6 | E11: GAS OIL; PRESENTACION: POR LITRO, USO: MOTORES DIESEL, COMERCIALIZACION: GRADO 3, DESTINO: DPTO. S.F.V. DE CATAMARCA | F11: LITROS EN VALES | G11: =145300*2 -> 290600 | H11: 70.4 | I11: =G11*H11 -> 20458240 | K11: =15000000*70/100 -> 10500000 | L11: =I11-K11 -> 9958240 | N11: =15000000-N10 -> -14983840
A12: 3 | B12: 2.5.6-797.28 | C12: COMBUSTIBLES Y LUBRICANTES | D12: =LEFT(B12,5) -> 2.5.6 | E12: NAFTA SUPER; TIPO: PREMIUN, OCTANO: 97, PRESENTACION: POR LITRO, DESTINO: DPTO. LA PAZ, COMERCIALIZACION: SIN VALOR | F12: LITROS EN VALES | G12: 2227 | H12: 77 | I12: =G12*H12 -> 171479 | J12: =SUM(I12:I13) -> 599790
A13: 4 | B13: 2.5.6-793.35 | C13: COMBUSTIBLES Y LUBRICANTES | D13: =LEFT(B13,5) -> 2.5.6 | E13: GAS OIL; PRESENTACION: POR LITRO, USO: MOTORES DIESEL, COMERCIALIZACION: GRADO 3, DESTINO: DPTO. LA PAZ | F13: LITROS EN VALES | G13: 6110 | H13: 70.1 | I13: =G13*H13 -> 428311 | K13: =600000*30/100 -> 180000 | L13: =I12-K13 -> -8521 | N13: =SUM(I12:I13) -> 599790
A14: 5 | B14: 2.5.6-797.53 | C14: COMBUSTIBLES Y LUBRICANTES | D14: =LEFT(B14,5) -> 2.5.6 | E14: NAFTA SUPER; TIPO: PREMIUN, OCTANO: 97, PRESENTACION: POR LITRO, DESTINO: DPTO. BELEN COMERCIALIZACION: SIN VALOR | F14: LITROS EN VALES | G14: 2165 | H14: 76.9 | I14: =G14*H14 -> 166488.5 | J14: =SUM(I14:I15) -> 599076.5 | K14: =600000*70/100 -> 420000 | L14: =I13-K14 -> 8311
A15: 6 | B15: 2.5.6-793.37 | C15: COMBUSTIBLES Y LUBRICANTES | D15: =LEFT(B15,5) -> 2.5.6 | E15: GAS OIL; PRESENTACION: POR LITRO, USO: MOTORES DIESEL, COMERCIALIZACION: GRADO 3, DESTINO: DPTO. BELEN | F15: LITROS EN VALES | G15: 6110 | H15: 70.8 | I15: =G15*H15 -> 432588
A16: 7 | B16: 2.5.6-797.29 | C16: COMBUSTIBLES Y LUBRICANTES | D16: =LEFT(B16,5) -> 2.5.6 | E16: NAFTA SUPER; TIPO: PREMIUN, OCTANO: 97, PRESENTACION: POR LITRO, DESTINO: DPTO. ANDALGALA, COMERCIALIZACION: SIN VALOR | F16: LITROS EN VALES | G16: 1560 | H16: 86.7 | I16: =G16*H16 -> 135252 | J16: =SUM(I16:I17) -> 599790
A17: 8 | B17: 2.5.6-793.45 | C17: COMBUSTIBLES Y LUBRICANTES | D17: =LEFT(B17,5) -> 2.5.6 | E17: GAS OIL; PRESENTACION: POR LITRO, USO: MOTORES DIESEL, COMERCIALIZACION: GRADO 3, DESTINO: DPTO. ANDALGALA | F17: LITROS EN VALES | G17: 5570 | H17: 83.4 | I17: =G17*H17 -> 464538
A18: 9 | B18: 2.5.6-797.45 | C18: COMBUSTIBLES Y LUBRICANTES | D18: =LEFT(B18,5) -> 2.5.6 | E18: NAFTA SUPER; TIPO: PREMIUN, OCTANO: 97, PRESENTACION: POR LITRO, DESTINO: DPTO. TINOGASTA, COMERCIALIZACION: SIN VALOR | F18: LITROS EN VALES | G18: 1500 | H18: 82.2 | I18: =G18*H18 -> 123300 | J18: =SUM(I18:I19) -> 599863.5
A19: 10 | B19: 2.5.6-793.36 | C19: COMBUSTIBLES Y LUBRICANTES | D19: =LEFT(B19,5) -> 2.5.6 | E19: GAS OIL; PRESENTACION: POR LITRO, USO: MOTORES DIESEL, COMERCIALIZACION: GRADO 3, DESTINO: DPTO. TINOGASTA | F19: LITROS EN VALES | G19: 5535 | H19: 86.1 | I19: =G19*H19 -> 476563.5
A20: 11 | B20: 2.5.6-797.47 | C20: COMBUSTIBLES Y LUBRICANTES | D20: =LEFT(B20,5) -> 2.5.6 | E20: NAFTA SUPER; TIPO: PREMIUN, OCTANO: 97, PRESENTACION: POR LITRO, DESTINO: DPTO. EL ALTO, COMERCIALIZACION: SIN VALOR | F20: LITROS EN VALES | G20: 2235 | H20: 77 | I20: =G20*H20 -> 172095 | J20: =SUM(I20:I21) -> 599705
A21: 12 | B21: 2.5.6-793.39 | C21: COMBUSTIBLES Y LUBRICANTES | D21: =LEFT(B21,5) -> 2.5.6 | E21: GAS OIL; PRESENTACION: POR LITRO, USO: MOTORES DIESEL, COMERCIALIZACION: GRADO 3, DESTINO: DPTO. EL ALTO | F21: LITROS EN VALES | G21: 6100 | H21: 70.1 | I21: =G21*H21 -> 427610
A22: 13 | B22: 2.5.6-797.32 | C22: COMBUSTIBLES Y LUBRICANTES | D22: =LEFT(B22,5) -> 2.5.6 | E22: NAFTA SUPER; TIPO: PREMIUN, OCTANO: 97, PRESENTACION: POR LITRO, DESTINO: DPTO. STA. MARIA, COMERCIALIZACION: SIN VALOR | F22: LITROS EN VALES | G22: 1510 | H22: 87.99 | I22: =G22*H22 -> 132864.9 | J22: =SUM(I22:I23) -> 599849.3
A23: 14 | B23: 2.5.6-793.38 | C23: COMBUSTIBLES Y LUBRICANTES | D23: =LEFT(B23,5) -> 2.5.6 | E23: GAS OIL; PRESENTACION: POR LITRO, USO: MOTORES DIESEL, COMERCIALIZACION: GRADO 3, DESTINO: DPTO. STA. MARIA | F23: LITROS EN VALES | G23: 5560 | H23: 83.99 | I23: =G23*H23 -> 466984.4
A24: 15 | B24: 2.5.6-797.26 | C24: COMBUSTIBLES Y LUBRICANTES | D24: =LEFT(B24,5) -> 2.5.6 | E24: NAFTA SUPER; TIPO: PREMIUN, OCTANO: 97, PRESENTACION: POR LITRO, DESTINO: DPTO. POMAN, COMERCIALIZACION: SIN VALOR | F24: LITROS EN VALES | G24: 1560 | H24: 86.7 | I24: =G24*H24 -> 135252 | J24: =SUM(I24:I25) -> 599790
A25: 16 | B25: 2.5.6-793.33 | C25: COMBUSTIBLES Y LUBRICANTES | D25: =LEFT(B25,5) -> 2.5.6 | E25: GAS OIL; PRESENTACION: POR LITRO, USO: MOTORES DIESEL, COMERCIALIZACION: GRADO 3, DESTINO: DPTO. POMAN | F25: LITROS EN VALES | G25: 5570 | H25: 83.4 | I25: =G25*H25 -> 464538
A26: 17 | B26: 2.5.6-7104.19 | C26: COMBUSTIBLES Y LUBRICANTES | D26: =LEFT(B26,5) -> 2.5.6 | E26: ACEITES LUBRICANTES; DENOMINACION: SAE 15 W 40, USO: AUTOMOTOR, PRESENTACION: TAMBOR X 205 L, NORMA: SAE 15 W 40 | F26: UNIDAD | G26: 2 | H26: 54000 | I26: =G26*H26 -> 108000
A27: 18 | B27: 2.5.6-7104.503 | C27: COMBUSTIBLES Y LUBRICANTES | D27: =LEFT(B27,5) -> 2.5.6 | E27: ACEITES LUBRICANTES; USO: AUTOMOTOR, PRESENTACION: ENVASE X 20 L, NORMA: 5W-30, COMERCIALIZACION: POR UNIDAD | F27: UNIDAD | G27: 7 | H27: 18900 | I27: =G27*H27 -> 132300 | K27: =SUM(I26:I28) -> 294300
A28: 19 | B28: 2.5.6-7104.31 | C28: COMBUSTIBLES Y LUBRICANTES | D28: =LEFT(B28,5) -> 2.5.6 | E28: ACEITES LUBRICANTES; DENOMINACION: SAE 20 W 50, USO: AUTOMOTOR, PRESENTACION: TAMBOR X 205 L, NORMA: SAE 20 W 50 | F28: UNIDAD | G28: 1 | H28: 54000 | I28: =G28*H28 -> 54000
I29: =SUM(I10:I28) -> 34476004
B31: Especificidades:
B33: Descripción técnica ITEM 1 al 16:
C34: NAFTA SUPER; TIPO: SUPER, OCTANO: 97, PRESENTACION: X LITRO, DESTINO: SIN VALOR - GAS OIL; PRESENTACION: POR LITRO, USO: MOTORES DIESEL, COMERCIALIZACION: GRADO 3
B35: Descripción técnica ITEM17:
C36: Caracteristicas: Aceite Sintético 15W40 con normas ACEA A3/B3, A3/B4. API SN, S, SL, SJ. Para Camioneta Tambor x 205 lts.
B37: Descripción técnica ITEM18:
C38: Caracteristicas: Aceite Semi sintético 5W30 con normas ACEA A3/B3, A3/B4. API SN, S, SL, SJ. Para Camionetas . Envase x 20 lts
B39: Descripción técnica ITEM19:
C40: Caracteristicas: Aceite Semi sintético 20W50 con normas API SL/SJ, SH, SG, JASO MA para motos Tambor x 205 lts
B41: Plazos y lugares de entrega
C42: Plazo de entrega tres 3 días hábiles. Periodo de utilización tres meses. ENTREGA en VALES, según pliego, en la DIRECCIÓN DE ADMINISTRACIÓN sito en Chacabuco N* 809 , San Fernando del Valle de Catamarca, en horario de 8 a 12 horas. El COMBUSTIBLE en la boca de expendio de las cabeceras departamentales. LOS LUBRICANTES , en Dpto. Logística, sito en Av. Felix Avellaneda Km2 RP N 33, Sumalao Valle Viejo, Actividad 1 – U.R. I (Dpto. CAPITAL) COMBUSTIBLE ( $ 15.000.000) 63,000 litros Nafta Súper.- 145,300 litros Gasoil Grado 3.- Actividad 1 – U.R. I (CAPITAL) LUBRICANTES ( $ 300.000) Actividad 7 – INTERIOR PROVINCIAL (Dpto. VALLE VIEJO- Dpto. FME- Dpto.AMBATO - Dpto. PACLIN) COMBUSTIBLE ( $ 15.000.000) 63,000 litros Nafta Súper.- 145.300 litros Gasoil Grado 3.- Actividad 09 – U.R. 2 Dpto. La Paz ($ 600.000) 2.227 litros Nafta Súper.- 6.110 litros Gasoil Grado 3.- Actividad 10 – U.R. 3 Dpto. Belen ($ 600.000) 2.165 litros Nafta Súper.- 6.110 litros Gasoil Grado 3.- Actividad 11 – U.R. 4 (Dpto. Andalgala) ($ 600.000) 1.560 litros Nafta Súper.- 6.100 litros Gasoil Grado 3.- Actividad 12 – U.R. 5 Dpto. Tinogasta ($ 600.000) 2.235 litros Nafta Súper.- 5.570 litros Gasoil Grado 3.- Actividad 13 –Jefatura de Zona “C” (Dpto. El Alto) ($ 600.000) 2.235 litros Nafta Súper.- 6.100 litros Gasoil Grado 3.- Actividad 14 – Jefatura de Zona “D” (Dpto. Santa María) ($ 600.000) 1.510 litros Nafta Súper.- 5.560 litros Gasoil Grado 3.- Actividad 15 – Jefatura de Zona “F” (Dpto. Poman) ($ 600.000) 1.560 litros Nafta Súper.- 6.100 litros Gasoil Grado 3.-
B56: Calidad Minima esperada
C57: Que Cumpla con lo Solicitado de Forma Integra.
B58: Mantenimiento
...

Sheet  NotaPedido
A1: NOTA DE PEDIDO | J1: N° | K1: 08/2021
A3: JURISDICCIÓN: | D3: Ministerio de Seguridad
A4: SAF: | D4: 7 - Direccion de Administracion de la Policía de la Provincia de Catamarca
A5: UNIDAD EJECUTORA: | D5: Policía de la Provincia de Catamarca
A6: DEPENDENCIA SOLICITANTE: | D6: División Transporte Departamento Logistica (D-4)
A7: PERIODO UTILIZACIÓN: | D7: ='Necesidades Trimestrales'!C7 & "° Trimestre - Año " & 'Necesidades Trimestrales'!C6 -> 1° Trimestre - Año 2021
A8: OBJETO: | D8: Adquisición de Combustibles destinados a Moviles de la Policia de la Provincia de Catamarca
A11: Ítem | B11: Codigo Item | C11: DESCRIPCIÓN | H11: Adjunta Detalle Técnico | I11: Unidad Medida | J11: Precio Unitario Estimado | K11: Cantidad Solicitada
A13: ='Necesidades Trimestrales'!A10 -> 1 | B13: ='Necesidades Trimestrales'!B10 -> 2.5.6-797.24 | C13: ='Necesidades Trimestrales'!E10 -> NAFTA SUPER; TIPO: PREMIUN, OCTANO: 97, PRESENTACION: POR LITRO, DESTINO: DPTO. S.F.V. DE CATAMARCA, COMERCIALIZACION: SIN VALOR | H13: SI | I13: =+'Necesidades Trimestrales'!F10 -> LITROS EN VALES | J13: ='Necesidades Trimestrales'!H10 -> 75.6 | K13: ='Necesidades Trimestrales'!G10 -> 126000
A14: ='Necesidades Trimestrales'!A11 -> 2 | B14: ='Necesidades Trimestrales'!B11 -> 2.5.6-793.31 | C14: ='Necesidades Trimestrales'!E11 -> GAS OIL; PRESENTACION: POR LITRO, USO: MOTORES DIESEL, COMERCIALIZACION: GRADO 3, DESTINO: DPTO. S.F.V. DE CATAMARCA | H14: SI | I14: =+'Necesidades Trimestrales'!F11 -> LITROS EN VALES | J14: ='Necesidades Trimestrales'!H11 -> 70.4 | K14: ='Necesidades Trimestrales'!G11 -> 290600
A15: ='Necesidades Trimestrales'!A12 -> 3 | B15: ='Necesidades Trimestrales'!B12 -> 2.5.6-797.28 | C15: ='Necesidades Trimestrales'!E12 -> NAFTA SUPER; TIPO: PREMIUN, OCTANO: 97, PRESENTACION: POR LITRO, DESTINO: DPTO. LA PAZ, COMERCIALIZACION: SIN VALOR | H15: SI | I15: =+'Necesidades Trimestrales'!F12 -> LITROS EN VALES | J15: ='Necesidades Trimestrales'!H12 -> 77 | K15: ='Necesidades Trimestrales'!G12 -> 2227
A16: ='Necesidades Trimestrales'!A13 -> 4 | B16: ='Necesidades Trimestrales'!B13 -> 2.5.6-793.35 | C16: ='Necesidades Trimestrales'!E13 -> GAS OIL; PRESENTACION: POR LITRO, USO: MOTORES DIESEL, COMERCIALIZACION: GRADO 3, DESTINO: DPTO. LA PAZ | H16: SI | I16: =+'Necesidades Trimestrales'!F13 -> LITROS EN VALES | J16: ='Necesidades Trimestrales'!H13 -> 70.1 | K16: ='Necesidades Trimestrales'!G13 -> 6110
A17: ='Necesidades Trimestrales'!A14 -> 5 | B17: ='Necesidades Trimestrales'!B14 -> 2.5.6-797.53 | C17: ='Necesidades Trimestrales'!E14 -> NAFTA SUPER; TIPO: PREMIUN, OCTANO: 97, PRESENTACION: POR LITRO, DESTINO: DPTO. BELEN COMERCIALIZACION: SIN VALOR | H17: SI | I17: =+'Necesidades Trimestrales'!F14 -> LITROS EN VALES | J17: ='Necesidades Trimestrales'!H14 -> 76.9 | K17: ='Necesidades Trimestrales'!G14 -> 2165
A18: ='Necesidades Trimestrales'!A15 -> 6 | B18: ='Necesidades Trimestrales'!B15 -> 2.5.6-793.37 | C18: ='Necesidades Trimestrales'!E15 -> GAS OIL; PRESENTACION: POR LITRO, USO: MOTORES DIESEL, COMERCIALIZACION: GRADO 3, DESTINO: DPTO. BELEN | H18: SI | I18: =+'Necesidades Trimestrales'!F15 -> LITROS EN VALES | J18: ='Necesidades Trimestrales'!H15 -> 70.8 | K18: ='Necesidades Trimestrales'!G15 -> 6110
A19: ='Necesidades Trimestrales'!A16 -> 7 | B19: ='Necesidades Trimestrales'!B16 -> 2.5.6-797.29 | C19: ='Necesidades Trimestrales'!E16 -> NAFTA SUPER; TIPO: PREMIUN, OCTANO: 97, PRESENTACION: POR LITRO, DESTINO: DPTO. ANDALGALA, COMERCIALIZACION: SIN VALOR | H19: SI | I19: =+'Necesidades Trimestrales'!F16 -> LITROS EN VALES | J19: ='Necesidades Trimestrales'!H16 -> 86.7 | K19: ='Necesidades Trimestrales'!G16 -> 1560
A20: ='Necesidades Trimestrales'!A17 -> 8 | B20: ='Necesidades Trimestrales'!B17 -> 2.5.6-793.45 | C20: ='Necesidades Trimestrales'!E17 -> GAS OIL; PRESENTACION: POR LITRO, USO: MOTORES DIESEL, COMERCIALIZACION: GRADO 3, DESTINO: DPTO. ANDALGALA | H20: SI | I20: =+'Necesidades Trimestrales'!F17 -> LITROS EN VALES | J20: ='Necesidades Trimestrales'!H17 -> 83.4 | K20: ='Necesidades Trimestrales'!G17 -> 5570
A21: ='Necesidades Trimestrales'!A18 -> 9 | B21: ='Necesidades Trimestrales'!B18 -> 2.5.6-797.45 | C21: ='Necesidades Trimestrales'!E18 -> NAFTA SUPER; TIPO: PREMIUN, OCTANO: 97, PRESENTACION: POR LITRO, DESTINO: DPTO. TINOGASTA, COMERCIALIZACION: SIN VALOR | H21: SI | I21: =+'Necesidades Trimestrales'!F18 -> LITROS EN VALES | J21: ='Necesidades Trimestrales'!H18 -> 82.2 | K21: ='Necesidades Trimestrales'!G18 -> 1500
A22: ='Necesidades Trimestrales'!A19 -> 10 | B22: ='Necesidades Trimestrales'!B19 -> 2.5.6-793.36 | C22: ='Necesidades Trimestrales'!E19 -> GAS OIL; PRESENTACION: POR LITRO, USO: MOTORES DIESEL, COMERCIALIZACION: GRADO 3, DESTINO: DPTO. TINOGASTA | H22: SI | I22: =+'Necesidades Trimestrales'!F19 -> LITROS EN VALES | J22: ='Necesidades Trimestrales'!H19 -> 86.1 | K22: ='Necesidades Trimestrales'!G19 -> 5535
A23: ='Necesidades Trimestrales'!A20 -> 11 | B23: ='Necesidades Trimestrales'!B20 -> 2.5.6-797.47 | C23: ='Necesidades Trimestrales'!E20 -> NAFTA SUPER; TIPO: PREMIUN, OCTANO: 97, PRESENTACION: POR LITRO, DESTINO: DPTO. EL ALTO, COMERCIALIZACION: SIN VALOR | H23: SI | I23: =+'Necesidades Trimestrales'!F20 -> LITROS EN VALES | J23: ='Necesidades Trimestrales'!H20 -> 77 | K23: ='Necesidades Trimestrales'!G20 -> 2235
A24: ='Necesidades Trimestrales'!A21 -> 12 | B24: ='Necesidades Trimestrales'!B21 -> 2.5.6-793.39 | C24: ='Necesidades Trimestrales'!E21 -> GAS OIL; PRESENTACION: POR LITRO, USO: MOTORES DIESEL, COMERCIALIZACION: GRADO 3, DESTINO: DPTO. EL ALTO | H24: SI | I24: =+'Necesidades Trimestrales'!F21 -> LITROS EN VALES | J24: ='Necesidades Trimestrales'!H21 -> 70.1 | K24: ='Necesidades Trimestrales'!G21 -> 6100
... A31: ='Necesidades Trimestrales'!A28 -> 19 | B31: ='Necesidades Trimestrales'!B28 -> 2.5.6-7104.31 | C31: ='Necesidades Trimestrales'!E28 -> ACEITES LUBRICANTES; DENOMINACION: SAE 20 W 50, USO: AUTOMOTOR, PRESENTACION: TAMBOR X 205 L, NORMA: SAE 20 W 50 | H31: SI | I31: =+'Necesidades Trimestrales'!F28 -> UNIDAD | J31: ='Necesidades Trimestrales'!H28 -> 54000 | K31: ='Necesidades Trimestrales'!G28 -> 1
A32: Costo total estimado: PESOS TREINTA Y CUATRO MILLONES CUATROCIENTOS SETENTA Y SEIS MIL CUATRO CON 30/100.- | J32: =SUMPRODUCT(J13:J31,K13:K31) -> 34476004

Sheet Autor Gastar
A1: EJERCICIO: | D1: ='Necesidades Trimestrales'!C6 -> 2021 | P1: AUTORIZACION PARA GASTAR
A4: JURISDICCIÓN: | G4: =' NotaPedido'!D3 -> Ministerio de Seguridad
A5: SAF: | G5: =' NotaPedido'!D4 -> 7 - Direccion de Administracion de la Policía de la Provincia de Catamarca
A6: UNIDAD EJECUTORA: | G6: =' NotaPedido'!D5 -> Policía de la Provincia de Catamarca
A7: DEPENDENCIA SOLICITANTE: | G7: =' NotaPedido'!D6 -> División Transporte Departamento Logistica (D-4)
A8: AUTORIZACIÓN:
A9: Señor Jefe de Servicio Administrativo Financiero:
A10: ="Autorizo la realización de los trámites correspondientes, a fin de proveer a este Organismo los bienes y/o servicios que se detallan en Nota de Pedido N° " & ' NotaPedido'!K1&", afectando la erogación resultante a los créditos presupuestarios aprobados a favor de esta Unidad Ejecutora, conforme al siguiente detalle:" -> Autorizo la realización de los trámites correspondientes, a fin de proveer a este Organismo los bienes y/o servicios que se detallan en Nota de Pedido N° 08/2021, afectando la erogación resultante a los créditos presupuestarios aprobados a favor de esta Unidad Ejecutora, conforme al siguiente detalle:
A12: IMPUTACIÓN PRESUPUESTARIA
A13: CÓDIGO | O13: DENOMINACIÓN DE LA PARTIDA PRESUPUESTARIA | Q13: IMPORTE
A14: PR | B14: SB | C14: PY | D14: AC | E14: OB | F14: UG | G14: FIN | H14: FUN | I14: I | J14: P | K14: P | L14: SubP | M14: M | N14: FF
A15: 16 | B15: 0 | C15: 0 | D15: 1 | E15: 0 | F15: 10 | G15: 2 | H15: 1 | I15: 2 | J15: 5 | K15: 6 | L15: 0 | M15: 1 | N15: 1.1. | O15: Combustibles y Lubricantes | Q15: ='Necesidades Trimestrales'!M10+'Necesidades Trimestrales'!K27 -> 15286220
A16: 16 | B16: 0 | C16: 0 | D16: 7 | E16: 0 | F16: 10 | G16: 2 | H16: 1 | I16: 2 | J16: 5 | K16: 6 | L16: 0 | M16: 1 | N16: 1.1. | O16: Combustibles y Lubricantes | Q16: ='Necesidades Trimestrales'!M10 -> 14991920
A17: 16 | B17: 0 | C17: 0 | D17: 9 | E17: 0 | F17: 7001 | G17: 2 | H17: 1 | I17: 2 | J17: 5 | K17: 6 | L17: 0 | M17: 1 | N17: 1.1. | O17: Combustibles y Lubricantes | Q17: ='Necesidades Trimestrales'!J12 -> 599790
A18: 16 | B18: 0 | C18: 0 | D18: 10 | E18: 0 | F18: 3501 | G18: 2 | H18: 1 | I18: 2 | J18: 5 | K18: 6 | L18: 0 | M18: 1 | N18: 1.1. | O18: Combustibles y Lubricantes | Q18: ='Necesidades Trimestrales'!J14 -> 599076.5
A19: 16 | B19: 0 | C19: 0 | D19: 11 | E19: 0 | F19: 2101 | G19: 2 | H19: 1 | I19: 2 | J19: 5 | K19: 6 | L19: 0 | M19: 1 | N19: 1.1. | O19: Combustibles y Lubricantes | Q19: ='Necesidades Trimestrales'!J16 -> 599790
A20: 16 | B20: 0 | C20: 0 | D20: 12 | E20: 0 | F20: 10501 | G20: 2 | H20: 1 | I20: 2 | J20: 5 | K20: 6 | L20: 0 | M20: 1 | N20: 1.1. | O20: Combustibles y Lubricantes | Q20: ='Necesidades Trimestrales'!J18 -> 599863.5
A21: 16 | B21: 0 | C21: 0 | D21: 13 | E21: 0 | F21: 5601 | G21: 2 | H21: 1 | I21: 2 | J21: 5 | K21: 6 | L21: 0 | M21: 1 | N21: 1.1. | O21: Combustibles y Lubricantes | Q21: ='Necesidades Trimestrales'!J20 -> 599705
A22: 16 | B22: 0 | C22: 0 | D22: 14 | E22: 0 | F22: 9101 | G22: 2 | H22: 1 | I22: 2 | J22: 5 | K22: 6 | L22: 0 | M22: 1 | N22: 1.1. | O22: Combustibles y Lubricantes | Q22: ='Necesidades Trimestrales'!J22 -> 599849.3
A23: 16 | B23: 0 | C23: 0 | D23: 15 | E23: 0 | F23: 8401 | G23: 2 | H23: 1 | I23: 2 | J23: 5 | K23: 6 | L23: 0 | M23: 1 | N23: 1.1. | O23: Combustibles y Lubricantes | Q23: ='Necesidades Trimestrales'!J24 -> 599790
A24: TOTAL DE PESOS: TREINTA Y CUATRO MILLONES CUATROCIENTOS SETENTA Y SEIS MIL CUATRO CON 30/100.- | Q24: =SUM(Q15:Q23) -> 34476004
A26: JUSTIFICACIÓN:
A27: Para la adquisición de combustibles y lubricantes destinados a las Unidades Móviles de la Policía de Catamarca.
