Workbook

Sheet Necesidades Trimestrales
B2: Pedido de Necesidades Trimestrales
A4: JURISDICCION: | C4: 40- Ministerio de Salud
A5: SAF N°: | C5: 28- Maternidad Provincial 25 de Mayo
A6: EJERCICIO: | C6: 2021
A7: TRIMESTRE: | C7: 3
A9: ID | B9: CODIGO ITEM | C9: RUBRO DE COMPRA | D9: I.P.P. | E9: DESCRIPCION | F9: UNIDAD DE MEDIDA | G9: CANTIDAD | H9: PRECIO UNITARIO ESTIMADO | I9: IMPORTE TOTAL ESTIMADO
A10: 1 | B10: 2.2.9-701.116 | C10: ARTICULOS DEL HOGAR | D10: =LEFT(B10,5) -> 2.2.9 | E10: COLCHONES; CONSTRUCCION: ESPUMA, DIMENSION: 30 X 70 Cm, ESPESOR: 6 Cm, DENSIDAD: 200 Kg/m3, TERMINACION: FUNDA | F10: UNIDAD | G10: 30 | H10: 2500 | I10: 75000
A11: 2 | B11: 2.2.9-702.2 | C11: ARTICULOS DEL HOGAR | D11: =LEFT(B11,5) -> 2.2.9 | E11: ALMOHADAS; DIMENSION: 70 X 35 Cm, CONSTRUCCION: ESPUMA | F11: UNIDAD | G11: 30 | H11: 1200 | I11: 36000
A12: 3 | B12: 2.2.9-701.177 | C12: ARTICULOS DEL HOGAR | D12: =LEFT(B12,5) -> 2.2.9 | E12: COLCHONES; CONSTRUCCION: ARTICULADO ESPUMA ALTA DENS, DIMENSION: 1900 X 870 mm, ESPESOR: 18 Cm, DENSIDAD: 33 Kg/m3, TERMINACION: FORRO PVC SANITARIO | F12: UNIDAD | G12: 60 | H12: 14600 | I12: 876000
B15: Especificidades Item N° 1:
B17: Descripción técnica
C18: COLCHONES NEONATALES CON FORRO DE VINIL COLOR BLANCO
B19: Plazos y lugares de entrega
C20: 10 DIAS DESDE LA FIRMA DEL INSTRUMENTO CONTRACTUAL
D21: SERVICIO DE ENFERMERIA HORARIO DE 08:00 A 12:00
C22: MATERNIDAD PROVINCIAL 25 DE MAYO, HERNANDO DE PEDRAZA 1500
B23: Calidad Minima esperada
B25: Mantenimiento
C26: 30 DIAS
B27: Garantia
B31: Especificidades Item N° 2:
B33: Descripción técnica
C34: ALMOHADA CON FORRO DE VINIL COLOR BLANCO
B35: Plazos y lugares de entrega
C36: 10 DIAS DESDE LA FIRMA DEL INSTRUMENTO CONTRACTUAL
D37: SERVICIO DE ENFERMERIA HORARIO DE 08:00 A 12:00
C38: MATERNIDAD PROVINCIAL 25 DE MAYO, HERNANDO DE PEDRAZA 1500
B39: Calidad Minima esperada
B41: Mantenimiento
C42: 30 DIAS
B43: Garantia
B47: Especificidades Item N° 3:
B49: Descripción técnica
C50: FORRO PVC SANITARIO COLOR BLANCO
B51: Plazos y lugares de entrega
C52: 10 DIAS DESDE LA FIRMA DEL INSTRUMENTO CONTRACTUAL
D53: SERVICIO DE ENFERMERIA HORARIO DE 08:00 A 12:00
C54: MATERNIDAD PROVINCIAL 25 DE MAYO, HERNANDO DE PEDRAZA 1500
B55: Calidad Minima esperada
B57: Mantenimiento
...

Sheet  NotaPedido
A1: NOTA DE PEDIDO | J1: N° | K1: 92/2021
A3: JURISDICCIÓN: | D3: ='Necesidades Trimestrales'!C4 -> 40- Ministerio de Salud
A4: SAF: | D4: ='Necesidades Trimestrales'!C5 -> 28- Maternidad Provincial 25 de Mayo
A5: UNIDAD EJECUTORA: | D5: Direccion Asistencial
A6: DEPENDENCIA SOLICITANTE: | D6: División de Enfermería
A7: PERIODO UTILIZACIÓN: | D7: 3° trimestre 2021
A8: OBJETO:
A10: Ítem | B10: Codigo Item | C10: DESCRIPCIÓN | H10: Adjunta Detalle Técnico | I10: Unidad Medida | J10: Precio Unitario Estimado | K10: Cantidad Solicitada
A12: ='Necesidades Trimestrales'!A10 -> 1 | B12: ='Necesidades Trimestrales'!B10 -> 2.2.9-701.116 | C12: ='Necesidades Trimestrales'!E10 -> COLCHONES; CONSTRUCCION: ESPUMA, DIMENSION: 30 X 70 Cm, ESPESOR: 6 Cm, DENSIDAD: 200 Kg/m3, TERMINACION: FUNDA | H12: SI | I12: ='Necesidades Trimestrales'!F10 -> UNIDAD | J12: ='Necesidades Trimestrales'!H10 -> 2500 | K12: ='Necesidades Trimestrales'!G10 -> 30
A13: ='Necesidades Trimestrales'!A11 -> 2 | B13: ='Necesidades Trimestrales'!B11 -> 2.2.9-702.2 | C13: ='Necesidades Trimestrales'!E11 -> ALMOHADAS; DIMENSION: 70 X 35 Cm, CONSTRUCCION: ESPUMA | H13: NO | I13: ='Necesidades Trimestrales'!F11 -> UNIDAD | J13: ='Necesidades Trimestrales'!H11 -> 1200 | K13: ='Necesidades Trimestrales'!G11 -> 30
A14: ='Necesidades Trimestrales'!A12 -> 3 | B14: ='Necesidades Trimestrales'!B12 -> 2.2.9-701.177 | C14: ='Necesidades Trimestrales'!E12 -> COLCHONES; CONSTRUCCION: ARTICULADO ESPUMA ALTA DENS, DIMENSION: 1900 X 870 mm, ESPESOR: 18 Cm, DENSIDAD: 33 Kg/m3, TERMINACION: FORRO PVC SANITARIO | H14: NO | I14: ='Necesidades Trimestrales'!F12 -> UNIDAD | J14: ='Necesidades Trimestrales'!H12 -> 14600 | K14: ='Necesidades Trimestrales'!G12 -> 60
A15: Costo total estimado: NOVECIENTOS OCHENTA Y SIETE MIL CON 00/100 CENTAVOS. | J15: =SUMPRODUCT(J12:J14,K12:K14) -> 987000

Sheet Autor Gastar
A1: EJERCICIO: | D1: ='Necesidades Trimestrales'!C6 -> 2021 | P1: AUTORIZACION PARA GASTAR
A4: JURISDICCIÓN: | G4: =' NotaPedido'!D3 -> 40- Ministerio de Salud
A5: SAF: | G5: =' NotaPedido'!D4 -> 28- Maternidad Provincial 25 de Mayo
A6: UNIDAD EJECUTORA: | G6: =' NotaPedido'!D5 -> Direccion Asistencial
A7: DEPENDENCIA SOLICITANTE: | G7: =' NotaPedido'!D6 -> División de Enfermería
A8: AUTORIZACIÓN:
A9: Señor Jefe de Servicio Administrativo Financiero:
A10: ="Autorizo la realización de los trámites correspondientes, a fin de proveer a este Organismo los bienes y/o servicios que se detallan en Nota de Pedido N° " & ' NotaPedido'!K1&", afectando la erogación resultante a los créditos presupuestarios aprobados a favor de esta Unidad Ejecutora, conforme al siguiente detalle:" -> Autorizo la realización de los trámites correspondientes, a fin de proveer a este Organismo los bienes y/o servicios que se detallan en Nota de Pedido N° 92/2021, afectando la erogación resultante a los créditos presupuestarios aprobados a favor de esta Unidad Ejecutora, conforme al siguiente detalle:
A12: IMPUTACIÓN PRESUPUESTARIA
A13: CÓDIGO | O13: DENOMINACIÓN DE LA PARTIDA PRESUPUESTARIA | Q13: IMPORTE
A14: PR | B14: SB | C14: PY | D14: AC | E14: OB | F14: UG | G14: FIN | H14: FUN | I14: I | J14: P | K14: P | L14: SubP | M14: M | N14: FF
A15: 42 | D15: 2 | F15: 4901 | G15: 3 | H15: 1 | I15: 2 | J15: 2 | K15: 9 | N15: 1.1 | O15: Otros N.E.P. | Q15: 987000
A17: TOTAL DE PESOS: NOVECIENTOS OCHENTA Y SIETE MIL CON 00/100 CENTAVOS. | Q17: =SUM(Q15:Q16) -> 987000
A19: JUSTIFICACIÓN:
A20: Para la adquisición de Colchones, para ser destinados la internacion de pacientes embarazadas y/ o puerperas que ingresan a nuestra Institucion.
