Workbook

Sheet Nececidades Trimestrales
B2: Pedido de Necesidades Trimestrales
A4: JURISDICCION: | C4: 42-Ministerio de Salud
A5: SAF N°: | C5: 28- Maternidad Provincial 25 de Mayo
A6: EJERCICIO: | C6: 2021
A7: TRIMESTRE: | C7: 1
A9: ID | B9: CODIGO ITEM | C9: RUBRO | D9: I.P.P. | E9: DESCRIPCION | F9: UNIDAD DE MEDIDA | G9: CANTIDAD | H9: PRECIO UNITARIO ESTIMADO | I9: IMPORTE TOTAL ESTIMADO
A10: =' NotaPedido'!A12 -> 1 | B10: =' NotaPedido'!B12 -> 2.1.1-439.67 | C10: ALIMENTOS | D10: =LEFT(B10,5) -> 2.1.1 | E10: =' NotaPedido'!C12:G12 -> ACEITES COMESTIBLES; TIPO: GIRASOL, PRESENTACION: ENVASE X 900 CM3, MATERIAL ENVASE: PLASTICO 1 (PET), ELEM. TRANSPORTE: SIN, MATERIAL ELEM. TRANSPORTE : SIN, LIBRE DE GLUTEN: NO | F10: =' NotaPedido'!I12 -> ENVASE | G10: =' NotaPedido'!K12 -> 65 | H10: =' NotaPedido'!J12 -> 128 | I10: =H10*G10 -> 8320
A11: =' NotaPedido'!A13 -> 2 | B11: =' NotaPedido'!B13 -> 2.1.1-6546.34 | C11: ALIMENTOS | D11: =LEFT(B11,5) -> 2.1.1 | E11: =' NotaPedido'!C13:G13 -> VERDURAS Y HORTALIZAS; VARIEDAD: ACELGA, ESTADO: EN HOJA, PRESENTACION: ATADO, PESO: SIN VALOR | F11: =' NotaPedido'!I13 -> ATADO | G11: =' NotaPedido'!K13 -> 96 | H11: =' NotaPedido'!J13 -> 19 | I11: =H11*G11 -> 1824
A12: =' NotaPedido'!A14 -> 3 | B12: =' NotaPedido'!B14 -> 2.1.1-6546.154 | C12: ALIMENTOS | D12: =LEFT(B12,5) -> 2.1.1 | E12: =' NotaPedido'!C14:G14 -> VERDURAS Y HORTALIZAS; ESTADO: NATURAL, PESO: SIN VALOR, VARIEDAD: AJO, PRESENTACION: UNIDAD | F12: UNIDAD | G12: =' NotaPedido'!K14 -> 27 | H12: =' NotaPedido'!J14 -> 42 | I12: =H12*G12 -> 1134
A13: =' NotaPedido'!A15 -> 4 | B13: =' NotaPedido'!B15 -> 2.1.1-6539.38 | C13: ALIMENTOS | D13: =LEFT(B13,5) -> 2.1.1 | E13: =' NotaPedido'!C15:G15 -> FRUTAS; VARIEDAD: ANANA, PRESENTACION: ENVASE X 850 GR, PESO: 850 GR, ESTADO: CONSERVA | F13: =' NotaPedido'!I15 -> LATA | G13: =' NotaPedido'!K15 -> 27 | H13: =' NotaPedido'!J15 -> 295 | I13: =H13*G13 -> 7965
A14: =' NotaPedido'!A16 -> 5 | B14: =' NotaPedido'!B16 -> 2.1.1-6546.330 | C14: ALIMENTOS | D14: =LEFT(B14,5) -> 2.1.1 | E14: =' NotaPedido'!C16:G16 -> VERDURAS Y HORTALIZAS; VARIEDAD: ZAPALLO ANCO, ESTADO: NATURAL, PRESENTACION: UNIDAD, PESO: 1 Kg | F14: =' NotaPedido'!I16 -> KG | G14: =' NotaPedido'!K16 -> 400 | H14: =' NotaPedido'!J16 -> 35 | I14: =H14*G14 -> 14000
A15: =' NotaPedido'!A17 -> 6 | B15: =' NotaPedido'!B17 -> 2.1.1-6546.230 | C15: ALIMENTOS | D15: =LEFT(B15,5) -> 2.1.1 | E15: =' NotaPedido'!C17:G17 -> VERDURAS Y HORTALIZAS; VARIEDAD: APIO, ESTADO: NATURAL, PRESENTACION: ATADO, PESO: 800 GR | F15: =' NotaPedido'!I17 -> ATADO | G15: =' NotaPedido'!K17 -> 13 | H15: =' NotaPedido'!J17 -> 85 | I15: =H15*G15 -> 1105
A16: =' NotaPedido'!A18 -> 7 | B16: =' NotaPedido'!B18 -> 2.1.1-435.38 | C16: ALIMENTOS | D16: =LEFT(B16,5) -> 2.1.1 | E16: =' NotaPedido'!C18:G18 -> ARROZ; TIPO GRANO: DOBLE, TIPO: BLANCO, PROCESO: PARBOLIZADO, PRESENTACION: ENVASE X 1 Kg, MATERIAL ENVASE: CARTON, CERTIFICADO FORESTAL (GFS): SIN, ELEM. TRANSPORTE: SIN, MATERIAL ELEM. TRANSPORTE: SIN | F16: =' NotaPedido'!I18 -> ENVASE | G16: =' NotaPedido'!K18 -> 85 | H16: =' NotaPedido'!J18 -> 125 | I16: =H16*G16 -> 10625
A17: =' NotaPedido'!A19 -> 8 | B17: =' NotaPedido'!B19 -> 2.1.1-435.60 | C17: ALIMENTOS | D17: =LEFT(B17,5) -> 2.1.1 | E17: =' NotaPedido'!C19:G19 -> ARROZ; TIPO GRANO: LARGO-FINO, TIPO: BLANCO, PROCESO: SIN CASCARA, PRESENTACION: BOLSA X 1 Kg, MATERIAL ENVASE: PLASTICO, CERTIFICADO FORESTAL (GFS): SIN, ELEM. TRANSPORTE: SIN, MATERIAL ELEM. TRANSPORTE: SIN, LIBRE DE GLUTEN: SI | F17: =' NotaPedido'!I19 -> ENVASE | G17: =' NotaPedido'!K19 -> 34 | H17: =' NotaPedido'!J19 -> 73 | I17: =H17*G17 -> 2482
A18: =' NotaPedido'!A20 -> 9 | B18: =' NotaPedido'!B20 -> 2.1.1-708.43 | C18: ALIMENTOS | D18: =LEFT(B18,5) -> 2.1.1 | E18: =' NotaPedido'!C20:G20 -> CONSERVAS PESCADO Y FRUTOS MAR; TIPO: ATUN, ESTADO: AL NATURAL, PESO: 170 GR, ENVASE: LATA, ELEM. TRANSPORTE: SIN, MATERIAL ELEM. TRANSPORTE: SIN | F18: =' NotaPedido'!I20 -> LATA | G18: =' NotaPedido'!K20 -> 160 | H18: =' NotaPedido'!J20 -> 99.5 | I18: =H18*G18 -> 15920
A19: =' NotaPedido'!A21 -> 10 | B19: =' NotaPedido'!B21 -> 2.1.1-2124.6 | C19: ALIMENTOS | D19: =LEFT(B19,5) -> 2.1.1 | E19: =' NotaPedido'!C21:G21 -> AVENAS; TIPO: ARROLLADA, ESTADO: INSTANTANEA, PRESENTACION: ENVASE X 350 GR, PESO: SIN VALOR | F19: =' NotaPedido'!I21 -> ENVASE | G19: =' NotaPedido'!K21 -> 20 | H19: =' NotaPedido'!J21 -> 123.1 | I19: =H19*G19 -> 2462
A20: =' NotaPedido'!A22 -> 11 | B20: =' NotaPedido'!B22 -> 2.1.1-6547.84 | C20: ALIMENTOS | D20: =LEFT(B20,5) -> 2.1.1 | E20: =' NotaPedido'!C22:G22 -> LEGUMBRES; VARIEDAD: ARVEJAS, ESTADO: CONSERVA, PRESENTACION: LATA, PESO: 350 GR, MATERIAL ENVASE: METAL, ELEM. TRANSPORTE: SIN, MATERIAL ELEM. TRANSPORTE: SIN, LIBRE DE GLUTEN: NO | F20: =' NotaPedido'!I22 -> LATA | G20: =' NotaPedido'!K22 -> 32 | H20: =' NotaPedido'!J22 -> 85 | I20: =H20*G20 -> 2720
A21: =' NotaPedido'!A23 -> 12 | B21: =' NotaPedido'!B23 -> 2.1.1-481.38 | C21: ALIMENTOS | D21: =LEFT(B21,5) -> 2.1.1 | E21: =' NotaPedido'!C23:G23 -> AZUCARES; TIPO: "A" COMUN, ESTADO: MOLIDA, PESO: 1 Kg, MATERIAL ENVASE: PLASTICO, CERTIFICADO FORESTAL (GFS): SIN, ELEM. TRANSPORTE: SIN, MATERIAL ELEM. TRANSPORTE: SIN | F21: =' NotaPedido'!I23 -> ENVASE | G21: =' NotaPedido'!K23 -> 133 | H21: =' NotaPedido'!J23 -> 55 | I21: =H21*G21 -> 7315
A22: =' NotaPedido'!A24 -> 13 | B22: =' NotaPedido'!B24 -> 2.1.1-6539.30 | C22: ALIMENTOS | D22: =LEFT(B22,5) -> 2.1.1 | E22: =' NotaPedido'!C24:G24 -> FRUTAS; VARIEDAD: BANANA, PRESENTACION: CAJON, ESTADO: NATURAL, PESO: SIN VALOR | F22: =' NotaPedido'!I24 -> CAJON | G22: =' NotaPedido'!K24 -> 4 | H22: =' NotaPedido'!J24 -> 1350 | I22: =H22*G22 -> 5400
A23: =' NotaPedido'!A25 -> 14 | B23: =' NotaPedido'!B25 -> 2.1.1-6546.207 | C23: ALIMENTOS | D23: =LEFT(B23,5) -> 2.1.1 | E23: =' NotaPedido'!C25:G25 -> VERDURAS Y HORTALIZAS; VARIEDAD: BATATA, ESTADO: NATURAL, PRESENTACION: BOLSA, PESO: 10 Kg | F23: =' NotaPedido'!I25 -> BOLSA | G23: =' NotaPedido'!K25 -> 5 | H23: =' NotaPedido'!J25 -> 330 | I23: =H23*G23 -> 1650
A24: =' NotaPedido'!A26 -> 15 | B24: =' NotaPedido'!B26 -> 2.1.1-6546.177 | C24: ALIMENTOS | D24: =LEFT(B24,5) -> 2.1.1 | E24: =' NotaPedido'!C26:G26 -> VERDURAS Y HORTALIZAS; VARIEDAD: BERENJENA, ESTADO: NATURAL, PRESENTACION: GRANEL, PESO: SIN VALOR | F24: KG | G24: 72 | H24: 118.75 | I24: =H24*G24 -> 8550
A25: =' NotaPedido'!A27 -> 16 | B25: =' NotaPedido'!B27 -> 2.1.1-541.33 | C25: ALIMENTOS | D25: =LEFT(B25,5) -> 2.1.1 | E25: =' NotaPedido'!C27:G27 -> CARNES; ESPECIE: VACUNA, CORTE: BOLA DE LOMO, TIPO: VACUNA | F25: =' NotaPedido'!I27 -> KG | G25: =' NotaPedido'!K27 -> 100 | H25: =' NotaPedido'!J27 -> 643 | I25: =H25*G25 -> 64300
A26: =' NotaPedido'!A28 -> 17 | B26: =' NotaPedido'!B28 -> 2.1.1-2615.15 | C26: ALIMENTOS | D26: =LEFT(B26,5) -> 2.1.1 | E26: =' NotaPedido'!C28:G28 -> CACAO; TIPO: INSTANTANEO, PRESENTACION: ENVASE X 800 GR, FORMA DE PRESENTACION: POLVO, MATERIAL ENVASE: CARTON, CERTICADO FORESTAL (GFS): CON, LIBRE DE GLUTEN: SI | F26: =' NotaPedido'!I28 -> ENVASE | G26: =' NotaPedido'!K28 -> 14 | H26: =' NotaPedido'!J28 -> 115 | I26: =H26*G26 -> 1610
A27: =' NotaPedido'!A29 -> 18 | B27: =' NotaPedido'!B29 -> 2.1.1-541.137 | C27: ALIMENTOS | D27: =LEFT(B27,5) -> 2.1.1 | E27: =' NotaPedido'!C29:G29 -> CARNES; ESPECIE: PORCINA, CORTE: CARRE CONGELADO, TIPO: PORCINA | F27: =' NotaPedido'!I29 -> KG | G27: =' NotaPedido'!K29 -> 50 | H27: =' NotaPedido'!J29 -> 383.5 | I27: =H27*G27 -> 19175
A28: =' NotaPedido'!A30 -> 19 | B28: =' NotaPedido'!B30 -> 2.1.1-6546.236 | C28: ALIMENTOS | D28: =LEFT(B28,5) -> 2.1.1 | E28: =' NotaPedido'!C30:G30 -> VERDURAS Y HORTALIZAS; VARIEDAD: CEBOLLA, ESTADO: NATURAL, PRESENTACION: BOLSA, PESO: 20 Kg | F28: =' NotaPedido'!I30 -> BOLSA | G28: =' NotaPedido'!K30 -> 12 | H28: =' NotaPedido'!J30 -> 1240 | I28: =H28*G28 -> 14880
A29: =' NotaPedido'!A31 -> 20 | B29: =' NotaPedido'!B31 -> 2.1.1-6546.377 | C29: ALIMENTOS | D29: =LEFT(B29,5) -> 2.1.1 | E29: =' NotaPedido'!C31:G31 -> VERDURAS Y HORTALIZAS; VARIEDAD: CEBOLLA DE VERDEO, ESTADO: NATURAL, PRESENTACION: CAJON, PESO: 10 Kg, ELEM. TRANSPORTE: CAJON, MATERIAL ELEM. TRANSPORTE: CARTON, LIBRE DE GLUTEN: NO | F29: =' NotaPedido'!I31 -> CAJON | G29: =' NotaPedido'!K31 -> 1 | H29: =' NotaPedido'!J31 -> 450 | I29: =H29*G29 -> 450
A30: =' NotaPedido'!A32 -> 21 | B30: =' NotaPedido'!B32 -> 2.1.1-6546.269 | C30: ALIMENTOS | D30: =LEFT(B30,5) -> 2.1.1 | E30: =' NotaPedido'!C32:G32 -> VERDURAS Y HORTALIZAS; VARIEDAD: CHOCLO, ESTADO: GRANO, PRESENTACION: LATA, PESO: 350 GR | F30: =' NotaPedido'!I32 -> LATA | G30: =' NotaPedido'!K32 -> 60 | H30: =' NotaPedido'!J32 -> 80 | I30: =H30*G30 -> 4800
A31: =' NotaPedido'!A33 -> 22 | B31: =' NotaPedido'!B33 -> 2.1.1-6539.123 | C31: ALIMENTOS | D31: =LEFT(B31,5) -> 2.1.1 | E31: =' NotaPedido'!C33:G33 -> FRUTAS; VARIEDAD: CIRUELA, ESTADO: DESECADA, PRESENTACION: ENVASE X 5 Kg, PESO: 5 Kg | F31: =' NotaPedido'!I33 -> ENVASE | G31: =' NotaPedido'!K33 -> 1 | H31: =' NotaPedido'!J33 -> 2470 | I31: =H31*G31 -> 2470
A32: =' NotaPedido'!A34 -> 23 | B32: =' NotaPedido'!B34 -> 2.1.1-597.41 | C32: ALIMENTOS | D32: =LEFT(B32,5) -> 2.1.1 | E32: =' NotaPedido'!C34:G34 -> CONSERVAS DE FRUTAS; VARIEDAD: COCTEL, ENVASE: LATA, PESO: 800 GR, ELEM. TRANSPORTE: SIN, MATERIAL ELEM. TRANSPORTE: SIN, LIBRE DE GLUTEN: NO | F32: =' NotaPedido'!I34 -> LATA | G32: =' NotaPedido'!K34 -> 13 | H32: =' NotaPedido'!J34 -> 210 | I32: =H32*G32 -> 2730
A33: =' NotaPedido'!A35 -> 24 | B33: =' NotaPedido'!B35 -> 2.1.1-597.43 | C33: ALIMENTOS | D33: =LEFT(B33,5) -> 2.1.1 | E33: =' NotaPedido'!C35:G35 -> CONSERVAS DE FRUTAS; VARIEDAD: COCTEL, ENVASE: LATA, PESO: 820 GR, ELEM. TRANSPORTE: SIN, MATERIAL ELEM. TRANSPORTE: SIN, LIBRE DE GLUTEN: SI | F33: =' NotaPedido'!I35 -> LATA | G33: =' NotaPedido'!K35 -> 13 | H33: =' NotaPedido'!J35 -> 210 | I33: =H33*G33 -> 2730
A34: =' NotaPedido'!A36 -> 25 | B34: =' NotaPedido'!B36 -> 2.1.1-541.164 | C34: ALIMENTOS | D34: =LEFT(B34,5) -> 2.1.1 | E34: =' NotaPedido'!C36:G36 -> CARNES; TIPO: PORCINA, CORTE: COSTELETA | F34: =' NotaPedido'!I36 -> KG | G34: =' NotaPedido'!K36 -> 67 | H34: =' NotaPedido'!J36 -> 442 | I34: =H34*G34 -> 29614
A35: =' NotaPedido'!A37 -> 26 | B35: =' NotaPedido'!B37 -> 2.1.1-489.91 | C35: ALIMENTOS | D35: =LEFT(B35,5) -> 2.1.1 | E35: =' NotaPedido'!C37:G37 -> ESPECIAS; TIPO: COMINO, PRESENTACION: SOBRE X 25 GR | F35: =' NotaPedido'!I37 -> SOBRE | G35: =' NotaPedido'!K37 -> 8 | H35: =' NotaPedido'!J37 -> 36 | I35: =H35*G35 -> 288
A36: =' NotaPedido'!A38 -> 27 | B36: =' NotaPedido'!B38 -> 2.1.1-489.82 | C36: ALIMENTOS | D36: =LEFT(B36,5) -> 2.1.1 | E36: =' NotaPedido'!C38:G38 -> ESPECIAS; TIPO: ADOBO PARA PIZZA, PRESENTACION: SOBRE X 25 GR | F36: =' NotaPedido'!I38 -> SOBRE | G36: =' NotaPedido'!K38 -> 20 | H36: =' NotaPedido'!J38 -> 35 | I36: =H36*G36 -> 700
... A62: =' NotaPedido'!A64 -> 53 | B62: =' NotaPedido'!B64 -> 2.1.1-6547.88 | C62: ALIMENTOS | D62: =LEFT(B62,5) -> 2.1.1 | E62: =' NotaPedido'!C64:G64 -> LEGUMBRES; VARIEDAD: LENTEJA, ESTADO: SECO, PRESENTACION: BOLSA, PESO: 450 GR, MATERIAL ENVASE: PLASTICO, ELEM. TRANSPORTE: SIN, MATERIAL ELEM. TRANSPORTE: SIN, LIBRE DE GLUTEN: SI | F62: =' NotaPedido'!I64 -> ENVASE | G62: =' NotaPedido'!K64 -> 8 | H62: =' NotaPedido'!J64 -> 115 | I62: =H62*G62 -> 920
A63: =' NotaPedido'!A65 -> 54 | B63: =' NotaPedido'!B65 -> 2.1.1-6546.374 | C63: ALIMENTOS | D63: =LEFT(B63,5) -> 2.1.1 | E63: =' NotaPedido'!C65:G65 -> VERDURAS Y HORTALIZAS; VARIEDAD: LECHUGA ARREPOLLADA, ESTADO: NATURAL, PRESENTACION: A GRANEL, PESO: 300 GR CADA PLANTA, ELEM. TRANSPORTE: SIN, MATERIAL ELEM. TRANSPORTE: SIN, LIBRE DE GLUTEN: SI | F63: KG | G63: 40 | H63: 42 | I63: =H63*G63 -> 1680
A64: =' NotaPedido'!A66 -> 55 | B64: =' NotaPedido'!B66 -> 2.1.1-2116.10 | C64: ALIMENTOS | D64: =LEFT(B64,5) -> 2.1.1 | E64: =' NotaPedido'!C66:G66 -> LEVADURAS; TIPO: SECA INSTANTANEA, PRESENTACION: SOBRE, PESO: 20 GR | F64: =' NotaPedido'!I66 -> SOBRE | G64: =' NotaPedido'!K66 -> 15 | H64: =' NotaPedido'!J66 -> 35 | I64: =H64*G64 -> 525
A65: =' NotaPedido'!A67 -> 56 | B65: =' NotaPedido'!B67 -> 2.1.1-6539.84 | C65: ALIMENTOS | D65: =LEFT(B65,5) -> 2.1.1 | E65: =' NotaPedido'!C67:G67 -> FRUTAS; VARIEDAD: LIMON, ESTADO: NATURAL, PRESENTACION: CAJON X 1 Kg, PESO: 1 Kg | F65: =' NotaPedido'!I67 -> CAJON | G65: =' NotaPedido'!K67 -> 15 | H65: =' NotaPedido'!J67 -> 45 | I65: =H65*G65 -> 675
A66: =' NotaPedido'!A68 -> 57 | B66: =' NotaPedido'!B68 -> 2.1.1-6539.20 | C66: ALIMENTOS | D66: =LEFT(B66,5) -> 2.1.1 | E66: =' NotaPedido'!C68:G68 -> FRUTAS; ESTADO: NATURAL, VARIEDAD: MANZANA RED DELICIOSA, PRESENTACION: CAJON, PESO: SIN VALOR | F66: =' NotaPedido'!I68 -> CAJON | G66: =' NotaPedido'!K68 -> 8 | H66: =' NotaPedido'!J68 -> 1920 | I66: =H66*G66 -> 15360
A67: =' NotaPedido'!A69 -> 58 | B67: =' NotaPedido'!B69 -> 2.1.1-706.6 | C67: ALIMENTOS | D67: =LEFT(B67,5) -> 2.1.1 | E67: =' NotaPedido'!C69:G69 -> MATE COCIDO; ENVASE: CAJA CARTON, PRESENTACION: ENSOBRADO, SAQUITOS P/CAJA: 100 UN, PESO X SAQ.: 3 GR | F67: =' NotaPedido'!I69 -> CAJA | G67: =' NotaPedido'!K69 -> 35 | H67: =' NotaPedido'!J69 -> 108.5 | I67: =H67*G67 -> 3797.5
A68: =' NotaPedido'!A70 -> 59 | B68: =' NotaPedido'!B70 -> 2.1.1-438.83 | C68: ALIMENTOS | D68: =LEFT(B68,5) -> 2.1.1 | E68: =' NotaPedido'!C70:G70 -> ADEREZOS; TIPO: MAYONESA LIGHT, PRESENTACION: ENVASE X 475 GR, LIBRE DE GLUTEN: SIN VALOR | F68: =' NotaPedido'!I70 -> ENVASE | G68: =' NotaPedido'!K70 -> 15 | H68: =' NotaPedido'!J70 -> 60 | I68: =H68*G68 -> 900
...

Sheet  NotaPedido
A1: NOTA DE PEDIDO | J1: N° | K1: 304/2020
A3: JURISDICCIÓN: | D3: 42-Miniterio de salud
A4: SAF: | D4: 28-Maternidad Provincial 25 de Mayo
A5: UNIDAD EJECUTORA: | D5: 169-Dirección Asistencial
A6: DEPENDENCIA SOLICITANTE: | D6: Servicio de Nutrición y Dietoterapia
A7: PERIODO UTILIZACIÓN: | D7: 2 Meses
A8: OBJETO: | D8: ALIMENTOS PARA PERSONAS
A10: Ítem | B10: Codigo Item | C10: DESCRIPCIÓN | H10: Adjunta Detalle Técnico | I10: Unidad Medida | J10: Precio Unitario Estimado | K10: Cantidad Solicitada
A12: 1 | B12: ='[1]Necesidades Trimestrales'!B10 -> 2.1.1-439.67 | C12: ACEITES COMESTIBLES; TIPO: GIRASOL, PRESENTACION: ENVASE X 900 CM3, MATERIAL ENVASE: PLASTICO 1 (PET), ELEM. TRANSPORTE: SIN, MATERIAL ELEM. TRANSPORTE : SIN, LIBRE DE GLUTEN: NO | D12: ACEITES COMESTIBLES; TIPO: GIRASOL, PRESENTACION: ENVASE X 900 CM3, MATERIAL ENVASE: PLASTICO 1 (PET), ELEM. TRANSPORTE: SIN, MATERIAL ELEM. TRANSPORTE : SIN, LIBRE DE GLUTEN: NO | E12: ACEITES COMESTIBLES; TIPO: GIRASOL, PRESENTACION: ENVASE X 900 CM3, MATERIAL ENVASE: PLASTICO 1 (PET), ELEM. TRANSPORTE: SIN, MATERIAL ELEM. TRANSPORTE : SIN, LIBRE DE GLUTEN: NO | F12: ACEITES COMESTIBLES; TIPO: GIRASOL, PRESENTACION: ENVASE X 900 CM3, MATERIAL ENVASE: PLASTICO 1 (PET), ELEM. TRANSPORTE: SIN, MATERIAL ELEM. TRANSPORTE : SIN, LIBRE DE GLUTEN: NO | G12: ACEITES COMESTIBLES; TIPO: GIRASOL, PRESENTACION: ENVASE X 900 CM3, MATERIAL ENVASE: PLASTICO 1 (PET), ELEM. TRANSPORTE: SIN, MATERIAL ELEM. TRANSPORTE : SIN, LIBRE DE GLUTEN: NO | H12: NO | I12: ENVASE | J12: 128 | K12: 65
A13: 2 | B13: ='[1]Necesidades Trimestrales'!B11 -> 2.1.1-6546.34 | C13: VERDURAS Y HORTALIZAS; VARIEDAD: ACELGA, ESTADO: EN HOJA, PRESENTACION: ATADO, PESO: SIN VALOR | D13: VERDURAS Y HORTALIZAS; VARIEDAD: ACELGA, ESTADO: EN HOJA, PRESENTACION: ATADO, PESO: SIN VALOR | E13: VERDURAS Y HORTALIZAS; VARIEDAD: ACELGA, ESTADO: EN HOJA, PRESENTACION: ATADO, PESO: SIN VALOR | F13: VERDURAS Y HORTALIZAS; VARIEDAD: ACELGA, ESTADO: EN HOJA, PRESENTACION: ATADO, PESO: SIN VALOR | G13: VERDURAS Y HORTALIZAS; VARIEDAD: ACELGA, ESTADO: EN HOJA, PRESENTACION: ATADO, PESO: SIN VALOR | H13: NO | I13: ATADO | J13: 19 | K13: 96
A14: 3 | B14: ='[1]Necesidades Trimestrales'!B12 -> 2.1.1-6546.154 | C14: VERDURAS Y HORTALIZAS; ESTADO: NATURAL, PESO: SIN VALOR, VARIEDAD: AJO, PRESENTACION: UNIDAD | D14: VERDURAS Y HORTALIZAS; ESTADO: NATURAL, PESO: SIN VALOR, VARIEDAD: AJO, PRESENTACION: UNIDAD | E14: VERDURAS Y HORTALIZAS; ESTADO: NATURAL, PESO: SIN VALOR, VARIEDAD: AJO, PRESENTACION: UNIDAD | F14: VERDURAS Y HORTALIZAS; ESTADO: NATURAL, PESO: SIN VALOR, VARIEDAD: AJO, PRESENTACION: UNIDAD | G14: VERDURAS Y HORTALIZAS; ESTADO: NATURAL, PESO: SIN VALOR, VARIEDAD: AJO, PRESENTACION: UNIDAD | H14: NO | I14: UNIDAD | J14: 42 | K14: 27
A15: 4 | B15: ='[1]Necesidades Trimestrales'!B13 -> 2.1.1-6539.38 | C15: FRUTAS; VARIEDAD: ANANA, PRESENTACION: ENVASE X 850 GR, PESO: 850 GR, ESTADO: CONSERVA | D15: FRUTAS; VARIEDAD: ANANA, PRESENTACION: ENVASE X 850 GR, PESO: 850 GR, ESTADO: CONSERVA | E15: FRUTAS; VARIEDAD: ANANA, PRESENTACION: ENVASE X 850 GR, PESO: 850 GR, ESTADO: CONSERVA | F15: FRUTAS; VARIEDAD: ANANA, PRESENTACION: ENVASE X 850 GR, PESO: 850 GR, ESTADO: CONSERVA | G15: FRUTAS; VARIEDAD: ANANA, PRESENTACION: ENVASE X 850 GR, PESO: 850 GR, ESTADO: CONSERVA | H15: NO | I15: LATA | J15: 295 | K15: 27
A16: 5 | B16: ='[1]Necesidades Trimestrales'!B14 -> 2.1.1-6546.330 | C16: VERDURAS Y HORTALIZAS; VARIEDAD: ZAPALLO ANCO, ESTADO: NATURAL, PRESENTACION: UNIDAD, PESO: 1 Kg | D16: VERDURAS Y HORTALIZAS; VARIEDAD: ZAPALLO ANCO, ESTADO: NATURAL, PRESENTACION: UNIDAD, PESO: 1 Kg | E16: VERDURAS Y HORTALIZAS; VARIEDAD: ZAPALLO ANCO, ESTADO: NATURAL, PRESENTACION: UNIDAD, PESO: 1 Kg | F16: VERDURAS Y HORTALIZAS; VARIEDAD: ZAPALLO ANCO, ESTADO: NATURAL, PRESENTACION: UNIDAD, PESO: 1 Kg | G16: VERDURAS Y HORTALIZAS; VARIEDAD: ZAPALLO ANCO, ESTADO: NATURAL, PRESENTACION: UNIDAD, PESO: 1 Kg | H16: NO | I16: KG | J16: 35 | K16: 400
A17: 6 | B17: ='[1]Necesidades Trimestrales'!B15 -> 2.1.1-6546.230 | C17: VERDURAS Y HORTALIZAS; VARIEDAD: APIO, ESTADO: NATURAL, PRESENTACION: ATADO, PESO: 800 GR | D17: VERDURAS Y HORTALIZAS; VARIEDAD: APIO, ESTADO: NATURAL, PRESENTACION: ATADO, PESO: 800 GR | E17: VERDURAS Y HORTALIZAS; VARIEDAD: APIO, ESTADO: NATURAL, PRESENTACION: ATADO, PESO: 800 GR | F17: VERDURAS Y HORTALIZAS; VARIEDAD: APIO, ESTADO: NATURAL, PRESENTACION: ATADO, PESO: 800 GR | G17: VERDURAS Y HORTALIZAS; VARIEDAD: APIO, ESTADO: NATURAL, PRESENTACION: ATADO, PESO: 800 GR | H17: NO | I17: ATADO | J17: 85 | K17: 13
A18: 7 | B18: ='[1]Necesidades Trimestrales'!B16 -> 2.1.1-435.38 | C18: ARROZ; TIPO GRANO: DOBLE, TIPO: BLANCO, PROCESO: PARBOLIZADO, PRESENTACION: ENVASE X 1 Kg, MATERIAL ENVASE: CARTON, CERTIFICADO FORESTAL (GFS): SIN, ELEM. TRANSPORTE: SIN, MATERIAL ELEM. TRANSPORTE: SIN | D18: ARROZ; TIPO GRANO: DOBLE, TIPO: BLANCO, PROCESO: PARBOLIZADO, PRESENTACION: ENVASE X 1 Kg, MATERIAL ENVASE: CARTON, CERTIFICADO FORESTAL (GFS): SIN, ELEM. TRANSPORTE: SIN, MATERIAL ELEM. TRANSPORTE: SIN | E18: ARROZ; TIPO GRANO: DOBLE, TIPO: BLANCO, PROCESO: PARBOLIZADO, PRESENTACION: ENVASE X 1 Kg, MATERIAL ENVASE: CARTON, CERTIFICADO FORESTAL (GFS): SIN, ELEM. TRANSPORTE: SIN, MATERIAL ELEM. TRANSPORTE: SIN | F18: ARROZ; TIPO GRANO: DOBLE, TIPO: BLANCO, PROCESO: PARBOLIZADO, PRESENTACION: ENVASE X 1 Kg, MATERIAL ENVASE: CARTON, CERTIFICADO FORESTAL (GFS): SIN, ELEM. TRANSPORTE: SIN, MATERIAL ELEM. TRANSPORTE: SIN | G18: ARROZ; TIPO GRANO: DOBLE, TIPO: BLANCO, PROCESO: PARBOLIZADO, PRESENTACION: ENVASE X 1 Kg, MATERIAL ENVASE: CARTON, CERTIFICADO FORESTAL (GFS): SIN, ELEM. TRANSPORTE: SIN, MATERIAL ELEM. TRANSPORTE: SIN | H18: NO | I18: ENVASE | J18: 125 | K18: 85
A19: 8 | B19: ='[1]Necesidades Trimestrales'!B17 -> 2.1.1-435.60 | C19: ARROZ; TIPO GRANO: LARGO-FINO, TIPO: BLANCO, PROCESO: SIN CASCARA, PRESENTACION: BOLSA X 1 Kg, MATERIAL ENVASE: PLASTICO, CERTIFICADO FORESTAL (GFS): SIN, ELEM. TRANSPORTE: SIN, MATERIAL ELEM. TRANSPORTE: SIN, LIBRE DE GLUTEN: SI | D19: ARROZ; TIPO GRANO: LARGO-FINO, TIPO: BLANCO, PROCESO: SIN CASCARA, PRESENTACION: BOLSA X 1 Kg, MATERIAL ENVASE: PLASTICO, CERTIFICADO FORESTAL (GFS): SIN, ELEM. TRANSPORTE: SIN, MATERIAL ELEM. TRANSPORTE: SIN, LIBRE DE GLUTEN: SI | E19: ARROZ; TIPO GRANO: LARGO-FINO, TIPO: BLANCO, PROCESO: SIN CASCARA, PRESENTACION: BOLSA X 1 Kg, MATERIAL ENVASE: PLASTICO, CERTIFICADO FORESTAL (GFS): SIN, ELEM. TRANSPORTE: SIN, MATERIAL ELEM. TRANSPORTE: SIN, LIBRE DE GLUTEN: SI | F19: ARROZ; TIPO GRANO: LARGO-FINO, TIPO: BLANCO, PROCESO: SIN CASCARA, PRESENTACION: BOLSA X 1 Kg, MATERIAL ENVASE: PLASTICO, CERTIFICADO FORESTAL (GFS): SIN, ELEM. TRANSPORTE: SIN, MATERIAL ELEM. TRANSPORTE: SIN, LIBRE DE GLUTEN: SI | G19: ARROZ; TIPO GRANO: LARGO-FINO, TIPO: BLANCO, PROCESO: SIN CASCARA, PRESENTACION: BOLSA X 1 Kg, MATERIAL ENVASE: PLASTICO, CERTIFICADO FORESTAL (GFS): SIN, ELEM. TRANSPORTE: SIN, MATERIAL ELEM. TRANSPORTE: SIN, LIBRE DE GLUTEN: SI | H19: NO | I19: ENVASE | J19: 73 | K19: 34
A20: 9 | B20: ='[1]Necesidades Trimestrales'!B18 -> 2.1.1-708.43 | C20: CONSERVAS PESCADO Y FRUTOS MAR; TIPO: ATUN, ESTADO: AL NATURAL, PESO: 170 GR, ENVASE: LATA, ELEM. TRANSPORTE: SIN, MATERIAL ELEM. TRANSPORTE: SIN | D20: CONSERVAS PESCADO Y FRUTOS MAR; TIPO: ATUN, ESTADO: AL NATURAL, PESO: 170 GR, ENVASE: LATA, ELEM. TRANSPORTE: SIN, MATERIAL ELEM. TRANSPORTE: SIN | E20: CONSERVAS PESCADO Y FRUTOS MAR; TIPO: ATUN, ESTADO: AL NATURAL, PESO: 170 GR, ENVASE: LATA, ELEM. TRANSPORTE: SIN, MATERIAL ELEM. TRANSPORTE: SIN | F20: CONSERVAS PESCADO Y FRUTOS MAR; TIPO: ATUN, ESTADO: AL NATURAL, PESO: 170 GR, ENVASE: LATA, ELEM. TRANSPORTE: SIN, MATERIAL ELEM. TRANSPORTE: SIN | G20: CONSERVAS PESCADO Y FRUTOS MAR; TIPO: ATUN, ESTADO: AL NATURAL, PESO: 170 GR, ENVASE: LATA, ELEM. TRANSPORTE: SIN, MATERIAL ELEM. TRANSPORTE: SIN | H20: NO | I20: LATA | J20: 99.5 | K20: 160
A21: 10 | B21: ='[1]Necesidades Trimestrales'!B19 -> 2.1.1-2124.6 | C21: AVENAS; TIPO: ARROLLADA, ESTADO: INSTANTANEA, PRESENTACION: ENVASE X 350 GR, PESO: SIN VALOR | D21: AVENAS; TIPO: ARROLLADA, ESTADO: INSTANTANEA, PRESENTACION: ENVASE X 350 GR, PESO: SIN VALOR | E21: AVENAS; TIPO: ARROLLADA, ESTADO: INSTANTANEA, PRESENTACION: ENVASE X 350 GR, PESO: SIN VALOR | F21: AVENAS; TIPO: ARROLLADA, ESTADO: INSTANTANEA, PRESENTACION: ENVASE X 350 GR, PESO: SIN VALOR | G21: AVENAS; TIPO: ARROLLADA, ESTADO: INSTANTANEA, PRESENTACION: ENVASE X 350 GR, PESO: SIN VALOR | H21: NO | I21: ENVASE | J21: 123.1 | K21: 20
A22: 11 | B22: ='[1]Necesidades Trimestrales'!B20 -> 2.1.1-6547.84 | C22: LEGUMBRES; VARIEDAD: ARVEJAS, ESTADO: CONSERVA, PRESENTACION: LATA, PESO: 350 GR, MATERIAL ENVASE: METAL, ELEM. TRANSPORTE: SIN, MATERIAL ELEM. TRANSPORTE: SIN, LIBRE DE GLUTEN: NO | D22: LEGUMBRES; VARIEDAD: ARVEJAS, ESTADO: CONSERVA, PRESENTACION: LATA, PESO: 350 GR, MATERIAL ENVASE: METAL, ELEM. TRANSPORTE: SIN, MATERIAL ELEM. TRANSPORTE: SIN, LIBRE DE GLUTEN: NO | E22: LEGUMBRES; VARIEDAD: ARVEJAS, ESTADO: CONSERVA, PRESENTACION: LATA, PESO: 350 GR, MATERIAL ENVASE: METAL, ELEM. TRANSPORTE: SIN, MATERIAL ELEM. TRANSPORTE: SIN, LIBRE DE GLUTEN: NO | F22: LEGUMBRES; VARIEDAD: ARVEJAS, ESTADO: CONSERVA, PRESENTACION: LATA, PESO: 350 GR, MATERIAL ENVASE: METAL, ELEM. TRANSPORTE: SIN, MATERIAL ELEM. TRANSPORTE: SIN, LIBRE DE GLUTEN: NO | G22: LEGUMBRES; VARIEDAD: ARVEJAS, ESTADO: CONSERVA, PRESENTACION: LATA, PESO: 350 GR, MATERIAL ENVASE: METAL, ELEM. TRANSPORTE: SIN, MATERIAL ELEM. TRANSPORTE: SIN, LIBRE DE GLUTEN: NO | H22: NO | I22: LATA | J22: 85 | K22: 32
A23: 12 | B23: ='[1]Necesidades Trimestrales'!B21 -> 2.1.1-481.38 | C23: AZUCARES; TIPO: "A" COMUN, ESTADO: MOLIDA, PESO: 1 Kg, MATERIAL ENVASE: PLASTICO, CERTIFICADO FORESTAL (GFS): SIN, ELEM. TRANSPORTE: SIN, MATERIAL ELEM. TRANSPORTE: SIN | D23: AZUCARES; TIPO: "A" COMUN, ESTADO: MOLIDA, PESO: 1 Kg, MATERIAL ENVASE: PLASTICO, CERTIFICADO FORESTAL (GFS): SIN, ELEM. TRANSPORTE: SIN, MATERIAL ELEM. TRANSPORTE: SIN | E23: AZUCARES; TIPO: "A" COMUN, ESTADO: MOLIDA, PESO: 1 Kg, MATERIAL ENVASE: PLASTICO, CERTIFICADO FORESTAL (GFS): SIN, ELEM. TRANSPORTE: SIN, MATERIAL ELEM. TRANSPORTE: SIN | F23: AZUCARES; TIPO: "A" COMUN, ESTADO: MOLIDA, PESO: 1 Kg, MATERIAL ENVASE: PLASTICO, CERTIFICADO FORESTAL (GFS): SIN, ELEM. TRANSPORTE: SIN, MATERIAL ELEM. TRANSPORTE: SIN | G23: AZUCARES; TIPO: "A" COMUN, ESTADO: MOLIDA, PESO: 1 Kg, MATERIAL ENVASE: PLASTICO, CERTIFICADO FORESTAL (GFS): SIN, ELEM. TRANSPORTE: SIN, MATERIAL ELEM. TRANSPORTE: SIN | H23: NO | I23: ENVASE | J23: 55 | K23: 133
... A54: 43 | B54: ='[1]Necesidades Trimestrales'!B52 -> 2.1.1-705.91 | C54: LECHE; ESTADO: POLVO, TIPO: LACTANTE, PROCESO: PASTEURIZADA, AGREGADO: HIDROL. EXT. PROTEINA DE SUERO, PRESENTACION: ENVASE X 400 GR, MATERIAL ENVASE: METAL, ELEM. TRANSPORTE: SIN, MATERIAL ELEM. TRANSPORTE: SIN, CERTIFICADO FORESTAL (GFS): SIN, LIBRE DE GLUTEN: NO | D54: LECHE; ESTADO: POLVO, TIPO: LACTANTE, PROCESO: PASTEURIZADA, AGREGADO: HIDROL. EXT. PROTEINA DE SUERO, PRESENTACION: ENVASE X 400 GR, MATERIAL ENVASE: METAL, ELEM. TRANSPORTE: SIN, MATERIAL ELEM. TRANSPORTE: SIN, CERTIFICADO FORESTAL (GFS): SIN, LIBRE DE GLUTEN: NO | E54: LECHE; ESTADO: POLVO, TIPO: LACTANTE, PROCESO: PASTEURIZADA, AGREGADO: HIDROL. EXT. PROTEINA DE SUERO, PRESENTACION: ENVASE X 400 GR, MATERIAL ENVASE: METAL, ELEM. TRANSPORTE: SIN, MATERIAL ELEM. TRANSPORTE: SIN, CERTIFICADO FORESTAL (GFS): SIN, LIBRE DE GLUTEN: NO | F54: LECHE; ESTADO: POLVO, TIPO: LACTANTE, PROCESO: PASTEURIZADA, AGREGADO: HIDROL. EXT. PROTEINA DE SUERO, PRESENTACION: ENVASE X 400 GR, MATERIAL ENVASE: METAL, ELEM. TRANSPORTE: SIN, MATERIAL ELEM. TRANSPORTE: SIN, CERTIFICADO FORESTAL (GFS): SIN, LIBRE DE GLUTEN: NO | G54: LECHE; ESTADO: POLVO, TIPO: LACTANTE, PROCESO: PASTEURIZADA, AGREGADO: HIDROL. EXT. PROTEINA DE SUERO, PRESENTACION: ENVASE X 400 GR, MATERIAL ENVASE: METAL, ELEM. TRANSPORTE: SIN, MATERIAL ELEM. TRANSPORTE: SIN, CERTIFICADO FORESTAL (GFS): SIN, LIBRE DE GLUTEN: NO | H54: NO | I54: ENVASE | J54: 2837.7 | K54: 3
A55: 44 | B55: ='[1]Necesidades Trimestrales'!B54 -> 2.1.1-788.222 | C55: GALLETITAS; VARIEDAD: SALADA TOSTADA, RELLENO: SIN, PRESENTACION: ENVASE X 140 GR, ELEM. TRANSPORTE: SIN, MATERIAL ELEM. TRANSPORTE: SIN, LIBRE DE GLUTEN: SI | D55: GALLETITAS; VARIEDAD: SALADA TOSTADA, RELLENO: SIN, PRESENTACION: ENVASE X 140 GR, ELEM. TRANSPORTE: SIN, MATERIAL ELEM. TRANSPORTE: SIN, LIBRE DE GLUTEN: SI | E55: GALLETITAS; VARIEDAD: SALADA TOSTADA, RELLENO: SIN, PRESENTACION: ENVASE X 140 GR, ELEM. TRANSPORTE: SIN, MATERIAL ELEM. TRANSPORTE: SIN, LIBRE DE GLUTEN: SI | F55: GALLETITAS; VARIEDAD: SALADA TOSTADA, RELLENO: SIN, PRESENTACION: ENVASE X 140 GR, ELEM. TRANSPORTE: SIN, MATERIAL ELEM. TRANSPORTE: SIN, LIBRE DE GLUTEN: SI | G55: GALLETITAS; VARIEDAD: SALADA TOSTADA, RELLENO: SIN, PRESENTACION: ENVASE X 140 GR, ELEM. TRANSPORTE: SIN, MATERIAL ELEM. TRANSPORTE: SIN, LIBRE DE GLUTEN: SI | H55: NO | I55: ENVASE | J55: 1280 | K55: 1
A56: 45 | B56: ='[1]Necesidades Trimestrales'!B55 -> 2.1.1-510.3 | C56: GELATINAS; TIPO: BAJAS CALORIAS, ENVASE: CAJA DE CARTON, PESO: 30 GR, SABOR: CEREZA | D56: GELATINAS; TIPO: BAJAS CALORIAS, ENVASE: CAJA DE CARTON, PESO: 30 GR, SABOR: CEREZA | E56: GELATINAS; TIPO: BAJAS CALORIAS, ENVASE: CAJA DE CARTON, PESO: 30 GR, SABOR: CEREZA | F56: GELATINAS; TIPO: BAJAS CALORIAS, ENVASE: CAJA DE CARTON, PESO: 30 GR, SABOR: CEREZA | G56: GELATINAS; TIPO: BAJAS CALORIAS, ENVASE: CAJA DE CARTON, PESO: 30 GR, SABOR: CEREZA | H56: NO | I56: CAJA | J56: 58.8 | K56: 100
A57: 46 | B57: ='[1]Necesidades Trimestrales'!B56 -> 2.1.1-510.65 | C57: GELATINAS; TIPO: COMUN, PESO: 50 GR, SABOR: DURAZNO, ENVASE: CAJA DE CARTON, LIBRE DE GLUTEN: NO | D57: GELATINAS; TIPO: COMUN, PESO: 50 GR, SABOR: DURAZNO, ENVASE: CAJA DE CARTON, LIBRE DE GLUTEN: NO | E57: GELATINAS; TIPO: COMUN, PESO: 50 GR, SABOR: DURAZNO, ENVASE: CAJA DE CARTON, LIBRE DE GLUTEN: NO | F57: GELATINAS; TIPO: COMUN, PESO: 50 GR, SABOR: DURAZNO, ENVASE: CAJA DE CARTON, LIBRE DE GLUTEN: NO | G57: GELATINAS; TIPO: COMUN, PESO: 50 GR, SABOR: DURAZNO, ENVASE: CAJA DE CARTON, LIBRE DE GLUTEN: NO | H57: NO | I57: CAJA | J57: 51.75 | K57: 100
A58: 47 | B58: ='[1]Necesidades Trimestrales'!B57 -> 2.1.1-482.77 | C58: HARINAS; TIPO: DE TRIGO 0000, PRESENTACION: ENVASE X 1 Kg, MATERIAL ENVASE: PAPEL, CERTICADO FORESTAL (GFS): SIN, ELEM. TRANSPORTE: SIN, MATERIAL ELEM. TRANSPORTE: SIN, LIBRE DE GLUTEN: NO | D58: HARINAS; TIPO: DE TRIGO 0000, PRESENTACION: ENVASE X 1 Kg, MATERIAL ENVASE: PAPEL, CERTICADO FORESTAL (GFS): SIN, ELEM. TRANSPORTE: SIN, MATERIAL ELEM. TRANSPORTE: SIN, LIBRE DE GLUTEN: NO | E58: HARINAS; TIPO: DE TRIGO 0000, PRESENTACION: ENVASE X 1 Kg, MATERIAL ENVASE: PAPEL, CERTICADO FORESTAL (GFS): SIN, ELEM. TRANSPORTE: SIN, MATERIAL ELEM. TRANSPORTE: SIN, LIBRE DE GLUTEN: NO | F58: HARINAS; TIPO: DE TRIGO 0000, PRESENTACION: ENVASE X 1 Kg, MATERIAL ENVASE: PAPEL, CERTICADO FORESTAL (GFS): SIN, ELEM. TRANSPORTE: SIN, MATERIAL ELEM. TRANSPORTE: SIN, LIBRE DE GLUTEN: NO | G58: HARINAS; TIPO: DE TRIGO 0000, PRESENTACION: ENVASE X 1 Kg, MATERIAL ENVASE: PAPEL, CERTICADO FORESTAL (GFS): SIN, ELEM. TRANSPORTE: SIN, MATERIAL ELEM. TRANSPORTE: SIN, LIBRE DE GLUTEN: NO | H58: NO | I58: ENVASE | J58: 55.5 | K58: 100
A59: 48 | B59: ='[1]Necesidades Trimestrales'!B58 -> 2.1.1-483.33 | C59: HUEVO DE GALLINA; TAMAÑO: MEDIANOS, COLOR: BLANCOS, PRESENTACION: 30 | D59: HUEVO DE GALLINA; TAMAÑO: MEDIANOS, COLOR: BLANCOS, PRESENTACION: 30 | E59: HUEVO DE GALLINA; TAMAÑO: MEDIANOS, COLOR: BLANCOS, PRESENTACION: 30 | F59: HUEVO DE GALLINA; TAMAÑO: MEDIANOS, COLOR: BLANCOS, PRESENTACION: 30 | G59: HUEVO DE GALLINA; TAMAÑO: MEDIANOS, COLOR: BLANCOS, PRESENTACION: 30 | H59: NO | I59: CARTON | J59: 275 | K59: 60
A60: 49 | B60: ='[1]Necesidades Trimestrales'!B59 -> 2.1.1-969.96 | C60: FIAMBRES; TIPO: JAMON COCIDO, PRESENTACION: AL VACIO | D60: FIAMBRES; TIPO: JAMON COCIDO, PRESENTACION: AL VACIO | E60: FIAMBRES; TIPO: JAMON COCIDO, PRESENTACION: AL VACIO | F60: FIAMBRES; TIPO: JAMON COCIDO, PRESENTACION: AL VACIO | G60: FIAMBRES; TIPO: JAMON COCIDO, PRESENTACION: AL VACIO | H60: NO | I60: KG | J60: 640 | K60: 13
A61: 50 | B61: ='[1]Necesidades Trimestrales'!B60 -> 2.1.1-705.95 | C61: LECHE; ESTADO: POLVO, TIPO: DESCREMADA, PROCESO: PASTEURIZADA, AGREGADO: VITAMINAS A Y D, PRESENTACION: ENVASE X 400 GR, MATERIAL ENVASE: CARTON, ELEM. TRANSPORTE: SIN, MATERIAL ELEM. TRANSPORTE: SIN, CERTIFICADO FORESTAL (GFS): SIN, LIBRE DE GLUTEN: NO | D61: LECHE; ESTADO: POLVO, TIPO: DESCREMADA, PROCESO: PASTEURIZADA, AGREGADO: VITAMINAS A Y D, PRESENTACION: ENVASE X 400 GR, MATERIAL ENVASE: CARTON, ELEM. TRANSPORTE: SIN, MATERIAL ELEM. TRANSPORTE: SIN, CERTIFICADO FORESTAL (GFS): SIN, LIBRE DE GLUTEN: NO | E61: LECHE; ESTADO: POLVO, TIPO: DESCREMADA, PROCESO: PASTEURIZADA, AGREGADO: VITAMINAS A Y D, PRESENTACION: ENVASE X 400 GR, MATERIAL ENVASE: CARTON, ELEM. TRANSPORTE: SIN, MATERIAL ELEM. TRANSPORTE: SIN, CERTIFICADO FORESTAL (GFS): SIN, LIBRE DE GLUTEN: NO | F61: LECHE; ESTADO: POLVO, TIPO: DESCREMADA, PROCESO: PASTEURIZADA, AGREGADO: VITAMINAS A Y D, PRESENTACION: ENVASE X 400 GR, MATERIAL ENVASE: CARTON, ELEM. TRANSPORTE: SIN, MATERIAL ELEM. TRANSPORTE: SIN, CERTIFICADO FORESTAL (GFS): SIN, LIBRE DE GLUTEN: NO | G61: LECHE; ESTADO: POLVO, TIPO: DESCREMADA, PROCESO: PASTEURIZADA, AGREGADO: VITAMINAS A Y D, PRESENTACION: ENVASE X 400 GR, MATERIAL ENVASE: CARTON, ELEM. TRANSPORTE: SIN, MATERIAL ELEM. TRANSPORTE: SIN, CERTIFICADO FORESTAL (GFS): SIN, LIBRE DE GLUTEN: NO | H61: NO | I61: ENVASE | J61: 327.57 | K61: 20
A62: 51 | B62: ='[1]Necesidades Trimestrales'!B61 -> 2.1.1-705.105 | C62: LECHE; ESTADO: LIQUIDO, TIPO: DESCREMADA, PROCESO: PASTEURIZADA, AGREGADO: VITAMINAS Y MINERALES, PRESENTACION: ENVASE X 1 L, MATERIAL ENVASE: CARTON, ELEM. TRANSPORTE: SIN, MATERIAL ELEM. TRANSPORTE: SIN, CERTIFICADO FORESTAL (GFS): SIN, LIBRE DE GLUTEN: SI | D62: LECHE; ESTADO: LIQUIDO, TIPO: DESCREMADA, PROCESO: PASTEURIZADA, AGREGADO: VITAMINAS Y MINERALES, PRESENTACION: ENVASE X 1 L, MATERIAL ENVASE: CARTON, ELEM. TRANSPORTE: SIN, MATERIAL ELEM. TRANSPORTE: SIN, CERTIFICADO FORESTAL (GFS): SIN, LIBRE DE GLUTEN: SI | E62: LECHE; ESTADO: LIQUIDO, TIPO: DESCREMADA, PROCESO: PASTEURIZADA, AGREGADO: VITAMINAS Y MINERALES, PRESENTACION: ENVASE X 1 L, MATERIAL ENVASE: CARTON, ELEM. TRANSPORTE: SIN, MATERIAL ELEM. TRANSPORTE: SIN, CERTIFICADO FORESTAL (GFS): SIN, LIBRE DE GLUTEN: SI | F62: LECHE; ESTADO: LIQUIDO, TIPO: DESCREMADA, PROCESO: PASTEURIZADA, AGREGADO: VITAMINAS Y MINERALES, PRESENTACION: ENVASE X 1 L, MATERIAL ENVASE: CARTON, ELEM. TRANSPORTE: SIN, MATERIAL ELEM. TRANSPORTE: SIN, CERTIFICADO FORESTAL (GFS): SIN, LIBRE DE GLUTEN: SI | G62: LECHE; ESTADO: LIQUIDO, TIPO: DESCREMADA, PROCESO: PASTEURIZADA, AGREGADO: VITAMINAS Y MINERALES, PRESENTACION: ENVASE X 1 L, MATERIAL ENVASE: CARTON, ELEM. TRANSPORTE: SIN, MATERIAL ELEM. TRANSPORTE: SIN, CERTIFICADO FORESTAL (GFS): SIN, LIBRE DE GLUTEN: SI | H62: NO | I62: ENVASE | J62: 100 | K62: 160
A63: 52 | B63: ='[1]Necesidades Trimestrales'!B62 -> 2.1.1-705.106 | C63: LECHE; ESTADO: LIQUIDO, TIPO: ENTERA, PROCESO: LARGA VIDA, AGREGADO: VITAMINAS A Y D, PRESENTACION: ENVASE X 1 L, MATERIAL ENVASE: PLASTICO, ELEM. TRANSPORTE: SIN, MATERIAL ELEM. TRANSPORTE: SIN, CERTIFICADO FORESTAL (GFS): SIN, LIBRE DE GLUTEN: SI | D63: LECHE; ESTADO: LIQUIDO, TIPO: ENTERA, PROCESO: LARGA VIDA, AGREGADO: VITAMINAS A Y D, PRESENTACION: ENVASE X 1 L, MATERIAL ENVASE: PLASTICO, ELEM. TRANSPORTE: SIN, MATERIAL ELEM. TRANSPORTE: SIN, CERTIFICADO FORESTAL (GFS): SIN, LIBRE DE GLUTEN: SI | E63: LECHE; ESTADO: LIQUIDO, TIPO: ENTERA, PROCESO: LARGA VIDA, AGREGADO: VITAMINAS A Y D, PRESENTACION: ENVASE X 1 L, MATERIAL ENVASE: PLASTICO, ELEM. TRANSPORTE: SIN, MATERIAL ELEM. TRANSPORTE: SIN, CERTIFICADO FORESTAL (GFS): SIN, LIBRE DE GLUTEN: SI | F63: LECHE; ESTADO: LIQUIDO, TIPO: ENTERA, PROCESO: LARGA VIDA, AGREGADO: VITAMINAS A Y D, PRESENTACION: ENVASE X 1 L, MATERIAL ENVASE: PLASTICO, ELEM. TRANSPORTE: SIN, MATERIAL ELEM. TRANSPORTE: SIN, CERTIFICADO FORESTAL (GFS): SIN, LIBRE DE GLUTEN: SI | G63: LECHE; ESTADO: LIQUIDO, TIPO: ENTERA, PROCESO: LARGA VIDA, AGREGADO: VITAMINAS A Y D, PRESENTACION: ENVASE X 1 L, MATERIAL ENVASE: PLASTICO, ELEM. TRANSPORTE: SIN, MATERIAL ELEM. TRANSPORTE: SIN, CERTIFICADO FORESTAL (GFS): SIN, LIBRE DE GLUTEN: SI | H63: NO | I63: ENVASE | J63: 100 | K63: 160
A64: 53 | B64: ='[1]Necesidades Trimestrales'!B63 -> 2.1.1-6547.88 | C64: LEGUMBRES; VARIEDAD: LENTEJA, ESTADO: SECO, PRESENTACION: BOLSA, PESO: 450 GR, MATERIAL ENVASE: PLASTICO, ELEM. TRANSPORTE: SIN, MATERIAL ELEM. TRANSPORTE: SIN, LIBRE DE GLUTEN: SI | D64: LEGUMBRES; VARIEDAD: LENTEJA, ESTADO: SECO, PRESENTACION: BOLSA, PESO: 450 GR, MATERIAL ENVASE: PLASTICO, ELEM. TRANSPORTE: SIN, MATERIAL ELEM. TRANSPORTE: SIN, LIBRE DE GLUTEN: SI | E64: LEGUMBRES; VARIEDAD: LENTEJA, ESTADO: SECO, PRESENTACION: BOLSA, PESO: 450 GR, MATERIAL ENVASE: PLASTICO, ELEM. TRANSPORTE: SIN, MATERIAL ELEM. TRANSPORTE: SIN, LIBRE DE GLUTEN: SI | F64: LEGUMBRES; VARIEDAD: LENTEJA, ESTADO: SECO, PRESENTACION: BOLSA, PESO: 450 GR, MATERIAL ENVASE: PLASTICO, ELEM. TRANSPORTE: SIN, MATERIAL ELEM. TRANSPORTE: SIN, LIBRE DE GLUTEN: SI | G64: LEGUMBRES; VARIEDAD: LENTEJA, ESTADO: SECO, PRESENTACION: BOLSA, PESO: 450 GR, MATERIAL ENVASE: PLASTICO, ELEM. TRANSPORTE: SIN, MATERIAL ELEM. TRANSPORTE: SIN, LIBRE DE GLUTEN: SI | H64: NO | I64: ENVASE | J64: 115 | K64: 8
A65: 54 | B65: ='[1]Necesidades Trimestrales'!B64 -> 2.1.1-6546.374 | C65: VERDURAS Y HORTALIZAS; VARIEDAD: LECHUGA ARREPOLLADA, ESTADO: NATURAL, PRESENTACION: A GRANEL, PESO: 300 GR CADA PLANTA, ELEM. TRANSPORTE: SIN, MATERIAL ELEM. TRANSPORTE: SIN, LIBRE DE GLUTEN: SI | D65: VERDURAS Y HORTALIZAS; VARIEDAD: LECHUGA ARREPOLLADA, ESTADO: NATURAL, PRESENTACION: A GRANEL, PESO: 300 GR CADA PLANTA, ELEM. TRANSPORTE: SIN, MATERIAL ELEM. TRANSPORTE: SIN, LIBRE DE GLUTEN: SI | E65: VERDURAS Y HORTALIZAS; VARIEDAD: LECHUGA ARREPOLLADA, ESTADO: NATURAL, PRESENTACION: A GRANEL, PESO: 300 GR CADA PLANTA, ELEM. TRANSPORTE: SIN, MATERIAL ELEM. TRANSPORTE: SIN, LIBRE DE GLUTEN: SI | F65: VERDURAS Y HORTALIZAS; VARIEDAD: LECHUGA ARREPOLLADA, ESTADO: NATURAL, PRESENTACION: A GRANEL, PESO: 300 GR CADA PLANTA, ELEM. TRANSPORTE: SIN, MATERIAL ELEM. TRANSPORTE: SIN, LIBRE DE GLUTEN: SI | G65: VERDURAS Y HORTALIZAS; VARIEDAD: LECHUGA ARREPOLLADA, ESTADO: NATURAL, PRESENTACION: A GRANEL, PESO: 300 GR CADA PLANTA, ELEM. TRANSPORTE: SIN, MATERIAL ELEM. TRANSPORTE: SIN, LIBRE DE GLUTEN: SI | H65: NO | I65: KG | J65: 42 | K65: 40
A66: 55 | B66: ='[1]Necesidades Trimestrales'!B65 -> 2.1.1-2116.10 | C66: LEVADURAS; TIPO: SECA INSTANTANEA, PRESENTACION: SOBRE, PESO: 20 GR | D66: LEVADURAS; TIPO: SECA INSTANTANEA, PRESENTACION: SOBRE, PESO: 20 GR | E66: LEVADURAS; TIPO: SECA INSTANTANEA, PRESENTACION: SOBRE, PESO: 20 GR | F66: LEVADURAS; TIPO: SECA INSTANTANEA, PRESENTACION: SOBRE, PESO: 20 GR | G66: LEVADURAS; TIPO: SECA INSTANTANEA, PRESENTACION: SOBRE, PESO: 20 GR | H66: NO | I66: SOBRE | J66: 35 | K66: 15
... A75: 64 | B75: ='[1]Necesidades Trimestrales'!B74 -> 2.1.1-489.85 | C75: ESPECIAS; PRESENTACION: SOBRE X 50 GR, TIPO: OREGANO | D75: ESPECIAS; PRESENTACION: SOBRE X 50 GR, TIPO: OREGANO | E75: ESPECIAS; PRESENTACION: SOBRE X 50 GR, TIPO: OREGANO | F75: ESPECIAS; PRESENTACION: SOBRE X 50 GR, TIPO: OREGANO | G75: ESPECIAS; PRESENTACION: SOBRE X 50 GR, TIPO: OREGANO | H75: NO | I75: SOBRE | J75: 54 | K75: 20
A76: 65 | B76: ='[1]Necesidades Trimestrales'!B77 -> 2.1.1-6546.335 | C76: VERDURAS Y HORTALIZAS; VARIEDAD: PAPA BLANCA, ESTADO: NATURAL, PRESENTACION: BOLSA, PESO: 25 Kg | D76: VERDURAS Y HORTALIZAS; VARIEDAD: PAPA BLANCA, ESTADO: NATURAL, PRESENTACION: BOLSA, PESO: 25 Kg | E76: VERDURAS Y HORTALIZAS; VARIEDAD: PAPA BLANCA, ESTADO: NATURAL, PRESENTACION: BOLSA, PESO: 25 Kg | F76: VERDURAS Y HORTALIZAS; VARIEDAD: PAPA BLANCA, ESTADO: NATURAL, PRESENTACION: BOLSA, PESO: 25 Kg | G76: VERDURAS Y HORTALIZAS; VARIEDAD: PAPA BLANCA, ESTADO: NATURAL, PRESENTACION: BOLSA, PESO: 25 Kg | H76: NO | I76: BOLSA | J76: =32*20 -> 640 | K76: 16
A77: 66 | B77: ='[1]Necesidades Trimestrales'!B78 -> 2.1.1-541.29 | C77: CARNES; CORTE: PECETO, ESPECIE: VACUNA, TIPO: VACUNA | D77: CARNES; CORTE: PECETO, ESPECIE: VACUNA, TIPO: VACUNA | E77: CARNES; CORTE: PECETO, ESPECIE: VACUNA, TIPO: VACUNA | F77: CARNES; CORTE: PECETO, ESPECIE: VACUNA, TIPO: VACUNA | G77: CARNES; CORTE: PECETO, ESPECIE: VACUNA, TIPO: VACUNA | H77: NO | I77: KG | J77: 500 | K77: 100
A78: 67 | B78: ='[1]Necesidades Trimestrales'!B79 -> 2.1.1-621.20 | C78: AVES; TIPO: POLLO, PRESENTACION: CAJA X 22 Kg, EVISCERADO: SI, ELEM. TRANSPORTE: SIN, MATERIAL ELEM. TRANSPORTE: SIN, LIBRE DE GLUTEN: SIN VALOR | D78: AVES; TIPO: POLLO, PRESENTACION: CAJA X 22 Kg, EVISCERADO: SI, ELEM. TRANSPORTE: SIN, MATERIAL ELEM. TRANSPORTE: SIN, LIBRE DE GLUTEN: SIN VALOR | E78: AVES; TIPO: POLLO, PRESENTACION: CAJA X 22 Kg, EVISCERADO: SI, ELEM. TRANSPORTE: SIN, MATERIAL ELEM. TRANSPORTE: SIN, LIBRE DE GLUTEN: SIN VALOR | F78: AVES; TIPO: POLLO, PRESENTACION: CAJA X 22 Kg, EVISCERADO: SI, ELEM. TRANSPORTE: SIN, MATERIAL ELEM. TRANSPORTE: SIN, LIBRE DE GLUTEN: SIN VALOR | G78: AVES; TIPO: POLLO, PRESENTACION: CAJA X 22 Kg, EVISCERADO: SI, ELEM. TRANSPORTE: SIN, MATERIAL ELEM. TRANSPORTE: SIN, LIBRE DE GLUTEN: SIN VALOR | H78: NO | I78: CAJA | J78: 2420 | K78: 30
A79: 68 | B79: ='[1]Necesidades Trimestrales'!B80 -> 2.1.1-6539.32 | C79: FRUTAS; VARIEDAD: PERA AMARILLA, ESTADO: NATURAL, PRESENTACION: CAJON, PESO: SIN VALOR | D79: FRUTAS; VARIEDAD: PERA AMARILLA, ESTADO: NATURAL, PRESENTACION: CAJON, PESO: SIN VALOR | E79: FRUTAS; VARIEDAD: PERA AMARILLA, ESTADO: NATURAL, PRESENTACION: CAJON, PESO: SIN VALOR | F79: FRUTAS; VARIEDAD: PERA AMARILLA, ESTADO: NATURAL, PRESENTACION: CAJON, PESO: SIN VALOR | G79: FRUTAS; VARIEDAD: PERA AMARILLA, ESTADO: NATURAL, PRESENTACION: CAJON, PESO: SIN VALOR | H79: NO | I79: CAJON | J79: 1650 | K79: 9
A80: 69 | B80: ='[1]Necesidades Trimestrales'!B81 -> 2.1.1-6546.133 | C80: VERDURAS Y HORTALIZAS; VARIEDAD: PEREJIL, ESTADO: NATURAL, PRESENTACION: ATADO, PESO: 1 Kg | D80: VERDURAS Y HORTALIZAS; VARIEDAD: PEREJIL, ESTADO: NATURAL, PRESENTACION: ATADO, PESO: 1 Kg | E80: VERDURAS Y HORTALIZAS; VARIEDAD: PEREJIL, ESTADO: NATURAL, PRESENTACION: ATADO, PESO: 1 Kg | F80: VERDURAS Y HORTALIZAS; VARIEDAD: PEREJIL, ESTADO: NATURAL, PRESENTACION: ATADO, PESO: 1 Kg | G80: VERDURAS Y HORTALIZAS; VARIEDAD: PEREJIL, ESTADO: NATURAL, PRESENTACION: ATADO, PESO: 1 Kg | H80: NO | I80: ATADO | J80: 40 | K80: 16
A81: 70 | B81: ='[1]Necesidades Trimestrales'!B82 -> 2.1.1-489.97 | C81: ESPECIAS; TIPO: PIMENTON DULCE, PRESENTACION: PAQUETE X 50 GR | D81: ESPECIAS; TIPO: PIMENTON DULCE, PRESENTACION: PAQUETE X 50 GR | E81: ESPECIAS; TIPO: PIMENTON DULCE, PRESENTACION: PAQUETE X 50 GR | F81: ESPECIAS; TIPO: PIMENTON DULCE, PRESENTACION: PAQUETE X 50 GR | G81: ESPECIAS; TIPO: PIMENTON DULCE, PRESENTACION: PAQUETE X 50 GR | H81: NO | I81: PAQUETE | J81: 29 | K81: 20
...

Sheet Autor Gastar
A1: EJERCICIO: | P1: AUTORIZACION PARA GASTAR
A4: JURISDICCIÓN: | G4: 42-Miniterio de salud
A5: SAF: | G5: 28-Maternidad Provincial 25 de Mayo
A6: UNIDAD EJECUTORA: | G6: 169-Direccion Asistencial
A7: DEPENDENCIA SOLICITANTE: | G7: Servicio de Nutricion y Dietoterapia
A8: AUTORIZACIÓN:
A9: Señor Director de Administración o Titular del Servicio Administrativo Financiero:
A10: Autorizo la realización de los trámites correspondientes, a fin de proveer a este Organismo los bienes, servicios que se detallan en Nota de Pedido N°304/2020 , afectando la erogación resultante a los créditos presupuestarios aprobados a favor de esta Unidad Ejecutora, conforme al siguiente detalle:
A12: IMPUTACIÓN PRESUPUESTARIA
A13: CÓDIGO | O13: DENOMINACIÓN DE LA PARTIDA PRESUPUESTARIA | Q13: IMPORTE
A14: PR | B14: SB | C14: PY | D14: AC | E14: OB | F14: UG | G14: FIN | H14: FUN | I14: I | J14: P | K14: P | L14: SubP | M14: M | N14: FF
A15: 42 | D15: 2 | F15: 4901 | G15: 3 | H15: 1 | I15: 2 | J15: 1 | K15: 1 | M15: 1 | N15: 1.1 | O15: Alimentos para personas | Q15: 1437600.6
A24: TOTAL DE PESOS: Un millon cuatrocientos treinta y siete mil seiscientos con 57/100 centavos. | Q24: =SUM(Q15:Q23) -> 1437600.6
A26: JUSTIFICACIÓN:
A27: Adquisicion de Alimentos para pacientes internados, destinados al servicio de nutricion de Maternidad Provincial "25 de Mayo"
