Workbook

Sheet Necesidades Trimestrales 
A1: 2021
B2: Pedido de Necesidades Trimestrales
A4: JURISDICCION: | C4: 40 - MINISTERIO DE SALUD
A5: SAF N°: | C5: 11 - DIR. PROV DE ADMINISTRACION - MINISTERIO DE SALUD
A6: EJERCICIO: | C6: 2021
A7: TRIMESTRE: | C7: SEGUNDO TRIMESTRE
A9: ID | B9: CODIGO ITEM | C9: RUBRO DE COMPRA | D9: I.P.P. | E9: DESCRIPCION | F9: UNIDAD DE MEDIDA | G9: DIR. ADM. | H9: TOTAL DIR DE ADM | I9: DIR. LAB. CENTRAL | J9: TOTAL DE LAB CENTRAL | K9: BCO DE SANGRE | L9: TOTAL BANCO DE SANGRE | M9: ATENCION PRIMARIA | N9: TOTAL ATENCION PRI | O9: DIR DE CANCER | P9: TOTAL DE DIR DE CANCER | Q9: FARMACIA | R9: TOTAL FARMACIA | S9: ODONTOLOGIA | T9: TOTAL DE ODONTOLOG | U9: SAME | V9: TOTAL DE SAME | W9: MALBRAN | X9: HOSPITAL MALBRAN | Y9: maternidade e infancia | Z9: total maternidad | AA9: SEC DE ASIST EN SALUD PUB | AB9: TOTAL SEC EN ASIS EN SAL | AC9: SALUD Y MEDIO AMBIENTE | AD9: TOTAL SALUD Y MEDIO AMBIENTE | AE9: VECTORES Y ZOONOSIS | AF9: TOTAL DE VECT Y ZOON | AG9: SUMAR | AH9: TOTAL SUMAR | AI9: CUR | AJ9: TOTAL CUR | AK9: PLANIFICACION | AL9: TOTAL PLANIFICA | AM9: SALUD MENTAL | AN9: TOTAL SALUD MENTAL | AO9: AREAS Y DPAS | AP9: TOTAL DPAS | AQ9: CANTIDAD TOTAL | AR9: PRECIO UNITARIO ESTIMADO | AS9: IMPORTE TOTAL ESTIMADO
A10: 1 | C10: PROD. MEDICO/FARMACEUTICOS/LAB | D10: 2.9.5 | E10: BARBIJO HEMORREPELENTE QUIRURGICO TRIPLE CAPA | F10: UNIDAD | Q10: 800000 | R10: =+Q10*AR10 -> 10400000 | S10: 1000 | T10: =+S10*AR10 -> 13000 | AQ10: =+AO10+AM10+AK10+AI10+AG10+AE10+AC10+AA10+Y10+W10+U10+S10+Q10+O10+M10+K10+I10+G10 -> 801000 | AR10: 13 | AS10: =+AR10*AQ10 -> 10413000
A11: 2 | C11: PROD. MEDICO/FARMACEUTICOS/LAB | D11: 2.9.5 | E11: BARBIJOS DE ALTA EFICIENCIA TIPO N95 | F11: UNIDAD | Q11: 2000 | R11: =+Q11*AR11 -> 260000 | S11: 300 | T11: =+S11*AR11 -> 39000 | AQ11: =+AO11+AM11+AK11+AI11+AG11+AE11+AC11+AA11+Y11+W11+U11+S11+Q11+O11+M11+K11+I11+G11 -> 2300 | AR11: 130 | AS11: =+AR11*AQ11 -> 299000
A12: 3 | C12: PROD. MEDICO/FARMACEUTICOS/LAB | D12: 2.9.5 | E12: CAL SODADA X KG | F12: UNIDAD | Q12: 20 | R12: =+Q12*AR12 -> 4600 | AQ12: =+AO12+AM12+AK12+AI12+AG12+AE12+AC12+AA12+Y12+W12+U12+S12+Q12+O12+M12+K12+I12+G12 -> 20 | AR12: 230 | AS12: =+AR12*AQ12 -> 4600
A13: 4 | C13: PROD. MEDICO/FARMACEUTICOS/LAB | D13: 2.9.5 | E13: CHATA PLASTICA X 1 | F13: UNIDAD | Q13: 10 | R13: =+Q13*AR13 -> 5600 | AQ13: =+AO13+AM13+AK13+AI13+AG13+AE13+AC13+AA13+Y13+W13+U13+S13+Q13+O13+M13+K13+I13+G13 -> 10 | AR13: 560 | AS13: =+AR13*AQ13 -> 5600
A14: 5 | C14: PROD. MEDICO/FARMACEUTICOS/LAB | D14: 2.9.5 | E14: CLAMP UMBILICAL | F14: UNIDAD | Q14: 3000 | R14: =+Q14*AR14 -> 24000 | AQ14: =+AO14+AM14+AK14+AI14+AG14+AE14+AC14+AA14+Y14+W14+U14+S14+Q14+O14+M14+K14+I14+G14 -> 3000 | AR14: 8 | AS14: =+AR14*AQ14 -> 24000
A15: 6 | C15: PROD. MEDICO/FARMACEUTICOS/LAB | D15: 2.9.5 | E15: CUBRE CAMILLA CON ELASTICO 30 GR | F15: UNIDAD | Q15: 200 | R15: =+Q15*AR15 -> 26000 | AQ15: =+AO15+AM15+AK15+AI15+AG15+AE15+AC15+AA15+Y15+W15+U15+S15+Q15+O15+M15+K15+I15+G15 -> 200 | AR15: 130 | AS15: =+AR15*AQ15 -> 26000
A16: 7 | C16: PROD. MEDICO/FARMACEUTICOS/LAB | D16: 2.9.5 | E16: ELECTRODO DESCARTABLE ADULTO | F16: UNIDAD | Q16: 5000 | R16: =+Q16*AR16 -> 40500 | AQ16: =+AO16+AM16+AK16+AI16+AG16+AE16+AC16+AA16+Y16+W16+U16+S16+Q16+O16+M16+K16+I16+G16 -> 5000 | AR16: 8.1 | AS16: =+AR16*AQ16 -> 40500
A17: 8 | C17: PROD.MEDICOS/FARMACEUTICOS/LAB. | D17: 2.9.5 | E17: ESPECULO VAGINA PEQUEÑO | F17: UNIDAD | O17: 1000 | P17: =+O17*AR17 -> 33000 | Y17: =2*100 -> 200 | Z17: =+Y17*AR17 -> 6600 | AQ17: =+AO17+AM17+AK17+AI17+AG17+AE17+AC17+AA17+Y17+W17+U17+S17+Q17+O17+M17+K17+I17+G17 -> 1200 | AR17: 33 | AS17: =+AR17*AQ17 -> 39600
A18: 9 | C18: PROD.MEDICOS/FARMACEUTICOS/LAB. | D18: 2.9.5 | E18: ESPECULO VAGINAL MEDIANO | F18: UNIDAD | O18: 1500 | P18: =+O18*AR18 -> 57000 | Y18: 300 | Z18: =+Y18*AR18 -> 11400 | AQ18: =+AO18+AM18+AK18+AI18+AG18+AE18+AC18+AA18+Y18+W18+U18+S18+Q18+O18+M18+K18+I18+G18 -> 1800 | AR18: 38 | AS18: =+AR18*AQ18 -> 68400
A19: 10 | C19: PROD.MEDICOS/FARMACEUTICOS/LAB. | D19: 2.9.5 | E19: ESPECULO VAGINAL GRANDE | F19: UNIDAD | O19: 500 | P19: =+O19*AR19 -> 18000 | Y19: 200 | Z19: =+Y19*AR19 -> 7200 | AQ19: =+AO19+AM19+AK19+AI19+AG19+AE19+AC19+AA19+Y19+W19+U19+S19+Q19+O19+M19+K19+I19+G19 -> 700 | AR19: 36 | AS19: =+AR19*AQ19 -> 25200
A20: 11 | C20: PROD.MEDICOS/FARMACEUTICOS/LAB. | D20: 2.9.5 | E20: ESPATULAS DE AYRE | F20: UNIDAD | O20: 10 | P20: =+O20*AR20 -> 6050 | AQ20: =+AO20+AM20+AK20+AI20+AG20+AE20+AC20+AA20+Y20+W20+U20+S20+Q20+O20+M20+K20+I20+G20 -> 10 | AR20: 605 | AS20: =+AR20*AQ20 -> 6050
A21: 12 | C21: PROD.MEDICOS/FARMACEUTICOS/LAB. | D21: 2.9.5 | E21: PORTAOBJETOS P/MICROSCOPIO; MATERIAL: VIDRIO, PRESENTACION: CAJA X 100 UN, TAMAÑO: 25 X 76 X 1,2 mm | F21: UNIDAD | O21: 20 | P21: =+O21*AR21 -> 2900 | AQ21: =+AO21+AM21+AK21+AI21+AG21+AE21+AC21+AA21+Y21+W21+U21+S21+Q21+O21+M21+K21+I21+G21 -> 20 | AR21: 145 | AS21: =+AR21*AQ21 -> 2900
A22: 13 | C22: PROD. MEDICO/FARMACEUTICOS/LAB | D22: 2.9.5 | E22: GEL BASE PARA ECOGRAFIA X 1 KG | F22: UNIDAD | Q22: 10 | R22: =+Q22*AR22 -> 1500 | AQ22: =+AO22+AM22+AK22+AI22+AG22+AE22+AC22+AA22+Y22+W22+U22+S22+Q22+O22+M22+K22+I22+G22 -> 10 | AR22: 150 | AS22: =+AR22*AQ22 -> 1500
A23: 14 | C23: PROD. MEDICO/FARMACEUTICOS/LAB | D23: 2.9.5 | E23: GUANTES DE EXAMINACION TAMAÑO L X 100 | F23: UNIDAD | K23: 50 | L23: =+K23*AR23 -> 55000 | Q23: 500 | R23: =+Q23*AR23 -> 550000 | U23: 150 | V23: =+U23*AR23 -> 165000 | Y23: 5 | Z23: =+Y23*AR23 -> 5500 | AQ23: =+AO23+AM23+AK23+AI23+AG23+AE23+AC23+AA23+Y23+W23+U23+S23+Q23+O23+M23+K23+I23+G23 -> 705 | AR23: 1100 | AS23: =+AR23*AQ23 -> 775500
A24: 15 | C24: PROD. MEDICO/FARMACEUTICOS/LAB | D24: 2.9.5 | E24: GUANTES DE EXAMINACION TAMAÑO M X 100 | F24: UNIDAD | K24: 50 | L24: =+K24*AR24 -> 55000 | Q24: 4000 | R24: =+Q24*AR24 -> 4400000 | U24: 150 | V24: =+U24*AR24 -> 165000 | Y24: 10 | Z24: =+Y24*AR24 -> 11000 | AI24: 30 | AJ24: =+AI24*AR24 -> 33000 | AQ24: =+AO24+AM24+AK24+AI24+AG24+AE24+AC24+AA24+Y24+W24+U24+S24+Q24+O24+M24+K24+I24+G24 -> 4240 | AR24: 1100 | AS24: =+AR24*AQ24 -> 4664000
A25: 16 | C25: PROD. MEDICO/FARMACEUTICOS/LAB | D25: 2.9.5 | E25: GUANTES DE EXAMINACON TAMAÑO S X 100 | F25: UNIDAD | K25: 50 | L25: =+K25*AR25 -> 55000 | Q25: 1500 | R25: =+Q25*AR25 -> 1650000 | AI25: 30 | AJ25: =+AI25*AR25 -> 33000 | AQ25: =+AO25+AM25+AK25+AI25+AG25+AE25+AC25+AA25+Y25+W25+U25+S25+Q25+O25+M25+K25+I25+G25 -> 1580 | AR25: 1100 | AS25: =+AR25*AQ25 -> 1738000
A26: 17 | C26: PROD. MEDICO/FARMACEUTICOS/LAB | D26: 2.9.5 | E26: GUANTES DE NITRILO TAMAÑO L X 100 | F26: UNIDAD | Q26: 500 | R26: =+Q26*AR26 -> 1300000 | AQ26: =+AO26+AM26+AK26+AI26+AG26+AE26+AC26+AA26+Y26+W26+U26+S26+Q26+O26+M26+K26+I26+G26 -> 500 | AR26: 2600 | AS26: =+AR26*AQ26 -> 1300000
A27: 18 | C27: PROD. MEDICO/FARMACEUTICOS/LAB | D27: 2.9.5 | E27: GUANTES DE NITRILO TAMAÑO M X 100 | F27: UNIDAD | Q27: 500 | R27: =+Q27*AR27 -> 1300000 | AQ27: =+AO27+AM27+AK27+AI27+AG27+AE27+AC27+AA27+Y27+W27+U27+S27+Q27+O27+M27+K27+I27+G27 -> 500 | AR27: 2600 | AS27: =+AR27*AQ27 -> 1300000
A28: 19 | C28: PROD. MEDICO/FARMACEUTICOS/LAB | D28: 2.9.5 | E28: JERINGA DESCARTABLE DE 20CC S/AGUJA | F28: UNIDAD | Q28: 5000 | R28: =+Q28*AR28 -> 55200 | AQ28: =+AO28+AM28+AK28+AI28+AG28+AE28+AC28+AA28+Y28+W28+U28+S28+Q28+O28+M28+K28+I28+G28 -> 5000 | AR28: 11.04 | AS28: =+AR28*AQ28 -> 55200
A29: 20 | C29: PROD. MEDICO/FARMACEUTICOS/LAB | D29: 2.9.5 | E29: JERINGA DESCARTABLE DE 5 CC S/AGUJA | F29: UNIDAD | Q29: 200000 | R29: =+Q29*AR29 -> 826000 | AQ29: =+AO29+AM29+AK29+AI29+AG29+AE29+AC29+AA29+Y29+W29+U29+S29+Q29+O29+M29+K29+I29+G29 -> 200000 | AR29: 4.13 | AS29: =+AR29*AQ29 -> 826000
A30: 21 | C30: PROD. MEDICO/FARMACEUTICOS/LAB | D30: 2.9.5 | E30: JERINGA DESCARTABLE DE 60 CC S/ AGUJA | F30: UNIDAD | Q30: 1000 | R30: =+Q30*AR30 -> 27080 | AQ30: =+AO30+AM30+AK30+AI30+AG30+AE30+AC30+AA30+Y30+W30+U30+S30+Q30+O30+M30+K30+I30+G30 -> 1000 | AR30: 27.08 | AS30: =+AR30*AQ30 -> 27080
A31: 22 | C31: PROD. MEDICO/FARMACEUTICOS/LAB | D31: 2.9.5 | E31: JERINGA DESCARTABLE PARA INSULINA 100 UI CON AGUJA | F31: UNIDAD | Q31: 80000 | R31: =+Q31*AR31 -> 252000 | AQ31: =+AO31+AM31+AK31+AI31+AG31+AE31+AC31+AA31+Y31+W31+U31+S31+Q31+O31+M31+K31+I31+G31 -> 80000 | AR31: 3.15 | AS31: =+AR31*AQ31 -> 252000
A32: 23 | C32: PROD. MEDICO/FARMACEUTICOS/LAB | D32: 2.9.5 | E32: KIT DESCARTABLE CAMISOLIN 40 GRS + COFIA + BOTAS PAR | F32: UNIDAD | Q32: 40000 | R32: =+Q32*AR32 -> 9680000 | AQ32: =+AO32+AM32+AK32+AI32+AG32+AE32+AC32+AA32+Y32+W32+U32+S32+Q32+O32+M32+K32+I32+G32 -> 40000 | AR32: 242 | AS32: =+AR32*AQ32 -> 9680000
A33: 24 | C33: PROD. MEDICO/FARMACEUTICOS/LAB | D33: 2.9.5 | E33: MAMELUCO LAMINADO TALLE L | F33: UNIDAD | Q33: 2000 | R33: =+Q33*AR33 -> 1700000 | AQ33: =+AO33+AM33+AK33+AI33+AG33+AE33+AC33+AA33+Y33+W33+U33+S33+Q33+O33+M33+K33+I33+G33 -> 2000 | AR33: 850 | AS33: =+AR33*AQ33 -> 1700000
A34: 25 | C34: PROD. MEDICO/FARMACEUTICOS/LAB | D34: 2.9.5 | E34: MAMELUCO LAMINADO TALLE M | F34: UNIDAD | Q34: 2000 | R34: =+Q34*AR34 -> 1700000 | AQ34: =+AO34+AM34+AK34+AI34+AG34+AE34+AC34+AA34+Y34+W34+U34+S34+Q34+O34+M34+K34+I34+G34 -> 2000 | AR34: 850 | AS34: =+AR34*AQ34 -> 1700000
A35: 26 | C35: PROD. MEDICO/FARMACEUTICOS/LAB | D35: 2.9.5 | E35: MAMELUCO LAMINADO TALLE XL | F35: UNIDAD | Q35: 2000 | R35: =+Q35*AR35 -> 1700000 | AQ35: =+AO35+AM35+AK35+AI35+AG35+AE35+AC35+AA35+Y35+W35+U35+S35+Q35+O35+M35+K35+I35+G35 -> 2000 | AR35: 850 | AS35: =+AR35*AQ35 -> 1700000
A36: 27 | C36: PROD. MEDICO/FARMACEUTICOS/LAB | D36: 2.9.5 | E36: MAMELUCO LAMINADO TALLE XXL | F36: UNIDAD | Q36: 1000 | R36: =+Q36*AR36 -> 850000 | AQ36: =+AO36+AM36+AK36+AI36+AG36+AE36+AC36+AA36+Y36+W36+U36+S36+Q36+O36+M36+K36+I36+G36 -> 1000 | AR36: 850 | AS36: =+AR36*AQ36 -> 850000
A37: 28 | C37: PROD. MEDICO/FARMACEUTICOS/LAB | D37: 2.9.5 | E37: OVATA DE ALGODÓN X 15 CM | F37: UNIDAD | Q37: 500 | R37: =+Q37*AR37 -> 30000 | AQ37: =+AO37+AM37+AK37+AI37+AG37+AE37+AC37+AA37+Y37+W37+U37+S37+Q37+O37+M37+K37+I37+G37 -> 500 | AR37: 60 | AS37: =+AR37*AQ37 -> 30000
... A45: 36 | C45: PROD. MEDICO/FARMACEUTICOS/LAB | D45: 2.9.5 | E45: TIRAS REACTIVAS PARA DETERMINACION GLUCOSA X 50 UNIDADES | F45: UNIDAD | Q45: 1000 | R45: =+Q45*AR45 -> 1400000 | AQ45: =+AO45+AM45+AK45+AI45+AG45+AE45+AC45+AA45+Y45+W45+U45+S45+Q45+O45+M45+K45+I45+G45 -> 1000 | AR45: 1400 | AS45: =+AR45*AQ45 -> 1400000
A46: 37 | C46: PROD. MEDICO/FARMACEUTICOS/LAB | D46: 2.9.5 | E46: APARATO PARA MEDICION DE GLUCOSA EN SANGRE | F46: UNIDAD | Q46: =+Q45*0.2 -> 200 | R46: =+Q46*AR46 -> 677600 | AQ46: =+AO46+AM46+AK46+AI46+AG46+AE46+AC46+AA46+Y46+W46+U46+S46+Q46+O46+M46+K46+I46+G46 -> 200 | AR46: =2800*1.21 -> 3388 | AS46: =+AR46*AQ46 -> 677600
A47: 38 | C47: PROD. MEDICO/FARMACEUTICOS/LAB | D47: 2.9.5 | E47: TUBO CONECTOR EN "Y" KT-95 EST. X 1 | F47: UNIDAD | Q47: 100 | R47: =+Q47*AR47 -> 10000 | AQ47: =+AO47+AM47+AK47+AI47+AG47+AE47+AC47+AA47+Y47+W47+U47+S47+Q47+O47+M47+K47+I47+G47 -> 100 | AR47: 100 | AS47: =+AR47*AQ47 -> 10000
A48: 39 | C48: PROD. MEDICO/FARMACEUTICOS/LAB | D48: 2.9.5 | E48: VENDA CAMBRIC 5 CM | F48: UNIDAD | Q48: 10000 | R48: =+Q48*AR48 -> 170000 | AQ48: =+AO48+AM48+AK48+AI48+AG48+AE48+AC48+AA48+Y48+W48+U48+S48+Q48+O48+M48+K48+I48+G48 -> 10000 | AR48: 17 | AS48: =+AR48*AQ48 -> 170000
A49: 40 | C49: PROD. MEDICO/FARMACEUTICOS/LAB | D49: 2.9.5 | E49: VENDA ENYESADA X 10 CM X 20 METROS DE FRAGUADO RAPIDO | F49: UNIDAD | Q49: 500 | R49: =+Q49*AR49 -> 41500 | AQ49: =+AO49+AM49+AK49+AI49+AG49+AE49+AC49+AA49+Y49+W49+U49+S49+Q49+O49+M49+K49+I49+G49 -> 500 | AR49: 83 | AS49: =+AR49*AQ49 -> 41500
...

Sheet  NotaPedido CANCER
A1: NOTA DE PEDIDO | J1: N° | K1: 4/2021
A3: JURISDICCIÓN: | D3: 040 - Ministerio de Salud
A4: SAF: | D4: 011 - Direccion Provincial de Administración - Ministerio de Salud
A5: UNIDAD EJECUTORA: | D5: 159 - DIRECCION PROVINCIAL DE CANCER
A6: DEPENDENCIA SOLICITANTE: | D6: 159 - DIRECCION PROVINCIAL DE CANCER
A7: PERIODO UTILIZACIÓN: | D7: 2° TRIMESTRE
A8: OBJETO: | D8: Adquisicion de Insumo Comun
A10: Ítem | B10: Codigo Item | C10: DESCRIPCIÓN | H10: Adjunta Detalle Técnico | I10: Unidad Medida | J10: Precio Unitario Estimado | K10: Cantidad Solicitada
A12: 1 | C12: ESPECULO VAGINA PEQUEÑO | H12: SI | I12: UNIDAD | J12: 33 | K12: 1000 | M12: =+K12*J12 -> 33000
A13: 2 | C13: ESPECULO VAGINAL MEDIANO | H13: SI | I13: UNIDAD | J13: 38 | K13: 1500 | M13: =+K13*J13 -> 57000
A14: 3 | C14: ESPECULO VAGINAL GRANDE | H14: SI | I14: UNIDAD | J14: 36 | K14: 500 | M14: =+K14*J14 -> 18000
A15: 4 | C15: ESPATULAS DE AYRE | H15: SI | I15: UNIDAD | J15: 605 | K15: 10 | M15: =+K15*J15 -> 6050
A16: 5 | C16: PORTAOBJETOS P/MICROSCOPIO; MATERIAL: VIDRIO, PRESENTACION: CAJA X 100 UN, TAMAÑO: 25 X 76 X 1,2 mm | H16: SI | I16: UNIDAD | J16: 145 | K16: 20 | M16: =+K16*J16 -> 2900
M17: =+K17*J17 -> 0
M18: =+K18*J18 -> 0
M19: =+K19*J19 -> 0
M20: =+K20*J20 -> 0
M21: =+K21*J21 -> 0
M22: =+K22*J22 -> 0
A24: Costo total estimado: CIENTO DIECISEIS MIL NOVECIENTOS CINCUENTA CON 00/100 | J24: =SUM(M12:M22) -> 116950

Sheet APG CANCER
A1: EJERCICIO: | D1: 2021 | P1: AUTORIZACION PARA GASTAR
A4: JURISDICCIÓN: | G4: 040 - Ministerio de Salud
A5: SAF: | G5: 011- Dirección Provincial de Administración
A6: UNIDAD EJECUTORA: | G6: 159 - DIRECCION PROVINCIAL DE CANCER
A7: DEPENDENCIA SOLICITANTE: | G7: 159 - DIRECCION PROVINCIAL DE CANCER
A8: AUTORIZACIÓN:
A9: Señor Jefe de Servicio Administrativo Financiero:
A10: Autorizo la realización de los trámites correspondientes, a fin de proveer a este Organismo los bienes que se detallan en Nota de pedido y Entrega N°4/2021, afectando la erogación resultante a los créditos presupuestarios aprobados a favor de esta Unidad Ejecutora, conforme al siguiente detalle:
A12: IMPUTACIÓN PRESUPUESTARIA
A13: CÓDIGO | O13: DENOMINACIÓN DE LA PARTIDA PRESUPUESTARIA | Q13: IMPORTE
A14: PR | B14: SB | C14: PY | D14: AC | E14: OB | F14: UG | G14: FIN | H14: FUN | I14: I | J14: P | K14: P | L14: SubP | M14: M | N14: FF
A15: 44 | D15: 1 | F15: 4901 | G15: 3 | H15: 1 | I15: 2 | J15: 9 | K15: 5 | M15: 1 | N15: 1.1 | O15: Útiles Menores Médico, Quirúrgico y de Laboratorio | Q15: =+'Necesidades Trimestrales '!P52 -> 116950
A23: TOTAL DE PESOS: CIENTO DIECISEIS MIL NOVECIENTOS CINCUENTA CON 00/100 | Q23: =SUM(Q15:Q22) -> 116950
A25: JUSTIFICACIÓN:
A26: Adquisición de Insumo comun.

Sheet NP BCO DE SANGRE
A1: NOTA DE PEDIDO | J1: N° | K1: 03/2021
A3: JURISDICCIÓN: | D3: 040 - Ministerio de Salud
A4: SAF: | D4: 011 - Direccion Provincial de Administración - Ministerio de Salud
A5: UNIDAD EJECUTORA: | D5: 747 - DIRECCION PROVINCIAL BANCO DE SANGRE
A6: DEPENDENCIA SOLICITANTE: | D6: 747 - DIRECCION PROVINCIAL BANCO DE SANGRE
A7: PERIODO UTILIZACIÓN: | D7: 2° TRIMESTRE
A8: OBJETO: | D8: Adquisicion de Insumos Comunes
A10: Ítem | B10: Codigo Item | C10: DESCRIPCIÓN | H10: Adjunta Detalle Técnico | I10: Unidad Medida | J10: Precio Unitario Estimado | K10: Cantidad Solicitada
A12: 1 | C12: GUANTES DE EXAMINACION TAMAÑO L X 100 | H12: SI | I12: UNIDAD | J12: 1100 | K12: 50 | M12: =+K12*J12 -> 55000
A13: 2 | C13: GUANTES DE EXAMINACION TAMAÑO M X 100 | H13: SI | I13: UNIDAD | J13: 1100 | K13: 50 | M13: =+K13*J13 -> 55000
A14: 3 | C14: GUANTES DE EXAMINACON TAMAÑO S X 100 | H14: SI | I14: UNIDAD | J14: 1100 | K14: 50 | M14: =+K14*J14 -> 55000
A15: 4 | C15: ALGODON X 500 GR | H15: SI | I15: UNIDAD | J15: 1600 | K15: 40 | M15: =+K15*J15 -> 64000
A19: Costo total estimado: Doscientos Veintinueve Mil con 00/100 | J19: =SUM(M12:M15) -> 229000

Sheet APG BCO DE SANGRE
A1: EJERCICIO: | D1: 2021 | P1: AUTORIZACION PARA GASTAR
A4: JURISDICCIÓN: | G4: 040 - Ministerio de Salud
A5: SAF: | G5: 011- Dirección Provincial de Administración
A6: UNIDAD EJECUTORA: | G6: 747 - DIRECCION PROVINCIAL BANCO DE SANGRE
A7: DEPENDENCIA SOLICITANTE: | G7: 747 - DIRECCION PROVINCIAL BANCO DE SANGRE
A8: AUTORIZACIÓN:
A9: Señor Jefe de Servicio Administrativo Financiero:
A10: Autorizo la realización de los trámites correspondientes, a fin de proveer a este Organismo los bienes que se detallan en Nota de pedido y Entrega N°03/2021, afectando la erogación resultante a los créditos presupuestarios aprobados a favor de esta Unidad Ejecutora, conforme al siguiente detalle:
A12: IMPUTACIÓN PRESUPUESTARIA
A13: CÓDIGO | O13: DENOMINACIÓN DE LA PARTIDA PRESUPUESTARIA | Q13: IMPORTE
A14: PR | B14: SB | C14: PY | D14: AC | E14: OB | F14: UG | G14: FIN | H14: FUN | I14: I | J14: P | K14: P | L14: SubP | M14: M | N14: FF
A15: 27 | D15: 1 | F15: 4901 | G15: 3 | H15: 1 | I15: 2 | J15: 9 | K15: 5 | M15: 1 | N15: 1.1 | O15: Útiles Menores Médico, Quirúrgico y de Laboratorio | Q15: =+'Necesidades Trimestrales '!L52 -> 229000
A23: TOTAL DE PESOS: Doscientos Veintinueve Mil con 00/100 | Q23: =SUM(Q15:Q22) -> 229000
A25: JUSTIFICACIÓN:
A26: Adquisición de Insumos Comunes.

Sheet NP BCO DE FARMACIA
A1: NOTA DE PEDIDO | J1: N° | K1: 07/2021
A3: JURISDICCIÓN: | D3: 040 - Ministerio de Salud
A4: SAF: | D4: 011 - Direccion Provincial de Administración - Ministerio de Salud
A5: UNIDAD EJECUTORA: | D5: 469 - DIRECCION PROVINCIAL DE FARMACIA E INSUMOS
A6: DEPENDENCIA SOLICITANTE: | D6: 469 - DIRECCION PROVINCIAL DE FARMACIA E INSUMOS
A7: PERIODO UTILIZACIÓN: | D7: 2° TRIMESTRE
A8: OBJETO: | D8: Adquisicion de Insumos Comunes
A10: Ítem | B10: Codigo Item | C10: DESCRIPCIÓN | H10: Adjunta Detalle Técnico | I10: Unidad Medida | J10: Precio Unitario Estimado | K10: Cantidad Solicitada
A12: 1 | C12: BARBIJO HEMORREPELENTE QUIRURGICO TRIPLE CAPA | H12: SI | I12: UNIDAD | J12: 13 | K12: 800000 | M12: =+K12*J12 -> 10400000
A13: 2 | C13: BARBIJOS DE ALTA EFICIENCIA TIPO N95 | H13: SI | I13: UNIDAD | J13: 130 | K13: 2000 | M13: =+K13*J13 -> 260000
A14: 3 | C14: CAL SODADA X KG | H14: SI | I14: UNIDAD | J14: 230 | K14: 20 | M14: =+K14*J14 -> 4600
A15: 4 | C15: CHATA PLASTICA X 1 | H15: SI | I15: UNIDAD | J15: 560 | K15: 10 | M15: =+K15*J15 -> 5600
A16: 5 | C16: CLAMP UMBILICAL | H16: SI | I16: UNIDAD | J16: 8 | K16: 3000 | M16: =+K16*J16 -> 24000
A17: 6 | C17: CUBRE CAMILLA CON ELASTICO 30 GR | H17: SI | I17: UNIDAD | J17: 130 | K17: 200 | M17: =+K17*J17 -> 26000
A18: 7 | C18: ELECTRODO DESCARTABLE ADULTO | H18: SI | I18: UNIDAD | J18: 8.1 | K18: 5000 | M18: =+K18*J18 -> 40500
A19: 8 | C19: GEL BASE PARA ECOGRAFIA X 1 KG | H19: SI | I19: UNIDAD | J19: 150 | K19: 10 | M19: =+K19*J19 -> 1500
A20: 9 | C20: GUANTES DE EXAMINACION TAMAÑO L X 100 | H20: SI | I20: UNIDAD | J20: 1100 | K20: 500 | M20: =+K20*J20 -> 550000
A21: 10 | C21: GUANTES DE EXAMINACION TAMAÑO M X 100 | H21: SI | I21: UNIDAD | J21: 1100 | K21: 4000 | M21: =+K21*J21 -> 4400000
A22: 11 | C22: GUANTES DE EXAMINACON TAMAÑO S X 100 | H22: SI | I22: UNIDAD | J22: 1100 | K22: 1500 | M22: =+K22*J22 -> 1650000
A23: 12 | C23: GUANTES DE NITRILO TAMAÑO L X 100 | H23: SI | I23: UNIDAD | J23: 2600 | K23: 500 | M23: =+K23*J23 -> 1300000
... A42: 31 | C42: TIRAS REACTIVAS PARA DETERMINACION GLUCOSA X 50 UNIDADES | H42: SI | I42: UNIDAD | J42: 1400 | K42: 1000 | M42: =+K42*J42 -> 1400000
A43: 32 | C43: APARATO PARA MEDICION DE GLUCOSA EN SANGRE | H43: SI | I43: UNIDAD | J43: =2800*1.21 -> 3388 | K43: =+K42*0.2 -> 200 | M43: =+K43*J43 -> 677600
A44: 33 | C44: TUBO CONECTOR EN "Y" KT-95 EST. X 1 | H44: SI | I44: UNIDAD | J44: 100 | K44: 100 | M44: =+K44*J44 -> 10000
A45: 34 | C45: VENDA CAMBRIC 5 CM | H45: SI | I45: UNIDAD | J45: 17 | K45: 10000 | M45: =+K45*J45 -> 170000
A46: 35 | C46: VENDA ENYESADA X 10 CM X 20 METROS DE FRAGUADO RAPIDO | H46: SI | I46: UNIDAD | J46: 83 | K46: 500 | M46: =+K46*J46 -> 41500
A48: Costo total estimado: Cuarenta Millones Seiscientos Cincuenta y Un Mil Ochocientos Sesenta y Cinco con 00/100 | J48: =SUM(M12:M46) -> 40651865

Sheet APG FARMACIA 
A1: EJERCICIO: | D1: 2021 | P1: AUTORIZACION PARA GASTAR
A4: JURISDICCIÓN: | G4: 040 - Ministerio de Salud
A5: SAF: | G5: 011- Dirección Provincial de Administración
A6: UNIDAD EJECUTORA: | G6: 469 - DIRECCION PROVINCIAL DE FARMACIA E INSUMOS
A7: DEPENDENCIA SOLICITANTE: | G7: 469 - DIRECCION PROVINCIAL DE FARMACIA E INSUMOS
A8: AUTORIZACIÓN:
A9: Señor Jefe de Servicio Administrativo Financiero:
A10: Autorizo la realización de los trámites correspondientes, a fin de proveer a este Organismo los bienes que se detallan en Nota de pedido y Entrega N°07/2021, afectando la erogación resultante a los créditos presupuestarios aprobados a favor de esta Unidad Ejecutora, conforme al siguiente detalle:
A12: IMPUTACIÓN PRESUPUESTARIA
A13: CÓDIGO | O13: DENOMINACIÓN DE LA PARTIDA PRESUPUESTARIA | Q13: IMPORTE
A14: PR | B14: SB | C14: PY | D14: AC | E14: OB | F14: UG | G14: FIN | H14: FUN | I14: I | J14: P | K14: P | L14: SubP | M14: M | N14: FF
A15: 30 | D15: 1 | F15: 4901 | G15: 3 | H15: 1 | I15: 2 | J15: 9 | K15: 5 | M15: 1 | N15: 1.1 | O15: Útiles Menores Médico, Quirúrgico y de Laboratorio | Q15: =+'Necesidades Trimestrales '!R52 -> 40651865
A23: TOTAL DE PESOS: Cuarenta Millones Seiscientos Cincuenta y Un Mil Ochocientos Sesenta y Cinco con 00/100 | Q23: =SUM(Q15:Q22) -> 40651865
A25: JUSTIFICACIÓN:
A26: Adquisición de Insumos Comunes.

Sheet  NotaPedido ODONTOLOGIA
A1: NOTA DE PEDIDO | J1: N° | K1: 05/2021
A3: JURISDICCIÓN: | D3: 040 - Ministerio de Salud
A4: SAF: | D4: 011 - Direccion Provincial de Administración - Ministerio de Salud
A5: UNIDAD EJECUTORA: | D5: 470 - DIRECCION PROVINCIAL DE ODONTOLOGIA
A6: DEPENDENCIA SOLICITANTE: | D6: 470 - DIRECCION PROVINCIAL DE ODONTOLOGIA
A7: PERIODO UTILIZACIÓN: | D7: 2° TRIMESTRE
A8: OBJETO: | D8: Adquisicion de Insumos Comunes
A10: Ítem | B10: Codigo Item | C10: DESCRIPCIÓN | H10: Adjunta Detalle Técnico | I10: Unidad Medida | J10: Precio Unitario Estimado | K10: Cantidad Solicitada
A12: 1 | C12: BARBIJO HEMORREPELENTE QUIRURGICO TRIPLE CAPA | H12: SI | I12: UNIDAD | J12: 13 | K12: 1000 | M12: =+K12*J12 -> 13000
A13: 2 | C13: BARBIJOS DE ALTA EFICIENCIA TIPO N95 | H13: SI | I13: UNIDAD | J13: 130 | K13: 300 | M13: =+K13*J13 -> 39000
A14: 3 | C14: ALGODON X 500 GR | H14: SI | I14: UNIDAD | J14: 1600 | K14: 10 | M14: =+K14*J14 -> 16000
A15: 4 | C15: GASA CORTADA DE 5CM X 5CM X 1 KILO | H15: SI | I15: UNIDAD | J15: 1575 | K15: 20 | M15: =+K15*J15 -> 31500
A23: Costo total estimado: Noventa y Nueve Mil Quinientos con 00/100 | J23: =SUM(M12:M15) -> 99500

Sheet APG ODONTOLOGIA
A1: EJERCICIO: | D1: 2021 | P1: AUTORIZACION PARA GASTAR
A4: JURISDICCIÓN: | G4: 040 - Ministerio de Salud
A5: SAF: | G5: 011- Dirección Provincial de Administración
A6: UNIDAD EJECUTORA: | G6: 470 - DIRECCION PROVINCIAL DE ODONTOLOGIA
A7: DEPENDENCIA SOLICITANTE: | G7: 470 - DIRECCION PROVINCIAL DE ODONTOLOGIA
A8: AUTORIZACIÓN:
A9: Señor Jefe de Servicio Administrativo Financiero:
A10: Autorizo la realización de los trámites correspondientes, a fin de proveer a este Organismo los bienes que se detallan en Nota de pedido y Entrega N°05/2021, afectando la erogación resultante a los créditos presupuestarios aprobados a favor de esta Unidad Ejecutora, conforme al siguiente detalle:
A12: IMPUTACIÓN PRESUPUESTARIA
A13: CÓDIGO | O13: DENOMINACIÓN DE LA PARTIDA PRESUPUESTARIA | Q13: IMPORTE
A14: PR | B14: SB | C14: PY | D14: AC | E14: OB | F14: UG | G14: FIN | H14: FUN | I14: I | J14: P | K14: P | L14: SubP | M14: M | N14: FF
A15: 29 | D15: 1 | F15: 4901 | G15: 3 | H15: 1 | I15: 2 | J15: 9 | K15: 5 | M15: 1 | N15: 1.1 | O15: Útiles Menores Médico, Quirúrgico y de Laboratorio | Q15: =+'Necesidades Trimestrales '!T52 -> 99500
A23: TOTAL DE PESOS: Noventa y Nueve Mil Quinientos con 00/100 | Q23: =SUM(Q15:Q22) -> 99500
A25: JUSTIFICACIÓN:
A26: Adquisición de Insumos Comunes.

Sheet  NotaPedido SAME
A1: NOTA DE PEDIDO | J1: N° | K1: 06/2021
A3: JURISDICCIÓN: | D3: 040 - Ministerio de Salud
A4: SAF: | D4: 011 - Direccion Provincial de Administración - Ministerio de Salud
A5: UNIDAD EJECUTORA: | D5: 748 - DIR.PROVINCIAL DEL SISTEMA DE ATENCION MEDICA DE EMERGENCIA
A6: DEPENDENCIA SOLICITANTE: | D6: 748 - DIR.PROVINCIAL DEL SISTEMA DE ATENCION MEDICA DE EMERGENCIA
A7: PERIODO UTILIZACIÓN: | D7: 2° TRIMESTRE
A8: OBJETO: | D8: Adquisicion de Insumos Comunes
A10: Ítem | B10: Codigo Item | C10: DESCRIPCIÓN | H10: Adjunta Detalle Técnico | I10: Unidad Medida | J10: Precio Unitario Estimado | K10: Cantidad Solicitada
A12: 1 | C12: GUANTES DE EXAMINACION TAMAÑO L X 100 | H12: SI | I12: UNIDAD | J12: 1100 | K12: 150 | M12: =+K12*J12 -> 165000
A13: 2 | C13: GUANTES DE EXAMINACION TAMAÑO M X 100 | H13: SI | I13: UNIDAD | J13: 1100 | K13: 150 | M13: =+K13*J13 -> 165000
M14: =+K14*J14 -> 0
M15: =+K15*J15 -> 0
A30: Costo total estimado: Trescientos Treinta Mil con 00/100 | J30: =SUM(M12:M15) -> 330000

Sheet APG SAME
A1: EJERCICIO: | D1: 2021 | P1: AUTORIZACION PARA GASTAR
A4: JURISDICCIÓN: | G4: 040 - Ministerio de Salud
A5: SAF: | G5: 011- Dirección Provincial de Administración
A6: UNIDAD EJECUTORA: | G6: 748 - DIR.PROVINCIAL DEL SISTEMA DE ATENCION MEDICA DE EMERGENCIA
A7: DEPENDENCIA SOLICITANTE: | G7: 748 - DIR.PROVINCIAL DEL SISTEMA DE ATENCION MEDICA DE EMERGENCIA
A8: AUTORIZACIÓN:
A9: Señor Jefe de Servicio Administrativo Financiero:
A10: Autorizo la realización de los trámites correspondientes, a fin de proveer a este Organismo los bienes que se detallan en Nota de pedido y Entrega N°06/2021, afectando la erogación resultante a los créditos presupuestarios aprobados a favor de esta Unidad Ejecutora, conforme al siguiente detalle:
A12: IMPUTACIÓN PRESUPUESTARIA
A13: CÓDIGO | O13: DENOMINACIÓN DE LA PARTIDA PRESUPUESTARIA | Q13: IMPORTE
A14: PR | B14: SB | C14: PY | D14: AC | E14: OB | F14: UG | G14: FIN | H14: FUN | I14: I | J14: P | K14: P | L14: SubP | M14: M | N14: FF
A15: 31 | D15: 1 | F15: 4901 | G15: 3 | H15: 1 | I15: 2 | J15: 9 | K15: 5 | M15: 1 | N15: 1.1 | O15: Útiles Menores Médico, Quirúrgico y de Laboratorio | Q15: =+'Necesidades Trimestrales '!V52 -> 330000
A23: TOTAL DE PESOS: Trescientos Treinta Mil con 00/100 | Q23: =SUM(Q15:Q22) -> 330000
A25: JUSTIFICACIÓN:
A26: Adquisición de Insumos Comunes.

Sheet  NotaPedido materno
A1: NOTA DE PEDIDO | J1: N° | K1: 06/2021
A3: JURISDICCIÓN: | D3: 040 - Ministerio de Salud
A4: SAF: | D4: 011 - Direccion Provincial de Administración - Ministerio de Salud
A5: UNIDAD EJECUTORA: | D5: 162 - DIR.PROVINCIAL MATERNIDAD, INFANCIA Y ADOLESCENCIA
A6: DEPENDENCIA SOLICITANTE: | D6: 162 - DIR.PROVINCIAL MATERNIDAD, INFANCIA Y ADOLESCENCIA
A7: PERIODO UTILIZACIÓN: | D7: 2° TRIMESTRE
A8: OBJETO: | D8: Adquisicion de Insumos Comunes
A10: Ítem | B10: Codigo Item | C10: DESCRIPCIÓN | H10: Adjunta Detalle Técnico | I10: Unidad Medida | J10: Precio Unitario Estimado | K10: Cantidad Solicitada
A12: 1 | C12: ESPECULO VAGINA PEQUEÑO | H12: SI | I12: UNIDAD | J12: 33 | K12: =2*100 -> 200 | M12: =+K12*J12 -> 6600
A13: 2 | C13: ESPECULO VAGINAL MEDIANO | H13: SI | I13: UNIDAD | J13: 38 | K13: 300 | M13: =+K13*J13 -> 11400
A14: 3 | C14: ESPECULO VAGINAL GRANDE | H14: SI | I14: UNIDAD | J14: 36 | K14: 200 | M14: =+K14*J14 -> 7200
A15: 4 | C15: GUANTES DE EXAMINACION TAMAÑO L X 100 | H15: SI | I15: UNIDAD | J15: 1100 | K15: 5 | M15: =+K15*J15 -> 5500
A16: 5 | C16: GUANTES DE EXAMINACION TAMAÑO M X 100 | H16: SI | I16: UNIDAD | J16: 1100 | K16: 10 | M16: =+K16*J16 -> 11000
A27: Costo total estimado: Cuarenta y Un Mil Setecientos con 00/100 | J27: =SUM(M12:M16) -> 41700

Sheet APG materno
A1: EJERCICIO: | D1: 2021 | P1: AUTORIZACION PARA GASTAR
A4: JURISDICCIÓN: | G4: 040 - Ministerio de Salud
A5: SAF: | G5: 011- Dirección Provincial de Administración
A6: UNIDAD EJECUTORA: | G6: 162 - DIR.PROVINCIAL MATERNIDAD, INFANCIA Y ADOLESCENCIA
A7: DEPENDENCIA SOLICITANTE: | G7: 162 - DIR.PROVINCIAL MATERNIDAD, INFANCIA Y ADOLESCENCIA
A8: AUTORIZACIÓN:
A9: Señor Jefe de Servicio Administrativo Financiero:
A10: Autorizo la realización de los trámites correspondientes, a fin de proveer a este Organismo los bienes que se detallan en Nota de pedido y Entrega N°06/2021, afectando la erogación resultante a los créditos presupuestarios aprobados a favor de esta Unidad Ejecutora, conforme al siguiente detalle:
A12: IMPUTACIÓN PRESUPUESTARIA
A13: CÓDIGO | O13: DENOMINACIÓN DE LA PARTIDA PRESUPUESTARIA | Q13: IMPORTE
A14: PR | B14: SB | C14: PY | D14: AC | E14: OB | F14: UG | G14: FIN | H14: FUN | I14: I | J14: P | K14: P | L14: SubP | M14: M | N14: FF
A15: 20 | D15: 1 | F15: 4901 | G15: 3 | H15: 1 | I15: 2 | J15: 9 | K15: 5 | M15: 1 | N15: 1.1 | O15: Útiles Menores Médico, Quirúrgico y de Laboratorio | Q15: =+'Necesidades Trimestrales '!Z52 -> 41700
A23: TOTAL DE PESOS: Cuarenta y Un Mil Setecientos con 00/100 | Q23: =SUM(Q15:Q22) -> 41700
A25: JUSTIFICACIÓN:
A26: Adquisición de Insumos Comunes.

Sheet  NotaPedido CUR
A1: NOTA DE PEDIDO | J1: N° | K1: 06/2021
A3: JURISDICCIÓN: | D3: 040 - Ministerio de Salud
A4: SAF: | D4: 011 - Direccion Provincial de Administración - Ministerio de Salud
A5: UNIDAD EJECUTORA: | D5: 160 - DIR.PROVINCIAL CENTRO UNICO DE REFERENCIA
A6: DEPENDENCIA SOLICITANTE: | D6: 160 - DIR.PROVINCIAL CENTRO UNICO DE REFERENCIA
A7: PERIODO UTILIZACIÓN: | D7: 2° TRIMESTRE
A8: OBJETO: | D8: Adquisicion de Insumos Comunes
A10: Ítem | B10: Codigo Item | C10: DESCRIPCIÓN | H10: Adjunta Detalle Técnico | I10: Unidad Medida | J10: Precio Unitario Estimado | K10: Cantidad Solicitada
A12: 1 | C12: GUANTES DE EXAMINACION TAMAÑO L X 100 | H12: SI | I12: UNIDAD | J12: 1100 | K12: 30 | M12: =+K12*J12 -> 33000
A13: 2 | C13: GUANTES DE EXAMINACION TAMAÑO M X 100 | H13: SI | I13: UNIDAD | J13: 1100 | K13: 30 | M13: =+K13*J13 -> 33000
M14: =+K14*J14 -> 0
M15: =+K15*J15 -> 0
A30: Costo total estimado: Sesenta y Seis Mil con 00/100 | J30: =SUM(M12:M15) -> 66000

Sheet APG CUR
A1: EJERCICIO: | D1: 2021 | P1: AUTORIZACION PARA GASTAR
A4: JURISDICCIÓN: | G4: 040 - Ministerio de Salud
A5: SAF: | G5: 011- Dirección Provincial de Administración
A6: UNIDAD EJECUTORA: | G6: 160 - DIR.PROVINCIAL CENTRO UNICO DE REFERENCIA
A7: DEPENDENCIA SOLICITANTE: | G7: 160 - DIR.PROVINCIAL CENTRO UNICO DE REFERENCIA
A8: AUTORIZACIÓN:
A9: Señor Jefe de Servicio Administrativo Financiero:
A10: Autorizo la realización de los trámites correspondientes, a fin de proveer a este Organismo los bienes que se detallan en Nota de pedido y Entrega N°06/2021, afectando la erogación resultante a los créditos presupuestarios aprobados a favor de esta Unidad Ejecutora, conforme al siguiente detalle:
A12: IMPUTACIÓN PRESUPUESTARIA
A13: CÓDIGO | O13: DENOMINACIÓN DE LA PARTIDA PRESUPUESTARIA | Q13: IMPORTE
A14: PR | B14: SB | C14: PY | D14: AC | E14: OB | F14: UG | G14: FIN | H14: FUN | I14: I | J14: P | K14: P | L14: SubP | M14: M | N14: FF
A15: 35 | D15: 1 | F15: 4901 | G15: 3 | H15: 1 | I15: 2 | J15: 9 | K15: 5 | M15: 1 | N15: 1.1 | O15: Útiles Menores Médico, Quirúrgico y de Laboratorio | Q15: =+'Necesidades Trimestrales '!AJ52 -> 66000
A23: TOTAL DE PESOS: Sesenta y Seis Mil con 00/100 | Q23: =SUM(Q15:Q22) -> 66000
A25: JUSTIFICACIÓN:
A26: Adquisición de Insumos Comunes.
