Workbook

Sheet Necesidades Trimestrales
B2: Pedido de Necesidades Trimestrales
A4: JURISDICCION: | C4: 40 - Ministerio de Salud
A5: SAF N°: | C5: 23 - Hospital Interzonal San Juan Bautista
A6: EJERCICIO: | C6: 2021
A7: TRIMESTRE: | C7: 2
A9: ID | B9: CODIGO ITEM | C9: RUBRO DE COMPRA | D9: I.P.P. | E9: DESCRIPCION | F9: UNIDAD DE MEDIDA | G9: CANTIDAD | H9: PRECIO UNITARIO ESTIMADO | I9: IMPORTE TOTAL ESTIMADO
A10: 1 | C10: Utiles Menores Med. Quirurg.y de Labor. | D10: 2.5.1 | E10: ALCOHOL 70 % X 1000 ML | F10: UNIDAD | G10: 200 | H10: 194 | I10: =G10*H10 -> 38800 | J10: 200 | K10: =I10+I11+I12+I13+I29+I31+I53 -> 2113083.4
A11: 2 | C11: Utiles Menores Med. Quirurg.y de Labor. | D11: 2.5.1 | E11: ALCOHOL 70 % X 500 ML | F11: UNIDAD | G11: 6000 | H11: 90 | I11: =G11*H11 -> 540000 | J11: 1000 | K11: =I14+I15+I16+I17+I18+I19+I20+I21+I22+I23+I24+I25+I26+I27+I28+I30+I32+I33+I34+I35+I36+I37+I38+I39+I40+I41+I42+I43+I44+I45+I46+I47+I48+I49+I50+I51+I52+I54+I55+I56+I57+I58+I59+I60+I61+I62+I63+I64+I65+I66+I67+I68 -> 107898248
A12: 3 | C12: Utiles Menores Med. Quirurg.y de Labor. | D12: 2.5.1 | E12: ALCOHOL EN GEL X 250 ML | F12: UNIDAD | G12: 600 | H12: 95 | I12: =G12*H12 -> 57000 | K12: =SUM(K10:K11) -> 1.1001133e+08
A13: 4 | C13: Utiles Menores Med. Quirurg.y de Labor. | D13: 2.5.1 | E13: AMONIO CUATERNARIO X 5 LITROS TIPO SURFANIOS | F13: UNIDAD | G13: 168 | H13: 7919.45 | I13: =G13*H13 -> 1330467.6 | J13: 168
A14: 5 | C14: Utiles Menores Med. Quirurg.y de Labor. | D14: 2.9.5 | E14: BARBIJO HEMORREPELENTE QUIRURGICO TRIPLE CAPA | F14: UNIDAD | G14: 150000 | H14: 12 | I14: =G14*H14 -> 1800000 | J14: 35000
A15: 6 | C15: Utiles Menores Med. Quirurg.y de Labor. | D15: 2.9.5 | E15: BARBIJOS DE ALTA EFICIENCIA TIPO N95 | F15: UNIDAD | G15: 6000 | H15: 145.2 | I15: =G15*H15 -> 871200 | J15: 2160
A16: 7 | C16: Utiles Menores Med. Quirurg.y de Labor. | D16: 2.9.5 | E16: BOTAS ALTAS DESCARTABLES DE 30 GRAMOS CON TIRA EL PAR | F16: UNIDAD | G16: 150000 | H16: 12.7 | I16: =G16*H16 -> 1905000 | J16: 35000
A17: 8 | C17: Utiles Menores Med. Quirurg.y de Labor. | D17: 2.9.5 | E17: CAMISOLIN DESCARTABLE DE TELA SMS 50 GRAMOS CON MANGA Y PUÑOS DE 1,4 M DE LARGO | F17: UNIDAD | G17: 150000 | H17: 190 | I17: =G17*H17 -> 28500000 | J17: 35000
A18: 9 | C18: Utiles Menores Med. Quirurg.y de Labor. | D18: 2.9.5 | E18: CANULA NASAL PARA ALTO FLUJO TIPO GGM ADULTO 6mm 4826R1V TAMAÑO L | F18: UNIDAD | G18: 30 | H18: 4200 | I18: =G18*H18 -> 126000
A19: 10 | C19: Utiles Menores Med. Quirurg.y de Labor. | D19: 2.9.5 | E19: CANULA NASAL PARA OXIGENOTERAPIA ADULTO | F19: UNIDAD | G19: 7000 | H19: 109.8 | I19: =G19*H19 -> 768600 | J19: 1200
A20: 11 | C20: Utiles Menores Med. Quirurg.y de Labor. | D20: 2.9.5 | E20: CANULA PARA TRAQUEOSTOMIA Nº 7 1/2 | F20: UNIDAD | G20: 80 | H20: 589.4 | I20: =G20*H20 -> 47152 | J20: 40
A21: 12 | C21: Utiles Menores Med. Quirurg.y de Labor. | D21: 2.9.5 | E21: CANULA PARA TRAQUEOSTOMIA Nº 8 | F21: UNIDAD | G21: 100 | H21: 589.4 | I21: =G21*H21 -> 58940 | J21: 40
A22: 13 | C22: Utiles Menores Med. Quirurg.y de Labor. | D22: 2.9.5 | E22: CANULA PARA TRAQUEOTOMIA N° 9 | F22: UNIDAD | G22: 40 | H22: 589.4 | I22: =G22*H22 -> 23576 | J22: 40
A23: 14 | C23: Utiles Menores Med. Quirurg.y de Labor. | D23: 2.9.5 | E23: CIRCUITO ANESTESIA EXTENSIBLE ADULTO AUTOCLAVABLE | F23: UNIDAD | G23: 60 | H23: 1950 | I23: =G23*H23 -> 117000 | J23: 60
A24: 15 | C24: Utiles Menores Med. Quirurg.y de Labor. | D24: 2.9.5 | E24: CIRCUITO ANESTESIA EXTENSIBLE ADULTO DESCARTABLE | F24: UNIDAD | G24: 600 | H24: 510 | I24: =G24*H24 -> 306000 | J24: 600
A25: 16 | C25: Utiles Menores Med. Quirurg.y de Labor. | D25: 2.9.5 | E25: CIRCUITO CERRADO P/ASPIRACION 14 FR | F25: UNIDAD | G25: 620 | H25: 1200 | I25: =G25*H25 -> 744000 | J25: 120
A26: 17 | C26: Utiles Menores Med. Quirurg.y de Labor. | D26: 2.9.5 | E26: CIRCUITO CERRADO P/ASPIRACION 16 FR | F26: UNIDAD | G26: 620 | H26: 1200 | I26: =G26*H26 -> 744000 | J26: 120
A27: 18 | C27: Utiles Menores Med. Quirurg.y de Labor. | D27: 2.9.5 | E27: CIRCUITO RESPIRADOR CON TRAMPA DE AGUA AUTOCLAVABLE ADULTO | F27: UNIDAD | G27: 600 | H27: 16100 | I27: =G27*H27 -> 9660000 | J27: 60
A28: 19 | C28: Utiles Menores Med. Quirurg.y de Labor. | D28: 2.9.5 | E28: CIRCUITO RESPIRADOR CON TRAMPA DE AGUA DESCARTABLE ADULTO | F28: UNIDAD | G28: 600 | H28: 1870 | I28: =G28*H28 -> 1122000 | J28: 600
A29: 20 | C29: Utiles Menores Med. Quirurg.y de Labor. | D29: 2.5.1 | E29: CLORHEXIDINA 4% JABON X 500 ML CON VALVULA DISPENSADORA | F29: UNIDAD | G29: 144 | H29: 466.8 | I29: =G29*H29 -> 67219.2 | J29: 144
A30: 21 | C30: Utiles Menores Med. Quirurg.y de Labor. | D30: 2.9.5 | E30: COFIAS PLIZADAS CON AJUSTE ELASTIZADO | F30: UNIDAD | G30: 150000 | H30: 7.55 | I30: =G30*H30 -> 1132500 | J30: 35000
... A33: 24 | C33: Utiles Menores Med. Quirurg.y de Labor. | D33: 2.9.5 | E33: FILTRO HME BACTERIAL VIRAL PARA CIRCUITO RESPIRADOR | F33: UNIDAD | G33: 500 | H33: 160 | I33: =G33*H33 -> 80000 | J33: 500
A34: 25 | C34: Utiles Menores Med. Quirurg.y de Labor. | D34: 2.9.5 | E34: GUANTES DE CIRUGIA ESTERIL N° 6 1/2 PAR ANATOMICOS. CAÑA LARGA SIN TALCO | F34: UNIDAD | G34: 4500 | H34: 31 | I34: =G34*H34 -> 139500
A35: 26 | C35: Utiles Menores Med. Quirurg.y de Labor. | D35: 2.9.5 | E35: GUANTES DE CIRUGIA ESTERIL N° 7 1/2 PAR NITRILO CAÑA LARGA | F35: UNIDAD | G35: 600 | H35: 31 | I35: =G35*H35 -> 18600 | J35: 600
A36: 27 | C36: Utiles Menores Med. Quirurg.y de Labor. | D36: 2.9.5 | E36: GUANTES DE CIRUGIA ESTERIL Nº 7 PAR. ANATOMICOS . CAÑA LARGA SIN TALCO | F36: UNIDAD | G36: 9000 | H36: 31 | I36: =G36*H36 -> 279000 | J36: 600
A37: 28 | C37: Utiles Menores Med. Quirurg.y de Labor. | D37: 2.9.5 | E37: GUANTES DE CIRUGIA ESTERIL Nº 7 1/2 PAR. ANATOMICOS . CAÑA LARGA SIN TALCO | F37: UNIDAD | G37: 9000 | H37: 31 | I37: =G37*H37 -> 279000 | J37: 600
A38: 29 | C38: Utiles Menores Med. Quirurg.y de Labor. | D38: 2.9.5 | E38: GUANTES DE CIRUGIA ESTERIL Nº 8 PAR. ANATOMICOS . CAÑA LARGA SIN TALCO | F38: UNIDAD | G38: 9000 | H38: 31 | I38: =G38*H38 -> 279000 | J38: 600
A39: 30 | C39: Utiles Menores Med. Quirurg.y de Labor. | D39: 2.9.5 | E39: GUANTES DE CIRUGIA ESTERIL Nº 81/2 PAR. ANATOMICOS . CAÑA LARGA SIN TALCO | F39: UNIDAD | G39: 6000 | H39: 31 | I39: =G39*H39 -> 186000 | J39: 240
A40: 31 | C40: Utiles Menores Med. Quirurg.y de Labor. | D40: 2.9.5 | E40: GUANTES DE EXAMINACION TAMAÑO L X 100 | F40: UNIDAD | G40: 1500 | H40: 990 | I40: =G40*H40 -> 1485000 | J40: 600
A41: 32 | C41: Utiles Menores Med. Quirurg.y de Labor. | D41: 2.9.5 | E41: GUANTES DE EXAMINACION TAMAÑO M X 100 | F41: UNIDAD | G41: 2500 | H41: 990 | I41: =G41*H41 -> 2475000 | J41: 840
A42: 33 | C42: Utiles Menores Med. Quirurg.y de Labor. | D42: 2.9.5 | E42: GUANTES DE EXAMINACON TAMAÑO S X 100 | F42: UNIDAD | G42: 2500 | H42: 990 | I42: =G42*H42 -> 2475000 | J42: 840
A43: 34 | C43: Utiles Menores Med. Quirurg.y de Labor. | D43: 2.9.5 | E43: KIT DESCARTABLE CAMISOLIN 50 GRS + COFIA + BOTAS PAR | F43: UNIDAD | G43: 150000 | H43: 230 | I43: =G43*H43 -> 34500000 | J43: 30000
A44: 35 | C44: Utiles Menores Med. Quirurg.y de Labor. | D44: 2.9.5 | E44: LLAVE DE TRES VIAS | F44: UNIDAD | G44: 4200 | H44: 24.55 | I44: =G44*H44 -> 103110 | J44: 600
A45: 36 | C45: Utiles Menores Med. Quirurg.y de Labor. | D45: 2.9.5 | E45: MAMELUCO LAMINADO TALLE L | F45: UNIDAD | G45: 600 | H45: 1050 | I45: =G45*H45 -> 630000 | J45: 600
...

Sheet NotaPedido
A1: NOTA DE PEDIDO | J1: N° | K1: 050 - 2021
A3: JURISDICCIÓN: | D3: ='Necesidades Trimestrales'!C4 -> 40 - Ministerio de Salud
A4: SAF: | D4: ='Necesidades Trimestrales'!C5 -> 23 - Hospital Interzonal San Juan Bautista
A5: UNIDAD EJECUTORA: | D5: 168 - Direccion Asistencial
A6: DEPENDENCIA SOLICITANTE: | D6: Servicio de Farmacia
A7: PERIODO UTILIZACIÓN: | D7: ='Necesidades Trimestrales'!C7 & "° Trimestre - Año " & 'Necesidades Trimestrales'!C6 -> 2° Trimestre - Año 2021
A8: OBJETO: | D8: Adquisición de Descartables COVID para Farmacia
A10: Ítem | B10: Codigo Item | C10: DESCRIPCIÓN | H10: Adjunta Detalle Técnico | I10: Unidad Medida | J10: Precio Unitario Estimado | K10: Cantidad Solicitada
A12: 1 | B12: ='Necesidades Trimestrales'!B10 -> 0 | C12: ='Necesidades Trimestrales'!E10 -> ALCOHOL 70 % X 1000 ML | H12: NO | I12: ='Necesidades Trimestrales'!F10 -> UNIDAD | J12: ='Necesidades Trimestrales'!H10 -> 194 | K12: ='Necesidades Trimestrales'!G10 -> 200
A13: 2 | B13: ='Necesidades Trimestrales'!B11 -> 0 | C13: ='Necesidades Trimestrales'!E11 -> ALCOHOL 70 % X 500 ML | H13: NO | I13: ='Necesidades Trimestrales'!F11 -> UNIDAD | J13: ='Necesidades Trimestrales'!H11 -> 90 | K13: ='Necesidades Trimestrales'!G11 -> 6000
A14: 3 | C14: ='Necesidades Trimestrales'!E12 -> ALCOHOL EN GEL X 250 ML | H14: NO | I14: ='Necesidades Trimestrales'!F12 -> UNIDAD | J14: ='Necesidades Trimestrales'!H12 -> 95 | K14: ='Necesidades Trimestrales'!G12 -> 600
A15: 4 | B15: ='Necesidades Trimestrales'!B13 -> 0 | C15: ='Necesidades Trimestrales'!E13 -> AMONIO CUATERNARIO X 5 LITROS TIPO SURFANIOS | H15: NO | I15: ='Necesidades Trimestrales'!F13 -> UNIDAD | J15: ='Necesidades Trimestrales'!H13 -> 7919.45 | K15: ='Necesidades Trimestrales'!G13 -> 168
A16: 5 | B16: ='Necesidades Trimestrales'!B14 -> 0 | C16: ='Necesidades Trimestrales'!E14 -> BARBIJO HEMORREPELENTE QUIRURGICO TRIPLE CAPA | H16: NO | I16: ='Necesidades Trimestrales'!F14 -> UNIDAD | J16: ='Necesidades Trimestrales'!H14 -> 12 | K16: ='Necesidades Trimestrales'!G14 -> 150000
A17: 6 | B17: ='Necesidades Trimestrales'!B15 -> 0 | C17: ='Necesidades Trimestrales'!E15 -> BARBIJOS DE ALTA EFICIENCIA TIPO N95 | H17: NO | I17: ='Necesidades Trimestrales'!F15 -> UNIDAD | J17: ='Necesidades Trimestrales'!H15 -> 145.2 | K17: ='Necesidades Trimestrales'!G15 -> 6000
A18: 7 | B18: ='Necesidades Trimestrales'!B16 -> 0 | C18: ='Necesidades Trimestrales'!E16 -> BOTAS ALTAS DESCARTABLES DE 30 GRAMOS CON TIRA EL PAR | H18: NO | I18: ='Necesidades Trimestrales'!F16 -> UNIDAD | J18: ='Necesidades Trimestrales'!H16 -> 12.7 | K18: ='Necesidades Trimestrales'!G16 -> 150000
A19: 8 | B19: ='Necesidades Trimestrales'!B17 -> 0 | C19: ='Necesidades Trimestrales'!E17 -> CAMISOLIN DESCARTABLE DE TELA SMS 50 GRAMOS CON MANGA Y PUÑOS DE 1,4 M DE LARGO | H19: NO | I19: ='Necesidades Trimestrales'!F17 -> UNIDAD | J19: ='Necesidades Trimestrales'!H17 -> 190 | K19: ='Necesidades Trimestrales'!G17 -> 150000
A20: 9 | B20: ='Necesidades Trimestrales'!B18 -> 0 | C20: ='Necesidades Trimestrales'!E18 -> CANULA NASAL PARA ALTO FLUJO TIPO GGM ADULTO 6mm 4826R1V TAMAÑO L | H20: NO | I20: ='Necesidades Trimestrales'!F18 -> UNIDAD | J20: ='Necesidades Trimestrales'!H18 -> 4200 | K20: ='Necesidades Trimestrales'!G18 -> 30
A21: 10 | B21: ='Necesidades Trimestrales'!B19 -> 0 | C21: ='Necesidades Trimestrales'!E19 -> CANULA NASAL PARA OXIGENOTERAPIA ADULTO | H21: NO | I21: ='Necesidades Trimestrales'!F19 -> UNIDAD | J21: ='Necesidades Trimestrales'!H19 -> 109.8 | K21: ='Necesidades Trimestrales'!G19 -> 7000
A22: 11 | B22: ='Necesidades Trimestrales'!B20 -> 0 | C22: ='Necesidades Trimestrales'!E20 -> CANULA PARA TRAQUEOSTOMIA Nº 7 1/2 | H22: NO | I22: ='Necesidades Trimestrales'!F20 -> UNIDAD | J22: ='Necesidades Trimestrales'!H20 -> 589.4 | K22: ='Necesidades Trimestrales'!G20 -> 80
A23: 12 | B23: ='Necesidades Trimestrales'!B21 -> 0 | C23: ='Necesidades Trimestrales'!E21 -> CANULA PARA TRAQUEOSTOMIA Nº 8 | H23: NO | I23: ='Necesidades Trimestrales'!F21 -> UNIDAD | J23: ='Necesidades Trimestrales'!H21 -> 589.4 | K23: ='Necesidades Trimestrales'!G21 -> 100
A24: 13 | B24: ='Necesidades Trimestrales'!B22 -> 0 | C24: ='Necesidades Trimestrales'!E22 -> CANULA PARA TRAQUEOTOMIA N° 9 | H24: NO | I24: ='Necesidades Trimestrales'!F22 -> UNIDAD | J24: ='Necesidades Trimestrales'!H22 -> 589.4 | K24: ='Necesidades Trimestrales'!G22 -> 40
A25: 14 | B25: ='Necesidades Trimestrales'!B23 -> 0 | C25: ='Necesidades Trimestrales'!E23 -> CIRCUITO ANESTESIA EXTENSIBLE ADULTO AUTOCLAVABLE | H25: NO | I25: ='Necesidades Trimestrales'!F23 -> UNIDAD | J25: ='Necesidades Trimestrales'!H23 -> 1950 | K25: ='Necesidades Trimestrales'!G23 -> 60
A26: 15 | B26: ='Necesidades Trimestrales'!B24 -> 0 | C26: ='Necesidades Trimestrales'!E24 -> CIRCUITO ANESTESIA EXTENSIBLE ADULTO DESCARTABLE | H26: NO | I26: ='Necesidades Trimestrales'!F24 -> UNIDAD | J26: ='Necesidades Trimestrales'!H24 -> 510 | K26: ='Necesidades Trimestrales'!G24 -> 600
... A35: 24 | B35: ='Necesidades Trimestrales'!B33 -> 0 | C35: ='Necesidades Trimestrales'!E33 -> FILTRO HME BACTERIAL VIRAL PARA CIRCUITO RESPIRADOR | H35: NO | I35: ='Necesidades Trimestrales'!F33 -> UNIDAD | J35: ='Necesidades Trimestrales'!H33 -> 160 | K35: ='Necesidades Trimestrales'!G33 -> 500
A36: 25 | C36: ='Necesidades Trimestrales'!E34 -> GUANTES DE CIRUGIA ESTERIL N° 6 1/2 PAR ANATOMICOS. CAÑA LARGA SIN TALCO | H36: NO | I36: ='Necesidades Trimestrales'!F34 -> UNIDAD | J36: ='Necesidades Trimestrales'!H34 -> 31 | K36: ='Necesidades Trimestrales'!G34 -> 4500
A37: 26 | B37: ='Necesidades Trimestrales'!B35 -> 0 | C37: ='Necesidades Trimestrales'!E35 -> GUANTES DE CIRUGIA ESTERIL N° 7 1/2 PAR NITRILO CAÑA LARGA | H37: NO | I37: ='Necesidades Trimestrales'!F35 -> UNIDAD | J37: ='Necesidades Trimestrales'!H35 -> 31 | K37: ='Necesidades Trimestrales'!G35 -> 600
A38: 27 | B38: ='Necesidades Trimestrales'!B36 -> 0 | C38: ='Necesidades Trimestrales'!E36 -> GUANTES DE CIRUGIA ESTERIL Nº 7 PAR. ANATOMICOS . CAÑA LARGA SIN TALCO | H38: NO | I38: ='Necesidades Trimestrales'!F36 -> UNIDAD | J38: ='Necesidades Trimestrales'!H36 -> 31 | K38: ='Necesidades Trimestrales'!G36 -> 9000
A39: 28 | B39: ='Necesidades Trimestrales'!B37 -> 0 | C39: ='Necesidades Trimestrales'!E37 -> GUANTES DE CIRUGIA ESTERIL Nº 7 1/2 PAR. ANATOMICOS . CAÑA LARGA SIN TALCO | H39: NO | I39: ='Necesidades Trimestrales'!F37 -> UNIDAD | J39: ='Necesidades Trimestrales'!H37 -> 31 | K39: ='Necesidades Trimestrales'!G37 -> 9000
A40: 29 | B40: ='Necesidades Trimestrales'!B38 -> 0 | C40: ='Necesidades Trimestrales'!E38 -> GUANTES DE CIRUGIA ESTERIL Nº 8 PAR. ANATOMICOS . CAÑA LARGA SIN TALCO | H40: NO | I40: ='Necesidades Trimestrales'!F38 -> UNIDAD | J40: ='Necesidades Trimestrales'!H38 -> 31 | K40: ='Necesidades Trimestrales'!G38 -> 9000
A41: 30 | B41: ='Necesidades Trimestrales'!B39 -> 0 | C41: ='Necesidades Trimestrales'!E39 -> GUANTES DE CIRUGIA ESTERIL Nº 81/2 PAR. ANATOMICOS . CAÑA LARGA SIN TALCO | H41: NO | I41: ='Necesidades Trimestrales'!F39 -> UNIDAD | J41: ='Necesidades Trimestrales'!H39 -> 31 | K41: ='Necesidades Trimestrales'!G39 -> 6000
A42: 31 | B42: ='Necesidades Trimestrales'!B40 -> 0 | C42: ='Necesidades Trimestrales'!E40 -> GUANTES DE EXAMINACION TAMAÑO L X 100 | H42: NO | I42: ='Necesidades Trimestrales'!F40 -> UNIDAD | J42: ='Necesidades Trimestrales'!H40 -> 990 | K42: ='Necesidades Trimestrales'!G40 -> 1500
A43: 32 | B43: ='Necesidades Trimestrales'!B41 -> 0 | C43: ='Necesidades Trimestrales'!E41 -> GUANTES DE EXAMINACION TAMAÑO M X 100 | H43: NO | I43: ='Necesidades Trimestrales'!F41 -> UNIDAD | J43: ='Necesidades Trimestrales'!H41 -> 990 | K43: ='Necesidades Trimestrales'!G41 -> 2500
A44: 33 | B44: ='Necesidades Trimestrales'!B42 -> 0 | C44: ='Necesidades Trimestrales'!E42 -> GUANTES DE EXAMINACON TAMAÑO S X 100 | H44: NO | I44: ='Necesidades Trimestrales'!F42 -> UNIDAD | J44: ='Necesidades Trimestrales'!H42 -> 990 | K44: ='Necesidades Trimestrales'!G42 -> 2500
A45: 34 | B45: ='Necesidades Trimestrales'!B43 -> 0 | C45: ='Necesidades Trimestrales'!E43 -> KIT DESCARTABLE CAMISOLIN 50 GRS + COFIA + BOTAS PAR | H45: NO | I45: ='Necesidades Trimestrales'!F43 -> UNIDAD | J45: ='Necesidades Trimestrales'!H43 -> 230 | K45: ='Necesidades Trimestrales'!G43 -> 150000
A46: 35 | B46: ='Necesidades Trimestrales'!B44 -> 0 | C46: ='Necesidades Trimestrales'!E44 -> LLAVE DE TRES VIAS | H46: NO | I46: ='Necesidades Trimestrales'!F44 -> UNIDAD | J46: ='Necesidades Trimestrales'!H44 -> 24.55 | K46: ='Necesidades Trimestrales'!G44 -> 4200
A47: 36 | B47: ='Necesidades Trimestrales'!B45 -> 0 | C47: ='Necesidades Trimestrales'!E45 -> MAMELUCO LAMINADO TALLE L | H47: NO | I47: ='Necesidades Trimestrales'!F45 -> UNIDAD | J47: ='Necesidades Trimestrales'!H45 -> 1050 | K47: ='Necesidades Trimestrales'!G45 -> 600
A48: 37 | B48: ='Necesidades Trimestrales'!B46 -> 0 | C48: ='Necesidades Trimestrales'!E46 -> MAMELUCO LAMINADO TALLE M | H48: NO | I48: ='Necesidades Trimestrales'!F46 -> UNIDAD | J48: ='Necesidades Trimestrales'!H46 -> 1050 | K48: ='Necesidades Trimestrales'!G46 -> 600
... A64: 53 | B64: ='Necesidades Trimestrales'!B62 -> 0 | C64: ='Necesidades Trimestrales'!E62 -> TUBO ENDOTRAQUEAL CON BALON Nº 81/2 | H64: NO | I64: ='Necesidades Trimestrales'!F62 -> UNIDAD | J64: ='Necesidades Trimestrales'!H62 -> 115 | K64: ='Necesidades Trimestrales'!G62 -> 200
A65: 54 | B65: ='Necesidades Trimestrales'!B63 -> 0 | C65: ='Necesidades Trimestrales'!E63 -> TUBO MAYO GUEDEL N°5 | H65: NO | I65: UNIDAD | J65: ='Necesidades Trimestrales'!H63 -> 58 | K65: ='Necesidades Trimestrales'!G63 -> 15
A66: 55 | B66: ='Necesidades Trimestrales'!B64 -> 0 | C66: ='Necesidades Trimestrales'!E64 -> TUBO MAYO GUEDEL N°3 | H66: NO | I66: ='Necesidades Trimestrales'!F64 -> UNIDAD | J66: ='Necesidades Trimestrales'!H64 -> 58 | K66: ='Necesidades Trimestrales'!G64 -> 25
...

Sheet Autor Gastar
A1: EJERCICIO: | D1: ='Necesidades Trimestrales'!C6 -> 2021 | P1: AUTORIZACION PARA GASTAR
A4: JURISDICCIÓN: | G4: =NotaPedido!D3 -> 40 - Ministerio de Salud
A5: SAF: | G5: =NotaPedido!D4 -> 23 - Hospital Interzonal San Juan Bautista
A6: UNIDAD EJECUTORA: | G6: =NotaPedido!D5 -> 168 - Direccion Asistencial
A7: DEPENDENCIA SOLICITANTE: | G7: =NotaPedido!D6 -> Servicio de Farmacia
A8: AUTORIZACIÓN:
A9: Señor Jefe de Servicio Administrativo Financiero:
A10: ="Autorizo la realización de los trámites correspondientes, a fin de proveer a este Organismo los bienes y/o servicios que se detallan en Nota de Pedido N° " & NotaPedido!K1&", afectando la erogación resultante a los créditos presupuestarios aprobados a favor de esta Unidad Ejecutora, conforme al siguiente detalle:" -> Autorizo la realización de los trámites correspondientes, a fin de proveer a este Organismo los bienes y/o servicios que se detallan en Nota de Pedido N° 050 - 2021, afectando la erogación resultante a los créditos presupuestarios aprobados a favor de esta Unidad Ejecutora, conforme al siguiente detalle:
A12: IMPUTACIÓN PRESUPUESTARIA
A13: CÓDIGO | O13: DENOMINACIÓN DE LA PARTIDA PRESUPUESTARIA | Q13: IMPORTE
A14: PR | B14: SB | C14: PY | D14: AC | E14: OB | F14: UG | G14: FIN | H14: FUN | I14: I | J14: P | K14: P | L14: SubP | M14: M | N14: FF
A15: 33 | D15: 2 | F15: 4901 | G15: 3 | H15: 3.1 | I15: 2 | J15: 9 | K15: 5 | M15: 1 | N15: 1.1 | O15: Utiles Menores Med. Quir. y de Lab. | Q15: ='Necesidades Trimestrales'!K11 -> 107898248
A16: 33 | D16: 2 | F16: 4901 | G16: 3 | H16: 3.1 | I16: 2 | J16: 5 | K16: 1 | M16: 1 | N16: 1.1 | O16: Compuestos Quimicos | Q16: ='Necesidades Trimestrales'!K10 -> 2113083.4
A23: TOTAL DE PESOS: Ciento diez millones once mil trescientos treinta y uno con 36/100.- | Q23: =SUM(Q15:Q22) -> 1.1001133e+08
A25: JUSTIFICACIÓN:
A26: ="Para la "& NotaPedido!D8 &" para ser destinados al " & NotaPedido!D6 &" del HISJB del Ministerio de Salud." -> Para la Adquisición de Descartables COVID para Farmacia para ser destinados al Servicio de Farmacia del HISJB del Ministerio de Salud.
