Workbook

Sheet SAF 011
A1: 2021
B2: Pedido de Necesidades Trimestrales
A4: JURISDICCION: | C4: 040 - MINISTERIO DE SALUD
A5: SAF N°: | C5: 011 - DIRECCION PROVINCIAL DE ADMINISTRACION - MINISTERIO DE SALUD
A6: EJERCICIO: | C6: 2021
A7: TRIMESTRE: | C7: CUARTO
A9: ID | B9: CODIGO ITEM | C9: RUBRO DE COMPRA | D9: I.P.P. | E9: DESCRIPCION | F9: UNIDAD DE MEDIDA | G9: SECRETARIA DE ADMINISTRACION | H9: TOTAL S.A. | I9: SMPyPS | J9: TOTAL SMPyPS | K9: DIR. LAB. CENTRAL | L9: TOTAL DE LAB CENTRAL | M9: BCO DE SANGRE | N9: TOTAL BANCO DE SANGRE | O9: APS | P9: TOTAL A.P.S. | Q9: DIR DE CANCER | R9: TOTAL DE DIR DE CANCER | S9: FARMACIA | T9: TOTAL FARMACIA | U9: ODONTOLOGIA | V9: TOTAL DE ODONTOLOG | W9: SAME | X9: TOTAL DE SAME | Y9: HPTAL MALBRAN | Z9: TOTAL HPTAL MALBRAN | AA9: MATERNIDAD E INFANCIA | AB9: TOTAL MATERNIDAD E INFANCIA | AC9: SASP | AD9: TOTAL SASP | AE9: SALUD Y MEDIO AMBIENTE | AF9: TOTAL SALUD Y MEDIO AMBIENTE | AG9: VECTORES Y ZOONOSIS | AH9: TOTAL DE VECT Y ZOON | AI9: SUMAR | AJ9: TOTAL SUMAR | AK9: CUR | AL9: TOTAL CUR | AM9: SPyGS | AN9: TOTAL SPyGS | AO9: SALUD MENTAL | AP9: TOTAL SALUD MENTAL | AQ9: AREAS Y DPAS | AR9: TOTAL DPAS | AS9: CANTIDAD TOTAL | AT9: PRECIO UNITARIO ESTIMADO | AU9: IMPORTE TOTAL ESTIMADO | AV9: ESPECIFICACION TECNICA
A10: 1 | C10: PROD. MEDICO/FARMACEUTICOS/LAB. | D10: 295 | E10: AMPOULE ADAPTER X 150 pcs TIPO ROCHE | F10: CAJA | K10: 2 | L10: =+K10*AT10 -> 11378 | AS10: 2 | AT10: 5689 | AU10: =+AS10*AT10 -> 11378
A11: 2 | C11: PROD. MEDICO/FARMACEUTICOS/LAB. | D11: 295 | E11: APOSITOS; TIPO: POST EXTRACCION SANGUINEA, hipoalergenica TAMAÑO: 40 X 40 mm X 100 | F11: CAJA | M11: 50 | N11: =+M11*AT11 -> 35100 | AS11: =+AQ11+AO11+AM11+AK11+AI11+AG11+AE11+AC11+AA11+Y11+W11+U11+S11+Q11+O11+M11+K11+I11 -> 50 | AT11: 702 | AU11: =+AS11*AT11 -> 35100
A12: 3 | C12: PROD. MEDICO/FARMACEUTICOS/LAB. | D12: 295 | E12: BOLSAS DE SANGRE TRIPLE KS TIPO GRIFOLS PARA EL EQUIPAMIENTO DE AFERESIS GRIFOLS | F12: UNIDAD | M12: 1700 | N12: =+M12*AT12 -> 1861500 | AS12: =+AQ12+AO12+AM12+AK12+AI12+AG12+AE12+AC12+AA12+Y12+W12+U12+S12+Q12+O12+M12+K12+I12 -> 1700 | AT12: 1095 | AU12: =+AS12*AT12 -> 1861500
A13: 4 | C13: PROD. MEDICO/FARMACEUTICOS/LAB. | D13: 295 | E13: CEPILLO LIMPIA PIPETA DE CERDA NATURAL DE 10 MM | F13: UNIDAD | M13: 10 | N13: =+M13*AT13 -> 1250 | AS13: =+AQ13+AO13+AM13+AK13+AI13+AG13+AE13+AC13+AA13+Y13+W13+U13+S13+Q13+O13+M13+K13+I13 -> 10 | AT13: 125 | AU13: =+AS13*AT13 -> 1250
A14: 5 | C14: PROD. MEDICO/FARMACEUTICOS/LAB. | D14: 295 | E14: CEPILLO LIMPIA TUBOS DE HEMOLISIS TAMAÑO UNIVERSAL | F14: UNIDAD | K14: 100 | L14: =+K14*AT14 -> 25000 | AS14: =+AQ14+AO14+AM14+AK14+AI14+AG14+AE14+AC14+AA14+Y14+W14+U14+S14+Q14+O14+M14+K14+I14 -> 100 | AT14: 250 | AU14: =+AS14*AT14 -> 25000
A15: 6 | C15: PROD. MEDICO/FARMACEUTICOS/LAB. | D15: 295 | E15: CLOT CATCHER X 250 UNIDADES TIPO ROCHE | F15: CAJA | K15: 20 | L15: =+K15*AT15 -> 31800 | AS15: =+AQ15+AO15+AM15+AK15+AI15+AG15+AE15+AC15+AA15+Y15+W15+U15+S15+Q15+O15+M15+K15+I15 -> 20 | AT15: 1590 | AU15: =+AS15*AT15 -> 31800
A16: 7 | C16: PROD. MEDICO/FARMACEUTICOS/LAB. | D16: 295 | E16: Criotubo Expell 5 ml Pre-esterilizados, graduado - Bolsa x 100 un Tipo CAPP (Dinamarca) | F16: BOLSA | K16: 10 | L16: =+K16*AT16 -> 41800 | AS16: =+AQ16+AO16+AM16+AK16+AI16+AG16+AE16+AC16+AA16+Y16+W16+U16+S16+Q16+O16+M16+K16+I16 -> 10 | AT16: 4180 | AU16: =+AS16*AT16 -> 41800
A17: 8 | C17: PROD. MEDICO/FARMACEUTICOS/LAB. | D17: 295 | E17: CUBREOBJETOS HDA 20x20 MM x 200 U Tipo KINDER | F17: CAJA | K17: 100 | L17: =+K17*AT17 -> 24000 | AS17: =+AQ17+AO17+AM17+AK17+AI17+AG17+AE17+AC17+AA17+Y17+W17+U17+S17+Q17+O17+M17+K17+I17 -> 100 | AT17: 240 | AU17: =+AS17*AT17 -> 24000
A18: 9 | C18: PROD. MEDICO/FARMACEUTICOS/LAB | D18: 295 | E18: DESCARTADOR PARA AGUJA P/500 AGUJAS, MODELO E-500 | F18: UNIDAD | M18: 200 | N18: =+M18*AT18 -> 39000 | AS18: =+AQ18+AO18+AM18+AK18+AI18+AG18+AE18+AC18+AA18+Y18+W18+U18+S18+Q18+O18+M18+K18+I18 -> 200 | AT18: 195 | AU18: =+AS18*AT18 -> 39000
A19: 10 | C19: PROD. MEDICO/FARMACEUTICOS/LAB. | D19: 295 | E19: ELECTRODO DE CALCIO COBAS B221 TIPO ROCHE | F19: UNIDAD | K19: 1 | L19: =+K19*AT19 -> 11629.98 | AS19: =+AQ19+AO19+AM19+AK19+AI19+AG19+AE19+AC19+AA19+Y19+W19+U19+S19+Q19+O19+M19+K19+I19 -> 1 | AT19: 11629.98 | AU19: =+AS19*AT19 -> 11629.98
A20: 11 | C20: PROD. MEDICO/FARMACEUTICOS/LAB. | D20: 295 | E20: EPENDORF 0,5 ML BOLSA POR 200 UNIDADES CALIDAD BIOLOGIA MOLECULAR | F20: BOLSA | K20: 1 | L20: =+K20*AT20 -> 4100 | AS20: =+AQ20+AO20+AM20+AK20+AI20+AG20+AE20+AC20+AA20+Y20+W20+U20+S20+Q20+O20+M20+K20+I20 -> 1 | AT20: 4100 | AU20: =+AS20*AT20 -> 4100
A21: 12 | C21: PROD. MEDICO/FARMACEUTICOS/LAB. | D21: 295 | E21: Ependorf 0,5 ml esteriles libres de ADNasa y RNAsa Bolsa x 500 tipo DELTALAB | F21: BOLSA | K21: 5 | L21: =+K21*AT21 -> 24000 | AS21: =+AQ21+AO21+AM21+AK21+AI21+AG21+AE21+AC21+AA21+Y21+W21+U21+S21+Q21+O21+M21+K21+I21 -> 5 | AT21: 4800 | AU21: =+AS21*AT21 -> 24000
A22: 13 | C22: PROD. MEDICO/FARMACEUTICOS/LAB. | D22: 295 | E22: Ependorf 2 ml esteriles libres de ADNasa y RNAsa Bolsa x 500 tipo DELTALAB | F22: BOLSA | K22: 20 | L22: =+K22*AT22 -> 107200 | AS22: =+AQ22+AO22+AM22+AK22+AI22+AG22+AE22+AC22+AA22+Y22+W22+U22+S22+Q22+O22+M22+K22+I22 -> 20 | AT22: 5360 | AU22: =+AS22*AT22 -> 107200
A23: 14 | C23: PROD. MEDICO/FARMACEUTICOS/LAB. | D23: 234 | E23: ETIQUETAS PARA IMPRESORA ZEBRA x 12 ROLLOS DE 1800 ETIQUETAS C/U | F23: CAJA | K23: 3 | L23: =+K23*AT23 -> 47400 | AS23: =+AQ23+AO23+AM23+AK23+AI23+AG23+AE23+AC23+AA23+Y23+W23+U23+S23+Q23+O23+M23+K23+I23 -> 3 | AT23: 15800 | AU23: =+AS23*AT23 -> 47400
A24: 15 | C24: PROD. MEDICO/FARMACEUTICOS/LAB. | D24: 295 | E24: FILTRO DE RESINA R15 PARA COBAS 311 ROCHE | F24: UNIDAD | K24: 2 | L24: =+K24*AT24 -> 23780 | AS24: =+AQ24+AO24+AM24+AK24+AI24+AG24+AE24+AC24+AA24+Y24+W24+U24+S24+Q24+O24+M24+K24+I24 -> 2 | AT24: 11890 | AU24: =+AS24*AT24 -> 23780
A25: 16 | C25: PROD. MEDICO/FARMACEUTICOS/LAB. | D25: 295 | E25: Frasco de Bioseguridad Triple envase Tipo SISTEG M6 | F25: UNIDAD | K25: 50 | L25: =+K25*AT25 -> 240000 | AS25: =+AQ25+AO25+AM25+AK25+AI25+AG25+AE25+AC25+AA25+Y25+W25+U25+S25+Q25+O25+M25+K25+I25 -> 50 | AT25: 4800 | AU25: =+AS25*AT25 -> 240000
A26: 17 | C26: PROD. MEDICO/FARMACEUTICOS/LAB. | D26: 295 | E26: Gradilla alambre / plastico 24 Tubos 30 MM Tipo ARGA | F26: UNIDAD | K26: 20 | L26: =+K26*AT26 -> 22000 | AS26: =+AQ26+AO26+AM26+AK26+AI26+AG26+AE26+AC26+AA26+Y26+W26+U26+S26+Q26+O26+M26+K26+I26 -> 20 | AT26: 1100 | AU26: =+AS26*AT26 -> 22000
A27: 18 | C27: PROD. MEDICO/FARMACEUTICOS/LAB. | D27: 295 | E27: Gradilla alambre / plastico 48 Tubos 30 MM Tipo ARGA | F27: UNIDAD | K27: 20 | L27: =+K27*AT27 -> 36000 | AS27: =+AQ27+AO27+AM27+AK27+AI27+AG27+AE27+AC27+AA27+Y27+W27+U27+S27+Q27+O27+M27+K27+I27 -> 20 | AT27: 1800 | AU27: =+AS27*AT27 -> 36000
A28: 19 | C28: PROD. MEDICO/FARMACEUTICOS/LAB. | D28: 295 | E28: Gradilla PP resistente 80ºC 80 Tubos Eppendorf Tipo DELTALAB | F28: UNIDAD | K28: 20 | L28: =+K28*AT28 -> 16000 | AS28: =+AQ28+AO28+AM28+AK28+AI28+AG28+AE28+AC28+AA28+Y28+W28+U28+S28+Q28+O28+M28+K28+I28 -> 20 | AT28: 800 | AU28: =+AS28*AT28 -> 16000
A29: 20 | C29: PROD. MEDICO/FARMACEUTICOS/LAB | D29: 295 | E29: GUIA V20 C/RUEDITA *SANGRE* | F29: UNIDAD | M29: 600 | N29: =+M29*AT29 -> 55200 | AS29: =+AQ29+AO29+AM29+AK29+AI29+AG29+AE29+AC29+AA29+Y29+W29+U29+S29+Q29+O29+M29+K29+I29 -> 600 | AT29: 92 | AU29: =+AS29*AT29 -> 55200
A30: 21 | C30: PROD. MEDICO/FARMACEUTICOS/LAB. | D30: 295 | E30: HISOPOS NASOFARINGEOS DE DACRON O NYLON | F30: UNIDAD | K30: 23100 | L30: =+K30*AT30 -> 1362900 | AS30: =+AQ30+AO30+AM30+AK30+AI30+AG30+AE30+AC30+AA30+Y30+W30+U30+S30+Q30+O30+M30+K30+I30 -> 23100 | AT30: 59 | AU30: =+AS30*AT30 -> 1362900
A31: 22 | C31: PROD. MEDICO/FARMACEUTICOS/LAB. | D31: 295 | E31: JERINGAS HEPARINIZADAS X 3 ML X100 UNIDADES | F31: CAJA | K31: 19 | L31: =+K31*AT31 -> 164730 | AS31: =+AQ31+AO31+AM31+AK31+AI31+AG31+AE31+AC31+AA31+Y31+W31+U31+S31+Q31+O31+M31+K31+I31 -> 19 | AT31: 8670 | AU31: =+AS31*AT31 -> 164730
A32: 23 | C32: PROD. MEDICO/FARMACEUTICOS/LAB. | D32: 293 | E32: LAMPARA COBAS C311 TIPO ROCHE | F32: UNIDAD | K32: 2 | L32: =+K32*AT32 -> 117200 | AS32: =+AQ32+AO32+AM32+AK32+AI32+AG32+AE32+AC32+AA32+Y32+W32+U32+S32+Q32+O32+M32+K32+I32 -> 2 | AT32: 58600 | AU32: =+AS32*AT32 -> 117200
A33: 24 | C33: PROD. MEDICO/FARMACEUTICOS/LAB. | D33: 295 | E33: MICROHEMATOCRITO CON HEPARINA X100 | F33: CAJA | K33: 100 | L33: =+K33*AT33 -> 89200 | AS33: =+AQ33+AO33+AM33+AK33+AI33+AG33+AE33+AC33+AA33+Y33+W33+U33+S33+Q33+O33+M33+K33+I33 -> 100 | AT33: 892 | AU33: =+AS33*AT33 -> 89200
A34: 25 | C34: PROD. MEDICO/FARMACEUTICOS/LAB. | D34: 295 | E34: MICROHEMATOCRITO SIN HEPARINA X100 | F34: CAJA | K34: 50 | L34: =+K34*AT34 -> 34150 | AS34: =+AQ34+AO34+AM34+AK34+AI34+AG34+AE34+AC34+AA34+Y34+W34+U34+S34+Q34+O34+M34+K34+I34 -> 50 | AT34: 683 | AU34: =+AS34*AT34 -> 34150
A35: 26 | C35: PROD. MEDICO/FARMACEUTICOS/LAB | D35: 295 | E35: MICROPIPETAS REGULABLES; CAPACIDAD: 100 - 1000 µL, DIVISIONES: CADA 5 µL, MATERIAL: PLASTICO | F35: UNIDAD | M35: 2 | N35: =+M35*AT35 -> 104700 | AS35: =+AQ35+AO35+AM35+AK35+AI35+AG35+AE35+AC35+AA35+Y35+W35+U35+S35+Q35+O35+M35+K35+I35 -> 2 | AT35: 52350 | AU35: =+AS35*AT35 -> 104700
A36: 27 | C36: PROD. MEDICO/FARMACEUTICOS/LAB | D36: 295 | E36: MICROPIPETAS REGULABLES; CAPACIDAD: 10-100 µL, DIVISIONES: CADA 1 µL, MATERIAL: PLASTICO | F36: UNIDAD | M36: 2 | N36: =+M36*AT36 -> 100700 | AS36: =+AQ36+AO36+AM36+AK36+AI36+AG36+AE36+AC36+AA36+Y36+W36+U36+S36+Q36+O36+M36+K36+I36 -> 2 | AT36: 50350 | AU36: =+AS36*AT36 -> 100700
A37: 28 | C37: PROD. MEDICO/FARMACEUTICOS/LAB. | D37: 295 | E37: PIPETA AUTOMATICA TIPO SOCOREX VOL REGULABLE DE 5-50 ul | F37: UNIDAD | K37: 8 | L37: =+K37*AT37 -> 751912 | AS37: =+AQ37+AO37+AM37+AK37+AI37+AG37+AE37+AC37+AA37+Y37+W37+U37+S37+Q37+O37+M37+K37+I37 -> 8 | AT37: 93989 | AU37: =+AS37*AT37 -> 751912
A38: 29 | C38: PROD. MEDICO/FARMACEUTICOS/LAB. | D38: 295 | E38: PIPETA AUTOMATICA TIPO SOCOREX VOL REGULABLE DE 10-100 ul | F38: UNIDAD | K38: 14 | L38: =+K38*AT38 -> 1166178 | AS38: =+AQ38+AO38+AM38+AK38+AI38+AG38+AE38+AC38+AA38+Y38+W38+U38+S38+Q38+O38+M38+K38+I38 -> 14 | AT38: 83298.43 | AU38: =+AS38*AT38 -> 1166178
A39: 30 | C39: PROD. MEDICO/FARMACEUTICOS/LAB. | D39: 295 | E39: PIPETA AUTOMATICA TIPO SOCOREX VOL REGULABLE DE 20-200 ul | F39: UNIDAD | K39: 9 | L39: =+K39*AT39 -> 798255 | AS39: =+AQ39+AO39+AM39+AK39+AI39+AG39+AE39+AC39+AA39+Y39+W39+U39+S39+Q39+O39+M39+K39+I39 -> 9 | AT39: 88695 | AU39: =+AS39*AT39 -> 798255
A40: 31 | C40: PROD. MEDICO/FARMACEUTICOS/LAB. | D40: 295 | E40: Placa de PCR Expell de 96 pocillos x 0,1 ml, sin pollera Calidad Biologia Molecular Libre de DNAasa y RNAasa, Capp x 25 Unidades | F40: CAJA | K40: 20 | L40: =+K40*AT40 -> 180000 | AS40: =+AQ40+AO40+AM40+AK40+AI40+AG40+AE40+AC40+AA40+Y40+W40+U40+S40+Q40+O40+M40+K40+I40 -> 20 | AT40: 9000 | AU40: =+AS40*AT40 -> 180000
A41: 32 | C41: PROD. MEDICO/FARMACEUTICOS/LAB. | D41: 295 | E41: PLACA DE VIDRIO PARA VDRL X 12 POCILLOS | F41: UNIDAD | K41: 10 | L41: =+K41*AT41 -> 21000 | AS41: =+AQ41+AO41+AM41+AK41+AI41+AG41+AE41+AC41+AA41+Y41+W41+U41+S41+Q41+O41+M41+K41+I41 -> 10 | AT41: 2100 | AU41: =+AS41*AT41 -> 21000
A42: 33 | C42: PROD. MEDICO/FARMACEUTICOS/LAB | D42: 295 | E42: PLACA PARA VDRL CON POCILLO PROFUNDO 12HOYOS | F42: UNIDAD | M42: 5 | N42: =+M42*AT42 -> 6100 | AS42: =+AQ42+AO42+AM42+AK42+AI42+AG42+AE42+AC42+AA42+Y42+W42+U42+S42+Q42+O42+M42+K42+I42 -> 5 | AT42: 1220 | AU42: =+AS42*AT42 -> 6100
...

Sheet NP LABORATORIO
A1: NOTA DE PEDIDO | J1: N° | K1: 19/2021
A3: JURISDICCIÓN: | D3: 040 - MINISTERIO DE SALUD
A4: SAF: | D4: 011 - DIRECCION PROVINCIAL DE ADMINISTRACION DEL MINISTERIO DE SALUD
A5: UNIDAD EJECUTORA: | D5: 468 - DIRECCION PROVINCIAL DE LABORATORIO
A6: DEPENDENCIA SOLICITANTE: | D6: 468 - DIRECCION PROVINCIAL DE LABORATORIO
A7: PERIODO UTILIZACIÓN: | D7: 4TO TRIMESTRE 2021
A8: OBJETO: | D8: ADQ. DEL RUBRO DESCARTABLES PARA LABORATORIO
A10: Ítem | B10: Codigo Item | C10: DESCRIPCIÓN | H10: Adjunta Detalle Técnico | I10: Unidad Medida | J10: Precio Unitario Estimado | K10: Cantidad Solicitada
A12: 1 | C12: ='SAF 011'!E10 -> AMPOULE ADAPTER X 150 pcs TIPO ROCHE | H12: NO | I12: ='SAF 011'!F10 -> CAJA | J12: ='SAF 011'!AT10 -> 5689 | K12: ='SAF 011'!K10 -> 2 | M12: =+J12*K12 -> 11378
A13: 2 | C13: ='SAF 011'!E14 -> CEPILLO LIMPIA TUBOS DE HEMOLISIS TAMAÑO UNIVERSAL | H13: NO | I13: ='SAF 011'!F14 -> UNIDAD | J13: ='SAF 011'!AT14 -> 250 | K13: ='SAF 011'!K14 -> 100 | M13: =+J13*K13 -> 25000
A14: 3 | C14: ='SAF 011'!E15 -> CLOT CATCHER X 250 UNIDADES TIPO ROCHE | H14: NO | I14: ='SAF 011'!F15 -> CAJA | J14: ='SAF 011'!AT15 -> 1590 | K14: ='SAF 011'!K15 -> 20 | M14: =+J14*K14 -> 31800
A15: 4 | C15: ='SAF 011'!E16 -> Criotubo Expell 5 ml Pre-esterilizados, graduado - Bolsa x 100 un Tipo CAPP (Dinamarca) | H15: NO | I15: ='SAF 011'!F16 -> BOLSA | J15: ='SAF 011'!AT16 -> 4180 | K15: ='SAF 011'!K16 -> 10 | M15: =+J15*K15 -> 41800
A16: 5 | C16: ='SAF 011'!E17 -> CUBREOBJETOS HDA 20x20 MM x 200 U Tipo KINDER | H16: NO | I16: ='SAF 011'!F17 -> CAJA | J16: ='SAF 011'!AT17 -> 240 | K16: ='SAF 011'!K17 -> 100 | M16: =+J16*K16 -> 24000
A17: 6 | C17: ='SAF 011'!E19 -> ELECTRODO DE CALCIO COBAS B221 TIPO ROCHE | H17: NO | I17: ='SAF 011'!F19 -> UNIDAD | J17: ='SAF 011'!AT19 -> 11629.98 | K17: ='SAF 011'!K19 -> 1 | M17: =+J17*K17 -> 11629.98
A18: 7 | C18: ='SAF 011'!E20 -> EPENDORF 0,5 ML BOLSA POR 200 UNIDADES CALIDAD BIOLOGIA MOLECULAR | H18: NO | I18: ='SAF 011'!F20 -> BOLSA | J18: ='SAF 011'!AT20 -> 4100 | K18: ='SAF 011'!K20 -> 1 | M18: =+J18*K18 -> 4100
A19: 8 | C19: ='SAF 011'!E21 -> Ependorf 0,5 ml esteriles libres de ADNasa y RNAsa Bolsa x 500 tipo DELTALAB | H19: NO | I19: ='SAF 011'!F21 -> BOLSA | J19: ='SAF 011'!AT21 -> 4800 | K19: ='SAF 011'!K21 -> 5 | M19: =+J19*K19 -> 24000
A20: 9 | C20: ='SAF 011'!E22 -> Ependorf 2 ml esteriles libres de ADNasa y RNAsa Bolsa x 500 tipo DELTALAB | H20: NO | I20: ='SAF 011'!F22 -> BOLSA | J20: ='SAF 011'!AT22 -> 5360 | K20: ='SAF 011'!K22 -> 20 | M20: =+J20*K20 -> 107200
A21: 10 | C21: ='SAF 011'!E23 -> ETIQUETAS PARA IMPRESORA ZEBRA x 12 ROLLOS DE 1800 ETIQUETAS C/U | H21: NO | I21: ='SAF 011'!F23 -> CAJA | J21: ='SAF 011'!AT23 -> 15800 | K21: ='SAF 011'!K23 -> 3 | M21: =+J21*K21 -> 47400
A22: 11 | C22: ='SAF 011'!E24 -> FILTRO DE RESINA R15 PARA COBAS 311 ROCHE | H22: NO | I22: ='SAF 011'!F24 -> UNIDAD | J22: ='SAF 011'!AT24 -> 11890 | K22: ='SAF 011'!K24 -> 2 | M22: =+J22*K22 -> 23780
A23: 12 | C23: ='SAF 011'!E25 -> Frasco de Bioseguridad Triple envase Tipo SISTEG M6 | H23: NO | I23: ='SAF 011'!F25 -> UNIDAD | J23: ='SAF 011'!AT25 -> 4800 | K23: ='SAF 011'!K25 -> 50 | M23: =+J23*K23 -> 240000
A24: 13 | C24: ='SAF 011'!E26 -> Gradilla alambre / plastico 24 Tubos 30 MM Tipo ARGA | H24: NO | I24: ='SAF 011'!F26 -> UNIDAD | J24: ='SAF 011'!AT26 -> 1100 | K24: ='SAF 011'!K26 -> 20 | M24: =+J24*K24 -> 22000
A25: 14 | C25: ='SAF 011'!E27 -> Gradilla alambre / plastico 48 Tubos 30 MM Tipo ARGA | H25: NO | I25: ='SAF 011'!F27 -> UNIDAD | J25: ='SAF 011'!AT27 -> 1800 | K25: ='SAF 011'!K27 -> 20 | M25: =+J25*K25 -> 36000
A26: 15 | C26: ='SAF 011'!E28 -> Gradilla PP resistente 80ºC 80 Tubos Eppendorf Tipo DELTALAB | H26: NO | I26: ='SAF 011'!F28 -> UNIDAD | J26: ='SAF 011'!AT28 -> 800 | K26: ='SAF 011'!K28 -> 20 | M26: =+J26*K26 -> 16000
A27: 16 | C27: ='SAF 011'!E30 -> HISOPOS NASOFARINGEOS DE DACRON O NYLON | H27: NO | I27: ='SAF 011'!F30 -> UNIDAD | J27: ='SAF 011'!AT30 -> 59 | K27: ='SAF 011'!K30 -> 23100 | M27: =+J27*K27 -> 1362900
A28: 17 | C28: ='SAF 011'!E31 -> JERINGAS HEPARINIZADAS X 3 ML X100 UNIDADES | H28: NO | I28: ='SAF 011'!F31 -> CAJA | J28: ='SAF 011'!AT31 -> 8670 | K28: ='SAF 011'!K31 -> 19 | M28: =+J28*K28 -> 164730
A29: 18 | C29: ='SAF 011'!E32 -> LAMPARA COBAS C311 TIPO ROCHE | H29: NO | I29: ='SAF 011'!F32 -> UNIDAD | J29: ='SAF 011'!AT32 -> 58600 | K29: ='SAF 011'!K32 -> 2 | M29: =+J29*K29 -> 117200
A30: 19 | C30: ='SAF 011'!E33 -> MICROHEMATOCRITO CON HEPARINA X100 | H30: NO | I30: ='SAF 011'!F33 -> CAJA | J30: ='SAF 011'!AT33 -> 892 | K30: ='SAF 011'!K33 -> 100 | M30: =+J30*K30 -> 89200
A31: 20 | C31: ='SAF 011'!E34 -> MICROHEMATOCRITO SIN HEPARINA X100 | H31: NO | I31: ='SAF 011'!F34 -> CAJA | J31: ='SAF 011'!AT34 -> 683 | K31: ='SAF 011'!K34 -> 50 | M31: =+J31*K31 -> 34150
A32: 21 | C32: ='SAF 011'!E37 -> PIPETA AUTOMATICA TIPO SOCOREX VOL REGULABLE DE 5-50 ul | H32: NO | I32: ='SAF 011'!F37 -> UNIDAD | J32: ='SAF 011'!AT37 -> 93989 | K32: ='SAF 011'!K37 -> 8 | M32: =+J32*K32 -> 751912
A33: 22 | C33: ='SAF 011'!E38 -> PIPETA AUTOMATICA TIPO SOCOREX VOL REGULABLE DE 10-100 ul | H33: NO | I33: ='SAF 011'!F38 -> UNIDAD | J33: ='SAF 011'!AT38 -> 83298.43 | K33: ='SAF 011'!K38 -> 14 | M33: =+J33*K33 -> 1166178
A34: 23 | C34: ='SAF 011'!E39 -> PIPETA AUTOMATICA TIPO SOCOREX VOL REGULABLE DE 20-200 ul | H34: NO | I34: ='SAF 011'!F39 -> UNIDAD | J34: ='SAF 011'!AT39 -> 88695 | K34: ='SAF 011'!K39 -> 9 | M34: =+J34*K34 -> 798255
A35: 24 | C35: ='SAF 011'!E40 -> Placa de PCR Expell de 96 pocillos x 0,1 ml, sin pollera Calidad Biologia Molecular Libre de DNAasa y RNAasa, Capp x 25 Unidades | H35: NO | I35: ='SAF 011'!F40 -> CAJA | J35: ='SAF 011'!AT40 -> 9000 | K35: ='SAF 011'!K40 -> 20 | M35: =+J35*K35 -> 180000
A36: 25 | C36: ='SAF 011'!E41 -> PLACA DE VIDRIO PARA VDRL X 12 POCILLOS | H36: NO | I36: ='SAF 011'!F41 -> UNIDAD | J36: ='SAF 011'!AT41 -> 2100 | K36: ='SAF 011'!K41 -> 10 | M36: =+J36*K36 -> 21000
A37: 26 | C37: ='SAF 011'!E43 -> Portaobjetos borde sin pulir 50 U Tipo BREMEN | H37: NO | I37: ='SAF 011'!F43 -> CAJA | J37: ='SAF 011'!AT43 -> 219 | K37: ='SAF 011'!K43 -> 200 | M37: =+J37*K37 -> 43800
A38: 27 | C38: ='SAF 011'!E44 -> rollo de papel para MINIVIDAS x5 unidades | H38: NO | I38: ='SAF 011'!F44 -> PACK | J38: ='SAF 011'!AT44 -> 5100 | K38: ='SAF 011'!K44 -> 3 | M38: =+J38*K38 -> 15300
A39: 28 | C39: ='SAF 011'!E45 -> SENSOR GLUCOSA LACTATO COBAS B221 TIPO ROCHE | H39: NO | I39: ='SAF 011'!F45 -> UNIDAD | J39: ='SAF 011'!AT45 -> 12544 | K39: ='SAF 011'!K45 -> 2 | M39: =+J39*K39 -> 25088
A40: 29 | C40: ='SAF 011'!E46 -> TERMOMETRO DE ALCOHOL -10 A 60°C | H40: NO | I40: ='SAF 011'!F46 -> UNIDAD | J40: ='SAF 011'!AT46 -> 405 | K40: ='SAF 011'!K46 -> 15 | M40: =+J40*K40 -> 6075
A41: 30 | C41: ='SAF 011'!E50 -> TIPS AMARILLOS SIN CORONA X1000 UNIDADES | H41: NO | I41: ='SAF 011'!F50 -> BOLSA | J41: ='SAF 011'!AT50 -> 1000 | K41: ='SAF 011'!K50 -> 30 | M41: =+J41*K41 -> 30000
A42: 31 | C42: ='SAF 011'!E52 -> TIPS AZULES X1000 UNIDADES | H42: NO | I42: ='SAF 011'!F52 -> BOLSA | J42: ='SAF 011'!AT52 -> 2850 | K42: ='SAF 011'!K52 -> 10 | M42: =+J42*K42 -> 28500
A43: 32 | C43: ='SAF 011'!E53 -> TIPS BLANCO GRADUADO C/CORONA 10 ul BOLSA POR 1000 UNIDADES | H43: NO | I43: ='SAF 011'!F53 -> BOLSA | J43: ='SAF 011'!AT53 -> 9519 | K43: ='SAF 011'!K53 -> 10 | M43: =+J43*K43 -> 95190
...

Sheet APG LABORATORIO
A1: EJERCICIO: | D1: 2021 | P1: AUTORIZACION PARA GASTAR
A4: JURISDICCIÓN: | G4: ='NP LABORATORIO'!D3 -> 040 - MINISTERIO DE SALUD
A5: SAF: | G5: ='NP LABORATORIO'!D4 -> 011 - DIRECCION PROVINCIAL DE ADMINISTRACION DEL MINISTERIO DE SALUD
A6: UNIDAD EJECUTORA: | G6: ='NP LABORATORIO'!D5 -> 468 - DIRECCION PROVINCIAL DE LABORATORIO
A7: DEPENDENCIA SOLICITANTE: | G7: ='NP LABORATORIO'!D6 -> 468 - DIRECCION PROVINCIAL DE LABORATORIO
A8: AUTORIZACIÓN:
A9: Señor Director de Administración o Titular del Servicio Administrativo Financiero:
A10: Autorizo la realización de los trámites correspondientes, a fin de proveer a este Organismo los bienes que se detallan en Nota de Pedido N° 19/2021 afectando la erogación resultante a los créditos presupuestarios aprobados a favor de esta Unidad Ejecutora, conforme al siguiente detalle:
A12: IMPUTACIÓN PRESUPUESTARIA
A13: CÓDIGO | O13: DENOMINACIÓN DE LA PARTIDA PRESUPUESTARIA | Q13: IMPORTE
A14: PR | B14: SB | C14: PY | D14: AC | E14: OB | F14: UG | G14: FIN | H14: FUN | I14: I | J14: P | K14: P | L14: SubP | M14: M | N14: FF
A15: 62 | D15: 1 | F15: 4901 | G15: 3 | H15: 1 | I15: 2 | J15: 9 | K15: 5 | M15: 1 | N15: 1.1 | O15: UTILES MENORES MEDICOS, QUIRURGICOS Y DE LABORATORIO | Q15: ='NP LABORATORIO'!M54-Q16-Q17 -> 10927366
A16: 62 | D16: 1 | F16: 4901 | G16: 3 | H16: 1 | I16: 2 | J16: 3 | K16: 4 | M16: 1 | N16: 1.1 | O16: Productos de Papel y Cartón | Q16: =+'SAF 011'!L23+'SAF 011'!L44 -> 62700
A17: 62 | D17: 1 | F17: 4901 | G17: 3 | H17: 1 | I17: 2 | J17: 9 | K17: 3 | M17: 1 | N17: 1.1 | O17: Útiles y Materiales Eléctricos | Q17: =+'SAF 011'!L32 -> 117200
A38: =+'NP LABORATORIO'!A54:I54 -> Costo total estimado: ONCE MILLONES CIENTO SIETE MIL DOSCIENTOS SESENTA Y SEIS CON 00/100.- | Q38: =SUM(Q15:Q37) -> 11107266
A40: JUSTIFICACIÓN:
A41: ='NP LABORATORIO'!D8 -> ADQ. DEL RUBRO DESCARTABLES PARA LABORATORIO

Sheet NP BANCO DE SANGRE
A1: NOTA DE PEDIDO | J1: N° | K1: 24/2021
A3: JURISDICCIÓN: | D3: 040 - MINISTERIO DE SALUD
A4: SAF: | D4: 011 - DIRECCION PROVINCIAL DE ADMINISTRACION DEL MINISTERIO DE SALUD
A5: UNIDAD EJECUTORA: | D5: 747 - DIRECCION PROVINCIAL BANCO DE SANGRE
A6: DEPENDENCIA SOLICITANTE: | D6: 747 - DIRECCION PROVINCIAL BANCO DE SANGRE
A7: PERIODO UTILIZACIÓN: | D7: 4TO TRIMESTRE 2021
A8: OBJETO: | D8: ADQ. DEL RUBRO DESCARTABLES DE LABORATORIO
A10: Ítem | B10: Codigo Item | C10: DESCRIPCIÓN | H10: Adjunta Detalle Técnico | I10: Unidad Medida | J10: Precio Unitario Estimado | K10: Cantidad Solicitada
A12: 1 | C12: ='SAF 011'!E11 -> APOSITOS; TIPO: POST EXTRACCION SANGUINEA, hipoalergenica TAMAÑO: 40 X 40 mm X 100 | H12: NO | I12: ='SAF 011'!F11 -> CAJA | J12: ='SAF 011'!AT11 -> 702 | K12: ='SAF 011'!M11 -> 50 | M12: =+K12*J12 -> 35100
A13: 2 | C13: ='SAF 011'!E12 -> BOLSAS DE SANGRE TRIPLE KS TIPO GRIFOLS PARA EL EQUIPAMIENTO DE AFERESIS GRIFOLS | H13: NO | I13: ='SAF 011'!F12 -> UNIDAD | J13: ='SAF 011'!AT12 -> 1095 | K13: ='SAF 011'!M12 -> 1700 | M13: =+K13*J13 -> 1861500
A14: 3 | C14: ='SAF 011'!E13 -> CEPILLO LIMPIA PIPETA DE CERDA NATURAL DE 10 MM | H14: NO | I14: ='SAF 011'!F13 -> UNIDAD | J14: ='SAF 011'!AT13 -> 125 | K14: ='SAF 011'!M13 -> 10 | M14: =+K14*J14 -> 1250
A15: 4 | C15: ='SAF 011'!E18 -> DESCARTADOR PARA AGUJA P/500 AGUJAS, MODELO E-500 | H15: NO | I15: ='SAF 011'!F18 -> UNIDAD | J15: ='SAF 011'!AT18 -> 195 | K15: ='SAF 011'!M18 -> 200 | M15: =+K15*J15 -> 39000
A16: 5 | C16: ='SAF 011'!E29 -> GUIA V20 C/RUEDITA *SANGRE* | H16: NO | I16: ='SAF 011'!F29 -> UNIDAD | J16: ='SAF 011'!AT29 -> 92 | K16: ='SAF 011'!M29 -> 600 | M16: =+K16*J16 -> 55200
A17: 6 | C17: ='SAF 011'!E35 -> MICROPIPETAS REGULABLES; CAPACIDAD: 100 - 1000 µL, DIVISIONES: CADA 5 µL, MATERIAL: PLASTICO | H17: NO | I17: ='SAF 011'!F35 -> UNIDAD | J17: ='SAF 011'!AT35 -> 52350 | K17: ='SAF 011'!M35 -> 2 | M17: =+K17*J17 -> 104700
A18: 7 | C18: ='SAF 011'!E36 -> MICROPIPETAS REGULABLES; CAPACIDAD: 10-100 µL, DIVISIONES: CADA 1 µL, MATERIAL: PLASTICO | H18: NO | I18: ='SAF 011'!F36 -> UNIDAD | J18: ='SAF 011'!AT36 -> 50350 | K18: ='SAF 011'!M36 -> 2 | M18: =+K18*J18 -> 100700
A19: 8 | C19: ='SAF 011'!E42 -> PLACA PARA VDRL CON POCILLO PROFUNDO 12HOYOS | H19: NO | I19: ='SAF 011'!F42 -> UNIDAD | J19: ='SAF 011'!AT42 -> 1220 | K19: ='SAF 011'!M42 -> 5 | M19: =+K19*J19 -> 6100
A20: 10 | C20: ='SAF 011'!E47 -> TIP; TIPO: AMARILLO, PRESENTACION: ENVASE X 1000 UN, CAPACIDAD: 5 A 200 µl | H20: NO | I20: ='SAF 011'!F47 -> BOLSA | J20: ='SAF 011'!AT47 -> 2865 | K20: ='SAF 011'!M47 -> 5 | M20: =+K20*J20 -> 14325
A21: 11 | C21: ='SAF 011'!E48 -> TIPS AMARILLO 5 A 200 µl, CON CORONA X 1000 UN TIPO DELTALAB | H21: NO | I21: ='SAF 011'!F48 -> BOLSA | J21: ='SAF 011'!AT48 -> 1540 | K21: ='SAF 011'!M48 -> 2 | M21: =+K21*J21 -> 3080
A22: 12 | C22: ='SAF 011'!E49 -> TIPS AMARILLO 5 A 200 µl, SIN CORONA X 1000 UN TIPO DELTALAB | H22: NO | I22: ='SAF 011'!F49 -> BOLSA | J22: ='SAF 011'!AT49 -> 1540 | K22: ='SAF 011'!M49 -> 2 | M22: =+K22*J22 -> 3080
A23: 13 | C23: ='SAF 011'!E51 -> TIPS AZUL 100-1000 UL AUTOCLAVABLE - CON CORONA BOLSA POR 1000 UNIDADES TIPO DELTALAB | H23: NO | I23: ='SAF 011'!F51 -> BOLSA | J23: ='SAF 011'!AT51 -> 2204 | K23: ='SAF 011'!M51 -> 2 | M23: =+K23*J23 -> 4408
A24: 14 | C24: ='SAF 011'!E63 -> TUBOS DE ENSAYO; TIPO: CONICO P/CENTRIFUGA, MATERIAL: POLIPROPILENO, DIMENSION: 0,5 A 15 mL, ACCESORIO: SIN VALOR, ACCESORIOS: SIN VALOR A ROSCA 15ML NO ETERIL, BOLSA X 100 UNID TIPO BIOLIX | H24: NO | I24: ='SAF 011'!F63 -> BOLSA | J24: ='SAF 011'!AT63 -> 5353 | K24: ='SAF 011'!M63 -> 9 | M24: =+K24*J24 -> 48177
A25: 15 | C25: ='SAF 011'!E64 -> TUBOS DE ENSAYO; TIPO: EPPENDORF, MATERIAL: PLASTICO, DIMENSION: 1.5 mL, ACCESORIOS: SIN, ACCESORIO: SIN, BOLSAS X 500 UNIDADES | H25: NO | I25: ='SAF 011'!F64 -> BOLSA | J25: ='SAF 011'!AT64 -> 3558 | K25: ='SAF 011'!M64 -> 9 | M25: =+K25*J25 -> 32022
A26: 16 | C26: ='SAF 011'!E65 -> TUBOS DE ENSAYO; TIPO: VACUTAINER UN, MATERIAL: VIDRIO, DIMENSION: 10 mL, ACCESORIOS: SIN, ACCESORIO: SIN, CAJA X 100 UNIDADES | H26: NO | I26: ='SAF 011'!F65 -> CAJA | J26: ='SAF 011'!AT65 -> 13000 | K26: ='SAF 011'!M65 -> 2 | M26: =+K26*J26 -> 26000
A27: 17 | C27: ='SAF 011'!E66 -> TUBOS DE HEMOLISIS; MATERIAL: VIDRIO, PRESENTACION: CAJA, DIMENSION: 100 X 13 DIAM. EXT., MEDIDAS: 100 X 13 DIAM. EXT., FORMA DE PRESENTACION: SOLIDO, ESTADO: SOLIDO | H27: NO | I27: ='SAF 011'!F66 -> UNIDAD | J27: ='SAF 011'!AT66 -> 72 | K27: ='SAF 011'!M66 -> 1000 | M27: =+K27*J27 -> 72000
A28: 18 | C28: ='SAF 011'!E67 -> TUBOS VACUTAINER P/SUERO DE 4ML, TAPA ROJA C/ETIQUETA CODIGO 367812 X100 UNIDADES | H28: NO | I28: ='SAF 011'!F67 -> CAJAS | J28: ='SAF 011'!AT67 -> 13700 | K28: ='SAF 011'!M67 -> 2 | M28: =+K28*J28 -> 27400
A30: Costo total estimado: DOS MILLONES CUATROCIENTOS TREINTA Y CUATRO MIL CUARENTA Y DOS CON 00/100.- | J30: =+M30 -> 2434042 | M30: =SUM(M12:M29) -> 2434042

Sheet APG BANCO DE SANGRE
A1: EJERCICIO: | D1: 2021 | P1: AUTORIZACION PARA GASTAR
A4: JURISDICCIÓN: | G4: ='NP BANCO DE SANGRE'!D3 -> 040 - MINISTERIO DE SALUD
A5: SAF: | G5: ='NP BANCO DE SANGRE'!D4 -> 011 - DIRECCION PROVINCIAL DE ADMINISTRACION DEL MINISTERIO DE SALUD
A6: UNIDAD EJECUTORA: | G6: ='NP BANCO DE SANGRE'!D5 -> 747 - DIRECCION PROVINCIAL BANCO DE SANGRE
A7: DEPENDENCIA SOLICITANTE: | G7: ='NP BANCO DE SANGRE'!D6 -> 747 - DIRECCION PROVINCIAL BANCO DE SANGRE
A8: AUTORIZACIÓN:
A9: Señor Director de Administración o Titular del Servicio Administrativo Financiero:
A10: Autorizo la realización de los trámites correspondientes, a fin de proveer a este Organismo los bienes que se detallan en Nota de Pedido N° 24/2021 afectando la erogación resultante a los créditos presupuestarios aprobados a favor de esta Unidad Ejecutora, conforme al siguiente detalle:
A12: IMPUTACIÓN PRESUPUESTARIA
A13: CÓDIGO | O13: DENOMINACIÓN DE LA PARTIDA PRESUPUESTARIA | Q13: IMPORTE
A14: PR | B14: SB | C14: PY | D14: AC | E14: OB | F14: UG | G14: FIN | H14: FUN | I14: I | J14: P | K14: P | L14: SubP | M14: M | N14: FF
A15: 27 | D15: 1 | F15: 4901 | G15: 3 | H15: 1 | I15: 2 | J15: 9 | K15: 5 | M15: 1 | N15: 1.1 | O15: UTILES MENORES MEDICOS, QUIRURGICOS Y DE LABORATORIO | Q15: ='NP BANCO DE SANGRE'!M30 -> 2434042
A38: =+'NP BANCO DE SANGRE'!A30:I30 -> Costo total estimado: DOS MILLONES CUATROCIENTOS TREINTA Y CUATRO MIL CUARENTA Y DOS CON 00/100.- | Q38: =SUM(Q15:Q37) -> 2434042
A40: JUSTIFICACIÓN:
A41: ='NP BANCO DE SANGRE'!D8 -> ADQ. DEL RUBRO DESCARTABLES DE LABORATORIO
