Workbook

Sheet Necesidades Trimestrales (2)
A1: 2021
B2: Pedido de Necesidades Trimestrales
A4: JURISDICCION: | C4: 40 - MINISTERIO DE SALUD
A5: SAF N°: | C5: 11 - DIRECCION PROVINCIAL DE ADMINISTRACION - MINISTERIO DE SALUD
A6: EJERCICIO: | C6: 2021
A7: TRIMESTRE: | C7: TERCER TRIMESTRE
A9: ID | B9: CODIGO ITEM | C9: RUBRO DE COMPRA | D9: I.P.P. | E9: DESCRIPCION | F9: UNIDAD DE MEDIDA | G9: DIR DE ADM | H9: TOTAL DIR ADM | I9: SEC PREV | J9: TOTAL SEC PREVEN | K9: DIR. LAB. CENTRAL | L9: TOTAL DE LAB CENTRAL | M9: BCO DE SANGRE | N9: TOTAL BANCO DE SANGRE | O9: ATENCION PRIMARIA | P9: TOTAL ATENCION PRI | Q9: DIR DE CANCER | R9: TOTAL DE DIR DE CANCER | S9: FARMACIA | T9: TOTAL FARMACIA | U9: ODONTOLOGIA | V9: TOTAL DE ODONTOLOG | W9: SAME | X9: TOTAL DE SAME | Y9: MALBRAN | Z9: HOSPITAL MALBRAN | AA9: maternidade e infancia | AB9: total maternidad | AC9: SEC DE ASIST EN SALUD PUB | AD9: TOTAL SEC EN ASIS EN SAL | AE9: SALUD Y MEDIO AMBIENTE | AF9: TOTAL SALUD Y MEDIO AMBIENTE | AG9: VECTORES Y ZOONOSIS | AH9: TOTAL DE VECT Y ZOON | AI9: SUMAR | AJ9: TOTAL SUMAR | AK9: CUR | AL9: TOTAL CUR | AM9: PLANIFICACION | AN9: TOTAL PLANIFICA | AO9: SALUD MENTAL | AP9: TOTAL SALUD MENTAL | AQ9: AREAS Y DPAS | AR9: TOTAL DPAS | AS9: CANTIDAD TOTAL | AT9: PRECIO UNITARIO ESTIMADO | AU9: IMPORTE TOTAL ESTIMADO
A10: 1 | C10: QUIMICOS | D10: 2.5.1. | E10: AGUA BIDESTILADA x 10 litros | F10: BIDON | AK10: 10 | AL10: =+AK10*AT10 -> 5740 | AS10: =+AQ10+AO10+AM10+AK10+AI10+AG10+AE10+AC10+AA10+Y10+W10+U10+S10+Q10+O10+M10+K10+I10 -> 10 | AT10: 574 | AU10: =+AS10*AT10 -> 5740
A11: 2 | C11: QUIMICOS | D11: 2.5.1. | E11: Albumina AA 120 X 6 Ml Tipo WIENER | F11: unidad | K11: 10 | L11: =+K11*AT11 -> 45660 | N11: =+M11*AT11 -> 0 | AS11: =+AQ11+AO11+AM11+AK11+AI11+AG11+AE11+AC11+AA11+Y11+W11+U11+S11+Q11+O11+M11+K11+I11 -> 10 | AT11: 4566 | AU11: =+AS11*AT11 -> 45660
A12: 3 | C12: QUIMICOS | D12: 2.5.1. | E12: ALBUMINA BOVINA TIPO WIENER | F12: UNIDAD | M12: 12 | N12: =+M12*AT12 -> 15012 | AS12: =+AQ12+AO12+AM12+AK12+AI12+AG12+AE12+AC12+AA12+Y12+W12+U12+S12+Q12+O12+M12+K12+I12 -> 12 | AT12: 1251 | AU12: =+AS12*AT12 -> 15012
A13: 4 | C13: QUIMICOS | D13: 2.5.1. | E13: ALBUMINA COBAS C311 X 300 DET. TIPO ROCHE | F13: UNIDAD | K13: 12 | L13: =+K13*AT13 -> 24372 | AS13: =+AQ13+AO13+AM13+AK13+AI13+AG13+AE13+AC13+AA13+Y13+W13+U13+S13+Q13+O13+M13+K13+I13 -> 12 | AT13: 2031 | AU13: =+AS13*AT13 -> 24372
A14: 5 | C14: QUIMICOS | D14: 2.5.1. | E14: ALCohol ISOPROPILICO Tipo CICARELLI X 1 LITRO | F14: unidad | K14: 30 | L14: =+K14*AT14 -> 61650 | N14: =+M14*AT14 -> 0 | AS14: =+AQ14+AO14+AM14+AK14+AI14+AG14+AE14+AC14+AA14+Y14+W14+U14+S14+Q14+O14+M14+K14+I14 -> 30 | AT14: 2055 | AU14: =+AS14*AT14 -> 61650
A15: 6 | C15: QUIMICOS | D15: 2.5.1. | E15: ALP 405 AA LL 100 Ml Tipo WIENER | F15: unidad | K15: 20 | L15: =+K15*AT15 -> 54340 | N15: =+M15*AT15 -> 0 | AS15: =+AQ15+AO15+AM15+AK15+AI15+AG15+AE15+AC15+AA15+Y15+W15+U15+S15+Q15+O15+M15+K15+I15 -> 20 | AT15: 2717 | AU15: =+AS15*AT15 -> 54340
A16: 7 | C16: QUIMICOS | D16: 2.5.1. | E16: Amilasa 405 liquida 30 Ml (3x10 ml) tipo WIENER | F16: unidad | K16: 20 | L16: =+K16*AT16 -> 102920 | N16: =+M16*AT16 -> 0 | AS16: =+AQ16+AO16+AM16+AK16+AI16+AG16+AE16+AC16+AA16+Y16+W16+U16+S16+Q16+O16+M16+K16+I16 -> 20 | AT16: 5146 | AU16: =+AS16*AT16 -> 102920
A17: 8 | C17: QUIMICOS | D17: 2.5.1. | E17: ANTI-A MONOCLONAL- FRASCO 10 ML TIPO WIENER | F17: UNIDAD | M17: 100 | N17: =+M17*AT17 -> 87600 | AS17: =+AQ17+AO17+AM17+AK17+AI17+AG17+AE17+AC17+AA17+Y17+W17+U17+S17+Q17+O17+M17+K17+I17 -> 100 | AT17: 876 | AU17: =+AS17*AT17 -> 87600
A18: 9 | C18: QUIMICOS | D18: 2.5.1. | E18: ANTI-AB MONOCLONAL- FRASCO 10 MLTIPO WIENER | F18: UNIDAD | M18: 100 | N18: =+M18*AT18 -> 88800 | AS18: =+AQ18+AO18+AM18+AK18+AI18+AG18+AE18+AC18+AA18+Y18+W18+U18+S18+Q18+O18+M18+K18+I18 -> 100 | AT18: 888 | AU18: =+AS18*AT18 -> 88800
A19: 10 | C19: QUIMICOS | D19: 2.5.1. | E19: ANTI-B MONOCLONAL-FRASCOS 10 ML TIPO WIENER | F19: UNIDAD | M19: 100 | N19: =+M19*AT19 -> 87600 | AS19: =+AQ19+AO19+AM19+AK19+AI19+AG19+AE19+AC19+AA19+Y19+W19+U19+S19+Q19+O19+M19+K19+I19 -> 100 | AT19: 876 | AU19: =+AS19*AT19 -> 87600
A20: 11 | C20: QUIMICOS | D20: 2.5.1. | E20: Anticoagulante W EDTA 6x50 ml tipo Wiener | F20: unidad | K20: 20 | L20: =+K20*AT20 -> 55600 | N20: =+M20*AT20 -> 0 | AS20: =+AQ20+AO20+AM20+AK20+AI20+AG20+AE20+AC20+AA20+Y20+W20+U20+S20+Q20+O20+M20+K20+I20 -> 20 | AT20: 2780 | AU20: =+AS20*AT20 -> 55600
A21: 12 | C21: QUIMICOS | D21: 2.5.1. | E21: ANTI-D (RHO) MONOCLONAL-FRASCOS 10 ML TIPO WIENER | F21: UNIDAD | M21: 100 | N21: =+M21*AT21 -> 165700 | AS21: =+AQ21+AO21+AM21+AK21+AI21+AG21+AE21+AC21+AA21+Y21+W21+U21+S21+Q21+O21+M21+K21+I21 -> 100 | AT21: 1657 | AU21: =+AS21*AT21 -> 165700
A22: 13 | C22: QUIMICOS | D22: 2.5.1. | E22: ANTIGENO FEBRIL BRUCELLA (HUDDLESON) | F22: unidad | K22: 30 | L22: =+K22*AT22 -> 39630 | M22: 12 | N22: =+M22*AT22 -> 15852 | AS22: =+AQ22+AO22+AM22+AK22+AI22+AG22+AE22+AC22+AA22+Y22+W22+U22+S22+Q22+O22+M22+K22+I22 -> 42 | AT22: 1321 | AU22: =+AS22*AT22 -> 55482
A23: 14 | C23: QUIMICOS | D23: 2.5.1. | E23: APTTest tipo Wiener 150 det. | F23: unidad | K23: 20 | L23: =+K23*AT23 -> 137020 | AS23: =+AQ23+AO23+AM23+AK23+AI23+AG23+AE23+AC23+AA23+Y23+W23+U23+S23+Q23+O23+M23+K23+I23 -> 20 | AT23: 6851 | AU23: =+AS23*AT23 -> 137020
A24: 15 | C24: QUIMICOS | D24: 2.5.1. | E24: APTT-P Tipo HEMO MEDICA (USA) | F24: unidad | K24: 20 | L24: =+K24*AT24 -> 175100 | N24: =+M24*AT24 -> 0 | AS24: =+AQ24+AO24+AM24+AK24+AI24+AG24+AE24+AC24+AA24+Y24+W24+U24+S24+Q24+O24+M24+K24+I24 -> 20 | AT24: 8755 | AU24: =+AS24*AT24 -> 175100
A25: 16 | C25: QUIMICOS | D25: 2.5.1. | E25: ARC ANTI HBC II CALIBRADOR TIPO ART. ABBOT | F25: KIT | AK25: 1 | AL25: =+AK25*AT25 -> 15850 | AS25: =+AQ25+AO25+AM25+AK25+AI25+AG25+AE25+AC25+AA25+Y25+W25+U25+S25+Q25+O25+M25+K25+I25 -> 1 | AT25: 15850 | AU25: =+AS25*AT25 -> 15850
A26: 17 | C26: QUIMICOS | D26: 2.5.1. | E26: ARC ANTI HBC II RGT X 100 DET. TIPO ART. ABBOT | F26: KIT | AK26: 2 | AL26: =+AK26*AT26 -> 73500 | AS26: =+AQ26+AO26+AM26+AK26+AI26+AG26+AE26+AC26+AA26+Y26+W26+U26+S26+Q26+O26+M26+K26+I26 -> 2 | AT26: 36750 | AU26: =+AS26*AT26 -> 73500
A27: 18 | C27: QUIMICOS | D27: 2.5.1. | E27: ARC ANTI HCV CALIBRADOR TIPO ART. ABBOT | F27: KIT | AK27: 1 | AL27: =+AK27*AT27 -> 15850 | AS27: =+AQ27+AO27+AM27+AK27+AI27+AG27+AE27+AC27+AA27+Y27+W27+U27+S27+Q27+O27+M27+K27+I27 -> 1 | AT27: 15850 | AU27: =+AS27*AT27 -> 15850
A28: 19 | C28: QUIMICOS | D28: 2.5.1. | E28: ARC ANTI HCV RGT X 100 DET. TIPO ART. ABBOT | F28: KIT | AK28: 2 | AL28: =+AK28*AT28 -> 143000 | AS28: =+AQ28+AO28+AM28+AK28+AI28+AG28+AE28+AC28+AA28+Y28+W28+U28+S28+Q28+O28+M28+K28+I28 -> 2 | AT28: 71500 | AU28: =+AS28*AT28 -> 143000
A29: 20 | C29: QUIMICOS | D29: 2.5.1. | E29: ARC BUFFER CONCENTRADO x 4 lts TIPO ART. ABBOT | F29: BIDON | AK29: 3 | AL29: =+AK29*AT29 -> 37650 | AS29: =+AQ29+AO29+AM29+AK29+AI29+AG29+AE29+AC29+AA29+Y29+W29+U29+S29+Q29+O29+M29+K29+I29 -> 3 | AT29: 12550 | AU29: =+AS29*AT29 -> 37650
A30: 21 | C30: QUIMICOS | D30: 2.5.1. | E30: ARC CELDAS DE REACCION TIPO ART. ABBOT | F30: CAJA | AK30: 3 | AL30: =+AK30*AT30 -> 84000 | AS30: =+AQ30+AO30+AM30+AK30+AI30+AG30+AE30+AC30+AA30+Y30+W30+U30+S30+Q30+O30+M30+K30+I30 -> 3 | AT30: 28000 | AU30: =+AS30*AT30 -> 84000
A31: 22 | C31: QUIMICOS | D31: 2.5.1. | E31: ARC CMV M CALIBRADOR TIPO ART. ABBOT | F31: KIT | AK31: 1 | AL31: =+AK31*AT31 -> 15039 | AS31: =+AQ31+AO31+AM31+AK31+AI31+AG31+AE31+AC31+AA31+Y31+W31+U31+S31+Q31+O31+M31+K31+I31 -> 1 | AT31: 15039 | AU31: =+AS31*AT31 -> 15039
A32: 23 | C32: QUIMICOS | D32: 2.5.1. | E32: ARC CMV M RGT X 100 TIPO ART. ABBOT | F32: KIT | AK32: 1 | AL32: =+AK32*AT32 -> 27595 | AS32: =+AQ32+AO32+AM32+AK32+AI32+AG32+AE32+AC32+AA32+Y32+W32+U32+S32+Q32+O32+M32+K32+I32 -> 1 | AT32: 27595 | AU32: =+AS32*AT32 -> 27595
A33: 24 | C33: QUIMICOS | D33: 2.5.1. | E33: ARC HBSAG CALIBRADOR TIPO ART. ABBOT | F33: KIT | AK33: 1 | AL33: =+AK33*AT33 -> 15850 | AS33: =+AQ33+AO33+AM33+AK33+AI33+AG33+AE33+AC33+AA33+Y33+W33+U33+S33+Q33+O33+M33+K33+I33 -> 1 | AT33: 15850 | AU33: =+AS33*AT33 -> 15850
A34: 25 | C34: QUIMICOS | D34: 2.5.1. | E34: ARC HBSAG RGT X 100 DET. TIPO ART. ABBOT | F34: KIT | AK34: 2 | AL34: =+AK34*AT34 -> 48960 | AS34: =+AQ34+AO34+AM34+AK34+AI34+AG34+AE34+AC34+AA34+Y34+W34+U34+S34+Q34+O34+M34+K34+I34 -> 2 | AT34: 24480 | AU34: =+AS34*AT34 -> 48960
A35: 26 | C35: QUIMICOS | D35: 2.5.1. | E35: ARC HIV COMBO CALIBRADOR TIPO ART. ABBOT | F35: KIT | AK35: 1 | AL35: =+AK35*AT35 -> 20240 | AS35: =+AQ35+AO35+AM35+AK35+AI35+AG35+AE35+AC35+AA35+Y35+W35+U35+S35+Q35+O35+M35+K35+I35 -> 1 | AT35: 20240 | AU35: =+AS35*AT35 -> 20240
A36: 27 | C36: QUIMICOS | D36: 2.5.1. | E36: ARC HIV COMBO RGT X 100 DET. TIPO ART. ABBOT | F36: KIT | AK36: 4 | AL36: =+AK36*AT36 -> 168956 | AS36: =+AQ36+AO36+AM36+AK36+AI36+AG36+AE36+AC36+AA36+Y36+W36+U36+S36+Q36+O36+M36+K36+I36 -> 4 | AT36: 42239 | AU36: =+AS36*AT36 -> 168956
... A40: 31 | C40: QUIMICOS | D40: 2.5.1. | E40: ARC TRIGGER x 4 lts TIPO ART. ABBOT | F40: BIDON | AK40: 2 | AL40: =+AK40*AT40 -> 22000 | AS40: =+AQ40+AO40+AM40+AK40+AI40+AG40+AE40+AC40+AA40+Y40+W40+U40+S40+Q40+O40+M40+K40+I40 -> 2 | AT40: 11000 | AU40: =+AS40*AT40 -> 22000
A41: 32 | C41: QUIMICOS | D41: 2.5.1. | E41: Artritest Directo 50 Det Tipo WIENER | F41: unidad | K41: 30 | L41: =+K41*AT41 -> 58950 | N41: =+M41*AT41 -> 0 | AS41: =+AQ41+AO41+AM41+AK41+AI41+AG41+AE41+AC41+AA41+Y41+W41+U41+S41+Q41+O41+M41+K41+I41 -> 30 | AT41: 1965 | AU41: =+AS41*AT41 -> 58950
A42: 33 | C42: QUIMICOS | D42: 2.5.1. | E42: ASO latex 50 Det Tipo WIENER | F42: unidad | K42: 5 | L42: =+K42*AT42 -> 19675 | N42: =+M42*AT42 -> 0 | AS42: =+AQ42+AO42+AM42+AK42+AI42+AG42+AE42+AC42+AA42+Y42+W42+U42+S42+Q42+O42+M42+K42+I42 -> 5 | AT42: 3935 | AU42: =+AS42*AT42 -> 19675
A43: 34 | C43: QUIMICOS | D43: 2.5.1. | E43: BC-3D Control Hematologico 3x3 Ml (1B, 1N, 1A) | F43: unidad | K43: 8 | L43: =+K43*AT43 -> 92000 | N43: =+M43*AT43 -> 0 | AS43: =+AQ43+AO43+AM43+AK43+AI43+AG43+AE43+AC43+AA43+Y43+W43+U43+S43+Q43+O43+M43+K43+I43 -> 8 | AT43: 11500 | AU43: =+AS43*AT43 -> 92000
A44: 35 | C44: QUIMICOS | D44: 2.5.1. | E44: Bilirrubina 200 Det Tipo WIENER | F44: unidad | K44: 10 | L44: =+K44*AT44 -> 48050 | N44: =+M44*AT44 -> 0 | AS44: =+AQ44+AO44+AM44+AK44+AI44+AG44+AE44+AC44+AA44+Y44+W44+U44+S44+Q44+O44+M44+K44+I44 -> 10 | AT44: 4805 | AU44: =+AS44*AT44 -> 48050
A45: 36 | C45: QUIMICOS | D45: 2.5.1. | E45: Bilirrubina DIRECTA AA LIQUIDA Tipo WIENER | F45: unidad | K45: 10 | L45: =+K45*AT45 -> 41200 | N45: =+M45*AT45 -> 0 | AS45: =+AQ45+AO45+AM45+AK45+AI45+AG45+AE45+AC45+AA45+Y45+W45+U45+S45+Q45+O45+M45+K45+I45 -> 10 | AT45: 4120 | AU45: =+AS45*AT45 -> 41200
...

Sheet lab centr
A1: NOTA DE PEDIDO | J1: N° | K1: 34/21
A3: JURISDICCIÓN: | D3: 040 - Ministerio de Salud
A4: SAF: | D4: 011 - Direccion Provincial de Administración - Ministerio de Salud
A5: UNIDAD EJECUTORA: | D5: 468 - DIRECCION PROVINCIAL DE LABORATORIO
A6: DEPENDENCIA SOLICITANTE: | D6: 468 - DIRECCION PROVINCIAL DE LABORATORIO
A7: PERIODO UTILIZACIÓN: | D7: 3° TRIMESTRE
A8: OBJETO: | D8: Adquisicion del RUBRO REACTIVOS PARA LABORATORIO
A10: Ítem | B10: Codigo Item | C10: DESCRIPCIÓN | H10: Adjunta Detalle Técnico | I10: Unidad Medida | J10: Precio Unitario Estimado | K10: Cantidad Solicitada
A12: 1 | C12: ='Necesidades Trimestrales (2)'!E11 -> Albumina AA 120 X 6 Ml Tipo WIENER | H12: SI | I12: ='Necesidades Trimestrales (2)'!F11 -> unidad | J12: ='Necesidades Trimestrales (2)'!AT11 -> 4566 | K12: ='Necesidades Trimestrales (2)'!AS11 -> 10 | L12: =+J12*K12 -> 45660 | M12: =+J12*K12 -> 45660
A13: 2 | C13: ='Necesidades Trimestrales (2)'!E13 -> ALBUMINA COBAS C311 X 300 DET. TIPO ROCHE | H13: SI | I13: ='Necesidades Trimestrales (2)'!F13 -> UNIDAD | J13: ='Necesidades Trimestrales (2)'!AT13 -> 2031 | K13: ='Necesidades Trimestrales (2)'!AS13 -> 12 | L13: =+J13*K13 -> 24372 | M13: =+J13*K13 -> 24372
A14: 3 | C14: ='Necesidades Trimestrales (2)'!E14 -> ALCohol ISOPROPILICO Tipo CICARELLI X 1 LITRO | H14: SI | I14: ='Necesidades Trimestrales (2)'!F14 -> unidad | J14: ='Necesidades Trimestrales (2)'!AT14 -> 2055 | K14: ='Necesidades Trimestrales (2)'!AS14 -> 30 | L14: =+J14*K14 -> 61650 | M14: =+J14*K14 -> 61650
A15: 4 | C15: ='Necesidades Trimestrales (2)'!E15 -> ALP 405 AA LL 100 Ml Tipo WIENER | H15: SI | I15: ='Necesidades Trimestrales (2)'!F15 -> unidad | J15: ='Necesidades Trimestrales (2)'!AT15 -> 2717 | K15: ='Necesidades Trimestrales (2)'!AS15 -> 20 | L15: =+J15*K15 -> 54340 | M15: =+J15*K15 -> 54340
A16: 5 | C16: ='Necesidades Trimestrales (2)'!E16 -> Amilasa 405 liquida 30 Ml (3x10 ml) tipo WIENER | H16: SI | I16: ='Necesidades Trimestrales (2)'!F16 -> unidad | J16: ='Necesidades Trimestrales (2)'!AT16 -> 5146 | K16: ='Necesidades Trimestrales (2)'!AS16 -> 20 | L16: =+J16*K16 -> 102920 | M16: =+J16*K16 -> 102920
A17: 6 | C17: ='Necesidades Trimestrales (2)'!E20 -> Anticoagulante W EDTA 6x50 ml tipo Wiener | H17: SI | I17: ='Necesidades Trimestrales (2)'!F20 -> unidad | J17: ='Necesidades Trimestrales (2)'!AT20 -> 2780 | K17: ='Necesidades Trimestrales (2)'!AS20 -> 20 | L17: =+J17*K17 -> 55600 | M17: =+J17*K17 -> 55600
A18: 7 | C18: ='Necesidades Trimestrales (2)'!E22 -> ANTIGENO FEBRIL BRUCELLA (HUDDLESON) | H18: SI | I18: ='Necesidades Trimestrales (2)'!F22 -> unidad | J18: ='Necesidades Trimestrales (2)'!AT22 -> 1321 | K18: 30 | L18: =+J18*K18 -> 39630 | M18: =+J18*K18 -> 39630
A19: 8 | C19: ='Necesidades Trimestrales (2)'!E23 -> APTTest tipo Wiener 150 det. | H19: SI | I19: ='Necesidades Trimestrales (2)'!F23 -> unidad | J19: ='Necesidades Trimestrales (2)'!AT23 -> 6851 | K19: ='Necesidades Trimestrales (2)'!AS23 -> 20 | L19: =+J19*K19 -> 137020 | M19: =+J19*K19 -> 137020
A20: 9 | C20: ='Necesidades Trimestrales (2)'!E24 -> APTT-P Tipo HEMO MEDICA (USA) | H20: SI | I20: ='Necesidades Trimestrales (2)'!F24 -> unidad | J20: ='Necesidades Trimestrales (2)'!AT24 -> 8755 | K20: ='Necesidades Trimestrales (2)'!AS24 -> 20 | L20: =+J20*K20 -> 175100 | M20: =+J20*K20 -> 175100
A21: 10 | C21: ='Necesidades Trimestrales (2)'!E41 -> Artritest Directo 50 Det Tipo WIENER | H21: SI | I21: ='Necesidades Trimestrales (2)'!F41 -> unidad | J21: ='Necesidades Trimestrales (2)'!AT41 -> 1965 | K21: ='Necesidades Trimestrales (2)'!AS41 -> 30 | L21: =+J21*K21 -> 58950 | M21: =+J21*K21 -> 58950
A22: 11 | C22: ='Necesidades Trimestrales (2)'!E42 -> ASO latex 50 Det Tipo WIENER | H22: SI | I22: ='Necesidades Trimestrales (2)'!F42 -> unidad | J22: ='Necesidades Trimestrales (2)'!AT42 -> 3935 | K22: ='Necesidades Trimestrales (2)'!AS42 -> 5 | L22: =+J22*K22 -> 19675 | M22: =+J22*K22 -> 19675
A23: 12 | C23: ='Necesidades Trimestrales (2)'!E43 -> BC-3D Control Hematologico 3x3 Ml (1B, 1N, 1A) | H23: SI | I23: ='Necesidades Trimestrales (2)'!F43 -> unidad | J23: ='Necesidades Trimestrales (2)'!AT43 -> 11500 | K23: ='Necesidades Trimestrales (2)'!AS43 -> 8 | L23: =+J23*K23 -> 92000 | M23: =+J23*K23 -> 92000
A24: 13 | C24: ='Necesidades Trimestrales (2)'!E44 -> Bilirrubina 200 Det Tipo WIENER | H24: SI | I24: ='Necesidades Trimestrales (2)'!F44 -> unidad | J24: ='Necesidades Trimestrales (2)'!AT44 -> 4805 | K24: ='Necesidades Trimestrales (2)'!AS44 -> 10 | L24: =+J24*K24 -> 48050 | M24: =+J24*K24 -> 48050
A25: 14 | C25: ='Necesidades Trimestrales (2)'!E45 -> Bilirrubina DIRECTA AA LIQUIDA Tipo WIENER | H25: SI | I25: ='Necesidades Trimestrales (2)'!F45 -> unidad | J25: ='Necesidades Trimestrales (2)'!AT45 -> 4120 | K25: ='Necesidades Trimestrales (2)'!AS45 -> 10 | L25: =+J25*K25 -> 41200 | M25: =+J25*K25 -> 41200
A26: 15 | C26: ='Necesidades Trimestrales (2)'!E46 -> Bilirrubina TOTAL AA LIQUIDA Tipo WIENER | H26: SI | I26: ='Necesidades Trimestrales (2)'!F46 -> unidad | J26: ='Necesidades Trimestrales (2)'!AT46 -> 4125 | K26: ='Necesidades Trimestrales (2)'!AS46 -> 10 | L26: =+J26*K26 -> 41250 | M26: =+J26*K26 -> 41250
A27: 16 | C27: ='Necesidades Trimestrales (2)'!E49 -> Botella de FA Plus Aerobico para Bact Alert | H27: SI | I27: ='Necesidades Trimestrales (2)'!F49 -> unidad | J27: ='Necesidades Trimestrales (2)'!AT49 -> 950 | K27: ='Necesidades Trimestrales (2)'!AS49 -> 1500 | L27: =+J27*K27 -> 1425000 | M27: =+J27*K27 -> 1425000
A28: 17 | C28: ='Necesidades Trimestrales (2)'!E51 -> CALCIO COLOR AATipo WIENER | H28: SI | I28: ='Necesidades Trimestrales (2)'!F51 -> unidad | J28: ='Necesidades Trimestrales (2)'!AT51 -> 2487 | K28: ='Necesidades Trimestrales (2)'!AS51 -> 10 | L28: =+J28*K28 -> 24870 | M28: =+J28*K28 -> 24870
A29: 18 | C29: ='Necesidades Trimestrales (2)'!E52 -> CALIBRADOR A PLUS Tipo WIENER | H29: SI | I29: ='Necesidades Trimestrales (2)'!F52 -> unidad | J29: ='Necesidades Trimestrales (2)'!AT52 -> 3929 | K29: ='Necesidades Trimestrales (2)'!AS52 -> 15 | L29: =+J29*K29 -> 58935 | M29: =+J29*K29 -> 58935
A30: 19 | C30: ='Necesidades Trimestrales (2)'!E53 -> CASSETE SENSOR OSMOTECH OPTI CCA TIPO E-GLU | H30: SI | I30: ='Necesidades Trimestrales (2)'!F53 -> unidad | J30: ='Necesidades Trimestrales (2)'!AT53 -> 46440 | K30: ='Necesidades Trimestrales (2)'!AS53 -> 20 | L30: =+J30*K30 -> 928800 | M30: =+J30*K30 -> 928800
A31: 20 | C31: ='Necesidades Trimestrales (2)'!E55 -> CELL PACKS Tipo SYSMEX 20 L | H31: SI | I31: ='Necesidades Trimestrales (2)'!F55 -> UNIDAD | J31: ='Necesidades Trimestrales (2)'!AT55 -> 7932 | K31: ='Necesidades Trimestrales (2)'!AS55 -> 16 | L31: =+J31*K31 -> 126912 | M31: =+J31*K31 -> 126912
A32: 21 | C32: ='Necesidades Trimestrales (2)'!E56 -> CELL WASH SOLITION I COBAS C311 TIPO ROCHE | H32: SI | I32: ='Necesidades Trimestrales (2)'!F56 -> unidad | J32: ='Necesidades Trimestrales (2)'!AT56 -> 5922 | K32: ='Necesidades Trimestrales (2)'!AS56 -> 15 | L32: =+J32*K32 -> 88830 | M32: =+J32*K32 -> 88830
A33: 22 | C33: ='Necesidades Trimestrales (2)'!E57 -> CHAGAS ELISA Tipo WIENER | H33: SI | I33: ='Necesidades Trimestrales (2)'!F57 -> unidad | J33: ='Necesidades Trimestrales (2)'!AT57 -> 11386 | K33: ='Necesidades Trimestrales (2)'!AS57 -> 30 | L33: =+J33*K33 -> 341580 | M33: =+J33*K33 -> 341580
A34: 23 | C34: ='Necesidades Trimestrales (2)'!E58 -> CHAGAS HAI Tipo WIENER | H34: SI | I34: ='Necesidades Trimestrales (2)'!F58 -> unidad | J34: ='Necesidades Trimestrales (2)'!AT58 -> 12092 | K34: ='Necesidades Trimestrales (2)'!AS58 -> 30 | L34: =+J34*K34 -> 362760 | M34: =+J34*K34 -> 362760
A35: 24 | C35: ='Necesidades Trimestrales (2)'!E61 -> CLORURO DE CALCIO Tipo HEMO MEDICA (USA) | H35: SI | I35: ='Necesidades Trimestrales (2)'!F61 -> unidad | J35: ='Necesidades Trimestrales (2)'!AT61 -> 10281 | K35: ='Necesidades Trimestrales (2)'!AS61 -> 5 | L35: =+J35*K35 -> 51405 | M35: =+J35*K35 -> 51405
A36: 25 | C36: ='Necesidades Trimestrales (2)'!E63 -> COBAS DIMERO D X 100 det: Tipo ROCHE | H36: SI | I36: ='Necesidades Trimestrales (2)'!F63 -> UNIDAD | J36: ='Necesidades Trimestrales (2)'!AT63 -> 76002 | K36: ='Necesidades Trimestrales (2)'!AS63 -> 12 | L36: =+J36*K36 -> 912024 | M36: =+J36*K36 -> 912024
A37: 26 | C37: ='Necesidades Trimestrales (2)'!E64 -> COBAS ECO-D Tipo ROCHE | H37: SI | I37: ='Necesidades Trimestrales (2)'!F64 -> unidad | J37: ='Necesidades Trimestrales (2)'!AT64 -> 5842 | K37: ='Necesidades Trimestrales (2)'!AS64 -> 15 | L37: =+J37*K37 -> 87630 | M37: =+J37*K37 -> 87630
A38: 27 | C38: ='Necesidades Trimestrales (2)'!E65 -> COBAS FERRITINA X 250 det. TIPO ROCHE | H38: SI | I38: ='Necesidades Trimestrales (2)'!F65 -> UNIDAD | J38: ='Necesidades Trimestrales (2)'!AT65 -> 53999 | K38: ='Necesidades Trimestrales (2)'!AS65 -> 9 | L38: =+J38*K38 -> 485991 | M38: =+J38*K38 -> 485991
A39: 28 | C39: ='Necesidades Trimestrales (2)'!E66 -> COBAS SMS Tipo ROCHE | H39: SI | I39: ='Necesidades Trimestrales (2)'!F66 -> unidad | J39: ='Necesidades Trimestrales (2)'!AT66 -> 1099 | K39: ='Necesidades Trimestrales (2)'!AS66 -> 21 | L39: =+J39*K39 -> 23079 | M39: =+J39*K39 -> 23079
A40: 29 | C40: ='Necesidades Trimestrales (2)'!E67 -> Colestat Enzimatico AA LL 400 Ml (4x100 Ml) Tipo WIENER | H40: SI | I40: ='Necesidades Trimestrales (2)'!F67 -> unidad | J40: ='Necesidades Trimestrales (2)'!AT67 -> 3879 | K40: ='Necesidades Trimestrales (2)'!AS67 -> 40 | L40: =+J40*K40 -> 155160 | M40: =+J40*K40 -> 155160
A41: 30 | C41: ='Necesidades Trimestrales (2)'!E68 -> Creatinina Cinetica AA LL Tipo WIENER | H41: SI | I41: ='Necesidades Trimestrales (2)'!F68 -> unidad | J41: ='Necesidades Trimestrales (2)'!AT68 -> 3305 | K41: ='Necesidades Trimestrales (2)'!AS68 -> 20 | L41: =+J41*K41 -> 66100 | M41: =+J41*K41 -> 66100
A42: 31 | C42: ='Necesidades Trimestrales (2)'!E69 -> Creatinina DIRECTA Tipo WIENER | H42: SI | I42: ='Necesidades Trimestrales (2)'!F69 -> unidad | J42: ='Necesidades Trimestrales (2)'!AT69 -> 2308 | K42: ='Necesidades Trimestrales (2)'!AS69 -> 20 | L42: =+J42*K42 -> 46160 | M42: =+J42*K42 -> 46160
A43: 32 | C43: ='Necesidades Trimestrales (2)'!E73 -> Ez Cleanser x 100 Ml Tipo MINDRAY | H43: SI | I43: ='Necesidades Trimestrales (2)'!F73 -> unidad | J43: ='Necesidades Trimestrales (2)'!AT73 -> 7100 | K43: ='Necesidades Trimestrales (2)'!AS73 -> 20 | L43: =+J43*K43 -> 142000 | M43: =+J43*K43 -> 142000
...

Sheet APG
A1: EJERCICIO: | D1: 2021 | P1: AUTORIZACION PARA GASTAR
A4: JURISDICCIÓN: | G4: ='lab centr'!D3 -> 040 - Ministerio de Salud
A5: SAF: | G5: ='lab centr'!D4 -> 011 - Direccion Provincial de Administración - Ministerio de Salud
A6: UNIDAD EJECUTORA: | G6: ='lab centr'!D5 -> 468 - DIRECCION PROVINCIAL DE LABORATORIO
A7: DEPENDENCIA SOLICITANTE: | G7: ='lab centr'!D6 -> 468 - DIRECCION PROVINCIAL DE LABORATORIO
A8: AUTORIZACIÓN:
A9: Señor Jefe de Servicio Administrativo Financiero:
A10: Autorizo la realización de los trámites correspondientes, a fin de proveer a este Organismo los bienes que se detallan en Nota de pedido y Entrega N° 34/2021, afectando la erogación resultante a los créditos presupuestarios aprobados a favor de esta Unidad Ejecutora, conforme al siguiente detalle:
A12: IMPUTACIÓN PRESUPUESTARIA
A13: CÓDIGO | O13: DENOMINACIÓN DE LA PARTIDA PRESUPUESTARIA | Q13: IMPORTE
A14: PR | B14: SB | C14: PY | D14: AC | E14: OB | F14: UG | G14: FIN | H14: FUN | I14: I | J14: P | K14: P | L14: SubP | M14: M | N14: FF
A15: 62 | D15: 1 | F15: 4901 | G15: 3 | H15: 1 | I15: 2 | J15: 5 | K15: 1 | M15: 1 | N15: 1.1 | O15: COMPUESTOS QUIMICOS | Q15: =+'Necesidades Trimestrales (2)'!L145 -> 14972267
A23: TOTAL DE PESOS: CATORCE MILLONES NOVECIENTOS SETENTA Y DOS MIL DOSCIENTOS SESENTA Y SIETE con 00/100 | Q23: =SUM(Q15:Q22) -> 14972267
A25: JUSTIFICACIÓN:
A26: ='lab centr'!D8 -> Adquisicion del RUBRO REACTIVOS PARA LABORATORIO

Sheet bco sangr
A1: NOTA DE PEDIDO | J1: N° | K1: _19/21
A3: JURISDICCIÓN: | D3: 040 - Ministerio de Salud
A4: SAF: | D4: 011 - Direccion Provincial de Administración - Ministerio de Salud
A5: UNIDAD EJECUTORA: | D5: 747 - DIRECCION PROVINCIAL BANCO DE SANGRE
A6: DEPENDENCIA SOLICITANTE: | D6: 747 - DIRECCION PROVINCIAL BANCO DE SANGRE
A7: PERIODO UTILIZACIÓN: | D7: 3° TRIMESTRE
A8: OBJETO: | D8: Adquisicion del RUBRO REACTIVOS PARA LABORATORIO
A10: Ítem | B10: Codigo Item | C10: DESCRIPCIÓN | H10: Adjunta Detalle Técnico | I10: Unidad Medida | J10: Precio Unitario Estimado | K10: Cantidad Solicitada
A12: 1 | C12: ='Necesidades Trimestrales (2)'!E12 -> ALBUMINA BOVINA TIPO WIENER | H12: SI | I12: ='Necesidades Trimestrales (2)'!F12 -> UNIDAD | J12: ='Necesidades Trimestrales (2)'!AT12 -> 1251 | K12: ='Necesidades Trimestrales (2)'!AS12 -> 12 | L12: =+J12*K12 -> 15012
A13: 2 | C13: ='Necesidades Trimestrales (2)'!E17 -> ANTI-A MONOCLONAL- FRASCO 10 ML TIPO WIENER | H13: SI | I13: ='Necesidades Trimestrales (2)'!F17 -> UNIDAD | J13: ='Necesidades Trimestrales (2)'!AT17 -> 876 | K13: ='Necesidades Trimestrales (2)'!AS17 -> 100 | L13: =+J13*K13 -> 87600
A14: 3 | C14: ='Necesidades Trimestrales (2)'!E18 -> ANTI-AB MONOCLONAL- FRASCO 10 MLTIPO WIENER | H14: SI | I14: ='Necesidades Trimestrales (2)'!F18 -> UNIDAD | J14: ='Necesidades Trimestrales (2)'!AT18 -> 888 | K14: ='Necesidades Trimestrales (2)'!AS18 -> 100 | L14: =+J14*K14 -> 88800
A15: 4 | C15: ='Necesidades Trimestrales (2)'!E19 -> ANTI-B MONOCLONAL-FRASCOS 10 ML TIPO WIENER | H15: SI | I15: ='Necesidades Trimestrales (2)'!F19 -> UNIDAD | J15: ='Necesidades Trimestrales (2)'!AT19 -> 876 | K15: ='Necesidades Trimestrales (2)'!AS19 -> 100 | L15: =+J15*K15 -> 87600
A16: 5 | C16: ='Necesidades Trimestrales (2)'!E21 -> ANTI-D (RHO) MONOCLONAL-FRASCOS 10 ML TIPO WIENER | H16: SI | I16: ='Necesidades Trimestrales (2)'!F21 -> UNIDAD | J16: ='Necesidades Trimestrales (2)'!AT21 -> 1657 | K16: ='Necesidades Trimestrales (2)'!AS21 -> 100 | L16: =+J16*K16 -> 165700
A17: 6 | C17: ='Necesidades Trimestrales (2)'!E22 -> ANTIGENO FEBRIL BRUCELLA (HUDDLESON) | H17: SI | I17: ='Necesidades Trimestrales (2)'!F22 -> unidad | J17: ='Necesidades Trimestrales (2)'!AT22 -> 1321 | K17: 12 | L17: =+J17*K17 -> 15852
A18: 7 | C18: BIOZIMA CHAGAS x192 DET. | H18: SI | I18: ='Necesidades Trimestrales (2)'!F23 -> unidad | J18: 10577.85 | K18: 12 | L18: =+J18*K18 -> 126934.2
A19: 8 | C19: BIOZIMA CHAGAS RECOMBINANTES x192 DET. | H19: SI | I19: ='Necesidades Trimestrales (2)'!F24 -> unidad | J19: 11502.26 | K19: 12 | L19: =+J19*K19 -> 138027.12
A20: 9 | C20: ='Necesidades Trimestrales (2)'!E50 -> Buffer TIPO ABBOTT P/ EQUIPO ARCHITECT | H20: SI | I20: ='Necesidades Trimestrales (2)'!F50 -> CAJA | J20: ='Necesidades Trimestrales (2)'!AT50 -> 8300 | K20: ='Necesidades Trimestrales (2)'!AS50 -> 14 | L20: =+J20*K20 -> 116200
A21: 10 | C21: ='Necesidades Trimestrales (2)'!E54 -> Celdas de Reaccion TIPO ABBOTT P/ EQUIPO ARCHITECT | H21: SI | I21: ='Necesidades Trimestrales (2)'!F54 -> CAJA | J21: ='Necesidades Trimestrales (2)'!AT54 -> 11685 | K21: ='Necesidades Trimestrales (2)'!AS54 -> 1 | L21: =+J21*K21 -> 11685
A22: 11 | C22: ='Necesidades Trimestrales (2)'!E59 -> CHAGATEST ELISA LISADO-96DET. TIPO WIENER | H22: SI | I22: ='Necesidades Trimestrales (2)'!F59 -> UNIDAD | J22: ='Necesidades Trimestrales (2)'!AT59 -> 10206 | K22: ='Necesidades Trimestrales (2)'!AS59 -> 12 | L22: =+J22*K22 -> 122472
A23: 12 | C23: ='Necesidades Trimestrales (2)'!E60 -> CHAGATEST ELISA RECOMBINANTE (V4,0)-96 DET. TIPO WIENER | H23: SI | I23: ='Necesidades Trimestrales (2)'!F60 -> UNIDAD | J23: ='Necesidades Trimestrales (2)'!AT60 -> 11295 | K23: ='Necesidades Trimestrales (2)'!AS60 -> 12 | L23: =+J23*K23 -> 135540
A24: 13 | C24: ='Necesidades Trimestrales (2)'!E62 -> CMV CITOMEGALOVIRUS IGM METODO ELISA 96 DET. TIPO WIENER | H24: SI | I24: ='Necesidades Trimestrales (2)'!F62 -> UNIDAD | J24: ='Necesidades Trimestrales (2)'!AT62 -> 19749 | K24: ='Necesidades Trimestrales (2)'!AS62 -> 12 | L24: =+J24*K24 -> 236988
A25: 14 | C25: =+'Necesidades Trimestrales (2)'!E70 -> EQUIPOS COVIDAR IgG x192 det. Para equipo elisa | H25: SI | I25: ='Necesidades Trimestrales (2)'!F63 -> UNIDAD | J25: 19743.57 | K25: =+'Necesidades Trimestrales (2)'!M70 -> 12 | L25: =+J25*K25 -> 236922.84
A26: 15 | C26: ='Necesidades Trimestrales (2)'!E71 -> Equipo para la deteccion de Anti Hb Core, por metodo de Elisa en microplacas en equipos de 96 det. Monolisa HBc Plus | H26: SI | I26: ='Necesidades Trimestrales (2)'!F71 -> CAJA | J26: ='Necesidades Trimestrales (2)'!AT71 -> 20160 | K26: ='Necesidades Trimestrales (2)'!AS71 -> 16 | L26: =+J26*K26 -> 322560
A27: 16 | C27: ='Necesidades Trimestrales (2)'!E72 -> Equipos por metodo de Elisa para la deteccion simultanea anticuerpos y antigenos de virus de Hepatitis C por Elisa en microplaca recubierta con anticuerpos monoclonales anti caspide de HCV con antigenos reconvinantes de la region NS3 genotipos 1 y 3º y de la region no estructural NS4 y un peptido mutado de la region de la caspide del Virus HCV. En equipos de 96 det. Por metodologia EIA en microplacas con provision de reactivos, calibradores,materias descartable, buffers, liquido de lavado, y todo insumo necesario para suprocesamiento Monolisa HCV Ag- Ab Ultra v.2 | H27: SI | I27: ='Necesidades Trimestrales (2)'!F72 -> CAJA | J27: ='Necesidades Trimestrales (2)'!AT72 -> 36300 | K27: ='Necesidades Trimestrales (2)'!AS72 -> 16 | L27: =+J27*K27 -> 580800
A28: 17 | C28: ='Necesidades Trimestrales (2)'!E88 -> HEPATISIS B Ag Superficie tipo Wiener | H28: SI | I28: ='Necesidades Trimestrales (2)'!F88 -> unidad | J28: ='Necesidades Trimestrales (2)'!AT88 -> 16272 | K28: 12 | L28: =+J28*K28 -> 195264
A29: 18 | C29: ='Necesidades Trimestrales (2)'!E89 -> HEPATITIS C HCV ELISA 3º GEN. 96 DET. TIPO WIENER | H29: SI | I29: ='Necesidades Trimestrales (2)'!F89 -> UNIDAD | J29: ='Necesidades Trimestrales (2)'!AT89 -> 39806 | K29: ='Necesidades Trimestrales (2)'!AS89 -> 12 | L29: =+J29*K29 -> 477672
A30: 19 | C30: ='Necesidades Trimestrales (2)'!E90 -> HIV ELISA AG/AC 4° GENERACION -96 DET- | H30: SI | I30: ='Necesidades Trimestrales (2)'!F90 -> Unidad | J30: ='Necesidades Trimestrales (2)'!AT90 -> 23147 | K30: ='Necesidades Trimestrales (2)'!AS90 -> 48 | L30: =+J30*K30 -> 1111056
A31: 20 | C31: ='Necesidades Trimestrales (2)'!E91 -> HTLV 1 Y 2 ELISA-96DET. TIPO WIENER | H31: SI | I31: ='Necesidades Trimestrales (2)'!F91 -> UNIDAD | J31: ='Necesidades Trimestrales (2)'!AT91 -> 25747 | K31: ='Necesidades Trimestrales (2)'!AS91 -> 12 | L31: =+J31*K31 -> 308964
A32: 21 | C32: ='Necesidades Trimestrales (2)'!E92 -> HVC REACTIVO x 100 det TIPO ABBOTT P/ EQUIPO ARCHITECT | H32: SI | I32: ='Necesidades Trimestrales (2)'!F92 -> CAJA | J32: ='Necesidades Trimestrales (2)'!AT92 -> 50545 | K32: ='Necesidades Trimestrales (2)'!AS92 -> 3 | L32: =+J32*K32 -> 151635
A33: 22 | C33: ='Necesidades Trimestrales (2)'!E93 -> KIT PLASMAFERESIS 980 TIPO GRIFOLS | H33: SI | I33: ='Necesidades Trimestrales (2)'!F93 -> UNIDAD | J33: ='Necesidades Trimestrales (2)'!AT93 -> 35090 | K33: ='Necesidades Trimestrales (2)'!AS93 -> 24 | L33: =+J33*K33 -> 842160
A34: 23 | C34: ='Necesidades Trimestrales (2)'!E94 -> KITS PARA PLAQUETOFERESIS CON FILTRO 994/995 TIPO GRIFOLS | H34: SI | I34: ='Necesidades Trimestrales (2)'!F94 -> UNIDAD | J34: ='Necesidades Trimestrales (2)'!AT94 -> 35695 | K34: ='Necesidades Trimestrales (2)'!AS94 -> 72 | L34: =+J34*K34 -> 2570040
A35: 24 | C35: ='Necesidades Trimestrales (2)'!E101 -> PANEL IDENTISERA DIANA TIPO GRIFOLS | H35: SI | I35: ='Necesidades Trimestrales (2)'!F101 -> UNIDAD | J35: ='Necesidades Trimestrales (2)'!AT101 -> 29160 | K35: ='Necesidades Trimestrales (2)'!AS101 -> 9 | L35: =+J35*K35 -> 262440
A36: 25 | C36: ='Necesidades Trimestrales (2)'!E102 -> PANEL SARASCAN DIANA 2 TIPOS GRIFOLS | H36: SI | I36: ='Necesidades Trimestrales (2)'!F102 -> UNIDAD | J36: ='Necesidades Trimestrales (2)'!AT102 -> 22500 | K36: ='Necesidades Trimestrales (2)'!AS102 -> 9 | L36: =+J36*K36 -> 202500
A37: 26 | C37: ='Necesidades Trimestrales (2)'!E103 -> PANEL SERIGRUP A1/B TIPO GRIFOLS | H37: SI | I37: ='Necesidades Trimestrales (2)'!F103 -> UNIDAD | J37: ='Necesidades Trimestrales (2)'!AT103 -> 15588 | K37: ='Necesidades Trimestrales (2)'!AS103 -> 9 | L37: =+J37*K37 -> 140292
A38: 27 | C38: ='Necesidades Trimestrales (2)'!E104 -> PANEL SERO cyte 0,8% TIPOS GRIFOLS | H38: SI | I38: ='Necesidades Trimestrales (2)'!F104 -> UNIDAD | J38: ='Necesidades Trimestrales (2)'!AT104 -> 16500 | K38: ='Necesidades Trimestrales (2)'!AS104 -> 9 | L38: =+J38*K38 -> 148500
A39: 28 | C39: ='Necesidades Trimestrales (2)'!E107 -> Pre-trigger TIPO ABBOTT P/ EQUIPO ARCHITECT | H39: SI | I39: ='Necesidades Trimestrales (2)'!F107 -> CAJA | J39: ='Necesidades Trimestrales (2)'!AT107 -> 16980 | K39: ='Necesidades Trimestrales (2)'!AS107 -> 3 | L39: =+J39*K39 -> 50940
A40: 29 | C40: ='Necesidades Trimestrales (2)'!E114 -> SARS- COV-2 Igm Control TIPO ABBOTT P/ EQUIPO ARCHITECT | H40: SI | I40: ='Necesidades Trimestrales (2)'!F114 -> CAJA | J40: ='Necesidades Trimestrales (2)'!AT114 -> 17788 | K40: ='Necesidades Trimestrales (2)'!AS114 -> 1 | L40: =+J40*K40 -> 17788
A41: 30 | C41: ='Necesidades Trimestrales (2)'!E115 -> SARS-COV-2 IgG Reactivo x 100 det TIPO ABBOTT P/ EQUIPO ARCHITECT | H41: SI | I41: ='Necesidades Trimestrales (2)'!F115 -> CAJA | J41: ='Necesidades Trimestrales (2)'!AT115 -> 64700 | K41: ='Necesidades Trimestrales (2)'!AS115 -> 15 | L41: =+J41*K41 -> 970500
A42: 31 | C42: ='Necesidades Trimestrales (2)'!E116 -> SARS-COV-2 IgM Calibrador TIPO ABBOTT P/ EQUIPO ARCHITECT | H42: SI | I42: ='Necesidades Trimestrales (2)'!F116 -> CAJA | J42: ='Necesidades Trimestrales (2)'!AT116 -> 12540 | K42: ='Necesidades Trimestrales (2)'!AS116 -> 1 | L42: =+J42*K42 -> 12540
A43: 32 | C43: ='Necesidades Trimestrales (2)'!E117 -> Solucion ACD ( ANTICOAGULANTE PARA EQUIPO DE AFERESIS) TIPO GRIFOLS | H43: SI | I43: ='Necesidades Trimestrales (2)'!F117 -> UNIDAD | J43: ='Necesidades Trimestrales (2)'!AT117 -> 4350 | K43: ='Necesidades Trimestrales (2)'!AS117 -> 81 | L43: =+J43*K43 -> 352350
...

Sheet APG (3)
A1: EJERCICIO: | D1: 2021 | P1: AUTORIZACION PARA GASTAR
A4: JURISDICCIÓN: | G4: ='lab centr'!D3 -> 040 - Ministerio de Salud
A5: SAF: | G5: ='lab centr'!D4 -> 011 - Direccion Provincial de Administración - Ministerio de Salud
A6: UNIDAD EJECUTORA: | G6: 747 - DIRECCION PROVINCIAL BANCO DE SANGRE
A7: DEPENDENCIA SOLICITANTE: | G7: 747 - DIRECCION PROVINCIAL BANCO DE SANGRE
A8: AUTORIZACIÓN:
A9: Señor Jefe de Servicio Administrativo Financiero:
A10: Autorizo la realización de los trámites correspondientes, a fin de proveer a este Organismo los bienes que se detallan en Nota de pedido y Entrega N° 19/2021, afectando la erogación resultante a los créditos presupuestarios aprobados a favor de esta Unidad Ejecutora, conforme al siguiente detalle:
A12: IMPUTACIÓN PRESUPUESTARIA
A13: CÓDIGO | O13: DENOMINACIÓN DE LA PARTIDA PRESUPUESTARIA | Q13: IMPORTE
A14: PR | B14: SB | C14: PY | D14: AC | E14: OB | F14: UG | G14: FIN | H14: FUN | I14: I | J14: P | K14: P | L14: SubP | M14: M | N14: FF
A15: 27 | D15: 1 | F15: 4901 | G15: 3 | H15: 1 | I15: 2 | J15: 5 | K15: 1 | M15: 1 | N15: 1.1 | O15: COMPUESTOS QUIMICOS | Q15: =+'Necesidades Trimestrales (2)'!N145 -> 13507277
A23: TOTAL DE PESOS: TRECE MILLONES QUINIENTOS SIETE MIL DOSCIENTOS SETENTA Y SIETE con 16/100 | Q23: =SUM(Q15:Q22) -> 13507277
A25: JUSTIFICACIÓN:
A26: ='lab centr'!D8 -> Adquisicion del RUBRO REACTIVOS PARA LABORATORIO

Sheet CUR
A1: NOTA DE PEDIDO | J1: N° | K1: _13/21
A3: JURISDICCIÓN: | D3: 040 - Ministerio de Salud
A4: SAF: | D4: 011 - Direccion Provincial de Administración - Ministerio de Salud
A5: UNIDAD EJECUTORA: | D5: 160 - DIRECCION PROVINCIAL CENTRO UNICO DE REFERENCIA
A6: DEPENDENCIA SOLICITANTE: | D6: 160 - DIRECCION PROVINCIAL CENTRO UNICO DE REFERENCIA
A7: PERIODO UTILIZACIÓN: | D7: 3° TRIMESTRE
A8: OBJETO: | D8: Adquisicion del RUBRO REACTIVOS PARA LABORATORIO
A10: Ítem | B10: Codigo Item | C10: DESCRIPCIÓN | H10: Adjunta Detalle Técnico | I10: Unidad Medida | J10: Precio Unitario Estimado | K10: Cantidad Solicitada
A12: 1 | C12: ='Necesidades Trimestrales (2)'!E10 -> AGUA BIDESTILADA x 10 litros | H12: SI | I12: ='Necesidades Trimestrales (2)'!F10 -> BIDON | J12: ='Necesidades Trimestrales (2)'!AT10 -> 574 | K12: ='Necesidades Trimestrales (2)'!AS10 -> 10 | L12: =+J12*K12 -> 5740 | M12: =+J12*K12 -> 5740
A13: 2 | C13: ='Necesidades Trimestrales (2)'!E25 -> ARC ANTI HBC II CALIBRADOR TIPO ART. ABBOT | H13: SI | I13: ='Necesidades Trimestrales (2)'!F25 -> KIT | J13: ='Necesidades Trimestrales (2)'!AT25 -> 15850 | K13: ='Necesidades Trimestrales (2)'!AS25 -> 1 | L13: =+J13*K13 -> 15850 | M13: =+J13*K13 -> 15850
A14: 3 | C14: ='Necesidades Trimestrales (2)'!E26 -> ARC ANTI HBC II RGT X 100 DET. TIPO ART. ABBOT | H14: SI | I14: ='Necesidades Trimestrales (2)'!F26 -> KIT | J14: ='Necesidades Trimestrales (2)'!AT26 -> 36750 | K14: ='Necesidades Trimestrales (2)'!AS26 -> 2 | L14: =+J14*K14 -> 73500 | M14: =+J14*K14 -> 73500
A15: 4 | C15: ='Necesidades Trimestrales (2)'!E27 -> ARC ANTI HCV CALIBRADOR TIPO ART. ABBOT | H15: SI | I15: ='Necesidades Trimestrales (2)'!F27 -> KIT | J15: ='Necesidades Trimestrales (2)'!AT27 -> 15850 | K15: ='Necesidades Trimestrales (2)'!AS27 -> 1 | L15: =+J15*K15 -> 15850 | M15: =+J15*K15 -> 15850
A16: 5 | C16: ='Necesidades Trimestrales (2)'!E28 -> ARC ANTI HCV RGT X 100 DET. TIPO ART. ABBOT | H16: SI | I16: ='Necesidades Trimestrales (2)'!F28 -> KIT | J16: ='Necesidades Trimestrales (2)'!AT28 -> 71500 | K16: ='Necesidades Trimestrales (2)'!AS28 -> 2 | L16: =+J16*K16 -> 143000 | M16: =+J16*K16 -> 143000
A17: 6 | C17: ='Necesidades Trimestrales (2)'!E29 -> ARC BUFFER CONCENTRADO x 4 lts TIPO ART. ABBOT | H17: SI | I17: ='Necesidades Trimestrales (2)'!F29 -> BIDON | J17: ='Necesidades Trimestrales (2)'!AT29 -> 12550 | K17: ='Necesidades Trimestrales (2)'!AS29 -> 3 | L17: =+J17*K17 -> 37650 | M17: =+J17*K17 -> 37650
A18: 7 | C18: ='Necesidades Trimestrales (2)'!E30 -> ARC CELDAS DE REACCION TIPO ART. ABBOT | H18: SI | I18: ='Necesidades Trimestrales (2)'!F30 -> CAJA | J18: ='Necesidades Trimestrales (2)'!AT30 -> 28000 | K18: ='Necesidades Trimestrales (2)'!AS30 -> 3 | L18: =+J18*K18 -> 84000 | M18: =+J18*K18 -> 84000
A19: 8 | C19: ='Necesidades Trimestrales (2)'!E31 -> ARC CMV M CALIBRADOR TIPO ART. ABBOT | H19: SI | I19: ='Necesidades Trimestrales (2)'!F31 -> KIT | J19: ='Necesidades Trimestrales (2)'!AT31 -> 15039 | K19: ='Necesidades Trimestrales (2)'!AS31 -> 1 | L19: =+J19*K19 -> 15039 | M19: =+J19*K19 -> 15039
A20: 9 | C20: ='Necesidades Trimestrales (2)'!E32 -> ARC CMV M RGT X 100 TIPO ART. ABBOT | H20: SI | I20: ='Necesidades Trimestrales (2)'!F32 -> KIT | J20: ='Necesidades Trimestrales (2)'!AT32 -> 27595 | K20: ='Necesidades Trimestrales (2)'!AS32 -> 1 | L20: =+J20*K20 -> 27595 | M20: =+J20*K20 -> 27595
A21: 10 | C21: ='Necesidades Trimestrales (2)'!E33 -> ARC HBSAG CALIBRADOR TIPO ART. ABBOT | H21: SI | I21: ='Necesidades Trimestrales (2)'!F33 -> KIT | J21: ='Necesidades Trimestrales (2)'!AT33 -> 15850 | K21: ='Necesidades Trimestrales (2)'!AS33 -> 1 | L21: =+J21*K21 -> 15850 | M21: =+J21*K21 -> 15850
A22: 11 | C22: ='Necesidades Trimestrales (2)'!E34 -> ARC HBSAG RGT X 100 DET. TIPO ART. ABBOT | H22: SI | I22: ='Necesidades Trimestrales (2)'!F34 -> KIT | J22: ='Necesidades Trimestrales (2)'!AT34 -> 24480 | K22: ='Necesidades Trimestrales (2)'!AS34 -> 2 | L22: =+J22*K22 -> 48960 | M22: =+J22*K22 -> 48960
A23: 12 | C23: ='Necesidades Trimestrales (2)'!E35 -> ARC HIV COMBO CALIBRADOR TIPO ART. ABBOT | H23: SI | I23: ='Necesidades Trimestrales (2)'!F35 -> KIT | J23: ='Necesidades Trimestrales (2)'!AT35 -> 20240 | K23: ='Necesidades Trimestrales (2)'!AS35 -> 1 | L23: =+J23*K23 -> 20240 | M23: =+J23*K23 -> 20240
A24: 13 | C24: ='Necesidades Trimestrales (2)'!E36 -> ARC HIV COMBO RGT X 100 DET. TIPO ART. ABBOT | H24: SI | I24: ='Necesidades Trimestrales (2)'!F36 -> KIT | J24: ='Necesidades Trimestrales (2)'!AT36 -> 42239 | K24: ='Necesidades Trimestrales (2)'!AS36 -> 4 | L24: =+J24*K24 -> 168956 | M24: =+J24*K24 -> 168956
... A28: 17 | C28: ='Necesidades Trimestrales (2)'!E40 -> ARC TRIGGER x 4 lts TIPO ART. ABBOT | H28: SI | I28: ='Necesidades Trimestrales (2)'!F40 -> BIDON | J28: ='Necesidades Trimestrales (2)'!AT40 -> 11000 | K28: ='Necesidades Trimestrales (2)'!AS40 -> 2 | L28: =+J28*K28 -> 22000 | M28: =+J28*K28 -> 22000
A30: Costo total estimado:OCHOCIENTOS VEINTISEIS MIL TRESCIENTOS CUARENTA Y OCHO CON 00/100 | J30: =SUM(L12:L28) -> 826348 | M30: =SUM(M12:M29) -> 826348

Sheet APG (2)
A1: EJERCICIO: | D1: 2021 | P1: AUTORIZACION PARA GASTAR
A4: JURISDICCIÓN: | G4: ='[1]lab centr'!D3 -> 040 - Ministerio de Salud
A5: SAF: | G5: ='[1]lab centr'!D4 -> 011 - Direccion Provincial de Administración - Ministerio de Salud
A6: UNIDAD EJECUTORA: | G6: 160 - DIRECCION PROVINCIAL CENTRO UNICO DE REFERENCIA
A7: DEPENDENCIA SOLICITANTE: | G7: 160 - DIRECCION PROVINCIAL CENTRO UNICO DE REFERENCIA
A8: AUTORIZACIÓN:
A9: Señor Jefe de Servicio Administrativo Financiero:
A10: Autorizo la realización de los trámites correspondientes, a fin de proveer a este Organismo los bienes que se detallan en Nota de pedido y Entrega N° 13/2021, afectando la erogación resultante a los créditos presupuestarios aprobados a favor de esta Unidad Ejecutora, conforme al siguiente detalle:
A12: IMPUTACIÓN PRESUPUESTARIA
A13: CÓDIGO | O13: DENOMINACIÓN DE LA PARTIDA PRESUPUESTARIA | Q13: IMPORTE
A14: PR | B14: SB | C14: PY | D14: AC | E14: OB | F14: UG | G14: FIN | H14: FUN | I14: I | J14: P | K14: P | L14: SubP | M14: M | N14: FF
A15: 35 | D15: 1 | F15: 4901 | G15: 3 | H15: 1 | I15: 2 | J15: 5 | K15: 1 | M15: 1 | N15: 1.1 | O15: COMPUESTOS QUIMICOS | Q15: =826348-16700-481880 -> 327768
A16: 35 | D16: 2 | F16: 4901 | G16: 3 | H16: 1 | I16: 2 | J16: 5 | K16: 1 | M16: 1 | N16: 1.1 | O16: COMPUESTOS QUIMICOS | Q16: 16700
A17: 35 | D17: 3 | F17: 4901 | G17: 3 | H17: 1 | I17: 2 | J17: 5 | K17: 1 | M17: 1 | N17: 1.1 | O17: COMPUESTOS QUIMICOS | Q17: 481880
A23: TOTAL DE PESOS: OCHOCIENTOS VEINTISEIS MIL TRESCIENTOS CUARENTA Y OCHO CON 00/100 | Q23: =SUM(Q15:Q22) -> 826348
A25: JUSTIFICACIÓN:
A26: ='[1]lab centr'!D8 -> Adquisicion del RUBRO REACTIVOS PARA LABORATORIO
