Workbook

Sheet SAF 011 - NECESIDAD TRIMESTRAL
A1: 2022
B2: Pedido de Necesidades Trimestrales
A4: JURISDICCION: | C4: 040 - MINISTERIO DE SALUD
A5: SAF N°: | C5: 011 - DIRECCION PROVINCIAL DE ADMINISTRACION - MINISTERIO DE SALUD
A6: EJERCICIO: | C6: 2022
A7: TRIMESTRE: | C7: SEGUNDO
A9: ID | B9: CODIGO ITEM | C9: RUBRO DE COMPRA | D9: I.P.P. | E9: DESCRIPCION | F9: UNIDAD DE MEDIDA | G9: CANTIDAD TOTAL | H9: PRECIO UNITARIO ESTIMADO | I9: IMPORTE TOTAL ESTIMADO | J9: ESPECIFICACION TECNICA
A10: 1 | C10: PRODUCTOS MEDICO/FARMACEUTICOS/LAB. | D10: 2.5.1 | E10: ACIDO ACETICO GLACIAL 6% P/V 1000 mL TIPO BIOPACK | F10: UNIDAD | G10: 5 | H10: 850 | I10: 4250
A11: 2 | C11: PRODUCTOS MEDICO/FARMACEUTICOS/LAB. | D11: 2.5.1 | E11: ACIDO CLORHIDRICO SOLUCIÓN 0.5 MOL/L (0,5 N) 1000 ML TIPO BIOPACK | F11: UNIDAD | G11: 3 | H11: 1900 | I11: 5700
A12: 3 | C12: PRODUCTOS MEDICO/FARMACEUTICOS/LAB. | D12: 2.5.1 | E12: ACIDO SULFURICO SOLUCIÓN 1 N (0.5 MOL/L) 1000 ML TIPO BIOPACK | F12: UNIDAD | G12: 5 | H12: 2000 | I12: 10000
A13: 4 | C13: PRODUCTOS MEDICO/FARMACEUTICOS/LAB. | D13: 2.5.1 | E13: AGAR PARA COLIFORMES PARA MICROBIOLOGÍA CHROMOCULT® 500 GR TIPO MERCK | F13: UNIDAD | G13: 2 | H13: 185000 | I13: 370000
A14: 5 | C14: PRODUCTOS MEDICO/FARMACEUTICOS/LAB. | D14: 2.5.1 | E14: AGAR TBX PARA MICROBIOLOGÍA CHROMOCULT® 500 GR TIPO MERCK | F14: UNIDAD | G14: 3 | H14: 97000 | I14: 291000
A15: 6 | C15: PRODUCTOS MEDICO/FARMACEUTICOS/LAB. | D15: 2.5.1 | E15: AGUA BIDESTILADA X 5 LITROS | F15: BIDON | G15: 10 | H15: 574 | I15: 5740
A16: 7 | C16: PRODUCTOS MEDICO/FARMACEUTICOS/LAB. | D16: 2.5.1. | E16: ALBUMINA AA 6X 120 ML Tipo WIENER | F16: CAJA | G16: 5 | H16: 4824 | I16: 24120
A17: 8 | C17: PRODUCTOS MEDICO/FARMACEUTICOS/LAB. | D17: 2.5.1. | E17: ALBUMINA BOVINA al 30% Tipo WIENER | F17: UNIDAD | G17: 12 | H17: 1251 | I17: 15012
A18: 9 | C18: PRODUCTOS MEDICO/FARMACEUTICOS/LAB. | D18: 2.5.1. | E18: ALCOHOL METILICO X 1 L TIPO CICARELLI | F18: BOTELLA | G18: 50 | H18: 2974 | I18: 148700
A19: 10 | C19: PRODUCTOS MEDICO/FARMACEUTICOS/LAB. | D19: 2.5.1. | E19: ALP 405 AA LIQUIDA 100 ML Tipo WIENER | F19: CAJA | G19: 20 | H19: 3523 | I19: 70460
A20: 11 | C20: PRODUCTOS MEDICO/FARMACEUTICOS/LAB. | D20: 2.5.1. | E20: AMILASA 405 AA LIQUIDA 3X10 ML (30 ML) Tipo WIENER | F20: CAJA | G20: 20 | H20: 7709 | I20: 154180
A21: 12 | C21: PRODUCTOS MEDICO/FARMACEUTICOS/LAB. | D21: 2.5.1 | E21: ANIDRIDO ACÉTICO X 1000 ML TIPO CICARILLI | F21: UNIDAD | G21: 4 | H21: 2500 | I21: 10000
... A172: 163 | C172: PRODUCTOS MEDICO/FARMACEUTICOS/LAB. | D172: 2.5.1. | E172: XS LYSE (LISANTE PARA COUNTER XS 20) x 200 ML Tipo WIENER | F172: BOTELLA | G172: 5 | H172: 9540 | I172: 47700
E173: TOTAL RUBRO REACTIVOS PARA LABORATORIO | I173: =SUM(I10:I172) -> 58933705
C176: DETALLE TECNICO Y ESPECIFICACIONES | D176: ANEXO 1-Para oferentes de la Provincia de Catamarca deberán presentar Habilitación Provincial para comercializar el producto que cotizan. 2-Para el resto de oferentes deberán presentar Certificado de Inscripción de ANMAT vigente al momento de la oferta, el mismo deberá ser correspondiente al objeto de la contratación y de encontrarse vencido adjuntar la solicitud de renovación. 3-No se aceptarán ofertas de productos no registrados y autorizada su venta por ANMAT. Se deberá especificar en cada ítem de la propuesta, marca y número de certificado otorgado por dicho ente regulador. 4-Los productos deberán tener un vencimiento posterior a doce (12) meses a partir de la fecha de su recepción.
C178: Plazos de entrega | D178: veinte (20) dias habiles
C180: Lugares de Entrega: | D180: ITEMS 7, 9 al 11, 13 (20 unid), 14 (10 unid), 15 (20 unid), 18, 35, 36, 43, 45, 48 al 51, 53, 54, 57 al 62, 67, 73 al 81, 90 al 92, 95 al 98, 101, 108, 113, 119, 120, 124, 125, 131, 135 al 137, 140, 141, 145, 147, 150 al 157, 158 (20 unid), 159 al 163 - DIR. PROV. DE LABORATORIO - CHACABUCO N° 169 - en el horario de 8:00hs a 12:00hs de lunes a viernes
D181: ITEMS 8, 13 (100 unid), 14 (100 unid) 15 (100 unid) 16, 17, 37 al 39, 44, 46, 47, 52, 63 al 66, 68 al 70, 82, 83, 85 al 87, 93, 94, 109 al 112, 118, 126 al 130, 133, 134, 138, 142 al 144, 148, 149, 158 (12 unid) - DIR. PROV. BANCO DE SANGRE - BOTO GARAY N° 500 - en el horario de 8:00hs a 12:00hs de lunes a viernes
D182: ITEMS 1 al 5, 12, 40 al 42, 55, 56, 71, 72, 84, 88, 89, 99 al 107, 114 al 117, 121 al 123, 132, 139, 146 - DIR. PROV. SALUD Y MEDIO AMBIENTE - OCAMPO N° 257 en el horario de 8:00hs a 12:00hs de lunes a viernes
D183: ITEMS 06, 19 al 34 - DIR. PROV. CENTRO UNICO DE REFERENCIA - JULIO HERRERA N° 250 en el horario de 8:00hs a 12:00hs de lunes a viernes
C185: Calidad Minima esperada
C187: Mantenimiento | D187: cuarenta y cinco (45) días

Sheet NP DPLAB
A1: NOTA DE PEDIDO | J1: N° | K1: 06/2022
A3: JURISDICCIÓN: | D3: 040 - MINISTERIO DE SALUD
A4: SAF: | D4: 011 - DIRECCION PROVINCIAL DE ADMINISTRACION DEL MINISTERIO DE SALUD
A5: UNIDAD EJECUTORA: | D5: 468 - DIRECCION PROVINCIAL DE LABORATORIO
A6: DEPENDENCIA SOLICITANTE: | D6: 468 - DIRECCION PROVINCIAL DE LABORATORIO
A7: PERIODO UTILIZACIÓN: | D7: TRES (3) MESES
A8: OBJETO: | D8: ADQUISICION DEL RUBRO REACTIVOS PARA LABORATORIO
A10: Ítem | B10: Codigo Item | C10: DESCRIPCIÓN | H10: Adjunta Detalle Técnico | I10: Unidad Medida | J10: Precio Unitario Estimado | K10: Cantidad Solicitada
A12: 1 | C12: ='SAF 011 - NECESIDAD TRIMESTRAL'!E16 -> ALBUMINA AA 6X 120 ML Tipo WIENER | H12: NO | I12: ='SAF 011 - NECESIDAD TRIMESTRAL'!F16 -> CAJA | J12: ='SAF 011 - NECESIDAD TRIMESTRAL'!H16 -> 4824 | K12: ='SAF 011 - NECESIDAD TRIMESTRAL'!#REF! -> #REF!
A13: 2 | C13: ='SAF 011 - NECESIDAD TRIMESTRAL'!E18 -> ALCOHOL METILICO X 1 L TIPO CICARELLI | H13: NO | I13: ='SAF 011 - NECESIDAD TRIMESTRAL'!F18 -> BOTELLA | J13: ='SAF 011 - NECESIDAD TRIMESTRAL'!H18 -> 2974 | K13: ='SAF 011 - NECESIDAD TRIMESTRAL'!#REF! -> #REF!
A14: 3 | C14: ='SAF 011 - NECESIDAD TRIMESTRAL'!E19 -> ALP 405 AA LIQUIDA 100 ML Tipo WIENER | H14: NO | I14: ='SAF 011 - NECESIDAD TRIMESTRAL'!F19 -> CAJA | J14: ='SAF 011 - NECESIDAD TRIMESTRAL'!H19 -> 3523 | K14: ='SAF 011 - NECESIDAD TRIMESTRAL'!#REF! -> #REF!
A15: 4 | C15: ='SAF 011 - NECESIDAD TRIMESTRAL'!E20 -> AMILASA 405 AA LIQUIDA 3X10 ML (30 ML) Tipo WIENER | H15: NO | I15: ='SAF 011 - NECESIDAD TRIMESTRAL'!F20 -> CAJA | J15: ='SAF 011 - NECESIDAD TRIMESTRAL'!H20 -> 7709 | K15: ='SAF 011 - NECESIDAD TRIMESTRAL'!#REF! -> #REF!
A16: 5 | C16: ='SAF 011 - NECESIDAD TRIMESTRAL'!E22 -> ANTI A MONOCLONAL FRASCO X 10 ML Tipo WIENER | H16: NO | I16: ='SAF 011 - NECESIDAD TRIMESTRAL'!F22 -> FRASCO | J16: ='SAF 011 - NECESIDAD TRIMESTRAL'!H22 -> 1434 | K16: ='SAF 011 - NECESIDAD TRIMESTRAL'!#REF! -> #REF!
A17: 6 | C17: ='SAF 011 - NECESIDAD TRIMESTRAL'!E23 -> ANTI B MONOCLONAL FRASCO X 10 ML Tipo WIENER | H17: NO | I17: ='SAF 011 - NECESIDAD TRIMESTRAL'!F23 -> FRASCO | J17: ='SAF 011 - NECESIDAD TRIMESTRAL'!H23 -> 1434 | K17: ='SAF 011 - NECESIDAD TRIMESTRAL'!#REF! -> #REF!
A18: 7 | C18: ='SAF 011 - NECESIDAD TRIMESTRAL'!E24 -> ANTI D(RHO) MONOCLONAL FRASCO X 10 ML Tipo WIENER | H18: NO | I18: ='SAF 011 - NECESIDAD TRIMESTRAL'!F24 -> FRASCO | J18: ='SAF 011 - NECESIDAD TRIMESTRAL'!H24 -> 2713 | K18: ='SAF 011 - NECESIDAD TRIMESTRAL'!#REF! -> #REF!
A19: 8 | C19: ='SAF 011 - NECESIDAD TRIMESTRAL'!E27 -> APTT TEST 6X25 ML (150 DET) TIPO WIENER | H19: NO | I19: ='SAF 011 - NECESIDAD TRIMESTRAL'!F27 -> CAJA | J19: ='SAF 011 - NECESIDAD TRIMESTRAL'!H27 -> 8949 | K19: ='SAF 011 - NECESIDAD TRIMESTRAL'!#REF! -> #REF!
A20: 9 | C20: ='SAF 011 - NECESIDAD TRIMESTRAL'!E44 -> ARTRITEST DIRECTO 50 DET. Tipo WIENER | H20: NO | I20: ='SAF 011 - NECESIDAD TRIMESTRAL'!F44 -> UNIDAD | J20: ='SAF 011 - NECESIDAD TRIMESTRAL'!H44 -> 2758 | K20: ='SAF 011 - NECESIDAD TRIMESTRAL'!#REF! -> #REF!
A21: 10 | C21: ='SAF 011 - NECESIDAD TRIMESTRAL'!E45 -> ASO LATEX 50 DET Tipo WIENER | H21: NO | I21: ='SAF 011 - NECESIDAD TRIMESTRAL'!F45 -> UNIDAD | J21: ='SAF 011 - NECESIDAD TRIMESTRAL'!H45 -> 5775 | K21: ='SAF 011 - NECESIDAD TRIMESTRAL'!#REF! -> #REF!
A22: 11 | C22: ='SAF 011 - NECESIDAD TRIMESTRAL'!E52 -> CASSETTE SENSOR 25 DET. OSMETECH OPTI CCA, Tipo OPTI MEDICAL "E-Glu" | H22: NO | I22: ='SAF 011 - NECESIDAD TRIMESTRAL'!F52 -> CASSETTE | J22: ='SAF 011 - NECESIDAD TRIMESTRAL'!H52 -> 73440 | K22: ='SAF 011 - NECESIDAD TRIMESTRAL'!#REF! -> #REF!
A23: 12 | C23: ='SAF 011 - NECESIDAD TRIMESTRAL'!E54 -> CELLPACK PK-30L x 20 LITROS Tipo SYSMEX | H23: NO | I23: ='SAF 011 - NECESIDAD TRIMESTRAL'!F54 -> BIDON | J23: ='SAF 011 - NECESIDAD TRIMESTRAL'!H54 -> 11620 | K23: ='SAF 011 - NECESIDAD TRIMESTRAL'!#REF! -> #REF!
A24: 13 | C24: ='SAF 011 - NECESIDAD TRIMESTRAL'!E57 -> CK-MB CONTROL 3 NIVELES 3x3 Tipo WIENER | H24: NO | I24: ='SAF 011 - NECESIDAD TRIMESTRAL'!F57 -> CAJA | J24: ='SAF 011 - NECESIDAD TRIMESTRAL'!H57 -> 5927 | K24: ='SAF 011 - NECESIDAD TRIMESTRAL'!#REF! -> #REF!
A25: 14 | C25: ='SAF 011 - NECESIDAD TRIMESTRAL'!E58 -> CK-MB NAC UV UNITEST 19 DET x 2,5-ICONTROL Tipo WIENER | H25: NO | I25: ='SAF 011 - NECESIDAD TRIMESTRAL'!F58 -> UNIDAD | J25: ='SAF 011 - NECESIDAD TRIMESTRAL'!H58 -> 19623 | K25: ='SAF 011 - NECESIDAD TRIMESTRAL'!#REF! -> #REF!
A26: 15 | C26: ='SAF 011 - NECESIDAD TRIMESTRAL'!E59 -> CK-NAC UV AA liquida 120 ML Tipo WIENER | H26: NO | I26: ='SAF 011 - NECESIDAD TRIMESTRAL'!F59 -> UNIDAD | J26: ='SAF 011 - NECESIDAD TRIMESTRAL'!H59 -> 15166 | K26: ='SAF 011 - NECESIDAD TRIMESTRAL'!#REF! -> #REF!
A27: 16 | C27: ='SAF 011 - NECESIDAD TRIMESTRAL'!E60 -> CK-NAC UV unitest 50 ML (20x2,5 ML) Tipo WIENER | H27: NO | I27: ='SAF 011 - NECESIDAD TRIMESTRAL'!F60 -> UNIDAD | J27: ='SAF 011 - NECESIDAD TRIMESTRAL'!H60 -> 9191 | K27: ='SAF 011 - NECESIDAD TRIMESTRAL'!#REF! -> #REF!
A28: 17 | C28: ='SAF 011 - NECESIDAD TRIMESTRAL'!E62 -> CMV G x 60dets. MINIVIDAS BIOMERIEUX | H28: NO | I28: ='SAF 011 - NECESIDAD TRIMESTRAL'!F62 -> CAJA | J28: ='SAF 011 - NECESIDAD TRIMESTRAL'!H62 -> 40594 | K28: ='SAF 011 - NECESIDAD TRIMESTRAL'!#REF! -> #REF!
A29: 18 | C29: ='SAF 011 - NECESIDAD TRIMESTRAL'!E63 -> CMV M x 60dets. MINIVIDAS BIOMERIEUX | H29: NO | I29: ='SAF 011 - NECESIDAD TRIMESTRAL'!F63 -> CAJA | J29: ='SAF 011 - NECESIDAD TRIMESTRAL'!H63 -> 37558 | K29: ='SAF 011 - NECESIDAD TRIMESTRAL'!#REF! -> #REF!
A30: 19 | C30: ='SAF 011 - NECESIDAD TRIMESTRAL'!E66 -> COLESTEROL 2 X 500 ML TIPO WIENER | H30: NO | I30: ='SAF 011 - NECESIDAD TRIMESTRAL'!F66 -> BOTELLA | J30: ='SAF 011 - NECESIDAD TRIMESTRAL'!H66 -> 11564 | K30: ='SAF 011 - NECESIDAD TRIMESTRAL'!#REF! -> #REF!
A31: 20 | C31: ='SAF 011 - NECESIDAD TRIMESTRAL'!E67 -> COLINESTERASA AA 78 ML Tipo WIENER | H31: NO | I31: ='SAF 011 - NECESIDAD TRIMESTRAL'!F67 -> UNIDAD | J31: ='SAF 011 - NECESIDAD TRIMESTRAL'!H67 -> 15800 | K31: ='SAF 011 - NECESIDAD TRIMESTRAL'!#REF! -> #REF!
A32: 21 | C32: ='SAF 011 - NECESIDAD TRIMESTRAL'!E68 -> CONTROL DE HEMATOLOGIA PARA SYSMEX | H32: NO | I32: ='SAF 011 - NECESIDAD TRIMESTRAL'!F68 -> CAJA | J32: ='SAF 011 - NECESIDAD TRIMESTRAL'!H68 -> 17075 | K32: ='SAF 011 - NECESIDAD TRIMESTRAL'!#REF! -> #REF!
A33: 22 | C33: ='SAF 011 - NECESIDAD TRIMESTRAL'!E69 -> CONTROL LIQUIDO TRI-NIVEL, OPTI CHECK, OSMETECH | H33: NO | I33: ='SAF 011 - NECESIDAD TRIMESTRAL'!F69 -> CAJA | J33: ='SAF 011 - NECESIDAD TRIMESTRAL'!H69 -> 40770 | K33: ='SAF 011 - NECESIDAD TRIMESTRAL'!#REF! -> #REF!
A34: 23 | C34: ='SAF 011 - NECESIDAD TRIMESTRAL'!E70 -> DETERGENTE CONCENTRADO (CD80) | H34: NO | I34: ='SAF 011 - NECESIDAD TRIMESTRAL'!F70 -> UNIDAD | J34: ='SAF 011 - NECESIDAD TRIMESTRAL'!H70 -> 39210 | K34: ='SAF 011 - NECESIDAD TRIMESTRAL'!#REF! -> #REF!
A35: 24 | C35: ='SAF 011 - NECESIDAD TRIMESTRAL'!E71 -> DETERGENTE NO IONICO X 500 ML TIPO WIENER | H35: NO | I35: ='SAF 011 - NECESIDAD TRIMESTRAL'!F71 -> BOTELLA | J35: ='SAF 011 - NECESIDAD TRIMESTRAL'!H71 -> 16800 | K35: ='SAF 011 - NECESIDAD TRIMESTRAL'!#REF! -> #REF!
A36: 25 | C36: ='SAF 011 - NECESIDAD TRIMESTRAL'!E76 -> DIESTRO TRILEVEL | H36: NO | I36: ='SAF 011 - NECESIDAD TRIMESTRAL'!F76 -> CAJA | J36: ='SAF 011 - NECESIDAD TRIMESTRAL'!H76 -> 53980 | K36: ='SAF 011 - NECESIDAD TRIMESTRAL'!#REF! -> #REF!
A37: 26 | C37: ='SAF 011 - NECESIDAD TRIMESTRAL'!E82 -> FORMOL X 1 L TIPO BIOPUR | H37: NO | I37: ='SAF 011 - NECESIDAD TRIMESTRAL'!F82 -> UNIDAD | J37: ='SAF 011 - NECESIDAD TRIMESTRAL'!H82 -> 6500 | K37: ='SAF 011 - NECESIDAD TRIMESTRAL'!#REF! -> #REF!
A38: 27 | C38: ='SAF 011 - NECESIDAD TRIMESTRAL'!E83 -> FOSFATASA ALCALINA Optimizada 200 DET. Tipo WIENER | H38: NO | I38: ='SAF 011 - NECESIDAD TRIMESTRAL'!F83 -> CAJA | J38: ='SAF 011 - NECESIDAD TRIMESTRAL'!H83 -> 7300 | K38: ='SAF 011 - NECESIDAD TRIMESTRAL'!#REF! -> #REF!
A39: 28 | C39: ='SAF 011 - NECESIDAD TRIMESTRAL'!E84 -> GAMMA G-test CINETICA AA Tipo WIENER | H39: NO | I39: ='SAF 011 - NECESIDAD TRIMESTRAL'!F84 -> CAJA | J39: ='SAF 011 - NECESIDAD TRIMESTRAL'!H84 -> 5896 | K39: ='SAF 011 - NECESIDAD TRIMESTRAL'!#REF! -> #REF!
A40: 29 | C40: ='SAF 011 - NECESIDAD TRIMESTRAL'!E85 -> g-G-test CINETICA AA LIQUIDA 100 ML Tipo WIENER | H40: NO | I40: ='SAF 011 - NECESIDAD TRIMESTRAL'!F85 -> CAJA | J40: ='SAF 011 - NECESIDAD TRIMESTRAL'!H85 -> 4896 | K40: ='SAF 011 - NECESIDAD TRIMESTRAL'!#REF! -> #REF!
A41: 30 | C41: ='SAF 011 - NECESIDAD TRIMESTRAL'!E86 -> GLUCOCURVE SDA 75 GR X 10 SOBRES Tipo GLUCOCURVE | H41: NO | I41: ='SAF 011 - NECESIDAD TRIMESTRAL'!F86 -> CAJA | J41: ='SAF 011 - NECESIDAD TRIMESTRAL'!H86 -> 993 | K41: ='SAF 011 - NECESIDAD TRIMESTRAL'!#REF! -> #REF!
A42: 31 | C42: ='SAF 011 - NECESIDAD TRIMESTRAL'!E87 -> GOT (AST) UV AA liquida 200 ML Tipo WIENER | H42: NO | I42: ='SAF 011 - NECESIDAD TRIMESTRAL'!F87 -> CAJA | J42: ='SAF 011 - NECESIDAD TRIMESTRAL'!H87 -> 7268 | K42: ='SAF 011 - NECESIDAD TRIMESTRAL'!#REF! -> #REF!
A43: 32 | C43: ='SAF 011 - NECESIDAD TRIMESTRAL'!E88 -> GPT (ALT) UV AA liquida 200 ML Tipo WIENER | H43: NO | I43: ='SAF 011 - NECESIDAD TRIMESTRAL'!F88 -> CAJA | J43: ='SAF 011 - NECESIDAD TRIMESTRAL'!H88 -> 7268 | K43: ='SAF 011 - NECESIDAD TRIMESTRAL'!#REF! -> #REF!
...

Sheet APG DPLAB
A1: EJERCICIO: | D1: 2022 | P1: AUTORIZACION PARA GASTAR
A4: JURISDICCIÓN: | G4: ='NP DPLAB'!D3 -> 040 - MINISTERIO DE SALUD
A5: SAF: | G5: ='NP DPLAB'!D4 -> 011 - DIRECCION PROVINCIAL DE ADMINISTRACION DEL MINISTERIO DE SALUD
A6: UNIDAD EJECUTORA: | G6: ='NP DPLAB'!D5 -> 468 - DIRECCION PROVINCIAL DE LABORATORIO
A7: DEPENDENCIA SOLICITANTE: | G7: ='NP DPLAB'!D6 -> 468 - DIRECCION PROVINCIAL DE LABORATORIO
A8: AUTORIZACIÓN:
A9: Señor Director de Administración o Titular del Servicio Administrativo Financiero:
A10: Autorizo la realización de los trámites correspondientes, a fin de proveer a este Organismo los bienes, servicios o ejecución de obras públicas que se detallan en Nota de Pedido N° 06/2022 , afectando la erogación resultante a los créditos presupuestarios aprobados a favor de esta Unidad Ejecutora, conforme al siguiente detalle:
A12: IMPUTACIÓN PRESUPUESTARIA
A13: CÓDIGO | O13: DENOMINACIÓN DE LA PARTIDA PRESUPUESTARIA | Q13: IMPORTE
A14: PR | B14: SB | C14: PY | D14: AC | E14: OB | F14: UG | G14: FIN | H14: FUN | I14: I | J14: P | K14: P | L14: SubP | M14: M | N14: FF
A15: 62 | D15: 1 | F15: 4901 | G15: 3 | H15: 1 | I15: 2 | J15: 5 | K15: 1 | M15: 1 | N15: 1.1 | O15: COMPUESTOS QUIMICOS | Q15: ='NP DPLAB'!J83 -> #REF!
A38: TOTAL DE PESOS: TREINTA Y DOS MILLONES CUATROCIENTOS TRECE MIL CUATROCIENTOS SETENTA Y NUEVE CON 00/100.- | Q38: =SUM(Q15:Q37) -> #REF!
A40: JUSTIFICACIÓN:
A41: ='NP DPLAB'!D8 -> ADQUISICION DEL RUBRO REACTIVOS PARA LABORATORIO

Sheet NP DPBS
A1: NOTA DE PEDIDO | J1: N° | K1: 09/2022
A3: JURISDICCIÓN: | D3: 040 - MINISTERIO DE SALUD
A4: SAF: | D4: 011 - DIRECCION PROVINCIAL DE ADMINISTRACION DEL MINISTERIO DE SALUD
A5: UNIDAD EJECUTORA: | D5: 747 - DIRECCION PROVINCIAL BANCO DE SANGRE
A6: DEPENDENCIA SOLICITANTE: | D6: 747 - DIRECCION PROVINCIAL BANCO DE SANGRE
A7: PERIODO UTILIZACIÓN: | D7: TRES (3) MESES
A8: OBJETO: | D8: ADQUISICION DEL RUBRO REACTIVOS PARA LABORATORIO
A10: Ítem | B10: Codigo Item | C10: DESCRIPCIÓN | H10: Adjunta Detalle Técnico | I10: Unidad Medida | J10: Precio Unitario Estimado | K10: Cantidad Solicitada
A12: 1 | C12: ='SAF 011 - NECESIDAD TRIMESTRAL'!E17 -> ALBUMINA BOVINA al 30% Tipo WIENER | H12: NO | I12: ='SAF 011 - NECESIDAD TRIMESTRAL'!F17 -> UNIDAD | J12: ='SAF 011 - NECESIDAD TRIMESTRAL'!H17 -> 1251 | K12: ='SAF 011 - NECESIDAD TRIMESTRAL'!#REF! -> #REF!
A13: 2 | C13: ='SAF 011 - NECESIDAD TRIMESTRAL'!E22 -> ANTI A MONOCLONAL FRASCO X 10 ML Tipo WIENER | H13: NO | I13: ='SAF 011 - NECESIDAD TRIMESTRAL'!F22 -> FRASCO | J13: ='SAF 011 - NECESIDAD TRIMESTRAL'!H22 -> 1434 | K13: ='SAF 011 - NECESIDAD TRIMESTRAL'!#REF! -> #REF!
A14: 3 | C14: ='SAF 011 - NECESIDAD TRIMESTRAL'!E23 -> ANTI B MONOCLONAL FRASCO X 10 ML Tipo WIENER | H14: NO | I14: ='SAF 011 - NECESIDAD TRIMESTRAL'!F23 -> FRASCO | J14: ='SAF 011 - NECESIDAD TRIMESTRAL'!H23 -> 1434 | K14: ='SAF 011 - NECESIDAD TRIMESTRAL'!#REF! -> #REF!
A15: 4 | C15: ='SAF 011 - NECESIDAD TRIMESTRAL'!E24 -> ANTI D(RHO) MONOCLONAL FRASCO X 10 ML Tipo WIENER | H15: NO | I15: ='SAF 011 - NECESIDAD TRIMESTRAL'!F24 -> FRASCO | J15: ='SAF 011 - NECESIDAD TRIMESTRAL'!H24 -> 2713 | K15: ='SAF 011 - NECESIDAD TRIMESTRAL'!#REF! -> #REF!
A16: 5 | C16: ='SAF 011 - NECESIDAD TRIMESTRAL'!E25 -> ANTI-AB MONOCLONAL- FRASCO 10 ML TIPO WIENER | H16: NO | I16: ='SAF 011 - NECESIDAD TRIMESTRAL'!F25 -> UNIDAD | J16: ='SAF 011 - NECESIDAD TRIMESTRAL'!H25 -> 888 | K16: ='SAF 011 - NECESIDAD TRIMESTRAL'!#REF! -> #REF!
A17: 6 | C17: ='SAF 011 - NECESIDAD TRIMESTRAL'!E26 -> ANTIGENO FEBRIL BRUCELLA (HUDDLESON 1 X 5 ML.) | H17: NO | I17: ='SAF 011 - NECESIDAD TRIMESTRAL'!F26 -> UNIDAD | J17: ='SAF 011 - NECESIDAD TRIMESTRAL'!H26 -> 1184 | K17: ='SAF 011 - NECESIDAD TRIMESTRAL'!#REF! -> #REF!
A18: 7 | C18: ='SAF 011 - NECESIDAD TRIMESTRAL'!E46 -> Biozima chagas reconvinante x 192 Determinaciones. Tipo Lemos | H18: NO | I18: ='SAF 011 - NECESIDAD TRIMESTRAL'!F46 -> CAJA | J18: ='SAF 011 - NECESIDAD TRIMESTRAL'!H46 -> 11502.26 | K18: ='SAF 011 - NECESIDAD TRIMESTRAL'!#REF! -> #REF!
A19: 8 | C19: ='SAF 011 - NECESIDAD TRIMESTRAL'!E47 -> Biozima chagas x 192 Determibaciones. Tipo Lemos | H19: NO | I19: ='SAF 011 - NECESIDAD TRIMESTRAL'!F47 -> CAJA | J19: ='SAF 011 - NECESIDAD TRIMESTRAL'!H47 -> 10577.85 | K19: ='SAF 011 - NECESIDAD TRIMESTRAL'!#REF! -> #REF!
A20: 9 | C20: ='SAF 011 - NECESIDAD TRIMESTRAL'!E48 -> Buffer TIPO ABBOTT | H20: NO | I20: ='SAF 011 - NECESIDAD TRIMESTRAL'!F48 -> CAJA | J20: ='SAF 011 - NECESIDAD TRIMESTRAL'!H48 -> 8300 | K20: ='SAF 011 - NECESIDAD TRIMESTRAL'!#REF! -> #REF!
A21: 10 | C21: ='SAF 011 - NECESIDAD TRIMESTRAL'!E53 -> Celdas de Reaccion TIPO ABBOTT | H21: NO | I21: ='SAF 011 - NECESIDAD TRIMESTRAL'!F53 -> CAJA | J21: ='SAF 011 - NECESIDAD TRIMESTRAL'!H53 -> 11685 | K21: ='SAF 011 - NECESIDAD TRIMESTRAL'!#REF! -> #REF!
A22: 11 | C22: ='SAF 011 - NECESIDAD TRIMESTRAL'!E55 -> CHAGATEST ELISA LISADO-96DET. | H22: NO | I22: ='SAF 011 - NECESIDAD TRIMESTRAL'!F55 -> UNIDAD | J22: ='SAF 011 - NECESIDAD TRIMESTRAL'!H55 -> 10206 | K22: ='SAF 011 - NECESIDAD TRIMESTRAL'!#REF! -> #REF!
A23: 12 | C23: ='SAF 011 - NECESIDAD TRIMESTRAL'!E56 -> CHAGATEST ELISA RECOMBINANTE (V4,0)-96 DET. | H23: NO | I23: ='SAF 011 - NECESIDAD TRIMESTRAL'!F56 -> UNIDAD | J23: ='SAF 011 - NECESIDAD TRIMESTRAL'!H56 -> 11295 | K23: ='SAF 011 - NECESIDAD TRIMESTRAL'!#REF! -> #REF!
A24: 13 | C24: ='SAF 011 - NECESIDAD TRIMESTRAL'!E61 -> CMV CITOMEGALOVIRUS IGM METODO ELISA 96 DET. | H24: NO | I24: ='SAF 011 - NECESIDAD TRIMESTRAL'!F61 -> UNIDAD | J24: ='SAF 011 - NECESIDAD TRIMESTRAL'!H61 -> 19749 | K24: ='SAF 011 - NECESIDAD TRIMESTRAL'!#REF! -> #REF!
A25: 14 | C25: ='SAF 011 - NECESIDAD TRIMESTRAL'!E72 -> DG GEL ABO RH 2D | H25: NO | I25: ='SAF 011 - NECESIDAD TRIMESTRAL'!F72 -> UNIDAD | J25: ='SAF 011 - NECESIDAD TRIMESTRAL'!H72 -> 590 | K25: ='SAF 011 - NECESIDAD TRIMESTRAL'!#REF! -> #REF!
A26: 15 | C26: ='SAF 011 - NECESIDAD TRIMESTRAL'!E73 -> DG GEL COOMBS | H26: NO | I26: ='SAF 011 - NECESIDAD TRIMESTRAL'!F73 -> UNIDAD | J26: ='SAF 011 - NECESIDAD TRIMESTRAL'!H73 -> 725 | K26: ='SAF 011 - NECESIDAD TRIMESTRAL'!#REF! -> #REF!
A27: 16 | C27: ='SAF 011 - NECESIDAD TRIMESTRAL'!E74 -> DG GEL PHENO+KELL | H27: NO | I27: ='SAF 011 - NECESIDAD TRIMESTRAL'!F74 -> UNIDAD | J27: ='SAF 011 - NECESIDAD TRIMESTRAL'!H74 -> 795 | K27: ='SAF 011 - NECESIDAD TRIMESTRAL'!#REF! -> #REF!
A28: 17 | C28: ='SAF 011 - NECESIDAD TRIMESTRAL'!E75 -> DG SOL | H28: NO | I28: ='SAF 011 - NECESIDAD TRIMESTRAL'!F75 -> UNIDAD | J28: ='SAF 011 - NECESIDAD TRIMESTRAL'!H75 -> 4980 | K28: ='SAF 011 - NECESIDAD TRIMESTRAL'!#REF! -> #REF!
A29: 18 | C29: ='SAF 011 - NECESIDAD TRIMESTRAL'!E77 -> Equipo para la deteccion de Anti Hb Core, por metodo de Elisa en microplacas en equipos de 96 det. Monolisa HBc Plus | H29: NO | I29: ='SAF 011 - NECESIDAD TRIMESTRAL'!F77 -> CAJA | J29: ='SAF 011 - NECESIDAD TRIMESTRAL'!H77 -> 20160 | K29: ='SAF 011 - NECESIDAD TRIMESTRAL'!#REF! -> #REF!
A30: 19 | C30: ='SAF 011 - NECESIDAD TRIMESTRAL'!E78 -> Equipos Covidar IGG x 192 determinaciones tipo Lemos | H30: NO | I30: ='SAF 011 - NECESIDAD TRIMESTRAL'!F78 -> CAJA | J30: ='SAF 011 - NECESIDAD TRIMESTRAL'!H78 -> 19743.57 | K30: ='SAF 011 - NECESIDAD TRIMESTRAL'!#REF! -> #REF!
A31: 20 | C31: ='SAF 011 - NECESIDAD TRIMESTRAL'!E79 -> Equipos por metodo de Elisa para la deteccion simultanea anticuerpos y antigenos de virus de Hepatitis C por Elisa en microplaca recubierta con anticuerpos monoclonales anti caspide de HCV con antigenos reconvinantes de la region NS3 genotipos 1 y 3º y de la region no estructural NS4 y un peptido mutado de la region de la caspide del Virus HCV. En equipos de 96 det. Por metodologia EIA en microplacas con provision de reactivos, calibradores,materias descartable, buffers, liquido de lavado, y todo insumo necesario para suprocesamiento Monolisa HCV Ag- Ab Ultra v.2 | H31: NO | I31: ='SAF 011 - NECESIDAD TRIMESTRAL'!F79 -> CAJA | J31: ='SAF 011 - NECESIDAD TRIMESTRAL'!H79 -> 36300 | K31: ='SAF 011 - NECESIDAD TRIMESTRAL'!#REF! -> #REF!
A32: 21 | C32: ='SAF 011 - NECESIDAD TRIMESTRAL'!E91 -> HEPATITIS B ELISA HBSAG-96DET. | H32: NO | I32: ='SAF 011 - NECESIDAD TRIMESTRAL'!F91 -> UNIDAD | J32: ='SAF 011 - NECESIDAD TRIMESTRAL'!H91 -> 14586 | K32: ='SAF 011 - NECESIDAD TRIMESTRAL'!#REF! -> #REF!
A33: 22 | C33: ='SAF 011 - NECESIDAD TRIMESTRAL'!E92 -> HEPATITIS C HCV ELISA 3º GEN. 96 DET. | H33: NO | I33: ='SAF 011 - NECESIDAD TRIMESTRAL'!F92 -> UNIDAD | J33: ='SAF 011 - NECESIDAD TRIMESTRAL'!H92 -> 39806 | K33: ='SAF 011 - NECESIDAD TRIMESTRAL'!#REF! -> #REF!
A34: 23 | C34: ='SAF 011 - NECESIDAD TRIMESTRAL'!E94 -> HIV ELISA AG/AC 4° GENERACION -96 DET- | H34: NO | I34: ='SAF 011 - NECESIDAD TRIMESTRAL'!F94 -> Unidad | J34: ='SAF 011 - NECESIDAD TRIMESTRAL'!H94 -> 23147 | K34: ='SAF 011 - NECESIDAD TRIMESTRAL'!#REF! -> #REF!
A35: 24 | C35: ='SAF 011 - NECESIDAD TRIMESTRAL'!E95 -> HTLV 1 Y 2 ELISA-96DET. | H35: NO | I35: ='SAF 011 - NECESIDAD TRIMESTRAL'!F95 -> UNIDAD | J35: ='SAF 011 - NECESIDAD TRIMESTRAL'!H95 -> 25747 | K35: ='SAF 011 - NECESIDAD TRIMESTRAL'!#REF! -> #REF!
A36: 25 | C36: ='SAF 011 - NECESIDAD TRIMESTRAL'!E96 -> HVC REACTIVO x 100 det | H36: NO | I36: ='SAF 011 - NECESIDAD TRIMESTRAL'!F96 -> CAJA | J36: ='SAF 011 - NECESIDAD TRIMESTRAL'!H96 -> 50545 | K36: ='SAF 011 - NECESIDAD TRIMESTRAL'!#REF! -> #REF!
A37: 26 | C37: ='SAF 011 - NECESIDAD TRIMESTRAL'!E102 -> KIT PLASMAFERESIS TIPO GRIFOLS | H37: NO | I37: ='SAF 011 - NECESIDAD TRIMESTRAL'!F102 -> UNIDAD | J37: ='SAF 011 - NECESIDAD TRIMESTRAL'!H102 -> 35090 | K37: ='SAF 011 - NECESIDAD TRIMESTRAL'!#REF! -> #REF!
A38: 27 | C38: ='SAF 011 - NECESIDAD TRIMESTRAL'!E103 -> KITS PARA PLAQUETOFERESIS CON FILTRO TIPO GRIFOLS | H38: NO | I38: ='SAF 011 - NECESIDAD TRIMESTRAL'!F103 -> UNIDAD | J38: ='SAF 011 - NECESIDAD TRIMESTRAL'!H103 -> 35695 | K38: ='SAF 011 - NECESIDAD TRIMESTRAL'!#REF! -> #REF!
A39: 28 | C39: ='SAF 011 - NECESIDAD TRIMESTRAL'!E118 -> PANEL IDENTISERA DIANA TIPO GRIFOLS | H39: NO | I39: ='SAF 011 - NECESIDAD TRIMESTRAL'!F118 -> UNIDAD | J39: ='SAF 011 - NECESIDAD TRIMESTRAL'!H118 -> 29160 | K39: ='SAF 011 - NECESIDAD TRIMESTRAL'!#REF! -> #REF!
A40: 29 | C40: ='SAF 011 - NECESIDAD TRIMESTRAL'!E119 -> PANEL SARASCAN DIANA 2 TIPO GRIFOLS | H40: NO | I40: ='SAF 011 - NECESIDAD TRIMESTRAL'!F119 -> UNIDAD | J40: ='SAF 011 - NECESIDAD TRIMESTRAL'!H119 -> 22500 | K40: ='SAF 011 - NECESIDAD TRIMESTRAL'!#REF! -> #REF!
A41: 30 | C41: ='SAF 011 - NECESIDAD TRIMESTRAL'!E120 -> PANEL SERIGRUP A1/B TIPO GRIFOLS | H41: NO | I41: ='SAF 011 - NECESIDAD TRIMESTRAL'!F120 -> UNIDAD | J41: ='SAF 011 - NECESIDAD TRIMESTRAL'!H120 -> 15588 | K41: ='SAF 011 - NECESIDAD TRIMESTRAL'!#REF! -> #REF!
A42: 31 | C42: ='SAF 011 - NECESIDAD TRIMESTRAL'!E121 -> PANEL SERO cyte 0,8% TIPO GRIFOLS | H42: NO | I42: ='SAF 011 - NECESIDAD TRIMESTRAL'!F121 -> UNIDAD | J42: ='SAF 011 - NECESIDAD TRIMESTRAL'!H121 -> 16500 | K42: ='SAF 011 - NECESIDAD TRIMESTRAL'!#REF! -> #REF!
A43: 32 | C43: ='SAF 011 - NECESIDAD TRIMESTRAL'!E127 -> Pre-trigger TIPO ABBOTT | H43: NO | I43: ='SAF 011 - NECESIDAD TRIMESTRAL'!F127 -> CAJA | J43: ='SAF 011 - NECESIDAD TRIMESTRAL'!H127 -> 16980 | K43: ='SAF 011 - NECESIDAD TRIMESTRAL'!#REF! -> #REF!
...

Sheet APG DPBS
A1: EJERCICIO: | D1: 2022 | P1: AUTORIZACION PARA GASTAR
A4: JURISDICCIÓN: | G4: ='NP DPBS'!D3 -> 040 - MINISTERIO DE SALUD
A5: SAF: | G5: ='NP DPBS'!D4 -> 011 - DIRECCION PROVINCIAL DE ADMINISTRACION DEL MINISTERIO DE SALUD
A6: UNIDAD EJECUTORA: | G6: ='NP DPBS'!D5 -> 747 - DIRECCION PROVINCIAL BANCO DE SANGRE
A7: DEPENDENCIA SOLICITANTE: | G7: ='NP DPBS'!D6 -> 747 - DIRECCION PROVINCIAL BANCO DE SANGRE
A8: AUTORIZACIÓN:
A9: Señor Director de Administración o Titular del Servicio Administrativo Financiero:
A10: Autorizo la realización de los trámites correspondientes, a fin de proveer a este Organismo los bienes, servicios o ejecución de obras públicas que se detallan en Nota de Pedido N° 09/2022 , afectando la erogación resultante a los créditos presupuestarios aprobados a favor de esta Unidad Ejecutora, conforme al siguiente detalle:
A12: IMPUTACIÓN PRESUPUESTARIA
A13: CÓDIGO | O13: DENOMINACIÓN DE LA PARTIDA PRESUPUESTARIA | Q13: IMPORTE
A14: PR | B14: SB | C14: PY | D14: AC | E14: OB | F14: UG | G14: FIN | H14: FUN | I14: I | J14: P | K14: P | L14: SubP | M14: M | N14: FF
A15: 27 | D15: 1 | F15: 4901 | G15: 3 | H15: 1 | I15: 2 | J15: 5 | K15: 1 | M15: 1 | N15: 1.1 | O15: COMPUESTOS QUIMICOS | Q15: ='NP DPBS'!J59 -> #REF!
A38: TOTAL DE PESOS: VEINTITRES MILLONES DOSCIENTOS DOCE MIL OCHOCIENTOS OCHENTA Y SEIS CON 16/100.- | Q38: =SUM(Q15:Q37) -> #REF!
A40: JUSTIFICACIÓN:
A41: ='NP DPBS'!D8 -> ADQUISICION DEL RUBRO REACTIVOS PARA LABORATORIO

Sheet NP DPSMA
A1: NOTA DE PEDIDO | J1: N° | K1: 06/2022
A3: JURISDICCIÓN: | D3: 040 - MINISTERIO DE SALUD
A4: SAF: | D4: 011 - DIRECCION PROVINCIAL DE ADMINISTRACION DEL MINISTERIO DE SALUD
A5: UNIDAD EJECUTORA: | D5: 488 - DIRECCION PROVINCIAL DE SALUD Y MEDIO AMBIENTE
A6: DEPENDENCIA SOLICITANTE: | D6: 488 - DIRECCION PROVINCIAL DE SALUD Y MEDIO AMBIENTE
A7: PERIODO UTILIZACIÓN: | D7: TRES (3) MESES
A8: OBJETO: | D8: ADQUISICION DEL RUBRO REACTIVOS PARA LABORATORIO
A10: Ítem | B10: Codigo Item | C10: DESCRIPCIÓN | H10: Adjunta Detalle Técnico | I10: Unidad Medida | J10: Precio Unitario Estimado | K10: Cantidad Solicitada
A12: 1 | C12: ='SAF 011 - NECESIDAD TRIMESTRAL'!E10 -> ACIDO ACETICO GLACIAL 6% P/V 1000 mL TIPO BIOPACK | H12: NO | I12: ='SAF 011 - NECESIDAD TRIMESTRAL'!F10 -> UNIDAD | J12: ='SAF 011 - NECESIDAD TRIMESTRAL'!H10 -> 850 | K12: ='SAF 011 - NECESIDAD TRIMESTRAL'!#REF! -> #REF!
A13: 2 | C13: ='SAF 011 - NECESIDAD TRIMESTRAL'!E11 -> ACIDO CLORHIDRICO SOLUCIÓN 0.5 MOL/L (0,5 N) 1000 ML TIPO BIOPACK | H13: NO | I13: ='SAF 011 - NECESIDAD TRIMESTRAL'!F11 -> UNIDAD | J13: ='SAF 011 - NECESIDAD TRIMESTRAL'!H11 -> 1900 | K13: ='SAF 011 - NECESIDAD TRIMESTRAL'!#REF! -> #REF!
A14: 3 | C14: ='SAF 011 - NECESIDAD TRIMESTRAL'!E12 -> ACIDO SULFURICO SOLUCIÓN 1 N (0.5 MOL/L) 1000 ML TIPO BIOPACK | H14: NO | I14: ='SAF 011 - NECESIDAD TRIMESTRAL'!F12 -> UNIDAD | J14: ='SAF 011 - NECESIDAD TRIMESTRAL'!H12 -> 2000 | K14: ='SAF 011 - NECESIDAD TRIMESTRAL'!#REF! -> #REF!
A15: 4 | C15: ='SAF 011 - NECESIDAD TRIMESTRAL'!E13 -> AGAR PARA COLIFORMES PARA MICROBIOLOGÍA CHROMOCULT® 500 GR TIPO MERCK | H15: NO | I15: ='SAF 011 - NECESIDAD TRIMESTRAL'!F13 -> UNIDAD | J15: ='SAF 011 - NECESIDAD TRIMESTRAL'!H13 -> 185000 | K15: ='SAF 011 - NECESIDAD TRIMESTRAL'!#REF! -> #REF!
A16: 5 | C16: ='SAF 011 - NECESIDAD TRIMESTRAL'!E14 -> AGAR TBX PARA MICROBIOLOGÍA CHROMOCULT® 500 GR TIPO MERCK | H16: NO | I16: ='SAF 011 - NECESIDAD TRIMESTRAL'!F14 -> UNIDAD | J16: ='SAF 011 - NECESIDAD TRIMESTRAL'!H14 -> 97000 | K16: ='SAF 011 - NECESIDAD TRIMESTRAL'!#REF! -> #REF!
A17: 6 | C17: ='SAF 011 - NECESIDAD TRIMESTRAL'!E21 -> ANIDRIDO ACÉTICO X 1000 ML TIPO CICARILLI | H17: NO | I17: ='SAF 011 - NECESIDAD TRIMESTRAL'!F21 -> UNIDAD | J17: ='SAF 011 - NECESIDAD TRIMESTRAL'!H21 -> 2500 | K17: ='SAF 011 - NECESIDAD TRIMESTRAL'!#REF! -> #REF!
A18: 7 | C18: ='SAF 011 - NECESIDAD TRIMESTRAL'!E49 -> CALDO EC 500 GR (SÓLIDO) TIPO OXOID | H18: NO | I18: ='SAF 011 - NECESIDAD TRIMESTRAL'!F49 -> UNIDAD | J18: ='SAF 011 - NECESIDAD TRIMESTRAL'!H49 -> 28000 | K18: ='SAF 011 - NECESIDAD TRIMESTRAL'!#REF! -> #REF!
A19: 8 | C19: ='SAF 011 - NECESIDAD TRIMESTRAL'!E50 -> CALDO EC CON MUG (SÓLIDO) 500 GR TIPO OXOID | H19: NO | I19: ='SAF 011 - NECESIDAD TRIMESTRAL'!F50 -> UNIDAD | J19: ='SAF 011 - NECESIDAD TRIMESTRAL'!H50 -> 75000 | K19: ='SAF 011 - NECESIDAD TRIMESTRAL'!#REF! -> #REF!
A20: 9 | C20: ='SAF 011 - NECESIDAD TRIMESTRAL'!E51 -> CALDO VERDE BRILLANTE BILIS 2% 500 GRS. TIPO OXOID | H20: NO | I20: ='SAF 011 - NECESIDAD TRIMESTRAL'!F51 -> UNIDAD | J20: ='SAF 011 - NECESIDAD TRIMESTRAL'!H51 -> 31200 | K20: ='SAF 011 - NECESIDAD TRIMESTRAL'!#REF! -> #REF!
A21: 10 | C21: ='SAF 011 - NECESIDAD TRIMESTRAL'!E64 -> COBRE (II) SULFATO 5-HIDRATO P.A. (A.C.S.) 250 GR TIPO BIOPACK | H21: NO | I21: ='SAF 011 - NECESIDAD TRIMESTRAL'!F64 -> UNIDAD | J21: ='SAF 011 - NECESIDAD TRIMESTRAL'!H64 -> 2500 | K21: ='SAF 011 - NECESIDAD TRIMESTRAL'!#REF! -> #REF!
A22: 11 | C22: ='SAF 011 - NECESIDAD TRIMESTRAL'!E65 -> COCTEL DE EXTRACCION 105 ML R-BIOPHARM PARA KIT RIDASCREEN GLIADINA | H22: NO | I22: ='SAF 011 - NECESIDAD TRIMESTRAL'!F65 -> UNIDAD | J22: ='SAF 011 - NECESIDAD TRIMESTRAL'!H65 -> 27300 | K22: ='SAF 011 - NECESIDAD TRIMESTRAL'!#REF! -> #REF!
A23: 12 | C23: ='SAF 011 - NECESIDAD TRIMESTRAL'!E80 -> ÉTER ANHIDRO X 1.000 ML TIPO CICARELLI | H23: NO | I23: ='SAF 011 - NECESIDAD TRIMESTRAL'!F80 -> UNIDAD | J23: ='SAF 011 - NECESIDAD TRIMESTRAL'!H80 -> 3950 | K23: ='SAF 011 - NECESIDAD TRIMESTRAL'!#REF! -> #REF!
A24: 13 | C24: ='SAF 011 - NECESIDAD TRIMESTRAL'!E81 -> ÉTER SULFÚRICO X 1.000 ML TIPO CICARELLI | H24: NO | I24: ='SAF 011 - NECESIDAD TRIMESTRAL'!F81 -> UNIDAD | J24: ='SAF 011 - NECESIDAD TRIMESTRAL'!H81 -> 5900 | K24: ='SAF 011 - NECESIDAD TRIMESTRAL'!#REF! -> #REF!
A25: 14 | C25: ='SAF 011 - NECESIDAD TRIMESTRAL'!E93 -> HIDRÓXIDO DE SÓDIO EN CRISTALES O LENTEJAS X 250 GRS TIPO CICARELLI | H25: NO | I25: ='SAF 011 - NECESIDAD TRIMESTRAL'!F93 -> UNIDAD | J25: ='SAF 011 - NECESIDAD TRIMESTRAL'!H93 -> 1500 | K25: ='SAF 011 - NECESIDAD TRIMESTRAL'!#REF! -> #REF!
A26: 15 | C26: ='SAF 011 - NECESIDAD TRIMESTRAL'!E97 -> INDIGO CARMIN (C.I. 73015) 25 GR TIPO BIOPACK | H26: NO | I26: ='SAF 011 - NECESIDAD TRIMESTRAL'!F97 -> UNIDAD | J26: ='SAF 011 - NECESIDAD TRIMESTRAL'!H97 -> 2800 | K26: ='SAF 011 - NECESIDAD TRIMESTRAL'!#REF! -> #REF!
A27: 16 | C27: ='SAF 011 - NECESIDAD TRIMESTRAL'!E98 -> IODO RESUBLIMADO PRO-ANÁLISIS (ACS) X 100 G TIPO CICARELLI | H27: NO | I27: ='SAF 011 - NECESIDAD TRIMESTRAL'!F98 -> UNIDAD | J27: ='SAF 011 - NECESIDAD TRIMESTRAL'!H98 -> 15000 | K27: ='SAF 011 - NECESIDAD TRIMESTRAL'!#REF! -> #REF!
A28: 17 | C28: ='SAF 011 - NECESIDAD TRIMESTRAL'!E108 -> MEDIOS DE CULTIVO Y SUPLEMENTO; NOMBRE DEL PRODUCTO: C.LAURIL SULFATO TRIPTOSA MODI, ESTADO: SOLIDO, PRESENTACION: ENVASE X 500 mGr | H28: NO | I28: ='SAF 011 - NECESIDAD TRIMESTRAL'!F108 -> UNIDAD | J28: ='SAF 011 - NECESIDAD TRIMESTRAL'!H108 -> 22300 | K28: ='SAF 011 - NECESIDAD TRIMESTRAL'!#REF! -> #REF!
A29: 18 | C29: ='SAF 011 - NECESIDAD TRIMESTRAL'!E109 -> MEDIOS DE CULTIVO Y SUPLEMENTO; NOMBRE DEL PRODUCTO: CALDO GIOLITTI CANTONI, ESTADO: SOLIDO, PRESENTACION: ENVASE X 500 GR | H29: NO | I29: ='SAF 011 - NECESIDAD TRIMESTRAL'!F109 -> UNIDAD | J29: ='SAF 011 - NECESIDAD TRIMESTRAL'!H109 -> 32300 | K29: ='SAF 011 - NECESIDAD TRIMESTRAL'!#REF! -> #REF!
A30: 19 | C30: ='SAF 011 - NECESIDAD TRIMESTRAL'!E111 -> MULLER-KAUFFMANN TETRATHIONATE-NOVOBIOCIN (MKTTN) CALDO 500 GR TIPO BIOKAR | H30: NO | I30: ='SAF 011 - NECESIDAD TRIMESTRAL'!F111 -> UNIDAD | J30: ='SAF 011 - NECESIDAD TRIMESTRAL'!H111 -> 40000 | K30: ='SAF 011 - NECESIDAD TRIMESTRAL'!#REF! -> #REF!
A31: 20 | C31: ='SAF 011 - NECESIDAD TRIMESTRAL'!E112 -> N-(1-NAFTIL) ETILENDIAMINA DICLORHIDRATO P.A. (A.C.S.) 25 GR TIPO BIOPACK | H31: NO | I31: ='SAF 011 - NECESIDAD TRIMESTRAL'!F112 -> UNIDAD | J31: ='SAF 011 - NECESIDAD TRIMESTRAL'!H112 -> 8500 | K31: ='SAF 011 - NECESIDAD TRIMESTRAL'!#REF! -> #REF!
A32: 21 | C32: ='SAF 011 - NECESIDAD TRIMESTRAL'!E113 -> NITRATO DE POTÁSIO P.A. DROGA SÓLIDA X 500 G. TIPO BIOPACK | H32: NO | I32: ='SAF 011 - NECESIDAD TRIMESTRAL'!F113 -> UNIDAD | J32: ='SAF 011 - NECESIDAD TRIMESTRAL'!H113 -> 3800 | K32: ='SAF 011 - NECESIDAD TRIMESTRAL'!#REF! -> #REF!
A33: 22 | C33: ='SAF 011 - NECESIDAD TRIMESTRAL'!E114 -> NITRITO DE SODIO DROGA SÓLIDA X 500 G. TIPO BIOPACK | H33: NO | I33: ='SAF 011 - NECESIDAD TRIMESTRAL'!F114 -> UNIDAD | J33: ='SAF 011 - NECESIDAD TRIMESTRAL'!H114 -> 2100 | K33: ='SAF 011 - NECESIDAD TRIMESTRAL'!#REF! -> #REF!
A34: 23 | C34: ='SAF 011 - NECESIDAD TRIMESTRAL'!E115 -> NOVOBIOCINA SAL MONOSODICA PFB 1 GR TIPO CALBIOCHEM/MERCK | H34: NO | I34: ='SAF 011 - NECESIDAD TRIMESTRAL'!F115 -> UNIDAD | J34: ='SAF 011 - NECESIDAD TRIMESTRAL'!H115 -> 28500 | K34: ='SAF 011 - NECESIDAD TRIMESTRAL'!#REF! -> #REF!
A35: 24 | C35: ='SAF 011 - NECESIDAD TRIMESTRAL'!E116 -> OXIDO DE CALCIO NATURAL EN GRANALLAS DROGA SÓLIDA X 500 G TIPO CICARELLI | H35: NO | I35: ='SAF 011 - NECESIDAD TRIMESTRAL'!F116 -> UNIDAD | J35: ='SAF 011 - NECESIDAD TRIMESTRAL'!H116 -> 4800 | K35: ='SAF 011 - NECESIDAD TRIMESTRAL'!#REF! -> #REF!
A36: 25 | C36: ='SAF 011 - NECESIDAD TRIMESTRAL'!E123 -> PEPTONA DE GELATINA POR DIGESTIÓN PANCR. P/MICROB. 1000 GR TIPO MERCK | H36: NO | I36: ='SAF 011 - NECESIDAD TRIMESTRAL'!F123 -> UNIDAD | J36: ='SAF 011 - NECESIDAD TRIMESTRAL'!H123 -> 38000 | K36: ='SAF 011 - NECESIDAD TRIMESTRAL'!#REF! -> #REF!
A37: 26 | C37: ='SAF 011 - NECESIDAD TRIMESTRAL'!E124 -> PERMANGANATO DE POTASIO DRÓGA SÓLIDA PRO-ANÁLISIS X 250 G TIPO CICARELLI | H37: NO | I37: ='SAF 011 - NECESIDAD TRIMESTRAL'!F124 -> UNIDAD | J37: ='SAF 011 - NECESIDAD TRIMESTRAL'!H124 -> 4100 | K37: ='SAF 011 - NECESIDAD TRIMESTRAL'!#REF! -> #REF!
A38: 27 | C38: ='SAF 011 - NECESIDAD TRIMESTRAL'!E125 -> PLOMO SUBACETATO p.a. (A.C.S.) X 250 GR DROGA SÓLIDA TIPO BIOPACK | H38: NO | I38: ='SAF 011 - NECESIDAD TRIMESTRAL'!F125 -> UNIDAD | J38: ='SAF 011 - NECESIDAD TRIMESTRAL'!H125 -> 4300 | K38: ='SAF 011 - NECESIDAD TRIMESTRAL'!#REF! -> #REF!
A39: 28 | C39: ='SAF 011 - NECESIDAD TRIMESTRAL'!E126 -> POTASIO HIDROXIDO SOLUCIÓN 0.1 N (0,1 MOL/L) 1000 ML TIPO BIOPACK | H39: NO | I39: ='SAF 011 - NECESIDAD TRIMESTRAL'!F126 -> UNIDAD | J39: ='SAF 011 - NECESIDAD TRIMESTRAL'!H126 -> 2800 | K39: ='SAF 011 - NECESIDAD TRIMESTRAL'!#REF! -> #REF!
A40: 29 | C40: ='SAF 011 - NECESIDAD TRIMESTRAL'!E130 -> REATIVO DE FEHLING A X 1000 ML TIPO BIOPACK | H40: NO | I40: ='SAF 011 - NECESIDAD TRIMESTRAL'!F130 -> UNIDAD | J40: ='SAF 011 - NECESIDAD TRIMESTRAL'!H130 -> 3600 | K40: ='SAF 011 - NECESIDAD TRIMESTRAL'!#REF! -> #REF!
A41: 30 | C41: ='SAF 011 - NECESIDAD TRIMESTRAL'!E131 -> REATIVO DE FEHLING B X 1000 ML TIPO BIOPACK | H41: NO | I41: ='SAF 011 - NECESIDAD TRIMESTRAL'!F131 -> UNIDAD | J41: ='SAF 011 - NECESIDAD TRIMESTRAL'!H131 -> 5200 | K41: ='SAF 011 - NECESIDAD TRIMESTRAL'!#REF! -> #REF!
A42: 31 | C42: ='SAF 011 - NECESIDAD TRIMESTRAL'!E132 -> RIDASCREEN GLIADINA X 96 DET ELISA TIPO R-BIOPHARM | H42: NO | I42: ='SAF 011 - NECESIDAD TRIMESTRAL'!F132 -> UNIDAD | J42: ='SAF 011 - NECESIDAD TRIMESTRAL'!H132 -> 135250 | K42: ='SAF 011 - NECESIDAD TRIMESTRAL'!#REF! -> #REF!
A43: 32 | C43: ='SAF 011 - NECESIDAD TRIMESTRAL'!E141 -> SODIO SULFATO ANHIDRO PRO-ANÁLISIS (ACS) X 250 G TIPO CICARELLI | H43: NO | I43: ='SAF 011 - NECESIDAD TRIMESTRAL'!F141 -> UNIDAD | J43: ='SAF 011 - NECESIDAD TRIMESTRAL'!H141 -> 3300 | K43: ='SAF 011 - NECESIDAD TRIMESTRAL'!#REF! -> #REF!
...

Sheet APG DPSMA
A1: EJERCICIO: | D1: 2022 | P1: AUTORIZACION PARA GASTAR
A4: JURISDICCIÓN: | G4: ='NP DPSMA'!D3 -> 040 - MINISTERIO DE SALUD
A5: SAF: | G5: ='NP DPSMA'!D4 -> 011 - DIRECCION PROVINCIAL DE ADMINISTRACION DEL MINISTERIO DE SALUD
A6: UNIDAD EJECUTORA: | G6: ='NP DPSMA'!D5 -> 488 - DIRECCION PROVINCIAL DE SALUD Y MEDIO AMBIENTE
A7: DEPENDENCIA SOLICITANTE: | G7: ='NP DPSMA'!D6 -> 488 - DIRECCION PROVINCIAL DE SALUD Y MEDIO AMBIENTE
A8: AUTORIZACIÓN:
A9: Señor Director de Administración o Titular del Servicio Administrativo Financiero:
A10: Autorizo la realización de los trámites correspondientes, a fin de proveer a este Organismo los bienes, servicios o ejecución de obras públicas que se detallan en Nota de Pedido N° 06/2022 , afectando la erogación resultante a los créditos presupuestarios aprobados a favor de esta Unidad Ejecutora, conforme al siguiente detalle:
A12: IMPUTACIÓN PRESUPUESTARIA
A13: CÓDIGO | O13: DENOMINACIÓN DE LA PARTIDA PRESUPUESTARIA | Q13: IMPORTE
A14: PR | B14: SB | C14: PY | D14: AC | E14: OB | F14: UG | G14: FIN | H14: FUN | I14: I | J14: P | K14: P | L14: SubP | M14: M | N14: FF
A15: 22 | D15: 1 | F15: 4901 | G15: 4 | H15: 4 | I15: 2 | J15: 5 | K15: 1 | M15: 1 | N15: 1.1 | O15: COMPUESTOS QUIMICOS | Q15: ='NP DPSMA'!J47 -> #REF!
A38: TOTAL DE PESOS: DOS MILLONES DOSCIENTOS CINCUENTA Y UN MIL TRESCIENTOS CON 00/100.- | Q38: =SUM(Q15:Q37) -> #REF!
A40: JUSTIFICACIÓN:
A41: ='NP DPSMA'!D8 -> ADQUISICION DEL RUBRO REACTIVOS PARA LABORATORIO

Sheet NP DPCUR
A1: NOTA DE PEDIDO | J1: N° | K1: 05/2022
A3: JURISDICCIÓN: | D3: 040 - MINISTERIO DE SALUD
A4: SAF: | D4: 011 - DIRECCION PROVINCIAL DE ADMINISTRACION DEL MINISTERIO DE SALUD
A5: UNIDAD EJECUTORA: | D5: 160 - DIRECCION PROVINCIAL CENTRO UNICO DE REFERENCIA
A6: DEPENDENCIA SOLICITANTE: | D6: 160 - DIRECCION PROVINCIAL CENTRO UNICO DE REFERENCIA
A7: PERIODO UTILIZACIÓN: | D7: TRES (3) MESES
A8: OBJETO: | D8: ADQUISICION DEL RUBRO REACTIVOS PARA LABORATORIO
A10: Ítem | B10: Codigo Item | C10: DESCRIPCIÓN | H10: Adjunta Detalle Técnico | I10: Unidad Medida | J10: Precio Unitario Estimado | K10: Cantidad Solicitada
A12: 1 | C12: ='SAF 011 - NECESIDAD TRIMESTRAL'!E15 -> AGUA BIDESTILADA X 5 LITROS | H12: NO | I12: ='SAF 011 - NECESIDAD TRIMESTRAL'!F15 -> BIDON | J12: ='SAF 011 - NECESIDAD TRIMESTRAL'!H15 -> 574 | K12: ='SAF 011 - NECESIDAD TRIMESTRAL'!#REF! -> #REF!
A13: 2 | C13: ='SAF 011 - NECESIDAD TRIMESTRAL'!E28 -> ARC ANTI HBC II CALIBRADOR | H13: NO | I13: ='SAF 011 - NECESIDAD TRIMESTRAL'!F28 -> KIT | J13: ='SAF 011 - NECESIDAD TRIMESTRAL'!H28 -> 15850 | K13: ='SAF 011 - NECESIDAD TRIMESTRAL'!#REF! -> #REF!
A14: 3 | C14: ='SAF 011 - NECESIDAD TRIMESTRAL'!E29 -> ARC ANTI HBC II RGT X 100 DET. | H14: NO | I14: ='SAF 011 - NECESIDAD TRIMESTRAL'!F29 -> KIT | J14: ='SAF 011 - NECESIDAD TRIMESTRAL'!H29 -> 36750 | K14: ='SAF 011 - NECESIDAD TRIMESTRAL'!#REF! -> #REF!
A15: 4 | C15: ='SAF 011 - NECESIDAD TRIMESTRAL'!E30 -> ARC ANTI HCV CALIBRADOR | H15: NO | I15: ='SAF 011 - NECESIDAD TRIMESTRAL'!F30 -> KIT | J15: ='SAF 011 - NECESIDAD TRIMESTRAL'!H30 -> 15850 | K15: ='SAF 011 - NECESIDAD TRIMESTRAL'!#REF! -> #REF!
A16: 5 | C16: ='SAF 011 - NECESIDAD TRIMESTRAL'!E31 -> ARC ANTI HCV RGT X 100 DET. | H16: NO | I16: ='SAF 011 - NECESIDAD TRIMESTRAL'!F31 -> KIT | J16: ='SAF 011 - NECESIDAD TRIMESTRAL'!H31 -> 71500 | K16: ='SAF 011 - NECESIDAD TRIMESTRAL'!#REF! -> #REF!
A17: 6 | C17: ='SAF 011 - NECESIDAD TRIMESTRAL'!E32 -> ARC BUFFER CONCENTRADO x 4 lts | H17: NO | I17: ='SAF 011 - NECESIDAD TRIMESTRAL'!F32 -> BIDON | J17: ='SAF 011 - NECESIDAD TRIMESTRAL'!H32 -> 12550 | K17: ='SAF 011 - NECESIDAD TRIMESTRAL'!#REF! -> #REF!
A18: 7 | C18: ='SAF 011 - NECESIDAD TRIMESTRAL'!E33 -> ARC CELDAS DE REACCION | H18: NO | I18: ='SAF 011 - NECESIDAD TRIMESTRAL'!F33 -> CAJA | J18: ='SAF 011 - NECESIDAD TRIMESTRAL'!H33 -> 28000 | K18: ='SAF 011 - NECESIDAD TRIMESTRAL'!#REF! -> #REF!
A19: 8 | C19: ='SAF 011 - NECESIDAD TRIMESTRAL'!E34 -> ARC CMV M CALIBRADOR | H19: NO | I19: ='SAF 011 - NECESIDAD TRIMESTRAL'!F34 -> KIT | J19: ='SAF 011 - NECESIDAD TRIMESTRAL'!H34 -> 15039 | K19: ='SAF 011 - NECESIDAD TRIMESTRAL'!#REF! -> #REF!
A20: 9 | C20: ='SAF 011 - NECESIDAD TRIMESTRAL'!E35 -> ARC CMV M RGT X 100 | H20: NO | I20: ='SAF 011 - NECESIDAD TRIMESTRAL'!F35 -> KIT | J20: ='SAF 011 - NECESIDAD TRIMESTRAL'!H35 -> 27595 | K20: ='SAF 011 - NECESIDAD TRIMESTRAL'!#REF! -> #REF!
A21: 10 | C21: ='SAF 011 - NECESIDAD TRIMESTRAL'!E36 -> ARC HBSAG CALIBRADOR | H21: NO | I21: ='SAF 011 - NECESIDAD TRIMESTRAL'!F36 -> KIT | J21: ='SAF 011 - NECESIDAD TRIMESTRAL'!H36 -> 15850 | K21: ='SAF 011 - NECESIDAD TRIMESTRAL'!#REF! -> #REF!
A22: 11 | C22: ='SAF 011 - NECESIDAD TRIMESTRAL'!E37 -> ARC HBSAG RGT X 100 DET. | H22: NO | I22: ='SAF 011 - NECESIDAD TRIMESTRAL'!F37 -> KIT | J22: ='SAF 011 - NECESIDAD TRIMESTRAL'!H37 -> 24480 | K22: ='SAF 011 - NECESIDAD TRIMESTRAL'!#REF! -> #REF!
A23: 12 | C23: ='SAF 011 - NECESIDAD TRIMESTRAL'!E38 -> ARC HIV COMBO CALIBRADOR | H23: NO | I23: ='SAF 011 - NECESIDAD TRIMESTRAL'!F38 -> KIT | J23: ='SAF 011 - NECESIDAD TRIMESTRAL'!H38 -> 20240 | K23: ='SAF 011 - NECESIDAD TRIMESTRAL'!#REF! -> #REF!
A24: 13 | C24: ='SAF 011 - NECESIDAD TRIMESTRAL'!E39 -> ARC HIV COMBO RGT X 100 DET | H24: NO | I24: ='SAF 011 - NECESIDAD TRIMESTRAL'!F39 -> KIT | J24: ='SAF 011 - NECESIDAD TRIMESTRAL'!H39 -> 42239 | K24: ='SAF 011 - NECESIDAD TRIMESTRAL'!#REF! -> #REF!
... A28: 17 | C28: ='SAF 011 - NECESIDAD TRIMESTRAL'!E43 -> ARC TRIGGER x 4 lts | H28: NO | I28: ='SAF 011 - NECESIDAD TRIMESTRAL'!F43 -> BIDON | J28: ='SAF 011 - NECESIDAD TRIMESTRAL'!H43 -> 11000 | K28: ='SAF 011 - NECESIDAD TRIMESTRAL'!#REF! -> #REF!
A30: Costo total estimado: OCHOCIENTOS VEINTISEIS MIL TRESCIENTOS CUARENTA Y OCHO CON 00/100.- | J30: =SUMPRODUCT(J12:J28,K12:K28) -> #REF!

Sheet APG DPCUR
A1: EJERCICIO: | D1: 2022 | P1: AUTORIZACION PARA GASTAR
A4: JURISDICCIÓN: | G4: ='NP DPCUR'!D3 -> 040 - MINISTERIO DE SALUD
A5: SAF: | G5: ='NP DPCUR'!D4 -> 011 - DIRECCION PROVINCIAL DE ADMINISTRACION DEL MINISTERIO DE SALUD
A6: UNIDAD EJECUTORA: | G6: ='NP DPCUR'!D5 -> 160 - DIRECCION PROVINCIAL CENTRO UNICO DE REFERENCIA
A7: DEPENDENCIA SOLICITANTE: | G7: ='NP DPCUR'!D6 -> 160 - DIRECCION PROVINCIAL CENTRO UNICO DE REFERENCIA
A8: AUTORIZACIÓN:
A9: Señor Director de Administración o Titular del Servicio Administrativo Financiero:
A10: Autorizo la realización de los trámites correspondientes, a fin de proveer a este Organismo los bienes, servicios o ejecución de obras públicas que se detallan en Nota de Pedido N° 05/2022 , afectando la erogación resultante a los créditos presupuestarios aprobados a favor de esta Unidad Ejecutora, conforme al siguiente detalle:
A12: IMPUTACIÓN PRESUPUESTARIA
A13: CÓDIGO | O13: DENOMINACIÓN DE LA PARTIDA PRESUPUESTARIA | Q13: IMPORTE
A14: PR | B14: SB | C14: PY | D14: AC | E14: OB | F14: UG | G14: FIN | H14: FUN | I14: I | J14: P | K14: P | L14: SubP | M14: M | N14: FF
A15: 35 | D15: 1 | F15: 4901 | G15: 3 | H15: 1 | I15: 2 | J15: 5 | K15: 1 | M15: 1 | N15: 1.1 | O15: COMPUESTOS QUIMICOS | Q15: 700000
A16: 35 | D16: 2 | F16: 4901 | G16: 3 | H16: 1 | I16: 2 | J16: 5 | K16: 1 | M16: 1 | N16: 1.1 | O16: COMPUESTOS QUIMICOS | Q16: 126348
A38: TOTAL DE PESOS: OCHOCIENTOS VEINTISEIS MIL TRESCIENTOS CUARENTA Y OCHO CON 00/100.- | Q38: =SUM(Q15:Q37) -> 826348
A40: JUSTIFICACIÓN:
A41: ='NP DPCUR'!D8 -> ADQUISICION DEL RUBRO REACTIVOS PARA LABORATORIO
