Workbook

Sheet Necesidades Trimestrales
B2: Pedido de Necesidades Trimestrales
A4: JURISDICCION: | C4: 95 - Ministerio de Cultura , Turismo y Deporte.-
A5: SAF N°: | C5: 18 - Secretaria de Administracion y Recursos Humanos.-
A6: EJERCICIO: | C6: 2022
A7: TRIMESTRE: | C7: 2° Trimestre
A10: ID | B10: CODIGO ITEM | C10: RUBRO DE COMPRA | D10: I.P.P. | E10: DESCRIPCION | F10: UNIDAD DE MEDIDA | G10: CANTIDAD | H10: PRECIO UNITARIO ESTIMADO | I10: IMPORTE TOTAL ESTIMADO
A11: 1 | B11: 2.9.2-261.14 | C11: LIBRERIA,PAP. Y UTILES OFICINA | D11: 2.9.2. | E11: ABROCHADORAS DE PAPEL; TIPO: PINZA, P/BROCHES: 10/50, MATERIAL: METALICA, MEDIDA: 10/50 | F11: UNIDAD | G11: 10 | H11: 2750 | I11: =G11*H11 -> 27500
A12: 2 | B12: 2.9.2-261.6 | C12: LIBRERIA,PAP. Y UTILES OFICINA | D12: 2.9.2. | E12: ABROCHADORAS DE PAPEL; MATERIAL: METALICA, TIPO: DE ESCRITORIO, MEDIDA: 21/6, P/BROCHES: 21/6 | F12: UNIDAD | G12: 10 | H12: 3540 | I12: =G12*H12 -> 35400
A13: 3 | B13: 2.9.2-700.28 | C13: LIBRERIA,PAP. Y UTILES OFICINA | D13: 2.9.2. | E13: BROCHES P/ABROCHADORA; NUMERO: 10/50, PRESENTACION: CAJA X 1000 UNIDADES | F13: CAJA | G13: 30 | H13: 142 | I13: =G13*H13 -> 4260
A14: 4 | B14: 2.9.2-700.6 | C14: LIBRERIA,PAP. Y UTILES OFICINA | D14: 2.9.2. | E14: BROCHES P/ABROCHADORA; NUMERO: 23/10, PRESENTACION: CAJA X 1000 | F14: CAJA | G14: 30 | H14: 120 | I14: =G14*H14 -> 3600
A15: 5 | B15: 2.9.2-700.2 | C15: LIBRERIA,PAP. Y UTILES OFICINA | D15: 2.9.2. | E15: BROCHES P/ABROCHADORA; NUMERO: 21/6, PRESENTACION: CAJA X 1000 UNIDADES | F15: CAJA | G15: 30 | H15: 195 | I15: =G15*H15 -> 5850
A16: 6 | B16: 2.9.2-700.29 | C16: LIBRERIA,PAP. Y UTILES OFICINA | D16: 2.9.2. | E16: BROCHES P/ABROCHADORA; NUMERO: 24/6, PRESENTACION: CAJA X 1000 UNIDADES | F16: CAJA | G16: 30 | H16: 230 | I16: =G16*H16 -> 6900
A17: 7 | B17: 2.9.2-262.28 | C17: LIBRERIA,PAP. Y UTILES OFICINA | D17: 2.9.2. | E17: ADHESIVOS P/PAPEL; PRESENTACION: 30 mL, TIPO: SINTETICO TRANSPARENTE | F17: UNIDAD | G17: 30 | H17: 96 | I17: =G17*H17 -> 2880
A18: 8 | B18: 2.9.2-1354.21 | C18: LIBRERIA,PAP. Y UTILES OFICINA | D18: 2.9.2. | E18: RESALTADORES; PUNTA: BISELADA, ACCESORIO: SIN, COLOR: SIN VALOR, TIPO PUNTA: BISELADA | F18: UNIDAD | G18: 100 | H18: 95 | I18: =G18*H18 -> 9500
A19: 9 | B19: 2.9.2-848.5 | C19: LIBRERIA,PAP. Y UTILES OFICINA | D19: 2.9.2. | E19: LAPIZ; TIPO: COMUN NRO 2, COLOR: NEGRO | F19: UNIDAD | G19: 50 | H19: 55 | I19: =G19*H19 -> 2750
A20: 10 | B20: 2.9.2-317.5 | C20: LIBRERIA,PAP. Y UTILES OFICINA | D20: 2.9.2. | E20: BOLIGRAFOS; TRAZO 1,0mm | F20: UNIDAD | G20: 150 | H20: 35 | I20: =G20*H20 -> 5250
A21: 11 | B21: 2.9.2-317.32 | C21: LIBRERIA,PAP. Y UTILES OFICINA | D21: 2.9.2. | E21: BOLIGRAFOS; TRAZO: 0,8 mm | F21: UNIDAD | G21: 150 | H21: 95 | I21: =G21*H21 -> 14250
A22: 12 | B22: 2.9.2-791.9 | C22: LIBRERIA,PAP. Y UTILES OFICINA | D22: 2.9.2. | E22: TALONARIOS NOTAS AUTOADHESIVAS; MEDIDA 76 X 76mm | F22: UNIDAD | G22: 30 | H22: 200 | I22: =G22*H22 -> 6000
... A51: 41 | B51: 2.3.1-928.8 | C51: LIBRERIA,PAP. Y UTILES OFICINA | D51: 2.3.1. | E51: ARANDELAS DE CARTON; DIAMETRO: 1 pulg, PRESENTACION: CAJA X 500 UNIDADES | F51: CAJA | G51: 20 | H51: 560 | I51: =G51*H51 -> 11200
I53: =SUM(I11:I52) -> 1124570
B55: Especificidades Item N° 8:
B57: Descripción técnica:
C58: COLOR AMARILLO, PUNTA BISELADA.
B59: Especificidades Item N° 10:
B61: Descripción técnica:
C62: COLOR: AZUL, CANTIDAD: 75 - COLOR: NEGRO, CANTIDAD: 75
B63: Especificidades Item N° 11:
B65: Descripción técnica:
C66: COLOR: AZUL, CANTIDAD: 75 - COLOR: NEGRO, CANTIDAD: 75
B67: Especificidades Item N° 14:
B69: Descripción técnica:
C70: COLOR: AZUL
B71: Especificidades Item N° 21 y 22:
B73: Descripción técnica:
C74: BASE OPACA, TAPA TRANSPARENTE
B75: Especificidades Item N° 27 y 28:
B77: Descripción técnica:
C78: CINTAS TRASNPARENTES
B80: Plazo y Lugar de entrega:
C81: El plazo de entrega no podrá ser superior a los Diez (10) días hábiles a partir de la fecha de recepción de la respectiva Orden de Compra. La entrega de dichos bienes se realizará en la Secretaria de Administracion y Recursos Humanos, sito en Avda. Mexico S/N° - Predio Ferial Catamarca, en la ciudad de San Fernando del Valle de Catamarca de 8:00hs. a 13:00hs. debiendo correr los gastos de fletes, acarreo, carga, descarga y seguro a cargo del adjudicatario. Se presentará Remito que deberá cumplimentar lo dispuesto por la R.G. AFIP 1415/03, sin excepción.
...

Sheet Nota Pedido
A1: NOTA DE PEDIDO | J1: N° | K1: 006/2022
A3: JURISDICCIÓN: | D3: ='Necesidades Trimestrales'!C4 -> 95 - Ministerio de Cultura , Turismo y Deporte.-
A4: SAF: | D4: ='Necesidades Trimestrales'!C5 -> 18 - Secretaria de Administracion y Recursos Humanos.-
A5: UNIDAD EJECUTORA: | D5: Ministerio de Cultura, Turismo y Deporte.-
A6: DEPENDENCIA SOLICITANTE: | D6: Ministerio de Cultura, Turismo y Deporte.-
A7: PERIODO UTILIZACIÓN: | D7: ='Necesidades Trimestrales'!C7 & " - Año " & 'Necesidades Trimestrales'!C6 -> 2° Trimestre - Año 2022
A8: OBJETO: | D8: Compra de elementos de librería para ser usados por las areas y direcciones pertenecientes al Ministerio de Cultura y Turismo.-
A10: Ítem | B10: Codigo Item | C10: DESCRIPCIÓN | H10: Adjunta Detalle Técnico | I10: Unidad Medida | J10: Cantidad Solicitada | K10: Precio Unitario Estimado
A12: 1 | B12: ='Necesidades Trimestrales'!B11 -> 2.9.2-261.14 | C12: ='Necesidades Trimestrales'!E11 -> ABROCHADORAS DE PAPEL; TIPO: PINZA, P/BROCHES: 10/50, MATERIAL: METALICA, MEDIDA: 10/50 | H12: NO | I12: ='Necesidades Trimestrales'!F11 -> UNIDAD | J12: ='Necesidades Trimestrales'!G11 -> 10 | K12: ='Necesidades Trimestrales'!H11 -> 2750
A13: ='Necesidades Trimestrales'!A12 -> 2 | B13: ='Necesidades Trimestrales'!B12 -> 2.9.2-261.6 | C13: ='Necesidades Trimestrales'!E12 -> ABROCHADORAS DE PAPEL; MATERIAL: METALICA, TIPO: DE ESCRITORIO, MEDIDA: 21/6, P/BROCHES: 21/6 | H13: NO | I13: ='Necesidades Trimestrales'!F12 -> UNIDAD | J13: ='Necesidades Trimestrales'!G12 -> 10 | K13: ='Necesidades Trimestrales'!H12 -> 3540
A14: ='Necesidades Trimestrales'!A13 -> 3 | B14: ='Necesidades Trimestrales'!B13 -> 2.9.2-700.28 | C14: ='Necesidades Trimestrales'!E13 -> BROCHES P/ABROCHADORA; NUMERO: 10/50, PRESENTACION: CAJA X 1000 UNIDADES | H14: NO | I14: ='Necesidades Trimestrales'!F13 -> CAJA | J14: ='Necesidades Trimestrales'!G13 -> 30 | K14: ='Necesidades Trimestrales'!H13 -> 142
A15: ='Necesidades Trimestrales'!A14 -> 4 | B15: ='Necesidades Trimestrales'!B14 -> 2.9.2-700.6 | C15: ='Necesidades Trimestrales'!E14 -> BROCHES P/ABROCHADORA; NUMERO: 23/10, PRESENTACION: CAJA X 1000 | H15: NO | I15: ='Necesidades Trimestrales'!F14 -> CAJA | J15: ='Necesidades Trimestrales'!G14 -> 30 | K15: ='Necesidades Trimestrales'!H14 -> 120
A16: ='Necesidades Trimestrales'!A15 -> 5 | B16: ='Necesidades Trimestrales'!B15 -> 2.9.2-700.2 | C16: ='Necesidades Trimestrales'!E15 -> BROCHES P/ABROCHADORA; NUMERO: 21/6, PRESENTACION: CAJA X 1000 UNIDADES | H16: NO | I16: ='Necesidades Trimestrales'!F15 -> CAJA | J16: ='Necesidades Trimestrales'!G15 -> 30 | K16: ='Necesidades Trimestrales'!H15 -> 195
A17: ='Necesidades Trimestrales'!A16 -> 6 | B17: ='Necesidades Trimestrales'!B16 -> 2.9.2-700.29 | C17: ='Necesidades Trimestrales'!E16 -> BROCHES P/ABROCHADORA; NUMERO: 24/6, PRESENTACION: CAJA X 1000 UNIDADES | H17: NO | I17: ='Necesidades Trimestrales'!F16 -> CAJA | J17: ='Necesidades Trimestrales'!G16 -> 30 | K17: ='Necesidades Trimestrales'!H16 -> 230
A18: ='Necesidades Trimestrales'!A17 -> 7 | B18: ='Necesidades Trimestrales'!B17 -> 2.9.2-262.28 | C18: ='Necesidades Trimestrales'!E17 -> ADHESIVOS P/PAPEL; PRESENTACION: 30 mL, TIPO: SINTETICO TRANSPARENTE | H18: NO | I18: ='Necesidades Trimestrales'!F17 -> UNIDAD | J18: ='Necesidades Trimestrales'!G17 -> 30 | K18: ='Necesidades Trimestrales'!H17 -> 96
A19: ='Necesidades Trimestrales'!A18 -> 8 | B19: ='Necesidades Trimestrales'!B18 -> 2.9.2-1354.21 | C19: ='Necesidades Trimestrales'!E18 -> RESALTADORES; PUNTA: BISELADA, ACCESORIO: SIN, COLOR: SIN VALOR, TIPO PUNTA: BISELADA | H19: NO | I19: ='Necesidades Trimestrales'!F18 -> UNIDAD | J19: ='Necesidades Trimestrales'!G18 -> 100 | K19: ='Necesidades Trimestrales'!H18 -> 95
A20: ='Necesidades Trimestrales'!A19 -> 9 | B20: ='Necesidades Trimestrales'!B19 -> 2.9.2-848.5 | C20: ='Necesidades Trimestrales'!E19 -> LAPIZ; TIPO: COMUN NRO 2, COLOR: NEGRO | H20: NO | I20: ='Necesidades Trimestrales'!F19 -> UNIDAD | J20: ='Necesidades Trimestrales'!G19 -> 50 | K20: ='Necesidades Trimestrales'!H19 -> 55
A21: ='Necesidades Trimestrales'!A20 -> 10 | B21: ='Necesidades Trimestrales'!B20 -> 2.9.2-317.5 | C21: ='Necesidades Trimestrales'!E20 -> BOLIGRAFOS; TRAZO 1,0mm | H21: NO | I21: ='Necesidades Trimestrales'!F20 -> UNIDAD | J21: ='Necesidades Trimestrales'!G20 -> 150 | K21: ='Necesidades Trimestrales'!H20 -> 35
A22: ='Necesidades Trimestrales'!A21 -> 11 | B22: ='Necesidades Trimestrales'!B21 -> 2.9.2-317.32 | C22: ='Necesidades Trimestrales'!E21 -> BOLIGRAFOS; TRAZO: 0,8 mm | H22: NO | I22: ='Necesidades Trimestrales'!F21 -> UNIDAD | J22: ='Necesidades Trimestrales'!G21 -> 150 | K22: ='Necesidades Trimestrales'!H21 -> 95
A23: ='Necesidades Trimestrales'!A22 -> 12 | B23: ='Necesidades Trimestrales'!B22 -> 2.9.2-791.9 | C23: ='Necesidades Trimestrales'!E22 -> TALONARIOS NOTAS AUTOADHESIVAS; MEDIDA 76 X 76mm | H23: NO | I23: ='Necesidades Trimestrales'!F22 -> UNIDAD | J23: ='Necesidades Trimestrales'!G22 -> 30 | K23: ='Necesidades Trimestrales'!H22 -> 200
A24: ='Necesidades Trimestrales'!A23 -> 13 | B24: ='Necesidades Trimestrales'!B23 -> 2.9.2-1428.44 | C24: ='Necesidades Trimestrales'!E23 -> BANDAS ELASTICAS; DIAMETRO: 40 mm, PRESENTACION: ENVASE X 500 GR, ESPESOR: 1 mm | H24: NO | I24: ='Necesidades Trimestrales'!F23 -> PAQUETE | J24: ='Necesidades Trimestrales'!G23 -> 10 | K24: ='Necesidades Trimestrales'!H23 -> 1225
... A36: ='Necesidades Trimestrales'!A35 -> 25 | B36: ='Necesidades Trimestrales'!B35 -> 2.9.2-274.3 | C36: ='Necesidades Trimestrales'!E35 -> BIBLIORATOS; ANCHO 80mm - ANILLO 2 Y PALANCA - TAMAÑO OFICIO - MATERIAL CARTON | H36: NO | I36: ='Necesidades Trimestrales'!F35 -> UNIDAD | J36: ='Necesidades Trimestrales'!G35 -> 30 | K36: ='Necesidades Trimestrales'!H35 -> 505
A37: 26 | B37: ='Necesidades Trimestrales'!B36 -> 2.9.2-323.4 | C37: ='Necesidades Trimestrales'!E36 -> CORRECTORES DE ESCRITURA; CAPACIDAD: 7 mL, ENVASE: LAPIZ (PUNTA METAL), PRESENTACION: LAPIZ (PUNTA METAL) X 7 mL | H37: NO | I37: ='Necesidades Trimestrales'!F36 -> UNIDAD | J37: ='Necesidades Trimestrales'!G36 -> 50 | K37: ='Necesidades Trimestrales'!H36 -> 115
A38: 27 | B38: ='Necesidades Trimestrales'!B37 -> 2.9.2-1153.9 | C38: ='Necesidades Trimestrales'!E37 -> CINTAS ADHESIVAS; ANCHO: 48 mm, LARGO ROLLO: 50 M, MATERIAL: POLIPROPILENO, ACCESORIO: SIN VALOR, TIPO: TRANSPARENTE, LARGO: 50 M | H38: NO | I38: ='Necesidades Trimestrales'!F37 -> UNIDAD | J38: ='Necesidades Trimestrales'!G37 -> 20 | K38: ='Necesidades Trimestrales'!H37 -> 190
A39: 28 | B39: ='Necesidades Trimestrales'!B38 -> 2.9.2-1153.220 | C39: ='Necesidades Trimestrales'!E38 -> CINTAS ADHESIVAS; TIPO: TRANSPARENTE, ANCHO: 24 mm, LARGO: 50 M, MATERIAL: POLIPROPILENO, ACCESORIO: SIN | H39: NO | I39: ='Necesidades Trimestrales'!F38 -> UNIDAD | J39: ='Necesidades Trimestrales'!G38 -> 10 | K39: ='Necesidades Trimestrales'!H38 -> 140
A40: 29 | B40: ='Necesidades Trimestrales'!B39 -> 2.9.2-660.1 | C40: ='Necesidades Trimestrales'!E39 -> CLIPS P/PAPEL; NUMERO: 3, MATERIAL: METAL, CANT. X CAJA: 100, PRESENTACION: CAJA X 100 | H40: NO | I40: ='Necesidades Trimestrales'!F39 -> CAJA | J40: ='Necesidades Trimestrales'!G39 -> 20 | K40: ='Necesidades Trimestrales'!H39 -> 85
A41: 30 | B41: ='Necesidades Trimestrales'!B40 -> 2.9.2-660.17 | C41: ='Necesidades Trimestrales'!E40 -> CLIPS P/PAPEL; NUMERO: 4, MATERIAL: ACERO INOXIDABLE TRIANGULARES, CANT. X CAJA: 100, PRESENTACION: CAJA X 100 | H41: NO | I41: ='Necesidades Trimestrales'!F40 -> CAJA | J41: ='Necesidades Trimestrales'!G40 -> 20 | K41: ='Necesidades Trimestrales'!H40 -> 92
A42: 31 | B42: ='Necesidades Trimestrales'!B41 -> 2.9.2-790.3 | C42: ='Necesidades Trimestrales'!E41 -> CUTER; MATERIAL MANGO: PLASTICO, TIPO HOJA: FIJA, ANCHO HOJA: 9 mm, TIPO DE HOJA: FIJA, ANCHO DE HOJA: 9 mm | H42: NO | I42: ='Necesidades Trimestrales'!F41 -> UNIDAD | J42: ='Necesidades Trimestrales'!G41 -> 10 | K42: ='Necesidades Trimestrales'!H41 -> 130
A43: 32 | B43: ='Necesidades Trimestrales'!B42 -> 2.9.2-790.19 | C43: ='Necesidades Trimestrales'!E42 -> CUTER; MATERIAL MANGO: PLASTICO, ANCHO HOJA: 20 mm, TIPO DE HOJA: MOVIL, TIPO HOJA: MOVIL, ANCHO DE HOJA: 20 mm | H43: NO | I43: ='Necesidades Trimestrales'!F42 -> UNIDAD | J43: ='Necesidades Trimestrales'!G42 -> 10 | K43: ='Necesidades Trimestrales'!H42 -> 236
A44: 33 | B44: ='Necesidades Trimestrales'!B43 -> 2.9.2-866.4 | C44: ='Necesidades Trimestrales'!E43 -> MAQUINAS SACABROCHES; EXTRACTOR: ACERO INOXIDABLE, MATERIAL: PLASTICO | H44: NO | I44: ='Necesidades Trimestrales'!F43 -> UNIDAD | J44: ='Necesidades Trimestrales'!G43 -> 20 | K44: ='Necesidades Trimestrales'!H43 -> 305
A45: 34 | B45: ='Necesidades Trimestrales'!B44 -> 2.3.1-6590.555 | C45: ='Necesidades Trimestrales'!E44 -> SOBRES DE PAPEL; TIPO: MANILA, TAMAÑO: OFICIO, GRAMAJE: 80 GR, PRESENTACION: UNIDAD, CERTIFICADO FORESTAL (GFS): SIN, PORC. FIBRAS RECICLADAS: 0 %, CERT. FIBRA ALTERNATIVA (FCA): SIN | H45: NO | I45: ='Necesidades Trimestrales'!F44 -> UNIDAD | J45: ='Necesidades Trimestrales'!G44 -> 30 | K45: ='Necesidades Trimestrales'!H44 -> 2075
A46: 35 | B46: ='Necesidades Trimestrales'!B45 -> 2.3.1-6590.556 | C46: ='Necesidades Trimestrales'!E45 -> SOBRES DE PAPEL; TIPO: MANILA, TAMAÑO: A4, GRAMAJE: 80 GR, PRESENTACION: UNIDAD, CERTIFICADO FORESTAL (GFS): SIN, PORC. FIBRAS RECICLADAS: 0 %, CERT. FIBRA ALTERNATIVA (FCA): SIN | H46: NO | I46: ='Necesidades Trimestrales'!F45 -> UNIDAD | J46: ='Necesidades Trimestrales'!G45 -> 30 | K46: ='Necesidades Trimestrales'!H45 -> 1690
A47: 36 | B47: ='Necesidades Trimestrales'!B46 -> 2.3.1-6563.953 | C47: ='Necesidades Trimestrales'!E46 -> PAPELES EN HOJA; TIPO DE PAPEL: OBRA, DIMENSION: 21 X 29,7 Cm, GRAMAJE: 80 GR/M2, PRESENTACION: ENVASE X 500 HOJAS, CERTIFICADO FORESTAL (GFS): SIN, PORC. FIBRAS RECICLADAS: 0 %, CERT. FIBRA ALTERNATIVA (FCA): SIN | H47: NO | I47: ='Necesidades Trimestrales'!F46 -> RESMA | J47: ='Necesidades Trimestrales'!G46 -> 250 | K47: ='Necesidades Trimestrales'!H46 -> 1090
A48: 37 | B48: ='Necesidades Trimestrales'!B47 -> 2.3.1-6563.917 | C48: ='Necesidades Trimestrales'!E47 -> PAPELES EN HOJA; TIPO DE PAPEL: OBRA, DIMENSION: 21,6 X 35,6 Cm, GRAMAJE: 80 GR/M2, PRESENTACION: ENVASE X 500 HOJAS, CERTIFICADO FORESTAL (GFS): SIN, PORC. FIBRAS RECICLADAS: 0 %, CERT. FIBRA ALTERNATIVA (FCA): SIN | H48: NO | I48: ='Necesidades Trimestrales'!F47 -> RESMA | J48: ='Necesidades Trimestrales'!G47 -> 250 | K48: ='Necesidades Trimestrales'!H47 -> 1345
... A52: 41 | B52: ='Necesidades Trimestrales'!B51 -> 2.3.1-928.8 | C52: ='Necesidades Trimestrales'!E51 -> ARANDELAS DE CARTON; DIAMETRO: 1 pulg, PRESENTACION: CAJA X 500 UNIDADES | H52: NO | I52: ='Necesidades Trimestrales'!F51 -> CAJA | J52: ='Necesidades Trimestrales'!G51 -> 20 | K52: ='Necesidades Trimestrales'!H51 -> 560
A53: Costo total estimado: | C53: UN MILLON CIENTO VEINTICUATRO MIL QUINIENTOS SETENTA CON 00/100 CENTAVOS.- | J53: =SUMPRODUCT(J12:J52*K12:K52) -> 1124570
