Workbook

Sheet SAF 011
A1: 2022
B2: Pedido de Necesidades Trimestrales
A4: JURISDICCION: | C4: 040 - MINISTERIO DE SALUD
A5: SAF N°: | C5: 011 - DIRECCION PROVINCIAL DE ADMINISTRACION - MINISTERIO DE SALUD
A6: EJERCICIO: | C6: 2022
A7: TRIMESTRE: | C7: CUARTO
A9: ID | B9: CODIGO ITEM | C9: RUBRO DE COMPRA | D9: I.P.P. | E9: DESCRIPCION | F9: UNIDAD DE MEDIDA | G9: SECRETARIA DE ADMINISTRACION | H9: TOTAL S.A. | I9: SMPyPS | J9: TOTAL SMPyPS | K9: DIR. LAB. CENTRAL | L9: TOTAL DE LAB CENTRAL | M9: BCO DE SANGRE | N9: TOTAL BANCO DE SANGRE | O9: APS | P9: TOTAL A.P.S. | Q9: DIR DE CANCER | R9: TOTAL DE DIR DE CANCER | S9: FARMACIA | T9: TOTAL FARMACIA | U9: ODONTOLOGIA | V9: TOTAL DE ODONTOLOG | W9: SAME | X9: TOTAL SAME | Y9: UAI | Z9: TOTAL UAI | AA9: MATERNIDAD E INFANCIA | AB9: TOTAL MATERNIDAD E INFANCIA | AC9: SASP | AD9: TOTAL SASP | AE9: SALUD Y MEDIO AMBIENTE | AF9: TOTAL SALUD Y MEDIO AMBIENTE | AG9: VECTORES Y ZOONOSIS | AH9: TOTAL DE VECT Y ZOON | AI9: DISCAPACIDAD | AJ9: TOTAL DISCAPACIDAD | AK9: REG Y CONTROL EN SALUD | AL9: TOTAL REG Y CONTROL EN SALUD | AM9: SPyGS | AN9: TOTAL SPyGS | AO9: SALUD MENTAL | AP9: TOTAL SALUD MENTAL | AQ9: AREAS Y DPAS | AR9: TOTAL DPAS | AS9: EPIDEMIOLOGIA | AT9: TOTAL EPIDEMIOLOGIA | AU9: MS | AV9: TOTAL MS | AW9: SIRM | AX9: TOTAL SIRM | AY9: CANTIDAD TOTAL | AZ9: PRECIO UNITARIO ESTIMADO | BA9: IMPORTE TOTAL ESTIMADO | BB9: ESPECIFICACION TECNICA
A10: 1 | B10: 2.5.6-793.31 | C10: COMBUSTIBLES Y LUBRICANTES | D10: 2.5.6 | E10: GAS OIL; PRESENTACION: POR LITRO, USO: MOTORES DIESEL,COMERCIALIZACION: GRADO 3, DESTINO: DPTO. S.F.V. DE CATAMARCA | F10: LITROS | G10: 700 | I10: 0 | J10: =+I10*AZ10 -> 0 | M10: 0 | N10: =+M10*AZ10 -> 0 | O10: 250 | P10: =+O10*AZ10 -> 59300 | R10: =+Q10*AZ10 -> 0 | U10: 0 | V10: =+U10*AZ10 -> 0 | W10: 21000 | X10: =+W10*AZ10 -> 4981200 | AA10: 0 | AB10: =+AA10*AZ10 -> 0 | AC10: 16000 | AD10: =+AC10*AZ10 -> 3795200 | AE10: 1500 | AF10: =+AE10*AZ10 -> 355800 | AG10: 700 | AH10: =+AG10*AZ10 -> 166040 | AI10: 550 | AJ10: =+AI10*AZ10 -> 130460 | AL10: =+AK10*AZ10 -> 0 | AM10: 0 | AN10: =+AM10*AZ10 -> 0 | AO10: 0 | AP10: =+AO10*AZ10 -> 0 | AQ10: 31500 | AR10: =+AQ10*AZ10 -> 7471800 | AS10: 0 | AT10: =+AS10*AZ10 -> 0 | AU10: 1700 | AV10: =+AU10*AZ10 -> 403240 | AW10: 11000 | AX10: =+AW10*AZ10 -> 2609200 | AY10: =+AQ10+AO10+AM10+AK10+AI10+AG10+AE10+AC10+AA10+Y10+W10+U10+S10+Q10+O10+M10+K10+I10+AS10+G10+AU10+AW10 -> 84900 | AZ10: 237.2 | BA10: =+AY10*AZ10 -> 20138280 | BB10: Se Entregarán Fraccionado bajo la forma de vales de 30 Lts. cada uno y cuando la cantidad adjudicada no permita la confección de dicho vale, para completar se emitirá uno por una cantidad menor hasta completar la cantidad solicitada
E11: TOTAL RUBRO COMBUSTIBLES | P11: =+O11*AZ11 -> 0 | BA11: =+SUM(BA10:BA10) -> 20138280
C14: ITEM 1
C15: DETALLE TECNICO Y ESPECIFICACIONES | D15: Se Entregarán Fraccionado bajo la forma de vales de 30 Lts. cada uno y cuando la cantidad adjudicada no permita la confección de dicho vale, para completar se emitirá uno por una cantidad menor hasta completar la cantidad solicitada
C17: SE ADJUNTA ANEXO CON LOS DOMINIOS Y MATRICULA DE LOS VEHICULOS PARA LOS QUE SE SOLICITA EL COMBUSTIBLE
C19: Plazos de entrega | D19: cinco (5) dias habiles
C21: Lugar de Entrega: | D21: SECRETARIA DE ADMINISTRACION - MS - CHACABUCO N° 169 - en el horario de 8:00hs a 12:00hs de lunes a viernes
C23: Calidad Minima esperada
C25: Mantenimiento | D25: cuarenta y cinco (45) días

Sheet ANEXO
A1: ANEXO VEHICULOS MINISTERIO DE SALUD
B3: Vehiculo | C3: Dominio | D3: Nº de Motor | E3: Nº de Chasis | F3: Año | G3: USO
A4: 1 | B4: Fiat Ducato Maxi Carga Multijet JTD Furgon. Ambulancia.- | C4: NUB-239 | D4: 7166186 | E4: 93W245G74D2109186 | F4: 2014 | G4: AMBULANCIA
A5: 2 | B5: Fiat Ducato Maxi Carga Multijet JTD Furgon. Ambulancia.- | C5: NWM-372 | D5: 7167174 | E5: 93W245G74D2109552 | F5: 2014 | G5: AMBULANCIA
A6: 3 | B6: Fiat Ducato Maxi Carga Multijet JTD Furgon. Ambulancia.- | C6: NYF-582 | D6: 7188314 | E6: 93W245G74E2121568 | F6: 2014 | G6: AMBULANCIA
A7: 4 | B7: Fiat Ducato Maxi Carga Multijet JTD Furgon. Ambulancia.- | C7: AA-658-GZ | D7: 72497599 | E7: 93W245G84H2161256 | F7: 2017 | G7: AMBULANCIA
A8: 5 | B8: Fiat Ducato Maxi Carga Multijet. Ambulancia.- | C8: AA-702-NG | D8: 72497500 | E8: 93W245G82H2160424 | F8: 2017 | G8: AMBULANCIA
A9: 6 | B9: Fiat Ducato Maxi Carga Multijet JTD Furgon. Ambulancia.- | C9: MPH-712 | D9: 7155140 | E9: 93W245G84D2102211 | F9: 2013 | G9: AMBULANCIA
A10: 7 | B10: Fiat Ducato Maxi Carga Multijet JTD Furgon. Ambulancia.- | C10: AB-518-CS | D10: 7257521 | E10: 93W245G84H2165048 | F10: 2017 | G10: AMBULANCIA
A11: 8 | B11: Fiat Ducato Maxi Carga Multijet JTD Furgon. Ambulancia.- | C11: AB-518-CT | D11: 7257618 | E11: 93W245G84H2165113 | F11: 2017 | G11: AMBULANCIA
A12: 9 | B12: Renault Master L2H2 AA. Amubulancia.- | C12: AD-993-OD | D12: M9TB870C260128 | E12: 93YMAFESCKJ625829 | F12: 2019 | G12: AMBULANCIA
A13: 10 | B13: Renault Master L2H2 AA. Amubulancia.- | C13: AD-993-OC | D13: M9TB870C260095 | E13: 93YMAFESCKJ625788 | F13: 2019 | G13: AMBULANCIA
A14: 11 | B14: Ford Transit 2,2 TDCI. Furgon. Ambulancia.- | C14: LYY-038 | D14: WF0XXPTTFCTC58018 | E14: CYRCCTC58018 | F14: 2013 | G14: AMBULANCIA
A15: 12 | B15: Ford Transit 2,2 L 125 T350 TA C/AA. Furgon Larga. Neonatal. Ambuancia.- | C15: MNW-260 | D15: CYRCDTS07184 | E15: WFOXXPTTFDTS07184 | F15: 2013 | G15: AMBULANCIA
A16: 13 | B16: Mercedez Benz Sprinter 313, combi 3550 9+1. Combi.- | C16: HQV-791 | D16: 61198170090932 | E16: 8AC9036629E010749 | F16: 2008 | G16: OFICIAL
A17: 14 | B17: Frod Ranger XL 3,0 TDI DC 4x4 Plus L. Camioneta.- | C17: JRJ-105 | D17: L1A008818 | E17: 8AFER13P48J398152 | F17: 2011 | G17: transp.combustible
A18: 15 | B18: Mercedez Benz 1114 Camion.- | C18: K-0022935 | D18: 37290710141314 | E18: 38400712097854 | F18: 1993 | G18: OFICIAL
A19: 16 | B19: Tanqueta Grosspal, chasis EGT2895,.- | C19: 101-JRJ105 | G19: transp.combustible
A20: 17 | B20: Ford Ranger DC 4X4 L 2.2L. Camioneta.- | C20: AD-398-KY | D20: QJ2RKJ113446 | E20: 8AFAR23KXKJ113446 | F20: 2018 | G20: OFICIAL
A21: 18 | B21: Ford Rnger XL 3,0 TDI D/C 4x4 Plus Camioneta..- | C21: FPU-504 | D21: C34197293 | E21: 8SAFDR13P56J473958 | F21: 2008 | G21: OFICIAL
A22: 19 | B22: Toyota Hilux SW4 4X4 SRX 2,8 TDI 6 M/T 7A. Camioneta.- | C22: AD-125-XM | D22: 1GD-G029980 | E22: 8AJBA3FS8H026028 | F22: 2018 | G22: OFICIAL
A23: 20 | B23: Chevrolet Blazer DLX 2,8 TDI. Camioneta.- | C23: GRL-150 | D23: M1A301900 | E23: 9BG116BJ08C407853 | F23: 2007 | G23: OFICIAL
A24: 21 | B24: Chevrolet Meriva GL 1,7 DTI. Sedan.- | C24: EQN-369 | D24: Y17DT0881965 | E24: 9BGXF75804C217860 | F24: 2006 | G24: OFICIAL
A25: 22 | B25: Iveco Turbo Daily 49,12 Chasis. Furgon.- | C25: GEG-132 | D25: 36214211157 | E25: 93ZC4980168323467 | F25: 2007 | G25: serv.especiales
A26: 23 | B26: Renault Master 2,3 DC I Furgon.- | C26: PIQ-472 | D26: M9TA876C029626 | E26: 93YMAIECATGJ94529 | F26: 2015 | G26: serv.especiales
A27: 24 | B27: TOYOTA HYLUX 4x4 CABINA DOBLE SR3.0 TDI. Camioneta.- | C27: OMA-771 | D27: 1KDA586508 | E27: 8AJFZZ263F5027841 | F27: 2015 | G27: OFICIAL
A28: 25 | B28: Ford Ranger 3,0 TDI SC 4x2 Plus. Camioneta- | C28: INA-475 | D28: D56285125 | E28: 8AFDR12P4AJ285846 | F28: 2009 | G28: OFICIAL
A29: 26 | B29: Chevrolet S10 2,8 TDI 4x2 D/C DLX EL. Camioneta.- | C29: FSI-818 | D29: M1T253871 | E29: 9BG138AC06C417378 | F29: 2005 | G29: OFICIAL
A30: 27 | B30: Crysler RAM laramie 1500 pick up 4x4 doble cabina. Camioneta.- | C30: AD-189-SN | D30: TNXE6209711768 | E30: 3C6RRBET7HG94960 | F30: 2017 | G30: OFICIAL
A31: 28 | B31: Chevrolet S10 2,8 TDI 4x2 D/C DLX EL. Camioneta.- | C31: GAJ-557 | D31: M1T241375 | E31: 9BG138AC06C426943 | F31: 2007 | G31: OFICIAL
A32: 29 | B32: VW Caddy 1,9 SD. Furgon.- | C32: DMQ-710 | D32: 1Y635412 | E32: 8AWZZZ9EZYA520052 | F32: 2000 | G32: OFICIAL
A33: 30 | B33: Ford Rnger XL 3,0 TDI D/C 4x2 Plus. Camioneta.- | C33: GVM-697 | D33: C34243556 | E33: 8AFER13P58J133751 | F33: 2007 | G33: OFICIAL
A34: 31 | B34: Ford Ranger XL T 3,0 TDI D/C 4x4 LIM. Camioneta.- | C34: GVU-547 | D34: C34243362 | E34: 8AFER13P18J133746 | F34: 2007 | G34: OFICIAL
A35: 32 | B35: Ford Ranger XL T 3,0 TDI D/C 4x2 PLUS. Camioneta.- | C35: IPE-911 | D35: D56289530 | E35: 8AFER10P6AJ299531 | F35: 2010 | G35: OFICIAL
A36: 33 | B36: Ford Ranger DC 4x2 XL Plus 3,0 D. Camioneta.- | C36: LCA-236 | D36: L1A029545 | E36: 8AFDR12PXCJ490431 | F36: 2012 | G36: OFICIAL
A37: 34 | B37: Fiat Ducato. Minibus.- | C37: AD-266-ZZ | D37: 7253701 | E37: 93W245G84H2162641 | F37: 2017 | G37: serv.especiales
A38: 35 | B38: Renault trafic. Furgon.- | C38: DNR-926 | D38: FSQJ606C012115 | E38: 8A1T31JZZYL086918 | F38: 1999 | G38: OFICIAL
A39: 36 | B39: Chevrolet S10 2,8 TED 4X2 LS Pick up . Camioneta.- | C39: AC-091-RR | D39: HRUF171781023 | E39: 9BG148CK0JC414811 | F39: 2017 | G39: OFICIAL
A40: 37 | B40: Ford Rnger XL 3,0 TDI D/C 4x2. Camioneta.- | C40: IPE-916 | D40: D56290126 | E40: 8AFER10P7AJ299795 | F40: 2010 | G40: OFICIAL
A41: 38 | B41: Toyota hylux AK-SW4-4x4 SRX 2,8 TDI. Camioneta.- | C41: AD-125-XL | D41: 1GD-4378200 | E41: 8AJBA3FS8J0250098 | F41: 2018 | G41: OFICIAL
...

Sheet NP
A1: NOTA DE PEDIDO | J1: N° | K1: XX/2022
A3: JURISDICCIÓN: | D3: ='SAF 011'!C4 -> 040 - MINISTERIO DE SALUD
A4: SAF: | D4: ='SAF 011'!C5 -> 011 - DIRECCION PROVINCIAL DE ADMINISTRACION - MINISTERIO DE SALUD
A5: UNIDAD EJECUTORA: | D5: 352 - MINISTERIO DE SALUD
A6: DEPENDENCIA SOLICITANTE: | D6: 352 - MINISTERIO DE SALUD
A7: PERIODO UTILIZACIÓN: | D7: 4° TRIMESTRE 2022
A8: OBJETO: | D8: ADQ. DEL RUBRO COMBUSTIBLE (GAS OIL) PARA LAS DEPENDENCIAS DEL MINISTERIO DE SALUD
A10: Ítem | B10: Codigo Item | C10: DESCRIPCIÓN | H10: Adjunta Detalle Técnico | I10: Unidad Medida | J10: Precio Unitario Estimado | K10: Cantidad Solicitada
A12: 1 | B12: ='SAF 011'!B10 -> 2.5.6-793.31 | C12: ='SAF 011'!E10 -> GAS OIL; PRESENTACION: POR LITRO, USO: MOTORES DIESEL,COMERCIALIZACION: GRADO 3, DESTINO: DPTO. S.F.V. DE CATAMARCA | H12: SI | I12: ='SAF 011'!F10 -> LITROS | J12: ='SAF 011'!AZ10 -> 237.2 | K12: ='SAF 011'!AY10 -> 84900
A14: Costo total estimado: PESOS VEINTE MILLONES CIENTO TREINTA Y OCHO MIL DOSCIENTOS OCHENTA CON 00/100.- | J14: =+J12*K12 -> 20138280

Sheet APG
A1: EJERCICIO: | D1: 2022 | P1: AUTORIZACION PARA GASTAR
A4: JURISDICCIÓN: | G4: =NP!D3 -> 040 - MINISTERIO DE SALUD
A5: SAF: | G5: =NP!D4 -> 011 - DIRECCION PROVINCIAL DE ADMINISTRACION - MINISTERIO DE SALUD
A6: UNIDAD EJECUTORA: | G6: =NP!D5 -> 352 - MINISTERIO DE SALUD
A7: DEPENDENCIA SOLICITANTE: | G7: =NP!D6 -> 352 - MINISTERIO DE SALUD
A8: AUTORIZACIÓN:
A9: Señor Director de Administración o Titular del Servicio Administrativo Financiero:
A10: Autorizo la realización de los trámites correspondientes, a fin de proveer a este Organismo los bienes que se detallan en Nota de Pedido N° XX/2022 , afectando la erogación resultante a los créditos presupuestarios aprobados a favor de esta Unidad Ejecutora, conforme al siguiente detalle:
A12: IMPUTACIÓN PRESUPUESTARIA
A13: CÓDIGO | O13: DENOMINACIÓN DE LA PARTIDA PRESUPUESTARIA | Q13: IMPORTE
A14: PR | B14: SB | C14: PY | D14: AC | E14: OB | F14: UG | G14: FIN | H14: FUN | I14: I | J14: P | K14: P | L14: SubP | M14: M | N14: FF
A15: 1 | D15: 1 | F15: 4901 | G15: 3 | H15: 1 | I15: 2 | J15: 5 | K15: 6 | M15: 1 | N15: 1.1 | O15: COMBUSTIBLES Y LUBRICANTES | Q15: =NP!J14 -> 20138280
A38: TOTAL DE PESOS: VEINTIUN MILLONES NOVECIENTOS NOVENTA Y NUEVE MIL DOSCIENTOS VEINTIDOS CON 00/100.- | Q38: =SUM(Q15:Q37) -> 20138280
A40: JUSTIFICACIÓN:
A41: =NP!D8 -> ADQ. DEL RUBRO COMBUSTIBLE (GAS OIL) PARA LAS DEPENDENCIAS DEL MINISTERIO DE SALUD
