Workbook

Sheet Necesidades Trimestrales
B2: Pedido de Necesidades Trimestrales
A4: JURISDICCION: | C4: 040 - Ministerio de Salud
A5: SAF N°: | C5: 11/ 23/ 24 o 28- "…......."
A6: EJERCICIO: | C6: 2022
A7: TRIMESTRE: | C7: 2
A9: ID | B9: CODIGO ITEM | C9: RUBRO DE COMPRA | D9: I.P.P. | E9: DESCRIPCION | F9: UNIDAD DE MEDIDA | G9: CANTIDAD | H9: PRECIO UNITARIO ESTIMADO | I9: IMPORTE TOTAL ESTIMADO
A10: 1 | B10: 2.5.2-1829.24 | C10: PROD. MEDICO/FARMACEUTICOS/LAB | D10: 252 | E10: ANTIVIRALES; TIPO: MONODROGA, DROGA GENERICA: ACICLOVIR, FORMA FARMACEUTICA: COMPRIMIDO, PRESENTACION: 200 mGr | F10: COMPRIMIDO | G10: 1 | H10: 28.9 | I10: =+G10*H10 -> 28.9
A11: 2 | B11: 2.5.2-1829.35 | C11: PROD. MEDICO/FARMACEUTICOS/LAB | D11: 252 | E11: ANTIVIRALES; TIPO: MONODROGA, DROGA GENERICA: ACICLOVIR, FORMA FARMACEUTICA: COMPRIMIDO, PRESENTACION: 400 mGr | F11: COMPRIMIDO | G11: 1 | H11: 37.5 | I11: =+G11*H11 -> 37.5
A12: 3 | B12: 2.5.2-1821.235 | C12: PROD. MEDICO/FARMACEUTICOS/LAB | D12: 252 | E12: ANTIBIOTICOS P/PERSONAS; TIPO: MONODROGA, DROGA GENERICA: ACICLOVIR 500 MG, FORMA FARMACEUTICA: FRASCO AMPOLLA, PRESENTACION: 500 mGr | F12: AMPOLLA | G12: 1 | H12: 350 | I12: =+G12*H12 -> 350
A13: 4 | B13: 2.5.2-1829.48 | C13: PROD. MEDICO/FARMACEUTICOS/LAB | D13: 252 | E13: ANTIVIRALES; TIPO: MONODROGA, DROGA GENERICA: ACICLOVIR 80 MG/ ML, FORMA FARMACEUTICA: SUSPENSION, PRESENTACION: ENVASE X 200 ML | F13: FRASCO | G13: 1 | H13: 980 | I13: =+G13*H13 -> 980
A14: 5 | B14: 2.5.2-1724.16 | C14: PROD. MEDICO/FARMACEUTICOS/LAB | D14: 252 | E14: ANALGESICOS; TIPO: MONODROGA, DROGA GENERICA: ACIDO ACETILSALICILICO, PRESENTACION: 100 mGr, FORMA FARMACEUTICA: COMPRIMIDO | F14: COMPRIMIDO | G14: 1 | H14: 1.88 | I14: =+G14*H14 -> 1.88
A15: 6 | B15: 2.5.2-1724.3 | C15: PROD. MEDICO/FARMACEUTICOS/LAB | D15: 252 | E15: ANALGESICOS ; PRESENTACION: 500 mGr, TIPO: MONODROGA, DROGA GENERICA: ACIDO ACETILSALICILICO, FORMA FARMACEUTICA: COMPRIMIDO | F15: COMPRIMIDO | G15: 1 | H15: 2.58 | I15: =+G15*H15 -> 2.58
A16: 7 | B16: 2.5.2-1864.6 | C16: PROD. MEDICO/FARMACEUTICOS/LAB | D16: 252 | E16: HIPOURICEMIANTES; TIPO: MONODROGA, DROGA GENERICA: ALOPURINOL 300 mGr, FORMA FARMACEUTICA: COMPRIMIDO, PRESENTACION: UNIDAD | F16: COMPRIMIDO | G16: 1 | H16: 41.3 | I16: =+G16*H16 -> 41.3
A17: 8 | B17: 2.5.2-1821.1 | C17: PROD. MEDICO/FARMACEUTICOS/LAB | D17: 252 | E17: ANTIBIOTICOS P/PERSONAS; TIPO: MONODROGA, DROGA GENERICA: AMIKACINA, PRESENTACION: 500 mGr, FORMA FARMACEUTICA: AMPOLLA | F17: AMPOLLA | G17: 1 | H17: 87.95 | I17: =+G17*H17 -> 87.95
A18: 9 | B18: 2.5.2-1821.524 | C18: PROD. MEDICO/FARMACEUTICOS/LAB | D18: 252 | E18: ANTIBIOTICOS P/PERSONAS; TIPO: ASOCIACION, DROGA GENERICA: AMOXICILINA + AC.CLAVULANICO 400 MG / 57 MG, FORMA FARMACEUTICA: SUSPENSION, PRESENTACION: ENVASE X 70 ML | F18: FRASCO | G18: 1 | H18: 410 | I18: =+G18*H18 -> 410
A19: 10 | B19: 2.5.2-1821.440 | C19: PROD. MEDICO/FARMACEUTICOS/LAB | D19: 252 | E19: ANTIBIOTICOS P/PERSONAS; TIPO: ASOCIACION, DROGA GENERICA: AMOXICIL. 875 MG+CLAVUL.125 MG mGr, FORMA FARMACEUTICA: COMPRIMIDO, PRESENTACION: UNIDAD | F19: COMPRIMIDO | G19: 1 | H19: 38 | I19: =+G19*H19 -> 38
A20: 11 | B20: 2.5.2-1821.9 | C20: PROD. MEDICO/FARMACEUTICOS/LAB | D20: 252 | E20: ANTIBIOTICOS P/PERSONAS; TIPO: MONODROGA, DROGA GENERICA: AMOXICILINA, PRESENTACION: 500 mGr, FORMA FARMACEUTICA: COMPRIMIDOS | F20: COMPRIMIDO | G20: 1 | H20: 15 | I20: =+G20*H20 -> 15
A21: 12 | B21: 2.5.2-1821.399 | C21: PROD. MEDICO/FARMACEUTICOS/LAB | D21: 252 | E21: ANTIBIOTICOS P/PERSONAS; TIPO: MONODROGA, DROGA GENERICA: AMOXICILINA 500 mGr, FORMA FARMACEUTICA: SUSPENSION, PRESENTACION: ENVASE X 90 mL | F21: FRASCO | G21: 1 | H21: 320 | I21: =+G21*H21 -> 320
A22: 13 | B22: 2.5.2-1821.389 | C22: PROD. MEDICO/FARMACEUTICOS/LAB | D22: 252 | E22: ANTIBIOTICOS P/PERSONAS; TIPO: ASOCIACION, DROGA GENERICA: AMPICILINA + SULBACTAN, FORMA FARMACEUTICA: FRASCO AMPOLLA, PRESENTACION: ENVASE X 1,5 GR | F22: AMPOLLA | G22: 1 | H22: 145 | I22: =+G22*H22 -> 145 | J22: STOCK FCIA CENTRAL
A23: 14 | B23: 2.5.2-1821.8 | C23: PROD. MEDICO/FARMACEUTICOS/LAB | D23: 252 | E23: ANTIBIOTICOS P/PERSONAS; TIPO: MONODROGA, DROGA GENERICA: AMPICILINA, FORMA FARMACEUTICA: AMPOLLA, PRESENTACION: 1 GR | F23: AMPOLLA | G23: 1 | H23: 99 | I23: =+G23*H23 -> 99
A24: 15 | B24: 2.5.2-1821.5 | C24: PROD. MEDICO/FARMACEUTICOS/LAB | D24: 252 | E24: ANTIBIOTICOS P/PERSONAS; TIPO: MONODROGA, DROGA GENERICA: AMPICILINA, FORMA FARMACEUTICA: COMPRIMIDOS, PRESENTACION: 500 mGr | F24: COMPRIMIDO | G24: 1 | H24: 22 | I24: =+G24*H24 -> 22
A25: 16 | B25: 2.5.2-1823.113 | C25: PROD. MEDICO/FARMACEUTICOS/LAB | D25: 252 | E25: ANTIMICOTICOS; DROGA GENERICA: ANFOTERICINA B LIPOSOMAL, FORMA FARMACEUTICA: AMPOLLA, PRESENTACION: 50 MGR, TIPO: MONODROGA | F25: AMPOLLA | G25: 1 | H25: 29500 | I25: =+G25*H25 -> 29500
A26: 17 | B26: 2.5.2-1823.1 | C26: PROD. MEDICO/FARMACEUTICOS/LAB | D26: 252 | E26: ANTIMICOTICOS; DROGA GENERICA: ANFOTERICINA B, FORMA FARMACEUTICA: AMPOLLA, PRESENTACION: 50 mGr, TIPO: MONODROGA | F26: AMPOLLA | G26: 1 | H26: 795 | I26: =+G26*H26 -> 795 | J26: STOCK FCIA CENTRAL
A27: 18 | B27: 2.5.2-1821.502 | C27: PROD. MEDICO/FARMACEUTICOS/LAB | D27: 252 | E27: ANTIBIOTICOS P/PERSONAS; TIPO: MONODROGA, DROGA GENERICA: AZITROMICINA 200 mGr, FORMA FARMACEUTICA: SUSPENSION, PRESENTACION: ENVASE X 15 Ml | F27: FRASCO | G27: 1 | H27: 562.5 | I27: =+G27*H27 -> 562.5
A28: 19 | B28: 2.5.2-2199.16 | C28: PROD. MEDICO/FARMACEUTICOS/LAB | D28: 252 | E28: BLOQUEANTES NEUROMUSCULARES; DROGA GENERICA: ATRACURIO, FORMA FARMACEUTICA: AMPOLLA, PRESENTACION: 50 mGr, TIPO: MONODROGA | F28: AMPOLLA | G28: 1 | H28: 259 | I28: =+G28*H28 -> 259 | J28: ENVIA NACION NO PEDIR 2022
A29: 20 | B29: 2.5.2-1821.94 | C29: PROD. MEDICO/FARMACEUTICOS/LAB | D29: 252 | E29: ANTIBIOTICOS P/PERSONAS; TIPO: MONODROGA, DROGA GENERICA: AZITROMICINA, FORMA FARMACEUTICA: COMPRIMIDO, PRESENTACION: 500 mGr | F29: COMPRIMIDO | G29: 1 | H29: 37.45 | I29: =+G29*H29 -> 37.45
A30: 21 | B30: 2.5.2-1837.19 | C30: PROD. MEDICO/FARMACEUTICOS/LAB | D30: 252 | E30: HIPOTENSORES; TIPO: MONODROGA, DROGA GENERICA: BACLOFENO, FORMA FARMACEUTICA: COMPRIMIDO, PRESENTACION: 10 mGr | F30: COMPRIMIDO | G30: 1 | H30: 16 | I30: =+G30*H30 -> 16
A31: 22 | B31: 2.5.2-1726.523 | C31: PROD. MEDICO/FARMACEUTICOS/LAB | D31: 252 | E31: SOLUCIONES P/MEDICINA; TIPO: SULFATO DE BARIO, PRESENTACION: ENVASE SUSPENSION X 225 ML | F31: FRASCO | G31: 1 | H31: 9664.28 | I31: =+G31*H31 -> 9664.28
A32: 23 | B32: 2.5.2-1726.524 | C32: PROD. MEDICO/FARMACEUTICOS/LAB | D32: 252 | E32: SOLUCIONES P/MEDICINA; TIPO: SULFATO DE BARIO, PRESENTACION: ENVASE SUSPENSION PARA ENEMA X 500 ML | F32: FRASCO | G32: 1 | H32: 16740 | I32: =+G32*H32 -> 16740
A33: 24 | B33: 2.5.2-1726.525 | C33: PROD. MEDICO/FARMACEUTICOS/LAB | D33: 252 | E33: SOLUCIONES P/MEDICINA; TIPO: SULFATO DE BARIO, PRESENTACION: ENVASE SUSPENSION ORAL X 300 ML | F33: FRASCO | G33: 1 | H33: 10347.39 | I33: =+G33*H33 -> 10347.39
A34: 25 | B34: 2.5.2-1883.139 | C34: PROD. MEDICO/FARMACEUTICOS/LAB | D34: 252 | E34: ANESTESICOS LOCALES; TIPO: ASOCIACION, DROGA GENERICA: BUPIVACAINA 0,5 % C/EPINEFRINA, FORMA FARMACEUTICA: FRASCO AMPOLLA, PRESENTACION: ENVASE X 20 mL | F34: FRASCO | G34: 1 | H34: 3100 | I34: =+G34*H34 -> 3100
A35: 26 | B35: 2.5.2-1883.24 | C35: PROD. MEDICO/FARMACEUTICOS/LAB | D35: 252 | E35: ANESTESICOS LOCALES; TIPO: MONODROGA, DROGA GENERICA: BUPIVACAINA 0,5 %, FORMA FARMACEUTICA: FRASCO, PRESENTACION: 20 mL | F35: FRASCO | G35: 1 | H35: 350 | I35: =+G35*H35 -> 350
A36: 27 | B36: 2.5.2-1883.188 | C36: PROD. MEDICO/FARMACEUTICOS/LAB | D36: 252 | E36: ANESTESICOS LOCALES; TIPO: MONODROGA, DROGA GENERICA: BUPIVACAINA 0,5% HIPERBARICA, FORMA FARMACEUTICA: AMPOLLA, PRESENTACION: 4 ML CON AGUJA 27 G X 3 1/2 CON INTRODUCTOR | F36: AMPOLLA | G36: 1 | H36: 1420 | I36: =+G36*H36 -> 1420
A37: 28 | B37: 2.5.2-1821.321 | C37: PROD. MEDICO/FARMACEUTICOS/LAB | D37: 252 | E37: ANTIBIOTICOS P/PERSONAS; TIPO: MONODROGA, DROGA GENERICA: CEFALEXINA 500 mGr, FORMA FARMACEUTICA: COMPRIMIDO, PRESENTACION: 1 UN | F37: COMPRIMIDO | G37: 1 | H37: 15.3 | I37: =+G37*H37 -> 15.3
A38: 29 | B38: 2.5.2-1821.337 | C38: PROD. MEDICO/FARMACEUTICOS/LAB | D38: 252 | E38: ANTIBIOTICOS P/PERSONAS; TIPO: MONODROGA, DROGA GENERICA: CEFALEXINA 500MG, FORMA FARMACEUTICA: SUSPENSION, PRESENTACION: ENVASE X 90 mL | F38: FRASCO | G38: 1 | H38: 298 | I38: =+G38*H38 -> 298
A39: 30 | B39: 2.5.2-1821.405 | C39: PROD. MEDICO/FARMACEUTICOS/LAB | D39: 252 | E39: ANTIBIOTICOS P/PERSONAS; TIPO: MONODROGA, DROGA GENERICA: CEFALOTINA SODICA, FORMA FARMACEUTICA: FRASCO AMPOLLA, PRESENTACION: 1 GR | F39: AMPOLLA | G39: 1 | H39: 145 | I39: =+G39*H39 -> 145
A40: 31 | B40: 2.5.2-1821.62 | C40: PROD. MEDICO/FARMACEUTICOS/LAB | D40: 252 | E40: ANTIBIOTICOS P/PERSONAS; TIPO: MONODROGA, DROGA GENERICA: CEFAZOLINA, FORMA FARMACEUTICA: AMPOLLA, PRESENTACION: 1 GR | F40: AMPOLLA | G40: 1 | H40: 148 | I40: =+G40*H40 -> 148
... A50: 41 | B50: 2.5.2-1821.43 | C50: PROD. MEDICO/FARMACEUTICOS/LAB | D50: 252 | E50: ANTIBIOTICOS P/PERSONAS; TIPO: MONODROGA, DROGA GENERICA: CLINDAMICINA, FORMA FARMACEUTICA: AMPOLLA, PRESENTACION: 600 mGr | F50: AMPOLLA | G50: 1 | H50: 85 | I50: =+G50*H50 -> 85
A51: 42 | B51: 2.5.2-1821.234 | C51: PROD. MEDICO/FARMACEUTICOS/LAB | D51: 252 | E51: ANTIBIOTICOS P/PERSONAS; TIPO: MONODROGA, DROGA GENERICA: COLISTINA 100 MG, FORMA FARMACEUTICA: FRASCO AMPOLLA, PRESENTACION: 100 mGr | F51: AMPOLLA | G51: 1 | H51: 451 | I51: =+G51*H51 -> 451 | J51: STOCK FCIA CENTRAL
A52: 43 | B52: 2.5.2-1726.526 | C52: PROD. MEDICO/FARMACEUTICOS/LAB | D52: 252 | E52: SOLUCIONES P/MEDICINA; TIPO: CONTRASTE RADIOLOGICO NO IONICO, PRESENTACION: ENVASE X 50 ML | F52: FRASCO | G52: 1 | H52: 1850 | I52: =+G52*H52 -> 1850
...

Sheet  NotaPedido
A1: NOTA DE PEDIDO | J1: N° | K1: xxx/2022
A3: JURISDICCIÓN: | D3: ='Necesidades Trimestrales'!C4 -> 040 - Ministerio de Salud
A4: SAF: | D4: ='Necesidades Trimestrales'!C5 -> 11/ 23/ 24 o 28- "…......."
A5: UNIDAD EJECUTORA: | D5: XXXX
A6: DEPENDENCIA SOLICITANTE: | D6: XXXX
A7: PERIODO UTILIZACIÓN: | D7: Semestral
A8: OBJETO: | D8: Adquisición de TERAPIA ANTIINFECCIOSA SISTEMICA/SUEROS INMUNES E INMUNOGLOBULINAS Y MEDIOS DE CONTRASTES /ANALGESICOS ANTINFLAMATORIOS /MIORRELAJANTES/ANESTESICOS/ANALGESICOS OPIACIOS
A10: Ítem | B10: Codigo Item | C10: DESCRIPCIÓN | H10: Adjunta Detalle Técnico | I10: Unidad Medida | J10: Precio Unitario Estimado | K10: Cantidad Solicitada
A12: 1 | B12: =+'Necesidades Trimestrales'!B10 -> 2.5.2-1829.24 | C12: =+'Necesidades Trimestrales'!E10 -> ANTIVIRALES; TIPO: MONODROGA, DROGA GENERICA: ACICLOVIR, FORMA FARMACEUTICA: COMPRIMIDO, PRESENTACION: 200 mGr | H12: NO | I12: =+'Necesidades Trimestrales'!F10 -> COMPRIMIDO | J12: =+'Necesidades Trimestrales'!H10 -> 28.9 | K12: 1
A13: 2 | B13: =+'Necesidades Trimestrales'!B11 -> 2.5.2-1829.35 | C13: =+'Necesidades Trimestrales'!E11 -> ANTIVIRALES; TIPO: MONODROGA, DROGA GENERICA: ACICLOVIR, FORMA FARMACEUTICA: COMPRIMIDO, PRESENTACION: 400 mGr | H13: NO | I13: =+'Necesidades Trimestrales'!F11 -> COMPRIMIDO | J13: =+'Necesidades Trimestrales'!H11 -> 37.5 | K13: 1
A14: 3 | B14: =+'Necesidades Trimestrales'!B12 -> 2.5.2-1821.235 | C14: =+'Necesidades Trimestrales'!E12 -> ANTIBIOTICOS P/PERSONAS; TIPO: MONODROGA, DROGA GENERICA: ACICLOVIR 500 MG, FORMA FARMACEUTICA: FRASCO AMPOLLA, PRESENTACION: 500 mGr | H14: NO | I14: =+'Necesidades Trimestrales'!F12 -> AMPOLLA | J14: =+'Necesidades Trimestrales'!H12 -> 350 | K14: 1
A15: 4 | B15: =+'Necesidades Trimestrales'!B13 -> 2.5.2-1829.48 | C15: =+'Necesidades Trimestrales'!E13 -> ANTIVIRALES; TIPO: MONODROGA, DROGA GENERICA: ACICLOVIR 80 MG/ ML, FORMA FARMACEUTICA: SUSPENSION, PRESENTACION: ENVASE X 200 ML | H15: NO | I15: =+'Necesidades Trimestrales'!F13 -> FRASCO | J15: =+'Necesidades Trimestrales'!H13 -> 980 | K15: 1
A16: 5 | B16: =+'Necesidades Trimestrales'!B14 -> 2.5.2-1724.16 | C16: =+'Necesidades Trimestrales'!E14 -> ANALGESICOS; TIPO: MONODROGA, DROGA GENERICA: ACIDO ACETILSALICILICO, PRESENTACION: 100 mGr, FORMA FARMACEUTICA: COMPRIMIDO | H16: NO | I16: =+'Necesidades Trimestrales'!F14 -> COMPRIMIDO | J16: =+'Necesidades Trimestrales'!H14 -> 1.88 | K16: 1
A17: 6 | B17: =+'Necesidades Trimestrales'!B15 -> 2.5.2-1724.3 | C17: =+'Necesidades Trimestrales'!E15 -> ANALGESICOS ; PRESENTACION: 500 mGr, TIPO: MONODROGA, DROGA GENERICA: ACIDO ACETILSALICILICO, FORMA FARMACEUTICA: COMPRIMIDO | H17: NO | I17: =+'Necesidades Trimestrales'!F15 -> COMPRIMIDO | J17: =+'Necesidades Trimestrales'!H15 -> 2.58 | K17: 1
A18: 7 | B18: =+'Necesidades Trimestrales'!B16 -> 2.5.2-1864.6 | C18: =+'Necesidades Trimestrales'!E16 -> HIPOURICEMIANTES; TIPO: MONODROGA, DROGA GENERICA: ALOPURINOL 300 mGr, FORMA FARMACEUTICA: COMPRIMIDO, PRESENTACION: UNIDAD | H18: NO | I18: =+'Necesidades Trimestrales'!F16 -> COMPRIMIDO | J18: =+'Necesidades Trimestrales'!H16 -> 41.3 | K18: 1
A19: 8 | B19: =+'Necesidades Trimestrales'!B17 -> 2.5.2-1821.1 | C19: =+'Necesidades Trimestrales'!E17 -> ANTIBIOTICOS P/PERSONAS; TIPO: MONODROGA, DROGA GENERICA: AMIKACINA, PRESENTACION: 500 mGr, FORMA FARMACEUTICA: AMPOLLA | H19: NO | I19: =+'Necesidades Trimestrales'!F17 -> AMPOLLA | J19: =+'Necesidades Trimestrales'!H17 -> 87.95 | K19: 1
A20: 9 | B20: =+'Necesidades Trimestrales'!B18 -> 2.5.2-1821.524 | C20: =+'Necesidades Trimestrales'!E18 -> ANTIBIOTICOS P/PERSONAS; TIPO: ASOCIACION, DROGA GENERICA: AMOXICILINA + AC.CLAVULANICO 400 MG / 57 MG, FORMA FARMACEUTICA: SUSPENSION, PRESENTACION: ENVASE X 70 ML | H20: NO | I20: =+'Necesidades Trimestrales'!F18 -> FRASCO | J20: =+'Necesidades Trimestrales'!H18 -> 410 | K20: 1
A21: 10 | B21: =+'Necesidades Trimestrales'!B19 -> 2.5.2-1821.440 | C21: =+'Necesidades Trimestrales'!E19 -> ANTIBIOTICOS P/PERSONAS; TIPO: ASOCIACION, DROGA GENERICA: AMOXICIL. 875 MG+CLAVUL.125 MG mGr, FORMA FARMACEUTICA: COMPRIMIDO, PRESENTACION: UNIDAD | H21: NO | I21: =+'Necesidades Trimestrales'!F19 -> COMPRIMIDO | J21: =+'Necesidades Trimestrales'!H19 -> 38 | K21: 1
A22: 11 | B22: =+'Necesidades Trimestrales'!B20 -> 2.5.2-1821.9 | C22: =+'Necesidades Trimestrales'!E20 -> ANTIBIOTICOS P/PERSONAS; TIPO: MONODROGA, DROGA GENERICA: AMOXICILINA, PRESENTACION: 500 mGr, FORMA FARMACEUTICA: COMPRIMIDOS | H22: NO | I22: =+'Necesidades Trimestrales'!F20 -> COMPRIMIDO | J22: =+'Necesidades Trimestrales'!H20 -> 15 | K22: 1
A23: 12 | B23: =+'Necesidades Trimestrales'!B21 -> 2.5.2-1821.399 | C23: =+'Necesidades Trimestrales'!E21 -> ANTIBIOTICOS P/PERSONAS; TIPO: MONODROGA, DROGA GENERICA: AMOXICILINA 500 mGr, FORMA FARMACEUTICA: SUSPENSION, PRESENTACION: ENVASE X 90 mL | H23: NO | I23: =+'Necesidades Trimestrales'!F21 -> FRASCO | J23: =+'Necesidades Trimestrales'!H21 -> 320 | K23: 1
... A142: 131 | B142: =+'Necesidades Trimestrales'!B140 -> 2.5.2-2199.13 | C142: =+'Necesidades Trimestrales'!E140 -> BLOQUEANTES NEUROMUSCULARES; DROGA GENERICA: BROMURO DE VECURONIO, FORMA FARMACEUTICA: AMPOLLA X 10 mGr, PRESENTACION: UNIDAD, TIPO: MONODROGA | H142: NO | I142: =+'Necesidades Trimestrales'!F140 -> AMPOLLA | J142: =+'Necesidades Trimestrales'!H140 -> 864 | K142: 1
A143: Costo total estimado: xxxxxxxxxxxxxxxxxxxx con 00/100. | J143: =SUMPRODUCT(J12:J142,K12:K142) -> 765344.06

Sheet Autor Gastar
A1: EJERCICIO: | D1: ='Necesidades Trimestrales'!C6 -> 2022 | P1: AUTORIZACION PARA GASTAR
A4: JURISDICCIÓN: | G4: =' NotaPedido'!D3 -> 040 - Ministerio de Salud
A5: SAF: | G5: =' NotaPedido'!D4 -> 11/ 23/ 24 o 28- "…......."
A6: UNIDAD EJECUTORA: | G6: =' NotaPedido'!D5 -> XXXX
A7: DEPENDENCIA SOLICITANTE: | G7: =' NotaPedido'!D6 -> XXXX
A8: AUTORIZACIÓN:
A9: Señor Jefe de Servicio Administrativo Financiero:
A10: ="Autorizo la realización de los trámites correspondientes, a fin de proveer a este Organismo los bienes y/o servicios que se detallan en Nota de Pedido N° " & ' NotaPedido'!K1&", afectando la erogación resultante a los créditos presupuestarios aprobados a favor de esta Unidad Ejecutora, conforme al siguiente detalle:" -> Autorizo la realización de los trámites correspondientes, a fin de proveer a este Organismo los bienes y/o servicios que se detallan en Nota de Pedido N° xxx/2022, afectando la erogación resultante a los créditos presupuestarios aprobados a favor de esta Unidad Ejecutora, conforme al siguiente detalle:
A12: IMPUTACIÓN PRESUPUESTARIA
A13: CÓDIGO | O13: DENOMINACIÓN DE LA PARTIDA PRESUPUESTARIA | Q13: IMPORTE
A14: PR | B14: SB | C14: PY | D14: AC | E14: OB | F14: UG | G14: FIN | H14: FUN | I14: I | J14: P | K14: P | L14: SubP | M14: M | N14: FF
F15: 4901 | G15: 3 | H15: 310 | I15: 2 | J15: 5 | K15: 2 | M15: 1 | N15: 1.1 | O15: Productos Farmacéuticos y Medicinales
A23: TOTAL DE PESOS: xxxxxxxxxxxxxxx con 00/100. | Q23: =SUM(Q15:Q22) -> 0
A25: JUSTIFICACIÓN:
A26: Para la adquisición de .... … destinados al servico de …... del Hospital …...............
