Workbook

Sheet Necesidades Trimestrales
B2: Pedido de Necesidades Trimestrales
A4: JURISDICCION: | C4: 45- Ministerio de Desarrollo Social
A5: SAF N°: | C5: 25- Direccion Provincial de Gestion Administracion y RRHH
A6: EJERCICIO: | C6: 2022
A7: TRIMESTRE: | C7: 2
A9: ID | B9: CODIGO ITEM | C9: RUBRO DE COMPRA | D9: I.P.P. | E9: DESCRIPCION | F9: UNIDAD DE MEDIDA | G9: CANTIDAD | H9: PRECIO UNITARIO ESTIMADO | I9: IMPORTE TOTAL ESTIMADO
A10: 1 | B10: 2.9.2-1153.166 | C10: LIBRERIA,PAP. Y UTILES OFICINA | D10: =LEFT(B10,5) -> 2.9.2 | E10: CINTAS ADHESIVAS; TIPO: P/EMBALAR, ANCHO: 48 mm, LARGO: 40 M, MATERIAL: TRANSPARENTE, ACCESORIO: SIN | F10: UNIDAD | G10: 300 | H10: 226.38 | I10: =+G10*H10 -> 67914
A11: 2 | B11: 2.9.2-1450.2 | C11: LIBRERIA,PAP. Y UTILES OFICINA | D11: =LEFT(B11,5) -> 2.9.2 | E11: TINTAS P/SELLOS; ENVASE: 30 CM3, COLOR: NEGRO, TIPO DE SELLO: DE GOMA, PRESENTACION: ENVASE X 30 CM3 | F11: UNIDAD | G11: 60 | H11: 616 | I11: =+G11*H11 -> 36960
A12: 3 | B12: 2.9.2-1611.19 | C12: LIBRERIA,PAP. Y UTILES OFICINA | D12: =LEFT(B12,5) -> 2.9.2 | E12: FOLIOS TRANSPARENTES; TAMAÑO: A4, PERFORACIONES: 5, MATERIAL: PLASTICO (POLIETILENO) | F12: UNIDAD | G12: 300 | H12: 21 | I12: =+G12*H12 -> 6300
A13: 4 | B13: 2.9.2-1611.18 | C13: LIBRERIA,PAP. Y UTILES OFICINA | D13: =LEFT(B13,5) -> 2.9.2 | E13: FOLIOS TRANSPARENTES; TAMAÑO: OFICIO, PERFORACIONES: 5, MATERIAL: PLASTICO (POLIETILENO) | F13: UNIDAD | G13: 300 | H13: 20.3 | I13: =+G13*H13 -> 6090
A14: 5 | B14: 2.9.2-323.4 | C14: LIBRERIA,PAP. Y UTILES OFICINA | D14: =LEFT(B14,5) -> 2.9.2 | E14: CORRECTORES DE ESCRITURA; CAPACIDAD: 7 mL, ENVASE: LAPIZ (PUNTA METAL), PRESENTACION: LAPIZ (PUNTA METAL) X 7 mL | F14: UNIDAD | G14: 180 | H14: 204.4 | I14: =+G14*H14 -> 36792
A15: 6 | B15: 2.9.2-858.7 | C15: LIBRERIA,PAP. Y UTILES OFICINA | D15: =LEFT(B15,5) -> 2.9.2 | E15: PERFORADORAS; DIST. ENTRE AGUJ.: FIJO, N° PERFORACIONES: 2, MATERIAL ESTRUCTURA: FUNDICION HIERRO BASE MADERA, GUIA POSICION PAPEL: CON, TAMAÑO: GRANDE, MATERIAL: FUNDICION HIERRO BASE MADERA | F15: UNIDAD | G15: 20 | H15: 5178.6 | I15: =+G15*H15 -> 103572
A16: 7 | B16: 2.3.1-6563.1077 | C16: LIBRERIA,PAP. Y UTILES OFICINA | D16: =LEFT(B16,5) -> 2.3.1 | E16: PAPELES EN HOJA; TIPO DE PAPEL: CARBONICO, DIMENSION: OFICIO, GRAMAJE: 30 GR/M2, PRESENTACION: ENVASE X 50 HOJAS, CERTIFICADO FORESTAL (GFS): SIN, PORC. FIBRAS RECICLADAS: 0 %, CERT. FIBRA ALTERNATIVA (FCA): SIN | F16: UNIDAD | G16: 10 | H16: 5780.6 | I16: =+G16*H16 -> 57806
A17: 8 | B17: 2.9.2-261.4 | C17: LIBRERIA,PAP. Y UTILES OFICINA | D17: =LEFT(B17,5) -> 2.9.2 | E17: ABROCHADORAS DE PAPEL; TIPO: PINZA, MATERIAL: SIN VALOR, P/BROCHES: 21/6, MEDIDA: 21/6 | F17: UNIDAD | G17: 40 | H17: 3836 | I17: =+G17*H17 -> 153440
A18: 9 | B18: 2.9.2-261.14 | C18: LIBRERIA,PAP. Y UTILES OFICINA | D18: =LEFT(B18,5) -> 2.9.2 | E18: ABROCHADORAS DE PAPEL; TIPO: PINZA, P/BROCHES: 10/50, MATERIAL: METALICA, MEDIDA: 10/50 | F18: UNIDAD | G18: 40 | H18: 2226 | I18: =+G18*H18 -> 89040
A19: 10 | B19: 2.9.2-700.2 | C19: LIBRERIA,PAP. Y UTILES OFICINA | D19: =LEFT(B19,5) -> 2.9.2 | E19: BROCHES P/ABROCHADORA; NUMERO: 21/6, PRESENTACION: CAJA X 1000 UNIDADES | F19: UNIDAD | G19: 400 | H19: 141.4 | I19: =+G19*H19 -> 56560
A20: 11 | B20: 2.9.2-700.28 | C20: LIBRERIA,PAP. Y UTILES OFICINA | D20: =LEFT(B20,5) -> 2.9.2 | E20: BROCHES P/ABROCHADORA; NUMERO: 10/50, PRESENTACION: CAJA X 1000 UNIDADES | F20: UNIDAD | G20: 600 | H20: 252 | I20: =+G20*H20 -> 151200
A21: 12 | B21: 2.3.1-6563.1009 | C21: LIBRERIA,PAP. Y UTILES OFICINA | D21: =LEFT(B21,5) -> 2.3.1 | E21: PAPELES EN HOJA; TIPO DE PAPEL: BLANCO, DIMENSION: OFICIO, GRAMAJE: 80 GR, PRESENTACION: ENVASE X 500 HOJAS, CERTIFICADO FORESTAL (GFS): SIN, PORC. FIBRAS RECICLADAS: 0 %, CERT. FIBRA ALTERNATIVA (FCA): SIN | F21: UNIDAD | G21: 600 | H21: 1428 | I21: =+G21*H21 -> 856800
... A32: 23 | B32: 2.9.2-872.21 | C32: LIBRERIA,PAP. Y UTILES OFICINA | D32: =LEFT(B32,5) -> 2.9.2 | E32: ANILLADOS; MATERIAL: PLASTICO, PASO: AMERICANO, LONG.DE CUERPO: 35,5 Cm, DIAMETRO: 33 mm | F32: UNIDAD | G32: 100 | H32: 56 | I32: =+G32*H32 -> 5600
A33: 24 | B33: 2.9.6-401.2045 | C33: REPUESTOS | D33: 2.9.6 | E33: CARTUCHOS DE TONER; CODIGO: TN 1060, USO: BROTHER | F33: UNIDAD | G33: 15 | H33: 1666 | I33: =+G33*H33 -> 24990
A34: 25 | B34: 2.9.6-401.1563 | C34: REPUESTOS | D34: 2.9.6 | E34: CARTUCHOS DE TONER; CODIGO: HP 85A, USO: HP | F34: UNIDAD | G34: 15 | H34: 1225 | I34: =+G34*H34 -> 18375
A35: 26 | B35: 2.9.2-1634.59 | C35: LIBRERIA,PAP. Y UTILES OFICINA | D35: =LEFT(B35,5) -> 2.9.2 | E35: TAPAS PLASTICAS; TIPO: POLIPROPILENO, FORMATO: OFICIO, PRESENTACION: ENVASE X 50 UN, GRAMAJE: 80 GR/M2 | F35: UNIDAD | G35: 2 | H35: 1062.6 | I35: =+G35*H35 -> 2125.2
A36: 27 | B36: 2.9.2-1634.60 | C36: LIBRERIA,PAP. Y UTILES OFICINA | D36: 2.9.2 | E36: TAPAS PLASTICAS; TIPO: POLIPROPILENO, FORMATO: A4, PRESENTACION: ENVASE X 100 UN, GRAMAJE: 80 GR/M2 | F36: UNIDAD | G36: 1 | H36: 2125.2 | I36: =+G36*H36 -> 2125.2
A37: 28 | B37: 2.9.2-1428.44 | C37: LIBRERIA,PAP. Y UTILES OFICINA | D37: 2.9.2 | E37: BANDAS ELASTICAS; DIAMETRO: 40 mm, PRESENTACION: ENVASE X 500 GR, ESPESOR: 1 mm | F37: UNIDAD | G37: 5 | H37: 1323 | I37: =+G37*H37 -> 6615
A38: 29 | B38: 2.9.2-1428.36 | C38: LIBRERIA,PAP. Y UTILES OFICINA | D38: 2.9.2 | E38: BANDAS ELASTICAS; DIAMETRO: 1 Cm, PRESENTACION: ENVASE X 100 GR, ESPESOR: 1 Cm | F38: UNIDAD | G38: 5 | H38: 1008 | I38: =+G38*H38 -> 5040
A39: 30 | B39: 2.9.2-674.22 | C39: LIBRERIA,PAP. Y UTILES OFICINA | D39: 2.9.2 | E39: REGLAS GRADUADAS; TIPO: PLANA, LONG.DE CUERPO: 30 Cm, MATERIAL: ACRILICO | F39: UNIDAD | G39: 30 | H39: 252 | I39: =+G39*H39 -> 7560
A40: 31 | B40: 2.9.2-1062.12 | C40: LIBRERIA,PAP. Y UTILES OFICINA | D40: =LEFT(B40,5) -> 2.9.2 | E40: PAPELES ANOTADOR AUTOADHESIVOS; PRESENTACION: 100 HOJAS, LARGO X ANCHO: 76 X 76 mm | F40: UNIDAD | G40: 50 | H40: 179.2 | I40: =+G40*H40 -> 8960
A41: 32 | B41: 2.9.2-696.18 | C41: LIBRERIA,PAP. Y UTILES OFICINA | D41: =LEFT(B41,5) -> 2.9.2 | E41: SACAPUNTAS; MATERIAL: PLASTICO, FIJACION: SIN, NUMERO: UNIVERSAL, CANTIDAD DE BOCAS: 1, TIPO: ESCOLAR | F41: UNIDAD | G41: 40 | H41: 173.6 | I41: =+G41*H41 -> 6944
A42: 33 | B42: 2.3.1-6587.276 | C42: LIBRERIA,PAP. Y UTILES OFICINA | D42: =LEFT(B42,5) -> 2.3.1 | E42: PAPELES ENCUADERNADOS; CANT. DE HOJAS: 80 HOJAS, TAMAÑO: A4, TIPO: BLOCK, CERTIFICADO FORESTAL (GFS): SIN, PORC. FIBRAS RECICLADAS: 0 % | F42: UNIDAD | G42: 50 | H42: 1064 | I42: =+G42*H42 -> 53200
A43: 34 | B43: 2.9.2-5042.36 | C43: HERRAMIENTAS | D43: =LEFT(B43,5) -> 2.9.2 | E43: TIJERA; USO: P/PAPEL, MATERIAL: ACERO INOXIDABLE, LONG.DE CUERPO: 17 Cm | F43: UNIDAD | G43: 30 | H43: 336 | I43: =+G43*H43 -> 10080
A44: 35 | B44: 2.9.2-1358.353 | C44: LIBRERIA,PAP. Y UTILES OFICINA | D44: =LEFT(B44,5) -> 2.9.2 | E44: CARPETAS; MATERIAL PLASTICO - TAMAÑO A4. | F44: UNIDAD | G44: 100 | H44: 92.4 | I44: =+G44*H44 -> 9240
A45: 36 | B45: 2.9.2-1358.354 | C45: LIBRERIA,PAP. Y UTILES OFICINA | D45: =LEFT(B45,5) -> 2.9.2 | E45: CARPETAS; MATERIAL PLASTICO - TAMAÑO OFICIO. | F45: UNIDAD | G45: 100 | H45: 78.4 | I45: =+G45*H45 -> 7840
A46: 37 | B46: 2.3.1-6563.967 | C46: LIBRERIA,PAP. Y UTILES OFICINA | D46: =LEFT(B46,5) -> 2.3.1 | E46: PAPELES EN HOJA; TIPO DE PAPEL: CARTULINA, DIMENSION: 74 X 110 Cm, GRAMAJE: 120 GR, PRESENTACION: UNIDAD, CERTIFICADO FORESTAL (GFS): SIN, PORC. FIBRAS RECICLADAS: 0 %, CERT. FIBRA ALTERNATIVA (FCA): 0 % | F46: UNIDAD | G46: 100 | H46: 20 | I46: =+G46*H46 -> 2000
A47: 38 | B47: 2.9.2-661.43 | C47: LIBRERIA,PAP. Y UTILES OFICINA | D47: =LEFT(B47,5) -> 2.9.2 | E47: GOMAS DE BORRAR; USO: LAPIZ Y TINTA, DIMENSION: 42 X 18 X 10 mm, MATERIAL: CAUCHO, PRESENTACION: ENVASE X 40 UN | F47: UNIDAD | G47: 4 | H47: 1783.6 | I47: =+G47*H47 -> 7134.4
A48: 39 | B48: 2.9.2-848.21 | C48: LIBRERIA,PAP. Y UTILES OFICINA | D48: =LEFT(B48,5) -> 2.9.2 | E48: LAPIZ; TIPO: CAJA X 24, COLOR: VARIADOS | F48: UNIDAD | G48: 15 | H48: 1960 | I48: =+G48*H48 -> 29400
A49: 40 | B49: 2.9.2-1954.1 | C49: LIBRERIA,PAP. Y UTILES OFICINA | D49: =LEFT(B49,5) -> 2.9.2 | E49: BORRADORES; MATERIAL: PLASTICO - FIBRA, TIPO: PARA MARCADOR | F49: UNIDAD | G49: 12 | H49: 392 | I49: =+G49*H49 -> 4704
A50: 41 | B50: 2.9.2-1616.128 | C50: LIBRERIA,PAP. Y UTILES OFICINA | D50: =LEFT(B50,5) -> 2.9.2 | E50: MARCADORES; TIPO PARA PIZARRA - TRAZO GRUESO - PUNTA REDONDA - RECARGABLE NO | F50: UNIDAD | G50: 48 | H50: 239.4 | I50: =+G50*H50 -> 11491.2
A51: 42 | B51: 2.9.2-5457.11 | C51: LIBRERIA,PAP. Y UTILES OFICINA | D51: =LEFT(B51,5) -> 2.9.2 | E51: ANOTADORES; TAMAÑO: 15 X 21 Cm, TIPO: RAYADO | F51: UNIDAD | G51: 60 | H51: 488.25 | I51: =+G51*H51 -> 29295
... A65: 56 | B65: 2.9.2-5042.40 | C65: HERRAMIENTAS | D65: =LEFT(B65,5) -> 2.9.2 | E65: TIJERA; USO: CORTE, MATERIAL: ACERO INOXIDABLE, LONG.DE CUERPO: 21 Cm | F65: UNIDAD | G65: 10 | H65: 532 | I65: =+G65*H65 -> 5320
B68: Especificidades Item N° 1:
...

Sheet  NotaPedido
A1: NOTA DE PEDIDO | J1: N° | K1: 177/2022
A3: JURISDICCIÓN: | D3: ='Necesidades Trimestrales'!C4 -> 45- Ministerio de Desarrollo Social
A4: SAF: | D4: ='Necesidades Trimestrales'!C5 -> 25- Direccion Provincial de Gestion Administracion y RRHH
A5: UNIDAD EJECUTORA: | D5: 01 - Ministerio Desarrollo Social
A6: DEPENDENCIA SOLICITANTE: | D6: 01- Actividad Central
A7: PERIODO UTILIZACIÓN: | D7: ='Necesidades Trimestrales'!C7 & "° Trimestre - Año " & 'Necesidades Trimestrales'!C6 -> 2° Trimestre - Año 2022
A8: OBJETO: | D8: Adquisicion de Articulos de Librería destinados a las distintas oficinas dependientes del Ministerio de Desarrollo Social
A10: Ítem | B10: Codigo Item | C10: DESCRIPCIÓN | H10: Adjunta Detalle Técnico | I10: Unidad Medida | J10: Precio Unitario Estimado | K10: Cantidad Solicitada
A12: 1 | B12: ='Necesidades Trimestrales'!B10 -> 2.9.2-1153.166 | C12: ='Necesidades Trimestrales'!E10 -> CINTAS ADHESIVAS; TIPO: P/EMBALAR, ANCHO: 48 mm, LARGO: 40 M, MATERIAL: TRANSPARENTE, ACCESORIO: SIN | H12: NO | I12: ='Necesidades Trimestrales'!F10 -> UNIDAD | J12: ='Necesidades Trimestrales'!H10 -> 226.38 | K12: ='Necesidades Trimestrales'!G10 -> 300
A13: 2 | B13: ='Necesidades Trimestrales'!B11 -> 2.9.2-1450.2 | C13: ='Necesidades Trimestrales'!E11 -> TINTAS P/SELLOS; ENVASE: 30 CM3, COLOR: NEGRO, TIPO DE SELLO: DE GOMA, PRESENTACION: ENVASE X 30 CM3 | H13: NO | I13: ='Necesidades Trimestrales'!F11 -> UNIDAD | J13: ='Necesidades Trimestrales'!H11 -> 616 | K13: ='Necesidades Trimestrales'!G11 -> 60
A14: 3 | B14: ='Necesidades Trimestrales'!B12 -> 2.9.2-1611.19 | C14: ='Necesidades Trimestrales'!E12 -> FOLIOS TRANSPARENTES; TAMAÑO: A4, PERFORACIONES: 5, MATERIAL: PLASTICO (POLIETILENO) | H14: NO | I14: ='Necesidades Trimestrales'!F12 -> UNIDAD | J14: ='Necesidades Trimestrales'!H12 -> 21 | K14: ='Necesidades Trimestrales'!G12 -> 300
A15: 4 | B15: ='Necesidades Trimestrales'!B13 -> 2.9.2-1611.18 | C15: ='Necesidades Trimestrales'!E13 -> FOLIOS TRANSPARENTES; TAMAÑO: OFICIO, PERFORACIONES: 5, MATERIAL: PLASTICO (POLIETILENO) | H15: NO | I15: ='Necesidades Trimestrales'!F13 -> UNIDAD | J15: ='Necesidades Trimestrales'!H13 -> 20.3 | K15: ='Necesidades Trimestrales'!G13 -> 300
A16: 5 | B16: ='Necesidades Trimestrales'!B14 -> 2.9.2-323.4 | C16: ='Necesidades Trimestrales'!E14 -> CORRECTORES DE ESCRITURA; CAPACIDAD: 7 mL, ENVASE: LAPIZ (PUNTA METAL), PRESENTACION: LAPIZ (PUNTA METAL) X 7 mL | H16: NO | I16: ='Necesidades Trimestrales'!F14 -> UNIDAD | J16: ='Necesidades Trimestrales'!H14 -> 204.4 | K16: ='Necesidades Trimestrales'!G14 -> 180
A17: 6 | B17: ='Necesidades Trimestrales'!B15 -> 2.9.2-858.7 | C17: ='Necesidades Trimestrales'!E15 -> PERFORADORAS; DIST. ENTRE AGUJ.: FIJO, N° PERFORACIONES: 2, MATERIAL ESTRUCTURA: FUNDICION HIERRO BASE MADERA, GUIA POSICION PAPEL: CON, TAMAÑO: GRANDE, MATERIAL: FUNDICION HIERRO BASE MADERA | H17: NO | I17: ='Necesidades Trimestrales'!F15 -> UNIDAD | J17: ='Necesidades Trimestrales'!H15 -> 5178.6 | K17: ='Necesidades Trimestrales'!G15 -> 20
A18: 7 | B18: ='Necesidades Trimestrales'!B16 -> 2.3.1-6563.1077 | C18: ='Necesidades Trimestrales'!E16 -> PAPELES EN HOJA; TIPO DE PAPEL: CARBONICO, DIMENSION: OFICIO, GRAMAJE: 30 GR/M2, PRESENTACION: ENVASE X 50 HOJAS, CERTIFICADO FORESTAL (GFS): SIN, PORC. FIBRAS RECICLADAS: 0 %, CERT. FIBRA ALTERNATIVA (FCA): SIN | H18: NO | I18: ='Necesidades Trimestrales'!F16 -> UNIDAD | J18: ='Necesidades Trimestrales'!H16 -> 5780.6 | K18: ='Necesidades Trimestrales'!G16 -> 10
A19: 8 | B19: ='Necesidades Trimestrales'!B17 -> 2.9.2-261.4 | C19: ='Necesidades Trimestrales'!E17 -> ABROCHADORAS DE PAPEL; TIPO: PINZA, MATERIAL: SIN VALOR, P/BROCHES: 21/6, MEDIDA: 21/6 | H19: NO | I19: ='Necesidades Trimestrales'!F17 -> UNIDAD | J19: ='Necesidades Trimestrales'!H17 -> 3836 | K19: ='Necesidades Trimestrales'!G17 -> 40
A20: 9 | B20: ='Necesidades Trimestrales'!B18 -> 2.9.2-261.14 | C20: ='Necesidades Trimestrales'!E18 -> ABROCHADORAS DE PAPEL; TIPO: PINZA, P/BROCHES: 10/50, MATERIAL: METALICA, MEDIDA: 10/50 | H20: NO | I20: ='Necesidades Trimestrales'!F18 -> UNIDAD | J20: ='Necesidades Trimestrales'!H18 -> 2226 | K20: ='Necesidades Trimestrales'!G18 -> 40
A21: 10 | B21: ='Necesidades Trimestrales'!B19 -> 2.9.2-700.2 | C21: ='Necesidades Trimestrales'!E19 -> BROCHES P/ABROCHADORA; NUMERO: 21/6, PRESENTACION: CAJA X 1000 UNIDADES | H21: NO | I21: ='Necesidades Trimestrales'!F19 -> UNIDAD | J21: ='Necesidades Trimestrales'!H19 -> 141.4 | K21: ='Necesidades Trimestrales'!G19 -> 400
A22: 11 | B22: ='Necesidades Trimestrales'!B20 -> 2.9.2-700.28 | C22: ='Necesidades Trimestrales'!E20 -> BROCHES P/ABROCHADORA; NUMERO: 10/50, PRESENTACION: CAJA X 1000 UNIDADES | H22: NO | I22: ='Necesidades Trimestrales'!F20 -> UNIDAD | J22: ='Necesidades Trimestrales'!H20 -> 252 | K22: ='Necesidades Trimestrales'!G20 -> 600
A23: 12 | B23: ='Necesidades Trimestrales'!B21 -> 2.3.1-6563.1009 | C23: ='Necesidades Trimestrales'!E21 -> PAPELES EN HOJA; TIPO DE PAPEL: BLANCO, DIMENSION: OFICIO, GRAMAJE: 80 GR, PRESENTACION: ENVASE X 500 HOJAS, CERTIFICADO FORESTAL (GFS): SIN, PORC. FIBRAS RECICLADAS: 0 %, CERT. FIBRA ALTERNATIVA (FCA): SIN | H23: NO | I23: ='Necesidades Trimestrales'!F21 -> UNIDAD | J23: ='Necesidades Trimestrales'!H21 -> 1428 | K23: ='Necesidades Trimestrales'!G21 -> 600
... A40: 29 | B40: ='Necesidades Trimestrales'!B38 -> 2.9.2-1428.36 | C40: ='Necesidades Trimestrales'!E38 -> BANDAS ELASTICAS; DIAMETRO: 1 Cm, PRESENTACION: ENVASE X 100 GR, ESPESOR: 1 Cm | H40: NO | I40: ='Necesidades Trimestrales'!F38 -> UNIDAD | J40: ='Necesidades Trimestrales'!H38 -> 1008 | K40: ='Necesidades Trimestrales'!G38 -> 5
A41: 30 | B41: ='Necesidades Trimestrales'!B39 -> 2.9.2-674.22 | C41: ='Necesidades Trimestrales'!E39 -> REGLAS GRADUADAS; TIPO: PLANA, LONG.DE CUERPO: 30 Cm, MATERIAL: ACRILICO | H41: NO | I41: ='Necesidades Trimestrales'!F38 -> UNIDAD | J41: ='Necesidades Trimestrales'!H39 -> 252 | K41: ='Necesidades Trimestrales'!G39 -> 30
A42: 31 | B42: ='Necesidades Trimestrales'!B40 -> 2.9.2-1062.12 | C42: ='Necesidades Trimestrales'!E40 -> PAPELES ANOTADOR AUTOADHESIVOS; PRESENTACION: 100 HOJAS, LARGO X ANCHO: 76 X 76 mm | H42: SI | I42: ='Necesidades Trimestrales'!F39 -> UNIDAD | J42: ='Necesidades Trimestrales'!H40 -> 179.2 | K42: ='Necesidades Trimestrales'!G40 -> 50
A43: 32 | B43: ='Necesidades Trimestrales'!B41 -> 2.9.2-696.18 | C43: ='Necesidades Trimestrales'!E41 -> SACAPUNTAS; MATERIAL: PLASTICO, FIJACION: SIN, NUMERO: UNIVERSAL, CANTIDAD DE BOCAS: 1, TIPO: ESCOLAR | H43: NO | I43: ='Necesidades Trimestrales'!F40 -> UNIDAD | J43: ='Necesidades Trimestrales'!H41 -> 173.6 | K43: ='Necesidades Trimestrales'!G41 -> 40
A44: 33 | B44: ='Necesidades Trimestrales'!B42 -> 2.3.1-6587.276 | C44: ='Necesidades Trimestrales'!E42 -> PAPELES ENCUADERNADOS; CANT. DE HOJAS: 80 HOJAS, TAMAÑO: A4, TIPO: BLOCK, CERTIFICADO FORESTAL (GFS): SIN, PORC. FIBRAS RECICLADAS: 0 % | H44: SI | I44: ='Necesidades Trimestrales'!F41 -> UNIDAD | J44: ='Necesidades Trimestrales'!H42 -> 1064 | K44: ='Necesidades Trimestrales'!G42 -> 50
A45: 34 | B45: ='Necesidades Trimestrales'!B43 -> 2.9.2-5042.36 | C45: ='Necesidades Trimestrales'!E43 -> TIJERA; USO: P/PAPEL, MATERIAL: ACERO INOXIDABLE, LONG.DE CUERPO: 17 Cm | H45: NO | I45: ='Necesidades Trimestrales'!F42 -> UNIDAD | J45: ='Necesidades Trimestrales'!H43 -> 336 | K45: ='Necesidades Trimestrales'!G43 -> 30
A46: 35 | B46: ='Necesidades Trimestrales'!B44 -> 2.9.2-1358.353 | C46: ='Necesidades Trimestrales'!E44 -> CARPETAS; MATERIAL PLASTICO - TAMAÑO A4. | H46: SI | I46: ='Necesidades Trimestrales'!F43 -> UNIDAD | J46: ='Necesidades Trimestrales'!H44 -> 92.4 | K46: ='Necesidades Trimestrales'!G44 -> 100
A47: 36 | B47: ='Necesidades Trimestrales'!B45 -> 2.9.2-1358.354 | C47: ='Necesidades Trimestrales'!E45 -> CARPETAS; MATERIAL PLASTICO - TAMAÑO OFICIO. | H47: SI | I47: ='Necesidades Trimestrales'!F44 -> UNIDAD | J47: ='Necesidades Trimestrales'!H45 -> 78.4 | K47: ='Necesidades Trimestrales'!G45 -> 100
A48: 37 | B48: ='Necesidades Trimestrales'!B46 -> 2.3.1-6563.967 | C48: ='Necesidades Trimestrales'!E46 -> PAPELES EN HOJA; TIPO DE PAPEL: CARTULINA, DIMENSION: 74 X 110 Cm, GRAMAJE: 120 GR, PRESENTACION: UNIDAD, CERTIFICADO FORESTAL (GFS): SIN, PORC. FIBRAS RECICLADAS: 0 %, CERT. FIBRA ALTERNATIVA (FCA): 0 % | H48: NO | I48: ='Necesidades Trimestrales'!F45 -> UNIDAD | J48: ='Necesidades Trimestrales'!H46 -> 20 | K48: ='Necesidades Trimestrales'!G46 -> 100
A49: 38 | B49: ='Necesidades Trimestrales'!B47 -> 2.9.2-661.43 | C49: ='Necesidades Trimestrales'!E47 -> GOMAS DE BORRAR; USO: LAPIZ Y TINTA, DIMENSION: 42 X 18 X 10 mm, MATERIAL: CAUCHO, PRESENTACION: ENVASE X 40 UN | H49: NO | I49: ='Necesidades Trimestrales'!F46 -> UNIDAD | J49: ='Necesidades Trimestrales'!H47 -> 1783.6 | K49: ='Necesidades Trimestrales'!G47 -> 4
A50: 39 | B50: ='Necesidades Trimestrales'!B48 -> 2.9.2-848.21 | C50: ='Necesidades Trimestrales'!E48 -> LAPIZ; TIPO: CAJA X 24, COLOR: VARIADOS | H50: NO | I50: ='Necesidades Trimestrales'!F47 -> UNIDAD | J50: ='Necesidades Trimestrales'!H48 -> 1960 | K50: ='Necesidades Trimestrales'!G48 -> 15
A51: 40 | B51: ='Necesidades Trimestrales'!B49 -> 2.9.2-1954.1 | C51: ='Necesidades Trimestrales'!E49 -> BORRADORES; MATERIAL: PLASTICO - FIBRA, TIPO: PARA MARCADOR | H51: NO | I51: ='Necesidades Trimestrales'!F48 -> UNIDAD | J51: ='Necesidades Trimestrales'!H49 -> 392 | K51: ='Necesidades Trimestrales'!G49 -> 12
A52: 41 | B52: ='Necesidades Trimestrales'!B50 -> 2.9.2-1616.128 | C52: ='Necesidades Trimestrales'!E50 -> MARCADORES; TIPO PARA PIZARRA - TRAZO GRUESO - PUNTA REDONDA - RECARGABLE NO | H52: SI | I52: ='Necesidades Trimestrales'!F42 -> UNIDAD | J52: ='Necesidades Trimestrales'!H50 -> 239.4 | K52: ='Necesidades Trimestrales'!G50 -> 48
A53: 42 | B53: ='Necesidades Trimestrales'!B51 -> 2.9.2-5457.11 | C53: ='Necesidades Trimestrales'!E51 -> ANOTADORES; TAMAÑO: 15 X 21 Cm, TIPO: RAYADO | H53: SI | I53: ='Necesidades Trimestrales'!F50 -> UNIDAD | J53: ='Necesidades Trimestrales'!H51 -> 488.25 | K53: ='Necesidades Trimestrales'!G51 -> 60
A54: 43 | B54: ='Necesidades Trimestrales'!B52 -> 2.9.2-660.7 | C54: ='Necesidades Trimestrales'!E52 -> CLIPS P/PAPEL; NUMERO: 5, MATERIAL: METAL, CANT. X CAJA: 50, PRESENTACION: CAJA X 50 | H54: NO | I54: ='Necesidades Trimestrales'!F51 -> UNIDAD | J54: ='Necesidades Trimestrales'!H52 -> 119 | K54: ='Necesidades Trimestrales'!G52 -> 30
A55: 44 | B55: ='Necesidades Trimestrales'!B53 -> 2.9.2-1358.121 | C55: ='Necesidades Trimestrales'!E53 -> CARPETAS; MATERIAL: POLIPROPILENO, COLOR: MARRON, TAMAÑO: OFICIO, TIPO: TRES SOLAPAS Y BANDA ELASTICA, PRESENTACION: SIN VALOR, MEMBRETE: SIN, LENGÜETA: SIN, SUJECION: SIN VALOR | H55: NO | I55: ='Necesidades Trimestrales'!F52 -> UNIDAD | J55: ='Necesidades Trimestrales'!H53 -> 180.6 | K55: ='Necesidades Trimestrales'!G53 -> 40
A56: 45 | B56: ='Necesidades Trimestrales'!B54 -> 2.9.2-1354.22 | C56: ='Necesidades Trimestrales'!E54 -> RESALTADORES; ACCESORIO SIN - TIPO PUNTA 5 (CHANFLEADA) mm | H56: SI | I56: ='Necesidades Trimestrales'!F53 -> UNIDAD | J56: ='Necesidades Trimestrales'!H54 -> 224 | K56: ='Necesidades Trimestrales'!G54 -> 10
A57: 46 | B57: ='Necesidades Trimestrales'!B55 -> 2.9.2-1354.22 | C57: ='Necesidades Trimestrales'!E55 -> RESALTADORES; ACCESORIO SIN - TIPO PUNTA 5 (CHANFLEADA) mm | H57: SI | I57: ='Necesidades Trimestrales'!F54 -> UNIDAD | J57: ='Necesidades Trimestrales'!H55 -> 224 | K57: ='Necesidades Trimestrales'!G55 -> 10
A58: 47 | B58: ='Necesidades Trimestrales'!B56 -> 2.9.2-1354.22 | C58: ='Necesidades Trimestrales'!E56 -> RESALTADORES; ACCESORIO SIN - TIPO PUNTA 5 (CHANFLEADA) mm | H58: SI | I58: ='Necesidades Trimestrales'!F55 -> UNIDAD | J58: ='Necesidades Trimestrales'!H56 -> 224 | K58: ='Necesidades Trimestrales'!G56 -> 10
A59: 48 | B59: ='Necesidades Trimestrales'!B57 -> 2.9.2-661.45 | C59: ='Necesidades Trimestrales'!E57 -> GOMAS DE BORRAR; USO: LAPIZ, DIMENSION: 20 X 30 X 8 mm, MATERIAL: CAUCHO, PRESENTACION: ENVASE X 40 UN | H59: NO | I59: ='Necesidades Trimestrales'!F56 -> UNIDAD | J59: ='Necesidades Trimestrales'!H57 -> 1820 | K59: ='Necesidades Trimestrales'!G57 -> 4
...

Sheet Autor Gastar
A1: EJERCICIO: | D1: ='Necesidades Trimestrales'!C6 -> 2022 | P1: AUTORIZACION PARA GASTAR
A4: JURISDICCIÓN: | G4: =' NotaPedido'!D3 -> 45- Ministerio de Desarrollo Social
A5: SAF: | G5: =' NotaPedido'!D4 -> 25- Direccion Provincial de Gestion Administracion y RRHH
A6: UNIDAD EJECUTORA: | G6: =' NotaPedido'!D5 -> 01 - Ministerio Desarrollo Social
A7: DEPENDENCIA SOLICITANTE: | G7: =' NotaPedido'!D6 -> 01- Actividad Central
A8: AUTORIZACIÓN:
A9: Señor Jefe de Servicio Administrativo Financiero:
A10: ="Autorizo la realización de los trámites correspondientes, a fin de proveer a este Organismo los bienes y/o servicios que se detallan en Nota de Pedido N° " & ' NotaPedido'!K1&", afectando la erogación resultante a los créditos presupuestarios aprobados a favor de esta Unidad Ejecutora, conforme al siguiente detalle:" -> Autorizo la realización de los trámites correspondientes, a fin de proveer a este Organismo los bienes y/o servicios que se detallan en Nota de Pedido N° 177/2022, afectando la erogación resultante a los créditos presupuestarios aprobados a favor de esta Unidad Ejecutora, conforme al siguiente detalle:
A12: IMPUTACIÓN PRESUPUESTARIA
A13: CÓDIGO | O13: DENOMINACIÓN DE LA PARTIDA PRESUPUESTARIA | Q13: IMPORTE
A14: PR | B14: SB | C14: PY | D14: AC | E14: OB | F14: UG | G14: FIN | H14: FUN | I14: I | J14: P | K14: P | L14: SubP | M14: M | N14: FF
A15: 1 | D15: 1 | F15: 4901 | G15: 1 | H15: 3 | I15: =LEFT('[1]Necesidades Trimestrales'!D10,1) -> 2 | J15: 3 | K15: 1 | M15: 1 | N15: 1.1 | O15: Papel de Escritorio y Carton | Q15: 1980706
A16: 1 | D16: 1 | F16: 4901 | G16: 1 | H16: 3 | I16: 2 | J16: 9 | K16: 2 | M16: 1 | N16: 1.1 | O16: Utiles de Escritorio, Oficina y Enseñanza | Q16: 1121706.6
A23: TOTAL DE PESOS: TRES MILLONES CIENTO DOS MIL CUATROCIENTOS DOCE CON 60/100.- | Q23: =SUM(Q15:Q22) -> 3102412.6
A25: JUSTIFICACIÓN:
A26: Adquisicion de Articulos de Librería destinados a las distintas oficinas dependientes del Ministerio de Desarrollo Social
