Workbook

Sheet Necesidades Trimestrales
B2: Pedido de Necesidades Trimestrales
A4: JURISDICCION: | C4: 90 - Ministerio de Seguridad
A5: SAF N°: | C5: 7- Dirección Provincial de Administración de la Policía de la Provincia de Catamarca
A6: EJERCICIO: | C6: 2022
A7: TRIMESTRE: | C7: 3
A9: ID | B9: CODIGO ITEM | C9: RUBRO DE COMPRA | D9: I.P.P. | E9: DESCRIPCION | F9: UNIDAD DE MEDIDA | G9: CANTIDAD | H9: PRECIO UNITARIO ESTIMADO | I9: IMPORTE TOTAL ESTIMADO
A10: 1 | B10: 2.4.4-6818.744 | C10: REPUESTOS | D10: 2.4.4. | E10: NEUMATICOS; VEHICULO: CAMIONETA, CONSTRUCCION: RADIAL, ARMADO: S/CAMARA, MEDIDA: 235/70R16 | F10: UNIDAD | G10: 128 | H10: 70000 | I10: =G10*H10 -> 8960000
A11: 2 | B11: 2.4.4-6818.530 | C11: REPUESTOS | D11: 2.4.4. | E11: NEUMATICOS; VEHICULO: CAMIONETA, CONSTRUCCION: RADIAL, ARMADO: S/CAMARA, MEDIDA: 245/70R16 | F11: UNIDAD | G11: 6 | H11: 85100 | I11: =G11*H11 -> 510600
A12: 3 | B12: 2.4.4-6818.244 | C12: REPUESTOS | D12: 2.4.4. | E12: NEUMATICOS; VEHICULO: AUTOMOVIL, CONSTRUCCION: RADIAL, ARMADO: S/CAMARA, MEDIDA: 205/55R16 | F12: UNIDAD | G12: 2 | H12: 59000 | I12: =G12*H12 -> 118000
A13: 4 | B13: 2.4.4-6818.97 | C13: REPUESTOS | D13: 2.4.4. | E13: NEUMATICOS; VEHICULO: AUTOMOVIL, ARMADO: S/CAMARA, MEDIDA: 175/70R14, CONSTRUCCION: RADIAL | F13: UNIDAD | G13: 4 | H13: 44200 | I13: =G13*H13 -> 176800
A14: 5 | B14: 2.4.4-6818.97 | C14: REPUESTOS | D14: 2.4.4. | E14: NEUMATICOS; VEHICULO: AUTOMOVIL, ARMADO: S/CAMARA, MEDIDA: 175/70R14, CONSTRUCCION: RADIAL | F14: UNIDAD | G14: 4 | H14: 44200 | I14: =G14*H14 -> 176800
A15: 6 | B15: 2.4.4-6818.89 | C15: REPUESTOS | D15: 2.4.4. | E15: NEUMATICOS; VEHICULO: AUTOMOVIL, CONSTRUCCION: CONVENCIONAL, ARMADO: C/CAMARA, MEDIDA: 185/60R14 | F15: UNIDAD | G15: 2 | H15: 47000 | I15: =G15*H15 -> 94000
A16: 7 | B16: 2.4.4-6818.891 | C16: REPUESTOS | D16: 2.4.4. | E16: NEUMATICOS; VEHICULO: MINIBUS, CONSTRUCCION: RADIAL, ARMADO: SIN CAMARA, MEDIDA: 195/75R16 | F16: UNIDAD | G16: 2 | H16: 83900 | I16: =G16*H16 -> 167800
A17: 8 | B17: 2.4.4-6818.810 | C17: REPUESTOS | D17: 2.4.4. | E17: NEUMATICOS; VEHICULO: MINIBUS, CONSTRUCCION: RADIAL, ARMADO: S/CAMARA, MEDIDA: 225/75R16 | F17: UNIDAD | G17: 2 | H17: 75000 | I17: =G17*H17 -> 150000
A18: 9 | B18: 2.4.4-6818.989 | C18: REPUESTOS | D18: 2.4.4. | E18: NEUMATICOS; VEHICULO: CAMIONETA, CONSTRUCCION: RADIAL, ARMADO: S/CAMARA, MEDIDA: 225/70 R17 | F18: UNIDAD | G18: 70 | H18: 84000 | I18: =G18*H18 -> 5880000
A19: 10 | B19: 2.4.4-6818.1032 | C19: REPUESTOS | D19: 2.4.4. | E19: NEUMATICOS; VEHICULO: CAMION, CONSTRUCCION: RADIAL, ARMADO: S/CAMARA, MEDIDA: SEGUN PLIEGO | F19: UNIDAD | G19: 2 | H19: 145000 | I19: =G19*H19 -> 290000
A20: 11 | B20: 2.4.4-6818.412 | C20: REPUESTOS | D20: 2.4.4. | E20: NEUMATICOS; VEHICULO: CAMION, CONSTRUCCION: RADIAL, ARMADO: S/CAMARA, MEDIDA: 275/80R22.5 | F20: UNIDAD | G20: 2 | H20: 321100 | I20: =G20*H20 -> 642200
A21: 12 | B21: 2.4.4-6818.148 | C21: REPUESTOS | D21: 2.4.4 | E21: NEUMATICOS; VEHICULO: MOTO, CONSTRUCCION: RADIAL, ARMADO: SIN VALOR, MEDIDA: 120/90R18 | F21: UNIDAD | G21: 20 | H21: 17390 | I21: =G21*H21 -> 347800
... A32: 23 | B32: 2.4.4-6818.203 | C32: REPUESTOS | D32: 2.4.4. | E32: NEUMATICOS; VEHICULO: CUATRICICLO, CONSTRUCCION: RADIAL, ARMADO: S/CAMARA, MEDIDA: 25 X 10-12 | F32: UNIDAD | G32: 2 | H32: 38000 | I32: =G32*H32 -> 76000
I34: =SUM(I10:I32) -> 21997130
B35: Especificidades
B36: Item N° : 01
C37: Descripción técnica | D37: MARCA TOYOTA/VOLKSWAGEN. MODELO: HILUX/AMAROK ELEMENTO: NEUMATICO MED. 235/70/16 CANTIDAD: 80 /AMAROK- 48/HILUX
B38: Item N° : 02
C39: Descripción técnica | D39: MARCA CHEVROLET MODELO: S-10 ELEMENTO: NEUMATICOS MED. 245/70/16
B40: Item N° : 03
C41: Descripción técnica | D41: MARCA TOYOTA MODELO: COROLA ELEMENTO: NEUMATICOS MED. 205/55/16
B42: Item N° : 04
C43: Descripción técnica | D43: MARCA TOYOTA MODELO: ETIOS ELEMENTO: NEUMATICO MED. 175/70/14
B44: Item N° : 05
C45: Descripción técnica | D45: MARCA FIAT MODELO: FIORINO ELEMENTO: NEUMATICO MED. 175/70/14
B46: Item N° : 06
C47: Descripción técnica | D47: MARCA CITROEN MODELO: BERLINGO ELEMENTO: NEUMATICO MED. 185/60/14
B48: Item N° : 07
C49: Descripción técnica | D49: MARCA: FORD MODELO: TRANSIT ELEMENTO: NEUMATICO PARA COMBI MED.195/75/16
B50: Item N° : 08
C51: Descripción técnica | D51: MARCA: MERCEDEZ BENZ MODELO: SPLINTER ELEMENTO: NEUMATICO PARA MINIBUS MED.225/75/16
B52: Item N° : 09
C53: Descripción técnica | D53: MARCA TOYOTA MODELO: HILUX AÑO: 2020 ELEMENTO: NEUMATICO PARA CAMIONETA MED.225/70/17
B54: Item N° : 10
...

Sheet PARQ. AUTOMOTOR
B1: AUTOMOVILES
B2: TIPO | C2: DOMINIO | D2: MARCA | E2: MODELO | F2: AÑO | G2: MOTOR | H2: CHASIS
A3: 1 | B3: AUTO | C3: HKX-841 | D3: CHEVROLET | E3: CORSA | F3: 2008 | G3: 7H5145376 | H3: 8AGSB19N09R102420
A4: 2 | B4: AUTO | C4: MXR-598 | D4: CHEVROLET | E4: CORSA -SPIRIT LT 1.4 | F4: 2013 | G4: T85170250 | H4: 8AGSC1950ER113477
A5: 3 | B5: AUTO | C5: MXR-597 | D5: CHEVROLET | E5: CORSA -SPIRIT LT 1.4 | F5: 2013 | G5: T85170468 | H5: 8AGSC1950ER113641
A6: 4 | B6: AUTO | C6: MXR-595 | D6: CHEVROLET | E6: CORSA -SPIRIT LT 1.4 | F6: 2013 | G6: T85170446 | H6: 8AGSC1950ER113711
A7: 5 | B7: AUTO | C7: KSV-199 | D7: FIAT | E7: SIENA | F7: 2011 | G7: 178F4055-2176328 | H7: 8AP17269HC 2241027
A8: 6 | B8: AUTO | C8: PHO-196 | D8: FIAT | E8: PALIO ATTRACTIVE 1,4 | F8: 2015 | G8: 327A0552346624 | H8: 8AP196475F4123099
A9: 7 | B9: AUTO | C9: PHO-195 | D9: FIAT | E9: PALIO ATTRACTIVE 1,4 | F9: 2015 | G9: 327A0552366431 | H9: 8AP196475F4124427
A10: 8 | B10: AUTO | C10: OAU-662 | D10: FIAT | E10: SIENA | F10: 2014 | G10: 310A20111946352 | H10: 8AP372316E6089443
A11: 9 | B11: AUTO | C11: EUE-056 | D11: VOLKSWAGEN | E11: POLO | F11: 2005 | G11: 1Y958444 | H11: 8AWZZZ9EZ5A688395
A12: 10 | B12: AUTO | C12: HKX-868 | D12: VOLKSWAGEN | E12: POLO CLASICC 1.6 | F12: 2008 | G12: UVC038611 | H12: 8AWZZZ9EZ9A002754
A13: 11 | B13: AUTO | C13: AE-097-AN | D13: RENAULT | E13: KWID 1,0 ZEN | F13: 2020 | G13: B4DA405Q063865 | H13: 93YRBB00XLJ268999
A14: 12 | B14: AUTO | C14: AB-538-JJ | D14: CHEVROLET | E14: PRISMA JOY LS | F14: 2017 | G14: GFK038284 | H14: 9BGKL69THG251124
... A24: 22 | B24: AUTO | C24: AB-322-SC | D24: TOYOTA | E24: ETIOS X 1,5 M/T 5P | F24: 2017 | G24: 2NR4073730 | H24: 9BRK29BT9H0111908
B25: CAMIONES
B26: TIPO | C26: DOMINIO | D26: MARCA | E26: MODELO | F26: AÑO | G26: MOTOR | H26: CHASIS
A27: 1 | B27: AUTOBOMBA B-10 | C27: HDT-554 | D27: FORD | E27: 4000 | F27: 2009 | G27: 30254572 | H27: 9BFLF47988B050027
A28: 2 | B28: AUTOBOMBA B-12 | C28: AD-016-LU | D28: FORD | E28: CARGO 1119-42 | F28: 2018 | G28: 36585550 | H28: 9BFWEA7B4JBS44819
A29: 3 | B29: AUTOBOMBA B-9 | C29: IFJ-295 | D29: FORD | E29: CARGO 1832 | F29: 2009 | G29: 36047899 | H29: 9BFYCAWYO9BB16113
A30: 4 | B30: CAMION JAULA | C30: FZT-783 | D30: MERCEDEZ BENZ | E30: L-1218,6L | F30: 2007 | G30: 904938U0701544 | H30: 9BM6940007B503596
A31: 5 | B31: CAMION RAMPA 9150 | C31: HVU-681 | D31: VOLKSWAGEN | F31: 2009 | G31: 36057009 | H31: 9BWAA52R39R848365
A32: 6 | B32: CAMION TERMICO 9150E | C32: HVU-682 | D32: VOLKSWAGEN | E32: 91.50 | F32: 2009 | G32: 36059297 | H32: 9BWAA52R09R850042
A33: 7 | B33: CAMION VOLCADOR | C33: HVU-683 | D33: VOLKSWAGEN | E33: 13180 | F33: 2009 | G33: G1T111162 | H33: 9BWB172S09R907813
A34: 8 | B34: AUTOBOMBA B-8 | C34: HVU-684 | D34: VOLKSWAGEN | E34: 13.180 | F34: 2009 | G34: G1T110738 | H34: 9BWB172S89R905534
B35: UTILITARIOS
B36: TIPO | C36: DOMINIO | D36: MARCA | E36: MODELO | F36: AÑO | G36: MOTOR | H36: CHASIS
A37: 1 | B37: FURGON | C37: AF-093-LT | D37: MERCEDEZ BENZ | E37: SPRINTER 311 CDI STREET FURGON 3250 | F37: 2021 | G37: 651958W0130709 | H37: 8AC907631NE208727
A38: 2 | B38: MINIBUS | C38: AD-363-UL | D38: FORD | E38: TRANSIT BUS 2.2L 460E (CAP. 16 PERS.) | F38: 2018 | G38: UHR5JTS31196 | H38: WF0DXMTTGJTS31196
A39: 3 | B39: UTILITARIO | C39: AD-016-LM | D39: FIAT | E39: FIORINO FURGONETA | F39: 2018 | G39: 327A0553238892 | H39: 9BD265524J9099595
A40: 4 | B40: UTILITARIO | C40: OPX-344 | D40: RENAULT | E40: KANGOO | F40: 2015 | G40: K4MJ730Q144802 | H40: 8A1FC1315FL498441
A41: 5 | B41: UTILITARIO | C41: OPX-343 | D41: RENAULT | E41: KANGOO | F41: 2015 | G41: K4MJ730Q153135 | H41: 8A1FC1315FL738957
A42: 6 | B42: UTILITARIO | C42: OOT-964 | D42: FIAT | E42: DUCATO MAXICARGO | F42: 2014 | G42: 7185440 | H42: 93W245G84E2120321
A43: 7 | B43: UTILITARIO | C43: FPF-665 | D43: MERCEDEZ BENZ | E43: SPRINTER | F43: 2006 | G43: 61198170043501 | H43: 8AC9036726A944356
A44: 8 | B44: UTILITARIO | C44: HKX-864 | D44: CITROEN | E44: BERLINGO | F44: 2008 | G44: 10DXBE0049749 | H44: 8BCMBWJZF9G504328
A45: 9 | B45: UTILITARIO | C45: HKX-863 | D45: CITROEN | E45: BERLINGO | F45: 2008 | G45: 10DXBE0047228 | H45: 8BCMBWJZF9G555587
A46: 10 | B46: UTILITARIO | C46: HMW-858 | D46: RENAULT | E46: MASTER DCI 120 | F46: 2008 | G46: G9UA724CO41695 | H46: 93YCDDUH59J082362
B47: CAMIONETAS
B48: TIPO | C48: DOMINIO | D48: MARCA | E48: MODELO | F48: AÑO | G48: MOTOR | H48: CHASIS
A49: 1 | B49: CAMIONETA | C49: AE-317-XK | D49: TOYOTA | E49: HILUX 4X2 D/C PACK DX 2,5 TDI | F49: 2020 | G49: 2GD-0701409 | H49: 8AJDB3CD0L1302672
...

Sheet  NotaPedido
A1: NOTA DE PEDIDO | J1: N° | K1: 32/2020
A3: JURISDICCIÓN: | D3: ='Necesidades Trimestrales'!C4 -> 90 - Ministerio de Seguridad
A4: SAF: | D4: ='Necesidades Trimestrales'!C5 -> 7- Dirección Provincial de Administración de la Policía de la Provincia de Catamarca
A5: UNIDAD EJECUTORA: | D5: Jefatura de Policía de la Provincia de Catamarca
A6: DEPENDENCIA SOLICITANTE: | D6: División Transporte- Dpto. Logistica (D-4)
A7: PERIODO UTILIZACIÓN: | D7: ='Necesidades Trimestrales'!C7 & "° Trimestre - Año " & 'Necesidades Trimestrales'!C6 -> 3° Trimestre - Año 2022
A8: OBJETO: | D8: Adquisición de CUBIERTAS destinadas a las Unidades Moviles de la Policia de Catamarca.-
A10: Ítem | B10: Codigo Item | C10: DESCRIPCIÓN | H10: Adjunta Detalle Técnico | I10: Unidad Medida | J10: Precio Unitario Estimado | K10: Cantidad Solicitada
A12: 1 | B12: ='Necesidades Trimestrales'!B10 -> 2.4.4-6818.744 | C12: ='Necesidades Trimestrales'!E10 -> NEUMATICOS; VEHICULO: CAMIONETA, CONSTRUCCION: RADIAL, ARMADO: S/CAMARA, MEDIDA: 235/70R16 | H12: SI | I12: UNIDAD | J12: ='Necesidades Trimestrales'!H10 -> 70000 | K12: ='Necesidades Trimestrales'!G10 -> 128
A13: 2 | B13: ='Necesidades Trimestrales'!B11 -> 2.4.4-6818.530 | C13: ='Necesidades Trimestrales'!E11 -> NEUMATICOS; VEHICULO: CAMIONETA, CONSTRUCCION: RADIAL, ARMADO: S/CAMARA, MEDIDA: 245/70R16 | H13: SI | I13: UNIDAD | J13: ='Necesidades Trimestrales'!H11 -> 85100 | K13: ='Necesidades Trimestrales'!G11 -> 6
A14: 3 | B14: ='Necesidades Trimestrales'!B12 -> 2.4.4-6818.244 | C14: ='Necesidades Trimestrales'!E12 -> NEUMATICOS; VEHICULO: AUTOMOVIL, CONSTRUCCION: RADIAL, ARMADO: S/CAMARA, MEDIDA: 205/55R16 | H14: SI | I14: UNIDAD | J14: ='Necesidades Trimestrales'!H12 -> 59000 | K14: ='Necesidades Trimestrales'!G12 -> 2
A15: 4 | B15: ='Necesidades Trimestrales'!B13 -> 2.4.4-6818.97 | C15: ='Necesidades Trimestrales'!E13 -> NEUMATICOS; VEHICULO: AUTOMOVIL, ARMADO: S/CAMARA, MEDIDA: 175/70R14, CONSTRUCCION: RADIAL | H15: SI | I15: UNIDAD | J15: ='Necesidades Trimestrales'!H13 -> 44200 | K15: ='Necesidades Trimestrales'!G13 -> 4
A16: 5 | B16: ='Necesidades Trimestrales'!B14 -> 2.4.4-6818.97 | C16: ='Necesidades Trimestrales'!E14 -> NEUMATICOS; VEHICULO: AUTOMOVIL, ARMADO: S/CAMARA, MEDIDA: 175/70R14, CONSTRUCCION: RADIAL | H16: SI | I16: UNIDAD | J16: ='Necesidades Trimestrales'!H14 -> 44200 | K16: ='Necesidades Trimestrales'!G14 -> 4
A17: 6 | B17: ='Necesidades Trimestrales'!#REF! -> #REF! | C17: ='Necesidades Trimestrales'!#REF! -> #REF! | H17: SI | I17: UNIDAD | J17: ='Necesidades Trimestrales'!#REF! -> #REF! | K17: ='Necesidades Trimestrales'!#REF! -> #REF!
A18: 7 | B18: ='Necesidades Trimestrales'!B15 -> 2.4.4-6818.89 | C18: ='Necesidades Trimestrales'!E15 -> NEUMATICOS; VEHICULO: AUTOMOVIL, CONSTRUCCION: CONVENCIONAL, ARMADO: C/CAMARA, MEDIDA: 185/60R14 | H18: SI | I18: UNIDAD | J18: ='Necesidades Trimestrales'!H15 -> 47000 | K18: ='Necesidades Trimestrales'!G15 -> 2
A19: 8 | B19: ='Necesidades Trimestrales'!#REF! -> #REF! | C19: ='Necesidades Trimestrales'!#REF! -> #REF! | H19: SI | I19: UNIDAD | J19: ='Necesidades Trimestrales'!#REF! -> #REF! | K19: ='Necesidades Trimestrales'!#REF! -> #REF!
A20: 9 | B20: ='Necesidades Trimestrales'!B16 -> 2.4.4-6818.891 | C20: ='Necesidades Trimestrales'!E16 -> NEUMATICOS; VEHICULO: MINIBUS, CONSTRUCCION: RADIAL, ARMADO: SIN CAMARA, MEDIDA: 195/75R16 | H20: SI | I20: UNIDAD | J20: ='Necesidades Trimestrales'!H16 -> 83900 | K20: ='Necesidades Trimestrales'!G16 -> 2
A21: 10 | B21: ='Necesidades Trimestrales'!B17 -> 2.4.4-6818.810 | C21: ='Necesidades Trimestrales'!E17 -> NEUMATICOS; VEHICULO: MINIBUS, CONSTRUCCION: RADIAL, ARMADO: S/CAMARA, MEDIDA: 225/75R16 | H21: SI | I21: UNIDAD | J21: ='Necesidades Trimestrales'!H17 -> 75000 | K21: ='Necesidades Trimestrales'!G17 -> 2
A22: 11 | B22: ='Necesidades Trimestrales'!B18 -> 2.4.4-6818.989 | C22: ='Necesidades Trimestrales'!E18 -> NEUMATICOS; VEHICULO: CAMIONETA, CONSTRUCCION: RADIAL, ARMADO: S/CAMARA, MEDIDA: 225/70 R17 | H22: SI | I22: UNIDAD | J22: ='Necesidades Trimestrales'!H18 -> 84000 | K22: ='Necesidades Trimestrales'!G18 -> 70
A23: 12 | B23: ='Necesidades Trimestrales'!#REF! -> #REF! | C23: ='Necesidades Trimestrales'!#REF! -> #REF! | H23: SI | I23: UNIDAD | J23: ='Necesidades Trimestrales'!#REF! -> #REF! | K23: ='Necesidades Trimestrales'!#REF! -> #REF!
A24: 13 | B24: ='Necesidades Trimestrales'!B19 -> 2.4.4-6818.1032 | C24: ='Necesidades Trimestrales'!E19 -> NEUMATICOS; VEHICULO: CAMION, CONSTRUCCION: RADIAL, ARMADO: S/CAMARA, MEDIDA: SEGUN PLIEGO | H24: SI | I24: UNIDAD | J24: ='Necesidades Trimestrales'!H19 -> 145000 | K24: ='Necesidades Trimestrales'!G19 -> 2
A25: 14 | B25: ='Necesidades Trimestrales'!#REF! -> #REF! | C25: ='Necesidades Trimestrales'!#REF! -> #REF! | H25: SI | I25: UNIDAD | J25: ='Necesidades Trimestrales'!#REF! -> #REF! | K25: ='Necesidades Trimestrales'!#REF! -> #REF!
A26: 15 | B26: ='Necesidades Trimestrales'!B28 -> 2.4.4-6818.631 | C26: ='Necesidades Trimestrales'!E28 -> NEUMATICOS; VEHICULO: MOTO, CONSTRUCCION: RADIAL, ARMADO: C/CAMARA, MEDIDA: 90/90-21 | H26: SI | I26: UNIDAD | J26: ='Necesidades Trimestrales'!H28 -> 137000 | K26: ='Necesidades Trimestrales'!G28 -> 20
A27: 16 | B27: ='Necesidades Trimestrales'!#REF! -> #REF! | C27: ='Necesidades Trimestrales'!#REF! -> #REF! | H27: SI | I27: UNIDAD | J27: ='Necesidades Trimestrales'!#REF! -> #REF! | K27: ='Necesidades Trimestrales'!#REF! -> #REF!
A28: 17 | B28: ='Necesidades Trimestrales'!#REF! -> #REF! | C28: ='Necesidades Trimestrales'!#REF! -> #REF! | H28: SI | I28: UNIDAD | J28: ='Necesidades Trimestrales'!#REF! -> #REF! | K28: ='Necesidades Trimestrales'!#REF! -> #REF!
A29: 18 | B29: ='Necesidades Trimestrales'!#REF! -> #REF! | C29: ='Necesidades Trimestrales'!#REF! -> #REF! | H29: SI | I29: UNIDAD | J29: ='Necesidades Trimestrales'!#REF! -> #REF! | K29: ='Necesidades Trimestrales'!#REF! -> #REF!
A30: Costo total estimado: Pesos . | D30: Trece Millones Quinientos Cuatro Mil Doscientos Cuatro con 00/100. | J30: =SUMPRODUCT(J12:J29,K12:K29) -> #REF!

Sheet Autor Gastar
A1: EJERCICIO: | D1: ='[1]Necesidades Trimestrales'!C6 -> 2021 | P1: AUTORIZACION PARA GASTAR
A4: JURISDICCIÓN: | G4: =' NotaPedido'!D3 -> 90 - Ministerio de Seguridad
A5: SAF: | G5: =' NotaPedido'!D4 -> 7- Dirección Provincial de Administración de la Policía de la Provincia de Catamarca
A6: UNIDAD EJECUTORA: | G6: =' NotaPedido'!D5 -> Jefatura de Policía de la Provincia de Catamarca
A7: DEPENDENCIA SOLICITANTE: | G7: =' NotaPedido'!D6 -> División Transporte- Dpto. Logistica (D-4)
A8: AUTORIZACIÓN:
A9: Señor Jefe de Servicio Administrativo Financiero:
A10: ="Autorizo la realización de los trámites correspondientes, a fin de proveer a este Organismo los bienes y/o servicios que se detallan en Nota de Pedido N° " & ' NotaPedido'!K1&", afectando la erogación resultante a los créditos presupuestarios aprobados a favor de esta Unidad Ejecutora, conforme al siguiente detalle:" -> Autorizo la realización de los trámites correspondientes, a fin de proveer a este Organismo los bienes y/o servicios que se detallan en Nota de Pedido N° 32/2020, afectando la erogación resultante a los créditos presupuestarios aprobados a favor de esta Unidad Ejecutora, conforme al siguiente detalle:
A12: IMPUTACIÓN PRESUPUESTARIA
A13: CÓDIGO | O13: DENOMINACIÓN DE LA PARTIDA PRESUPUESTARIA | Q13: IMPORTE
A14: PR | B14: SB | C14: PY | D14: AC | E14: OB | F14: UG | G14: FIN | H14: FUN | I14: I | J14: P | K14: P | L14: SubP | M14: M | N14: FF
A15: 16 | B15: 0 | C15: 0 | D15: 1 | E15: 0 | F15: 10 | G15: 2 | H15: 1 | I15: 2 | J15: 4 | K15: 4 | L15: 0 | M15: 1 | N15: 1.1 | O15: CUBIERTAS Y CAMARAS DE AIRE | Q15: ='Necesidades Trimestrales'!I33 -> 0
A16: TOTAL DE PESOS | Q16: =+Q15 -> 0
E17: =' NotaPedido'!D30 -> Trece Millones Quinientos Cuatro Mil Doscientos Cuatro con 00/100.
A18: JUSTIFICACIÓN:
A19: =' NotaPedido'!D8 -> Adquisición de CUBIERTAS destinadas a las Unidades Moviles de la Policia de Catamarca.-
