Workbook

Sheet Necesidades Trimestrales
B2: Pedido de Necesidades Trimestrales
A4: JURISDICCION: | C4: 70 - MINISTERIO DE CIENCIA E INNOVACION TECNOLOGICA
A5: SAF N°: | C5: 20 - MINISTERIO DE CIENCIA E INNOVACION TECNOLOGICA
A6: EJERCICIO: | C6: 2021
A7: TRIMESTRE: | C7: 4
A9: ID | B9: CODIGO ITEM | C9: RUBRO DE COMPRA | D9: I.P.P. | E9: DESCRIPCION | F9: UNIDAD DE MEDIDA | G9: CANTIDAD | H9: PRECIO UNITARIO ESTIMADO | I9: IMPORTE TOTAL ESTIMADO
A10: 1 | B10: 4.3.5-3162.9 | C10: EQUIPOS | D10: =LEFT(B10,5) -> 4.3.5 | E10: GRABADOR DE DATOS; TIPO: REGIST. DE HUM., TEMP. E ILUM., LINEAS DE ENTRADA: USB, LINEAS DE SALIDA: USB, ALIMENTACION: 3 V | F10: UNIDAD | G10: 10 | H10: 39000 | I10: =G10*H10 -> 390000 | J10: 435
A11: 2 | B11: 4.3.9-7151.2 | C11: EQUIPOS | D11: =LEFT(B11,5) -> 4.3.9 | E11: PLUVIOGRAFOS; TIPO: DIGITAL, RANGO DE MEDICION: 0 A 200 mm | F11: UNIDAD | G11: 10 | H11: 24000 | I11: =G11*H11 -> 240000 | J11: 433
A12: 3 | B12: 4.3.9-7144.6 | C12: EQUIPOS | D12: =LEFT(B12,5) -> 4.3.9 | E12: SENSORES DE TEMPERATURAS; RANGO DE MEDICION: -20 A 60 °C, RESOLUCION: 0,3 °C | F12: UNIDAD | G12: 10 | H12: 24000 | I12: =G12*H12 -> 240000 | J12: 439
A13: 4 | B13: 4.3.3-3958.115 | C13: EQUIPOS | D13: =LEFT(B13,5) -> 4.3.3 | E13: INSTRUMENTOS DE MEDICION; USO: MEDIDOR DE HUMEDAD, RANGO DE MEDICION: 0 A 100 %, PRECISION: 5 %, NOMBRE: HIGROGRAFO | F13: UNIDAD | G13: 10 | H13: 23000 | I13: =G13*H13 -> 230000 | J13: 433
A14: 5 | B14: 4.3.3-3958.156 | C14: EQUIPOS | D14: =LEFT(B14,5) -> 4.3.3 | E14: INSTRUMENTOS DE MEDICION; USO: MEDIDOR RADIACION GLOBAL Y DIF, RANGO DE MEDICION: 0 - 1000 W/M2, PRECISION: 7 - 14 µV/WM² , NOMBRE: PIRANOMETRO | F14: UNIDAD | G14: 10 | H14: 24000 | I14: =G14*H14 -> 240000 | J14: 433
A15: 6 | B15: 4.3.3-7572.18 | C15: EQUIPOS | D15: =LEFT(B15,5) -> 4.3.3 | E15: SENSORES DE PRESIONES; RANGO DE MEDICION: 0 A 700 KPa, RESOLUCION: 0,1 Kpa | F15: UNIDAD | G15: 10 | H15: 24000 | I15: =G15*H15 -> 240000 | J15: 439
A16: 7 | B16: 4.3.3-3969.3 | C16: EQUIPOS | D16: =LEFT(B16,5) -> 4.3.3 | E16: ANEMOMETROS; TIPO: METEOROLOGICO, PRECISION: SIN VALOR, AUTONOMIA: SIN VALOR, ALIMENTACION: SIN VALOR, RANGO DE MEDICION: 0 - 100 Km/h | F16: UNIDAD | G16: 10 | H16: 23000 | I16: =G16*H16 -> 230000 | J16: 433
A17: 8 | B17: 4.3.9-7150.1 | C17: EQUIPOS | D17: =LEFT(B17,5) -> 4.3.9 | E17: EVAPORIMETROS; TIPO: PICHE, RANGO DE MEDICION: 1 A 25 mm, ESCALA: MILIMETRO | F17: UNIDAD | G17: 10 | H17: 21000 | I17: =G17*H17 -> 210000 | J17: 439
A18: 9 | B18: 3.4.9-8903.1 | C18: SERV. PROFESIONAL Y COMERCIAL | D18: =LEFT(B18,5) -> 3.4.9 | E18: MONTAJE Y DESMONTAJE DE EQUIPO; DESCRIPCION: MONTAJE Y DESMONTAJE DE EQUIPO | F18: SERVICIO | G18: 1 | H18: 1080000 | I18: =G18*H18 -> 1080000 | J18: 349
B20: Especificidades Item N° 1:
B22: Descripción técnica
C23: Equipo Registrador electrónico con muestreo configurable y conexión rs232 , tiempo de almacenamiento mínimo 350 días (con muestras cada 1 hora como mínimo) con Modem para transmisión datos vía GPRS o SMS , con generación de alarmas
B24: Plazos y lugares de entrega
C25: El plazo de entrega no podrá ser superior a los sesenta (60) días hábiles a partir de la fecha de recepción de la respectiva Orden de Compra en el domicilio especial electrónico constituido, en virtud del método de contratación. La entrega de dichos bienes se realizará en los Departamentos:Tinogasta, Antofagasta de las Sierras Paclín, Capayán, Santa Rosa, El Alto, Fray Mamerto Esquiu, Capital, La Paz y Belén: 1 1 Ubicación: Medanitos dpto Tinogasta. Latitud 27° 31’ 35” Longuitud 67° 35’27” 2 Ubicación: Villa de Antofagasta de las Sierras dpto Antofagasta de las Sierras. Latitud 26° 03’ 38” Longuitud 67° 24’28” 3 Ubicación: Palo Labrado dpto Paclín. Latitud 28° 19’ 20” Longuitud 65° 37’09” 4 Ubicación: Chumbicha dpto Capayán. Latitud 28° 51’ 25” Longuitud 66° 14’14” 5 Ubicación: Los Altos dpto Santa Rosa. Latitud 28° 02’ 55” Longuitud 65° 30’04” 6 Ubicación: Colonia Achalco dpto El Alto. Latitud 28° 22’ 10” Longuitud 65° 09’49” 7 Ubicación: Dique Pirquitas dpto Fray Mamerto Esquiu. Latitud 28° 19’ 08” Longuitud 65° 24’44” 8 Ubicación: Dique El Jumeal dpto Capital. Latitud 28° 27’ 25” Longuitud 65° 48’35” 9 Ubicación: Dique Motegasta dpto La Paz. Latitud 29° 02’ 10” Longuitud 65° 11’36” 10 Ubicación: La Cienaga dpto Belén. Latitud 27° 29’ 03” Longuitud 66° 57’06” En el horario de 08 a 13 horas. Se presentará Remito que deberá cumplimentar lo dispuesto por la R.G. AFIP 1415/03, sin excepción.
B27: Calidad Minima esperada
B29: Mantenimiento: Treinta (30) Días hábiles.-
B31: Garantia
C32: • Garantía total extendida por 2 (dos) años mínimo.
B34: Especificidades Item N° 2:
B36: Descripción técnica
C37: Registro de lluvia: sistema a cangilones , resolución 0.2mm precisión ±10% @ lluvia 50mm/hora como minimo
B38: Plazos y lugares de entrega
C39: El plazo de entrega no podrá ser superior a los sesenta (60) días hábiles a partir de la fecha de recepción de la respectiva Orden de Compra en el domicilio especial electrónico constituido, en virtud del método de contratación. La entrega de dichos bienes se realizará en los Departamentos:Tinogasta, Antofagasta de las Sierras Paclín, Capayán, Santa Rosa, El Alto, Fray Mamerto Esquiu, Capital, La Paz y Belén: 1 1 Ubicación: Medanitos dpto Tinogasta. Latitud 27° 31’ 35” Longuitud 67° 35’27” 2 Ubicación: Villa de Antofagasta de las Sierras dpto Antofagasta de las Sierras. Latitud 26° 03’ 38” Longuitud 67° 24’28” 3 Ubicación: Palo Labrado dpto Paclín. Latitud 28° 19’ 20” Longuitud 65° 37’09” 4 Ubicación: Chumbicha dpto Capayán. Latitud 28° 51’ 25” Longuitud 66° 14’14” 5 Ubicación: Los Altos dpto Santa Rosa. Latitud 28° 02’ 55” Longuitud 65° 30’04” 6 Ubicación: Colonia Achalco dpto El Alto. Latitud 28° 22’ 10” Longuitud 65° 09’49” 7 Ubicación: Dique Pirquitas dpto Fray Mamerto Esquiu. Latitud 28° 19’ 08” Longuitud 65° 24’44” 8 Ubicación: Dique El Jumeal dpto Capital. Latitud 28° 27’ 25” Longuitud 65° 48’35” 9 Ubicación: Dique Motegasta dpto La Paz. Latitud 29° 02’ 10” Longuitud 65° 11’36” 10 Ubicación: La Cienaga dpto Belén. Latitud 27° 29’ 03” Longuitud 66° 57’06” En el horario de 08 a 13 horas. Se presentará Remito que deberá cumplimentar lo dispuesto por la R.G. AFIP 1415/03, sin excepción.
B41: Calidad Minima esperada
B43: Mantenimiento: Treinta (30) Días hábiles.-
B45: Garantia
C46: • Garantía total extendida por 2 (dos) años mínimo.
B48: Especificidades Item N° 3:
B50: Descripción técnica
C51: Sensor de Temperatura ambiente: rango -20 °C a 60 °C aproximadamente
B52: Plazos y lugares de entrega
C53: El plazo de entrega no podrá ser superior a los sesenta (60) días hábiles a partir de la fecha de recepción de la respectiva Orden de Compra en el domicilio especial electrónico constituido, en virtud del método de contratación. La entrega de dichos bienes se realizará en los Departamentos:Tinogasta, Antofagasta de las Sierras Paclín, Capayán, Santa Rosa, El Alto, Fray Mamerto Esquiu, Capital, La Paz y Belén: 1 1 Ubicación: Medanitos dpto Tinogasta. Latitud 27° 31’ 35” Longuitud 67° 35’27” 2 Ubicación: Villa de Antofagasta de las Sierras dpto Antofagasta de las Sierras. Latitud 26° 03’ 38” Longuitud 67° 24’28” 3 Ubicación: Palo Labrado dpto Paclín. Latitud 28° 19’ 20” Longuitud 65° 37’09” 4 Ubicación: Chumbicha dpto Capayán. Latitud 28° 51’ 25” Longuitud 66° 14’14” 5 Ubicación: Los Altos dpto Santa Rosa. Latitud 28° 02’ 55” Longuitud 65° 30’04” 6 Ubicación: Colonia Achalco dpto El Alto. Latitud 28° 22’ 10” Longuitud 65° 09’49” 7 Ubicación: Dique Pirquitas dpto Fray Mamerto Esquiu. Latitud 28° 19’ 08” Longuitud 65° 24’44” 8 Ubicación: Dique El Jumeal dpto Capital. Latitud 28° 27’ 25” Longuitud 65° 48’35” 9 Ubicación: Dique Motegasta dpto La Paz. Latitud 29° 02’ 10” Longuitud 65° 11’36” 10 Ubicación: La Cienaga dpto Belén. Latitud 27° 29’ 03” Longuitud 66° 57’06” En el horario de 08 a 13 horas. Se presentará Remito que deberá cumplimentar lo dispuesto por la R.G. AFIP 1415/03, sin excepción.
B55: Calidad Minima esperada
B57: Mantenimiento: Treinta (30) Días hábiles-
...

Sheet  NotaPedido
A1: NOTA DE PEDIDO | J1: N° | K1: 020/2021
A3: JURISDICCIÓN: | D3: 70 - MINISTERIO DE CIENCIA E INNOVACION TECNOLOGICA
A4: SAF: | D4: 20 - MINISTERIO DE CIENCIA E INNOVACION TECNOLOGICA
A5: UNIDAD EJECUTORA: | D5: SECRETARIA DE CIENCIA Y TECNOLOGIA
A6: DEPENDENCIA SOLICITANTE: | D6: DIRECCION PROVINCIAL DE GESTION ADMINISTRATIVA Y RECURSOS HUMANOS
A7: PERIODO UTILIZACIÓN: | D7: 4º TRIMESTRE
A8: OBJETO: | D8: ADQUISICIÓN DE EQUIPOS PARA LA CREACIÓN DE LA RED DE CENTRALES METEOROLOGICAS PROVINCIAL.-
A10: Ítem | B10: Codigo Item | C10: DESCRIPCIÓN | H10: Adjunta Detalle Técnico | I10: Unidad Medida | J10: Precio Unitario Estimado | K10: Cantidad Solicitada
A12: 1 | B12: ='Necesidades Trimestrales'!B10 -> 4.3.5-3162.9 | C12: ='Necesidades Trimestrales'!E10 -> GRABADOR DE DATOS; TIPO: REGIST. DE HUM., TEMP. E ILUM., LINEAS DE ENTRADA: USB, LINEAS DE SALIDA: USB, ALIMENTACION: 3 V | H12: SI | I12: UNIDAD | J12: ='Necesidades Trimestrales'!H10 -> 39000 | K12: ='Necesidades Trimestrales'!G10 -> 10
A13: 2 | B13: ='Necesidades Trimestrales'!B11 -> 4.3.9-7151.2 | C13: ='Necesidades Trimestrales'!E11 -> PLUVIOGRAFOS; TIPO: DIGITAL, RANGO DE MEDICION: 0 A 200 mm | H13: SI | I13: UNIDAD | J13: ='Necesidades Trimestrales'!H11 -> 24000 | K13: ='Necesidades Trimestrales'!G11 -> 10
A14: 3 | B14: ='Necesidades Trimestrales'!B12 -> 4.3.9-7144.6 | C14: ='Necesidades Trimestrales'!E12 -> SENSORES DE TEMPERATURAS; RANGO DE MEDICION: -20 A 60 °C, RESOLUCION: 0,3 °C | H14: SI | I14: UNIDAD | J14: ='Necesidades Trimestrales'!H12 -> 24000 | K14: ='Necesidades Trimestrales'!G12 -> 10
A15: 4 | B15: ='Necesidades Trimestrales'!B13 -> 4.3.3-3958.115 | C15: ='Necesidades Trimestrales'!E13 -> INSTRUMENTOS DE MEDICION; USO: MEDIDOR DE HUMEDAD, RANGO DE MEDICION: 0 A 100 %, PRECISION: 5 %, NOMBRE: HIGROGRAFO | H15: SI | I15: UNIDAD | J15: ='Necesidades Trimestrales'!H13 -> 23000 | K15: ='Necesidades Trimestrales'!G13 -> 10
A16: 5 | B16: ='Necesidades Trimestrales'!B14 -> 4.3.3-3958.156 | C16: ='Necesidades Trimestrales'!E14 -> INSTRUMENTOS DE MEDICION; USO: MEDIDOR RADIACION GLOBAL Y DIF, RANGO DE MEDICION: 0 - 1000 W/M2, PRECISION: 7 - 14 µV/WM² , NOMBRE: PIRANOMETRO | H16: NO | I16: UNIDAD | J16: ='Necesidades Trimestrales'!H14 -> 24000 | K16: ='Necesidades Trimestrales'!G14 -> 10
A17: 6 | B17: ='Necesidades Trimestrales'!B15 -> 4.3.3-7572.18 | C17: ='Necesidades Trimestrales'!E15 -> SENSORES DE PRESIONES; RANGO DE MEDICION: 0 A 700 KPa, RESOLUCION: 0,1 Kpa | H17: NO | I17: UNIDAD | J17: ='Necesidades Trimestrales'!H15 -> 24000 | K17: ='Necesidades Trimestrales'!G15 -> 10
A18: 7 | B18: ='Necesidades Trimestrales'!B16 -> 4.3.3-3969.3 | C18: ='Necesidades Trimestrales'!E16 -> ANEMOMETROS; TIPO: METEOROLOGICO, PRECISION: SIN VALOR, AUTONOMIA: SIN VALOR, ALIMENTACION: SIN VALOR, RANGO DE MEDICION: 0 - 100 Km/h | H18: NO | I18: UNIDAD | J18: ='Necesidades Trimestrales'!H16 -> 23000 | K18: ='Necesidades Trimestrales'!G16 -> 10
A19: 8 | B19: ='Necesidades Trimestrales'!B17 -> 4.3.9-7150.1 | C19: ='Necesidades Trimestrales'!E17 -> EVAPORIMETROS; TIPO: PICHE, RANGO DE MEDICION: 1 A 25 mm, ESCALA: MILIMETRO | H19: SI | I19: UNIDAD | J19: ='Necesidades Trimestrales'!H17 -> 21000 | K19: ='Necesidades Trimestrales'!G17 -> 10
A20: 9 | B20: ='Necesidades Trimestrales'!B18 -> 3.4.9-8903.1 | C20: ='Necesidades Trimestrales'!E18 -> MONTAJE Y DESMONTAJE DE EQUIPO; DESCRIPCION: MONTAJE Y DESMONTAJE DE EQUIPO | H20: SI | I20: SERVICIO | J20: ='Necesidades Trimestrales'!H18 -> 1080000 | K20: ='Necesidades Trimestrales'!G18 -> 1
A21: Costo total estimado: PESOS TRES MILLONES CIEN MIL CON 00/100.- | J21: =SUMPRODUCT(J12:J20,K12:K20) -> 3100000

Sheet Autor Gastar
A1: EJERCICIO: | D1: ='Necesidades Trimestrales'!C6 -> 2021 | P1: AUTORIZACION PARA GASTAR
A4: JURISDICCIÓN: | G4: =' NotaPedido'!D3 -> 70 - MINISTERIO DE CIENCIA E INNOVACION TECNOLOGICA
A5: SAF: | G5: =' NotaPedido'!D4 -> 20 - MINISTERIO DE CIENCIA E INNOVACION TECNOLOGICA
A6: UNIDAD EJECUTORA: | G6: =' NotaPedido'!D5 -> SECRETARIA DE CIENCIA Y TECNOLOGIA
A7: DEPENDENCIA SOLICITANTE: | G7: =' NotaPedido'!D6 -> DIRECCION PROVINCIAL DE GESTION ADMINISTRATIVA Y RECURSOS HUMANOS
A8: AUTORIZACIÓN:
A9: Señor Jefe de Servicio Administrativo Financiero:
A10: ="Autorizo la realización de los trámites correspondientes, a fin de proveer a este Organismo los bienes y/o servicios que se detallan en Nota de Pedido N° " & ' NotaPedido'!K1&", afectando la erogación resultante a los créditos presupuestarios aprobados a favor de esta Unidad Ejecutora, conforme al siguiente detalle:" -> Autorizo la realización de los trámites correspondientes, a fin de proveer a este Organismo los bienes y/o servicios que se detallan en Nota de Pedido N° 020/2021, afectando la erogación resultante a los créditos presupuestarios aprobados a favor de esta Unidad Ejecutora, conforme al siguiente detalle:
A12: IMPUTACIÓN PRESUPUESTARIA
A13: CÓDIGO | O13: DENOMINACIÓN DE LA PARTIDA PRESUPUESTARIA | Q13: IMPORTE
A14: PR | B14: SB | C14: PY | D14: AC | E14: OB | F14: UG | G14: FIN | H14: FUN | I14: I | J14: P | K14: P | L14: SubP | M14: M | N14: FF
A15: 2 | B15: 0 | C15: 0 | D15: 1 | E15: 0 | F15: 4901 | G15: 3 | H15: 5 | I15: 4 | J15: 3 | K15: 3 | L15: 0 | M15: 1 | N15: 1.1 | O15: Equipo de Sanitario y de Laboratorio | Q15: 940000
A16: 2 | B16: 0 | C16: 0 | D16: 1 | E16: 0 | F16: 4901 | G16: 3 | H16: 5 | I16: 4 | J16: 3 | K16: 5 | L16: 0 | M16: 1 | N16: 1.1 | O16: Equipo Educacional y Recreativo | Q16: 390000
A17: 2 | B17: 0 | C17: 0 | D17: 1 | E17: 0 | F17: 4901 | G17: 3 | H17: 5 | I17: 4 | J17: 3 | K17: 9 | L17: 0 | M17: 1 | N17: 1.1 | O17: Equipos Varios | Q17: 690000
A18: 2 | B18: 0 | C18: 0 | D18: 1 | E18: 0 | F18: 4901 | G18: 3 | H18: 5 | I18: 3 | J18: 4 | K18: 9 | L18: 0 | M18: 1 | N18: 1.1 | O18: Otros Servicios Tecnicos y Profesionales | Q18: 1080000
A21: PESOS: TRES MILLONES CIEN MIL CON 00/100.- | Q21: =SUM(Q15:Q20) -> 3100000
A23: JUSTIFICACIÓN:
A24: ADQUISICIÓN DE EQUIPOS PARA LA CREACIÓN DE LA RED DE CENTRALES METEOROLOGICAS PROVINCIAL.-
