Workbook

Sheet Necesidades Trimestrales 
B2: Pedido de Necesidades Trimestrales
A4: JURISDICCION: | C4: 040 - Ministerio de Salud
A5: SAF N°: | C5: 011 - Direccion Provincial de Administracion - MS
A6: EJERCICIO: | C6: 2023
A7: TRIMESTRE: | C7: 1
A9: ID | B9: CODIGO ITEM | C9: RUBRO DE COMPRA | D9: I.P.P. | E9: DESCRIPCION | F9: UNIDAD DE MEDIDA | G9: DPFeI | H9: Total DPFeI | I9: DPBD | J9: Total DPBS | K9: DPSAME | L9: Total DPSAME | M9: DPMIA | N9: Total DPMIA | O9: CANTIDAD TOTAL | P9: PRECIO UNITARIO ESTIMADO | Q9: IMPORTE TOTAL ESTIMADO
A10: 1 | B10: 2.5.2-1726.10 | C10: PROD. MEDICO/FARMACEUTICOS/LAB | D10: 252 | E10: SOLUCIONES P/MEDICINA; TIPO: AGUA P/IRRIGACION QUIRURGICA, PRESENTACION: SACHET X 2000 mL | F10: SACHET | G10: 0 | H10: =+G10*P10 -> 0 | J10: =+I10*P10 -> 0 | L10: =+K10*P10 -> 0 | N10: =+M10*P10 -> 0 | O10: =+N10+K10+I10+G10 -> 0 | P10: 560 | Q10: =+O10*P10 -> 0
A11: 2 | B11: 2.5.2-1726.520 | C11: PROD. MEDICO/FARMACEUTICOS/LAB | D11: 252 | E11: SOLUCIONES P/MEDICINA; TIPO: AGUA DESTILADA, PRESENTACION: AMPOLLA DE 10 ML | F11: AMPOLLA | G11: 25000 | H11: =+G11*P11 -> 1125000 | J11: =+I11*P11 -> 0 | L11: =+K11*P11 -> 0 | N11: =+M11*P11 -> 0 | O11: =+N11+K11+I11+G11 -> 25000 | P11: 45 | Q11: =+O11*P11 -> 1125000
A12: 3 | B12: 2.5.2-1726.186 | C12: PROD. MEDICO/FARMACEUTICOS/LAB | D12: 252 | E12: SOLUCIONES P/MEDICINA; TIPO: AGUA DESTILADA, PRESENTACION: ENVASE X 500 mL | F12: SACHET | G12: 500 | H12: =+G12*P12 -> 106000 | J12: =+I12*P12 -> 0 | L12: =+K12*P12 -> 0 | N12: =+M12*P12 -> 0 | O12: =+N12+K12+I12+G12 -> 500 | P12: 212 | Q12: =+O12*P12 -> 106000
A13: 4 | B13: 2.5.2-2183.7 | C13: PROD. MEDICO/FARMACEUTICOS/LAB | D13: 252 | E13: EXPANSORES PLASMATICOS; PRINCIPIO ACTIVO: ALBUMINA HUMANA, CONCENTRACION: 20 %, PRESENTACION: 50ML | F13: SACHET | G13: 0 | H13: =+G13*P13 -> 0 | J13: =+I13*P13 -> 0 | L13: =+K13*P13 -> 0 | N13: =+M13*P13 -> 0 | O13: =+N13+K13+I13+G13 -> 0 | P13: 3600 | Q13: =+O13*P13 -> 0 | R13: CONSULTAR STOCK FCIA CENTRAL
A14: 5 | B14: 2.5.2-1903.103 | C14: PROD. MEDICO/FARMACEUTICOS/LAB | D14: 252 | E14: RECONSTITUYENTE GENERAL; DROGA GENERICA: ALIMENTO ENTERAL PARA SONDA FORTIFICADO CON FIBRAS, FORMA FARMACEUTICA: ENVASE, PRESENTACION: 1 L, TIPO: ASOCIACION | F14: UNIDAD | G14: 30 | H14: =+G14*P14 -> 84000 | J14: =+I14*P14 -> 0 | L14: =+K14*P14 -> 0 | N14: =+M14*P14 -> 0 | O14: =+N14+K14+I14+G14 -> 30 | P14: 2800 | Q14: =+O14*P14 -> 84000
A15: 6 | B15: 2.5.2-1903.104 | C15: PROD. MEDICO/FARMACEUTICOS/LAB | D15: 252 | E15: RECONSTITUYENTE GENERAL; DROGA GENERICA: ALIMENTO ENTERAL PARA SONDA BAJO INDICE GLUCEMICO, FORMA FARMACEUTICA: ENVASE, PRESENTACION: 1 L, TIPO: ASOCIACION | F15: UNIDAD | G15: 50 | H15: =+G15*P15 -> 160000 | J15: =+I15*P15 -> 0 | L15: =+K15*P15 -> 0 | N15: =+M15*P15 -> 0 | O15: =+N15+K15+I15+G15 -> 50 | P15: 3200 | Q15: =+O15*P15 -> 160000
A16: 7 | B16: 2.5.2-1903.105 | C16: PROD. MEDICO/FARMACEUTICOS/LAB | D16: 252 | E16: RECONSTITUYENTE GENERAL; TIPO: ASOCIACION, DROGA GENERICA: ALIMENTO ENTERAL PARA SONDA BAJO INDICE GLUCEMICO, FORMA FARMACEUTICA: SOLUCION, PRESENTACION: ENVASE X 500 CM3 | F16: UNIDAD | G16: 50 | H16: =+G16*P16 -> 47000 | J16: =+I16*P16 -> 0 | L16: =+K16*P16 -> 0 | N16: =+M16*P16 -> 0 | O16: =+N16+K16+I16+G16 -> 50 | P16: 940 | Q16: =+O16*P16 -> 47000
A17: 8 | B17: 2.1.1-4227.56 | C17: PROD. MEDICO/FARMACEUTICOS/LAB | D17: 252 | E17: SUPLEMENTOS DIETARIOS; TIPO: ASOCIACION, DROGA GENERICA: S. PARENTERAL ADULTO 1501-2000 ML, PRESENTACION: UNIDAD | F17: UNIDAD | G17: 0 | H17: =+G17*P17 -> 0 | J17: =+I17*P17 -> 0 | L17: =+K17*P17 -> 0 | N17: =+M17*P17 -> 0 | O17: =+N17+K17+I17+G17 -> 0 | P17: 14800 | Q17: =+O17*P17 -> 0
A18: 9 | B18: 2.1.1-4227.19 | C18: PROD. MEDICO/FARMACEUTICOS/LAB | D18: 252 | E18: SUPLEMENTOS DIETARIOS; TIPO: ASOCIACION, DROGA GENERICA: S. PARENTERAL NEONATAL 0-500 ML, PRESENTACION: UNIDAD, ACCESORIO: CON FILTRO | F18: UNIDAD | G18: 0 | H18: =+G18*P18 -> 0 | J18: =+I18*P18 -> 0 | L18: =+K18*P18 -> 0 | N18: =+M18*P18 -> 0 | O18: =+N18+K18+I18+G18 -> 0 | P18: 9800 | Q18: =+O18*P18 -> 0
A19: 10 | B19: 2.5.2-1726.191 | C19: PROD. MEDICO/FARMACEUTICOS/LAB | D19: 252 | E19: SOLUCIONES P/MEDICINA; TIPO: AMINOACIDOS 10%, PRESENTACION: ENVASE X 500 ML | F19: FRASCO | G19: 0 | H19: =+G19*P19 -> 0 | J19: =+I19*P19 -> 0 | L19: =+K19*P19 -> 0 | N19: =+M19*P19 -> 0 | O19: =+N19+K19+I19+G19 -> 0 | P19: 8840 | Q19: =+O19*P19 -> 0
A20: 11 | B20: 2.5.2-1726.9 | C20: PROD. MEDICO/FARMACEUTICOS/LAB | D20: 252 | E20: SOLUCIONES P/MEDICINA; TIPO: BICARBONATO 1 MOLAR, PRESENTACION: SACHET DE 100 mL | F20: SACHET | G20: 400 | H20: =+G20*P20 -> 155200 | J20: =+I20*P20 -> 0 | L20: =+K20*P20 -> 0 | N20: =+M20*P20 -> 0 | O20: =+N20+K20+I20+G20 -> 400 | P20: 388 | Q20: =+O20*P20 -> 155200
A21: 12 | B21: 2.5.2-1726.305 | C21: PROD. MEDICO/FARMACEUTICOS/LAB | D21: 252 | E21: SOLUCIONES P/MEDICINA; TIPO: CLORURO DE POTASIO 15 MEQ, PRESENTACION: AMPOLLA DE 5 mL | F21: AMPOLLA | G21: 3000 | H21: =+G21*P21 -> 135000 | J21: =+I21*P21 -> 0 | L21: =+K21*P21 -> 0 | N21: =+M21*P21 -> 0 | O21: =+N21+K21+I21+G21 -> 3000 | P21: 45 | Q21: =+O21*P21 -> 135000
A22: 13 | B22: 2.5.2-1726.519 | C22: PROD. MEDICO/FARMACEUTICOS/LAB | D22: 252 | E22: SOLUCIONES P/MEDICINA; PRESENTACION: AMPOLLA X 20 ML, TIPO: CLORURO DE SODIO MOLAR AL 20 % | F22: AMPOLLA | G22: 3000 | H22: =+G22*P22 -> 233400 | J22: =+I22*P22 -> 0 | L22: =+K22*P22 -> 0 | N22: =+M22*P22 -> 0 | O22: =+N22+K22+I22+G22 -> 3000 | P22: 77.8 | Q22: =+O22*P22 -> 233400
A23: 14 | B23: 2.5.2-1726.382 | C23: PROD. MEDICO/FARMACEUTICOS/LAB | D23: 252 | E23: SOLUCIONES P/MEDICINA; TIPO: CLORURO DE POTASIO MOLAR, PRESENTACION: ENVASE X 100 mL | F23: SACHET | G23: 0 | H23: =+G23*P23 -> 0 | J23: =+I23*P23 -> 0 | L23: =+K23*P23 -> 0 | N23: =+M23*P23 -> 0 | O23: =+N23+K23+I23+G23 -> 0 | P23: 320 | Q23: =+O23*P23 -> 0
A24: 15 | B24: 2.5.2-2689.7 | C24: PROD. MEDICO/FARMACEUTICOS/LAB | D24: 252 | E24: NORMALIZADORES DE CALCEMIA; TIPO: MONODROGA, DROGA GENERICA: GLUCONATO DE CALCIO 10 %, FORMA FARMACEUTICA: AMPOLLA, PRESENTACION: ENVASE X 10 mL | F24: AMPOLLA | G24: 1500 | H24: =+G24*P24 -> 132750 | J24: =+I24*P24 -> 0 | L24: =+K24*P24 -> 0 | N24: =+M24*P24 -> 0 | O24: =+N24+K24+I24+G24 -> 1500 | P24: 88.5 | Q24: =+O24*P24 -> 132750
A25: 16 | B25: 2.5.2-1726.460 | C25: PROD. MEDICO/FARMACEUTICOS/LAB | D25: 252 | E25: SOLUCIONES P/MEDICINA; TIPO: HEMODIALISIS ACIDA A, PRESENTACION: ENVASE X 10 L | F25: BIDON | G25: 0 | H25: =+G25*P25 -> 0 | J25: =+I25*P25 -> 0 | L25: =+K25*P25 -> 0 | N25: =+M25*P25 -> 0 | O25: =+N25+K25+I25+G25 -> 0 | P25: 2000 | Q25: =+O25*P25 -> 0
... A30: 21 | B30: 2.5.2-1726.377 | C30: PROD. MEDICO/FARMACEUTICOS/LAB | D30: 252 | E30: SOLUCIONES P/MEDICINA; TIPO: DEXTROSA AL 25 %, PRESENTACION: ENVASE X 500 mL | F30: SACHET | G30: 0 | H30: =+G30*P30 -> 0 | J30: =+I30*P30 -> 0 | L30: =+K30*P30 -> 0 | N30: =+M30*P30 -> 0 | O30: =+N30+K30+I30+G30 -> 0 | P30: 275 | Q30: =+O30*P30 -> 0
A31: 22 | B31: 2.5.2-1726.24 | C31: PROD. MEDICO/FARMACEUTICOS/LAB | D31: 252 | E31: SOLUCIONES P/MEDICINA; TIPO: DEXTROSA AL 5%, PRESENTACION: ENVASE X 500 mL | F31: SACHET | G31: 25000 | H31: =+G31*P31 -> 5709250 | J31: =+I31*P31 -> 0 | K31: 1000 | L31: =+K31*P31 -> 228370 | N31: =+M31*P31 -> 0 | O31: =+N31+K31+I31+G31 -> 26000 | P31: 228.37 | Q31: =+O31*P31 -> 5937620
A32: 23 | B32: 2.5.2-1726.376 | C32: PROD. MEDICO/FARMACEUTICOS/LAB | D32: 252 | E32: SOLUCIONES P/MEDICINA; TIPO: DEXTROSA AL 5%, PRESENTACION: ENVASE X 100 mL | F32: SACHET | G32: 2000 | H32: =+G32*P32 -> 374400 | J32: =+I32*P32 -> 0 | L32: =+K32*P32 -> 0 | N32: =+M32*P32 -> 0 | O32: =+N32+K32+I32+G32 -> 2000 | P32: 187.2 | Q32: =+O32*P32 -> 374400
A33: 24 | B33: 2.5.2-1726.17 | C33: PROD. MEDICO/FARMACEUTICOS/LAB | D33: 252 | E33: SOLUCIONES P/MEDICINA; TIPO: FISIOLOGICA CLORURO DE SODIO, PRESENTACION: 500 CM3 | F33: SACHET | G33: 60000 | H33: =+G33*P33 -> 11910000 | I33: 100 | J33: =+I33*P33 -> 19850 | K33: 3000 | L33: =+K33*P33 -> 595500 | N33: =+M33*P33 -> 0 | O33: =+N33+K33+I33+G33 -> 63100 | P33: 198.5 | Q33: =+O33*P33 -> 12525350
A34: 25 | B34: 2.5.2-1726.369 | C34: PROD. MEDICO/FARMACEUTICOS/LAB | D34: 252 | E34: SOLUCIONES P/MEDICINA; TIPO: FISIOLOGICA, PRESENTACION: ENVASE X 100 mL | F34: SACHET | G34: 5000 | H34: =+G34*P34 -> 930000 | J34: =+I34*P34 -> 0 | L34: =+K34*P34 -> 0 | N34: =+M34*P34 -> 0 | O34: =+N34+K34+I34+G34 -> 5000 | P34: 186 | Q34: =+O34*P34 -> 930000
A35: 26 | B35: 2.5.2-1726.419 | C35: PROD. MEDICO/FARMACEUTICOS/LAB | D35: 252 | E35: SOLUCIONES P/MEDICINA; TIPO: FISIOLOGICA, PRESENTACION: ENVASE X 10 mL | F35: AMPOLLA | G35: 0 | H35: =+G35*P35 -> 0 | J35: =+I35*P35 -> 0 | L35: =+K35*P35 -> 0 | N35: =+M35*P35 -> 0 | O35: =+N35+K35+I35+G35 -> 0 | P35: 46 | Q35: =+O35*P35 -> 0
A36: 27 | B36: 2.5.2-1726.393 | C36: PROD. MEDICO/FARMACEUTICOS/LAB | D36: 252 | E36: SOLUCIONES P/MEDICINA; TIPO: GLUCOSADA HIPERTONICA AL 25%, PRESENTACION: ENVASE X 10 mL | F36: AMPOLLA | G36: 4000 | H36: =+G36*P36 -> 281000 | J36: =+I36*P36 -> 0 | L36: =+K36*P36 -> 0 | N36: =+M36*P36 -> 0 | O36: =+N36+K36+I36+G36 -> 4000 | P36: 70.25 | Q36: =+O36*P36 -> 281000 | R36: CONSULTAR STOCK FCIA CENTRAL
A37: 28 | B37: 2.5.2-1726.381 | C37: PROD. MEDICO/FARMACEUTICOS/LAB | D37: 252 | E37: SOLUCIONES P/MEDICINA; TIPO: MANITOL AL 15%, PRESENTACION: ENVASE X 500 mL | F37: SACHET | G37: 500 | H37: =+G37*P37 -> 258500 | J37: =+I37*P37 -> 0 | L37: =+K37*P37 -> 0 | N37: =+M37*P37 -> 0 | O37: =+N37+K37+I37+G37 -> 500 | P37: 517 | Q37: =+O37*P37 -> 258500
A38: 29 | B38: 2.5.2-1726.521 | C38: PROD. MEDICO/FARMACEUTICOS/LAB | D38: 252 | E38: SOLUCIONES P/MEDICINA; TIPO: DIALISIS PERITONEAL DEXTROSA AL 1,5 %, PRESENTACION: ENVASE X 2 L | F38: UNIDAD | G38: 0 | H38: =+G38*P38 -> 0 | J38: =+I38*P38 -> 0 | L38: =+K38*P38 -> 0 | N38: =+M38*P38 -> 0 | O38: =+N38+K38+I38+G38 -> 0 | P38: 2900 | Q38: =+O38*P38 -> 0 | R38: COMODATO HOSPITAL DE NINOS
A39: 30 | B39: 2.5.2-1726.522 | C39: PROD. MEDICO/FARMACEUTICOS/LAB | D39: 252 | E39: SOLUCIONES P/MEDICINA; TIPO: DIALISIS PERITONEAL DEXTROSA AL 2,5 %, PRESENTACION: ENVASE X 2 L | F39: UNIDAD | G39: 0 | H39: =+G39*P39 -> 0 | J39: =+I39*P39 -> 0 | L39: =+K39*P39 -> 0 | N39: =+M39*P39 -> 0 | O39: =+N39+K39+I39+G39 -> 0 | P39: 2900 | Q39: =+O39*P39 -> 0
A40: 31 | B40: 2.5.2-1726.182 | C40: PROD. MEDICO/FARMACEUTICOS/LAB | D40: 252 | E40: SOLUCIONES P/MEDICINA; TIPO: RINGER LACTATO, PRESENTACION: ENVASE X 500 mL | F40: SACHET | G40: 5000 | H40: =+G40*P40 -> 1376000 | J40: =+I40*P40 -> 0 | K40: 300 | L40: =+K40*P40 -> 82560 | N40: =+M40*P40 -> 0 | O40: =+N40+K40+I40+G40 -> 5300 | P40: 275.2 | Q40: =+O40*P40 -> 1458560
A41: 32 | B41: 2.5.2-1726.371 | C41: PROD. MEDICO/FARMACEUTICOS/LAB | D41: 252 | E41: SOLUCIONES P/MEDICINA; TIPO: SULFATO DE MAGNESIO AL 25%, PRESENTACION: ENVASE X 5 mL | F41: AMPOLLA | G41: 1000 | H41: =+G41*P41 -> 42500 | J41: =+I41*P41 -> 0 | L41: =+K41*P41 -> 0 | M41: 2000 | N41: =+M41*P41 -> 85000 | O41: =+N41+K41+I41+G41 -> 86000 | P41: 42.5 | Q41: =+O41*P41 -> 3655000
A42: 33 | B42: 2.5.2-1836.10 | C42: PROD. MEDICO/FARMACEUTICOS/LAB | D42: 252 | E42: HIPERTENSORES; TIPO: MONODROGA, DROGA GENERICA: ZINC SULFATO, FORMA FARMACEUTICA: AMPOLLAS, PRESENTACION: 5 mL | F42: AMPOLLA | G42: 0 | H42: =+G42*P42 -> 0 | J42: =+I42*P42 -> 0 | L42: =+K42*P42 -> 0 | N42: =+M42*P42 -> 0 | O42: =+N42+K42+I42+G42 -> 0 | P42: 3500 | Q42: =+O42*P42 -> 0
A43: 34 | B43: 2.1.1-4227.55 | C43: PROD. MEDICO/FARMACEUTICOS/LAB | D43: 252 | E43: SUPLEMENTOS DIETARIOS; TIPO: MONODROGA, DROGA GENERICA: TRIGLICER CADENA MEDIA, PRESENTACION: ENVASE X 500 CM3 | F43: BOTELLA | G43: 0 | H43: =+G43*P43 -> 0 | J43: =+I43*P43 -> 0 | L43: =+K43*P43 -> 0 | N43: =+M43*P43 -> 0 | O43: =+N43+K43+I43+G43 -> 0 | P43: 12110 | Q43: =+O43*P43 -> 0
H44: =SUM(H10:H43) -> 23287115 | J44: =SUM(J10:J43) -> 19850 | L44: =SUM(L10:L43) -> 906430 | N44: =SUM(N10:N43) -> 85000 | Q44: =SUM(Q10:Q43) -> 27825895
B46: Especificidades:ITEMS 18,19,20,21,22,23,24 Y 25 DEBERAN CUMPLIR CON LA DISPOSICION ANMAT 11857/2017 SOLUCIONES PARENTERALES DE GRAN VOLUMEN
B47: Lugar de Entrega: …........................... DE XX:00 AXX:00HS., DEBIENDO CORRER LOS GASTOS DE FLETES, ACARREO, CARGA, DESCARGA Y SEGURO A CARGO DEL ADJUDICATARIO.
B49: Plazo de entrega: XXXX
...

Sheet  NotaPedido
A1: NOTA DE PEDIDO | J1: N° | K1: xxx/2022
A3: JURISDICCIÓN: | D3: =+'Necesidades Trimestrales '!C4 -> 040 - Ministerio de Salud
A4: SAF: | D4: =+'Necesidades Trimestrales '!C5 -> 011 - Direccion Provincial de Administracion - MS
A5: UNIDAD EJECUTORA: | D5: XXXX
A6: DEPENDENCIA SOLICITANTE: | D6: XXXX
A7: PERIODO UTILIZACIÓN: | D7: Semestral
A8: OBJETO: | D8: Adquisición de SANGRE Y ORGANOS HEMATOPOYETICOS/SISTEMA CARDIOVASCULAR
A10: Ítem | B10: Codigo Item | C10: DESCRIPCIÓN | H10: Adjunta Detalle Técnico | I10: Unidad Medida | J10: Precio Unitario Estimado | K10: Cantidad Solicitada
A12: 1 | B12: =+'Necesidades Trimestrales '!B10 -> 2.5.2-1726.10 | C12: =+'Necesidades Trimestrales '!E10 -> SOLUCIONES P/MEDICINA; TIPO: AGUA P/IRRIGACION QUIRURGICA, PRESENTACION: SACHET X 2000 mL | H12: NO | I12: =+'Necesidades Trimestrales '!F10 -> SACHET | J12: =+'Necesidades Trimestrales '!P10 -> 560 | K12: =+'Necesidades Trimestrales '!I10 -> 0
A13: 2 | B13: =+'Necesidades Trimestrales '!B11 -> 2.5.2-1726.520 | C13: =+'Necesidades Trimestrales '!E11 -> SOLUCIONES P/MEDICINA; TIPO: AGUA DESTILADA, PRESENTACION: AMPOLLA DE 10 ML | H13: NO | I13: =+'Necesidades Trimestrales '!F11 -> AMPOLLA | J13: =+'Necesidades Trimestrales '!P11 -> 45 | K13: =+'Necesidades Trimestrales '!I11 -> 0
A14: 3 | B14: =+'Necesidades Trimestrales '!B12 -> 2.5.2-1726.186 | C14: =+'Necesidades Trimestrales '!E12 -> SOLUCIONES P/MEDICINA; TIPO: AGUA DESTILADA, PRESENTACION: ENVASE X 500 mL | H14: NO | I14: =+'Necesidades Trimestrales '!F12 -> SACHET | J14: =+'Necesidades Trimestrales '!P12 -> 212 | K14: =+'Necesidades Trimestrales '!I12 -> 0
A15: 4 | B15: =+'Necesidades Trimestrales '!B13 -> 2.5.2-2183.7 | C15: =+'Necesidades Trimestrales '!E13 -> EXPANSORES PLASMATICOS; PRINCIPIO ACTIVO: ALBUMINA HUMANA, CONCENTRACION: 20 %, PRESENTACION: 50ML | H15: NO | I15: =+'Necesidades Trimestrales '!F13 -> SACHET | J15: =+'Necesidades Trimestrales '!P13 -> 3600 | K15: =+'Necesidades Trimestrales '!I13 -> 0
A16: 5 | B16: =+'Necesidades Trimestrales '!B14 -> 2.5.2-1903.103 | C16: =+'Necesidades Trimestrales '!E14 -> RECONSTITUYENTE GENERAL; DROGA GENERICA: ALIMENTO ENTERAL PARA SONDA FORTIFICADO CON FIBRAS, FORMA FARMACEUTICA: ENVASE, PRESENTACION: 1 L, TIPO: ASOCIACION | H16: NO | I16: =+'Necesidades Trimestrales '!F14 -> UNIDAD | J16: =+'Necesidades Trimestrales '!P14 -> 2800 | K16: =+'Necesidades Trimestrales '!I14 -> 0
A17: 6 | B17: =+'Necesidades Trimestrales '!B15 -> 2.5.2-1903.104 | C17: =+'Necesidades Trimestrales '!E15 -> RECONSTITUYENTE GENERAL; DROGA GENERICA: ALIMENTO ENTERAL PARA SONDA BAJO INDICE GLUCEMICO, FORMA FARMACEUTICA: ENVASE, PRESENTACION: 1 L, TIPO: ASOCIACION | H17: NO | I17: =+'Necesidades Trimestrales '!F15 -> UNIDAD | J17: =+'Necesidades Trimestrales '!P15 -> 3200 | K17: =+'Necesidades Trimestrales '!I15 -> 0
A18: 7 | B18: =+'Necesidades Trimestrales '!B16 -> 2.5.2-1903.105 | C18: =+'Necesidades Trimestrales '!E16 -> RECONSTITUYENTE GENERAL; TIPO: ASOCIACION, DROGA GENERICA: ALIMENTO ENTERAL PARA SONDA BAJO INDICE GLUCEMICO, FORMA FARMACEUTICA: SOLUCION, PRESENTACION: ENVASE X 500 CM3 | H18: NO | I18: =+'Necesidades Trimestrales '!F16 -> UNIDAD | J18: =+'Necesidades Trimestrales '!P16 -> 940 | K18: =+'Necesidades Trimestrales '!I16 -> 0
A19: 8 | B19: =+'Necesidades Trimestrales '!B17 -> 2.1.1-4227.56 | C19: =+'Necesidades Trimestrales '!E17 -> SUPLEMENTOS DIETARIOS; TIPO: ASOCIACION, DROGA GENERICA: S. PARENTERAL ADULTO 1501-2000 ML, PRESENTACION: UNIDAD | H19: NO | I19: =+'Necesidades Trimestrales '!F17 -> UNIDAD | J19: =+'Necesidades Trimestrales '!P17 -> 14800 | K19: =+'Necesidades Trimestrales '!I17 -> 0
A20: 9 | B20: =+'Necesidades Trimestrales '!B18 -> 2.1.1-4227.19 | C20: =+'Necesidades Trimestrales '!E18 -> SUPLEMENTOS DIETARIOS; TIPO: ASOCIACION, DROGA GENERICA: S. PARENTERAL NEONATAL 0-500 ML, PRESENTACION: UNIDAD, ACCESORIO: CON FILTRO | H20: NO | I20: =+'Necesidades Trimestrales '!F18 -> UNIDAD | J20: =+'Necesidades Trimestrales '!P18 -> 9800 | K20: =+'Necesidades Trimestrales '!I18 -> 0
A21: 10 | B21: =+'Necesidades Trimestrales '!B19 -> 2.5.2-1726.191 | C21: =+'Necesidades Trimestrales '!E19 -> SOLUCIONES P/MEDICINA; TIPO: AMINOACIDOS 10%, PRESENTACION: ENVASE X 500 ML | H21: NO | I21: =+'Necesidades Trimestrales '!F19 -> FRASCO | J21: =+'Necesidades Trimestrales '!P19 -> 8840 | K21: =+'Necesidades Trimestrales '!I19 -> 0
A22: 11 | B22: =+'Necesidades Trimestrales '!B20 -> 2.5.2-1726.9 | C22: =+'Necesidades Trimestrales '!E20 -> SOLUCIONES P/MEDICINA; TIPO: BICARBONATO 1 MOLAR, PRESENTACION: SACHET DE 100 mL | H22: NO | I22: =+'Necesidades Trimestrales '!F20 -> SACHET | J22: =+'Necesidades Trimestrales '!P20 -> 388 | K22: =+'Necesidades Trimestrales '!I20 -> 0
A23: 12 | B23: =+'Necesidades Trimestrales '!B21 -> 2.5.2-1726.305 | C23: =+'Necesidades Trimestrales '!E21 -> SOLUCIONES P/MEDICINA; TIPO: CLORURO DE POTASIO 15 MEQ, PRESENTACION: AMPOLLA DE 5 mL | H23: NO | I23: =+'Necesidades Trimestrales '!F21 -> AMPOLLA | J23: =+'Necesidades Trimestrales '!P21 -> 45 | K23: =+'Necesidades Trimestrales '!I21 -> 0
... A45: 34 | B45: =+'Necesidades Trimestrales '!B43 -> 2.1.1-4227.55 | C45: =+'Necesidades Trimestrales '!E43 -> SUPLEMENTOS DIETARIOS; TIPO: MONODROGA, DROGA GENERICA: TRIGLICER CADENA MEDIA, PRESENTACION: ENVASE X 500 CM3 | H45: NO | I45: =+'Necesidades Trimestrales '!F43 -> BOTELLA | J45: =+'Necesidades Trimestrales '!P43 -> 12110 | K45: =+'Necesidades Trimestrales '!I43 -> 0
A46: Costo total estimado: xxxxxxxxxxxxxxxxxxxx con 00/100. | J46: =SUMPRODUCT(J12:J45,K12:K45) -> 19850

Sheet Autor Gastar
A1: EJERCICIO: | D1: 2022 | P1: AUTORIZACION PARA GASTAR
A4: JURISDICCIÓN: | G4: =+'Necesidades Trimestrales '!C4 -> 040 - Ministerio de Salud
A5: SAF: | G5: =' NotaPedido'!D4 -> 011 - Direccion Provincial de Administracion - MS
A6: UNIDAD EJECUTORA: | G6: =' NotaPedido'!D5 -> XXXX
A7: DEPENDENCIA SOLICITANTE: | G7: =' NotaPedido'!D6 -> XXXX
A8: AUTORIZACIÓN:
A9: Señor Jefe de Servicio Administrativo Financiero:
A10: ="Autorizo la realización de los trámites correspondientes, a fin de proveer a este Organismo los bienes y/o servicios que se detallan en Nota de Pedido N° " & ' NotaPedido'!K1&", afectando la erogación resultante a los créditos presupuestarios aprobados a favor de esta Unidad Ejecutora, conforme al siguiente detalle:" -> Autorizo la realización de los trámites correspondientes, a fin de proveer a este Organismo los bienes y/o servicios que se detallan en Nota de Pedido N° xxx/2022, afectando la erogación resultante a los créditos presupuestarios aprobados a favor de esta Unidad Ejecutora, conforme al siguiente detalle:
A12: IMPUTACIÓN PRESUPUESTARIA
A13: CÓDIGO | O13: DENOMINACIÓN DE LA PARTIDA PRESUPUESTARIA | Q13: IMPORTE
A14: PR | B14: SB | C14: PY | D14: AC | E14: OB | F14: UG | G14: FIN | H14: FUN | I14: I | J14: P | K14: P | L14: SubP | M14: M | N14: FF
F15: 4901 | G15: 3 | H15: 310 | I15: 2 | J15: 5 | K15: 2 | M15: 1 | N15: 1.1 | O15: Productos Farmacéuticos y Medicinales
A23: TOTAL DE PESOS: xxxxxxxxxxxxxxx con 00/100. | Q23: =SUM(Q15:Q22) -> 0
A25: JUSTIFICACIÓN:
A26: Para la adquisición de .... … destinados al servico de …... del Hospital …...............
