Workbook

Sheet Necesidades Trimestrales
B2: Pedido de Necesidades Trimestrales
A4: JURISDICCION: | C4: 040 - Ministerio de Salud
A5: SAF N°: | C5: 011 - Direccion Provincial de Administracion - MS
A6: EJERCICIO: | C6: 2022
A7: TRIMESTRE: | C7: 3
A9: ID | B9: CODIGO ITEM | C9: RUBRO DE COMPRA | D9: I.P.P. | E9: DESCRIPCION | F9: UNIDAD DE MEDIDA | G9: CANTIDAD | H9: PRECIO UNITARIO ESTIMADO | I9: IMPORTE TOTAL ESTIMADO | K9: 295 | L9: 252
A10: 1 | B10: 2.9.5-3020.3 | C10: PROD. MEDICO/FARMACEUTICOS/LAB | D10: 295 | E10: BOLSAS P/COLOSTOMIA; TIPO: DESCARTABLE ADHESIVA P/ ADULTOS, DIAMETRO DE ARO: SIN ARO | F10: UNIDAD | G10: 20 | H10: 225 | I10: =+G10*H10 -> 4500 | K10: =+I10 -> 4500
A11: 2 | B11: 2.9.5-4198.93 | C11: PROD. MEDICO/FARMACEUTICOS/LAB | D11: 295 | E11: ELEMENTOS DESC. P/CIRUGIAS; TIPO: CAMPO QUIRURGICO 60 X 45 Cm, PRESENTACION: UNIDAD | F11: UNIDAD | G11: 20 | H11: 870 | I11: =+G11*H11 -> 17400 | K11: =+I11 -> 17400
A12: 3 | B12: 2.9.5-4198.41 | C12: PROD. MEDICO/FARMACEUTICOS/LAB | D12: 295 | E12: ELEMENTOS DESC. P/CIRUGIAS; TIPO: CAMPO QUIRURGICO 120 X 130 Cm, PRESENTACION: UNIDAD | F12: UNIDAD | G12: 15 | H12: 750 | I12: =+G12*H12 -> 11250 | K12: =+I12 -> 11250
A13: 4 | B13: 2.9.5-8220.15 | C13: PROD. MEDICO/FARMACEUTICOS/LAB | D13: 295 | E13: CANASTILLAS DE DORMIA; TIPO: HELICOIDAL, DIMENSION: 2.8 mm, USO: P/EXTRACCION DE CALCULOS | F13: UNIDAD | G13: 3 | H13: 55600 | I13: =+G13*H13 -> 166800 | K13: =+I13 -> 166800
A14: 5 | B14: 2.9.5-2161.554 | C14: PROD. MEDICO/FARMACEUTICOS/LAB | D14: 295 | E14: CATETERES/SONDAS; NUMERO: 12 FRENCH, TIPO: DIALISIS PERITONEAL | F14: UNIDAD | G14: 3 | H14: 33500 | I14: =+G14*H14 -> 100500 | K14: =+I14 -> 100500
A15: 6 | B15: 2.9.5-2161.555 | C15: PROD. MEDICO/FARMACEUTICOS/LAB | D15: 295 | E15: CATETERES/SONDAS; NUMERO: 15 FRENCH, TIPO: DIALISIS PERITONEAL | F15: UNIDAD | G15: 3 | H15: 33500 | I15: =+G15*H15 -> 100500 | K15: =+I15 -> 100500
A16: 7 | B16: 2.9.5-2161.586 | C16: PROD. MEDICO/FARMACEUTICOS/LAB | D16: 295 | E16: CATETERES/SONDAS; NUMERO: 4,7 FR X 26 CM, TIPO: DOBLE J COOK | F16: UNIDAD | G16: 10 | H16: 13500 | I16: =+G16*H16 -> 135000 | K16: =+I16 -> 135000
A17: 8 | B17: 2.9.5-2161.473 | C17: PROD. MEDICO/FARMACEUTICOS/LAB | D17: 295 | E17: CATETERES/SONDAS; NUMERO: 7 FR X 26 CM, TIPO: DOBLE J COOK | F17: UNIDAD | G17: 6 | H17: 13500 | I17: =+G17*H17 -> 81000 | K17: =+I17 -> 81000
A18: 9 | B18: 2.9.5-2161.556 | C18: PROD. MEDICO/FARMACEUTICOS/LAB | D18: 295 | E18: CATETERES/SONDAS; NUMERO: SIN DATOS, TIPO: DOBLE P/LAVADO BRONCO ALVEOLAR P/DIAGNOSTICO NEUMONIA | F18: UNIDAD | G18: 3 | H18: 8500 | I18: =+G18*H18 -> 25500 | K18: =+I18 -> 25500
A19: 10 | B19: 2.9.5-2161.147 | C19: PROD. MEDICO/FARMACEUTICOS/LAB | D19: 295 | E19: CATETERES/SONDAS; NUMERO: 3, TIPO: FOGARTY | F19: UNIDAD | G19: 10 | H19: 4500 | I19: =+G19*H19 -> 45000 | K19: =+I19 -> 45000
A20: 11 | B20: 2.9.5-2161.519 | C20: PROD. MEDICO/FARMACEUTICOS/LAB | D20: 295 | E20: CATETERES/SONDAS; NUMERO: 4 , TIPO: FOGARTY | F20: UNIDAD | G20: 10 | H20: 4500 | I20: =+G20*H20 -> 45000 | K20: =+I20 -> 45000
A21: 12 | B21: 2.9.5-2161.148 | C21: PROD. MEDICO/FARMACEUTICOS/LAB | D21: 295 | E21: CATETERES/SONDAS; NUMERO: 5, TIPO: FOGARTY | F21: UNIDAD | G21: 10 | H21: 4500 | I21: =+G21*H21 -> 45000 | K21: =+I21 -> 45000
... A26: 17 | B26: 2.9.5-2161.574 | C26: PROD. MEDICO/FARMACEUTICOS/LAB | D26: 295 | E26: CATETERES/SONDAS; NUMERO: 2,5 FR, TIPO: UMBILICAL VENOSO, PRESENTACION: UNIDAD | F26: UNIDAD | G26: 20 | H26: 2500 | I26: =+G26*H26 -> 50000 | K26: =+I26 -> 50000
A27: 18 | B27: 2.9.5-5294.5 | C27: PROD. MEDICO/FARMACEUTICOS/LAB | D27: 252 | E27: CERAS P/HUESOS; USO: HEMOSTASIA, PRESENTACION: UNIDAD ESTERIL DE 2,5 GR | F27: UNIDAD | G27: 10 | H27: 488 | I27: =+G27*H27 -> 4880 | L27: =+I27 -> 4880
A28: 19 | B28: 2.9.5-6379.10 | C28: PROD. MEDICO/FARMACEUTICOS/LAB | D28: 295 | E28: CLAVIJAS DE CIRUGIA; TIPO: STEIMANN, MATERIAL: ACERO INOXIDABLE, DIAMETRO: 5 MM, PRESENTACION: UNIDAD | F28: UNIDAD | G28: 20 | H28: 530 | I28: =+G28*H28 -> 10600 | K28: =+I28 -> 10600
A29: 20 | B29: 2.9.5-6379.1 | C29: PROD. MEDICO/FARMACEUTICOS/LAB | D29: 295 | E29: CLAVIJAS DE CIRUGIA; TIPO: KIRSCHNER, MATERIAL: ACERO INOXIDABLE, DIAMETRO: 0,5 mm, PRESENTACION: UNIDAD | F29: UNIDAD | G29: 100 | H29: 421.2 | I29: =+G29*H29 -> 42120 | K29: =+I29 -> 42120
A30: 21 | B30: 2.9.5-6379.2 | C30: PROD. MEDICO/FARMACEUTICOS/LAB | D30: 295 | E30: CLAVIJAS DE CIRUGIA; TIPO: KIRSCHNER, MATERIAL: ACERO INOXIDABLE, DIAMETRO: 1 mm, PRESENTACION: UNIDAD | F30: UNIDAD | G30: 80 | H30: 390 | I30: =+G30*H30 -> 31200 | K30: =+I30 -> 31200
A31: 22 | B31: 2.9.5-6379.3 | C31: PROD. MEDICO/FARMACEUTICOS/LAB | D31: 295 | E31: CLAVIJAS DE CIRUGIA; TIPO: KIRSCHNER, MATERIAL: ACERO INOXIDABLE, DIAMETRO: 1,5 mm, PRESENTACION: UNIDAD | F31: UNIDAD | G31: 100 | H31: 395 | I31: =+G31*H31 -> 39500 | K31: =+I31 -> 39500
A32: 23 | B32: 2.9.5-6379.5 | C32: PROD. MEDICO/FARMACEUTICOS/LAB | D32: 295 | E32: CLAVIJAS DE CIRUGIA; TIPO: KIRSCHNER, MATERIAL: ACERO INOXIDABLE, DIAMETRO: 2 MM, PRESENTACION: UNIDAD | F32: UNIDAD | G32: 100 | H32: 392.6 | I32: =+G32*H32 -> 39260 | K32: =+I32 -> 39260
A33: 24 | B33: 2.9.5-6379.6 | C33: PROD. MEDICO/FARMACEUTICOS/LAB | D33: 295 | E33: CLAVIJAS DE CIRUGÍA; TIPO: KIRSCHNER; DIÁMETRO: 2,5 MM; MATERIAL: ACERO INOXIDABLE; PRESENTACIÓN: UNIDAD | F33: UNIDAD | G33: 100 | H33: 451.1 | I33: =+G33*H33 -> 45110 | K33: =+I33 -> 45110
A34: 25 | B34: 2.9.5-6379.7 | C34: PROD. MEDICO/FARMACEUTICOS/LAB | D34: 295 | E34: CLAVIJAS DE CIRUGIA; TIPO: STEIMANN, MATERIAL: ACERO INOXIDABLE, DIAMETRO: 4 mm, PRESENTACION: UNIDAD | F34: UNIDAD | G34: 30 | H34: 453.7 | I34: =+G34*H34 -> 13611 | K34: =+I34 -> 13611
A35: 26 | B35: 2.9.5-6286.11 | C35: PROD. MEDICO/FARMACEUTICOS/LAB | D35: 295 | E35: HEMOSTATICOS ABSORBIBLES; TIPO: TOPICO, MEDIDA: 5 X 7,5 Cm, PRESENTACION: UNIDAD | F35: UNIDAD | G35: 50 | H35: 768.4 | I35: =+G35*H35 -> 38420 | K35: =+I35 -> 38420
A36: 27 | B36: 2.9.5-448.95 | C36: PROD. MEDICO/FARMACEUTICOS/LAB | D36: 295 | E36: FRASCOS ESTERILES; CAPACIDAD: 750 CC, PRESENTACION: UNIDAD, GRABADO: SIN, USO: BITUBULADO DRENAJE | F36: UNIDAD | G36: 20 | H36: 330 | I36: =+G36*H36 -> 6600 | K36: =+I36 -> 6600
A37: 28 | B37: 2.9.5-6752.2 | C37: PROD. MEDICO/FARMACEUTICOS/LAB | D37: 295 | E37: ASPIRADORES MÉDICOS; TIPO: HEMOSUCTOR PLÁSTICO; CAPACIDAD: 750/800 CM3; EQUIPO: INDIVIDUAL, USO: QUIRÚRGICO | F37: UNIDAD | G37: 50 | H37: 1387.5 | I37: =+G37*H37 -> 69375 | K37: =+I37 -> 69375
A38: 29 | B38: 2.9.5-2496.403 | C38: PROD. MEDICO/FARMACEUTICOS/LAB | D38: 295 | E38: SUTURAS MECANICAS; TIPO: LIGA CLIPS MEDIUM LT200, USO: QUIRURGICO, PRESENTACION: UNIDAD | F38: UNIDAD | G38: 20 | H38: 2600 | I38: =+G38*H38 -> 52000 | K38: =+I38 -> 52000
A39: 30 | B39: 2.9.5-2496.402 | C39: PROD. MEDICO/FARMACEUTICOS/LAB | D39: 295 | E39: SUTURAS MECANICAS; TIPO: LIGA CLIPS LARGE LT300, USO: QUIRURGICO, PRESENTACION: UNIDAD | F39: UNIDAD | G39: 50 | H39: 2600 | I39: =+G39*H39 -> 130000 | K39: =+I39 -> 130000
... A66: 57 | B66: 2.9.5-6700.26 | C66: PROD. MEDICO/FARMACEUTICOS/LAB | D66: 295 | E66: TROCAR DE PUNCION; USO: PUNCION TORAXICA, TIPO: N° 24 FR, CAMISA: SIN | F66: UNIDAD | G66: 10 | H66: 1350 | I66: =+G66*H66 -> 13500 | K66: =+I66 -> 13500
A67: TOTAL RUBRO DESCARTABLE COMPLEJO | I67: =SUM(I10:I66) -> 4707919.5 | K67: =SUM(K10:K66) -> 4703039.5 | L67: =SUM(L10:L66) -> 4880 | M67: =SUM(K67:L67) -> 4707919.5
B70: DETALLE TECNICO Y ESPECIFICACIONES | C70: ANEXO 1-Para oferentes de la Provincia de Catamarca deberán presentar Habilitación Provincial para comercializar el producto que cotizan. 2-Para el resto de oferentes deberán presentar Certificado de Inscripción de ANMAT vigente al momento de la oferta, el mismo deberá ser correspondiente al objeto de la contratación y de encontrarse vencido adjuntar la solicitud de renovación. 3-No se aceptarán ofertas de productos no registrados y autorizada su venta por ANMAT. Se deberá especificar en cada ítem de la propuesta, marca y número de certificado otorgado por dicho ente regulador. 4-Los productos deberán tener un vencimiento posterior a doce (12) meses a partir de la fecha de su recepción.
B72: Plazos de entrega | C72: veinte (20) dias habiles
B74: Lugar de Entrega: | C74: DIR. PROV. DE FARMACIA E INSUMOS - CHACABUCO N° 169 - en el horario de 8:00hs a 12:00hs de lunes a viernes
B76: Calidad Minima esperada
B78: Mantenimiento | C78: cuarenta y cinco (45) días
B81: Especificidades: ITEMS 2 TIPO STERIDRAPE 1050
...

Sheet  NotaPedido
A1: NOTA DE PEDIDO | J1: N° | K1: xxx/2022
A3: JURISDICCIÓN: | D3: ='Necesidades Trimestrales'!C4 -> 040 - Ministerio de Salud
A4: SAF: | D4: ='Necesidades Trimestrales'!C5 -> 011 - Direccion Provincial de Administracion - MS
A5: UNIDAD EJECUTORA: | D5: 469 - DIRECCION PROVINCIAL DE FARMACIA E INSUMOS
A6: DEPENDENCIA SOLICITANTE: | D6: 469 - DIRECCION PROVINCIAL DE FARMACIA E INSUMOS
A7: PERIODO UTILIZACIÓN: | D7: Semestral
A8: OBJETO: | D8: Adquisición de Descartable Complejo
A10: Ítem | B10: Codigo Item | C10: DESCRIPCIÓN | H10: Adjunta Detalle Técnico | I10: Unidad Medida | J10: Precio Unitario Estimado | K10: Cantidad Solicitada
A12: 1 | B12: =+'Necesidades Trimestrales'!B10 -> 2.9.5-3020.3 | C12: =+'Necesidades Trimestrales'!E10 -> BOLSAS P/COLOSTOMIA; TIPO: DESCARTABLE ADHESIVA P/ ADULTOS, DIAMETRO DE ARO: SIN ARO | H12: NO | I12: =+'Necesidades Trimestrales'!F10 -> UNIDAD | J12: =+'Necesidades Trimestrales'!H10 -> 225 | K12: =+'Necesidades Trimestrales'!G10 -> 20
A13: 2 | B13: =+'Necesidades Trimestrales'!B11 -> 2.9.5-4198.93 | C13: =+'Necesidades Trimestrales'!E11 -> ELEMENTOS DESC. P/CIRUGIAS; TIPO: CAMPO QUIRURGICO 60 X 45 Cm, PRESENTACION: UNIDAD | H13: SI | I13: =+'Necesidades Trimestrales'!F11 -> UNIDAD | J13: =+'Necesidades Trimestrales'!H11 -> 870 | K13: =+'Necesidades Trimestrales'!G11 -> 20
A14: 3 | B14: =+'Necesidades Trimestrales'!B12 -> 2.9.5-4198.41 | C14: =+'Necesidades Trimestrales'!E12 -> ELEMENTOS DESC. P/CIRUGIAS; TIPO: CAMPO QUIRURGICO 120 X 130 Cm, PRESENTACION: UNIDAD | H14: SI | I14: =+'Necesidades Trimestrales'!F12 -> UNIDAD | J14: =+'Necesidades Trimestrales'!H12 -> 750 | K14: =+'Necesidades Trimestrales'!G12 -> 15
A15: 4 | B15: =+'Necesidades Trimestrales'!B13 -> 2.9.5-8220.15 | C15: =+'Necesidades Trimestrales'!E13 -> CANASTILLAS DE DORMIA; TIPO: HELICOIDAL, DIMENSION: 2.8 mm, USO: P/EXTRACCION DE CALCULOS | H15: SI | I15: =+'Necesidades Trimestrales'!F13 -> UNIDAD | J15: =+'Necesidades Trimestrales'!H13 -> 55600 | K15: =+'Necesidades Trimestrales'!G13 -> 3
A16: 5 | B16: =+'Necesidades Trimestrales'!B14 -> 2.9.5-2161.554 | C16: =+'Necesidades Trimestrales'!E14 -> CATETERES/SONDAS; NUMERO: 12 FRENCH, TIPO: DIALISIS PERITONEAL | H16: SI | I16: =+'Necesidades Trimestrales'!F14 -> UNIDAD | J16: =+'Necesidades Trimestrales'!H14 -> 33500 | K16: =+'Necesidades Trimestrales'!G14 -> 3
A17: 6 | B17: =+'Necesidades Trimestrales'!B15 -> 2.9.5-2161.555 | C17: =+'Necesidades Trimestrales'!E15 -> CATETERES/SONDAS; NUMERO: 15 FRENCH, TIPO: DIALISIS PERITONEAL | H17: SI | I17: =+'Necesidades Trimestrales'!F15 -> UNIDAD | J17: =+'Necesidades Trimestrales'!H15 -> 33500 | K17: =+'Necesidades Trimestrales'!G15 -> 3
A18: 7 | B18: =+'Necesidades Trimestrales'!B16 -> 2.9.5-2161.586 | C18: =+'Necesidades Trimestrales'!E16 -> CATETERES/SONDAS; NUMERO: 4,7 FR X 26 CM, TIPO: DOBLE J COOK | H18: SI | I18: =+'Necesidades Trimestrales'!F16 -> UNIDAD | J18: =+'Necesidades Trimestrales'!H16 -> 13500 | K18: =+'Necesidades Trimestrales'!G16 -> 10
A19: 8 | B19: =+'Necesidades Trimestrales'!B17 -> 2.9.5-2161.473 | C19: =+'Necesidades Trimestrales'!E17 -> CATETERES/SONDAS; NUMERO: 7 FR X 26 CM, TIPO: DOBLE J COOK | H19: SI | I19: =+'Necesidades Trimestrales'!F17 -> UNIDAD | J19: =+'Necesidades Trimestrales'!H17 -> 13500 | K19: =+'Necesidades Trimestrales'!G17 -> 6
A20: 9 | B20: =+'Necesidades Trimestrales'!B18 -> 2.9.5-2161.556 | C20: =+'Necesidades Trimestrales'!E18 -> CATETERES/SONDAS; NUMERO: SIN DATOS, TIPO: DOBLE P/LAVADO BRONCO ALVEOLAR P/DIAGNOSTICO NEUMONIA | H20: NO | I20: =+'Necesidades Trimestrales'!F18 -> UNIDAD | J20: =+'Necesidades Trimestrales'!H18 -> 8500 | K20: =+'Necesidades Trimestrales'!G18 -> 3
A21: 10 | B21: =+'Necesidades Trimestrales'!B19 -> 2.9.5-2161.147 | C21: =+'Necesidades Trimestrales'!E19 -> CATETERES/SONDAS; NUMERO: 3, TIPO: FOGARTY | H21: NO | I21: =+'Necesidades Trimestrales'!F19 -> UNIDAD | J21: =+'Necesidades Trimestrales'!H19 -> 4500 | K21: =+'Necesidades Trimestrales'!G19 -> 10
A22: 11 | B22: =+'Necesidades Trimestrales'!B20 -> 2.9.5-2161.519 | C22: =+'Necesidades Trimestrales'!E20 -> CATETERES/SONDAS; NUMERO: 4 , TIPO: FOGARTY | H22: NO | I22: =+'Necesidades Trimestrales'!F20 -> UNIDAD | J22: =+'Necesidades Trimestrales'!H20 -> 4500 | K22: =+'Necesidades Trimestrales'!G20 -> 10
A23: 12 | B23: =+'Necesidades Trimestrales'!B21 -> 2.9.5-2161.148 | C23: =+'Necesidades Trimestrales'!E21 -> CATETERES/SONDAS; NUMERO: 5, TIPO: FOGARTY | H23: NO | I23: =+'Necesidades Trimestrales'!F21 -> UNIDAD | J23: =+'Necesidades Trimestrales'!H21 -> 4500 | K23: =+'Necesidades Trimestrales'!G21 -> 10
... A68: 57 | B68: =+'Necesidades Trimestrales'!B66 -> 2.9.5-6700.26 | C68: =+'Necesidades Trimestrales'!E66 -> TROCAR DE PUNCION; USO: PUNCION TORAXICA, TIPO: N° 24 FR, CAMISA: SIN | H68: NO | I68: =+'Necesidades Trimestrales'!F66 -> UNIDAD | J68: =+'Necesidades Trimestrales'!H66 -> 1350 | K68: =+'Necesidades Trimestrales'!G66 -> 10
A69: Costo total estimado: CUATRO MILLONES SETECIENTOS SIETE MIL NOVECIENTOS DIECINUEVE con 50/100. | J69: =SUMPRODUCT(J12:J68,K12:K68) -> 4707919.5

Sheet Autor Gastar
A1: EJERCICIO: | D1: ='Necesidades Trimestrales'!C6 -> 2022 | P1: AUTORIZACION PARA GASTAR
A4: JURISDICCIÓN: | G4: =' NotaPedido'!D3 -> 040 - Ministerio de Salud
A5: SAF: | G5: =' NotaPedido'!D4 -> 011 - Direccion Provincial de Administracion - MS
A6: UNIDAD EJECUTORA: | G6: =' NotaPedido'!D5 -> 469 - DIRECCION PROVINCIAL DE FARMACIA E INSUMOS
A7: DEPENDENCIA SOLICITANTE: | G7: =' NotaPedido'!D6 -> 469 - DIRECCION PROVINCIAL DE FARMACIA E INSUMOS
A8: AUTORIZACIÓN:
A9: Señor Jefe de Servicio Administrativo Financiero:
A10: ="Autorizo la realización de los trámites correspondientes, a fin de proveer a este Organismo los bienes y/o servicios que se detallan en Nota de Pedido N° " & ' NotaPedido'!K1&", afectando la erogación resultante a los créditos presupuestarios aprobados a favor de esta Unidad Ejecutora, conforme al siguiente detalle:" -> Autorizo la realización de los trámites correspondientes, a fin de proveer a este Organismo los bienes y/o servicios que se detallan en Nota de Pedido N° xxx/2022, afectando la erogación resultante a los créditos presupuestarios aprobados a favor de esta Unidad Ejecutora, conforme al siguiente detalle:
A12: IMPUTACIÓN PRESUPUESTARIA
A13: CÓDIGO | O13: DENOMINACIÓN DE LA PARTIDA PRESUPUESTARIA | Q13: IMPORTE
A14: PR | B14: SB | C14: PY | D14: AC | E14: OB | F14: UG | G14: FIN | H14: FUN | I14: I | J14: P | K14: P | L14: SubP | M14: M | N14: FF
A15: 30 | D15: 1 | F15: 4901 | G15: 3 | H15: 1 | I15: 2 | J15: 5 | K15: 2 | M15: 1 | N15: 1.1 | O15: Productos Farmacéuticos y Medicinales | Q15: ='Necesidades Trimestrales'!L67 -> 4880
A16: 30 | D16: 1 | F16: 4901 | G16: 3 | H16: 1 | I16: 2 | J16: 9 | K16: 5 | M16: 1 | N16: 1.1 | O16: Útiles Menores Médico, Quirúrgico y de Laboratorio | Q16: ='Necesidades Trimestrales'!K67 -> 4703039.5
A23: TOTAL DE PESOS: CUATRO MILLONES SETECIENTOS SIETE MIL NOVECIENTOS DIECINUEVE CON 50/100. | Q23: =SUM(Q15:Q22) -> 4707919.5
A25: JUSTIFICACIÓN:
A26: =' NotaPedido'!D8 -> Adquisición de Descartable Complejo
