Workbook

Sheet SAF 011 - NECESIDAD TRIMESTRAL
A1: 2022
B2: Pedido de Necesidades Trimestrales
A4: JURISDICCION: | C4: 040 - MINISTERIO DE SALUD
A5: SAF N°: | C5: 011 - DIRECCION PROVINCIAL DE ADMINISTRACION - MINISTERIO DE SALUD
A6: EJERCICIO: | C6: 2022
A7: TRIMESTRE: | C7: TERCERO
A9: ID | B9: CODIGO ITEM | C9: RUBRO DE COMPRA | D9: I.P.P. | E9: DESCRIPCION | F9: UNIDAD DE MEDIDA | G9: CANTIDAD TOTAL | H9: PRECIO UNITARIO ESTIMADO | I9: IMPORTE TOTAL ESTIMADO
A10: 1 | B10: 4.3.3-8790.6 | C10: PROD. MEDICO/FARMACEUTICOS/LAB | D10: 4.3.3 | E10: BAÑOS MARIA; DIMENSION: 45 X 30 X 13 mm, ALIMENTACION: 220 V, MATERIAL: ACERO INOXIDABLE, TEMPERATURA MAXIMA: 100 °C | F10: UNIDAD | G10: 4 | H10: 50000 | I10: =+G10*H10 -> 200000
A11: 2 | B11: 4.3.3-208.17 | C11: PROD. MEDICO/FARMACEUTICOS/LAB | D11: 4.3.3 | E11: CAMAS HOSPITALARIAS; DESTINO: DE INTERNACION, DIMENSION: 190 X 80 X 20 Cm, LECHO: REGULABLE, MOV. ORTOPEDICO: A MANIVELA, MATERIAL ESTRUCTURA: ACERO, TIPO PANEL LATERAL: BARANDA DESMONTABLE, MOVILIDAD: A MANIVELA, MATERIAL: ACERO | F11: UNIDAD | G11: 70 | H11: 125000 | I11: =+G11*H11 -> 8750000
A12: 3 | B12: 4.3.3-208.12 | C12: PROD. MEDICO/FARMACEUTICOS/LAB | D12: 4.3.3 | E12: CAMAS HOSPITALARIAS; DESTINO: PACIENTES + DE 200 KG, DIMENSION: 110 X 200 X 62 Cm, LECHO: ESTRATIFICADO, MOV. ORTOPEDICO: A MANIVELA, MATERIAL ESTRUCTURA: CAÑO, TIPO PANEL LATERAL: DESMONTABLE, MOVILIDAD: A MANIVELA, MATERIAL: CAÑO | F12: UNIDAD | G12: 14 | H12: =278250+36113 -> 314363 | I12: =+G12*H12 -> 4401082
A13: 4 | B13: 4.3.3-1719.21 | C13: EQUIPOS | D13: 4.3.3 | E13: CAMILLAS; ANCHO: 50 Cm, LARGO: 200 Cm, ALTO: 75 Cm, ARNESES: SIN, TIPO: EXAMEN | F13: UNIDAD | G13: 80 | H13: 32000 | I13: =+G13*H13 -> 2560000
A14: 5 | B14: 4.3.3-1719.15 | C14: EQUIPOS | D14: 4.3.3 | E14: CAMILLAS; ANCHO: 55 Cm, LARGO: 130 Cm, ALTO: 85 Cm, ARNESES: SIN, TIPO: EXAMEN PEDIATRICO | F14: UNIDAD | G14: 10 | H14: 32000 | I14: =+G14*H14 -> 320000
A15: 6 | B15: 4.3.3-1719.14 | C15: EQUIPOS | D15: 4.3.3 | E15: CAMILLAS; ANCHO: 55 Cm, LARGO: 180 Cm, ALTO: 70 Cm, ARNESES: SIN VALOR, TIPO: GINECOLOGICA | F15: UNIDAD | G15: 10 | H15: 53000 | I15: =+G15*H15 -> 530000
A16: 7 | B16: 4.3.3-1719.22 | C16: EQUIPOS | D16: 4.3.3 | E16: CAMILLAS; ANCHO: 80 Cm, LARGO: 200 Cm, ALTO: 75 Cm, ARNESES: SIN, TIPO: EXAMEN | F16: UNIDAD | G16: 10 | H16: 43000 | I16: =+G16*H16 -> 430000
A17: 8 | B17: 4.3.3-2046.9 | C17: PROD. MEDICO/FARMACEUTICOS/LAB | D17: 4.3.3 | E17: CARDIODESFIBRILADORES; ALIMENTACION: BATERIA, TIPO: EXTERNO BIFASICO, ACCESORIO: MONITOR | F17: UNIDAD | G17: 7 | H17: 610000 | I17: =+G17*H17 -> 4270000
A18: 9 | B18: 4.3.3-5412.12 | C18: EQUIPOS | D18: 4.3.3 | E18: CARROS DE CURACIONES; MATERIAL: MELAMINA, ESTANTE: 2, DEFENSA: METALICAS CROMADAS, CAPACIDAD: 3 PORTAFRASCOS, CANT. DE RUEDAS: 4, DIMENSION: 46 X 55 X 78 Cm | F18: UNIDAD | G18: 25 | H18: 14300 | I18: =+G18*H18 -> 357500
A19: 10 | B19: 4.3.3-5412.10 | C19: EQUIPOS | D19: 4.3.3 | E19: CARROS DE CURACIONES; MATERIAL: METAL, ESTANTE: 3, DEFENSA: CON, CAPACIDAD: 7 CRESTAS, CANT. DE RUEDAS: 4, DIMENSION: 76 X 50 X 100 Cm | F19: UNIDAD | G19: 25 | H19: 32000 | I19: =+G19*H19 -> 800000
A20: 11 | B20: 4.3.3-67.7 | C20: PROD. MEDICO/FARMACEUTICOS/LAB | D20: 4.3.3 | E20: CENTRIFUGAS P/LABORATORIO; CABEZAL: 24 TUBOS, TIPO CABEZAL: 24 TUBOS | F20: UNIDAD | G20: 5 | H20: 255062.41 | I20: =+G20*H20 -> 1275312.1
A21: 12 | B21: 4.3.3-6359.1 | C21: EQUIPOS | D21: 4.3.3 | E21: COLPOSCOPIOS; OBJETIVO: DE F 300 DIST. DE TRABAJO mm, MODELO: OP-C2, AUMENTOS: TRES, LUZ: FRIA DE 150 DE POTENCIA W, PARALELOGRAMO: BALANCEADO Y COMPENSADO, FILTRO: VERDE, BINOCULAR: INCLINADO A 45 °C, SIST. DE VIDEO: P/COLPOSCOPIA, VIDEO PRINTER: CON, AUMENTO: TRES | F21: UNIDAD | G21: 4 | H21: 175000 | I21: =+G21*H21 -> 700000
A22: 13 | B22: 4.3.3-134.4 | C22: PROD. MEDICO/FARMACEUTICOS/LAB | D22: 4.3.3 | E22: ELECTROCARDIOGRAFOS; TIPO: PORTATIL, ALIMENTACION: 220V Y BATERIA RECARGABLE | F22: UNIDAD | G22: 7 | H22: 215000 | I22: =+G22*H22 -> 1505000
A23: 14 | B23: 4.3.3-4084.13 | C23: EQUIPOS | D23: 4.3.3 | E23: EQUIPOS DE RAYOS X; USO: PORTATIL, FRECUENCIA: SIN VALOR, REGULACION: AUTOMATICA, COMANDOS: CON INSTRUMENTOS CONTROLADORES, AMPLIACION DE APLIQUE: APLIQUE POTENCIA 20/40/125 KW, COMANDO: CON INSTRUMENTOS CONTROLADORES | F23: UNIDAD | G23: 2 | H23: 5500000 | I23: =+G23*H23 -> 11000000
A24: 15 | B24: 4.3.3-7797.2 | C24: PROD. MEDICO/FARMACEUTICOS/LAB | D24: 4.3.3 | E24: FOTOSFOROS; TIPO: RODANTE, USO: MEDICO | F24: UNIDAD | G24: 30 | H24: 19000 | I24: =+G24*H24 -> 570000
... A28: 19 | B28: 4.3.3-1711.9 | C28: EQUIPOS | D28: 4.3.3 | E28: SILLAS DE RUEDAS; ANCHO: 61 Cm, APOYABRAZO: DESMONTABLE, PIERNERA: DESMONTABLE, FRENO: CON, MATERIAL: METALICA CROMADA | F28: UNIDAD | G28: 28 | H28: 43000 | I28: =+G28*H28 -> 1204000
E29: TOTAL RUBRO EQUIPOS | I29: =+SUM(I10:I28) -> 42301867
C32: ESPECIFICADES Y DETALLE TECNICO:
C33: * ADJUNTAR FOLLETERIA, MANUALES Y/O CUALQUIER OTRA DOCUMENTACION QUE EL PROVEEDOR ESTIME NECESARIO PARA ACLARAR EL BIEN COTIZADO
C35: Plazos de entrega: | D35: veinte (20) dias habiles
C37: Lugar de Entrega: | D37: MINISTERIO DE SALUD - CHACABUCO N° 169 - en el horario de 8:00hs a 12:00hs de lunes a viernes
C39: Calidad Minima esperada:
C41: Garantia: | D41: minima un (1) año
C43: Mantenimiento: | D43: cuarenta y cinco (45) días
C46: ESPECIFICIDADES ITEM 1
C47: Con un rango de desvío no mayor a 1 grado centígrado. Aprobado por ANMAT.
C49: ESPECIFICIDADES ITEM 2
C50: Manual, 3 movimientos, barandas rebatibles y desmontables, ruedas por 125mm con freno independiente, lecho de chapa , porta suero inoxidables telescopico recto. Incluye colchon sanitario.
C52: ESPECIFICIDADES ITEM 3
C53: Manual, 3 movimientos, barandas rebatibles y desmontables, ruedas por 125mm con freno independiente, lecho de chapa , porta suero inoxidables telescopico recto. Incluye colchon sanitario para obesos.
C55: ESPECIFICIDADES ITEM 4
C56: Estructura de caño de 25 x 25, esmaltado en Epoxi. Reforzada, 4 patas fijas con refuerzo perimetral, tapizado en cuerina de gran espesor. Que soporte hasta 150 kg.
C58: ESPECIFICIDADES ITEM 5
...

Sheet NP
A1: NOTA DE PEDIDO | J1: N° | K1: 09/2022
A3: JURISDICCIÓN: | D3: 040 - MINISTERIO DE SALUD
A4: SAF: | D4: 011 - DIRECCION PROVINCIAL DE ADMINISTRACION DEL MINISTERIO DE SALUD
A5: UNIDAD EJECUTORA: | D5: 352 - MINISTERIO DE SALUD
A6: DEPENDENCIA SOLICITANTE: | D6: 352 - MINISTERIO DE SALUD
A7: PERIODO UTILIZACIÓN: | D7: 3er TRIMESTRE 2022
A8: OBJETO: | D8: ADQUISICION DE EQUIPOS SANITARIOS Y DE LABORATORIO CON DESTINO A HOSPITALES DE LA PROVINCIA
A10: Ítem | B10: Codigo Item | C10: DESCRIPCIÓN | H10: Adjunta Detalle Técnico | I10: Unidad Medida | J10: Precio Unitario Estimado | K10: Cantidad Solicitada
A12: 1 | B12: ='SAF 011 - NECESIDAD TRIMESTRAL'!B10 -> 4.3.3-8790.6 | C12: ='SAF 011 - NECESIDAD TRIMESTRAL'!E10 -> BAÑOS MARIA; DIMENSION: 45 X 30 X 13 mm, ALIMENTACION: 220 V, MATERIAL: ACERO INOXIDABLE, TEMPERATURA MAXIMA: 100 °C | H12: SI | I12: UNIDAD | J12: 50000 | K12: 4
A13: 2 | B13: ='SAF 011 - NECESIDAD TRIMESTRAL'!B11 -> 4.3.3-208.17 | C13: ='SAF 011 - NECESIDAD TRIMESTRAL'!E11 -> CAMAS HOSPITALARIAS; DESTINO: DE INTERNACION, DIMENSION: 190 X 80 X 20 Cm, LECHO: REGULABLE, MOV. ORTOPEDICO: A MANIVELA, MATERIAL ESTRUCTURA: ACERO, TIPO PANEL LATERAL: BARANDA DESMONTABLE, MOVILIDAD: A MANIVELA, MATERIAL: ACERO | H13: SI | I13: UNIDAD | J13: 125000 | K13: 70
A14: 3 | B14: ='SAF 011 - NECESIDAD TRIMESTRAL'!B12 -> 4.3.3-208.12 | C14: ='SAF 011 - NECESIDAD TRIMESTRAL'!E12 -> CAMAS HOSPITALARIAS; DESTINO: PACIENTES + DE 200 KG, DIMENSION: 110 X 200 X 62 Cm, LECHO: ESTRATIFICADO, MOV. ORTOPEDICO: A MANIVELA, MATERIAL ESTRUCTURA: CAÑO, TIPO PANEL LATERAL: DESMONTABLE, MOVILIDAD: A MANIVELA, MATERIAL: CAÑO | H14: SI | I14: UNIDAD | J14: 314363 | K14: 14
A15: 4 | B15: ='SAF 011 - NECESIDAD TRIMESTRAL'!B13 -> 4.3.3-1719.21 | C15: ='SAF 011 - NECESIDAD TRIMESTRAL'!E13 -> CAMILLAS; ANCHO: 50 Cm, LARGO: 200 Cm, ALTO: 75 Cm, ARNESES: SIN, TIPO: EXAMEN | H15: SI | I15: UNIDAD | J15: 32000 | K15: 80
A16: 5 | B16: ='SAF 011 - NECESIDAD TRIMESTRAL'!B14 -> 4.3.3-1719.15 | C16: ='SAF 011 - NECESIDAD TRIMESTRAL'!E14 -> CAMILLAS; ANCHO: 55 Cm, LARGO: 130 Cm, ALTO: 85 Cm, ARNESES: SIN, TIPO: EXAMEN PEDIATRICO | H16: SI | I16: UNIDAD | J16: 32000 | K16: 10
A17: 6 | B17: ='SAF 011 - NECESIDAD TRIMESTRAL'!B15 -> 4.3.3-1719.14 | C17: ='SAF 011 - NECESIDAD TRIMESTRAL'!E15 -> CAMILLAS; ANCHO: 55 Cm, LARGO: 180 Cm, ALTO: 70 Cm, ARNESES: SIN VALOR, TIPO: GINECOLOGICA | H17: SI | I17: UNIDAD | J17: 53000 | K17: 10
A18: 7 | B18: ='SAF 011 - NECESIDAD TRIMESTRAL'!B16 -> 4.3.3-1719.22 | C18: ='SAF 011 - NECESIDAD TRIMESTRAL'!E16 -> CAMILLAS; ANCHO: 80 Cm, LARGO: 200 Cm, ALTO: 75 Cm, ARNESES: SIN, TIPO: EXAMEN | H18: SI | I18: UNIDAD | J18: 43000 | K18: 10
A19: 8 | B19: ='SAF 011 - NECESIDAD TRIMESTRAL'!B17 -> 4.3.3-2046.9 | C19: ='SAF 011 - NECESIDAD TRIMESTRAL'!E17 -> CARDIODESFIBRILADORES; ALIMENTACION: BATERIA, TIPO: EXTERNO BIFASICO, ACCESORIO: MONITOR | H19: SI | I19: UNIDAD | J19: 610000 | K19: 7
A20: 9 | B20: ='SAF 011 - NECESIDAD TRIMESTRAL'!B18 -> 4.3.3-5412.12 | C20: ='SAF 011 - NECESIDAD TRIMESTRAL'!E18 -> CARROS DE CURACIONES; MATERIAL: MELAMINA, ESTANTE: 2, DEFENSA: METALICAS CROMADAS, CAPACIDAD: 3 PORTAFRASCOS, CANT. DE RUEDAS: 4, DIMENSION: 46 X 55 X 78 Cm | H20: SI | I20: UNIDAD | J20: 14300 | K20: 25
A21: 10 | B21: ='SAF 011 - NECESIDAD TRIMESTRAL'!B19 -> 4.3.3-5412.10 | C21: ='SAF 011 - NECESIDAD TRIMESTRAL'!E19 -> CARROS DE CURACIONES; MATERIAL: METAL, ESTANTE: 3, DEFENSA: CON, CAPACIDAD: 7 CRESTAS, CANT. DE RUEDAS: 4, DIMENSION: 76 X 50 X 100 Cm | H21: SI | I21: UNIDAD | J21: 32000 | K21: 25
A22: 11 | B22: ='SAF 011 - NECESIDAD TRIMESTRAL'!B20 -> 4.3.3-67.7 | C22: ='SAF 011 - NECESIDAD TRIMESTRAL'!E20 -> CENTRIFUGAS P/LABORATORIO; CABEZAL: 24 TUBOS, TIPO CABEZAL: 24 TUBOS | H22: SI | I22: UNIDAD | J22: 255062.41 | K22: 5
A23: 12 | B23: ='SAF 011 - NECESIDAD TRIMESTRAL'!B21 -> 4.3.3-6359.1 | C23: ='SAF 011 - NECESIDAD TRIMESTRAL'!E21 -> COLPOSCOPIOS; OBJETIVO: DE F 300 DIST. DE TRABAJO mm, MODELO: OP-C2, AUMENTOS: TRES, LUZ: FRIA DE 150 DE POTENCIA W, PARALELOGRAMO: BALANCEADO Y COMPENSADO, FILTRO: VERDE, BINOCULAR: INCLINADO A 45 °C, SIST. DE VIDEO: P/COLPOSCOPIA, VIDEO PRINTER: CON, AUMENTO: TRES | H23: SI | I23: UNIDAD | J23: 175000 | K23: 4
... A30: 19 | B30: ='SAF 011 - NECESIDAD TRIMESTRAL'!B28 -> 4.3.3-1711.9 | C30: ='SAF 011 - NECESIDAD TRIMESTRAL'!E28 -> SILLAS DE RUEDAS; ANCHO: 61 Cm, APOYABRAZO: DESMONTABLE, PIERNERA: DESMONTABLE, FRENO: CON, MATERIAL: METALICA CROMADA | H30: SI | I30: UNIDAD | J30: 43000 | K30: 28
A32: Costo total estimado: PESOS CUARENTA Y DOS MILLONES TRESCIENTOS UN MIL OCHOCIENTOS SESENTA Y SIETE CON 17/100.- | J32: =SUMPRODUCT(J12:J30,K12:K30) -> 42301867

Sheet APG
A1: EJERCICIO: | D1: 2022 | P1: AUTORIZACION PARA GASTAR
A4: JURISDICCIÓN: | G4: =NP!D3 -> 040 - MINISTERIO DE SALUD
A5: SAF: | G5: =NP!D4 -> 011 - DIRECCION PROVINCIAL DE ADMINISTRACION DEL MINISTERIO DE SALUD
A6: UNIDAD EJECUTORA: | G6: =NP!D5 -> 352 - MINISTERIO DE SALUD
A7: DEPENDENCIA SOLICITANTE: | G7: =NP!D6 -> 352 - MINISTERIO DE SALUD
A8: AUTORIZACIÓN:
A9: Señor Director de Administración o Titular del Servicio Administrativo Financiero:
A10: Autorizo la realización de los trámites correspondientes, a fin de proveer a este Organismo los bienes, servicios o ejecución de obras públicas que se detallan en Nota de Pedido N° 09/2022 , afectando la erogación resultante a los créditos presupuestarios aprobados a favor de esta Unidad Ejecutora, conforme al siguiente detalle:
A12: IMPUTACIÓN PRESUPUESTARIA
A13: CÓDIGO | O13: DENOMINACIÓN DE LA PARTIDA PRESUPUESTARIA | Q13: IMPORTE
A14: PR | B14: SB | C14: PY | D14: AC | E14: OB | F14: UG | G14: FIN | H14: FUN | I14: I | J14: P | K14: P | L14: SubP | M14: M | N14: FF
A15: 1 | D15: 1 | F15: 4901 | G15: 3 | H15: 1 | I15: 4 | J15: 3 | K15: 3 | M15: 1 | N15: 1.1 | O15: EQUIPOS SANITARIOS Y DE LABORATORIO | Q15: 42301867
A38: TOTAL DE PESOS: CUARENTA Y DOS MILLONES TRESCIENTOS UN MIL OCHOCIENTOS SESENTA Y SIETE CON 17/100.- | Q38: =SUM(Q15:Q37) -> 42301867
A40: JUSTIFICACIÓN:
A41: =NP!D8 -> ADQUISICION DE EQUIPOS SANITARIOS Y DE LABORATORIO CON DESTINO A HOSPITALES DE LA PROVINCIA
