Workbook

Sheet Inicio
E7: Primer Fila | F7: 8
E8: Ultima Fila | F8: 159
A13: AYUDA
A14: Los encabezados de color amarillo | D14: indican las celdas que deben modificarse, la ACTUALIZACION ES AUTOMATICA en el Cuadro.
A15: Inicio
A16: CARGAR EL CUADRO DEL COMPR.AR HACIENDO CLICK EN "ARMAR CUADRO"
A17: Ponderacion
A18: CARGA LAS PONDERACIONES: ENTREGA - ANTECEDENTES - PRECIO (valor por defecto 83)
A19: Cuadro
A20: CARGAR LA PONDERACION: CALIDAD EN CADA ITEM

Sheet Ponderacion
A1: Proveedor | B1: Plazo de entrega | C1: Antecedentes | E1: Ponderación precio: | F1: 80 | G1: %
A2: BRUNO RODOLFO LUCERO ALESSANDRO | B2: 3 | C2: 5
A3: SUCESION DE LUIS JAIME KOTLER | B3: 3 | C3: 5
A4: MIGUEL ANGEL MURO | B4: 1.5 | C4: 5

Sheet Cuadro
A2: CUADRO COMPARATIVO DE OFERTAS - PONDERACIÓN DE FACTORES SEGÚN PLIEGO
A5: CONTRATACIÓN DIRECTA 100-0008-CDI22 Adquisición de artículos de librería y papelería para el M.I.D.yS.P. y H.S.J.B.
A7: ITEM | B7: Cant. Solicit. | C7: Alter. | D7: Razon Social Proveedor | E7: Marca | F7: Cant. Ofertada | G7: Precio Unitario | H7: Puntaje Factor Precio | I7: Puntaje Factor Calidad | J7: Puntaje Factor Plazo de Entrega | K7: Puntaje Factor Antecedentes | L7: PUNTAJE TOTAL | M7: Cant. Preadj | N7: Total Preadj
A8: 1 | B8: 100 | C8: 1 | D8: BRUNO RODOLFO LUCERO ALESSANDRO | E8: Resma A4 X500 HOJAS 80GR BOREAL | F8: 100 | G8: 1018 | H8: =(G9*Ponderacion!F1)/G8 -> 67.583497 | I8: 5 | J8: =VLOOKUP(D8,Ponderacion!A2:C4,2,0) -> 3 | K8: =VLOOKUP(D8,Ponderacion!A2:C4,3,0) -> 5 | L8: =SUM(H8:K8) -> 80.583497
A9: 1 | B9: 100 | C9: 1 | D9: SUCESION DE LUIS JAIME KOTLER | E9: PAPELES P/FOTOCOPIADORA; FOTOCOPIADORA: CLC, ANCHO | F9: 100 | G9: 860 | H9: =(G9*Ponderacion!F1)/G9 -> 80 | I9: 12 | J9: =VLOOKUP(D9,Ponderacion!A2:C4,2,0) -> 3 | K9: =VLOOKUP(D9,Ponderacion!A2:C4,3,0) -> 5 | L9: =SUM(H9:K9) -> 100 | M9: =F9 -> 100 | N9: =G9*M9 -> 86000
A10: 1 | B10: 100 | C10: 1 | D10: MIGUEL ANGEL MURO | E10: Resma A4 X500 HOJAS 75GR AUTOR | F10: 100 | G10: 1400 | H10: =(G9*Ponderacion!F1)/G10 -> 49.142857 | I10: 5 | J10: =VLOOKUP(D10,Ponderacion!A2:C4,2,0) -> 1.5 | K10: =VLOOKUP(D10,Ponderacion!A2:C4,3,0) -> 5 | L10: =SUM(H10:K10) -> 60.642857
A11: 2 | B11: 500 | C11: 1 | D11: BRUNO RODOLFO LUCERO ALESSANDRO | E11: LAPICERAS BIC OPACO 1.0MM AZUL | F11: 500 | G11: 34 | H11: =(G11*Ponderacion!F1)/G11 -> 80 | I11: 12 | J11: =VLOOKUP(D11,Ponderacion!A2:C4,2,0) -> 3 | K11: =VLOOKUP(D11,Ponderacion!A2:C4,3,0) -> 5 | L11: =SUM(H11:K11) -> 100 | M11: =F11 -> 500 | N11: =G11*M11 -> 17000
A12: 2 | B12: 500 | C12: 1 | D12: SUCESION DE LUIS JAIME KOTLER | E12: LAPICERAS ESTILOGRAFICAS; TIPO: TRAZO GRUESO, MATE | F12: 500 | G12: 291.86 | H12: =(G11*Ponderacion!F1)/G12 -> 9.3195368 | I12: 5 | J12: =VLOOKUP(D12,Ponderacion!A2:C4,2,0) -> 3 | K12: =VLOOKUP(D12,Ponderacion!A2:C4,3,0) -> 5 | L12: =SUM(H12:K12) -> 22.319537
A13: 2 | B13: 500 | C13: 1 | D13: MIGUEL ANGEL MURO | E13: LAPICERAS BIC OPACO 1.0MM AZUL | F13: 500 | G13: 50 | H13: =(G11*Ponderacion!F1)/G13 -> 54.4 | I13: 5 | J13: =VLOOKUP(D13,Ponderacion!A2:C4,2,0) -> 1.5 | K13: =VLOOKUP(D13,Ponderacion!A2:C4,3,0) -> 5 | L13: =SUM(H13:K13) -> 65.9
A14: 3 | B14: 300 | C14: 1 | D14: BRUNO RODOLFO LUCERO ALESSANDRO | E14: LAPIZ GRADUACION MAPED HB2 N°1 | F14: 300 | G14: 18 | H14: =(G15*Ponderacion!F1)/G14 -> 66.666667 | I14: 5 | J14: =VLOOKUP(D14,Ponderacion!A2:C4,2,0) -> 3 | K14: =VLOOKUP(D14,Ponderacion!A2:C4,3,0) -> 5 | L14: =SUM(H14:K14) -> 79.666667
A15: 3 | B15: 300 | C15: 1 | D15: SUCESION DE LUIS JAIME KOTLER | E15: LAPIZ; COLOR: NEGRO, TIPO: COMUN NRO 1 MARCA GRAF | F15: 300 | G15: 15 | H15: =(G15*Ponderacion!F1)/G15 -> 80 | I15: 12 | J15: =VLOOKUP(D15,Ponderacion!A2:C4,2,0) -> 3 | K15: =VLOOKUP(D15,Ponderacion!A2:C4,3,0) -> 5 | L15: =SUM(H15:K15) -> 100 | M15: =F15 -> 300 | N15: =G15*M15 -> 4500
A16: 3 | B16: 300 | C16: 1 | D16: MIGUEL ANGEL MURO | E16: LAPIZ GRADUACION MAPED HB2 | F16: 300 | G16: 30 | H16: =(G15*Ponderacion!F1)/G16 -> 40 | I16: 5 | J16: =VLOOKUP(D16,Ponderacion!A2:C4,2,0) -> 1.5 | K16: =VLOOKUP(D16,Ponderacion!A2:C4,3,0) -> 5 | L16: =SUM(H16:K16) -> 51.5
A17: 4 | B17: 100 | C17: 1 | D17: BRUNO RODOLFO LUCERO ALESSANDRO | E17: RESMA OFICIO X500HOJAS 80 GR BOREAL | F17: 100 | G17: 1362.5 | H17: =(G18*Ponderacion!F1)/G17 -> 58.656881 | I17: 5 | J17: =VLOOKUP(D17,Ponderacion!A2:C4,2,0) -> 3 | K17: =VLOOKUP(D17,Ponderacion!A2:C4,3,0) -> 5 | L17: =SUM(H17:K17) -> 71.656881
A18: 4 | B18: 100 | C18: 1 | D18: SUCESION DE LUIS JAIME KOTLER | E18: PAPELES P/FOTOCOPIADORA; FOTOCOPIADORA: SIN VALOR, | F18: 100 | G18: 999 | H18: =(G18*Ponderacion!F1)/G18 -> 80 | I18: 12 | J18: =VLOOKUP(D18,Ponderacion!A2:C4,2,0) -> 3 | K18: =VLOOKUP(D18,Ponderacion!A2:C4,3,0) -> 5 | L18: =SUM(H18:K18) -> 100 | M18: =F18 -> 100 | N18: =G18*M18 -> 99900
A19: 4 | B19: 100 | C19: 1 | D19: MIGUEL ANGEL MURO | E19: RESMA OFICIO X500HOJAS 80 GR AUTOR | F19: 100 | G19: 1600 | H19: =(G18*Ponderacion!F1)/G19 -> 49.95 | I19: 5 | J19: =VLOOKUP(D19,Ponderacion!A2:C4,2,0) -> 1.5 | K19: =VLOOKUP(D19,Ponderacion!A2:C4,3,0) -> 5 | L19: =SUM(H19:K19) -> 61.45
A20: 5 | B20: 200 | C20: 1 | D20: BRUNO RODOLFO LUCERO ALESSANDRO | E20: CORRECTOR EZCO X7ML PUNTA METAL. | F20: 200 | G20: 113 | H20: =(G21*Ponderacion!F1)/G20 -> 50.223009 | I20: 5 | J20: =VLOOKUP(D20,Ponderacion!A2:C4,2,0) -> 3 | K20: =VLOOKUP(D20,Ponderacion!A2:C4,3,0) -> 5 | L20: =SUM(H20:K20) -> 63.223009
A21: 5 | B21: 200 | C21: 1 | D21: SUCESION DE LUIS JAIME KOTLER | E21: CORRECTORES DE ESCRITURA; ENVASE: LAPIZ (PUNTA MET | F21: 200 | G21: 70.94 | H21: =(G21*Ponderacion!F1)/G21 -> 80 | I21: 12 | J21: =VLOOKUP(D21,Ponderacion!A2:C4,2,0) -> 3 | K21: =VLOOKUP(D21,Ponderacion!A2:C4,3,0) -> 5 | L21: =SUM(H21:K21) -> 100 | M21: =F21 -> 200 | N21: =G21*M21 -> 14188
A22: 5 | B22: 200 | C22: 1 | D22: MIGUEL ANGEL MURO | E22: CORRECTOR X7ML PIZZINI | F22: 200 | G22: 130 | H22: =(G21*Ponderacion!F1)/G22 -> 43.655385 | I22: 5 | J22: =VLOOKUP(D22,Ponderacion!A2:C4,2,0) -> 1.5 | K22: =VLOOKUP(D22,Ponderacion!A2:C4,3,0) -> 5 | L22: =SUM(H22:K22) -> 55.155385
A23: 6 | B23: 20 | C23: 1 | D23: BRUNO RODOLFO LUCERO ALESSANDRO | E23: ABROCHADORA DE PAPEL, METALICA 21/6 GRAP | F23: 20 | G23: 3504 | H23: =(G24*Ponderacion!F1)/G23 -> 69.911872 | I23: 5 | J23: =VLOOKUP(D23,Ponderacion!A2:C4,2,0) -> 3 | K23: =VLOOKUP(D23,Ponderacion!A2:C4,3,0) -> 5 | L23: =SUM(H23:K23) -> 82.911872
A24: 6 | B24: 20 | C24: 1 | D24: SUCESION DE LUIS JAIME KOTLER | E24: ABROCHADORAS DE PAPEL; MATERIAL: METALICA, TIPO: | F24: 20 | G24: 3062.14 | H24: =(G24*Ponderacion!F1)/G24 -> 80 | I24: 12 | J24: =VLOOKUP(D24,Ponderacion!A2:C4,2,0) -> 3 | K24: =VLOOKUP(D24,Ponderacion!A2:C4,3,0) -> 5 | L24: =SUM(H24:K24) -> 100 | M24: =F24 -> 20 | N24: =G24*M24 -> 61242.8
A25: 6 | B25: 20 | C25: 1 | D25: MIGUEL ANGEL MURO | E25: ABROCHADORAS DE PAPEL; MATERIAL: METALICA, TIPO: D | F25: 20 | G25: 4000 | H25: =(G24*Ponderacion!F1)/G25 -> 61.2428 | I25: 5 | J25: =VLOOKUP(D25,Ponderacion!A2:C4,2,0) -> 1.5 | K25: =VLOOKUP(D25,Ponderacion!A2:C4,3,0) -> 5 | L25: =SUM(H25:K25) -> 72.7428
A26: 7 | B26: 250 | C26: 1 | D26: BRUNO RODOLFO LUCERO ALESSANDRO | E26: RESALTADOR PTA. 5 (CHANFLEADA) TRABI AMARILLO | F26: 250 | G26: 93 | H26: =(G27*Ponderacion!F1)/G26 -> 59.784946 | I26: 5 | J26: =VLOOKUP(D26,Ponderacion!A2:C4,2,0) -> 3 | K26: =VLOOKUP(D26,Ponderacion!A2:C4,3,0) -> 5 | L26: =SUM(H26:K26) -> 72.784946
A27: 7 | B27: 250 | C27: 1 | D27: SUCESION DE LUIS JAIME KOTLER | E27: RESALTADORES; ACCESORIO SIN - TIPO PUNTA 5 (CHANF | F27: 250 | G27: 69.5 | H27: =(G27*Ponderacion!F1)/G27 -> 80 | I27: 12 | J27: =VLOOKUP(D27,Ponderacion!A2:C4,2,0) -> 3 | K27: =VLOOKUP(D27,Ponderacion!A2:C4,3,0) -> 5 | L27: =SUM(H27:K27) -> 100 | M27: =F27 -> 250 | N27: =G27*M27 -> 17375
A28: 7 | B28: 250 | C28: 1 | D28: MIGUEL ANGEL MURO | E28: RESALTADOR PTA CHANFLEADA FILGO AMARILLO | F28: 250 | G28: 110 | H28: =(G27*Ponderacion!F1)/G28 -> 50.545455 | I28: 5 | J28: =VLOOKUP(D28,Ponderacion!A2:C4,2,0) -> 1.5 | K28: =VLOOKUP(D28,Ponderacion!A2:C4,3,0) -> 5 | L28: =SUM(H28:K28) -> 62.045455
A29: 8 | B29: 600 | C29: 1 | D29: BRUNO RODOLFO LUCERO ALESSANDRO | E29: FOLIOS TRANSPARENTES OFICIO LIGGO | F29: 600 | G29: 11.4 | H29: =(G30*Ponderacion!F1)/G29 -> 57.122807 | I29: 5 | J29: =VLOOKUP(D29,Ponderacion!A2:C4,2,0) -> 3 | K29: =VLOOKUP(D29,Ponderacion!A2:C4,3,0) -> 5 | L29: =SUM(H29:K29) -> 70.122807
A30: 8 | B30: 600 | C30: 1 | D30: SUCESION DE LUIS JAIME KOTLER | E30: FOLIOS TRANSPARENTES; MATERIAL: PLASTICO (POLIETIL | F30: 600 | G30: 8.14 | H30: =(G30*Ponderacion!F1)/G30 -> 80 | I30: 12 | J30: =VLOOKUP(D30,Ponderacion!A2:C4,2,0) -> 3 | K30: =VLOOKUP(D30,Ponderacion!A2:C4,3,0) -> 5 | L30: =SUM(H30:K30) -> 100 | M30: =F30 -> 600 | N30: =G30*M30 -> 4884
A31: 8 | B31: 600 | C31: 1 | D31: MIGUEL ANGEL MURO | E31: FOLIOS TRANSPARENTES; MATERIAL: PLASTICO (POLIETI | F31: 600 | G31: 21 | H31: =(G30*Ponderacion!F1)/G31 -> 31.009524 | I31: 5 | J31: =VLOOKUP(D31,Ponderacion!A2:C4,2,0) -> 1.5 | K31: =VLOOKUP(D31,Ponderacion!A2:C4,3,0) -> 5 | L31: =SUM(H31:K31) -> 42.509524
A32: 9 | B32: 1200 | C32: 1 | D32: BRUNO RODOLFO LUCERO ALESSANDRO | E32: FOLIOS TRANSPARENTES A4 LIGGO | F32: 1200 | G32: 10.2 | H32: =(G33*Ponderacion!F1)/G32 -> 53.333333 | I32: 5 | J32: =VLOOKUP(D32,Ponderacion!A2:C4,2,0) -> 3 | K32: =VLOOKUP(D32,Ponderacion!A2:C4,3,0) -> 5 | L32: =SUM(H32:K32) -> 66.333333
A33: 9 | B33: 1200 | C33: 1 | D33: SUCESION DE LUIS JAIME KOTLER | E33: FOLIOS TRANSPARENTES; TAMAÑO: A-4, PERFORACIONES: | F33: 1200 | G33: 6.8 | H33: =(G33*Ponderacion!F1)/G33 -> 80 | I33: 12 | J33: =VLOOKUP(D33,Ponderacion!A2:C4,2,0) -> 3 | K33: =VLOOKUP(D33,Ponderacion!A2:C4,3,0) -> 5 | L33: =SUM(H33:K33) -> 100 | M33: =F33 -> 1200 | N33: =G33*M33 -> 8160
A34: 9 | B34: 1200 | C34: 1 | D34: MIGUEL ANGEL MURO | E34: FOLIOS TRANSPARENTES; TAMAÑO: A-4, PERFORACIONES: | F34: 1200 | G34: 18 | H34: =(G33*Ponderacion!F1)/G34 -> 30.222222 | I34: 5 | J34: =VLOOKUP(D34,Ponderacion!A2:C4,2,0) -> 1.5 | K34: =VLOOKUP(D34,Ponderacion!A2:C4,3,0) -> 5 | L34: =SUM(H34:K34) -> 41.722222
A35: 10 | B35: 250 | C35: 1 | D35: BRUNO RODOLFO LUCERO ALESSANDRO | E35: CAJA DE ARCHIVO LIBREJET OFICIO PLASTICO AZUL | F35: 250 | G35: 300 | H35: =(G37*Ponderacion!F1)/G35 -> 69.333333 | I35: 5 | J35: =VLOOKUP(D35,Ponderacion!A2:C4,2,0) -> 3 | K35: =VLOOKUP(D35,Ponderacion!A2:C4,3,0) -> 5 | L35: =SUM(H35:K35) -> 82.333333
A36: 10 | B36: 250 | C36: 1 | D36: SUCESION DE LUIS JAIME KOTLER | E36: CAJAS DE ARCHIVO; DIMENSION: 26.5 X 38 X 9 Cm, CO | F36: 250 | G36: 288.98 | H36: =(G37*Ponderacion!F1)/G36 -> 71.977299 | I36: 12 | J36: =VLOOKUP(D36,Ponderacion!A2:C4,2,0) -> 3 | K36: =VLOOKUP(D36,Ponderacion!A2:C4,3,0) -> 5 | L36: =SUM(H36:K36) -> 91.977299 | M36: =+F36 -> 250 | N36: =+G36*M36 -> 72245
A37: 10 | B37: 250 | C37: 1 | D37: MIGUEL ANGEL MURO | E37: CAJAS DE ARCHIVO; DIMENSION: 26.5 X 38 X 9 Cm, CO | F37: 250 | G37: 260 | H37: =(G37*Ponderacion!F1)/G37 -> 80 | I37: 5 | J37: =VLOOKUP(D37,Ponderacion!A2:C4,2,0) -> 1.5 | K37: =VLOOKUP(D37,Ponderacion!A2:C4,3,0) -> 5 | L37: =SUM(H37:K37) -> 91.5
A38: 11 | B38: 30 | C38: 1 | D38: BRUNO RODOLFO LUCERO ALESSANDRO | E38: BANDA ELASTICAS EZCO 5CMX100GR BOLSA | F38: 30 | G38: 253 | H38: =(G39*Ponderacion!F1)/G38 -> 41.928854 | I38: 5 | J38: =VLOOKUP(D38,Ponderacion!A2:C4,2,0) -> 3 | K38: =VLOOKUP(D38,Ponderacion!A2:C4,3,0) -> 5 | L38: =SUM(H38:K38) -> 54.928854
A39: 11 | B39: 30 | C39: 1 | D39: SUCESION DE LUIS JAIME KOTLER | E39: BANDAS ELASTICAS; PRESENTACION: CAJA DE 100 GR, E | F39: 30 | G39: 132.6 | H39: =(G39*Ponderacion!F1)/G39 -> 80 | I39: 12 | J39: =VLOOKUP(D39,Ponderacion!A2:C4,2,0) -> 3 | K39: =VLOOKUP(D39,Ponderacion!A2:C4,3,0) -> 5 | L39: =SUM(H39:K39) -> 100 | M39: =F39 -> 30 | N39: =G39*M39 -> 3978
A40: 11 | B40: 30 | C40: 1 | D40: MIGUEL ANGEL MURO | E40: BANDAS ELASTICAS; PRESENTACION: CAJA DE 100 GR, ES | F40: 30 | G40: 335 | H40: =(G39*Ponderacion!F1)/G40 -> 31.665672 | I40: 5 | J40: =VLOOKUP(D40,Ponderacion!A2:C4,2,0) -> 1.5 | K40: =VLOOKUP(D40,Ponderacion!A2:C4,3,0) -> 5 | L40: =SUM(H40:K40) -> 43.165672
A41: 12 | B41: 100 | C41: 1 | D41: BRUNO RODOLFO LUCERO ALESSANDRO | E41: CARPETA COMERCIAL LAMA A4 C/VAINA | F41: 100 | G41: 105 | H41: =(G42*Ponderacion!F1)/G41 -> 68.739048 | I41: 5 | J41: =VLOOKUP(D41,Ponderacion!A2:C4,2,0) -> 3 | K41: =VLOOKUP(D41,Ponderacion!A2:C4,3,0) -> 5 | L41: =SUM(H41:K41) -> 81.739048
A42: 12 | B42: 100 | C42: 1 | D42: SUCESION DE LUIS JAIME KOTLER | E42: CARPETAS COLGANTES; TIPO: INTERIOR, MATERIAL: PLAS | F42: 100 | G42: 90.22 | H42: =(G42*Ponderacion!F1)/G42 -> 80 | I42: 12 | J42: =VLOOKUP(D42,Ponderacion!A2:C4,2,0) -> 3 | K42: =VLOOKUP(D42,Ponderacion!A2:C4,3,0) -> 5 | L42: =SUM(H42:K42) -> 100 | M42: =F42 -> 100 | N42: =G42*M42 -> 9022
A43: 12 | B43: 100 | C43: 1 | D43: MIGUEL ANGEL MURO | E43: CARPETAS COLGANTES; TIPO: INTERIOR, MATERIAL: PLAS | F43: 100 | G43: 200 | H43: =(G42*Ponderacion!F1)/G43 -> 36.088 | I43: 5 | J43: =VLOOKUP(D43,Ponderacion!A2:C4,2,0) -> 1.5 | K43: =VLOOKUP(D43,Ponderacion!A2:C4,3,0) -> 5 | L43: =SUM(H43:K43) -> 47.588
A44: 13 | B44: 100 | C44: 1 | D44: BRUNO RODOLFO LUCERO ALESSANDRO | E44: CARPETA COLGANTE EXTERIOR NEPACO OFICIO AMARILLO | F44: 100 | G44: 188 | H44: =(G44*Ponderacion!F1)/G44 -> 80 | I44: 12 | J44: =VLOOKUP(D44,Ponderacion!A2:C4,2,0) -> 3 | K44: =VLOOKUP(D44,Ponderacion!A2:C4,3,0) -> 5 | L44: =SUM(H44:K44) -> 100 | M44: =F44 -> 100 | N44: =G44*M44 -> 18800
...
