Workbook

Sheet F. CM
A2: ID | B2: CODIGO DEL ITEM | C2: DESCRIPCION | D2: UNIDAD DE MEDIDA | E2: CANTIDAD SOLICITADA
A3: 1 | B3: 2.9.5-441.470 | C3: AGUJAS QUIRURGICAS; TIPO: TERUMO 21GX1", ESPECIFICACION: 25/8, UNIDAD VENTA: CAJA X 100, PRESENTACION: CAJA X 100 TERUMO | D3: CAJA | E3: 3 | F3: BANCO DE SANGRE
A4: 2 | B4: 2.9.5-470.13 | C4: ALGODONES; TIPO: HIDROFILADO, CAPACIDAD: 500 GR, PRESENTACION: ENVASE X 500 GR | D4: UNIDAD | E4: 20
A5: 3 | B5: 2.9.5-428.21 | C5: BARBIJOS; TIPO: 3 CAPAS | D5: UNIDAD | E5: 1000
A6: 4 | B6: 2.9.5-1909.78 | C6: GUANTES USO MEDICINAL; TIPO: EXAMINACION , TAMAÑO: GRANDE, MATERIAL: LATEX, PRESENTACION: ENVASE X 100 UN | D6: CAJA | E6: 10
A7: 5 | B7: 2.9.5-1909.79 | C7: GUANTES USO MEDICINAL; TIPO: EXAMINACION , TAMAÑO: MEDIANO, MATERIAL: LATEX, PRESENTACION: ENVASE X 100 UN | D7: CAJA | E7: 10
A8: 6 | B8: 2.9.5-1909.195 | C8: GUANTES USO MEDICINAL; TIPO: EXAMINACION, TAMAÑO: S 6/7, MATERIAL: LATEX, PRESENTACION: ENVASE X 100 UN, ESTERIL: NO, TALCO: CON, DESCARTABLE: SI | D8: CAJA | E8: 10
A9: 7 | B9: 2.9.5-2157.60 | C9: JERINGAS DESCARTABLES; CAPACIDAD: 10 mL, AGUJA: SIN, USO: MEDICINAL | D9: UNIDAD | E9: 500
A10: 8 | B10: 2.9.5-8239.1 | C10: CHATAS; MATERIAL: PVC | D10: UNIDAD | E10: 10 | F10: FARMACIA
A11: 9 | B11: 2.9.5-2160.10 | C11: DESCARTADORES DE AGUJAS; BOCA: 2, CAPACIDAD: 2 L, MODELO: P/AGUJAS COLECTA MULTIPLE, MODELO EQUIPO: P/AGUJAS COLECTA MULTIPLE, SISTEMA DE CIERRE: P/AGUJAS COLECTA MULTIPLE | D11: UNIDAD | E11: 100
A12: 10 | B12: 2.9.5-1909.135 | C12: GUANTES USO MEDICINAL; TIPO: ESTERIL, TAMAÑO: 6 1/2 CAÑA LARGA, MATERIAL: LATEX, PRESENTACION: PAR, ESTERIL: SI, TALCO: SIN, DESCARTABLE: SI | D12: UNIDAD | E12: 1000
A13: 11 | B13: 2.9.5-1909.79 | C13: GUANTES USO MEDICINAL; TIPO: EXAMINACION , TAMAÑO: MEDIANO, MATERIAL: LATEX, PRESENTACION: ENVASE X 100 UN | D13: UNIDAD | E13: 2000
A14: 12 | B14: 2.9.5-2157.60 | C14: JERINGAS DESCARTABLES; CAPACIDAD: 10 mL, AGUJA: SIN, USO: MEDICINAL | D14: UNIDAD | E14: 50000
A15: 13 | B15: 2.9.5-461.78 | C15: VENDAS USO MEDICO; TIPO: OVATA, MEDIDA: 10 Cm | D15: UNIDAD | E15: 100
A16: 14 | B16: 2.9.5-2205.31 | C16: PROLONGADORES P/GUIA SUERO; USO: ADMINISTRACION DE SOLUCIONES, MODELO: PT26 LONGITUD: 30 CM | D16: UNIDAD | E16: 80
A17: 15 | B17: 2.9.5-931.49 | C17: TELAS ADHESIVAS; ANCHO: 2,5 Cm, LONG.DE CUERPO: 9 M, TIPO: IMPERMEABLE | D17: UNIDAD | E17: 2000
A18: 16 | B18: 2.9.5-931.9 | C18: TELAS ADHESIVAS; LONG.DE CUERPO: 9 M, ANCHO: 5.00 CM, TIPO: HIPOALERGENICA MACROPOROSA TRANSPARENTE | D18: UNIDAD | E18: 200
A19: 17 | B19: 2.9.5-6526.10 | C19: TUBOS P/MEDICINA; TIPO: DE LATEX, USO: P/DRENAJE, PRESENTACION: M, DIMENSION: 5 X 8 MM | D19: UNIDAD | E19: 10
A20: 18 | B20: 2.9.5-2569.151 | C20: TUBOS TRAQUEALES; TIPO: ENDOTRAQUEAL PEDIATR. S/BALON, Nº: 3, NUMERO: 3 | D20: UNIDAD | E20: 10
A21: 19 | B21: 2.9.5-2569.99 | C21: TUBOS TRAQUEALES; Nº: 3 1/2 S/BALON DESCARTABLE, TIPO: ENDOTRAQUEAL PEDIATRICO PERFOR, NUMERO: 3 1/2 S/BALON DESCARTABLE | D21: UNIDAD | E21: 10
A22: 20 | B22: 2.9.5-461.4 | C22: VENDAS USO MEDICO; TIPO: CAMBRIC, MEDIDA: 7 CM X 3 M | D22: UNIDAD | E22: 100
... A25: 23 | B25: 2.9.5-461.27 | C25: VENDAS USO MEDICO; , MEDIDA: 20 CM X 4 M, TIPO: ENYESADA FRAGUADO RAPIDO GYSOFIX | D25: UNIDAD | E25: 150
A26: 24 | B26: 2.9.5-441.470 | C26: AGUJAS QUIRURGICAS; TIPO: TERUMO 21 GX1", ESPECIFICACION: 25/8, UNIDAD VENTA: CAJA X 100, PRESENTACION: CAJA X 100 | D26: UNIDAD | E26: 300 | F26: LABORATORIO
A27: 25 | B27: 2.9.5-441.471 | C27: AGUJAS QUIRURGICAS; TIPO: TERUMO 25GX5/8", ESPECIFICACION: 16/5, UNIDAD VENTA: CAJA X 100, PRESENTACION: CAJA X 100 | D27: UNIDAD | E27: 90
A28: 26 | B28: 2.9.5-470.13 | C28: ALGODONES; TIPO: HIDROFILADO, CAPACIDAD: 500 GR, PRESENTACION: ENVASE X 500 GR | D28: UNIDAD | E28: 300
A29: 27 | B29: 2.9.5-2160.10 | C29: DESCARTADORES DE AGUJAS; BOCA: 2,CAPACIDAD: 2L, MODELO: P/AGUJAS COLECTA MULTIPLE, MODELO EQUIPO: P/AGUJAS COLECTA MULTIPLE, SISTEMA DE CIERRE: P/AGUJAS COLECTA MULTIPLE | D29: UNIDAD | E29: 90
A30: 28 | B30: 2.9.5-1909.79 | C30: GUANTES USO MEDICINAL; TIPO: EXAMINACION, TAMAÑO: MEDIANO, MATERIAL: LATEX, PRESENTACION: ENVASE X 100 UN | D30: UNIDAD | E30: 150
A31: 29 | B31: 2.9.5-1909.195 | C31: GUANTES USO MEDICINAL; TIPO: EXAMINACION, TAMAÑO: S 6/7, MATERIAL: LATEX, PRESENTACION: ENVASE X 100 UN, ESTERIL: NO, TALCO: CON, DESCARTABLE: SI | D31: UNIDAD | E31: 150
A32: 30 | B32: 2.9.5-1909.172 | C32: GUANTES USO MEDICINAL; TIPO: EXAMINACION, TAMAÑO: S 6/7, MATERIAL: NITRILO, PRESENTACION: ENVASE X 100 UN, ESTERIL: NO, TALCO: SIN, DESCARTABLE: SI | D32: UNIDAD | E32: 30
A33: 31 | B33: 2.9.5-1909.174 | C33: GUANTES USO MEDICINAL; TIPO: EXAMINACION, TAMAÑO: L 8/9, MATERIAL: NITRILO, PRESENTACION: ENVASE X 100 UN, ESTERIL: NO, TALCO: SIN, DESCARTABLE: SI | D33: UNIDAD | E33: 15
A34: 32 | B34: 2.9.5-1909.173 | C34: GUANTES USO MEDICINAL; TIPO: EXAMINACION, TAMAÑO: M 7/8, MATERIAL: NITRILO, PRESENTACION: ENVASE X 100 UN, ESTERIL: NO, TALCO: SIN, DESCARTABLE: SI | D34: UNIDAD | E34: 30
A35: 33 | B35: 2.9.5-1909.169 | C35: GUANTES USO MEDICINAL; TIPO: EXAMINACION, TAMAÑO: L 8/9, MATERIAL: VINILO, PRESENTACION: ENVASE X 100 UN, ESTERIL: NO, TALCO: SIN, DESCARTABLE: SI | D35: UNIDAD | E35: 15
A36: 34 | B36: 2.9.5-1909.168 | C36: GUANTES USO MEDICINAL; TIPO: EXAMINACION, TAMAÑO: M 7/8, MATERIAL: VINILO, PRESENTACION: ENVASE X 100 UN, ESTERIL: NO, TALCO: SIN, DESCARTABLE: SI | D36: UNIDAD | E36: 150
A37: 35 | B37: 2.9.5-2157.60 | C37: JERINGAS DESCARTABLES; CAPACIDAD: 10 ML, AGUJA: SIN, USO: MEDICINAL | D37: UNIDAD | E37: 90
A38: 36 | B38: 2.9.5-2157.67 | C38: JERINGAS DESCARTABLES; CAPACIDAD: 5 CM3, AGUJA: SIN, USO: SIN VALOR | D38: UNIDAD | E38: 150
... A40: 38 | B40: 2.9.5-2562.11 | C40: PORTAOBJETOS P/MICROSCOPIO; MATERIAL: VIDRIO, PRESENTACION: CAJA X 100 UN, TAMAÑO: 25 X 76 X 1,2 MM | D40: UNIDAD | E40: 150
A41: 39 | B41: 2.9.5- 470.13 | C41: ALGODONES; TIPO: HIDROFILADO, CAPACIDAD: 500 GR, PRESENTACION: ENVASE X 500 GR | D41: UNIDAD | E41: 20 | F41: ODONTOLOGIA
A42: 40 | B42: 2.9.5- 446.1 | C42: BAJALENGUAS DESCARTABLES; USO: ADULTOS, PAQUETES DE UNIDADES: X 100, PRESENTACION: X 100 | D42: UNIDAD | E42: 1500
A43: 41 | B43: 2.9.5- 428.21 | C43: BARBIJOS; TIPO: 3 CAPAS | D43: UNIDAD | E43: 1500
A44: 42 | B44: 2.9.5- 428.36 | C44: BARBIJOS; TIPO: COPA N95 SIN VALVULA, MATERIAL: NO TEJIDO, CANTIDAD DE CAPAS: DOS, DESCARTABLE: SI, PRESENTACION: UNIDAD | D44: UNIDAD | E44: 300
...

Sheet ACUERDO
A1: Detalle de productos o servicios
A2: N° | B2: Objeto del gasto | C2: Código del ítem | D2: Descripción | E2: Cantidad | F2: UM | G2: Cantidad Farmacia | H2: Importe Farmacia | I2: Cantidad Laboratorio | J2: Importe Laboratorio | K2: Cantidad SAME | L2: Importe SAME | M2: Cantidad CUR | N2: Importe CUR | O2: Cantidad Banco de Sangre | P2: Importe Banco de Sangre | Q2: Cantidad Odontologia | R2: Importe Odontologia | S2: Cantidad Total MS | T2: Precio Unitario | U2: Importe Total
A3: 1 | B3: 2.9.5 | C3: 2.9.5-441.470 | D3: AGUJAS QUIRURGICAS; TIPO: TERUMO 21GX1", ESPECIFICACION: 25/8, UNIDAD VENTA: CAJA X 100, PRESENTACION: CAJA X 100 | E3: 600 | F3: UNIDAD | H3: =+G3*T3 -> 0 | I3: 300 | J3: =+I3*T3 -> 30000 | N3: =+M3*T3 -> 0 | O3: 3 | P3: =+O3*T3 -> 300 | R3: =+Q3*T3 -> 0 | S3: =+G3+I3+K3+M3+O3+Q3 -> 303 | T3: 100 | U3: =+S3*T3 -> 30300
A4: 2 | B4: 2.9.5 | C4: 2.9.5-441.471 | D4: AGUJAS QUIRURGICAS; TIPO: TERUMO 25GX5/8", ESPECIFICACION: 16/5, UNIDAD VENTA: CAJA X 100, PRESENTACION: CAJA X 100 | E4: 105 | F4: UNIDAD | H4: =+G4*T4 -> 0 | I4: 90 | J4: =+I4*T4 -> 9000 | N4: =+M4*T4 -> 0 | P4: =+O4*T4 -> 0 | R4: =+Q4*T4 -> 0 | S4: =+G4+I4+K4+M4+O4+Q4 -> 90 | T4: 100 | U4: =+S4*T4 -> 9000
A5: 3 | B5: 2.9.5 | C5: 2.9.5-441.472 | D5: AGUJAS QUIRURGICAS; TIPO: 25GX5/8", ESPECIFICACION: 16/5, UNIDAD VENTA: CAJA X 100 UN, PRESENTACION: CAJA X 100 UN | E5: 650 | F5: UNIDAD | H5: =+G5*T5 -> 0 | J5: =+I5*T5 -> 0 | N5: =+M5*T5 -> 0 | P5: =+O5*T5 -> 0 | R5: =+Q5*T5 -> 0 | S5: =+G5+I5+K5+M5+O5+Q5 -> 0 | T5: 93 | U5: =+S5*T5 -> 0
A6: 4 | B6: 2.9.5 | C6: 2.9.5-441.92 | D6: AGUJAS QUIRURGICAS; TIPO: DESCARTABLE, ESPECIFICACION: 25 X 0,8, UNIDAD VENTA: CAJA X 100, PRESENTACION: CAJA X 100 | E6: 5500 | F6: UNIDAD | H6: =+G6*T6 -> 0 | J6: =+I6*T6 -> 0 | N6: =+M6*T6 -> 0 | P6: =+O6*T6 -> 0 | R6: =+Q6*T6 -> 0 | S6: =+G6+I6+K6+M6+O6+Q6 -> 0 | T6: 93 | U6: =+S6*T6 -> 0
A7: 5 | B7: 2.9.5 | C7: 2.9.5-441.356 | D7: AGUJAS QUIRURGICAS; TIPO: DESCARTABLE, ESPECIFICACION: 40/12, PRESENTACION: ENVASE X 100 UN | E7: 180 | F7: UNIDAD | H7: =+G7*T7 -> 0 | J7: =+I7*T7 -> 0 | N7: =+M7*T7 -> 0 | P7: =+O7*T7 -> 0 | R7: =+Q7*T7 -> 0 | S7: =+G7+I7+K7+M7+O7+Q7 -> 0 | T7: 93 | U7: =+S7*T7 -> 0
A8: 6 | B8: 2.9.5 | C8: 2.9.5-441.51 | D8: AGUJAS QUIRURGICAS; TIPO: DESCARTABLE, UNIDAD VENTA: 100, ESPECIFICACION: 40/8, PRESENTACION: 100 | E8: 3400 | F8: UNIDAD | H8: =+G8*T8 -> 0 | J8: =+I8*T8 -> 0 | N8: =+M8*T8 -> 0 | P8: =+O8*T8 -> 0 | R8: =+Q8*T8 -> 0 | S8: =+G8+I8+K8+M8+O8+Q8 -> 0 | T8: 93 | U8: =+S8*T8 -> 0
A9: 7 | B9: 2.9.5 | C9: 2.9.5-441.245 | D9: AGUJAS QUIRURGICAS; TIPO: ESTERIL, ESPECIFICACION: 50/8, UNIDAD VENTA: CAJA X 100 UN, PRESENTACION: CAJA X 100 UN | E9: 2555 | F9: UNIDAD
A10: 8 | B10: 2.9.5 | C10: 2.9.5-470.13 | D10: ALGODONES; TIPO: HIDROFILADO, CAPACIDAD: 500 GR, PRESENTACION: ENVASE X 500 GR | E10: 7300 | F10: UNIDAD | H10: =+G10*T10 -> 0 | I10: 300 | J10: =+I10*T10 -> 30000 | N10: =+M10*T10 -> 0 | O10: 20 | P10: =+O10*T10 -> 2000 | Q10: 20 | R10: =+Q10*T10 -> 2000 | S10: =+G10+I10+K10+M10+O10+Q10 -> 340 | T10: 100 | U10: =+S10*T10 -> 34000
A11: 9 | B11: 2.9.5 | C11: 2.9.5-446.1 | D11: BAJALENGUAS DESCARTABLES; USO: ADULTOS, PAQUETES DE UNIDADES: X 100, PRESENTACION: X 100 | E11: 2150 | F11: UNIDAD | H11: =+G11*T11 -> 0 | J11: =+I11*T11 -> 0 | N11: =+M11*T11 -> 0 | P11: =+O11*T11 -> 0 | Q11: 1500 | R11: =+Q11*T11 -> 150000 | S11: =+G11+I11+K11+M11+O11+Q11 -> 1500 | T11: 100 | U11: =+S11*T11 -> 150000
A12: 10 | B12: 2.9.5 | C12: 2.9.5-428.21 | D12: BARBIJOS; TIPO: 3 CAPAS | E12: 1266000 | F12: UNIDAD | H12: =+G12*T12 -> 0 | J12: =+I12*T12 -> 0 | N12: =+M12*T12 -> 0 | O12: 1000 | P12: =+O12*T12 -> 91000 | Q12: 1500 | R12: =+Q12*T12 -> 136500 | S12: =+G12+I12+K12+M12+O12+Q12 -> 2500 | T12: 91 | U12: =+S12*T12 -> 227500
A13: 11 | B13: 2.9.5 | C13: 2.9.5-428.36 | D13: BARBIJOS; TIPO: COPA N95 SIN VALVULA, MATERIAL: NO TEJIDO, CANTIDAD DE CAPAS: DOS, DESCARTABLE: SI, PRESENTACION: UNIDAD | E13: 26800 | F13: UNIDAD | H13: =+G13*T13 -> 0 | J13: =+I13*T13 -> 0 | N13: =+M13*T13 -> 0 | P13: =+O13*T13 -> 0 | Q13: 1500 | R13: =+Q13*T13 -> 139500 | S13: =+G13+I13+K13+M13+O13+Q13 -> 1500 | T13: 93 | U13: =+S13*T13 -> 139500
A14: 12 | B14: 2.9.5 | C14: 2.9.5-4198.9 | D14: ELEMENTOS DESC. P/CIRUGIAS; TIPO: BOTA CAÑA ALTA CON TIRAS, CANTIDAD: 1, PRESENTACION: 1 | E14: 20000 | F14: UNIDAD | H14: =+G14*T14 -> 0 | J14: =+I14*T14 -> 0 | N14: =+M14*T14 -> 0 | P14: =+O14*T14 -> 0 | R14: =+Q14*T14 -> 0 | S14: =+G14+I14+K14+M14+O14+Q14 -> 0 | T14: 91 | U14: =+S14*T14 -> 0
A15: 13 | B15: 2.5.1 | C15: 2.5.1-9004.1319 | D15: SALES; COMPUESTO QUIMICO: CAL SODADA, ESTADO: GRANULADO, CALIDAD: MEDICA, PRESENTACION: ENVASE X 1 KG | E15: 201 | F15: UNIDAD | H15: =+G15*T15 -> 0 | J15: =+I15*T15 -> 0 | N15: =+M15*T15 -> 0 | P15: =+O15*T15 -> 0 | R15: =+Q15*T15 -> 0 | S15: =+G15+I15+K15+M15+O15+Q15 -> 0 | T15: 93 | U15: =+S15*T15 -> 0
A16: 14 | B16: 2.9.5 | C16: 2.9.5-4198.170 | D16: ELEMENTOS DESC. P/CIRUGIAS; TIPO: CAMISOLIN HEMORREP. DE 30 GRAMOS CON MANGAS Y PUÑOS ELASTICOS DE 1,4 MTRS DE LARGO, CANTIDAD: POR UNIDAD, PRESENTACION: UNIDAD | E16: 41000 | F16: UNIDAD | H16: =+G16*T16 -> 0 | J16: =+I16*T16 -> 0 | N16: =+M16*T16 -> 0 | P16: =+O16*T16 -> 0 | Q16: 50 | R16: =+Q16*T16 -> 4550 | S16: =+G16+I16+K16+M16+O16+Q16 -> 50 | T16: 91 | U16: =+S16*T16 -> 4550
A17: 15 | B17: 2.9.5 | C17: 2.9.5-4198.169 | D17: ELEMENTOS DESC. P/CIRUGIAS; TIPO: CAMISOLIN HEMORREP. DE 50 GRAMOS CON MANGAS Y PUÑOS ALGODON DE 1,4 MTRS DE LARGO, CANTIDAD: POR UNIDAD, PRESENTACION: UNIDAD | E17: 51400 | F17: UNIDAD | H17: =+G17*T17 -> 0 | J17: =+I17*T17 -> 0 | N17: =+M17*T17 -> 0 | P17: =+O17*T17 -> 0 | R17: =+Q17*T17 -> 0 | S17: =+G17+I17+K17+M17+O17+Q17 -> 0 | T17: 98 | U17: =+S17*T17 -> 0
A18: 16 | B18: 2.9.5 | C18: 2.9.5-4198.28 | D18: ELEMENTOS DESC. P/CIRUGIAS; TIPO: CEPILLO ESTERIL, CANTIDAD: UNIDAD, PRESENTACION: UNIDAD | E18: 1100 | F18: UNIDAD | H18: =+G18*T18 -> 0 | J18: =+I18*T18 -> 0 | N18: =+M18*T18 -> 0 | P18: =+O18*T18 -> 0 | R18: =+Q18*T18 -> 0 | S18: =+G18+I18+K18+M18+O18+Q18 -> 0 | T18: 93 | U18: =+S18*T18 -> 0
A19: 17 | B19: 2.9.5 | C19: 2.9.5-8239.1 | D19: CHATAS; MATERIAL: PVC | E19: 81 | F19: UNIDAD | G19: 10 | H19: =+G19*T19 -> 930 | J19: =+I19*T19 -> 0 | N19: =+M19*T19 -> 0 | P19: =+O19*T19 -> 0 | R19: =+Q19*T19 -> 0 | S19: =+G19+I19+K19+M19+O19+Q19 -> 10 | T19: 93 | U19: =+S19*T19 -> 930
A20: 18 | B20: 2.9.5 | C20: 2.9.5-8050.1 | D20: CLAMPS UMBILICALES; MATERIAL: PLASTICO, PRESENTACION: UNIDAD | E20: 5000 | F20: UNIDAD | H20: =+G20*T20 -> 0 | J20: =+I20*T20 -> 0 | N20: =+M20*T20 -> 0 | P20: =+O20*T20 -> 0 | R20: =+Q20*T20 -> 0 | S20: =+G20+I20+K20+M20+O20+Q20 -> 0 | T20: 100 | U20: =+S20*T20 -> 0
A21: 19 | B21: 2.2.2 | C21: 2.2.2-915.15 | D21: ROPA DESCARTABLE; ELEMENTO: COFIA, VARIEDAD: CON ELASTICO, ESPECIFICACION: CON ELASTICO | E21: 225000 | F21: UNIDAD | H21: =+G21*T21 -> 0 | J21: =+I21*T21 -> 0 | N21: =+M21*T21 -> 0 | P21: =+O21*T21 -> 0 | R21: =+Q21*T21 -> 0 | S21: =+G21+I21+K21+M21+O21+Q21 -> 0 | T21: 93 | U21: =+S21*T21 -> 0
A22: 20 | B22: 2.9.5 | C22: 2.9.5-2505.24 | D22: BOLSAS COLECTORAS; TIPO: DE ORINA, USO: PEDIATRICO, CAPACIDAD: 100 CM3 | E22: 2000 | F22: UNIDAD | H22: =+G22*T22 -> 0 | J22: =+I22*T22 -> 0 | N22: =+M22*T22 -> 0 | P22: =+O22*T22 -> 0 | R22: =+Q22*T22 -> 0 | S22: =+G22+I22+K22+M22+O22+Q22 -> 0 | T22: 93 | U22: =+S22*T22 -> 0
A23: 21 | B23: 2.9.5 | C23: 2.9.5-9998.1 | D23: RECIPIENTE RECOLECTOR; TIPO: FRASCO, USO: P/ALIMENTACION ENTERAL, CAPACIDAD: 250 ML | E23: 65 | F23: UNIDAD | H23: =+G23*T23 -> 0 | J23: =+I23*T23 -> 0 | N23: =+M23*T23 -> 0 | P23: =+O23*T23 -> 0 | R23: =+Q23*T23 -> 0 | S23: =+G23+I23+K23+M23+O23+Q23 -> 0 | U23: =+S23*T23 -> 0
A24: 22 | B24: 2.9.5 | C24: 2.9.5-466.6 | D24: CUBRECAMILLAS; TIPO: DESCARTABLE DE 30 GRS, CON ELASTICO DE 80 X 210 CM | E24: 505 | F24: UNIDAD | H24: =+G24*T24 -> 0 | J24: =+I24*T24 -> 0 | N24: =+M24*T24 -> 0 | P24: =+O24*T24 -> 0 | R24: =+Q24*T24 -> 0 | S24: =+G24+I24+K24+M24+O24+Q24 -> 0 | T24: 91 | U24: =+S24*T24 -> 0
A25: 23 | B25: 2.9.5 | C25: 2.9.5-2160.10 | D25: DESCARTADORES DE AGUJAS; BOCA: 2, CAPACIDAD: 2 L, MODELO: P/AGUJAS COLECTA MULTIPLE, MODELO EQUIPO: P/AGUJAS COLECTA MULTIPLE, SISTEMA DE CIERRE: P/AGUJAS COLECTA MULTIPLE | E25: 1352 | F25: UNIDAD | G25: 100 | H25: =+G25*T25 -> 9100 | I25: 90 | J25: =+I25*T25 -> 8190 | N25: =+M25*T25 -> 0 | P25: =+O25*T25 -> 0 | R25: =+Q25*T25 -> 0 | S25: =+G25+I25+K25+M25+O25+Q25 -> 190 | T25: 91 | U25: =+S25*T25 -> 17290
A26: 24 | B26: 2.9.5 | C26: 2.9.5-2160.45 | D26: DESCARTADORES DE AGUJAS; BOCA: 2, CAPACIDAD: 8 L, MODELO: P/AGUJAS COLECTA MULTIPLE, MODELO EQUIPO: P/AGUJAS COLECTA MULTIPLE, SISTEMA DE CIERRE: P/AGUJAS COLECTA MULTIPLE | E26: 100 | F26: UNIDAD | H26: =+G26*T26 -> 0 | J26: =+I26*T26 -> 0 | N26: =+M26*T26 -> 0 | P26: =+O26*T26 -> 0 | R26: =+Q26*T26 -> 0 | S26: =+G26+I26+K26+M26+O26+Q26 -> 0 | T26: 91 | U26: =+S26*T26 -> 0
A27: 25 | B27: 2.9.5 | C27: 2.9.5-2225.87 | D27: ELECTRODOS P/MEDICINA; TIPO: ECG, USO: MONITORIZACION, PIN: SIN, AGUJA: SIN, DESCARTABLE: SI | E27: 50000 | F27: UNIDAD | H27: =+G27*T27 -> 0 | J27: =+I27*T27 -> 0 | N27: =+M27*T27 -> 0 | P27: =+O27*T27 -> 0 | R27: =+Q27*T27 -> 0 | S27: =+G27+I27+K27+M27+O27+Q27 -> 0 | T27: 98 | U27: =+S27*T27 -> 0
A28: 26 | B28: 2.9.5 | C28: 2.9.5-448.46 | D28: FRASCOS ESTERILES; CAPACIDAD: 125 mL, PRESENTACION: UNIDAD, GRABADO: SIN, USO: UROCULTIVO | E28: 7000 | F28: UNIDAD | H28: =+G28*T28 -> 0 | J28: =+I28*T28 -> 0 | N28: =+M28*T28 -> 0 | P28: =+O28*T28 -> 0 | R28: =+Q28*T28 -> 0 | S28: =+G28+I28+K28+M28+O28+Q28 -> 0 | T28: 92 | U28: =+S28*T28 -> 0
A29: 27 | B29: 2.9.5 | C29: 2.9.5-5723.1 | D29: ESPATULAS DE AYRE; MATERIAL: MADERA (DESCARTABLE), BOLSA X 100 | E29: 31 | F29: UNIDAD | H29: =+G29*T29 -> 0 | J29: =+I29*T29 -> 0 | N29: =+M29*T29 -> 0 | P29: =+O29*T29 -> 0 | R29: =+Q29*T29 -> 0 | S29: =+G29+I29+K29+M29+O29+Q29 -> 0 | T29: 100 | U29: =+S29*T29 -> 0
A30: 28 | B30: 2.9.5 | C30: 2.9.5-3255.10 | D30: ESPECULOS DESCARTABLES; TIPO: VAGINAL PEQUEÑO, PRESENTACION: UNIDAD, MATERIAL: PLASTICO | E30: 1950 | F30: UNIDAD | H30: =+G30*T30 -> 0 | J30: =+I30*T30 -> 0 | N30: =+M30*T30 -> 0 | P30: =+O30*T30 -> 0 | R30: =+Q30*T30 -> 0 | S30: =+G30+I30+K30+M30+O30+Q30 -> 0 | T30: 93 | U30: =+S30*T30 -> 0
A31: 29 | B31: 2.9.5 | C31: 2.9.5-3255.12 | D31: ESPECULOS DESCARTABLES; TIPO: VAGINAL GRANDE, PRESENTACION: UNIDAD, MATERIAL: PLASTICO | E31: 1250 | F31: UNIDAD | H31: =+G31*T31 -> 0 | J31: =+I31*T31 -> 0 | N31: =+M31*T31 -> 0 | P31: =+O31*T31 -> 0 | R31: =+Q31*T31 -> 0 | S31: =+G31+I31+K31+M31+O31+Q31 -> 0 | T31: 93 | U31: =+S31*T31 -> 0
A32: 30 | B32: 2.9.5 | C32: 2.9.5-3255.11 | D32: ESPECULOS DESCARTABLES; TIPO: VAGINAL MEDIO, PRESENTACION: UNIDAD, MATERIAL: PLASTICO | E32: 3100 | F32: UNIDAD | H32: =+G32*T32 -> 0 | J32: =+I32*T32 -> 0 | N32: =+M32*T32 -> 0 | P32: =+O32*T32 -> 0 | R32: =+Q32*T32 -> 0 | S32: =+G32+I32+K32+M32+O32+Q32 -> 0 | T32: 93 | U32: =+S32*T32 -> 0
A33: 31 | B33: 2.5.2 | C33: 2.5.2-3584.1 | D33: GEL P/ECOGRAFIA; PRESENTACION: ENVASE X 1 Kg | E33: 140 | F33: UNIDAD | H33: =+G33*T33 -> 0 | J33: =+I33*T33 -> 0 | N33: =+M33*T33 -> 0 | P33: =+O33*T33 -> 0 | R33: =+Q33*T33 -> 0 | S33: =+G33+I33+K33+M33+O33+Q33 -> 0 | T33: 93 | U33: =+S33*T33 -> 0
A34: 32 | B34: 2.5.2 | C34: 2.5.2-3584.3 | D34: GEL P/ECOGRAFIA; PRESENTACION: ENVASE X 5 Kg | E34: 30 | F34: UNIDAD | H34: =+G34*T34 -> 0 | J34: =+I34*T34 -> 0 | N34: =+M34*T34 -> 0 | P34: =+O34*T34 -> 0 | R34: =+Q34*T34 -> 0 | S34: =+G34+I34+K34+M34+O34+Q34 -> 0 | T34: 93 | U34: =+S34*T34 -> 0
A35: 33 | B35: 2.9.5 | C35: 2.9.5-1909.224 | D35: GUANTES USO MEDICINAL; TIPO: ESTERIL, TAMAÑO: 7 1/2 CAÑA LARGA, MATERIAL: NITRILO, PRESENTACION: ENVASE X 50 PAR, ESTERIL: SI, TALCO: SIN, DESCARTABLE: SI | E35: 48 | F35: UNIDAD | H35: =+G35*T35 -> 0 | J35: =+I35*T35 -> 0 | N35: =+M35*T35 -> 0 | P35: =+O35*T35 -> 0 | R35: =+Q35*T35 -> 0 | S35: =+G35+I35+K35+M35+O35+Q35 -> 0 | T35: 98 | U35: =+S35*T35 -> 0
A36: 34 | B36: 2.9.5 | C36: 2.9.5-1909.135 | D36: GUANTES USO MEDICINAL; TIPO: ESTERIL, TAMAÑO: 6 1/2 CAÑA LARGA, MATERIAL: LATEX, PRESENTACION: PAR, ESTERIL: SI, TALCO: SIN, DESCARTABLE: SI | E36: 10500 | F36: UNIDAD | G36: 1000 | H36: =+G36*T36 -> 93000 | J36: =+I36*T36 -> 0 | N36: =+M36*T36 -> 0 | P36: =+O36*T36 -> 0 | Q36: 10 | R36: =+Q36*T36 -> 930 | S36: =+G36+I36+K36+M36+O36+Q36 -> 1010 | T36: 93 | U36: =+S36*T36 -> 93930
A37: 35 | B37: 2.9.5 | C37: 2.9.5-1909.203 | D37: GUANTES USO MEDICINAL; TIPO: ESTERIL, TAMAÑO: 7 CAÑA LARGA, MATERIAL: LATEX, PRESENTACION: PAR, ESTERIL: SI, TALCO: SIN, DESCARTABLE: SI | E37: 40000 | F37: UNIDAD | H37: =+G37*T37 -> 0 | J37: =+I37*T37 -> 0 | N37: =+M37*T37 -> 0 | P37: =+O37*T37 -> 0 | Q37: 10 | R37: =+Q37*T37 -> 930 | S37: =+G37+I37+K37+M37+O37+Q37 -> 10 | T37: 93 | U37: =+S37*T37 -> 930
A38: 36 | B38: 2.9.5 | C38: 2.9.5-1909.184 | D38: GUANTES USO MEDICINAL; TIPO: ESTERIL, TAMAÑO: 7 1/2 CAÑA LARGA, MATERIAL: LATEX, PRESENTACION: PAR, ESTERIL: SI, TALCO: SIN, DESCARTABLE: SI | E38: 46000 | F38: UNIDAD | H38: =+G38*T38 -> 0 | J38: =+I38*T38 -> 0 | N38: =+M38*T38 -> 0 | P38: =+O38*T38 -> 0 | R38: =+Q38*T38 -> 0 | S38: =+G38+I38+K38+M38+O38+Q38 -> 0 | T38: 93 | U38: =+S38*T38 -> 0
A39: 37 | B39: 2.9.5 | C39: 2.9.5-1909.202 | D39: GUANTES USO MEDICINAL; TIPO: ESTERIL, TAMAÑO: 8 CAÑA LARGA, MATERIAL: LATEX, PRESENTACION: PAR, ESTERIL: SI, TALCO: SIN, DESCARTABLE: SI | E39: 31300 | F39: UNIDAD | H39: =+G39*T39 -> 0 | J39: =+I39*T39 -> 0 | N39: =+M39*T39 -> 0 | P39: =+O39*T39 -> 0 | R39: =+Q39*T39 -> 0 | S39: =+G39+I39+K39+M39+O39+Q39 -> 0 | T39: 93 | U39: =+S39*T39 -> 0
A40: 38 | B40: 2.9.5 | C40: 2.9.5-1909.223 | D40: GUANTES USO MEDICINAL; TIPO: ESTERIL, TAMAÑO: 8 1/2 CAÑA LARGA, MATERIAL: LATEX, PRESENTACION: PAR, ESTERIL: SI, TALCO: SIN, DESCARTABLE: SI | E40: 9300 | F40: UNIDAD | H40: =+G40*T40 -> 0 | J40: =+I40*T40 -> 0 | N40: =+M40*T40 -> 0 | P40: =+O40*T40 -> 0 | R40: =+Q40*T40 -> 0 | S40: =+G40+I40+K40+M40+O40+Q40 -> 0 | T40: 93 | U40: =+S40*T40 -> 0
...

Sheet NP FCIA
A1: NOTA DE PEDIDO | J1: N° | K1: 018/2022
A3: JURISDICCIÓN: | D3: 040 - MINISTERIO DE SALUD
A4: SAF: | D4: 011 - DIRECCION PROVINCIAL DE ADMINISTRACION - MS
A5: UNIDAD EJECUTORA: | D5: DIRECCION PROVINCIAL DE FARMACIA E INSUMOS
A6: DEPENDENCIA SOLICITANTE: | D6: DIRECCION PROVINCIAL DE FARMACIA E INSUMOS
A7: PERIODO UTILIZACIÓN: | D7: UN (1) MES
A8: OBJETO: | D8: ACUERDO MARCO PEDIDO DE INSUMOS COMUNES
A10: Ítem | B10: Codigo Item | C10: DESCRIPCIÓN | H10: Adjunta Detalle Técnico | I10: Unidad Medida | J10: Precio Unitario Estimado | K10: Cantidad Solicitada
A12: 17 | B12: =ACUERDO!C19 -> 2.9.5-8239.1 | C12: =ACUERDO!D19 -> CHATAS; MATERIAL: PVC | H12: NO | I12: =ACUERDO!F19 -> UNIDAD | J12: =ACUERDO!T19 -> 93 | K12: =ACUERDO!G19 -> 10
A13: 23 | B13: =ACUERDO!C25 -> 2.9.5-2160.10 | C13: =ACUERDO!D25 -> DESCARTADORES DE AGUJAS; BOCA: 2, CAPACIDAD: 2 L, MODELO: P/AGUJAS COLECTA MULTIPLE, MODELO EQUIPO: P/AGUJAS COLECTA MULTIPLE, SISTEMA DE CIERRE: P/AGUJAS COLECTA MULTIPLE | H13: NO | I13: =ACUERDO!F25 -> UNIDAD | J13: =ACUERDO!T25 -> 91 | K13: =ACUERDO!G25 -> 100
A14: 34 | B14: =ACUERDO!C36 -> 2.9.5-1909.135 | C14: =ACUERDO!D36 -> GUANTES USO MEDICINAL; TIPO: ESTERIL, TAMAÑO: 6 1/2 CAÑA LARGA, MATERIAL: LATEX, PRESENTACION: PAR, ESTERIL: SI, TALCO: SIN, DESCARTABLE: SI | H14: NO | I14: =ACUERDO!F36 -> UNIDAD | J14: =ACUERDO!T36 -> 93 | K14: =ACUERDO!G36 -> 1000
A15: 40 | B15: =ACUERDO!C42 -> 2.9.5-1909.79 | C15: =ACUERDO!D42 -> GUANTES USO MEDICINAL; TIPO: EXAMINACION , TAMAÑO: MEDIANO, MATERIAL: LATEX, PRESENTACION: ENVASE X 100 UN | H15: NO | I15: =ACUERDO!F42 -> UNIDAD | J15: =ACUERDO!T42 -> 93 | K15: =ACUERDO!G42 -> 2000
A16: 55 | B16: =ACUERDO!C57 -> 2.9.5-2157.60 | C16: =ACUERDO!D57 -> JERINGAS DESCARTABLES; CAPACIDAD: 10 mL, AGUJA: SIN, USO: MEDICINAL | H16: NO | I16: =ACUERDO!F57 -> UNIDAD | J16: =ACUERDO!T57 -> 93 | K16: =ACUERDO!G57 -> 50000
A17: 66 | B17: =ACUERDO!C68 -> 2.9.5-461.78 | C17: =ACUERDO!D68 -> VENDAS USO MEDICO; TIPO: OVATA, MEDIDA: 10 Cm | H17: NO | I17: =ACUERDO!F68 -> UNIDAD | J17: =ACUERDO!T68 -> 100 | K17: =ACUERDO!G68 -> 100
A18: 77 | B18: =ACUERDO!C79 -> 2.9.5-2205.31 | C18: =ACUERDO!D79 -> PROLONGADORES P/GUIA SUERO; USO: ADMINISTRACION DE SOLUCIONES, MODELO: PT26 LONGITUD: 30 CM | H18: NO | I18: =ACUERDO!F79 -> UNIDAD | J18: =ACUERDO!T79 -> 93 | K18: =ACUERDO!G79 -> 80
A19: 89 | B19: =ACUERDO!C91 -> 2.9.5-931.49 | C19: =ACUERDO!D91 -> TELAS ADHESIVAS; ANCHO: 2,5 Cm, LONG.DE CUERPO: 9 M, TIPO: IMPERMEABLE | H19: NO | I19: =ACUERDO!F91 -> UNIDAD | J19: =ACUERDO!T91 -> 93 | K19: =ACUERDO!G91 -> 2000
A20: 94 | B20: =ACUERDO!C96 -> 2.9.5-931.9 | C20: =ACUERDO!D96 -> TELAS ADHESIVAS; LONG.DE CUERPO: 9 M, ANCHO: 5.00 CM, TIPO: HIPOALERGENICA MACROPOROSA TRANSPARENTE | H20: NO | I20: =ACUERDO!F96 -> UNIDAD | J20: =ACUERDO!T96 -> 93 | K20: =ACUERDO!G96 -> 200
A21: 100 | B21: =ACUERDO!C102 -> 2.9.5-6526.10 | C21: =ACUERDO!D102 -> TUBOS P/MEDICINA; TIPO: DE LATEX, USO: P/DRENAJE, PRESENTACION: M, DIMENSION: 5 X 8 MM | H21: NO | I21: =ACUERDO!F102 -> UNIDAD | J21: =ACUERDO!T102 -> 91 | K21: =ACUERDO!G102 -> 10
A22: 121 | B22: =ACUERDO!C123 -> 2.9.5-2569.151 | C22: =ACUERDO!D123 -> TUBOS TRAQUEALES; TIPO: ENDOTRAQUEAL PEDIATR. S/BALON, Nº: 3, NUMERO: 3 | H22: NO | I22: =ACUERDO!F123 -> UNIDAD | J22: =ACUERDO!T123 -> 93 | K22: =ACUERDO!G123 -> 10
A23: 122 | B23: =ACUERDO!C124 -> 2.9.5-2569.99 | C23: =ACUERDO!D124 -> TUBOS TRAQUEALES; Nº: 3 1/2 S/BALON DESCARTABLE, TIPO: ENDOTRAQUEAL PEDIATRICO PERFOR, NUMERO: 3 1/2 S/BALON DESCARTABLE | H23: NO | I23: =ACUERDO!F124 -> UNIDAD | J23: =ACUERDO!T124 -> 93 | K23: =ACUERDO!G124 -> 10
A24: 127 | B24: =ACUERDO!C129 -> 2.9.5-461.4 | C24: =ACUERDO!D129 -> VENDAS USO MEDICO; TIPO: CAMBRIC, MEDIDA: 7 CM X 3 M | H24: NO | I24: =ACUERDO!F129 -> UNIDAD | J24: =ACUERDO!T129 -> 100 | K24: =ACUERDO!G129 -> 100
A25: 130 | B25: =ACUERDO!C132 -> 2.9.5-461.29 | C25: =ACUERDO!D132 -> VENDAS USO MEDICO; MEDIDA: 10 CM X 4 M, TIPO: ENYESADA FRAGUADO RAPIDO GYSOFIX | H25: NO | I25: =ACUERDO!F132 -> UNIDAD | J25: =ACUERDO!T132 -> 93 | K25: =ACUERDO!G132 -> 300
A26: 131 | B26: =ACUERDO!C133 -> 2.9.5-461.28 | C26: =ACUERDO!D133 -> VENDAS USO MEDICO; MEDIDA: 15 CM X 4 M, TIPO: ENYESADA FRAGUADO RAPIDO GYSOFIX | H26: NO | I26: =ACUERDO!F133 -> UNIDAD | J26: =ACUERDO!T133 -> 93 | K26: =ACUERDO!G133 -> 500
A27: 132 | B27: =ACUERDO!C134 -> 2.9.5-461.27 | C27: =ACUERDO!D134 -> VENDAS USO MEDICO; , MEDIDA: 20 CM X 4 M, TIPO: ENYESADA FRAGUADO RAPIDO GYSOFIX | H27: NO | I27: =ACUERDO!F134 -> UNIDAD | J27: =ACUERDO!T134 -> 93 | K27: =ACUERDO!G134 -> 150
A29: Costo total estimado: PESOS CINCO MILLONES DOSCIENTO SESENTA Y DOS MIL CIENTO NOVENTA CON 00/100.- | J29: =SUMPRODUCT(J12:J27,K12:K27) -> 5262190

Sheet APG FCIA
A1: EJERCICIO: | D1: 2022 | P1: AUTORIZACION PARA GASTAR
A4: JURISDICCIÓN: | G4: ='NP FCIA'!D3 -> 040 - MINISTERIO DE SALUD
A5: SAF: | G5: ='NP FCIA'!D4 -> 011 - DIRECCION PROVINCIAL DE ADMINISTRACION - MS
A6: UNIDAD EJECUTORA: | G6: ='NP FCIA'!D5 -> DIRECCION PROVINCIAL DE FARMACIA E INSUMOS
A7: DEPENDENCIA SOLICITANTE: | G7: ='NP FCIA'!D6 -> DIRECCION PROVINCIAL DE FARMACIA E INSUMOS
A8: AUTORIZACIÓN:
A9: Señor Director de Administración o Titular del Servicio Administrativo Financiero:
A10: Autorizo la realización de los trámites correspondientes, a fin de proveer a este Organismo los bienes que se detallan en Nota de Pedido N° 018/2022 , afectando la erogación resultante a los créditos presupuestarios aprobados a favor de esta Unidad Ejecutora, conforme al siguiente detalle:
A12: IMPUTACIÓN PRESUPUESTARIA
A13: CÓDIGO | O13: DENOMINACIÓN DE LA PARTIDA PRESUPUESTARIA | Q13: IMPORTE
A14: PR | B14: SB | C14: PY | D14: AC | E14: OB | F14: UG | G14: FIN | H14: FUN | I14: I | J14: P | K14: P | L14: SubP | M14: M | N14: FF
A15: 30 | D15: 1 | F15: 4901 | G15: 3 | H15: 1 | I15: 2 | J15: 9 | K15: 5 | M15: 1 | N15: 1.1 | O15: UTILES MENORES MEDICOS, QUIRURGICOS Y DE LABORATORIO | Q15: ='NP FCIA'!J29 -> 5262190
A38: TOTAL DE PESOS: CINCO MILLONES DOSCIENTO SESENTA Y DOS MIL CIENTO NOVENTA CON 00/100.- | Q38: =SUM(Q15:Q37) -> 5262190
A40: JUSTIFICACIÓN:
A41: ='NP FCIA'!D8 -> ACUERDO MARCO PEDIDO DE INSUMOS COMUNES
N125: 91

Sheet NP LAB
A1: NOTA DE PEDIDO | J1: N° | K1: 008/2022
A3: JURISDICCIÓN: | D3: 040 - MINISTERIO DE SALUD
A4: SAF: | D4: 011 - DIRECCION PROVINCIAL DE ADMINISTRACION - MS
A5: UNIDAD EJECUTORA: | D5: DIRECCION PROVINCIAL DE LABORATORIO
A6: DEPENDENCIA SOLICITANTE: | D6: DIRECCION PROVINCIAL DE LABORATORIO
A7: PERIODO UTILIZACIÓN: | D7: UN (1) MES
A8: OBJETO: | D8: ACUERDO MARCO PEDIDO DE INSUMOS COMUNES
A10: Ítem | B10: Codigo Item | C10: DESCRIPCIÓN | H10: Adjunta Detalle Técnico | I10: Unidad Medida | J10: Precio Unitario Estimado | K10: Cantidad Solicitada
A12: 1 | B12: =ACUERDO!C3 -> 2.9.5-441.470 | C12: =ACUERDO!D3 -> AGUJAS QUIRURGICAS; TIPO: TERUMO 21GX1", ESPECIFICACION: 25/8, UNIDAD VENTA: CAJA X 100, PRESENTACION: CAJA X 100 | H12: NO | I12: =ACUERDO!F3 -> UNIDAD | J12: =ACUERDO!T3 -> 100 | K12: =ACUERDO!I3 -> 300
A13: 2 | B13: =ACUERDO!C4 -> 2.9.5-441.471 | C13: =ACUERDO!D4 -> AGUJAS QUIRURGICAS; TIPO: TERUMO 25GX5/8", ESPECIFICACION: 16/5, UNIDAD VENTA: CAJA X 100, PRESENTACION: CAJA X 100 | H13: NO | I13: =ACUERDO!F4 -> UNIDAD | J13: =ACUERDO!T4 -> 100 | K13: =ACUERDO!I4 -> 90
A14: 8 | B14: =ACUERDO!C10 -> 2.9.5-470.13 | C14: =ACUERDO!D10 -> ALGODONES; TIPO: HIDROFILADO, CAPACIDAD: 500 GR, PRESENTACION: ENVASE X 500 GR | H14: NO | I14: =ACUERDO!F10 -> UNIDAD | J14: =ACUERDO!T10 -> 100 | K14: =ACUERDO!I10 -> 300
A15: 23 | B15: =ACUERDO!C25 -> 2.9.5-2160.10 | C15: =ACUERDO!D25 -> DESCARTADORES DE AGUJAS; BOCA: 2, CAPACIDAD: 2 L, MODELO: P/AGUJAS COLECTA MULTIPLE, MODELO EQUIPO: P/AGUJAS COLECTA MULTIPLE, SISTEMA DE CIERRE: P/AGUJAS COLECTA MULTIPLE | H15: NO | I15: =ACUERDO!F25 -> UNIDAD | J15: =ACUERDO!T25 -> 91 | K15: =ACUERDO!I25 -> 90
A16: 40 | B16: =ACUERDO!C42 -> 2.9.5-1909.79 | C16: =ACUERDO!D42 -> GUANTES USO MEDICINAL; TIPO: EXAMINACION , TAMAÑO: MEDIANO, MATERIAL: LATEX, PRESENTACION: ENVASE X 100 UN | H16: NO | I16: =ACUERDO!F42 -> UNIDAD | J16: =ACUERDO!T42 -> 93 | K16: =ACUERDO!I42 -> 150
A17: 41 | B17: =ACUERDO!C43 -> 2.9.5-1909.195 | C17: =ACUERDO!D43 -> GUANTES USO MEDICINAL; TIPO: EXAMINACION, TAMAÑO: S 6/7, MATERIAL: LATEX, PRESENTACION: ENVASE X 100 UN, ESTERIL: NO, TALCO: CON, DESCARTABLE: SI | H17: NO | I17: =ACUERDO!F43 -> UNIDAD | J17: =ACUERDO!T43 -> 93 | K17: =ACUERDO!I43 -> 150
A18: 42 | B18: =ACUERDO!C44 -> 2.9.5-1909.172 | C18: =ACUERDO!D44 -> GUANTES USO MEDICINAL; TIPO: EXAMINACION, TAMAÑO: S 6/7, MATERIAL: NITRILO, PRESENTACION: ENVASE X 100 UN, ESTERIL: NO, TALCO: SIN, DESCARTABLE: SI | H18: NO | I18: =ACUERDO!F44 -> UNIDAD | J18: =ACUERDO!T44 -> 93 | K18: =ACUERDO!I44 -> 30
A19: 43 | B19: =ACUERDO!C45 -> 2.9.5-1909.174 | C19: =ACUERDO!D45 -> GUANTES USO MEDICINAL; TIPO: EXAMINACION, TAMAÑO: L 8/9, MATERIAL: NITRILO, PRESENTACION: ENVASE X 100 UN, ESTERIL: NO, TALCO: SIN, DESCARTABLE: SI | H19: NO | I19: =ACUERDO!F45 -> UNIDAD | J19: =ACUERDO!T45 -> 93 | K19: =ACUERDO!I45 -> 15
A20: 44 | B20: =ACUERDO!C46 -> 2.9.5-1909.173 | C20: =ACUERDO!D46 -> GUANTES USO MEDICINAL; TIPO: EXAMINACION, TAMAÑO: M 7/8, MATERIAL: NITRILO, PRESENTACION: ENVASE X 100 UN, ESTERIL: NO, TALCO: SIN, DESCARTABLE: SI | H20: NO | I20: =ACUERDO!F46 -> UNIDAD | J20: =ACUERDO!T46 -> 93 | K20: =ACUERDO!I46 -> 30
A21: 45 | B21: =ACUERDO!C47 -> 2.9.5-1909.169 | C21: =ACUERDO!D47 -> GUANTES USO MEDICINAL; TIPO: EXAMINACION, TAMAÑO: L 8/9, MATERIAL: VINILO, PRESENTACION: ENVASE X 100 UN, ESTERIL: NO, TALCO: SIN, DESCARTABLE: SI | H21: NO | I21: =ACUERDO!F47 -> UNIDAD | J21: =ACUERDO!T47 -> 93 | K21: =ACUERDO!I47 -> 15
A22: 46 | B22: =ACUERDO!C48 -> 2.9.5-1909.168 | C22: =ACUERDO!D48 -> GUANTES USO MEDICINAL; TIPO: EXAMINACION, TAMAÑO: M 7/8, MATERIAL: VINILO, PRESENTACION: ENVASE X 100 UN, ESTERIL: NO, TALCO: SIN, DESCARTABLE: SI | H22: NO | I22: =ACUERDO!F48 -> UNIDAD | J22: =ACUERDO!T48 -> 93 | K22: =ACUERDO!I48 -> 150
A23: 55 | B23: =ACUERDO!C57 -> 2.9.5-2157.60 | C23: =ACUERDO!D57 -> JERINGAS DESCARTABLES; CAPACIDAD: 10 mL, AGUJA: SIN, USO: MEDICINAL | H23: NO | I23: =ACUERDO!F57 -> UNIDAD | J23: =ACUERDO!T57 -> 93 | K23: =ACUERDO!I57 -> 90
A24: 57 | B24: =ACUERDO!C59 -> 2.9.5-2157.67 | C24: =ACUERDO!D59 -> JERINGAS DESCARTABLES; CAPACIDAD: 5 CM3, AGUJA: SIN, USO: SIN VALOR | H24: NO | I24: =ACUERDO!F59 -> UNIDAD | J24: =ACUERDO!T59 -> 93 | K24: =ACUERDO!I59 -> 150
A25: 65 | B25: =ACUERDO!C67 -> 2.9.5-1909.96 | C25: =ACUERDO!D67 -> GUANTES USO MEDICINAL; TIPO: MANOPLA, TAMAÑO: MEDIANO, MATERIAL: POLIETILENO, PRESENTACION: ENVASE X 100 | H25: NO | I25: =ACUERDO!F67 -> UNIDAD | J25: =ACUERDO!T67 -> 93 | K25: =ACUERDO!I67 -> 150
A26: 75 | B26: =ACUERDO!C77 -> 2.9.5-2562.11 | C26: =ACUERDO!D77 -> PORTAOBJETOS P/MICROSCOPIO; MATERIAL: VIDRIO, PRESENTACION: CAJA X 100 UN, TAMAÑO: 25 X 76 X 1,2 mm | H26: NO | I26: =ACUERDO!F77 -> UNIDAD | J26: =ACUERDO!T77 -> 91 | K26: =ACUERDO!I77 -> 150
A28: Costo total estimado: PESOS CIENTO SETENTA Y SIETE MIL TRESCIENTOS TREINTA CON 00/100.- | J28: =SUMPRODUCT(J12:J26,K12:K26) -> 177330

Sheet APG LAB
A1: EJERCICIO: | D1: 2022 | P1: AUTORIZACION PARA GASTAR
A4: JURISDICCIÓN: | G4: ='NP LAB'!D3 -> 040 - MINISTERIO DE SALUD
A5: SAF: | G5: ='NP LAB'!D4 -> 011 - DIRECCION PROVINCIAL DE ADMINISTRACION - MS
A6: UNIDAD EJECUTORA: | G6: ='NP LAB'!D5 -> DIRECCION PROVINCIAL DE LABORATORIO
A7: DEPENDENCIA SOLICITANTE: | G7: ='NP LAB'!D6 -> DIRECCION PROVINCIAL DE LABORATORIO
A8: AUTORIZACIÓN:
A9: Señor Director de Administración o Titular del Servicio Administrativo Financiero:
A10: Autorizo la realización de los trámites correspondientes, a fin de proveer a este Organismo los bienes que se detallan en Nota de Pedido N° 008/2022 , afectando la erogación resultante a los créditos presupuestarios aprobados a favor de esta Unidad Ejecutora, conforme al siguiente detalle:
A12: IMPUTACIÓN PRESUPUESTARIA
A13: CÓDIGO | O13: DENOMINACIÓN DE LA PARTIDA PRESUPUESTARIA | Q13: IMPORTE
A14: PR | B14: SB | C14: PY | D14: AC | E14: OB | F14: UG | G14: FIN | H14: FUN | I14: I | J14: P | K14: P | L14: SubP | M14: M | N14: FF
A15: 62 | D15: 1 | F15: 4901 | G15: 3 | H15: 1 | I15: 2 | J15: 9 | K15: 5 | M15: 1 | N15: 1.1 | O15: UTILES MENORES MEDICOS, QUIRURGICOS Y DE LABORATORIO | Q15: ='NP LAB'!J28 -> 177330
A38: TOTAL DE PESOS: CIENTO SETENTA Y SIETE MIL TRESCIENTOS TREINTA CON 00/100.- | Q38: =SUM(Q15:Q37) -> 177330
A40: JUSTIFICACIÓN:
A41: ='NP LAB'!D8 -> ACUERDO MARCO PEDIDO DE INSUMOS COMUNES
N125: 91

Sheet NP BS
A1: NOTA DE PEDIDO | J1: N° | K1: 011/2022
A3: JURISDICCIÓN: | D3: 040 - MINISTERIO DE SALUD
A4: SAF: | D4: 011 - DIRECCION PROVINCIAL DE ADMINISTRACION - MS
A5: UNIDAD EJECUTORA: | D5: DIRECCION PROVINCIAL BANCO DE SANGRE
A6: DEPENDENCIA SOLICITANTE: | D6: DIRECCION PROVINCIAL BANCO DE SANGRE
A7: PERIODO UTILIZACIÓN: | D7: UN (1) MES
A8: OBJETO: | D8: ACUERDO MARCO PEDIDO DE INSUMOS COMUNES
A10: Ítem | B10: Codigo Item | C10: DESCRIPCIÓN | H10: Adjunta Detalle Técnico | I10: Unidad Medida | J10: Precio Unitario Estimado | K10: Cantidad Solicitada
A12: 1 | B12: =ACUERDO!C3 -> 2.9.5-441.470 | C12: =ACUERDO!D3 -> AGUJAS QUIRURGICAS; TIPO: TERUMO 21GX1", ESPECIFICACION: 25/8, UNIDAD VENTA: CAJA X 100, PRESENTACION: CAJA X 100 | H12: NO | I12: =ACUERDO!F3 -> UNIDAD | J12: =ACUERDO!T3 -> 100 | K12: =ACUERDO!O3 -> 3
A13: 8 | B13: =ACUERDO!C10 -> 2.9.5-470.13 | C13: =ACUERDO!D10 -> ALGODONES; TIPO: HIDROFILADO, CAPACIDAD: 500 GR, PRESENTACION: ENVASE X 500 GR | H13: NO | I13: =ACUERDO!F10 -> UNIDAD | J13: =ACUERDO!T10 -> 100 | K13: =ACUERDO!O10 -> 20
A14: 10 | B14: =ACUERDO!C12 -> 2.9.5-428.21 | C14: =ACUERDO!D12 -> BARBIJOS; TIPO: 3 CAPAS | H14: NO | I14: =ACUERDO!F12 -> UNIDAD | J14: =ACUERDO!T12 -> 91 | K14: =ACUERDO!O12 -> 1000
A15: 39 | B15: =ACUERDO!C41 -> 2.9.5-1909.78 | C15: =ACUERDO!D41 -> GUANTES USO MEDICINAL; TIPO: EXAMINACION , TAMAÑO: GRANDE, MATERIAL: LATEX, PRESENTACION: ENVASE X 100 UN | H15: NO | I15: =ACUERDO!F41 -> UNIDAD | J15: =ACUERDO!T41 -> 93 | K15: =ACUERDO!O41 -> 10
A16: 40 | B16: =ACUERDO!C42 -> 2.9.5-1909.79 | C16: =ACUERDO!D42 -> GUANTES USO MEDICINAL; TIPO: EXAMINACION , TAMAÑO: MEDIANO, MATERIAL: LATEX, PRESENTACION: ENVASE X 100 UN | H16: NO | I16: =ACUERDO!F42 -> UNIDAD | J16: =ACUERDO!T42 -> 93 | K16: =ACUERDO!O42 -> 10
A17: 41 | B17: =ACUERDO!C43 -> 2.9.5-1909.195 | C17: =ACUERDO!D43 -> GUANTES USO MEDICINAL; TIPO: EXAMINACION, TAMAÑO: S 6/7, MATERIAL: LATEX, PRESENTACION: ENVASE X 100 UN, ESTERIL: NO, TALCO: CON, DESCARTABLE: SI | H17: NO | I17: =ACUERDO!F43 -> UNIDAD | J17: =ACUERDO!T43 -> 93 | K17: =ACUERDO!O43 -> 10
A18: 55 | B18: =ACUERDO!C57 -> 2.9.5-2157.60 | C18: =ACUERDO!D57 -> JERINGAS DESCARTABLES; CAPACIDAD: 10 mL, AGUJA: SIN, USO: MEDICINAL | H18: NO | I18: =ACUERDO!F57 -> UNIDAD | J18: =ACUERDO!T57 -> 93 | K18: =ACUERDO!O57 -> 500
A20: Costo total estimado: PESOS CIENTO CUARENTA Y DOS MIL QUINIENTOS NOVENTA CON 00/100.- | J20: =SUMPRODUCT(J12:J18,K12:K18) -> 142590

Sheet APG BS
A1: EJERCICIO: | D1: 2022 | P1: AUTORIZACION PARA GASTAR
A4: JURISDICCIÓN: | G4: ='NP BS'!D3 -> 040 - MINISTERIO DE SALUD
A5: SAF: | G5: ='NP BS'!D4 -> 011 - DIRECCION PROVINCIAL DE ADMINISTRACION - MS
A6: UNIDAD EJECUTORA: | G6: ='NP BS'!D5 -> DIRECCION PROVINCIAL BANCO DE SANGRE
A7: DEPENDENCIA SOLICITANTE: | G7: ='NP BS'!D6 -> DIRECCION PROVINCIAL BANCO DE SANGRE
A8: AUTORIZACIÓN:
A9: Señor Director de Administración o Titular del Servicio Administrativo Financiero:
A10: Autorizo la realización de los trámites correspondientes, a fin de proveer a este Organismo los bienes que se detallan en Nota de Pedido N° 011/2022 , afectando la erogación resultante a los créditos presupuestarios aprobados a favor de esta Unidad Ejecutora, conforme al siguiente detalle:
A12: IMPUTACIÓN PRESUPUESTARIA
A13: CÓDIGO | O13: DENOMINACIÓN DE LA PARTIDA PRESUPUESTARIA | Q13: IMPORTE
A14: PR | B14: SB | C14: PY | D14: AC | E14: OB | F14: UG | G14: FIN | H14: FUN | I14: I | J14: P | K14: P | L14: SubP | M14: M | N14: FF
A15: 27 | D15: 1 | F15: 4901 | G15: 3 | H15: 1 | I15: 2 | J15: 9 | K15: 5 | M15: 1 | N15: 1.1 | O15: UTILES MENORES MEDICOS, QUIRURGICOS Y DE LABORATORIO | Q15: ='NP BS'!J20 -> 142590
A38: TOTAL DE PESOS: CIENTO CUARENTA Y DOS MIL QUINIENTOS NOVENTA CON 00/100.- | Q38: =SUM(Q15:Q37) -> 142590
A40: JUSTIFICACIÓN:
A41: ='NP BS'!D8 -> ACUERDO MARCO PEDIDO DE INSUMOS COMUNES
N125: 91

Sheet NP DPO
A1: NOTA DE PEDIDO | J1: N° | K1: 006/2022
A3: JURISDICCIÓN: | D3: 040 - MINISTERIO DE SALUD
A4: SAF: | D4: 011 - DIRECCION PROVINCIAL DE ADMINISTRACION - MS
A5: UNIDAD EJECUTORA: | D5: DIRECCION PROVINCIAL DE ODONTOLOGIA
A6: DEPENDENCIA SOLICITANTE: | D6: DIRECCION PROVINCIAL DE ODONTOLOGIA
A7: PERIODO UTILIZACIÓN: | D7: UN (1) MES
A8: OBJETO: | D8: ACUERDO MARCO PEDIDO DE INSUMOS COMUNES
A10: Ítem | B10: Codigo Item | C10: DESCRIPCIÓN | H10: Adjunta Detalle Técnico | I10: Unidad Medida | J10: Precio Unitario Estimado | K10: Cantidad Solicitada
A12: 8 | B12: =ACUERDO!C10 -> 2.9.5-470.13 | C12: =ACUERDO!D10 -> ALGODONES; TIPO: HIDROFILADO, CAPACIDAD: 500 GR, PRESENTACION: ENVASE X 500 GR | H12: NO | I12: =ACUERDO!F10 -> UNIDAD | J12: =ACUERDO!T10 -> 100 | K12: =ACUERDO!Q10 -> 20
A13: 9 | B13: =ACUERDO!C11 -> 2.9.5-446.1 | C13: =ACUERDO!D11 -> BAJALENGUAS DESCARTABLES; USO: ADULTOS, PAQUETES DE UNIDADES: X 100, PRESENTACION: X 100 | H13: NO | I13: =ACUERDO!F11 -> UNIDAD | J13: =ACUERDO!T11 -> 100 | K13: =ACUERDO!Q11 -> 1500
A14: 10 | B14: =ACUERDO!C12 -> 2.9.5-428.21 | C14: =ACUERDO!D12 -> BARBIJOS; TIPO: 3 CAPAS | H14: NO | I14: =ACUERDO!F12 -> UNIDAD | J14: =ACUERDO!T12 -> 91 | K14: =ACUERDO!Q12 -> 1500
A15: 11 | B15: =ACUERDO!C13 -> 2.9.5-428.36 | C15: =ACUERDO!D13 -> BARBIJOS; TIPO: COPA N95 SIN VALVULA, MATERIAL: NO TEJIDO, CANTIDAD DE CAPAS: DOS, DESCARTABLE: SI, PRESENTACION: UNIDAD | H15: NO | I15: =ACUERDO!F13 -> UNIDAD | J15: =ACUERDO!T13 -> 93 | K15: =ACUERDO!Q13 -> 1500
A16: 14 | B16: =ACUERDO!C16 -> 2.9.5-4198.170 | C16: =ACUERDO!D16 -> ELEMENTOS DESC. P/CIRUGIAS; TIPO: CAMISOLIN HEMORREP. DE 30 GRAMOS CON MANGAS Y PUÑOS ELASTICOS DE 1,4 MTRS DE LARGO, CANTIDAD: POR UNIDAD, PRESENTACION: UNIDAD | H16: NO | I16: =ACUERDO!F16 -> UNIDAD | J16: =ACUERDO!T16 -> 91 | K16: =ACUERDO!Q16 -> 50
A17: 34 | B17: =ACUERDO!C36 -> 2.9.5-1909.135 | C17: =ACUERDO!D36 -> GUANTES USO MEDICINAL; TIPO: ESTERIL, TAMAÑO: 6 1/2 CAÑA LARGA, MATERIAL: LATEX, PRESENTACION: PAR, ESTERIL: SI, TALCO: SIN, DESCARTABLE: SI | H17: NO | I17: =ACUERDO!F36 -> UNIDAD | J17: =ACUERDO!T36 -> 93 | K17: =ACUERDO!Q36 -> 10
A18: 35 | B18: =ACUERDO!C37 -> 2.9.5-1909.203 | C18: =ACUERDO!D37 -> GUANTES USO MEDICINAL; TIPO: ESTERIL, TAMAÑO: 7 CAÑA LARGA, MATERIAL: LATEX, PRESENTACION: PAR, ESTERIL: SI, TALCO: SIN, DESCARTABLE: SI | H18: NO | I18: =ACUERDO!F37 -> UNIDAD | J18: =ACUERDO!T37 -> 93 | K18: =ACUERDO!Q37 -> 10
A19: 41 | B19: =ACUERDO!C43 -> 2.9.5-1909.195 | C19: =ACUERDO!D43 -> GUANTES USO MEDICINAL; TIPO: EXAMINACION, TAMAÑO: S 6/7, MATERIAL: LATEX, PRESENTACION: ENVASE X 100 UN, ESTERIL: NO, TALCO: CON, DESCARTABLE: SI | H19: NO | I19: =ACUERDO!F43 -> UNIDAD | J19: =ACUERDO!T43 -> 93 | K19: =ACUERDO!Q43 -> 10
A20: 43 | B20: =ACUERDO!C45 -> 2.9.5-1909.174 | C20: =ACUERDO!D45 -> GUANTES USO MEDICINAL; TIPO: EXAMINACION, TAMAÑO: L 8/9, MATERIAL: NITRILO, PRESENTACION: ENVASE X 100 UN, ESTERIL: NO, TALCO: SIN, DESCARTABLE: SI | H20: NO | I20: =ACUERDO!F45 -> UNIDAD | J20: =ACUERDO!T45 -> 93 | K20: =ACUERDO!Q45 -> 10
A21: 44 | B21: =ACUERDO!C46 -> 2.9.5-1909.173 | C21: =ACUERDO!D46 -> GUANTES USO MEDICINAL; TIPO: EXAMINACION, TAMAÑO: M 7/8, MATERIAL: NITRILO, PRESENTACION: ENVASE X 100 UN, ESTERIL: NO, TALCO: SIN, DESCARTABLE: SI | H21: NO | I21: =ACUERDO!F46 -> UNIDAD | J21: =ACUERDO!T46 -> 93 | K21: =ACUERDO!Q46 -> 10
A22: 50 | B22: =ACUERDO!C52 -> 2.9.5-444.24 | C22: =ACUERDO!D52 -> HOJAS DE BISTURI; TIPO: CAJA X 100 UN, Nº: 15, NUMERO: 15 | H22: NO | I22: =ACUERDO!F52 -> UNIDAD | J22: =ACUERDO!T52 -> 93 | K22: =ACUERDO!Q52 -> 4
A23: 62 | B23: =ACUERDO!C64 -> 2.9.5-4198.171 | C23: =ACUERDO!D64 -> ELEMENTOS DESC. P/CIRUGIAS; TIPO: KIT DE CAMISOLIN 50 GRS CON PUÑO DE ALGODON + COFIA + BOTAS PAR, PRESENTACION: INDIVIDUAL, ESTERIL: NO | H23: NO | I23: =ACUERDO!F64 -> UNIDAD | J23: =ACUERDO!T64 -> 98 | K23: =ACUERDO!Q64 -> 40
A25: Costo total estimado: PESOS CUATROCIENTOS CUARENTA Y UN MIL CUATROCIENTOS NOVENTA Y DOS CON 00/100.- | J25: =SUMPRODUCT(J12:J23,K12:K23) -> 441492

Sheet APG DPO
A1: EJERCICIO: | D1: 2022 | P1: AUTORIZACION PARA GASTAR
A4: JURISDICCIÓN: | G4: ='NP DPO'!D3 -> 040 - MINISTERIO DE SALUD
A5: SAF: | G5: ='NP DPO'!D4 -> 011 - DIRECCION PROVINCIAL DE ADMINISTRACION - MS
A6: UNIDAD EJECUTORA: | G6: ='NP DPO'!D5 -> DIRECCION PROVINCIAL DE ODONTOLOGIA
A7: DEPENDENCIA SOLICITANTE: | G7: ='NP DPO'!D6 -> DIRECCION PROVINCIAL DE ODONTOLOGIA
A8: AUTORIZACIÓN:
A9: Señor Director de Administración o Titular del Servicio Administrativo Financiero:
A10: Autorizo la realización de los trámites correspondientes, a fin de proveer a este Organismo los bienes que se detallan en Nota de Pedido N° 006/2022 , afectando la erogación resultante a los créditos presupuestarios aprobados a favor de esta Unidad Ejecutora, conforme al siguiente detalle:
A12: IMPUTACIÓN PRESUPUESTARIA
A13: CÓDIGO | O13: DENOMINACIÓN DE LA PARTIDA PRESUPUESTARIA | Q13: IMPORTE
A14: PR | B14: SB | C14: PY | D14: AC | E14: OB | F14: UG | G14: FIN | H14: FUN | I14: I | J14: P | K14: P | L14: SubP | M14: M | N14: FF
A15: 29 | D15: 1 | F15: 4901 | G15: 3 | H15: 1 | I15: 2 | J15: 9 | K15: 5 | M15: 1 | N15: 1.1 | O15: UTILES MENORES MEDICOS, QUIRURGICOS Y DE LABORATORIO | Q15: ='NP DPO'!J25 -> 441492
A38: TOTAL DE PESOS: CUATROCIENTOS CUARENTA Y UN MIL CUATROCIENTOS NOVENTA Y DOS CON 00/100.- | Q38: =SUM(Q15:Q37) -> 441492
A40: JUSTIFICACIÓN:
A41: ='NP DPO'!D8 -> ACUERDO MARCO PEDIDO DE INSUMOS COMUNES
N125: 91
